Workbook

Sheet Лист1
A1: Device 0: Tesla V100-SXM2-16GB | B1: Max thread in blocks: 1024 Total Global Memory: 16151,1 MB GPU Global Memory Usage: 0,250568 MB GPU Global Memory Hash Table: 1024 MB Max PARAMETR_SIZE in GPU Global Memory: 7482045 Shared memory per block: 49152 bytes (48 KB) Shared memory per multiprocessor: 98304 bytes (96 KB) Data size in Shared memory per block: 336 bytes (0,328125 KB) Constant Memory: 65536 bytes Parameter data size (in Constant Memory): 1680 bytes (1,64062 KB) Registers per Block: 65536 Warp Size: 32 Compute Capability: 7,0 Can Map Host Memory: Yes Clock Rate: 1530 MHz L2 Cache Size: 6291456 bytes Multiprocessor Count: 80 | C1: Max thread in blocks by axis: (1024, 1024, 64) | D1: Max blocks by axis: (2147483647, 65535, 65535) | E1: PARAMETR_SIZE: 42 | F1: MAX_VALUE_SIZE: 5 | G1: SET_PARAMETR_SIZE_ONE_X: 21 | H1: ANT_SIZE: 500 | I1: MAX_THREAD_CUDA: 512 | J1: NAME_FILE_GRAPH: Parametr_Graph/test42,txt | K1: KOL_ITERATION: 500 | L1: KOL_PROGREV: 5 | M1: KOL_PROGON_STATISTICS: 50 | N1: PARAMETR_RO: 0,999 | O1: PARAMETR_Q: 1 | P1: PRINT_INFORMATION: 0 | Q1: MAX_PARAMETR_VALUE_TO_MIN_OPT: 1 | R1: OPTIMIZE: OPTIMIZE_MIN_1 | S1: FUNCTION: SHAFFERA GO_HASH: 1 | T1: HASH_TABLE_SIZE: 67108864 | U1: ZERO_HASH_RESULT: -1 | V1: ZERO_HASH: 18446744073709551615 | W1: MAX_PROBES: 10000 | X1: MAX_CONST: 8192 | Y1: MAX_SHARED: 6144 | Z1: BLOCK_SIZE: 64 | AA1: BIN_SEARCH: 0 | AB1: NON_WHILE_ANT: 1
A2: Run 4 function ACO 4start0 | B2: 238.033 | C2: 94.5489 | D2: 2.69518 | E2: 4.82714 | F2: 77.8465 | G2: 143.484 | H2: 82.2112 | I2: 100 | J2: 0.182013 | K2: 0.00123005 | L2: 1
A3: Run 4 function ACO 4start1 | B3: 247.767 | C3: 100.253 | D3: 3.6434 | E3: 5.56339 | F3: 79.188 | G3: 147.515 | H3: 79.9068 | I3: 100 | J3: 0.174862 | K3: 0.00123006 | L3: 1
A4: Run 4 function ACO 4start2 | B4: 102.854 | C4: 96.4035 | D4: 2.93992 | E4: 4.96232 | F4: 78.084 | G4: 6.4508 | H4: 78.0544 | I4: 100 | J4: 0.421228 | K4: 0 | L4: 0.999996
A5: Run 4 function ACO 4start3 | B5: 102.874 | C5: 96.3952 | D5: 2.81908 | E5: 5.00123 | F5: 78.0891 | G5: 6.47829 | H5: 76.0684 | I5: 100 | J5: 0.421149 | K5: 0.00123008 | L5: 0.999996
A6: Run 4 function ACO 4start4 | B6: 102.878 | C6: 96.4669 | D6: 2.90715 | E6: 4.95617 | F6: 78.1598 | G6: 6.411 | H6: 74.286 | I6: 100 | J6: 0.421131 | K6: 0.00123006 | L6: 1
A7: Run 4 function ACO 4start5 | B7: 103.02 | C7: 96.553 | D7: 2.8836 | E7: 4.98177 | F7: 78.2018 | G7: 6.46743 | H7: 72.75 | I7: 100 | J7: 0.420549 | K7: 0.00123008 | L7: 0.999999
A8: Run 4 function ACO 4start6 | B8: 106.713 | C8: 99.3402 | D8: 3.41096 | E8: 5.42619 | F8: 78.9718 | G8: 7.37289 | H8: 71.1188 | I8: 100 | J8: 0.405996 | K8: 0.00123006 | L8: 1
A9: Run 4 function ACO 4start7 | B9: 102.101 | C9: 95.7969 | D9: 2.83444 | E9: 4.98177 | F9: 78.0297 | G9: 6.30421 | H9: 69.5212 | I9: 100 | J9: 0.424336 | K9: 0.00123007 | L9: 0.999996
A10: Run 4 function ACO 4start8 | B10: 100.356 | C10: 94.554 | D10: 2.71668 | E10: 4.80154 | F10: 77.743 | G10: 5.80215 | H10: 68.3052 | I10: 100 | J10: 0.431714 | K10: 0.00123005 | L10: 0.999984
A11: Run 4 function ACO 4start9 | B11: 100.166 | C11: 94.3584 | D11: 2.70132 | E11: 4.80359 | F11: 77.7082 | G11: 5.80784 | H11: 66.9964 | I11: 100 | J11: 0.432532 | K11: 0.00123006 | L11: 0.999997
A12: Run 4 function ACO 4start10 | B12: 100.177 | C12: 94.3492 | D12: 2.70644 | E12: 4.81178 | F12: 77.7358 | G12: 5.82825 | H12: 65.6792 | I12: 100 | J12: 0.432484 | K12: 0.00123006 | L12: 1
A13: Run 4 function ACO 4start11 | B13: 100.179 | C13: 94.386 | D13: 2.69108 | E13: 4.80973 | F13: 77.7184 | G13: 5.79274 | H13: 64.5496 | I13: 100 | J13: 0.432478 | K13: 0.00123006 | L13: 0.999996
... A201: Run 4 function ACO 4start transposed49 | B201: 86.0826 | C201: 80.4595 | D201: 2.78734 | E201: 12.7417 | F201: 55.8948 | G201: 5.62304 | H201: 51.3776 | I201: 100 | J201: 0.503297 | K201: 0.00123006 | L201: 0.999717
A202: Device 0: Tesla V100-SXM2-16GB | B202: Max thread in blocks: 1024 Total Global Memory: 16151,1 MB GPU Global Memory Usage: 0,497303 MB GPU Global Memory Hash Table: 1024 MB Max PARAMETR_SIZE in GPU Global Memory: 7482045 Shared memory per block: 49152 bytes (48 KB) Shared memory per multiprocessor: 98304 bytes (96 KB) Data size in Shared memory per block: 672 bytes (0,65625 KB) Constant Memory: 65536 bytes Parameter data size (in Constant Memory): 3360 bytes (3,28125 KB) Registers per Block: 65536 Warp Size: 32 Compute Capability: 7,0 Can Map Host Memory: Yes Clock Rate: 1530 MHz L2 Cache Size: 6291456 bytes Multiprocessor Count: 80 | C202: Max thread in blocks by axis: (1024, 1024, 64) | D202: Max blocks by axis: (2147483647, 65535, 65535) | E202: PARAMETR_SIZE: 84 | F202: MAX_VALUE_SIZE: 5 | G202: SET_PARAMETR_SIZE_ONE_X: 21 | H202: ANT_SIZE: 500 | I202: MAX_THREAD_CUDA: 512 | J202: NAME_FILE_GRAPH: Parametr_Graph/test84,txt | K202: KOL_ITERATION: 500 | L202: KOL_PROGREV: 5 | M202: KOL_PROGON_STATISTICS: 50 | N202: PARAMETR_RO: 0,999 | O202: PARAMETR_Q: 1 | P202: PRINT_INFORMATION: 0 | Q202: MAX_PARAMETR_VALUE_TO_MIN_OPT: 1 | R202: OPTIMIZE: OPTIMIZE_MIN_1 | S202: FUNCTION: SHAFFERA GO_HASH: 1 | T202: HASH_TABLE_SIZE: 67108864 | U202: ZERO_HASH_RESULT: -1 | V202: ZERO_HASH: 18446744073709551615 | W202: MAX_PROBES: 10000 | X202: MAX_CONST: 8192 | Y202: MAX_SHARED: 6144 | Z202: BLOCK_SIZE: 64 | AA202: BIN_SEARCH: 0 | AB202: NON_WHILE_ANT: 1
A203: Run 4 function ACO 4start0 | B203: 107.144 | C203: 101.557 | D203: 2.81192 | E203: 5.91054 | F203: 83.6893 | G203: 5.58665 | H203: 98.8364 | I203: 100 | J203: 0.791344 | K203: 0.0012301 | L203: 0.995116
A204: Run 4 function ACO 4start1 | B204: 107.023 | C204: 101.388 | D204: 2.79348 | E204: 5.92078 | F204: 83.6166 | G204: 5.63462 | H204: 98.6512 | I204: 100 | J204: 0.792239 | K204: 0.00123053 | L204: 0.995116
A205: Run 4 function ACO 4start2 | B205: 107.16 | C205: 101.523 | D205: 2.78632 | E205: 5.94945 | F205: 83.6309 | G205: 5.63651 | H205: 98.3508 | I205: 100 | J205: 0.791226 | K205: 0.00123085 | L205: 0.995115
A206: Run 4 function ACO 4start3 | B206: 107.246 | C206: 101.541 | D206: 2.78529 | E206: 5.94843 | F206: 83.6699 | G206: 5.70474 | H206: 98.1628 | I206: 100 | J206: 0.790593 | K206: 0.00123276 | L206: 0.995116
A207: Run 4 function ACO 4start4 | B207: 107.182 | C207: 101.523 | D207: 2.81396 | E207: 5.94228 | F207: 83.6258 | G207: 5.65817 | H207: 97.9712 | I207: 100 | J207: 0.791066 | K207: 0.00123035 | L207: 0.995116
A208: Run 4 function ACO 4start5 | B208: 107.152 | C208: 101.496 | D208: 2.81499 | E208: 5.95969 | F208: 83.6063 | G208: 5.65612 | H208: 99.8664 | I208: 100 | J208: 0.791285 | K208: 0.00123028 | L208: 0.995116
A209: Run 4 function ACO 4start6 | B209: 107.031 | C209: 101.424 | D209: 2.78017 | E209: 5.96071 | F209: 83.5808 | G209: 5.60678 | H209: 99.7016 | I209: 100 | J209: 0.792179 | K209: 0.00123107 | L209: 0.995116
A210: Run 4 function ACO 4start7 | B210: 107.083 | C210: 101.452 | D210: 2.78529 | E210: 5.973 | F210: 83.5644 | G210: 5.63168 | H210: 99.5044 | I210: 100 | J210: 0.79179 | K210: 0.00123007 | L210: 0.995116
A211: Run 4 function ACO 4start8 | B211: 107.177 | C211: 101.505 | D211: 2.80372 | E211: 5.95048 | F211: 83.6207 | G211: 5.67251 | H211: 99.332 | I211: 100 | J211: 0.791096 | K211: 0.00123012 | L211: 0.995116
A212: Run 4 function ACO 4start9 | B212: 107.139 | C212: 101.522 | D212: 2.80372 | E212: 6.0068 | F212: 83.5889 | G212: 5.61676 | H212: 99.0668 | I212: 100 | J212: 0.791379 | K212: 0.00123188 | L212: 0.995116
A213: Run 4 function ACO 4start10 | B213: 107.012 | C213: 101.426 | D213: 2.7812 | E213: 5.99861 | F213: 83.5838 | G213: 5.58545 | H213: 98.8936 | I213: 100 | J213: 0.792322 | K213: 0.0012301 | L213: 0.995116
A214: Run 4 function ACO 4start11 | B214: 107.126 | C214: 101.519 | D214: 2.8242 | E214: 6.01602 | F214: 83.6042 | G214: 5.60699 | H214: 98.6652 | I214: 100 | J214: 0.791474 | K214: 0.00123008 | L214: 0.995116
... A402: Run 4 function ACO 4start transposed49 | B402: 96.7612 | C402: 90.991 | D402: 2.82625 | E402: 21.9688 | F402: 56.9292 | G402: 5.77023 | H402: 50.6972 | I402: 100 | J402: 0.876256 | K402: 0.00123557 | L402: 0.995116
A403: Device 0: Tesla V100-SXM2-16GB | B403: Max thread in blocks: 1024 Total Global Memory: 16151,1 MB GPU Global Memory Usage: 0,990772 MB GPU Global Memory Hash Table: 1024 MB Max PARAMETR_SIZE in GPU Global Memory: 7482045 Shared memory per block: 49152 bytes (48 KB) Shared memory per multiprocessor: 98304 bytes (96 KB) Data size in Shared memory per block: 1344 bytes (1,3125 KB) Constant Memory: 65536 bytes Parameter data size (in Constant Memory): 6720 bytes (6,5625 KB) Registers per Block: 65536 Warp Size: 32 Compute Capability: 7,0 Can Map Host Memory: Yes Clock Rate: 1530 MHz L2 Cache Size: 6291456 bytes Multiprocessor Count: 80 | C403: Max thread in blocks by axis: (1024, 1024, 64) | D403: Max blocks by axis: (2147483647, 65535, 65535) | E403: PARAMETR_SIZE: 168 | F403: MAX_VALUE_SIZE: 5 | G403: SET_PARAMETR_SIZE_ONE_X: 21 | H403: ANT_SIZE: 500 | I403: MAX_THREAD_CUDA: 512 | J403: NAME_FILE_GRAPH: Parametr_Graph/test168,txt | K403: KOL_ITERATION: 500 | L403: KOL_PROGREV: 5 | M403: KOL_PROGON_STATISTICS: 50 | N403: PARAMETR_RO: 0,999 | O403: PARAMETR_Q: 1 | P403: PRINT_INFORMATION: 0 | Q403: MAX_PARAMETR_VALUE_TO_MIN_OPT: 1 | R403: OPTIMIZE: OPTIMIZE_MIN_1 | S403: FUNCTION: SHAFFERA GO_HASH: 1 | T403: HASH_TABLE_SIZE: 67108864 | U403: ZERO_HASH_RESULT: -1 | V403: ZERO_HASH: 18446744073709551615 | W403: MAX_PROBES: 10000 | X403: MAX_CONST: 8192 | Y403: MAX_SHARED: 6144 | Z403: BLOCK_SIZE: 64 | AA403: BIN_SEARCH: 0 | AB403: NON_WHILE_ANT: 1
A404: Run 4 function ACO 4start0 | B404: 248.806 | C404: 104.453 | D404: 2.8539 | E404: 8.07527 | F404: 84.1226 | G404: 144.353 | H404: 99.9844 | I404: 100 | J404: 0.674069 | K404: 0.0108605 | L404: 0.994598
A405: Run 4 function ACO 4start1 | B405: 1613.64 | C405: 104.219 | D405: 2.81192 | E405: 8.12033 | F405: 84.0264 | G405: 1509.42 | H405: 99.9768 | I405: 100 | J405: 0.103934 | K405: 0.0108592 | L405: 0.990449
A406: Run 4 function ACO 4start2 | B406: 242.608 | C406: 105.912 | D406: 3.07918 | E406: 8.34151 | F406: 84.269 | G406: 136.696 | H406: 99.9936 | I406: 100 | J406: 0.69129 | K406: 0.0141769 | L406: 0.981019
A407: Run 4 function ACO 4start3 | B407: 258.594 | C407: 108.83 | D407: 3.54818 | E407: 8.86374 | F407: 84.993 | G407: 149.765 | H407: 99.9836 | I407: 100 | J407: 0.648555 | K407: 0.0108671 | L407: 0.995023
A408: Run 4 function ACO 4start4 | B408: 110.068 | C408: 104.279 | D408: 2.81908 | E408: 8.09268 | F408: 83.9956 | G408: 5.78907 | H408: 99.9864 | I408: 100 | J408: 1.52372 | K408: 0.0108606 | L408: 0.987039
A409: Run 4 function ACO 4start5 | B409: 109.618 | C409: 103.993 | D409: 2.79758 | E409: 8.08347 | F409: 84.0263 | G409: 5.62524 | H409: 99.9624 | I409: 100 | J409: 1.52997 | K409: 0.0108658 | L409: 0.993821
A410: Run 4 function ACO 4start6 | B410: 109.701 | C410: 104.046 | D410: 2.79758 | E410: 8.10292 | F410: 84.0407 | G410: 5.65479 | H410: 99.9516 | I410: 100 | J410: 1.52881 | K410: 0.0108872 | L410: 0.994407
A411: Run 4 function ACO 4start7 | B411: 109.633 | C411: 103.996 | D411: 2.80372 | E411: 8.08244 | F411: 84.0294 | G411: 5.63659 | H411: 99.966 | I411: 100 | J411: 1.52977 | K411: 0.0108627 | L411: 0.981016
A412: Run 4 function ACO 4start8 | B412: 109.654 | C412: 104.029 | D412: 2.79758 | E412: 8.10087 | F412: 84.0366 | G412: 5.62502 | H412: 99.9452 | I412: 100 | J412: 1.52947 | K412: 0.0109455 | L412: 0.988477
A413: Run 4 function ACO 4start9 | B413: 109.644 | C413: 104.006 | D413: 2.81806 | E413: 8.08756 | F413: 84.0335 | G413: 5.63713 | H413: 99.9424 | I413: 100 | J413: 1.52962 | K413: 0.0118968 | L413: 0.990892
A414: Run 4 function ACO 4start10 | B414: 109.592 | C414: 103.988 | D414: 2.81601 | E414: 8.11009 | F414: 84.0478 | G414: 5.60356 | H414: 99.9344 | I414: 100 | J414: 1.53034 | K414: 0.0109552 | L414: 0.981019
...

Sheet Лист1_1
A1: Device 0: Tesla V100-SXM2-16GB | B1: Max thread in blocks: 1024 Total Global Memory: 16151,1 MB GPU Global Memory Usage: 0,250568 MB GPU Global Memory Hash Table: 16 MB Max PARAMETR_SIZE in GPU Global Memory: 7980613 Shared memory per block: 49152 bytes (48 KB) Shared memory per multiprocessor: 98304 bytes (96 KB) Data size in Shared memory per block: 336 bytes (0,328125 KB) Constant Memory: 65536 bytes Parameter data size (in Constant Memory): 1680 bytes (1,64062 KB) Registers per Block: 65536 Warp Size: 32 Compute Capability: 7,0 Can Map Host Memory: Yes Clock Rate: 1530 MHz L2 Cache Size: 6291456 bytes Multiprocessor Count: 80 | C1: Max thread in blocks by axis: (1024, 1024, 64) | D1: Max blocks by axis: (2147483647, 65535, 65535) | E1: PARAMETR_SIZE: 42 | F1: MAX_VALUE_SIZE: 5 | G1: SET_PARAMETR_SIZE_ONE_X: 21 | H1: ANT_SIZE: 500 | I1: MAX_THREAD_CUDA: 512 | J1: NAME_FILE_GRAPH: Parametr_Graph/test42,txt | K1: KOL_ITERATION: 500 | L1: KOL_PROGREV: 5 | M1: KOL_PROGON_STATISTICS: 50 | N1: PARAMETR_RO: 0,999 | O1: PARAMETR_Q: 1 | P1: PRINT_INFORMATION: 0 | Q1: MAX_PARAMETR_VALUE_TO_MIN_OPT: 1 | R1: OPTIMIZE: OPTIMIZE_MIN_1 | S1: FUNCTION: SHAFFERA GO_HASH: 1 | T1: HASH_TABLE_SIZE: 1048576 | U1: ZERO_HASH_RESULT: -1 | V1: ZERO_HASH: 18446744073709551615 | W1: MAX_PROBES: 10000 | X1: MAX_CONST: 8192 | Y1: MAX_SHARED: 49152 | Z1: BLOCK_SIZE: 64 | AA1: BIN_SEARCH: 0 | AB1: NON_WHILE_ANT: 1
A2: Run 4 function ACO 4start0 | B2: 4020.3 | C2: 4014.01 | D2: 3.08123 | E2: 3992.29 | F2: 8.21453 | G2: 6.28564 | H2: 100 | I2: 100 | J2: 0.0107766 | K2: 0.00123005 | L2: 0.996112
A3: Run 4 function ACO 4start1 | B3: 4452.78 | C3: 4015.81 | D3: 3.1355 | E3: 3994.61 | F3: 7.71072 | G3: 436.968 | H3: 100 | I3: 100 | J3: 0.0097299 | K3: 0.00123006 | L3: 0.995116
A4: Run 4 function ACO 4start2 | B4: 4011.96 | C4: 4005.6 | D4: 3.09557 | E4: 3984.23 | F4: 7.74144 | G4: 6.35254 | H4: 98.5228 | I4: 100 | J4: 0.010799 | K4: 0.00123037 | L4: 0.995897
A5: Run 4 function ACO 4start3 | B5: 4143.5 | C5: 4011.91 | D5: 3.02184 | E5: 3990.76 | F5: 7.71584 | G5: 131.596 | H5: 99.6348 | I5: 100 | J5: 0.0104562 | K5: 0.00123006 | L5: 0.995116
A6: Run 4 function ACO 4start4 | B6: 4022.23 | C6: 4015.87 | D6: 3.08635 | E6: 3994.39 | F6: 7.78343 | G6: 6.36035 | H6: 100 | I6: 100 | J6: 0.0107714 | K6: 0.00123005 | L6: 0.995235
A7: Run 4 function ACO 4start5 | B7: 4023.08 | C7: 4016.73 | D7: 3.04027 | E7: 3995.36 | F7: 7.79366 | G7: 6.34937 | H7: 100 | I7: 100 | J7: 0.0107692 | K7: 0.00123005 | L7: 0.995586
A8: Run 4 function ACO 4start6 | B8: 4022.04 | C8: 4015.76 | D8: 3.06894 | E8: 3994.56 | F8: 7.70048 | G8: 6.27759 | H8: 100 | I8: 100 | J8: 0.0107719 | K8: 0.00123007 | L8: 0.996122
A9: Run 4 function ACO 4start7 | B9: 4020.93 | C9: 4014.46 | D9: 3.1611 | E9: 3992.79 | F9: 7.93702 | G9: 6.46704 | H9: 100 | I9: 100 | J9: 0.0107749 | K9: 0.0012301 | L9: 0.995239
A10: Run 4 function ACO 4start8 | B10: 4527.18 | C10: 4014.22 | D10: 3.11809 | E10: 3992.9 | F10: 7.78239 | G10: 512.954 | H10: 99.9368 | I10: 100 | J10: 0.00957001 | K10: 0.00123047 | L10: 0.998067
A11: Run 4 function ACO 4start9 | B11: 4618.44 | C11: 4015.85 | D11: 3.07918 | E11: 3994.46 | F11: 7.81311 | G11: 602.588 | H11: 99.9572 | I11: 100 | J11: 0.00938091 | K11: 0.00123005 | L11: 0.996693
A12: Run 4 function ACO 4start10 | B12: 5043.74 | C12: 4017.84 | D12: 3.1396 | E12: 3996.18 | F12: 7.86739 | G12: 1025.9 | H12: 100 | I12: 100 | J12: 0.00858988 | K12: 0.00123005 | L12: 0.996709
A13: Run 4 function ACO 4start11 | B13: 4021.02 | C13: 4014.64 | D13: 3.03515 | E13: 3993.3 | F13: 7.73939 | G13: 6.3772 | H13: 99.9988 | I13: 100 | J13: 0.0107747 | K13: 0.00123009 | L13: 0.995116
... A201: Run 4 function ACO 4start transposed49 | B201: 5153.75 | C201: 5147.53 | D201: 3.2123 | E201: 5038.12 | F201: 95.8311 | G201: 6.21875 | H201: 51.7996 | I201: 100 | J201: 0.00840653 | K201: 0.00123006 | L201: 0.995116
A202: Device 0: Tesla V100-SXM2-16GB | B202: Max thread in blocks: 1024 Total Global Memory: 16151,1 MB GPU Global Memory Usage: 0,497303 MB GPU Global Memory Hash Table: 16 MB Max PARAMETR_SIZE in GPU Global Memory: 7980613 Shared memory per block: 49152 bytes (48 KB) Shared memory per multiprocessor: 98304 bytes (96 KB) Data size in Shared memory per block: 672 bytes (0,65625 KB) Constant Memory: 65536 bytes Parameter data size (in Constant Memory): 3360 bytes (3,28125 KB) Registers per Block: 65536 Warp Size: 32 Compute Capability: 7,0 Can Map Host Memory: Yes Clock Rate: 1530 MHz L2 Cache Size: 6291456 bytes Multiprocessor Count: 80 | C202: Max thread in blocks by axis: (1024, 1024, 64) | D202: Max blocks by axis: (2147483647, 65535, 65535) | E202: PARAMETR_SIZE: 84 | F202: MAX_VALUE_SIZE: 5 | G202: SET_PARAMETR_SIZE_ONE_X: 21 | H202: ANT_SIZE: 500 | I202: MAX_THREAD_CUDA: 512 | J202: NAME_FILE_GRAPH: Parametr_Graph/test84,txt | K202: KOL_ITERATION: 500 | L202: KOL_PROGREV: 5 | M202: KOL_PROGON_STATISTICS: 50 | N202: PARAMETR_RO: 0,999 | O202: PARAMETR_Q: 1 | P202: PRINT_INFORMATION: 0 | Q202: MAX_PARAMETR_VALUE_TO_MIN_OPT: 1 | R202: OPTIMIZE: OPTIMIZE_MIN_1 | S202: FUNCTION: SHAFFERA GO_HASH: 1 | T202: HASH_TABLE_SIZE: 1048576 | U202: ZERO_HASH_RESULT: -1 | V202: ZERO_HASH: 18446744073709551615 | W202: MAX_PROBES: 10000 | X202: MAX_CONST: 8192 | Y202: MAX_SHARED: 49152 | Z202: BLOCK_SIZE: 64 | AA202: BIN_SEARCH: 0 | AB202: NON_WHILE_ANT: 1
A203: Run 4 function ACO 4start0 | B203: 4035.52 | C203: 4029.07 | D203: 3.46421 | E203: 3995.39 | F203: 8.36403 | G203: 6.45557 | H203: 100 | I203: 100 | J203: 0.0210103 | K203: 0.00125174 | L203: 0.995114
A204: Run 4 function ACO 4start1 | B204: 4260.19 | C204: 4016.94 | D204: 3.35464 | E204: 3995.07 | F204: 7.94726 | G204: 243.248 | H204: 100 | I204: 100 | J204: 0.0199023 | K204: 0.00135373 | L204: 0.995115
A205: Run 4 function ACO 4start2 | B205: 4024.61 | C205: 4018.24 | D205: 3.36078 | E205: 3996.05 | F205: 8.03328 | G205: 6.36914 | H205: 99.9924 | I205: 100 | J205: 0.0210673 | K205: 0.00125079 | L205: 0.995116
A206: Run 4 function ACO 4start3 | B206: 4022.61 | C206: 4016.37 | D206: 3.27989 | E206: 3994.9 | F206: 7.82745 | G206: 6.24072 | H206: 100 | I206: 100 | J206: 0.0210777 | K206: 0.00123005 | L206: 0.995115
A207: Run 4 function ACO 4start4 | B207: 4025.12 | C207: 4018.81 | D207: 3.33314 | E207: 3996.95 | F207: 7.96058 | G207: 6.30737 | H207: 100 | I207: 100 | J207: 0.0210646 | K207: 0.00134037 | L207: 0.995115
A208: Run 4 function ACO 4start5 | B208: 4023.63 | C208: 4017.2 | D208: 3.43451 | E208: 3995.03 | F208: 8.11623 | G208: 6.42627 | H208: 100 | I208: 100 | J208: 0.0210724 | K208: 0.00127372 | L208: 0.995116
A209: Run 4 function ACO 4start6 | B209: 4488.06 | C209: 4017.9 | D209: 3.40482 | E209: 3995.93 | F209: 7.98822 | G209: 470.161 | H209: 100 | I209: 100 | J209: 0.0188918 | K209: 0.00123045 | L209: 0.995115
A210: Run 4 function ACO 4start7 | B210: 4023.05 | C210: 4016.71 | D210: 3.29422 | E210: 3995.06 | F210: 7.89401 | G210: 6.33154 | H210: 100 | I210: 100 | J210: 0.0210755 | K210: 0.00123336 | L210: 0.995116
A211: Run 4 function ACO 4start8 | B211: 4022.58 | C211: 4016.42 | D211: 3.40687 | E211: 3994.84 | F211: 7.851 | G211: 6.15503 | H211: 100 | I211: 100 | J211: 0.0210779 | K211: 0.0012439 | L211: 0.995115
A212: Run 4 function ACO 4start9 | B212: 4025.44 | C212: 4019.16 | D212: 3.40789 | E212: 3997.32 | F212: 7.93805 | G212: 6.28442 | H212: 100 | I212: 100 | J212: 0.0210629 | K212: 0.00123196 | L212: 0.995116
A213: Run 4 function ACO 4start10 | B213: 4023.33 | C213: 4016.97 | D213: 3.46421 | E213: 3994.92 | F213: 8.05069 | G213: 6.35278 | H213: 100 | I213: 100 | J213: 0.021074 | K213: 0.00123416 | L213: 0.995116
A214: Run 4 function ACO 4start11 | B214: 4025.28 | C214: 4018.89 | D214: 3.3403 | E214: 3997.08 | F214: 7.95546 | G214: 6.39014 | H214: 100 | I214: 100 | J214: 0.0210638 | K214: 0.00123534 | L214: 0.995116
... A402: Run 4 function ACO 4start transposed49 | B402: 5210.96 | C402: 5204.49 | D402: 3.46319 | E402: 5095.8 | F402: 94.814 | G402: 6.47314 | H402: 50.9932 | I402: 100 | J402: 0.016271 | K402: 0.00123144 | L402: 0.995116
A403: Device 0: Tesla V100-SXM2-16GB | B403: Max thread in blocks: 1024 Total Global Memory: 16151,1 MB GPU Global Memory Usage: 0,990772 MB GPU Global Memory Hash Table: 16 MB Max PARAMETR_SIZE in GPU Global Memory: 7980613 Shared memory per block: 49152 bytes (48 KB) Shared memory per multiprocessor: 98304 bytes (96 KB) Data size in Shared memory per block: 1344 bytes (1,3125 KB) Constant Memory: 65536 bytes Parameter data size (in Constant Memory): 6720 bytes (6,5625 KB) Registers per Block: 65536 Warp Size: 32 Compute Capability: 7,0 Can Map Host Memory: Yes Clock Rate: 1530 MHz L2 Cache Size: 6291456 bytes Multiprocessor Count: 80 | C403: Max thread in blocks by axis: (1024, 1024, 64) | D403: Max blocks by axis: (2147483647, 65535, 65535) | E403: PARAMETR_SIZE: 168 | F403: MAX_VALUE_SIZE: 5 | G403: SET_PARAMETR_SIZE_ONE_X: 21 | H403: ANT_SIZE: 500 | I403: MAX_THREAD_CUDA: 512 | J403: NAME_FILE_GRAPH: Parametr_Graph/test168,txt | K403: KOL_ITERATION: 500 | L403: KOL_PROGREV: 5 | M403: KOL_PROGON_STATISTICS: 50 | N403: PARAMETR_RO: 0,999 | O403: PARAMETR_Q: 1 | P403: PRINT_INFORMATION: 0 | Q403: MAX_PARAMETR_VALUE_TO_MIN_OPT: 1 | R403: OPTIMIZE: OPTIMIZE_MIN_1 | S403: FUNCTION: SHAFFERA GO_HASH: 1 | T403: HASH_TABLE_SIZE: 1048576 | U403: ZERO_HASH_RESULT: -1 | V403: ZERO_HASH: 18446744073709551615 | W403: MAX_PROBES: 10000 | X403: MAX_CONST: 8192 | Y403: MAX_SHARED: 49152 | Z403: BLOCK_SIZE: 64 | AA403: BIN_SEARCH: 0 | AB403: NON_WHILE_ANT: 1
A404: Run 4 function ACO 4start0 | B404: 4024.22 | C404: 4018.56 | D404: 2.91636 | E404: 3998.43 | F404: 7.84076 | G404: 5.66309 | H404: 100 | I404: 100 | J404: 0.0416758 | K404: 0.0151234 | L404: 0.980924
A405: Run 4 function ACO 4start1 | B405: 4027.91 | C405: 4021.73 | D405: 3.09352 | E405: 4000.48 | F405: 7.95649 | G405: 6.17725 | H405: 100 | I405: 100 | J405: 0.0416377 | K405: 0.0117191 | L405: 0.98098
A406: Run 4 function ACO 4start2 | B406: 4023.87 | C406: 4018.21 | D406: 2.92251 | E406: 3998.27 | F406: 7.6759 | G406: 5.65381 | H406: 100 | I406: 100 | J406: 0.0416794 | K406: 0.0226716 | L406: 0.980991
A407: Run 4 function ACO 4start3 | B407: 4278.54 | C407: 4019.11 | D407: 2.96449 | E407: 3998.93 | F407: 7.7783 | G407: 259.426 | H407: 100 | I407: 100 | J407: 0.0391986 | K407: 0.0111844 | L407: 0.981019
A408: Run 4 function ACO 4start4 | B408: 4025.6 | C408: 4019.45 | D408: 3.07304 | E408: 3998.21 | F408: 7.9923 | G408: 6.14307 | H408: 100 | I408: 100 | J408: 0.0416616 | K408: 0.0118759 | L408: 0.981019
A409: Run 4 function ACO 4start5 | B409: 4023.76 | C409: 4018.13 | D409: 2.89384 | E409: 3998.34 | F409: 7.65952 | G409: 5.63452 | H409: 100 | I409: 100 | J409: 0.0416806 | K409: 0.0114666 | L409: 0.980976
A410: Run 4 function ACO 4start6 | B410: 4027.61 | C410: 4021.52 | D410: 3.09352 | E410: 4000.33 | F410: 7.95135 | G410: 6.09326 | H410: 100 | I410: 100 | J410: 0.0416407 | K410: 0.0111219 | L410: 0.981018
A411: Run 4 function ACO 4start7 | B411: 4023.89 | C411: 4018.2 | D411: 2.9051 | E411: 3998.31 | F411: 7.69331 | G411: 5.68091 | H411: 100 | I411: 100 | J411: 0.0416793 | K411: 0.0246223 | L411: 0.981019
A412: Run 4 function ACO 4start8 | B412: 4027.35 | C412: 4020.67 | D412: 2.92456 | E412: 4000.37 | F412: 7.84077 | G412: 6.67896 | H412: 100 | I412: 100 | J412: 0.0416434 | K412: 0.0133764 | L412: 0.9949
A413: Run 4 function ACO 4start9 | B413: 4025.86 | C413: 4019.5 | D413: 3.03925 | E413: 3998.32 | F413: 7.81823 | G413: 6.36572 | H413: 100 | I413: 100 | J413: 0.0416588 | K413: 0.0134136 | L413: 0.995104
A414: Run 4 function ACO 4start10 | B414: 4025.78 | C414: 4019.5 | D414: 2.95425 | E414: 3998.55 | F414: 7.73324 | G414: 6.28027 | H414: 100 | I414: 100 | J414: 0.0416597 | K414: 0.0119778 | L414: 0.993836
...

Sheet Лист2
A1: Device 0: Tesla V100-SXM2-16GB | B1: Max thread in blocks: 1024 Total Global Memory: 16151,1 MB GPU Global Memory Usage: 0,250568 MB GPU Global Memory Hash Table: 1024 MB Max PARAMETR_SIZE in GPU Global Memory: 7482045 Shared memory per block: 49152 bytes (48 KB) Shared memory per multiprocessor: 98304 bytes (96 KB) Data size in Shared memory per block: 336 bytes (0,328125 KB) Constant Memory: 65536 bytes Parameter data size (in Constant Memory): 1680 bytes (1,64062 KB) Registers per Block: 65536 Warp Size: 32 Compute Capability: 7,0 Can Map Host Memory: Yes Clock Rate: 1530 MHz L2 Cache Size: 6291456 bytes Multiprocessor Count: 80 | C1: Max thread in blocks by axis: (1024, 1024, 64) | D1: Max blocks by axis: (2147483647, 65535, 65535) | E1: PARAMETR_SIZE: 42 | F1: MAX_VALUE_SIZE: 5 | G1: SET_PARAMETR_SIZE_ONE_X: 21 | H1: ANT_SIZE: 500 | I1: MAX_THREAD_CUDA: 512 | J1: NAME_FILE_GRAPH: Parametr_Graph/test42,txt | K1: KOL_ITERATION: 500 | L1: KOL_PROGREV: 5 | M1: KOL_PROGON_STATISTICS: 50 | N1: PARAMETR_RO: 0,999 | O1: PARAMETR_Q: 1 | P1: PRINT_INFORMATION: 0 | Q1: MAX_PARAMETR_VALUE_TO_MIN_OPT: 1 | R1: OPTIMIZE: OPTIMIZE_MIN_1 | S1: FUNCTION: SHAFFERA GO_HASH: 0 | T1: HASH_TABLE_SIZE: 67108864 | U1: ZERO_HASH_RESULT: -1 | V1: ZERO_HASH: 18446744073709551615 | W1: MAX_PROBES: 10000 | X1: MAX_CONST: 8192 | Y1: MAX_SHARED: 6144 | Z1: BLOCK_SIZE: 64 | AA1: BIN_SEARCH: 0 | AB1: NON_WHILE_ANT: 1
A2: Run 4 function ACO 4start0 | B2: 104.56 | C2: 97.8819 | D2: 3.22254 | E2: 5.18657 | F2: 79.0253 | G2: 6.67862 | H2: 100 | I2: 100 | J2: 0.414355 | K2: 0.00123009 | L2: 0.999998
A3: Run 4 function ACO 4start1 | B3: 105.052 | C3: 98.2587 | D3: 3.25429 | E3: 5.27976 | F3: 79.0703 | G3: 6.79322 | H3: 100 | I3: 100 | J3: 0.412416 | K3: 0.00123005 | L3: 0.999989
A4: Run 4 function ACO 4start2 | B4: 104.92 | C4: 98.1164 | D4: 3.27681 | E4: 5.27975 | F4: 79.015 | G4: 6.80357 | H4: 100 | I4: 100 | J4: 0.412935 | K4: 0.00123005 | L4: 0.999996
A5: Run 4 function ACO 4start3 | B5: 104.889 | C5: 98.1133 | D5: 3.24405 | E5: 5.25415 | F5: 79.0549 | G5: 6.77603 | H5: 100 | I5: 100 | J5: 0.413056 | K5: 0.00123006 | L5: 0.999996
A6: Run 4 function ACO 4start4 | B6: 104.603 | C6: 97.9034 | D6: 3.22459 | E6: 5.22139 | F6: 78.9699 | G6: 6.7 | H6: 100 | I6: 100 | J6: 0.414185 | K6: 0.00123006 | L6: 0.999996
A7: Run 4 function ACO 4start5 | B7: 104.751 | C7: 97.9812 | D7: 3.25531 | E7: 5.23265 | F7: 78.9606 | G7: 6.77027 | H7: 100 | I7: 100 | J7: 0.413599 | K7: 0.00123006 | L7: 0.999983
A8: Run 4 function ACO 4start6 | B8: 103.614 | C8: 96.9277 | D8: 3.08225 | E8: 5.08827 | F8: 78.421 | G8: 6.68615 | H8: 100 | I8: 100 | J8: 0.41814 | K8: 0.00123006 | L8: 0.999999
A9: Run 4 function ACO 4start7 | B9: 104.751 | C9: 97.9465 | D9: 3.25122 | E9: 5.27669 | F9: 78.7927 | G9: 6.80412 | H9: 100 | I9: 100 | J9: 0.413603 | K9: 0.00123006 | L9: 0.999999
A10: Run 4 function ACO 4start8 | B10: 104.824 | C10: 98.0478 | D10: 3.30754 | E10: 5.29512 | F10: 78.8459 | G10: 6.77657 | H10: 100 | I10: 100 | J10: 0.413311 | K10: 0.00123006 | L10: 1
A11: Run 4 function ACO 4start9 | B11: 104.793 | C11: 97.9842 | D11: 3.25224 | E11: 5.30023 | F11: 78.8132 | G11: 6.80831 | H11: 100 | I11: 100 | J11: 0.413437 | K11: 0.00123006 | L11: 0.999981
A12: Run 4 function ACO 4start10 | B12: 103.4 | C12: 96.8314 | D12: 3.09249 | E12: 5.10875 | F12: 78.3698 | G12: 6.56848 | H12: 100 | I12: 100 | J12: 0.419006 | K12: 0.00123005 | L12: 0.999994
A13: Run 4 function ACO 4start11 | B13: 104.779 | C13: 98.0222 | D13: 3.25531 | E13: 5.34632 | F13: 78.802 | G13: 6.75699 | H13: 100 | I13: 100 | J13: 0.41349 | K13: 0.00123006 | L13: 1
... A201: Run 4 function ACO 4start transposed49 | B201: 105.391 | C201: 98.7652 | D201: 3.22152 | E201: 12.9444 | F201: 72.1714 | G201: 6.62604 | H201: 100 | I201: 100 | J201: 0.411089 | K201: 0.00123006 | L201: 0.998549
A202: Device 0: Tesla V100-SXM2-16GB | B202: Max thread in blocks: 1024 Total Global Memory: 16151,1 MB GPU Global Memory Usage: 0,497303 MB GPU Global Memory Hash Table: 1024 MB Max PARAMETR_SIZE in GPU Global Memory: 7482045 Shared memory per block: 49152 bytes (48 KB) Shared memory per multiprocessor: 98304 bytes (96 KB) Data size in Shared memory per block: 672 bytes (0,65625 KB) Constant Memory: 65536 bytes Parameter data size (in Constant Memory): 3360 bytes (3,28125 KB) Registers per Block: 65536 Warp Size: 32 Compute Capability: 7,0 Can Map Host Memory: Yes Clock Rate: 1530 MHz L2 Cache Size: 6291456 bytes Multiprocessor Count: 80 | C202: Max thread in blocks by axis: (1024, 1024, 64) | D202: Max blocks by axis: (2147483647, 65535, 65535) | E202: PARAMETR_SIZE: 84 | F202: MAX_VALUE_SIZE: 5 | G202: SET_PARAMETR_SIZE_ONE_X: 21 | H202: ANT_SIZE: 500 | I202: MAX_THREAD_CUDA: 512 | J202: NAME_FILE_GRAPH: Parametr_Graph/test84,txt | K202: KOL_ITERATION: 500 | L202: KOL_PROGREV: 5 | M202: KOL_PROGON_STATISTICS: 50 | N202: PARAMETR_RO: 0,999 | O202: PARAMETR_Q: 1 | P202: PRINT_INFORMATION: 0 | Q202: MAX_PARAMETR_VALUE_TO_MIN_OPT: 1 | R202: OPTIMIZE: OPTIMIZE_MIN_1 | S202: FUNCTION: SHAFFERA GO_HASH: 0 | T202: HASH_TABLE_SIZE: 67108864 | U202: ZERO_HASH_RESULT: -1 | V202: ZERO_HASH: 18446744073709551615 | W202: MAX_PROBES: 10000 | X202: MAX_CONST: 8192 | Y202: MAX_SHARED: 6144 | Z202: BLOCK_SIZE: 64 | AA202: BIN_SEARCH: 0 | AB202: NON_WHILE_ANT: 1
A203: Run 4 function ACO 4start0 | B203: 112.77 | C203: 106.112 | D203: 2.99726 | E203: 6.08258 | F203: 86.4966 | G203: 6.65776 | H203: 100 | I203: 100 | J203: 0.751864 | K203: 0.00123085 | L203: 0.995116
A204: Run 4 function ACO 4start1 | B204: 112.677 | C204: 106.03 | D204: 3.00648 | E204: 6.08463 | F204: 86.4025 | G204: 6.64655 | H204: 100 | I204: 100 | J204: 0.752485 | K204: 0.00123009 | L204: 0.995116
A205: Run 4 function ACO 4start2 | B205: 113.272 | C205: 106.108 | D205: 3.06177 | E205: 6.10613 | F205: 86.4178 | G205: 7.16456 | H205: 100 | I205: 100 | J205: 0.748528 | K205: 0.00123019 | L205: 0.995116
A206: Run 4 function ACO 4start3 | B206: 113.993 | C206: 106.915 | D206: 3.22971 | E206: 6.25357 | F206: 86.6336 | G206: 7.07848 | H206: 100 | I206: 100 | J206: 0.743794 | K206: 0.00123005 | L206: 0.995116
A207: Run 4 function ACO 4start4 | B207: 115.767 | C207: 108.232 | D207: 3.4171 | E207: 6.45531 | F207: 87.0789 | G207: 7.53529 | H207: 100 | I207: 100 | J207: 0.732399 | K207: 0.00123078 | L207: 0.995116
A208: Run 4 function ACO 4start5 | B208: 115.538 | C208: 107.526 | D208: 3.25224 | E208: 6.3437 | F208: 86.8693 | G208: 8.01195 | H208: 100 | I208: 100 | J208: 0.733851 | K208: 0.00123005 | L208: 0.995116
A209: Run 4 function ACO 4start6 | B209: 113.045 | C209: 106.319 | D209: 3.08225 | E209: 6.23003 | F209: 86.5756 | G209: 6.72568 | H209: 100 | I209: 100 | J209: 0.750035 | K209: 0.00123103 | L209: 0.995116
A210: Run 4 function ACO 4start7 | B210: 113.226 | C210: 106.434 | D210: 3.13653 | E210: 6.20034 | F210: 86.6122 | G210: 6.79253 | H210: 100 | I210: 100 | J210: 0.748835 | K210: 0.0012312 | L210: 0.995116
A211: Run 4 function ACO 4start8 | B211: 113.275 | C211: 106.415 | D211: 3.13448 | E211: 6.25871 | F211: 86.4393 | G211: 6.85965 | H211: 100 | I211: 100 | J211: 0.748513 | K211: 0.0012301 | L211: 0.995116
A212: Run 4 function ACO 4start9 | B212: 112.614 | C212: 105.841 | D212: 3.06792 | E212: 6.16654 | F212: 86.2363 | G212: 6.77395 | H212: 100 | I212: 100 | J212: 0.752901 | K212: 0.00123012 | L212: 0.995116
A213: Run 4 function ACO 4start10 | B213: 112.027 | C213: 105.426 | D213: 3.01774 | E213: 6.14504 | F213: 86.1052 | G213: 6.60099 | H213: 100 | I213: 100 | J213: 0.75685 | K213: 0.00123122 | L213: 0.995116
A214: Run 4 function ACO 4start11 | B214: 111.425 | C214: 104.959 | D214: 2.92046 | E214: 6.07336 | F214: 85.9701 | G214: 6.46629 | H214: 100 | I214: 100 | J214: 0.760937 | K214: 0.00123149 | L214: 0.995116
... A402: Run 4 function ACO 4start transposed49 | B402: 209.134 | C402: 202.596 | D402: 2.98395 | E402: 22.1419 | F402: 167.196 | G402: 6.53775 | H402: 100 | I402: 100 | J402: 0.405423 | K402: 0.0108569 | L402: 0.995113
A403: Device 0: Tesla V100-SXM2-16GB | B403: Max thread in blocks: 1024 Total Global Memory: 16151,1 MB GPU Global Memory Usage: 0,990772 MB GPU Global Memory Hash Table: 1024 MB Max PARAMETR_SIZE in GPU Global Memory: 7482045 Shared memory per block: 49152 bytes (48 KB) Shared memory per multiprocessor: 98304 bytes (96 KB) Data size in Shared memory per block: 1344 bytes (1,3125 KB) Constant Memory: 65536 bytes Parameter data size (in Constant Memory): 6720 bytes (6,5625 KB) Registers per Block: 65536 Warp Size: 32 Compute Capability: 7,0 Can Map Host Memory: Yes Clock Rate: 1530 MHz L2 Cache Size: 6291456 bytes Multiprocessor Count: 80 | C403: Max thread in blocks by axis: (1024, 1024, 64) | D403: Max blocks by axis: (2147483647, 65535, 65535) | E403: PARAMETR_SIZE: 168 | F403: MAX_VALUE_SIZE: 5 | G403: SET_PARAMETR_SIZE_ONE_X: 21 | H403: ANT_SIZE: 500 | I403: MAX_THREAD_CUDA: 512 | J403: NAME_FILE_GRAPH: Parametr_Graph/test168,txt | K403: KOL_ITERATION: 500 | L403: KOL_PROGREV: 5 | M403: KOL_PROGON_STATISTICS: 50 | N403: PARAMETR_RO: 0,999 | O403: PARAMETR_Q: 1 | P403: PRINT_INFORMATION: 0 | Q403: MAX_PARAMETR_VALUE_TO_MIN_OPT: 1 | R403: OPTIMIZE: OPTIMIZE_MIN_1 | S403: FUNCTION: SHAFFERA GO_HASH: 0 | T403: HASH_TABLE_SIZE: 67108864 | U403: ZERO_HASH_RESULT: -1 | V403: ZERO_HASH: 18446744073709551615 | W403: MAX_PROBES: 10000 | X403: MAX_CONST: 8192 | Y403: MAX_SHARED: 6144 | Z403: BLOCK_SIZE: 64 | AA403: BIN_SEARCH: 0 | AB403: NON_WHILE_ANT: 1
A404: Run 4 function ACO 4start0 | B404: 114.98 | C404: 108.457 | D404: 2.99829 | E404: 8.17562 | F404: 87.0155 | G404: 6.52263 | H404: 100 | I404: 100 | J404: 1.45863 | K404: 0.011379 | L404: 0.980969
A405: Run 4 function ACO 4start1 | B405: 115.049 | C405: 108.487 | D405: 2.98907 | E405: 8.23501 | F405: 86.9858 | G405: 6.56214 | H405: 100 | I405: 100 | J405: 1.45775 | K405: 0.0111864 | L405: 0.991873
A406: Run 4 function ACO 4start2 | B406: 115.988 | C406: 109.236 | D406: 3.09352 | E406: 8.28826 | F406: 87.0318 | G406: 6.75227 | H406: 100 | I406: 100 | J406: 1.44594 | K406: 0.0108569 | L406: 0.981014
A407: Run 4 function ACO 4start3 | B407: 115.138 | C407: 108.457 | D407: 2.99829 | E407: 8.2176 | F407: 86.9407 | G407: 6.68084 | H407: 100 | I407: 100 | J407: 1.45663 | K407: 0.0115929 | L407: 0.981019
A408: Run 4 function ACO 4start4 | B408: 114.805 | C408: 108.294 | D408: 2.94504 | E408: 8.18689 | F408: 86.9008 | G408: 6.51131 | H408: 100 | I408: 100 | J408: 1.46084 | K408: 0.010878 | L408: 0.994867
A409: Run 4 function ACO 4start5 | B409: 114.718 | C409: 108.229 | D409: 2.92763 | E409: 8.19303 | F409: 86.9091 | G409: 6.48949 | H409: 100 | I409: 100 | J409: 1.46195 | K409: 0.0113744 | L409: 0.991578
A410: Run 4 function ACO 4start6 | B410: 115.087 | C410: 108.5 | D410: 2.98395 | E410: 8.2473 | F410: 86.9746 | G410: 6.587 | H410: 100 | I410: 100 | J410: 1.45727 | K410: 0.0108682 | L410: 0.981018
A411: Run 4 function ACO 4start7 | B411: 115.012 | C411: 108.433 | D411: 2.96859 | E411: 8.24321 | F411: 86.95 | G411: 6.57822 | H411: 100 | I411: 100 | J411: 1.45822 | K411: 0.0108597 | L411: 0.991912
A412: Run 4 function ACO 4start8 | B412: 114.998 | C412: 108.436 | D412: 2.99317 | E412: 8.23399 | F412: 86.9345 | G412: 6.56183 | H412: 100 | I412: 100 | J412: 1.45839 | K412: 0.0108571 | L412: 0.994998
A413: Run 4 function ACO 4start9 | B413: 115.078 | C413: 108.475 | D413: 2.98088 | E413: 8.26368 | F413: 86.956 | G413: 6.60279 | H413: 100 | I413: 100 | J413: 1.45738 | K413: 0.010997 | L413: 0.995031
A414: Run 4 function ACO 4start10 | B414: 114.971 | C414: 108.39 | D414: 2.9563 | E414: 8.21351 | F414: 86.9397 | G414: 6.58106 | H414: 100 | I414: 100 | J414: 1.45873 | K414: 0.0111615 | L414: 0.981019
...

Sheet Лист2_1
A1: Device 0: Tesla V100-SXM2-16GB | B1: Max thread in blocks: 1024 Total Global Memory: 16151,1 MB GPU Global Memory Usage: 0,250568 MB GPU Global Memory Hash Table: 1024 MB Max PARAMETR_SIZE in GPU Global Memory: 7482045 Shared memory per block: 49152 bytes (48 KB) Shared memory per multiprocessor: 98304 bytes (96 KB) Data size in Shared memory per block: 336 bytes (0,328125 KB) Constant Memory: 65536 bytes Parameter data size (in Constant Memory): 1680 bytes (1,64062 KB) Registers per Block: 65536 Warp Size: 32 Compute Capability: 7,0 Can Map Host Memory: Yes Clock Rate: 1530 MHz L2 Cache Size: 6291456 bytes Multiprocessor Count: 80 | C1: Max thread in blocks by axis: (1024, 1024, 64) | D1: Max blocks by axis: (2147483647, 65535, 65535) | E1: PARAMETR_SIZE: 42 | F1: MAX_VALUE_SIZE: 5 | G1: SET_PARAMETR_SIZE_ONE_X: 21 | H1: ANT_SIZE: 500 | I1: MAX_THREAD_CUDA: 512 | J1: NAME_FILE_GRAPH: Parametr_Graph/test42,txt | K1: KOL_ITERATION: 500 | L1: KOL_PROGREV: 5 | M1: KOL_PROGON_STATISTICS: 50 | N1: PARAMETR_RO: 0,999 | O1: PARAMETR_Q: 1 | P1: PRINT_INFORMATION: 0 | Q1: MAX_PARAMETR_VALUE_TO_MIN_OPT: 1 | R1: OPTIMIZE: OPTIMIZE_MIN_1 | S1: FUNCTION: SHAFFERA GO_HASH: 1 | T1: HASH_TABLE_SIZE: 67108864 | U1: ZERO_HASH_RESULT: -1 | V1: ZERO_HASH: 18446744073709551615 | W1: MAX_PROBES: 10000 | X1: MAX_CONST: 8192 | Y1: MAX_SHARED: 6144 | Z1: BLOCK_SIZE: 64 | AA1: BIN_SEARCH: 0 | AB1: NON_WHILE_ANT: 1
A2: Run 4 function ACO 4start0 | B2: 41.3497 | C2: 23.5489 | D2: 2.92456 | E2: 5.14869 | F2: 6.14914 | G2: 17.8008 | H2: 81.8356 | I2: 100 | J2: 1.04777 | K2: 0.00123006 | L2: 0.995116
A3: Run 4 function ACO 4start1 | B3: 29.2548 | C3: 23.4055 | D3: 2.92456 | E3: 5.14664 | F3: 6.09077 | G3: 5.84927 | H3: 79.664 | I3: 100 | J3: 1.48096 | K3: 0.00123009 | L3: 0.995116
A4: Run 4 function ACO 4start2 | B4: 29.5232 | C4: 23.4413 | D4: 2.94504 | E4: 5.15483 | F4: 6.09384 | G4: 6.08191 | H4: 77.618 | I4: 100 | J4: 1.46749 | K4: 0.00123007 | L4: 0.995116
A5: Run 4 function ACO 4start3 | B5: 35.5826 | C5: 23.5253 | D5: 2.97678 | E5: 5.15585 | F5: 6.0621 | G5: 12.0573 | H5: 75.7016 | I5: 100 | J5: 1.21759 | K5: 0.00123007 | L5: 0.995116
A6: Run 4 function ACO 4start4 | B6: 516.201 | C6: 22.276 | D6: 2.76584 | E6: 4.80666 | F6: 5.63405 | G6: 493.925 | H6: 74.0636 | I6: 100 | J6: 0.0839308 | K6: 0.00123011 | L6: 0.995116
A7: Run 4 function ACO 4start5 | B7: 28.5012 | C7: 22.6221 | D7: 2.79041 | E7: 4.83533 | F7: 5.68013 | G7: 5.87904 | H7: 72.0492 | I7: 100 | J7: 1.52012 | K7: 0.00123007 | L7: 0.995116
A8: Run 4 function ACO 4start6 | B8: 28.1784 | C8: 22.4624 | D8: 2.79553 | E8: 4.80359 | F8: 5.65965 | G8: 5.71601 | H8: 70.528 | I8: 100 | J8: 1.53753 | K8: 0.00123011 | L8: 0.995116
A9: Run 4 function ACO 4start7 | B9: 28.1392 | C9: 22.4204 | D9: 2.7515 | E9: 4.8169 | F9: 5.63814 | G9: 5.71876 | H9: 69.266 | I9: 100 | J9: 1.53967 | K9: 0.00123011 | L9: 0.995116
A10: Run 4 function ACO 4start8 | B10: 28.243 | C10: 22.5054 | D10: 2.7812 | E10: 4.81792 | F10: 5.67603 | G10: 5.73758 | H10: 67.7712 | I10: 100 | J10: 1.53401 | K10: 0.00123005 | L10: 0.995116
A11: Run 4 function ACO 4start9 | B11: 28.6083 | C11: 22.3999 | D11: 2.79246 | E11: 4.8169 | F11: 5.63917 | G11: 6.20838 | H11: 66.2408 | I11: 100 | J11: 1.51442 | K11: 0.00123011 | L11: 0.995116
A12: Run 4 function ACO 4start10 | B12: 27.9624 | C12: 22.276 | D12: 2.77505 | E12: 4.81792 | F12: 5.61152 | G12: 5.68641 | H12: 65.186 | I12: 100 | J12: 1.5494 | K12: 0.0012301 | L12: 0.995116
A13: Run 4 function ACO 4start11 | B13: 27.9921 | C13: 22.318 | D13: 2.74433 | E13: 4.84148 | F13: 5.64019 | G13: 5.67409 | H13: 64.3424 | I13: 100 | J13: 1.54776 | K13: 0.00123011 | L13: 0.995116
... A201: Run 4 function ACO 4start transposed49 | B201: 85.9668 | C201: 80.3613 | D201: 2.83035 | E201: 12.6168 | F201: 55.9163 | G201: 5.60547 | H201: 51.3932 | I201: 100 | J201: 0.503975 | K201: 0.00123006 | L201: 0.995677
A202: Device 0: Tesla V100-SXM2-16GB | B202: Max thread in blocks: 1024 Total Global Memory: 16151,1 MB GPU Global Memory Usage: 0,497303 MB GPU Global Memory Hash Table: 1024 MB Max PARAMETR_SIZE in GPU Global Memory: 7482045 Shared memory per block: 49152 bytes (48 KB) Shared memory per multiprocessor: 98304 bytes (96 KB) Data size in Shared memory per block: 672 bytes (0,65625 KB) Constant Memory: 65536 bytes Parameter data size (in Constant Memory): 3360 bytes (3,28125 KB) Registers per Block: 65536 Warp Size: 32 Compute Capability: 7,0 Can Map Host Memory: Yes Clock Rate: 1530 MHz L2 Cache Size: 6291456 bytes Multiprocessor Count: 80 | C202: Max thread in blocks by axis: (1024, 1024, 64) | D202: Max blocks by axis: (2147483647, 65535, 65535) | E202: PARAMETR_SIZE: 84 | F202: MAX_VALUE_SIZE: 5 | G202: SET_PARAMETR_SIZE_ONE_X: 21 | H202: ANT_SIZE: 500 | I202: MAX_THREAD_CUDA: 512 | J202: NAME_FILE_GRAPH: Parametr_Graph/test84,txt | K202: KOL_ITERATION: 500 | L202: KOL_PROGREV: 5 | M202: KOL_PROGON_STATISTICS: 50 | N202: PARAMETR_RO: 0,999 | O202: PARAMETR_Q: 1 | P202: PRINT_INFORMATION: 0 | Q202: MAX_PARAMETR_VALUE_TO_MIN_OPT: 1 | R202: OPTIMIZE: OPTIMIZE_MIN_1 | S202: FUNCTION: SHAFFERA GO_HASH: 1 | T202: HASH_TABLE_SIZE: 67108864 | U202: ZERO_HASH_RESULT: -1 | V202: ZERO_HASH: 18446744073709551615 | W202: MAX_PROBES: 10000 | X202: MAX_CONST: 8192 | Y202: MAX_SHARED: 6144 | Z202: BLOCK_SIZE: 64 | AA202: BIN_SEARCH: 0 | AB202: NON_WHILE_ANT: 1
A203: Run 4 function ACO 4start0 | B203: 30.4163 | C203: 24.8823 | D203: 2.89998 | E203: 6.20137 | F203: 6.7502 | G203: 5.53399 | H203: 98.9064 | I203: 100 | J203: 2.78758 | K203: 0.00142329 | L203: 0.995116
A204: Run 4 function ACO 4start1 | B204: 30.4755 | C204: 24.8505 | D204: 2.89896 | E204: 6.20342 | F204: 6.69286 | G204: 5.62497 | H204: 98.7632 | I204: 100 | J204: 2.78216 | K204: 0.00123007 | L204: 0.995116
A205: Run 4 function ACO 4start2 | B205: 30.3305 | C205: 24.7635 | D205: 2.90305 | E205: 6.20853 | F205: 6.699 | G205: 5.567 | H205: 98.5668 | I205: 100 | J205: 2.79546 | K205: 0.00123384 | L205: 0.995116
A206: Run 4 function ACO 4start3 | B206: 30.3832 | C206: 24.7962 | D206: 2.89179 | E206: 6.21673 | F206: 6.6519 | G206: 5.58698 | H206: 98.412 | I206: 100 | J206: 2.79061 | K206: 0.00123295 | L206: 0.995115
A207: Run 4 function ACO 4start4 | B207: 30.3772 | C207: 24.8126 | D207: 2.91329 | E207: 6.22184 | F207: 6.66624 | G207: 5.56455 | H207: 98.1612 | I207: 100 | J207: 2.79116 | K207: 0.00124204 | L207: 0.995116
A208: Run 4 function ACO 4start5 | B208: 29.5832 | C208: 24.0456 | D208: 2.79451 | E208: 5.95867 | F208: 6.33858 | G208: 5.53757 | H208: 98.0612 | I208: 100 | J208: 2.86608 | K208: 0.00123114 | L208: 0.995115
A209: Run 4 function ACO 4start6 | B209: 29.49 | C209: 23.9637 | D209: 2.77096 | E209: 5.96481 | F209: 6.3355 | G209: 5.52634 | H209: 97.8924 | I209: 100 | J209: 2.87513 | K209: 0.00123055 | L209: 0.995116
A210: Run 4 function ACO 4start7 | B210: 29.5694 | C210: 24.0231 | D210: 2.78017 | E210: 5.96379 | F210: 6.34062 | G210: 5.54636 | H210: 97.6628 | I210: 100 | J210: 2.86741 | K210: 0.00123117 | L210: 0.995115
A211: Run 4 function ACO 4start8 | B211: 29.5228 | C211: 24.0241 | D211: 2.79451 | E211: 5.98529 | F211: 6.3396 | G211: 5.4987 | H211: 97.5064 | I211: 100 | J211: 2.87194 | K211: 0.00123117 | L211: 0.995116
A212: Run 4 function ACO 4start9 | B212: 29.5274 | C212: 23.9718 | D212: 2.78017 | E212: 5.96891 | F212: 6.30888 | G212: 5.55553 | H212: 97.3436 | I212: 100 | J212: 2.87149 | K212: 0.00124204 | L212: 0.995116
A213: Run 4 function ACO 4start10 | B213: 29.4651 | C213: 23.9544 | D213: 2.78632 | E213: 5.96379 | F213: 6.29557 | G213: 5.51067 | H213: 97.2508 | I213: 100 | J213: 2.87756 | K213: 0.00123008 | L213: 0.995116
A214: Run 4 function ACO 4start11 | B214: 29.5451 | C214: 23.9841 | D214: 2.77812 | E214: 5.97608 | F214: 6.30069 | G214: 5.56091 | H214: 97.0764 | I214: 100 | J214: 2.86977 | K214: 0.00123528 | L214: 0.995116
... A402: Run 4 function ACO 4start transposed49 | B402: 97.3928 | C402: 91.4364 | D402: 2.86312 | E402: 22.02 | F402: 56.9619 | G402: 5.95646 | H402: 50.6996 | I402: 100 | J402: 0.870573 | K402: 0.00125346 | L402: 0.995116
A403: Device 0: Tesla V100-SXM2-16GB | B403: Max thread in blocks: 1024 Total Global Memory: 16151,1 MB GPU Global Memory Usage: 0,990772 MB GPU Global Memory Hash Table: 1024 MB Max PARAMETR_SIZE in GPU Global Memory: 7482045 Shared memory per block: 49152 bytes (48 KB) Shared memory per multiprocessor: 98304 bytes (96 KB) Data size in Shared memory per block: 1344 bytes (1,3125 KB) Constant Memory: 65536 bytes Parameter data size (in Constant Memory): 6720 bytes (6,5625 KB) Registers per Block: 65536 Warp Size: 32 Compute Capability: 7,0 Can Map Host Memory: Yes Clock Rate: 1530 MHz L2 Cache Size: 6291456 bytes Multiprocessor Count: 80 | C403: Max thread in blocks by axis: (1024, 1024, 64) | D403: Max blocks by axis: (2147483647, 65535, 65535) | E403: PARAMETR_SIZE: 168 | F403: MAX_VALUE_SIZE: 5 | G403: SET_PARAMETR_SIZE_ONE_X: 21 | H403: ANT_SIZE: 500 | I403: MAX_THREAD_CUDA: 512 | J403: NAME_FILE_GRAPH: Parametr_Graph/test168,txt | K403: KOL_ITERATION: 500 | L403: KOL_PROGREV: 5 | M403: KOL_PROGON_STATISTICS: 50 | N403: PARAMETR_RO: 0,999 | O403: PARAMETR_Q: 1 | P403: PRINT_INFORMATION: 0 | Q403: MAX_PARAMETR_VALUE_TO_MIN_OPT: 1 | R403: OPTIMIZE: OPTIMIZE_MIN_1 | S403: FUNCTION: SHAFFERA GO_HASH: 1 | T403: HASH_TABLE_SIZE: 67108864 | U403: ZERO_HASH_RESULT: -1 | V403: ZERO_HASH: 18446744073709551615 | W403: MAX_PROBES: 10000 | X403: MAX_CONST: 8192 | Y403: MAX_SHARED: 6144 | Z403: BLOCK_SIZE: 64 | AA403: BIN_SEARCH: 0 | AB403: NON_WHILE_ANT: 1
A404: Run 4 function ACO 4start0 | B404: 34.0077 | C404: 28.2572 | D404: 2.9532 | E404: 8.66611 | F404: 7.3288 | G404: 5.75051 | H404: 99.9592 | I404: 100 | J404: 4.9316 | K404: 0.0112518 | L404: 0.981002
A405: Run 4 function ACO 4start1 | B405: 33.3917 | C405: 27.6254 | D405: 2.91636 | E405: 8.51046 | F405: 7.12809 | G405: 5.76627 | H405: 99.9144 | I405: 100 | J405: 5.02258 | K405: 0.0113369 | L405: 0.981015
A406: Run 4 function ACO 4start2 | B406: 33.3649 | C406: 27.5548 | D406: 2.88155 | E406: 8.49305 | F406: 7.10659 | G406: 5.81015 | H406: 99.9236 | I406: 100 | J406: 5.02661 | K406: 0.0110202 | L406: 0.981019
A407: Run 4 function ACO 4start3 | B407: 33.2413 | C407: 27.5558 | D407: 2.89691 | E407: 8.50226 | F407: 7.09737 | G407: 5.68549 | H407: 99.9312 | I407: 100 | J407: 5.04531 | K407: 0.0111812 | L407: 0.991982
A408: Run 4 function ACO 4start4 | B408: 33.0751 | C408: 27.4319 | D408: 2.89588 | E408: 8.46643 | F408: 7.09532 | G408: 5.64323 | H408: 99.934 | I408: 100 | J408: 5.07066 | K408: 0.0122221 | L408: 0.988727
A409: Run 4 function ACO 4start5 | B409: 33.0488 | C409: 27.3387 | D409: 2.88155 | E409: 8.28314 | F409: 6.90892 | G409: 5.7101 | H409: 99.9172 | I409: 100 | J409: 5.0747 | K409: 0.017729 | L409: 0.981017
A410: Run 4 function ACO 4start6 | B410: 32.3267 | C410: 26.7233 | D410: 2.80884 | E410: 8.11419 | F410: 6.80141 | G410: 5.60343 | H410: 99.9108 | I410: 100 | J410: 5.18805 | K410: 0.0108611 | L410: 0.981007
A411: Run 4 function ACO 4start7 | B411: 32.8681 | C411: 26.8451 | D411: 2.81396 | E411: 8.09985 | F411: 6.80755 | G411: 6.02293 | H411: 99.8992 | I411: 100 | J411: 5.1026 | K411: 0.0114177 | L411: 0.992435
A412: Run 4 function ACO 4start8 | B412: 260.313 | C412: 26.9291 | D412: 2.83035 | E412: 8.08858 | F412: 6.80653 | G412: 233.384 | H412: 99.8876 | I412: 100 | J412: 0.644272 | K412: 0.0109067 | L412: 0.981001
A413: Run 4 function ACO 4start9 | B413: 301.56 | C413: 29.3224 | D413: 3.15086 | E413: 8.47769 | F413: 7.15164 | G413: 272.237 | H413: 99.8732 | I413: 100 | J413: 0.556151 | K413: 0.0108651 | L413: 0.981019
A414: Run 4 function ACO 4start10 | B414: 40.3252 | C414: 32.6604 | D414: 3.74888 | E414: 9.00608 | F414: 8.03839 | G414: 7.66476 | H414: 99.8716 | I414: 100 | J414: 4.159 | K414: 0.0135348 | L414: 0.988225
...

Sheet Лист3
A1: Device 0: Tesla V100-SXM2-16GB | B1: Max thread in blocks: 1024 Total Global Memory: 16151,1 MB GPU Global Memory Usage: 0,250568 MB GPU Global Memory Hash Table: 1024 MB Max PARAMETR_SIZE in GPU Global Memory: 7482045 Shared memory per block: 49152 bytes (48 KB) Shared memory per multiprocessor: 98304 bytes (96 KB) Data size in Shared memory per block: 336 bytes (0,328125 KB) Constant Memory: 65536 bytes Parameter data size (in Constant Memory): 1680 bytes (1,64062 KB) Registers per Block: 65536 Warp Size: 32 Compute Capability: 7,0 Can Map Host Memory: Yes Clock Rate: 1530 MHz L2 Cache Size: 6291456 bytes Multiprocessor Count: 80 | C1: Max thread in blocks by axis: (1024, 1024, 64) | D1: Max blocks by axis: (2147483647, 65535, 65535) | E1: PARAMETR_SIZE: 42 | F1: MAX_VALUE_SIZE: 5 | G1: SET_PARAMETR_SIZE_ONE_X: 21 | H1: ANT_SIZE: 500 | I1: MAX_THREAD_CUDA: 512 | J1: NAME_FILE_GRAPH: Parametr_Graph/test42,txt | K1: KOL_ITERATION: 500 | L1: KOL_PROGREV: 5 | M1: KOL_PROGON_STATISTICS: 50 | N1: PARAMETR_RO: 0,999 | O1: PARAMETR_Q: 1 | P1: PRINT_INFORMATION: 0 | Q1: MAX_PARAMETR_VALUE_TO_MIN_OPT: 1 | R1: OPTIMIZE: OPTIMIZE_MIN_1 | S1: FUNCTION: SHAFFERA GO_HASH: 0 | T1: HASH_TABLE_SIZE: 67108864 | U1: ZERO_HASH_RESULT: -1 | V1: ZERO_HASH: 18446744073709551615 | W1: MAX_PROBES: 10000 | X1: MAX_CONST: 8192 | Y1: MAX_SHARED: 6144 | Z1: BLOCK_SIZE: 64 | AA1: BIN_SEARCH: 0 | AB1: NON_WHILE_ANT: 1
A2: Run 4 function ACO 4start0 | B2: 104.56 | C2: 97.8819 | D2: 3.22254 | E2: 5.18657 | F2: 79.0253 | G2: 6.67862 | H2: 100 | I2: 100 | J2: 0.414355 | K2: 0.00123009 | L2: 0.999998
A3: Run 4 function ACO 4start1 | B3: 105.052 | C3: 98.2587 | D3: 3.25429 | E3: 5.27976 | F3: 79.0703 | G3: 6.79322 | H3: 100 | I3: 100 | J3: 0.412416 | K3: 0.00123005 | L3: 0.999989
A4: Run 4 function ACO 4start2 | B4: 104.92 | C4: 98.1164 | D4: 3.27681 | E4: 5.27975 | F4: 79.015 | G4: 6.80357 | H4: 100 | I4: 100 | J4: 0.412935 | K4: 0.00123005 | L4: 0.999996
A5: Run 4 function ACO 4start3 | B5: 104.889 | C5: 98.1133 | D5: 3.24405 | E5: 5.25415 | F5: 79.0549 | G5: 6.77603 | H5: 100 | I5: 100 | J5: 0.413056 | K5: 0.00123006 | L5: 0.999996
A6: Run 4 function ACO 4start4 | B6: 104.603 | C6: 97.9034 | D6: 3.22459 | E6: 5.22139 | F6: 78.9699 | G6: 6.7 | H6: 100 | I6: 100 | J6: 0.414185 | K6: 0.00123006 | L6: 0.999996
A7: Run 4 function ACO 4start5 | B7: 104.751 | C7: 97.9812 | D7: 3.25531 | E7: 5.23265 | F7: 78.9606 | G7: 6.77027 | H7: 100 | I7: 100 | J7: 0.413599 | K7: 0.00123006 | L7: 0.999983
A8: Run 4 function ACO 4start6 | B8: 103.614 | C8: 96.9277 | D8: 3.08225 | E8: 5.08827 | F8: 78.421 | G8: 6.68615 | H8: 100 | I8: 100 | J8: 0.41814 | K8: 0.00123006 | L8: 0.999999
A9: Run 4 function ACO 4start7 | B9: 104.751 | C9: 97.9465 | D9: 3.25122 | E9: 5.27669 | F9: 78.7927 | G9: 6.80412 | H9: 100 | I9: 100 | J9: 0.413603 | K9: 0.00123006 | L9: 0.999999
A10: Run 4 function ACO 4start8 | B10: 104.824 | C10: 98.0478 | D10: 3.30754 | E10: 5.29512 | F10: 78.8459 | G10: 6.77657 | H10: 100 | I10: 100 | J10: 0.413311 | K10: 0.00123006 | L10: 1
A11: Run 4 function ACO 4start9 | B11: 104.793 | C11: 97.9842 | D11: 3.25224 | E11: 5.30023 | F11: 78.8132 | G11: 6.80831 | H11: 100 | I11: 100 | J11: 0.413437 | K11: 0.00123006 | L11: 0.999981
A12: Run 4 function ACO 4start10 | B12: 103.4 | C12: 96.8314 | D12: 3.09249 | E12: 5.10875 | F12: 78.3698 | G12: 6.56848 | H12: 100 | I12: 100 | J12: 0.419006 | K12: 0.00123005 | L12: 0.999994
A13: Run 4 function ACO 4start11 | B13: 104.779 | C13: 98.0222 | D13: 3.25531 | E13: 5.34632 | F13: 78.802 | G13: 6.75699 | H13: 100 | I13: 100 | J13: 0.41349 | K13: 0.00123006 | L13: 1
... A201: Run 4 function ACO 4start transposed49 | B201: 105.391 | C201: 98.7652 | D201: 3.22152 | E201: 12.9444 | F201: 72.1714 | G201: 6.62604 | H201: 100 | I201: 100 | J201: 0.411089 | K201: 0.00123006 | L201: 0.998549
A202: Device 0: Tesla V100-SXM2-16GB | B202: Max thread in blocks: 1024 Total Global Memory: 16151,1 MB GPU Global Memory Usage: 0,497303 MB GPU Global Memory Hash Table: 1024 MB Max PARAMETR_SIZE in GPU Global Memory: 7482045 Shared memory per block: 49152 bytes (48 KB) Shared memory per multiprocessor: 98304 bytes (96 KB) Data size in Shared memory per block: 672 bytes (0,65625 KB) Constant Memory: 65536 bytes Parameter data size (in Constant Memory): 3360 bytes (3,28125 KB) Registers per Block: 65536 Warp Size: 32 Compute Capability: 7,0 Can Map Host Memory: Yes Clock Rate: 1530 MHz L2 Cache Size: 6291456 bytes Multiprocessor Count: 80 | C202: Max thread in blocks by axis: (1024, 1024, 64) | D202: Max blocks by axis: (2147483647, 65535, 65535) | E202: PARAMETR_SIZE: 84 | F202: MAX_VALUE_SIZE: 5 | G202: SET_PARAMETR_SIZE_ONE_X: 21 | H202: ANT_SIZE: 500 | I202: MAX_THREAD_CUDA: 512 | J202: NAME_FILE_GRAPH: Parametr_Graph/test84,txt | K202: KOL_ITERATION: 500 | L202: KOL_PROGREV: 5 | M202: KOL_PROGON_STATISTICS: 50 | N202: PARAMETR_RO: 0,999 | O202: PARAMETR_Q: 1 | P202: PRINT_INFORMATION: 0 | Q202: MAX_PARAMETR_VALUE_TO_MIN_OPT: 1 | R202: OPTIMIZE: OPTIMIZE_MIN_1 | S202: FUNCTION: SHAFFERA GO_HASH: 0 | T202: HASH_TABLE_SIZE: 67108864 | U202: ZERO_HASH_RESULT: -1 | V202: ZERO_HASH: 18446744073709551615 | W202: MAX_PROBES: 10000 | X202: MAX_CONST: 8192 | Y202: MAX_SHARED: 6144 | Z202: BLOCK_SIZE: 64 | AA202: BIN_SEARCH: 0 | AB202: NON_WHILE_ANT: 1
A203: Run 4 function ACO 4start0 | B203: 112.77 | C203: 106.112 | D203: 2.99726 | E203: 6.08258 | F203: 86.4966 | G203: 6.65776 | H203: 100 | I203: 100 | J203: 0.751864 | K203: 0.00123085 | L203: 0.995116
A204: Run 4 function ACO 4start1 | B204: 112.677 | C204: 106.03 | D204: 3.00648 | E204: 6.08463 | F204: 86.4025 | G204: 6.64655 | H204: 100 | I204: 100 | J204: 0.752485 | K204: 0.00123009 | L204: 0.995116
A205: Run 4 function ACO 4start2 | B205: 113.272 | C205: 106.108 | D205: 3.06177 | E205: 6.10613 | F205: 86.4178 | G205: 7.16456 | H205: 100 | I205: 100 | J205: 0.748528 | K205: 0.00123019 | L205: 0.995116
A206: Run 4 function ACO 4start3 | B206: 113.993 | C206: 106.915 | D206: 3.22971 | E206: 6.25357 | F206: 86.6336 | G206: 7.07848 | H206: 100 | I206: 100 | J206: 0.743794 | K206: 0.00123005 | L206: 0.995116
A207: Run 4 function ACO 4start4 | B207: 115.767 | C207: 108.232 | D207: 3.4171 | E207: 6.45531 | F207: 87.0789 | G207: 7.53529 | H207: 100 | I207: 100 | J207: 0.732399 | K207: 0.00123078 | L207: 0.995116
A208: Run 4 function ACO 4start5 | B208: 115.538 | C208: 107.526 | D208: 3.25224 | E208: 6.3437 | F208: 86.8693 | G208: 8.01195 | H208: 100 | I208: 100 | J208: 0.733851 | K208: 0.00123005 | L208: 0.995116
A209: Run 4 function ACO 4start6 | B209: 113.045 | C209: 106.319 | D209: 3.08225 | E209: 6.23003 | F209: 86.5756 | G209: 6.72568 | H209: 100 | I209: 100 | J209: 0.750035 | K209: 0.00123103 | L209: 0.995116
A210: Run 4 function ACO 4start7 | B210: 113.226 | C210: 106.434 | D210: 3.13653 | E210: 6.20034 | F210: 86.6122 | G210: 6.79253 | H210: 100 | I210: 100 | J210: 0.748835 | K210: 0.0012312 | L210: 0.995116
A211: Run 4 function ACO 4start8 | B211: 113.275 | C211: 106.415 | D211: 3.13448 | E211: 6.25871 | F211: 86.4393 | G211: 6.85965 | H211: 100 | I211: 100 | J211: 0.748513 | K211: 0.0012301 | L211: 0.995116
A212: Run 4 function ACO 4start9 | B212: 112.614 | C212: 105.841 | D212: 3.06792 | E212: 6.16654 | F212: 86.2363 | G212: 6.77395 | H212: 100 | I212: 100 | J212: 0.752901 | K212: 0.00123012 | L212: 0.995116
A213: Run 4 function ACO 4start10 | B213: 112.027 | C213: 105.426 | D213: 3.01774 | E213: 6.14504 | F213: 86.1052 | G213: 6.60099 | H213: 100 | I213: 100 | J213: 0.75685 | K213: 0.00123122 | L213: 0.995116
A214: Run 4 function ACO 4start11 | B214: 111.425 | C214: 104.959 | D214: 2.92046 | E214: 6.07336 | F214: 85.9701 | G214: 6.46629 | H214: 100 | I214: 100 | J214: 0.760937 | K214: 0.00123149 | L214: 0.995116
... A402: Run 4 function ACO 4start transposed49 | B402: 209.134 | C402: 202.596 | D402: 2.98395 | E402: 22.1419 | F402: 167.196 | G402: 6.53775 | H402: 100 | I402: 100 | J402: 0.405423 | K402: 0.0108569 | L402: 0.995113
A403: Device 0: Tesla V100-SXM2-16GB | B403: Max thread in blocks: 1024 Total Global Memory: 16151,1 MB GPU Global Memory Usage: 0,990772 MB GPU Global Memory Hash Table: 1024 MB Max PARAMETR_SIZE in GPU Global Memory: 7482045 Shared memory per block: 49152 bytes (48 KB) Shared memory per multiprocessor: 98304 bytes (96 KB) Data size in Shared memory per block: 1344 bytes (1,3125 KB) Constant Memory: 65536 bytes Parameter data size (in Constant Memory): 6720 bytes (6,5625 KB) Registers per Block: 65536 Warp Size: 32 Compute Capability: 7,0 Can Map Host Memory: Yes Clock Rate: 1530 MHz L2 Cache Size: 6291456 bytes Multiprocessor Count: 80 | C403: Max thread in blocks by axis: (1024, 1024, 64) | D403: Max blocks by axis: (2147483647, 65535, 65535) | E403: PARAMETR_SIZE: 168 | F403: MAX_VALUE_SIZE: 5 | G403: SET_PARAMETR_SIZE_ONE_X: 21 | H403: ANT_SIZE: 500 | I403: MAX_THREAD_CUDA: 512 | J403: NAME_FILE_GRAPH: Parametr_Graph/test168,txt | K403: KOL_ITERATION: 500 | L403: KOL_PROGREV: 5 | M403: KOL_PROGON_STATISTICS: 50 | N403: PARAMETR_RO: 0,999 | O403: PARAMETR_Q: 1 | P403: PRINT_INFORMATION: 0 | Q403: MAX_PARAMETR_VALUE_TO_MIN_OPT: 1 | R403: OPTIMIZE: OPTIMIZE_MIN_1 | S403: FUNCTION: SHAFFERA GO_HASH: 0 | T403: HASH_TABLE_SIZE: 67108864 | U403: ZERO_HASH_RESULT: -1 | V403: ZERO_HASH: 18446744073709551615 | W403: MAX_PROBES: 10000 | X403: MAX_CONST: 8192 | Y403: MAX_SHARED: 6144 | Z403: BLOCK_SIZE: 64 | AA403: BIN_SEARCH: 0 | AB403: NON_WHILE_ANT: 1
A404: Run 4 function ACO 4start0 | B404: 114.98 | C404: 108.457 | D404: 2.99829 | E404: 8.17562 | F404: 87.0155 | G404: 6.52263 | H404: 100 | I404: 100 | J404: 1.45863 | K404: 0.011379 | L404: 0.980969
A405: Run 4 function ACO 4start1 | B405: 115.049 | C405: 108.487 | D405: 2.98907 | E405: 8.23501 | F405: 86.9858 | G405: 6.56214 | H405: 100 | I405: 100 | J405: 1.45775 | K405: 0.0111864 | L405: 0.991873
A406: Run 4 function ACO 4start2 | B406: 115.988 | C406: 109.236 | D406: 3.09352 | E406: 8.28826 | F406: 87.0318 | G406: 6.75227 | H406: 100 | I406: 100 | J406: 1.44594 | K406: 0.0108569 | L406: 0.981014
A407: Run 4 function ACO 4start3 | B407: 115.138 | C407: 108.457 | D407: 2.99829 | E407: 8.2176 | F407: 86.9407 | G407: 6.68084 | H407: 100 | I407: 100 | J407: 1.45663 | K407: 0.0115929 | L407: 0.981019
A408: Run 4 function ACO 4start4 | B408: 114.805 | C408: 108.294 | D408: 2.94504 | E408: 8.18689 | F408: 86.9008 | G408: 6.51131 | H408: 100 | I408: 100 | J408: 1.46084 | K408: 0.010878 | L408: 0.994867
A409: Run 4 function ACO 4start5 | B409: 114.718 | C409: 108.229 | D409: 2.92763 | E409: 8.19303 | F409: 86.9091 | G409: 6.48949 | H409: 100 | I409: 100 | J409: 1.46195 | K409: 0.0113744 | L409: 0.991578
A410: Run 4 function ACO 4start6 | B410: 115.087 | C410: 108.5 | D410: 2.98395 | E410: 8.2473 | F410: 86.9746 | G410: 6.587 | H410: 100 | I410: 100 | J410: 1.45727 | K410: 0.0108682 | L410: 0.981018
A411: Run 4 function ACO 4start7 | B411: 115.012 | C411: 108.433 | D411: 2.96859 | E411: 8.24321 | F411: 86.95 | G411: 6.57822 | H411: 100 | I411: 100 | J411: 1.45822 | K411: 0.0108597 | L411: 0.991912
A412: Run 4 function ACO 4start8 | B412: 114.998 | C412: 108.436 | D412: 2.99317 | E412: 8.23399 | F412: 86.9345 | G412: 6.56183 | H412: 100 | I412: 100 | J412: 1.45839 | K412: 0.0108571 | L412: 0.994998
A413: Run 4 function ACO 4start9 | B413: 115.078 | C413: 108.475 | D413: 2.98088 | E413: 8.26368 | F413: 86.956 | G413: 6.60279 | H413: 100 | I413: 100 | J413: 1.45738 | K413: 0.010997 | L413: 0.995031
A414: Run 4 function ACO 4start10 | B414: 114.971 | C414: 108.39 | D414: 2.9563 | E414: 8.21351 | F414: 86.9397 | G414: 6.58106 | H414: 100 | I414: 100 | J414: 1.45873 | K414: 0.0111615 | L414: 0.981019
...

Sheet Лист4
