Workbook

Sheet Лист1
A1: Device 0: Tesla V100-SXM2-16GB | B1: Max thread in blocks: 1024 Total Global Memory: 16151,1 MB GPU Global Memory Usage: 0,250568 MB GPU Global Memory Hash Table: 1024 MB Max PARAMETR_SIZE in GPU Global Memory: 2574989 Shared memory per block: 49152 bytes (48 KB) Shared memory per multiprocessor: 98304 bytes (96 KB) Data size in Shared memory per block: 336 bytes (0,328125 KB) Constant Memory: 65536 bytes Parameter data size (in Constant Memory): 1680 bytes (1,64062 KB) Registers per Block: 65536 Warp Size: 32 Compute Capability: 7,0 Can Map Host Memory: Yes Clock Rate: 1530 MHz L2 Cache Size: 6291456 bytes Multiprocessor Count: 80 | C1: Max thread in blocks by axis: (1024, 1024, 64) | D1: Max blocks by axis: (2147483647, 65535, 65535) | E1: Device 1: Tesla V100-SXM2-16GB | F1: Max thread in blocks: 1024 Total Global Memory: 16151,1 MB GPU Global Memory Usage: 0,250568 MB GPU Global Memory Hash Table: 1024 MB Max PARAMETR_SIZE in GPU Global Memory: 2574989 Shared memory per block: 49152 bytes (48 KB) Shared memory per multiprocessor: 98304 bytes (96 KB) Data size in Shared memory per block: 336 bytes (0,328125 KB) Constant Memory: 65536 bytes Parameter data size (in Constant Memory): 1680 bytes (1,64062 KB) Registers per Block: 65536 Warp Size: 32 Compute Capability: 7,0 Can Map Host Memory: Yes Clock Rate: 1530 MHz L2 Cache Size: 6291456 bytes Multiprocessor Count: 80 | G1: Max thread in blocks by axis: (1024, 1024, 64) | H1: Max blocks by axis: (2147483647, 65535, 65535) | I1: Device 2: Tesla V100-SXM2-16GB | J1: Max thread in blocks: 1024 Total Global Memory: 16151,1 MB GPU Global Memory Usage: 0,250568 MB GPU Global Memory Hash Table: 1024 MB Max PARAMETR_SIZE in GPU Global Memory: 2574989 Shared memory per block: 49152 bytes (48 KB) Shared memory per multiprocessor: 98304 bytes (96 KB) Data size in Shared memory per block: 336 bytes (0,328125 KB) Constant Memory: 65536 bytes Parameter data size (in Constant Memory): 1680 bytes (1,64062 KB) Registers per Block: 65536 Warp Size: 32 Compute Capability: 7,0 Can Map Host Memory: Yes Clock Rate: 1530 MHz L2 Cache Size: 6291456 bytes Multiprocessor Count: 80 | K1: Max thread in blocks by axis: (1024, 1024, 64) | L1: Max blocks by axis: (2147483647, 65535, 65535) | M1: Device 3: Tesla V100-SXM2-16GB | N1: Max thread in blocks: 1024 Total Global Memory: 16151,1 MB GPU Global Memory Usage: 0,250568 MB GPU Global Memory Hash Table: 1024 MB Max PARAMETR_SIZE in GPU Global Memory: 2574989 Shared memory per block: 49152 bytes (48 KB) Shared memory per multiprocessor: 98304 bytes (96 KB) Data size in Shared memory per block: 336 bytes (0,328125 KB) Constant Memory: 65536 bytes Parameter data size (in Constant Memory): 1680 bytes (1,64062 KB) Registers per Block: 65536 Warp Size: 32 Compute Capability: 7,0 Can Map Host Memory: Yes Clock Rate: 1530 MHz L2 Cache Size: 6291456 bytes Multiprocessor Count: 80 | O1: Max thread in blocks by axis: (1024, 1024, 64) | P1: Max blocks by axis: (2147483647, 65535, 65535) | Q1: PARAMETR_SIZE: 42 | R1: MAX_VALUE_SIZE: 5 | S1: SET_PARAMETR_SIZE_ONE_X: 21 | T1: ANT_SIZE: 500 | U1: MAX_THREAD_CUDA: 512 | V1: NAME_FILE_GRAPH: Parametr_Graph/test42,txt | W1: KOL_ITERATION: 500 | X1: KOL_PROGREV: 5 | Y1: KOL_PROGON_STATISTICS: 50 | Z1: PARAMETR_RO: 0,999 | AA1: PARAMETR_Q: 1 | AB1: PRINT_INFORMATION: 0 | AC1: MAX_PARAMETR_VALUE_TO_MIN_OPT: 1 | AD1: OPTIMIZE: OPTIMIZE_MIN_1 | AE1: FUNCTION: SHAFFERA GO_HASH: 1 | AF1: HASH_TABLE_SIZE: 67108864 | AG1: ZERO_HASH_RESULT: -1 | AH1: ZERO_HASH: 18446744073709551615 | AI1: MAX_PROBES: 10000
A2: Run 4 function ACO 4start0 | B2: 87.1499 | C2: 80.2928 | D2: 2.99009 | E2: 4.96027 | F2: 61.7248 | G2: 6.85704 | H2: 85.4896 | I2: 100 | J2: 0.497134 | K2: 0.00123005 | L2: 0.996599
A3: Run 4 function ACO 4start1 | B3: 86.5451 | C3: 79.8074 | D3: 2.84059 | E3: 4.93467 | F3: 61.5066 | G3: 6.73769 | H3: 88.4084 | I3: 100 | J3: 0.500608 | K3: 0.00123005 | L3: 0.996524
A4: Run 4 function ACO 4start2 | B4: 87.0999 | C4: 80.2846 | D4: 3.0075 | E4: 4.98177 | F4: 61.6365 | G4: 6.8153 | H4: 87.4448 | I4: 100 | J4: 0.497419 | K4: 0.00123008 | L4: 0.995117
A5: Run 4 function ACO 4start3 | B5: 87.1133 | C5: 80.2765 | D5: 2.95425 | E5: 5.04833 | F5: 61.6201 | G5: 6.83688 | H5: 87.6588 | I5: 100 | J5: 0.497342 | K5: 0.00123005 | L5: 0.997923
A6: Run 4 function ACO 4start4 | B6: 87.1472 | C6: 80.3503 | D6: 2.97269 | E6: 5.03195 | F6: 61.7124 | G6: 6.79696 | H6: 86.9784 | I6: 100 | J6: 0.497149 | K6: 0.00123008 | L6: 0.997921
A7: Run 4 function ACO 4start5 | B7: 86.5994 | C7: 79.8576 | D7: 2.87745 | E7: 4.96846 | F7: 61.567 | G7: 6.74188 | H7: 86.3516 | I7: 100 | J7: 0.500293 | K7: 0.00123008 | L7: 0.995627
A8: Run 4 function ACO 4start6 | B8: 87.0387 | C8: 80.2753 | D8: 2.96961 | E8: 4.99815 | F8: 61.6376 | G8: 6.76341 | H8: 87.4776 | I8: 100 | J8: 0.497768 | K8: 0.00123005 | L8: 0.997921
A9: Run 4 function ACO 4start7 | B9: 87.0886 | C9: 80.2539 | D9: 2.93275 | E9: 5.08929 | F9: 61.6365 | G9: 6.83479 | H9: 87.07 | I9: 100 | J9: 0.497483 | K9: 0.00123005 | L9: 0.996921
A10: Run 4 function ACO 4start8 | B10: 87.1729 | C10: 80.3646 | D10: 3.01057 | E10: 5.04424 | F10: 61.6828 | G10: 6.80831 | H10: 86.1972 | I10: 100 | J10: 0.497002 | K10: 0.00123005 | L10: 0.995116
A11: Run 4 function ACO 4start9 | B11: 87.1399 | C11: 80.2754 | D11: 2.94401 | E11: 5.0811 | F11: 61.6654 | G11: 6.86449 | H11: 85.3564 | I11: 100 | J11: 0.497191 | K11: 0.00123005 | L11: 0.995116
A12: Run 4 function ACO 4start10 | B12: 86.716 | C12: 79.9631 | D12: 2.91534 | E12: 5.0002 | F12: 61.5834 | G12: 6.75291 | H12: 84.3288 | I12: 100 | J12: 0.499621 | K12: 0.00123005 | L12: 0.995613
A13: Run 4 function ACO 4start11 | B13: 86.9728 | C13: 80.1689 | D13: 2.93685 | E13: 5.07393 | F13: 61.5956 | G13: 6.80393 | H13: 83.7524 | I13: 100 | J13: 0.498146 | K13: 0.00123005 | L13: 0.995116
... A151: Run Combined Run 2start49 | B151: 79.0935 | C151: 72.3292 | D151: 60.4179 | E151: 6.60072 | F151: 0 | G151: 6.76436 | H151: 72.38 | I151: 100 | J151: 0.557662 | K151: 0.0290376 | L151: 0.92863
A152: Device 0: Tesla V100-SXM2-16GB | B152: Max thread in blocks: 1024 Total Global Memory: 16151,1 MB GPU Global Memory Usage: 0,497303 MB GPU Global Memory Hash Table: 1024 MB Max PARAMETR_SIZE in GPU Global Memory: 2574989 Shared memory per block: 49152 bytes (48 KB) Shared memory per multiprocessor: 98304 bytes (96 KB) Data size in Shared memory per block: 672 bytes (0,65625 KB) Constant Memory: 65536 bytes Parameter data size (in Constant Memory): 3360 bytes (3,28125 KB) Registers per Block: 65536 Warp Size: 32 Compute Capability: 7,0 Can Map Host Memory: Yes Clock Rate: 1530 MHz L2 Cache Size: 6291456 bytes Multiprocessor Count: 80 | C152: Max thread in blocks by axis: (1024, 1024, 64) | D152: Max blocks by axis: (2147483647, 65535, 65535) | E152: Device 1: Tesla V100-SXM2-16GB | F152: Max thread in blocks: 1024 Total Global Memory: 16151,1 MB GPU Global Memory Usage: 0,497303 MB GPU Global Memory Hash Table: 1024 MB Max PARAMETR_SIZE in GPU Global Memory: 2574989 Shared memory per block: 49152 bytes (48 KB) Shared memory per multiprocessor: 98304 bytes (96 KB) Data size in Shared memory per block: 672 bytes (0,65625 KB) Constant Memory: 65536 bytes Parameter data size (in Constant Memory): 3360 bytes (3,28125 KB) Registers per Block: 65536 Warp Size: 32 Compute Capability: 7,0 Can Map Host Memory: Yes Clock Rate: 1530 MHz L2 Cache Size: 6291456 bytes Multiprocessor Count: 80 | G152: Max thread in blocks by axis: (1024, 1024, 64) | H152: Max blocks by axis: (2147483647, 65535, 65535) | I152: Device 2: Tesla V100-SXM2-16GB | J152: Max thread in blocks: 1024 Total Global Memory: 16151,1 MB GPU Global Memory Usage: 0,497303 MB GPU Global Memory Hash Table: 1024 MB Max PARAMETR_SIZE in GPU Global Memory: 2574989 Shared memory per block: 49152 bytes (48 KB) Shared memory per multiprocessor: 98304 bytes (96 KB) Data size in Shared memory per block: 672 bytes (0,65625 KB) Constant Memory: 65536 bytes Parameter data size (in Constant Memory): 3360 bytes (3,28125 KB) Registers per Block: 65536 Warp Size: 32 Compute Capability: 7,0 Can Map Host Memory: Yes Clock Rate: 1530 MHz L2 Cache Size: 6291456 bytes Multiprocessor Count: 80 | K152: Max thread in blocks by axis: (1024, 1024, 64) | L152: Max blocks by axis: (2147483647, 65535, 65535) | M152: Device 3: Tesla V100-SXM2-16GB | N152: Max thread in blocks: 1024 Total Global Memory: 16151,1 MB GPU Global Memory Usage: 0,497303 MB GPU Global Memory Hash Table: 1024 MB Max PARAMETR_SIZE in GPU Global Memory: 2574989 Shared memory per block: 49152 bytes (48 KB) Shared memory per multiprocessor: 98304 bytes (96 KB) Data size in Shared memory per block: 672 bytes (0,65625 KB) Constant Memory: 65536 bytes Parameter data size (in Constant Memory): 3360 bytes (3,28125 KB) Registers per Block: 65536 Warp Size: 32 Compute Capability: 7,0 Can Map Host Memory: Yes Clock Rate: 1530 MHz L2 Cache Size: 6291456 bytes Multiprocessor Count: 80 | O152: Max thread in blocks by axis: (1024, 1024, 64) | P152: Max blocks by axis: (2147483647, 65535, 65535) | Q152: PARAMETR_SIZE: 84 | R152: MAX_VALUE_SIZE: 5 | S152: SET_PARAMETR_SIZE_ONE_X: 21 | T152: ANT_SIZE: 500 | U152: MAX_THREAD_CUDA: 512 | V152: NAME_FILE_GRAPH: Parametr_Graph/test84,txt | W152: KOL_ITERATION: 500 | X152: KOL_PROGREV: 5 | Y152: KOL_PROGON_STATISTICS: 50 | Z152: PARAMETR_RO: 0,999 | AA152: PARAMETR_Q: 1 | AB152: PRINT_INFORMATION: 0 | AC152: MAX_PARAMETR_VALUE_TO_MIN_OPT: 1 | AD152: OPTIMIZE: OPTIMIZE_MIN_1 | AE152: FUNCTION: SHAFFERA GO_HASH: 1 | AF152: HASH_TABLE_SIZE: 67108864 | AG152: ZERO_HASH_RESULT: -1 | AH152: ZERO_HASH: 18446744073709551615 | AI152: MAX_PROBES: 10000
A153: Run 4 function ACO 4start0 | B153: 94.9932 | C153: 88.5267 | D153: 2.95425 | E153: 5.97915 | F153: 69.3954 | G153: 6.46654 | H153: 99.2596 | I153: 100 | J153: 0.892565 | K153: 0.00123848 | L153: 0.995114
A154: Run 4 function ACO 4start1 | B154: 94.9181 | C154: 88.4345 | D154: 2.92865 | E154: 6.02523 | F154: 69.2613 | G154: 6.48354 | H154: 99.1496 | I154: 100 | J154: 0.893271 | K154: 0.00123011 | L154: 0.995114
A155: Run 4 function ACO 4start2 | B155: 94.2638 | C155: 87.9296 | D155: 2.88052 | E155: 5.91873 | F155: 69.1733 | G155: 6.33417 | H155: 99.1048 | I155: 100 | J155: 0.899472 | K155: 0.00123066 | L155: 0.995116
A156: Run 4 function ACO 4start3 | B156: 94.9936 | C156: 88.5225 | D156: 2.93377 | E156: 6.0836 | F156: 69.2633 | G156: 6.47113 | H156: 99.0728 | I156: 100 | J156: 0.892561 | K156: 0.00123174 | L156: 0.995116
A157: Run 4 function ACO 4start4 | B157: 94.7373 | C157: 88.3075 | D157: 2.92456 | E157: 5.98632 | F157: 69.2441 | G157: 6.42983 | H157: 99.0272 | I157: 100 | J157: 0.894976 | K157: 0.00123217 | L157: 0.995116
A158: Run 4 function ACO 4start5 | B158: 94.5588 | C158: 88.1395 | D158: 2.87643 | E158: 5.9812 | F158: 69.1897 | G158: 6.41928 | H158: 99.3052 | I158: 100 | J158: 0.896665 | K158: 0.00123065 | L158: 0.995116
A159: Run 4 function ACO 4start6 | B159: 95.0807 | C159: 88.5983 | D159: 2.98805 | E159: 6.03034 | F159: 69.3002 | G159: 6.48241 | H159: 99.28 | I159: 100 | J159: 0.891744 | K159: 0.00123076 | L159: 0.995116
A160: Run 4 function ACO 4start7 | B160: 95.015 | C160: 88.4949 | D160: 2.90612 | E160: 6.06722 | F160: 69.2511 | G160: 6.52001 | H160: 99.2552 | I160: 100 | J160: 0.892361 | K160: 0.00126087 | L160: 0.995116
A161: Run 4 function ACO 4start8 | B161: 94.338 | C161: 88.0269 | D161: 2.89076 | E161: 5.94843 | F161: 69.1866 | G161: 6.31114 | H161: 99.1792 | I161: 100 | J161: 0.898764 | K161: 0.00123075 | L161: 0.995116
A162: Run 4 function ACO 4start9 | B162: 95.0541 | C162: 88.5636 | D162: 2.91534 | E162: 6.10101 | F162: 69.2787 | G162: 6.49049 | H162: 99.1604 | I162: 100 | J162: 0.891994 | K162: 0.0012447 | L162: 0.995116
A163: Run 4 function ACO 4start10 | B163: 95.006 | C163: 88.5257 | D163: 2.93377 | E163: 6.07745 | F163: 69.2932 | G163: 6.48029 | H163: 99.2192 | I163: 100 | J163: 0.892445 | K163: 0.00123068 | L163: 0.995116
A164: Run 4 function ACO 4start11 | B164: 94.4911 | C164: 88.1354 | D164: 2.86312 | E164: 6.01601 | F164: 69.1968 | G164: 6.35574 | H164: 99.052 | I164: 100 | J164: 0.897307 | K164: 0.00125935 | L164: 0.995116
... A302: Run Combined Run 2start49 | B302: 87.945 | C302: 81.7336 | D302: 68.0622 | E302: 8.59546 | F302: 0 | G302: 6.21146 | H302: 97.4192 | I302: 100 | J302: 0.981889 | K302: 0.0108572 | L302: 0.995099
A303: Device 0: Tesla V100-SXM2-16GB | B303: Max thread in blocks: 1024 Total Global Memory: 16151,1 MB GPU Global Memory Usage: 0,990772 MB GPU Global Memory Hash Table: 1024 MB Max PARAMETR_SIZE in GPU Global Memory: 2574989 Shared memory per block: 49152 bytes (48 KB) Shared memory per multiprocessor: 98304 bytes (96 KB) Data size in Shared memory per block: 1344 bytes (1,3125 KB) Constant Memory: 65536 bytes Parameter data size (in Constant Memory): 6720 bytes (6,5625 KB) Registers per Block: 65536 Warp Size: 32 Compute Capability: 7,0 Can Map Host Memory: Yes Clock Rate: 1530 MHz L2 Cache Size: 6291456 bytes Multiprocessor Count: 80 | C303: Max thread in blocks by axis: (1024, 1024, 64) | D303: Max blocks by axis: (2147483647, 65535, 65535) | E303: Device 1: Tesla V100-SXM2-16GB | F303: Max thread in blocks: 1024 Total Global Memory: 16151,1 MB GPU Global Memory Usage: 0,990772 MB GPU Global Memory Hash Table: 1024 MB Max PARAMETR_SIZE in GPU Global Memory: 2574989 Shared memory per block: 49152 bytes (48 KB) Shared memory per multiprocessor: 98304 bytes (96 KB) Data size in Shared memory per block: 1344 bytes (1,3125 KB) Constant Memory: 65536 bytes Parameter data size (in Constant Memory): 6720 bytes (6,5625 KB) Registers per Block: 65536 Warp Size: 32 Compute Capability: 7,0 Can Map Host Memory: Yes Clock Rate: 1530 MHz L2 Cache Size: 6291456 bytes Multiprocessor Count: 80 | G303: Max thread in blocks by axis: (1024, 1024, 64) | H303: Max blocks by axis: (2147483647, 65535, 65535) | I303: Device 2: Tesla V100-SXM2-16GB | J303: Max thread in blocks: 1024 Total Global Memory: 16151,1 MB GPU Global Memory Usage: 0,990772 MB GPU Global Memory Hash Table: 1024 MB Max PARAMETR_SIZE in GPU Global Memory: 2574989 Shared memory per block: 49152 bytes (48 KB) Shared memory per multiprocessor: 98304 bytes (96 KB) Data size in Shared memory per block: 1344 bytes (1,3125 KB) Constant Memory: 65536 bytes Parameter data size (in Constant Memory): 6720 bytes (6,5625 KB) Registers per Block: 65536 Warp Size: 32 Compute Capability: 7,0 Can Map Host Memory: Yes Clock Rate: 1530 MHz L2 Cache Size: 6291456 bytes Multiprocessor Count: 80 | K303: Max thread in blocks by axis: (1024, 1024, 64) | L303: Max blocks by axis: (2147483647, 65535, 65535) | M303: Device 3: Tesla V100-SXM2-16GB | N303: Max thread in blocks: 1024 Total Global Memory: 16151,1 MB GPU Global Memory Usage: 0,990772 MB GPU Global Memory Hash Table: 1024 MB Max PARAMETR_SIZE in GPU Global Memory: 2574989 Shared memory per block: 49152 bytes (48 KB) Shared memory per multiprocessor: 98304 bytes (96 KB) Data size in Shared memory per block: 1344 bytes (1,3125 KB) Constant Memory: 65536 bytes Parameter data size (in Constant Memory): 6720 bytes (6,5625 KB) Registers per Block: 65536 Warp Size: 32 Compute Capability: 7,0 Can Map Host Memory: Yes Clock Rate: 1530 MHz L2 Cache Size: 6291456 bytes Multiprocessor Count: 80 | O303: Max thread in blocks by axis: (1024, 1024, 64) | P303: Max blocks by axis: (2147483647, 65535, 65535) | Q303: PARAMETR_SIZE: 168 | R303: MAX_VALUE_SIZE: 5 | S303: SET_PARAMETR_SIZE_ONE_X: 21 | T303: ANT_SIZE: 500 | U303: MAX_THREAD_CUDA: 512 | V303: NAME_FILE_GRAPH: Parametr_Graph/test168,txt | W303: KOL_ITERATION: 500 | X303: KOL_PROGREV: 5 | Y303: KOL_PROGON_STATISTICS: 50 | Z303: PARAMETR_RO: 0,999 | AA303: PARAMETR_Q: 1 | AB303: PRINT_INFORMATION: 0 | AC303: MAX_PARAMETR_VALUE_TO_MIN_OPT: 1 | AD303: OPTIMIZE: OPTIMIZE_MIN_1 | AE303: FUNCTION: SHAFFERA GO_HASH: 1 | AF303: HASH_TABLE_SIZE: 67108864 | AG303: ZERO_HASH_RESULT: -1 | AH303: ZERO_HASH: 18446744073709551615 | AI303: MAX_PROBES: 10000
A304: Run 4 function ACO 4start0 | B304: 101.274 | C304: 93.316 | D304: 3.28194 | E304: 8.46848 | F304: 70.6162 | G304: 7.95766 | H304: 99.9836 | I304: 100 | J304: 1.65603 | K304: 0.0129673 | L304: 0.995102
A305: Run 4 function ACO 4start1 | B305: 100.231 | C305: 93.231 | D305: 3.2717 | E305: 8.51148 | F305: 70.44 | G305: 6.99989 | H305: 99.982 | I305: 100 | J305: 1.67326 | K305: 0.0122035 | L305: 0.981016
A306: Run 4 function ACO 4start2 | B306: 100.167 | C306: 93.1666 | D306: 3.2932 | E306: 8.46029 | F306: 70.4738 | G306: 7.00091 | H306: 99.9784 | I306: 100 | J306: 1.67432 | K306: 0.0136972 | L306: 0.981019
A307: Run 4 function ACO 4start3 | B307: 97.8145 | C307: 91.3655 | D307: 2.93992 | E307: 8.25037 | F307: 70.0038 | G307: 6.44901 | H307: 99.9752 | I307: 100 | J307: 1.7146 | K307: 0.0125838 | L307: 0.980849
A308: Run 4 function ACO 4start4 | B308: 97.5472 | C308: 91.1558 | D308: 2.93377 | E308: 8.17358 | F308: 69.9352 | G308: 6.39141 | H308: 99.9784 | I308: 100 | J308: 1.7193 | K308: 0.0119196 | L308: 0.981016
A309: Run 4 function ACO 4start5 | B309: 97.877 | C309: 91.4118 | D309: 2.93787 | E309: 8.2596 | F309: 70.0089 | G309: 6.46519 | H309: 99.9704 | I309: 100 | J309: 1.7135 | K309: 0.0197938 | L309: 0.980721
A310: Run 4 function ACO 4start6 | B310: 97.9065 | C310: 91.4504 | D310: 2.97166 | E310: 8.24935 | F310: 70.0028 | G310: 6.45605 | H310: 99.9656 | I310: 100 | J310: 1.71299 | K310: 0.0128157 | L310: 0.981015
A311: Run 4 function ACO 4start7 | B311: 97.2641 | C311: 90.9244 | D311: 2.86209 | E311: 8.20839 | F311: 69.8839 | G311: 6.33976 | H311: 99.9608 | I311: 100 | J311: 1.7243 | K311: 0.013763 | L311: 0.981009
A312: Run 4 function ACO 4start8 | B312: 97.9056 | C312: 91.4712 | D312: 2.99214 | E312: 8.2299 | F312: 70.0376 | G312: 6.43436 | H312: 99.9576 | I312: 100 | J312: 1.713 | K312: 0.0154241 | L312: 0.980998
A313: Run 4 function ACO 4start9 | B313: 97.8429 | C313: 91.2743 | D313: 2.89281 | E313: 8.25959 | F313: 69.9617 | G313: 6.56853 | H313: 99.9604 | I313: 100 | J313: 1.7141 | K313: 0.011879 | L313: 0.981019
A314: Run 4 function ACO 4start10 | B314: 97.3741 | C314: 91.0422 | D314: 2.89588 | E314: 8.17358 | F314: 69.9218 | G314: 6.33187 | H314: 99.978 | I314: 100 | J314: 1.72235 | K314: 0.0111973 | L314: 0.988792
...

Sheet Лист2
A1: Device 0: Tesla V100-SXM2-16GB | B1: Max thread in blocks: 1024 Total Global Memory: 16151,1 MB GPU Global Memory Usage: 0,0903511 MB GPU Global Memory Hash Table: 1024 MB Max PARAMETR_SIZE in GPU Global Memory: 7343488 Shared memory per block: 49152 bytes (48 KB) Shared memory per multiprocessor: 98304 bytes (96 KB) Data size in Shared memory per block: 336 bytes (0,328125 KB) Constant Memory: 65536 bytes Parameter data size (in Constant Memory): 1680 bytes (1,64062 KB) Registers per Block: 65536 Warp Size: 32 Compute Capability: 7,0 Can Map Host Memory: Yes Clock Rate: 1530 MHz L2 Cache Size: 6291456 bytes Multiprocessor Count: 80 | C1: Max thread in blocks by axis: (1024, 1024, 64) | D1: Max blocks by axis: (2147483647, 65535, 65535) | E1: Device 1: Tesla V100-SXM2-16GB | F1: Max thread in blocks: 1024 Total Global Memory: 16151,1 MB GPU Global Memory Usage: 0,0903511 MB GPU Global Memory Hash Table: 1024 MB Max PARAMETR_SIZE in GPU Global Memory: 7343488 Shared memory per block: 49152 bytes (48 KB) Shared memory per multiprocessor: 98304 bytes (96 KB) Data size in Shared memory per block: 336 bytes (0,328125 KB) Constant Memory: 65536 bytes Parameter data size (in Constant Memory): 1680 bytes (1,64062 KB) Registers per Block: 65536 Warp Size: 32 Compute Capability: 7,0 Can Map Host Memory: Yes Clock Rate: 1530 MHz L2 Cache Size: 6291456 bytes Multiprocessor Count: 80 | G1: Max thread in blocks by axis: (1024, 1024, 64) | H1: Max blocks by axis: (2147483647, 65535, 65535) | I1: Device 2: Tesla V100-SXM2-16GB | J1: Max thread in blocks: 1024 Total Global Memory: 16151,1 MB GPU Global Memory Usage: 0,0903511 MB GPU Global Memory Hash Table: 1024 MB Max PARAMETR_SIZE in GPU Global Memory: 7343488 Shared memory per block: 49152 bytes (48 KB) Shared memory per multiprocessor: 98304 bytes (96 KB) Data size in Shared memory per block: 336 bytes (0,328125 KB) Constant Memory: 65536 bytes Parameter data size (in Constant Memory): 1680 bytes (1,64062 KB) Registers per Block: 65536 Warp Size: 32 Compute Capability: 7,0 Can Map Host Memory: Yes Clock Rate: 1530 MHz L2 Cache Size: 6291456 bytes Multiprocessor Count: 80 | K1: Max thread in blocks by axis: (1024, 1024, 64) | L1: Max blocks by axis: (2147483647, 65535, 65535) | M1: Device 3: Tesla V100-SXM2-16GB | N1: Max thread in blocks: 1024 Total Global Memory: 16151,1 MB GPU Global Memory Usage: 0,0903511 MB GPU Global Memory Hash Table: 1024 MB Max PARAMETR_SIZE in GPU Global Memory: 7343488 Shared memory per block: 49152 bytes (48 KB) Shared memory per multiprocessor: 98304 bytes (96 KB) Data size in Shared memory per block: 336 bytes (0,328125 KB) Constant Memory: 65536 bytes Parameter data size (in Constant Memory): 1680 bytes (1,64062 KB) Registers per Block: 65536 Warp Size: 32 Compute Capability: 7,0 Can Map Host Memory: Yes Clock Rate: 1530 MHz L2 Cache Size: 6291456 bytes Multiprocessor Count: 80 | O1: Max thread in blocks by axis: (1024, 1024, 64) | P1: Max blocks by axis: (2147483647, 65535, 65535) | Q1: PARAMETR_SIZE: 42 | R1: MAX_VALUE_SIZE: 5 | S1: SET_PARAMETR_SIZE_ONE_X: 21 | T1: ANT_SIZE: 500 | U1: MAX_THREAD_CUDA: 512 | V1: NAME_FILE_GRAPH: Parametr_Graph/test42,txt | W1: KOL_ITERATION: 500 | X1: KOL_PROGREV: 5 | Y1: KOL_PROGON_STATISTICS: 50 | Z1: PARAMETR_RO: 0,999 | AA1: PARAMETR_Q: 1 | AB1: PRINT_INFORMATION: 0 | AC1: MAX_PARAMETR_VALUE_TO_MIN_OPT: 1 | AD1: OPTIMIZE: OPTIMIZE_MIN_1 | AE1: FUNCTION: SHAFFERA GO_HASH: 1 | AF1: HASH_TABLE_SIZE: 67108864 | AG1: ZERO_HASH_RESULT: -1 | AH1: ZERO_HASH: 18446744073709551615 | AI1: MAX_PROBES: 10000
A2: Run 4 function ACO 4start0 | B2: 93.3506 | C2: 84.8128 | D2: 4.24756 | E2: 5.58797 | F2: 62.8829 | G2: 8.53784 | H2: 83.5484 | I2: 100 | J2: 0.464112 | K2: 0.00123006 | L2: 0.995116
A3: Run 4 function ACO 4start1 | B3: 93.312 | C3: 84.6632 | D3: 4.21684 | E3: 5.62381 | F3: 62.8635 | G3: 8.64872 | H3: 82.4424 | I3: 100 | J3: 0.464304 | K3: 0.00123006 | L3: 0.995116
A4: Run 4 function ACO 4start2 | B4: 94.0844 | C4: 85.3422 | D4: 4.42778 | E4: 5.71699 | F4: 62.9259 | G4: 8.74219 | H4: 82.0028 | I4: 100 | J4: 0.460492 | K4: 0.00123006 | L4: 0.995116
A5: Run 4 function ACO 4start3 | B5: 94.9025 | C5: 85.1466 | D5: 4.37658 | E5: 5.72006 | F5: 62.926 | G5: 9.75594 | H5: 86.7204 | I5: 100 | J5: 0.456522 | K5: 0.00123005 | L5: 0.995116
A6: Run 4 function ACO 4start4 | B6: 94.7414 | C6: 85.8214 | D6: 4.43495 | E6: 5.71289 | F6: 63.5106 | G6: 8.91998 | H6: 86.13 | I6: 100 | J6: 0.457299 | K6: 0.00123005 | L6: 0.995116
A7: Run 4 function ACO 4start5 | B7: 95.0728 | C7: 85.1681 | D7: 4.32436 | E7: 5.68627 | F7: 63.0652 | G7: 9.90474 | H7: 85.5484 | I7: 100 | J7: 0.455705 | K7: 0.00123007 | L7: 0.995116
A8: Run 4 function ACO 4start6 | B8: 94.0667 | C8: 85.3001 | D8: 4.43495 | E8: 5.70368 | F8: 63.0191 | G8: 8.76654 | H8: 85.202 | I8: 100 | J8: 0.460579 | K8: 0.00123009 | L8: 0.995116
A9: Run 4 function ACO 4start7 | B9: 95.2962 | C9: 85.1835 | D9: 4.34074 | E9: 5.73645 | F9: 63.0171 | G9: 10.1127 | H9: 84.9284 | I9: 100 | J9: 0.454636 | K9: 0.0012301 | L9: 0.995116
A10: Run 4 function ACO 4start8 | B10: 91.116 | C10: 82.5601 | D10: 3.54203 | E10: 5.37601 | F10: 62.2336 | G10: 8.55592 | H10: 85.228 | I10: 100 | J10: 0.475494 | K10: 0.00123005 | L10: 0.995116
A11: Run 4 function ACO 4start9 | B11: 89.0236 | C11: 81.6824 | D11: 3.21435 | E11: 5.32276 | F11: 62.035 | G11: 7.34118 | H11: 85.9752 | I11: 100 | J11: 0.48667 | K11: 0.00123006 | L11: 0.995116
A12: Run 4 function ACO 4start10 | B12: 89.0703 | C12: 81.7551 | D12: 3.25121 | E12: 5.29409 | F12: 62.0166 | G12: 7.31518 | H12: 85.312 | I12: 100 | J12: 0.486415 | K12: 0.00123012 | L12: 0.995116
A13: Run 4 function ACO 4start11 | B13: 88.7584 | C13: 81.4818 | D13: 3.19387 | E13: 5.3156 | F13: 61.9746 | G13: 7.27669 | H13: 84.5216 | I13: 100 | J13: 0.488124 | K13: 0.00123005 | L13: 0.995116
... A151: Run Combined Run 2start49 | B151: 78.1633 | C151: 71.8408 | D151: 60.376 | E151: 6.46452 | F151: 0 | G151: 6.32251 | H151: 70.088 | I151: 100 | J151: 0.564299 | K151: 0.0290376 | L151: 0.920762
A152: Device 0: Tesla V100-SXM2-16GB | B152: Max thread in blocks: 1024 Total Global Memory: 16151,1 MB GPU Global Memory Usage: 0,176868 MB GPU Global Memory Hash Table: 1024 MB Max PARAMETR_SIZE in GPU Global Memory: 7343488 Shared memory per block: 49152 bytes (48 KB) Shared memory per multiprocessor: 98304 bytes (96 KB) Data size in Shared memory per block: 672 bytes (0,65625 KB) Constant Memory: 65536 bytes Parameter data size (in Constant Memory): 3360 bytes (3,28125 KB) Registers per Block: 65536 Warp Size: 32 Compute Capability: 7,0 Can Map Host Memory: Yes Clock Rate: 1530 MHz L2 Cache Size: 6291456 bytes Multiprocessor Count: 80 | C152: Max thread in blocks by axis: (1024, 1024, 64) | D152: Max blocks by axis: (2147483647, 65535, 65535) | E152: Device 1: Tesla V100-SXM2-16GB | F152: Max thread in blocks: 1024 Total Global Memory: 16151,1 MB GPU Global Memory Usage: 0,176868 MB GPU Global Memory Hash Table: 1024 MB Max PARAMETR_SIZE in GPU Global Memory: 7343488 Shared memory per block: 49152 bytes (48 KB) Shared memory per multiprocessor: 98304 bytes (96 KB) Data size in Shared memory per block: 672 bytes (0,65625 KB) Constant Memory: 65536 bytes Parameter data size (in Constant Memory): 3360 bytes (3,28125 KB) Registers per Block: 65536 Warp Size: 32 Compute Capability: 7,0 Can Map Host Memory: Yes Clock Rate: 1530 MHz L2 Cache Size: 6291456 bytes Multiprocessor Count: 80 | G152: Max thread in blocks by axis: (1024, 1024, 64) | H152: Max blocks by axis: (2147483647, 65535, 65535) | I152: Device 2: Tesla V100-SXM2-16GB | J152: Max thread in blocks: 1024 Total Global Memory: 16151,1 MB GPU Global Memory Usage: 0,176868 MB GPU Global Memory Hash Table: 1024 MB Max PARAMETR_SIZE in GPU Global Memory: 7343488 Shared memory per block: 49152 bytes (48 KB) Shared memory per multiprocessor: 98304 bytes (96 KB) Data size in Shared memory per block: 672 bytes (0,65625 KB) Constant Memory: 65536 bytes Parameter data size (in Constant Memory): 3360 bytes (3,28125 KB) Registers per Block: 65536 Warp Size: 32 Compute Capability: 7,0 Can Map Host Memory: Yes Clock Rate: 1530 MHz L2 Cache Size: 6291456 bytes Multiprocessor Count: 80 | K152: Max thread in blocks by axis: (1024, 1024, 64) | L152: Max blocks by axis: (2147483647, 65535, 65535) | M152: Device 3: Tesla V100-SXM2-16GB | N152: Max thread in blocks: 1024 Total Global Memory: 16151,1 MB GPU Global Memory Usage: 0,176868 MB GPU Global Memory Hash Table: 1024 MB Max PARAMETR_SIZE in GPU Global Memory: 7343488 Shared memory per block: 49152 bytes (48 KB) Shared memory per multiprocessor: 98304 bytes (96 KB) Data size in Shared memory per block: 672 bytes (0,65625 KB) Constant Memory: 65536 bytes Parameter data size (in Constant Memory): 3360 bytes (3,28125 KB) Registers per Block: 65536 Warp Size: 32 Compute Capability: 7,0 Can Map Host Memory: Yes Clock Rate: 1530 MHz L2 Cache Size: 6291456 bytes Multiprocessor Count: 80 | O152: Max thread in blocks by axis: (1024, 1024, 64) | P152: Max blocks by axis: (2147483647, 65535, 65535) | Q152: PARAMETR_SIZE: 84 | R152: MAX_VALUE_SIZE: 5 | S152: SET_PARAMETR_SIZE_ONE_X: 21 | T152: ANT_SIZE: 500 | U152: MAX_THREAD_CUDA: 512 | V152: NAME_FILE_GRAPH: Parametr_Graph/test84,txt | W152: KOL_ITERATION: 500 | X152: KOL_PROGREV: 5 | Y152: KOL_PROGON_STATISTICS: 50 | Z152: PARAMETR_RO: 0,999 | AA152: PARAMETR_Q: 1 | AB152: PRINT_INFORMATION: 0 | AC152: MAX_PARAMETR_VALUE_TO_MIN_OPT: 1 | AD152: OPTIMIZE: OPTIMIZE_MIN_1 | AE152: FUNCTION: SHAFFERA GO_HASH: 1 | AF152: HASH_TABLE_SIZE: 67108864 | AG152: ZERO_HASH_RESULT: -1 | AH152: ZERO_HASH: 18446744073709551615 | AI152: MAX_PROBES: 10000
A153: Run 4 function ACO 4start0 | B153: 94.2179 | C153: 88.1477 | D153: 2.81396 | E153: 5.87572 | F153: 69.9054 | G153: 6.07021 | H153: 98.9272 | I153: 100 | J153: 0.89991 | K153: 0.00321284 | L153: 0.995104
A154: Run 4 function ACO 4start1 | B154: 94.4358 | C154: 88.2798 | D154: 2.82728 | E154: 5.96891 | F154: 69.8245 | G154: 6.15605 | H154: 98.7672 | I154: 100 | J154: 0.897833 | K154: 0.0014099 | L154: 0.995116
A155: Run 4 function ACO 4start2 | B155: 94.4014 | C155: 88.2104 | D155: 2.84161 | E155: 5.91669 | F155: 69.8174 | G155: 6.19103 | H155: 98.6524 | I155: 100 | J155: 0.89816 | K155: 0.00240563 | L155: 0.995116
A156: Run 4 function ACO 4start3 | B156: 94.1775 | C156: 88.1026 | D156: 2.80475 | E156: 5.93716 | F156: 69.8143 | G156: 6.07487 | H156: 98.522 | I156: 100 | J156: 0.900296 | K156: 0.00952604 | L156: 0.995116
A157: Run 4 function ACO 4start4 | B157: 94.4954 | C157: 88.3372 | D157: 2.84468 | E157: 5.94843 | F157: 69.8286 | G157: 6.15816 | H157: 98.4552 | I157: 100 | J157: 0.897267 | K157: 0.00148243 | L157: 0.995114
A158: Run 4 function ACO 4start5 | B158: 94.1844 | C158: 88.1047 | D158: 2.81089 | E158: 5.94331 | F158: 69.7692 | G158: 6.07966 | H158: 98.6688 | I158: 100 | J158: 0.90023 | K158: 0.00124171 | L158: 0.995116
A159: Run 4 function ACO 4start6 | B159: 94.5298 | C159: 88.3547 | D159: 2.85902 | E159: 5.98734 | F159: 69.843 | G159: 6.17513 | H159: 98.8748 | I159: 100 | J159: 0.896941 | K159: 0.00143552 | L159: 0.995115
A160: Run 4 function ACO 4start7 | B160: 94.5444 | C160: 88.3435 | D160: 2.82728 | E160: 6.01397 | F160: 69.8092 | G160: 6.20092 | H160: 98.8332 | I160: 100 | J160: 0.896802 | K160: 0.0033431 | L160: 0.995114
A161: Run 4 function ACO 4start8 | B161: 94.2263 | C161: 88.1601 | D161: 2.80987 | E161: 5.97198 | F161: 69.7702 | G161: 6.06623 | H161: 98.7816 | I161: 100 | J161: 0.89983 | K161: 0.00184028 | L161: 0.995116
A162: Run 4 function ACO 4start9 | B162: 94.5329 | C162: 88.3803 | D162: 2.8498 | E162: 6.04469 | F162: 69.8532 | G162: 6.15264 | H162: 98.766 | I162: 100 | J162: 0.896911 | K162: 0.00670291 | L162: 0.995116
A163: Run 4 function ACO 4start10 | B163: 94.5246 | C163: 88.3875 | D163: 2.83752 | E163: 6.07746 | F163: 69.7867 | G163: 6.13707 | H163: 98.7292 | I163: 100 | J163: 0.89699 | K163: 0.00123455 | L163: 0.995114
A164: Run 4 function ACO 4start11 | B164: 94.2938 | C164: 88.2072 | D164: 2.78939 | E164: 6.02523 | F164: 69.7487 | G164: 6.08659 | H164: 98.762 | I164: 100 | J164: 0.899186 | K164: 0.00132286 | L164: 0.995108
... A302: Run Combined Run 2start49 | B302: 88.8328 | C302: 82.5948 | D302: 69.1292 | E302: 8.68352 | F302: 0 | G302: 6.23797 | H302: 98.5988 | I302: 100 | J302: 0.972076 | K302: 0.00123113 | L302: 0.995116
A303: Device 0: Tesla V100-SXM2-16GB | B303: Max thread in blocks: 1024 Total Global Memory: 16151,1 MB GPU Global Memory Usage: 0,349903 MB GPU Global Memory Hash Table: 1024 MB Max PARAMETR_SIZE in GPU Global Memory: 7343488 Shared memory per block: 49152 bytes (48 KB) Shared memory per multiprocessor: 98304 bytes (96 KB) Data size in Shared memory per block: 1344 bytes (1,3125 KB) Constant Memory: 65536 bytes Parameter data size (in Constant Memory): 6720 bytes (6,5625 KB) Registers per Block: 65536 Warp Size: 32 Compute Capability: 7,0 Can Map Host Memory: Yes Clock Rate: 1530 MHz L2 Cache Size: 6291456 bytes Multiprocessor Count: 80 | C303: Max thread in blocks by axis: (1024, 1024, 64) | D303: Max blocks by axis: (2147483647, 65535, 65535) | E303: Device 1: Tesla V100-SXM2-16GB | F303: Max thread in blocks: 1024 Total Global Memory: 16151,1 MB GPU Global Memory Usage: 0,349903 MB GPU Global Memory Hash Table: 1024 MB Max PARAMETR_SIZE in GPU Global Memory: 7343488 Shared memory per block: 49152 bytes (48 KB) Shared memory per multiprocessor: 98304 bytes (96 KB) Data size in Shared memory per block: 1344 bytes (1,3125 KB) Constant Memory: 65536 bytes Parameter data size (in Constant Memory): 6720 bytes (6,5625 KB) Registers per Block: 65536 Warp Size: 32 Compute Capability: 7,0 Can Map Host Memory: Yes Clock Rate: 1530 MHz L2 Cache Size: 6291456 bytes Multiprocessor Count: 80 | G303: Max thread in blocks by axis: (1024, 1024, 64) | H303: Max blocks by axis: (2147483647, 65535, 65535) | I303: Device 2: Tesla V100-SXM2-16GB | J303: Max thread in blocks: 1024 Total Global Memory: 16151,1 MB GPU Global Memory Usage: 0,349903 MB GPU Global Memory Hash Table: 1024 MB Max PARAMETR_SIZE in GPU Global Memory: 7343488 Shared memory per block: 49152 bytes (48 KB) Shared memory per multiprocessor: 98304 bytes (96 KB) Data size in Shared memory per block: 1344 bytes (1,3125 KB) Constant Memory: 65536 bytes Parameter data size (in Constant Memory): 6720 bytes (6,5625 KB) Registers per Block: 65536 Warp Size: 32 Compute Capability: 7,0 Can Map Host Memory: Yes Clock Rate: 1530 MHz L2 Cache Size: 6291456 bytes Multiprocessor Count: 80 | K303: Max thread in blocks by axis: (1024, 1024, 64) | L303: Max blocks by axis: (2147483647, 65535, 65535) | M303: Device 3: Tesla V100-SXM2-16GB | N303: Max thread in blocks: 1024 Total Global Memory: 16151,1 MB GPU Global Memory Usage: 0,349903 MB GPU Global Memory Hash Table: 1024 MB Max PARAMETR_SIZE in GPU Global Memory: 7343488 Shared memory per block: 49152 bytes (48 KB) Shared memory per multiprocessor: 98304 bytes (96 KB) Data size in Shared memory per block: 1344 bytes (1,3125 KB) Constant Memory: 65536 bytes Parameter data size (in Constant Memory): 6720 bytes (6,5625 KB) Registers per Block: 65536 Warp Size: 32 Compute Capability: 7,0 Can Map Host Memory: Yes Clock Rate: 1530 MHz L2 Cache Size: 6291456 bytes Multiprocessor Count: 80 | O303: Max thread in blocks by axis: (1024, 1024, 64) | P303: Max blocks by axis: (2147483647, 65535, 65535) | Q303: PARAMETR_SIZE: 168 | R303: MAX_VALUE_SIZE: 5 | S303: SET_PARAMETR_SIZE_ONE_X: 21 | T303: ANT_SIZE: 500 | U303: MAX_THREAD_CUDA: 512 | V303: NAME_FILE_GRAPH: Parametr_Graph/test168,txt | W303: KOL_ITERATION: 500 | X303: KOL_PROGREV: 5 | Y303: KOL_PROGON_STATISTICS: 50 | Z303: PARAMETR_RO: 0,999 | AA303: PARAMETR_Q: 1 | AB303: PRINT_INFORMATION: 0 | AC303: MAX_PARAMETR_VALUE_TO_MIN_OPT: 1 | AD303: OPTIMIZE: OPTIMIZE_MIN_1 | AE303: FUNCTION: SHAFFERA GO_HASH: 1 | AF303: HASH_TABLE_SIZE: 67108864 | AG303: ZERO_HASH_RESULT: -1 | AH303: ZERO_HASH: 18446744073709551615 | AI303: MAX_PROBES: 10000
A304: Run 4 function ACO 4start0 | B304: 98.1404 | C304: 91.4731 | D304: 3.00136 | E304: 8.13978 | F304: 69.9587 | G304: 6.66731 | H304: 99.9808 | I304: 100 | J304: 1.7089 | K304: 0.0140816 | L304: 0.980555
A305: Run 4 function ACO 4start1 | B305: 98.1219 | C305: 91.4014 | D305: 2.98702 | E305: 8.18177 | F305: 69.8368 | G305: 6.72053 | H305: 99.9844 | I305: 100 | J305: 1.70923 | K305: 0.0134914 | L305: 0.981002
A306: Run 4 function ACO 4start2 | B306: 97.9154 | C306: 91.2795 | D306: 3.0075 | E306: 8.11623 | F306: 69.844 | G306: 6.6359 | H306: 99.9724 | I306: 100 | J306: 1.71283 | K306: 0.0111572 | L306: 0.981016
A307: Run 4 function ACO 4start3 | B307: 97.9947 | C307: 91.3308 | D307: 2.96961 | E307: 8.16538 | F307: 69.8389 | G307: 6.66393 | H307: 99.9768 | I307: 100 | J307: 1.71145 | K307: 0.0166429 | L307: 0.980865
A308: Run 4 function ACO 4start4 | B308: 97.9825 | C308: 91.3308 | D308: 3.00648 | E308: 8.17153 | F308: 69.8338 | G308: 6.6517 | H308: 99.9732 | I308: 100 | J308: 1.71166 | K308: 0.0108607 | L308: 0.981018
A309: Run 4 function ACO 4start5 | B309: 97.8699 | C309: 91.2233 | D309: 2.94197 | E309: 8.15207 | F309: 69.8471 | G309: 6.64665 | H309: 99.9684 | I309: 100 | J309: 1.71363 | K309: 0.0110933 | L309: 0.980911
A310: Run 4 function ACO 4start6 | B310: 98.0456 | C310: 91.3851 | D310: 3.0075 | E310: 8.16949 | F310: 69.8645 | G310: 6.66051 | H310: 99.9708 | I310: 100 | J310: 1.71056 | K310: 0.0183951 | L310: 0.980896
A311: Run 4 function ACO 4start7 | B311: 98.0382 | C311: 91.3818 | D311: 2.94504 | E311: 8.15923 | F311: 69.8696 | G311: 6.65632 | H311: 99.9656 | I311: 100 | J311: 1.71069 | K311: 0.0129052 | L311: 0.980767
A312: Run 4 function ACO 4start8 | B312: 97.9762 | C312: 91.3215 | D312: 2.99214 | E312: 8.19815 | F312: 69.8369 | G312: 6.65471 | H312: 99.9728 | I312: 100 | J312: 1.71177 | K312: 0.0290377 | L312: 0.980983
A313: Run 4 function ACO 4start9 | B313: 98.0264 | C313: 91.3818 | D313: 2.92968 | E313: 8.21249 | F313: 69.8727 | G313: 6.64465 | H313: 99.9668 | I313: 100 | J313: 1.71089 | K313: 0.0203811 | L313: 0.981014
A314: Run 4 function ACO 4start10 | B314: 97.6119 | C314: 91.1107 | D314: 2.95937 | E314: 8.14081 | F314: 69.7897 | G314: 6.50117 | H314: 99.9712 | I314: 100 | J314: 1.71816 | K314: 0.0145521 | L314: 0.981015
...

Sheet Лист3
A1: Device 0: Tesla V100-SXM2-16GB | B1: Max thread in blocks: 1024 Total Global Memory: 16151,1 MB GPU Global Memory Usage: 0,0887489 MB GPU Global Memory Hash Table: 1024 MB Max PARAMETR_SIZE in GPU Global Memory: 7482045 Shared memory per block: 49152 bytes (48 KB) Shared memory per multiprocessor: 98304 bytes (96 KB) Data size in Shared memory per block: 336 bytes (0,328125 KB) Constant Memory: 65536 bytes Parameter data size (in Constant Memory): 1680 bytes (1,64062 KB) Registers per Block: 65536 Warp Size: 32 Compute Capability: 7,0 Can Map Host Memory: Yes Clock Rate: 1530 MHz L2 Cache Size: 6291456 bytes Multiprocessor Count: 80 | C1: Max thread in blocks by axis: (1024, 1024, 64) | D1: Max blocks by axis: (2147483647, 65535, 65535) | E1: Device 1: Tesla V100-SXM2-16GB | F1: Max thread in blocks: 1024 Total Global Memory: 16151,1 MB GPU Global Memory Usage: 0,0887489 MB GPU Global Memory Hash Table: 1024 MB Max PARAMETR_SIZE in GPU Global Memory: 7482045 Shared memory per block: 49152 bytes (48 KB) Shared memory per multiprocessor: 98304 bytes (96 KB) Data size in Shared memory per block: 336 bytes (0,328125 KB) Constant Memory: 65536 bytes Parameter data size (in Constant Memory): 1680 bytes (1,64062 KB) Registers per Block: 65536 Warp Size: 32 Compute Capability: 7,0 Can Map Host Memory: Yes Clock Rate: 1530 MHz L2 Cache Size: 6291456 bytes Multiprocessor Count: 80 | G1: Max thread in blocks by axis: (1024, 1024, 64) | H1: Max blocks by axis: (2147483647, 65535, 65535) | I1: Device 2: Tesla V100-SXM2-16GB | J1: Max thread in blocks: 1024 Total Global Memory: 16151,1 MB GPU Global Memory Usage: 0,0887489 MB GPU Global Memory Hash Table: 1024 MB Max PARAMETR_SIZE in GPU Global Memory: 7482045 Shared memory per block: 49152 bytes (48 KB) Shared memory per multiprocessor: 98304 bytes (96 KB) Data size in Shared memory per block: 336 bytes (0,328125 KB) Constant Memory: 65536 bytes Parameter data size (in Constant Memory): 1680 bytes (1,64062 KB) Registers per Block: 65536 Warp Size: 32 Compute Capability: 7,0 Can Map Host Memory: Yes Clock Rate: 1530 MHz L2 Cache Size: 6291456 bytes Multiprocessor Count: 80 | K1: Max thread in blocks by axis: (1024, 1024, 64) | L1: Max blocks by axis: (2147483647, 65535, 65535) | M1: Device 3: Tesla V100-SXM2-16GB | N1: Max thread in blocks: 1024 Total Global Memory: 16151,1 MB GPU Global Memory Usage: 0,0887489 MB GPU Global Memory Hash Table: 1024 MB Max PARAMETR_SIZE in GPU Global Memory: 7482045 Shared memory per block: 49152 bytes (48 KB) Shared memory per multiprocessor: 98304 bytes (96 KB) Data size in Shared memory per block: 336 bytes (0,328125 KB) Constant Memory: 65536 bytes Parameter data size (in Constant Memory): 1680 bytes (1,64062 KB) Registers per Block: 65536 Warp Size: 32 Compute Capability: 7,0 Can Map Host Memory: Yes Clock Rate: 1530 MHz L2 Cache Size: 6291456 bytes Multiprocessor Count: 80 | O1: Max thread in blocks by axis: (1024, 1024, 64) | P1: Max blocks by axis: (2147483647, 65535, 65535) | Q1: PARAMETR_SIZE: 42 | R1: MAX_VALUE_SIZE: 5 | S1: SET_PARAMETR_SIZE_ONE_X: 21 | T1: ANT_SIZE: 500 | U1: MAX_THREAD_CUDA: 512 | V1: NAME_FILE_GRAPH: Parametr_Graph/test42,txt | W1: KOL_ITERATION: 500 | X1: KOL_PROGREV: 5 | Y1: KOL_PROGON_STATISTICS: 50 | Z1: PARAMETR_RO: 0,999 | AA1: PARAMETR_Q: 1 | AB1: PRINT_INFORMATION: 0 | AC1: MAX_PARAMETR_VALUE_TO_MIN_OPT: 1 | AD1: OPTIMIZE: OPTIMIZE_MIN_1 | AE1: FUNCTION: SHAFFERA GO_HASH: 1 | AF1: HASH_TABLE_SIZE: 67108864 | AG1: ZERO_HASH_RESULT: -1 | AH1: ZERO_HASH: 18446744073709551615 | AI1: MAX_PROBES: 10000 | AJ1: MAX_CONST: 8192 | AK1: MAX_SHARED: 6144 | AL1: BLOCK_SIZE: 64 | AM1: BIN_SEARCH: 0 | AN1: NON_WHILE_ANT: 1
A2: Run 4 function ACO 4start0 | B2: 86.9006 | C2: 80.4117 | D2: 3.02184 | E2: 5.00225 | F2: 62.0944 | G2: 6.48891 | H2: 17.5024 | I2: 100 | J2: 0.49856 | K2: 0.0108579 | L2: 0.995105
A3: Run 4 function ACO 4start1 | B3: 86.2698 | C3: 79.8585 | D3: 2.9563 | E3: 4.92545 | F3: 61.8906 | G3: 6.4113 | H3: 16.408 | I3: 100 | J3: 0.502205 | K3: 0.0108599 | L3: 0.995008
A4: Run 4 function ACO 4start2 | B4: 86.3633 | C4: 79.9713 | D4: 2.98395 | E4: 4.94183 | F4: 61.9234 | G4: 6.392 | H4: 15.0256 | I4: 100 | J4: 0.501661 | K4: 0.010858 | L4: 0.995005
A5: Run 4 function ACO 4start3 | B5: 86.7892 | C5: 80.3174 | D5: 3.03208 | E5: 4.98689 | F5: 61.9715 | G5: 6.47181 | H5: 12.4032 | I5: 100 | J5: 0.4992 | K5: 0.010858 | L5: 0.988449
A6: Run 4 function ACO 4start4 | B6: 86.2595 | C6: 79.8853 | D6: 3.01057 | E6: 4.88448 | F6: 61.8865 | G6: 6.37416 | H6: 10.5964 | I6: 100 | J6: 0.502265 | K6: 0.0108578 | L6: 0.959327
A7: Run 4 function ACO 4start5 | B7: 86.1488 | C7: 79.7224 | D7: 2.9266 | E7: 4.86401 | F7: 61.8957 | G7: 6.42648 | H7: 9.1432 | I7: 100 | J7: 0.50291 | K7: 0.0108581 | L7: 0.959661
A8: Run 4 function ACO 4start6 | B8: 86.3138 | C8: 79.9488 | D8: 2.97883 | E8: 4.89575 | F8: 61.9367 | G8: 6.36502 | H8: 8.0928 | I8: 100 | J8: 0.501949 | K8: 0.0108578 | L8: 0.937405
A9: Run 4 function ACO 4start7 | B9: 86.6828 | C9: 80.2131 | D9: 3.01774 | E9: 4.95412 | F9: 61.9787 | G9: 6.46973 | H9: 7.1492 | I9: 100 | J9: 0.499812 | K9: 0.010858 | L9: 0.905193
A10: Run 4 function ACO 4start8 | B10: 86.5862 | C10: 80.1453 | D10: 3.02184 | E10: 4.90088 | F10: 61.9756 | G10: 6.4409 | H10: 6.4776 | I10: 100 | J10: 0.50037 | K10: 0.010858 | L10: 0.923499
A11: Run 4 function ACO 4start9 | B11: 86.704 | C11: 80.2252 | D11: 3.02389 | E11: 4.92852 | F11: 62.0401 | G11: 6.47883 | H11: 5.936 | I11: 100 | J11: 0.49969 | K11: 0.010858 | L11: 0.986935
A12: Run 4 function ACO 4start10 | B12: 85.8871 | C12: 79.529 | D12: 2.88872 | E12: 4.82304 | F12: 61.819 | G12: 6.35813 | H12: 5.3576 | I12: 100 | J12: 0.504443 | K12: 0.010858 | L12: 0.972202
A13: Run 4 function ACO 4start11 | B13: 86.7105 | C13: 80.2149 | D13: 3.04334 | E13: 4.92648 | F13: 61.9653 | G13: 6.49561 | H13: 4.9944 | I13: 100 | J13: 0.499653 | K13: 0.0108597 | L13: 0.904935
... A151: Run Combined Run 2start49 | B151: 76.9814 | C151: 70.5557 | D151: 61.0243 | E151: 4.42471 | F151: 0 | G151: 6.42561 | H151: 0.1196 | I151: 100 | J151: 0.572963 | K151: 0.0108625 | L151: 0.905156
A152: Device 0: Tesla V100-SXM2-16GB | B152: Max thread in blocks: 1024 Total Global Memory: 16151,1 MB GPU Global Memory Usage: 0,173664 MB GPU Global Memory Hash Table: 1024 MB Max PARAMETR_SIZE in GPU Global Memory: 7482045 Shared memory per block: 49152 bytes (48 KB) Shared memory per multiprocessor: 98304 bytes (96 KB) Data size in Shared memory per block: 672 bytes (0,65625 KB) Constant Memory: 65536 bytes Parameter data size (in Constant Memory): 3360 bytes (3,28125 KB) Registers per Block: 65536 Warp Size: 32 Compute Capability: 7,0 Can Map Host Memory: Yes Clock Rate: 1530 MHz L2 Cache Size: 6291456 bytes Multiprocessor Count: 80 | C152: Max thread in blocks by axis: (1024, 1024, 64) | D152: Max blocks by axis: (2147483647, 65535, 65535) | E152: Device 1: Tesla V100-SXM2-16GB | F152: Max thread in blocks: 1024 Total Global Memory: 16151,1 MB GPU Global Memory Usage: 0,173664 MB GPU Global Memory Hash Table: 1024 MB Max PARAMETR_SIZE in GPU Global Memory: 7482045 Shared memory per block: 49152 bytes (48 KB) Shared memory per multiprocessor: 98304 bytes (96 KB) Data size in Shared memory per block: 672 bytes (0,65625 KB) Constant Memory: 65536 bytes Parameter data size (in Constant Memory): 3360 bytes (3,28125 KB) Registers per Block: 65536 Warp Size: 32 Compute Capability: 7,0 Can Map Host Memory: Yes Clock Rate: 1530 MHz L2 Cache Size: 6291456 bytes Multiprocessor Count: 80 | G152: Max thread in blocks by axis: (1024, 1024, 64) | H152: Max blocks by axis: (2147483647, 65535, 65535) | I152: Device 2: Tesla V100-SXM2-16GB | J152: Max thread in blocks: 1024 Total Global Memory: 16151,1 MB GPU Global Memory Usage: 0,173664 MB GPU Global Memory Hash Table: 1024 MB Max PARAMETR_SIZE in GPU Global Memory: 7482045 Shared memory per block: 49152 bytes (48 KB) Shared memory per multiprocessor: 98304 bytes (96 KB) Data size in Shared memory per block: 672 bytes (0,65625 KB) Constant Memory: 65536 bytes Parameter data size (in Constant Memory): 3360 bytes (3,28125 KB) Registers per Block: 65536 Warp Size: 32 Compute Capability: 7,0 Can Map Host Memory: Yes Clock Rate: 1530 MHz L2 Cache Size: 6291456 bytes Multiprocessor Count: 80 | K152: Max thread in blocks by axis: (1024, 1024, 64) | L152: Max blocks by axis: (2147483647, 65535, 65535) | M152: Device 3: Tesla V100-SXM2-16GB | N152: Max thread in blocks: 1024 Total Global Memory: 16151,1 MB GPU Global Memory Usage: 0,173664 MB GPU Global Memory Hash Table: 1024 MB Max PARAMETR_SIZE in GPU Global Memory: 7482045 Shared memory per block: 49152 bytes (48 KB) Shared memory per multiprocessor: 98304 bytes (96 KB) Data size in Shared memory per block: 672 bytes (0,65625 KB) Constant Memory: 65536 bytes Parameter data size (in Constant Memory): 3360 bytes (3,28125 KB) Registers per Block: 65536 Warp Size: 32 Compute Capability: 7,0 Can Map Host Memory: Yes Clock Rate: 1530 MHz L2 Cache Size: 6291456 bytes Multiprocessor Count: 80 | O152: Max thread in blocks by axis: (1024, 1024, 64) | P152: Max blocks by axis: (2147483647, 65535, 65535) | Q152: PARAMETR_SIZE: 84 | R152: MAX_VALUE_SIZE: 5 | S152: SET_PARAMETR_SIZE_ONE_X: 21 | T152: ANT_SIZE: 500 | U152: MAX_THREAD_CUDA: 512 | V152: NAME_FILE_GRAPH: Parametr_Graph/test84,txt | W152: KOL_ITERATION: 500 | X152: KOL_PROGREV: 5 | Y152: KOL_PROGON_STATISTICS: 50 | Z152: PARAMETR_RO: 0,999 | AA152: PARAMETR_Q: 1 | AB152: PRINT_INFORMATION: 0 | AC152: MAX_PARAMETR_VALUE_TO_MIN_OPT: 1 | AD152: OPTIMIZE: OPTIMIZE_MIN_1 | AE152: FUNCTION: SHAFFERA GO_HASH: 1 | AF152: HASH_TABLE_SIZE: 67108864 | AG152: ZERO_HASH_RESULT: -1 | AH152: ZERO_HASH: 18446744073709551615 | AI152: MAX_PROBES: 10000 | AJ152: MAX_CONST: 8192 | AK152: MAX_SHARED: 6144 | AL152: BLOCK_SIZE: 64 | AM152: BIN_SEARCH: 0 | AN152: NON_WHILE_ANT: 1
A153: Run 4 function ACO 4start0 | B153: 95.6668 | C153: 89.4189 | D153: 2.91227 | E153: 6.29865 | F153: 70.4021 | G153: 6.24788 | H153: 94.8328 | I153: 100 | J153: 0.886281 | K153: 0.0109391 | L153: 0.977733
A154: Run 4 function ACO 4start1 | B154: 95.8488 | C154: 89.4853 | D154: 2.89384 | E154: 6.37851 | F154: 70.3438 | G154: 6.36349 | H154: 94.1628 | I154: 100 | J154: 0.884597 | K154: 0.0110637 | L154: 0.977794
A155: Run 4 function ACO 4start2 | B155: 95.66 | C155: 89.3859 | D155: 2.89691 | E155: 6.34369 | F155: 70.3407 | G155: 6.27414 | H155: 93.648 | I155: 100 | J155: 0.886343 | K155: 0.0122962 | L155: 0.976932
A156: Run 4 function ACO 4start3 | B156: 96.5344 | C156: 89.6931 | D156: 2.96142 | E156: 6.4082 | F156: 70.4268 | G156: 6.84131 | H156: 92.6284 | I156: 100 | J156: 0.878315 | K156: 0.0108606 | L156: 0.97763
A157: Run 4 function ACO 4start4 | B157: 97.1434 | C157: 89.4618 | D157: 2.9266 | E157: 6.37031 | F157: 70.3356 | G157: 7.68162 | H157: 91.826 | I157: 100 | J157: 0.872808 | K157: 0.0112381 | L157: 0.977691
A158: Run 4 function ACO 4start5 | B158: 97.5862 | C158: 90.87 | D158: 3.16212 | E158: 6.6007 | F158: 70.6816 | G158: 6.71614 | H158: 90.9956 | I158: 100 | J158: 0.868848 | K158: 0.0127065 | L158: 0.97638
A159: Run 4 function ACO 4start6 | B159: 99.1062 | C159: 92.2986 | D159: 3.21845 | E159: 6.63142 | F159: 70.7656 | G159: 6.80755 | H159: 91.7392 | I159: 100 | J159: 0.855523 | K159: 0.0109377 | L159: 0.972011
A160: Run 4 function ACO 4start7 | B160: 95.6805 | C160: 89.428 | D160: 2.89896 | E160: 6.35598 | F160: 70.3602 | G160: 6.25253 | H160: 90.9444 | I160: 100 | J160: 0.886154 | K160: 0.01271 | L160: 0.981681
A161: Run 4 function ACO 4start8 | B161: 95.384 | C161: 89.1926 | D161: 2.85697 | E161: 6.34267 | F161: 70.2721 | G161: 6.19147 | H161: 89.8084 | I161: 100 | J161: 0.888908 | K161: 0.0127065 | L161: 0.970204
A162: Run 4 function ACO 4start9 | B162: 95.3682 | C162: 89.1916 | D162: 2.8498 | E162: 6.32527 | F162: 70.2988 | G162: 6.1766 | H162: 88.8724 | I162: 100 | J162: 0.889055 | K162: 0.0127066 | L162: 0.971441
A163: Run 4 function ACO 4start10 | B163: 95.2781 | C163: 89.089 | D163: 2.80475 | E163: 6.35598 | F163: 70.267 | G163: 6.18905 | H163: 87.9416 | I163: 100 | J163: 0.889896 | K163: 0.0110608 | L163: 0.967582
A164: Run 4 function ACO 4start11 | B164: 95.3392 | C164: 89.1413 | D164: 2.86209 | E164: 6.34984 | F164: 70.2629 | G164: 6.19794 | H164: 86.9752 | I164: 100 | J164: 0.889325 | K164: 0.0127065 | L164: 0.97221
... A302: Run Combined Run 2start49 | B302: 88.9054 | C302: 82.6818 | D302: 69.7487 | E302: 8.12749 | F302: 0 | G302: 6.22358 | H302: 80.0152 | I302: 100 | J302: 0.971282 | K302: 0.0127014 | L302: 0.550938
A303: Device 0: Tesla V100-SXM2-16GB | B303: Max thread in blocks: 1024 Total Global Memory: 16151,1 MB GPU Global Memory Usage: 0,343494 MB GPU Global Memory Hash Table: 1024 MB Max PARAMETR_SIZE in GPU Global Memory: 7482045 Shared memory per block: 49152 bytes (48 KB) Shared memory per multiprocessor: 98304 bytes (96 KB) Data size in Shared memory per block: 1344 bytes (1,3125 KB) Constant Memory: 65536 bytes Parameter data size (in Constant Memory): 6720 bytes (6,5625 KB) Registers per Block: 65536 Warp Size: 32 Compute Capability: 7,0 Can Map Host Memory: Yes Clock Rate: 1530 MHz L2 Cache Size: 6291456 bytes Multiprocessor Count: 80 | C303: Max thread in blocks by axis: (1024, 1024, 64) | D303: Max blocks by axis: (2147483647, 65535, 65535) | E303: Device 1: Tesla V100-SXM2-16GB | F303: Max thread in blocks: 1024 Total Global Memory: 16151,1 MB GPU Global Memory Usage: 0,343494 MB GPU Global Memory Hash Table: 1024 MB Max PARAMETR_SIZE in GPU Global Memory: 7482045 Shared memory per block: 49152 bytes (48 KB) Shared memory per multiprocessor: 98304 bytes (96 KB) Data size in Shared memory per block: 1344 bytes (1,3125 KB) Constant Memory: 65536 bytes Parameter data size (in Constant Memory): 6720 bytes (6,5625 KB) Registers per Block: 65536 Warp Size: 32 Compute Capability: 7,0 Can Map Host Memory: Yes Clock Rate: 1530 MHz L2 Cache Size: 6291456 bytes Multiprocessor Count: 80 | G303: Max thread in blocks by axis: (1024, 1024, 64) | H303: Max blocks by axis: (2147483647, 65535, 65535) | I303: Device 2: Tesla V100-SXM2-16GB | J303: Max thread in blocks: 1024 Total Global Memory: 16151,1 MB GPU Global Memory Usage: 0,343494 MB GPU Global Memory Hash Table: 1024 MB Max PARAMETR_SIZE in GPU Global Memory: 7482045 Shared memory per block: 49152 bytes (48 KB) Shared memory per multiprocessor: 98304 bytes (96 KB) Data size in Shared memory per block: 1344 bytes (1,3125 KB) Constant Memory: 65536 bytes Parameter data size (in Constant Memory): 6720 bytes (6,5625 KB) Registers per Block: 65536 Warp Size: 32 Compute Capability: 7,0 Can Map Host Memory: Yes Clock Rate: 1530 MHz L2 Cache Size: 6291456 bytes Multiprocessor Count: 80 | K303: Max thread in blocks by axis: (1024, 1024, 64) | L303: Max blocks by axis: (2147483647, 65535, 65535) | M303: Device 3: Tesla V100-SXM2-16GB | N303: Max thread in blocks: 1024 Total Global Memory: 16151,1 MB GPU Global Memory Usage: 0,343494 MB GPU Global Memory Hash Table: 1024 MB Max PARAMETR_SIZE in GPU Global Memory: 7482045 Shared memory per block: 49152 bytes (48 KB) Shared memory per multiprocessor: 98304 bytes (96 KB) Data size in Shared memory per block: 1344 bytes (1,3125 KB) Constant Memory: 65536 bytes Parameter data size (in Constant Memory): 6720 bytes (6,5625 KB) Registers per Block: 65536 Warp Size: 32 Compute Capability: 7,0 Can Map Host Memory: Yes Clock Rate: 1530 MHz L2 Cache Size: 6291456 bytes Multiprocessor Count: 80 | O303: Max thread in blocks by axis: (1024, 1024, 64) | P303: Max blocks by axis: (2147483647, 65535, 65535) | Q303: PARAMETR_SIZE: 168 | R303: MAX_VALUE_SIZE: 5 | S303: SET_PARAMETR_SIZE_ONE_X: 21 | T303: ANT_SIZE: 500 | U303: MAX_THREAD_CUDA: 512 | V303: NAME_FILE_GRAPH: Parametr_Graph/test168,txt | W303: KOL_ITERATION: 500 | X303: KOL_PROGREV: 5 | Y303: KOL_PROGON_STATISTICS: 50 | Z303: PARAMETR_RO: 0,999 | AA303: PARAMETR_Q: 1 | AB303: PRINT_INFORMATION: 0 | AC303: MAX_PARAMETR_VALUE_TO_MIN_OPT: 1 | AD303: OPTIMIZE: OPTIMIZE_MIN_1 | AE303: FUNCTION: SHAFFERA GO_HASH: 1 | AF303: HASH_TABLE_SIZE: 67108864 | AG303: ZERO_HASH_RESULT: -1 | AH303: ZERO_HASH: 18446744073709551615 | AI303: MAX_PROBES: 10000 | AJ303: MAX_CONST: 8192 | AK303: MAX_SHARED: 6144 | AL303: BLOCK_SIZE: 64 | AM303: BIN_SEARCH: 0 | AN303: NON_WHILE_ANT: 1
A304: Run 4 function ACO 4start0 | B304: 99.7703 | C304: 93.2135 | D304: 2.95425 | E304: 9.01324 | F304: 70.951 | G304: 6.55682 | H304: 99.8644 | I304: 100 | J304: 1.68099 | K304: 0.0290377 | L304: 0.980845
A305: Run 4 function ACO 4start1 | B305: 99.7121 | C305: 93.1665 | D305: 2.94094 | E305: 9.08082 | F305: 70.867 | G305: 6.54566 | H305: 99.8488 | I305: 100 | J305: 1.68197 | K305: 0.0290377 | L305: 0.980814
A306: Run 4 function ACO 4start2 | B306: 99.9717 | C306: 93.3345 | D306: 3.01774 | E306: 9.06445 | F306: 70.9101 | G306: 6.63712 | H306: 99.8028 | I306: 100 | J306: 1.6776 | K306: 0.0290377 | L306: 0.980824
A307: Run 4 function ACO 4start3 | B307: 99.6524 | C307: 93.1103 | D307: 2.95323 | E307: 9.08186 | F307: 70.8671 | G307: 6.54208 | H307: 99.7764 | I307: 100 | J307: 1.68298 | K307: 0.0290377 | L307: 0.980707
A308: Run 4 function ACO 4start4 | B308: 99.6485 | C308: 93.1183 | D308: 2.96859 | E308: 9.0798 | F308: 70.8547 | G308: 6.5302 | H308: 99.7628 | I308: 100 | J308: 1.68304 | K308: 0.0290376 | L308: 0.980803
A309: Run 4 function ACO 4start5 | B309: 100.161 | C309: 93.438 | D309: 2.98907 | E309: 9.13509 | F309: 70.9427 | G309: 6.72333 | H309: 99.758 | I309: 100 | J309: 1.67443 | K309: 0.0290377 | L309: 0.980533
A310: Run 4 function ACO 4start6 | B310: 99.734 | C310: 93.2004 | D310: 2.97781 | E310: 9.09517 | F310: 70.8578 | G310: 6.53367 | H310: 99.6944 | I310: 100 | J310: 1.6816 | K310: 0.0290376 | L310: 0.980608
A311: Run 4 function ACO 4start7 | B311: 100.018 | C311: 93.4 | D311: 3.00443 | E311: 9.15455 | F311: 70.8916 | G311: 6.61806 | H311: 99.6892 | I311: 100 | J311: 1.67682 | K311: 0.0290376 | L311: 0.980613
A312: Run 4 function ACO 4start8 | B312: 100.15 | C312: 93.5045 | D312: 2.99726 | E312: 9.16377 | F312: 70.9336 | G312: 6.64578 | H312: 99.6608 | I312: 100 | J312: 1.67461 | K312: 0.0290377 | L312: 0.980844
A313: Run 4 function ACO 4start9 | B313: 99.7591 | C313: 93.182 | D313: 2.96347 | E313: 9.12998 | F313: 70.8947 | G313: 6.57715 | H313: 99.6504 | I313: 100 | J313: 1.68118 | K313: 0.0290377 | L313: 0.980815
A314: Run 4 function ACO 4start10 | B314: 99.6574 | C314: 93.1378 | D314: 2.93172 | E314: 9.11667 | F314: 70.8444 | G314: 6.51965 | H314: 99.6224 | I314: 100 | J314: 1.68289 | K314: 0.0290377 | L314: 0.980283
...

Sheet itog all
E1: supercomput global | F1: supercomputing not const | G1: supercomput non while
E2: 42 | F2: =E2*2 -> 84
B3: 1 | D3: 50 | E3: 0 | F3: 49
B4: 42clangOMP31 | D4: 0 | E4: 2
A5: 0 | B5: 1 | C5: 42 | D5: =OFFSET(Лист1!$A$1,$B$3+($B5-1)*$D$3+$A5,D$4) -> Run 4 function ACO 4start0 | E5: =AVERAGE(OFFSET(Лист1!$A$1,$B$3+($B5-1)*$D$3+$E$3+$A5,E$4):OFFSET(Лист1!$A$1,$B$3+($B5-1)*$D$3+$E$3+$F$3+$A5,E$4)) -> 80.267238 | F5: =AVERAGE(OFFSET(Лист2!$A$1,$B$3+($B5-1)*$D$3+$E$3+$A5,E$4):OFFSET(Лист2!$A$1,$B$3+($B5-1)*$D$3+$E$3+$F$3+$A5,E$4)) -> 81.132812 | G5: =AVERAGE(OFFSET(Лист3!$A$1,$B$3+($B5-1)*$D$3+$E$3+$A5,E$4):OFFSET(Лист3!$A$1,$B$3+($B5-1)*$D$3+$E$3+$F$3+$A5,E$4)) -> 79.806714
B6: 2 | D6: =OFFSET(Лист1!$A$1,$B$3+($B6-1)*$D$3+$A5,D$4) -> Run Original ACO 3start0 | E6: =AVERAGE(OFFSET(Лист1!$A$1,$B$3+($B6-1)*$D$3+$E$3+$A5,E$4):OFFSET(Лист1!$A$1,$B$3+($B6-1)*$D$3+$E$3+$F$3+$A5,E$4)) -> 78.243826 | F6: =AVERAGE(OFFSET(Лист2!$A$1,$B$3+($B6-1)*$D$3+$E$3+$A5,E$4):OFFSET(Лист2!$A$1,$B$3+($B6-1)*$D$3+$E$3+$F$3+$A5,E$4)) -> 78.421454 | G6: =AVERAGE(OFFSET(Лист3!$A$1,$B$3+($B6-1)*$D$3+$E$3+$A5,E$4):OFFSET(Лист3!$A$1,$B$3+($B6-1)*$D$3+$E$3+$F$3+$A5,E$4)) -> 77.271158
B7: 3 | D7: =OFFSET(Лист1!$A$1,$B$3+($B7-1)*$D$3+$A5,D$4) -> Run Combined Run 2start0 | E7: =AVERAGE(OFFSET(Лист1!$A$1,$B$3+($B7-1)*$D$3+$E$3+$A5,E$4):OFFSET(Лист1!$A$1,$B$3+($B7-1)*$D$3+$E$3+$F$3+$A5,E$4)) -> 72.09867 | F7: =AVERAGE(OFFSET(Лист2!$A$1,$B$3+($B7-1)*$D$3+$E$3+$A5,E$4):OFFSET(Лист2!$A$1,$B$3+($B7-1)*$D$3+$E$3+$F$3+$A5,E$4)) -> 71.947644 | G7: =AVERAGE(OFFSET(Лист3!$A$1,$B$3+($B7-1)*$D$3+$E$3+$A5,E$4):OFFSET(Лист3!$A$1,$B$3+($B7-1)*$D$3+$E$3+$F$3+$A5,E$4)) -> 70.539358
A8: 1 | B8: 4 | C8: =C5*2 -> 84 | D8: =OFFSET(Лист1!$A$1,$B$3+($B8-1)*$D$3+$A8,D$4) -> Run 4 function ACO 4start0 | E8: =AVERAGE(OFFSET(Лист1!$A$1,$B$3+($B8-1)*$D$3+$E$3+$A8,E$4):OFFSET(Лист1!$A$1,$B$3+($B8-1)*$D$3+$E$3+$F$3+$A8,E$4)) -> 88.560004 | F8: =AVERAGE(OFFSET(Лист2!$A$1,$B$3+($B8-1)*$D$3+$E$3+$A8,E$4):OFFSET(Лист2!$A$1,$B$3+($B8-1)*$D$3+$E$3+$F$3+$A8,E$4)) -> 88.485404 | G8: =AVERAGE(OFFSET(Лист3!$A$1,$B$3+($B8-1)*$D$3+$E$3+$A8,E$4):OFFSET(Лист3!$A$1,$B$3+($B8-1)*$D$3+$E$3+$F$3+$A8,E$4)) -> 89.40883
A9: 2 | B9: 5 | C9: 2 | D9: =OFFSET(Лист1!$A$1,$B$3+($B9-1)*$D$3+$A8,D$4) -> Run Original ACO 3start0 | E9: =AVERAGE(OFFSET(Лист1!$A$1,$B$3+($B9-1)*$D$3+$E$3+$A8,E$4):OFFSET(Лист1!$A$1,$B$3+($B9-1)*$D$3+$E$3+$F$3+$A8,E$4)) -> 87.01521 | F9: =AVERAGE(OFFSET(Лист2!$A$1,$B$3+($B9-1)*$D$3+$E$3+$A8,E$4):OFFSET(Лист2!$A$1,$B$3+($B9-1)*$D$3+$E$3+$F$3+$A8,E$4)) -> 87.780558 | G9: =AVERAGE(OFFSET(Лист3!$A$1,$B$3+($B9-1)*$D$3+$E$3+$A8,E$4):OFFSET(Лист3!$A$1,$B$3+($B9-1)*$D$3+$E$3+$F$3+$A8,E$4)) -> 88.461338
B10: 6 | D10: =OFFSET(Лист1!$A$1,$B$3+($B10-1)*$D$3+$A8,D$4) -> Run Combined Run 2start0 | E10: =AVERAGE(OFFSET(Лист1!$A$1,$B$3+($B10-1)*$D$3+$E$3+$A8,E$4):OFFSET(Лист1!$A$1,$B$3+($B10-1)*$D$3+$E$3+$F$3+$A8,E$4)) -> 80.88057 | F10: =AVERAGE(OFFSET(Лист2!$A$1,$B$3+($B10-1)*$D$3+$E$3+$A8,E$4):OFFSET(Лист2!$A$1,$B$3+($B10-1)*$D$3+$E$3+$F$3+$A8,E$4)) -> 81.886832 | G10: =AVERAGE(OFFSET(Лист3!$A$1,$B$3+($B10-1)*$D$3+$E$3+$A8,E$4):OFFSET(Лист3!$A$1,$B$3+($B10-1)*$D$3+$E$3+$F$3+$A8,E$4)) -> 82.24686
A11: 2 | B11: 7 | C11: =C8*2 -> 168 | D11: =OFFSET(Лист1!$A$1,$B$3+($B11-1)*$D$3+$A11,D$4) -> Run 4 function ACO 4start0 | E11: =AVERAGE(OFFSET(Лист1!$A$1,$B$3+($B11-1)*$D$3+$E$3+$A11,E$4):OFFSET(Лист1!$A$1,$B$3+($B11-1)*$D$3+$E$3+$F$3+$A11,E$4)) -> 91.111314 | F11: =AVERAGE(OFFSET(Лист2!$A$1,$B$3+($B11-1)*$D$3+$E$3+$A11,E$4):OFFSET(Лист2!$A$1,$B$3+($B11-1)*$D$3+$E$3+$F$3+$A11,E$4)) -> 91.473214 | G11: =AVERAGE(OFFSET(Лист3!$A$1,$B$3+($B11-1)*$D$3+$E$3+$A11,E$4):OFFSET(Лист3!$A$1,$B$3+($B11-1)*$D$3+$E$3+$F$3+$A11,E$4)) -> 93.512702
B12: 8 | C12: 3 | D12: =OFFSET(Лист1!$A$1,$B$3+($B12-1)*$D$3+$A11,D$4) -> Run Original ACO 3start0 | E12: =AVERAGE(OFFSET(Лист1!$A$1,$B$3+($B12-1)*$D$3+$E$3+$A11,E$4):OFFSET(Лист1!$A$1,$B$3+($B12-1)*$D$3+$E$3+$F$3+$A11,E$4)) -> 90.012796 | F12: =AVERAGE(OFFSET(Лист2!$A$1,$B$3+($B12-1)*$D$3+$E$3+$A11,E$4):OFFSET(Лист2!$A$1,$B$3+($B12-1)*$D$3+$E$3+$F$3+$A11,E$4)) -> 90.680294 | G12: =AVERAGE(OFFSET(Лист3!$A$1,$B$3+($B12-1)*$D$3+$E$3+$A11,E$4):OFFSET(Лист3!$A$1,$B$3+($B12-1)*$D$3+$E$3+$F$3+$A11,E$4)) -> 92.884518
