Workbook

Sheet 42clangOMP31
A1: Max threads OMP : 12 OpenMP version: 201107 :OpenMP 3,1 (2011) supported
A2: PARAMETR_SIZE: 42 | B2: PARAMETR_SIZE_ONE_X: 21 | C2: MAX_VALUE_SIZE: 5 | D2: NAME_FILE_GRAPH: Parametr_Graph/test42,txt | E2: ANT_SIZE: 500 | F2: KOL_ITERATION: 500 | G2: KOL_PROGON_STATISTICS: 50 | H2: PARAMETR_Q: 1 | I2: PARAMETR_RO: 0,999 | J2: TYPE_ACO: 1 | K2: ACOCCyN_KOL_ITERATION: 50, MAX_PARAMETR_VALUE_TO_MIN_OPT: 1, HASH_TABLE_SIZE: 67108864, MAX_PROBES: 10000, MAX_THREAD_CUDA: 512, CPU_RANDOM: 0, KOL_THREAD_CPU_ANT: 12, CONST_RANDOM: 100000, MAX_CONST: 8000, OPTIMIZE: OPTIMIZE_MAX | L2: FUNCTION: GO_ALG_MINMAX: 1(1, 1000)
A3: Time non CUDA_time | B3: 332.093 | C3: 242.681 | D3: 242.662 | E3: 242.442 | F3: 5.7892 | G3: 108.435 | H3: 20.7169 | I3: 15.1636 | J3: 57.251 | K3: 117.409 | L3: 1.74518e-07 | M3: 724.704 | N3: 0
A4: Time non CUDA_time | B4: 347.295 | C4: 254.437 | D4: 254.417 | E4: 254.19 | F4: 6.1156 | G4: 114.765 | H4: 21.2956 | I4: 16.328 | J4: 61.3861 | K4: 122.321 | L4: 1.32572e-05 | M4: 724.704 | N4: 0
A5: Time non CUDA_time | B5: 344.517 | C5: 254.989 | D5: 254.969 | E5: 254.735 | F5: 6.0924 | G5: 113.982 | H5: 21.3584 | I5: 15.4761 | J5: 61.8081 | K5: 123.263 | L5: 8.16369e-08 | M5: 724.704 | N5: 0
A6: Time non CUDA_time | B6: 329.173 | C6: 244.339 | D6: 244.321 | E6: 244.106 | F6: 5.9917 | G6: 108.147 | H6: 21.3265 | I6: 15.2165 | J6: 56.0935 | K6: 118.992 | L6: 2.5658e-08 | M6: 724.703 | N6: 0
A7: Time non CUDA_time | B7: 345.865 | C7: 252.376 | D7: 252.358 | E7: 252.134 | F7: 7.2257 | G7: 112.526 | H7: 21.2631 | I7: 15.6848 | J7: 59.9079 | K7: 121.142 | L7: 3.83913e-08 | M7: 724.704 | N7: 0
A8: Time non CUDA_time | B8: 339.283 | C8: 249.559 | D8: 249.539 | E8: 249.309 | F8: 5.7838 | G8: 112.462 | H8: 21.2141 | I8: 15.6529 | J8: 59.2914 | K8: 118.986 | L8: 1.45714e-08 | M8: 724.704 | N8: 0
A9: Time non CUDA_time | B9: 332.127 | C9: 242.676 | D9: 242.658 | E9: 242.445 | F9: 5.7431 | G9: 108.022 | H9: 21.1985 | I9: 15.2821 | J9: 56.3098 | K9: 117.93 | L9: 5.08293e-06 | M9: 724.704 | N9: 0
A10: Time non CUDA_time | B10: 340.494 | C10: 252.983 | D10: 252.957 | E10: 252.733 | F10: 6.2984 | G10: 113.999 | H10: 21.5591 | I10: 16.7554 | J10: 60.2362 | K10: 121.28 | L10: 1.30741e-06 | M10: 724.704 | N10: 0
A11: Time non CUDA_time | B11: 341.411 | C11: 251.933 | D11: 251.909 | E11: 251.673 | F11: 5.8656 | G11: 114.424 | H11: 20.7445 | I11: 15.6283 | J11: 62.5974 | K11: 120.345 | L11: 7.97349e-08 | M11: 724.704 | N11: 0
A12: Time non CUDA_time | B12: 339.79 | C12: 249.083 | D12: 249.061 | E12: 248.847 | F12: 5.8868 | G12: 112.167 | H12: 21.2291 | I12: 15.4996 | J12: 59.9904 | K12: 119.828 | L12: 1.19711e-07 | M12: 724.704 | N12: 0
A13: Time non CUDA_time | B13: 342.096 | C13: 251.711 | D13: 251.691 | E13: 251.462 | F13: 5.9338 | G13: 113.166 | H13: 21.115 | I13: 15.4124 | J13: 60.7044 | K13: 120.841 | L13: 3.12848e-06 | M13: 724.704 | N13: 0
A14: Time non CUDA_time | B14: 342.285 | C14: 251.554 | D14: 251.536 | E14: 251.306 | F14: 5.9084 | G14: 114.565 | H14: 22.2216 | I14: 17.0115 | J14: 60.1212 | K14: 120.031 | L14: 6.84744e-07 | M14: 724.704 | N14: 0
... A57: Time non CUDA_time | B57: 335.368 | C57: 245.214 | D57: 245.196 | E57: 244.977 | F57: 5.8934 | G57: 110.106 | H57: 21.0585 | I57: 15.3474 | J57: 58.2586 | K57: 117.986 | L57: 4.09695e-10 | M57: 724.704 | N57: 0
A58: Time non CUDA_time: | B58: 17267.304 | C58: sec
A59: Time non CUDA | B59: 268.933 | C59: 0 | D59: 0 | E59: 0 | F59: 0 | G59: 0 | H59: 0 | I59: 0 | J59: 0 | K59: 9.76062e-07 | L59: 724.704 | M59: 0
A60: Time non CUDA | B60: 265.948 | C60: 0 | D60: 0 | E60: 0 | F60: 0 | G60: 0 | H60: 0 | I60: 0 | J60: 0 | K60: 7.63268e-06 | L60: 724.704 | M60: 0
A61: Time non CUDA | B61: 273.392 | C61: 0 | D61: 0 | E61: 0 | F61: 0 | G61: 0 | H61: 0 | I61: 0 | J61: 0 | K61: 1.35105e-05 | L61: 724.704 | M61: 0
A62: Time non CUDA | B62: 282.192 | C62: 0 | D62: 0 | E62: 0 | F62: 0 | G62: 0 | H62: 0 | I62: 0 | J62: 0 | K62: 3.70315e-06 | L62: 724.704 | M62: 0
A63: Time non CUDA | B63: 264.56 | C63: 0 | D63: 0 | E63: 0 | F63: 0 | G63: 0 | H63: 0 | I63: 0 | J63: 0 | K63: 4.9561e-06 | L63: 724.704 | M63: 0
A64: Time non CUDA | B64: 261.446 | C64: 0 | D64: 0 | E64: 0 | F64: 0 | G64: 0 | H64: 0 | I64: 0 | J64: 0 | K64: 8.24945e-06 | L64: 724.702 | M64: 0
A65: Time non CUDA | B65: 271.258 | C65: 0 | D65: 0 | E65: 0 | F65: 0 | G65: 0 | H65: 0 | I65: 0 | J65: 0 | K65: 1.04223e-06 | L65: 724.701 | M65: 0
A66: Time non CUDA | B66: 267.984 | C66: 0 | D66: 0 | E66: 0 | F66: 0 | G66: 0 | H66: 0 | I66: 0 | J66: 0 | K66: 6.93993e-07 | L66: 724.704 | M66: 0
A67: Time non CUDA | B67: 268.026 | C67: 0 | D67: 0 | E67: 0 | F67: 0 | G67: 0 | H67: 0 | I67: 0 | J67: 0 | K67: 3.02566e-05 | L67: 724.704 | M67: 0
A68: Time non CUDA | B68: 275.76 | C68: 0 | D68: 0 | E68: 0 | F68: 0 | G68: 0 | H68: 0 | I68: 0 | J68: 0 | K68: 8.7522e-06 | L68: 724.704 | M68: 0
A69: Time non CUDA | B69: 266.981 | C69: 0 | D69: 0 | E69: 0 | F69: 0 | G69: 0 | H69: 0 | I69: 0 | J69: 0 | K69: 4.99724e-07 | L69: 724.703 | M69: 0
A70: Time non CUDA | B70: 269.43 | C70: 0 | D70: 0 | E70: 0 | F70: 0 | G70: 0 | H70: 0 | I70: 0 | J70: 0 | K70: 9.27797e-07 | L70: 724.704 | M70: 0
... A113: Time non CUDA | B113: 272.982 | C113: 0 | D113: 0 | E113: 0 | F113: 0 | G113: 0 | H113: 0 | I113: 0 | J113: 0 | K113: 3.87342e-09 | L113: 724.704 | M113: 0
A114: Time non CUDA: | B114: 13714.558 | C114: sec
A115: Time non CUDA non hash: | B115: 146.513 | C115: 146.347 | D115: 146.331 | E115: 146.111 | F115: 5.9177 | G115: 0 | H115: 20.6733 | I115: 0 | J115: 1.83465e-06 | K115: 724.704 | L115: 0
A116: Time non CUDA non hash: | B116: 148.409 | C116: 148.231 | D116: 148.215 | E116: 147.992 | F116: 6.1586 | G116: 0 | H116: 21.2904 | I116: 0 | J116: 3.29209e-07 | K116: 724.702 | L116: 0
A117: Time non CUDA non hash: | B117: 147.297 | C117: 147.116 | D117: 147.099 | E117: 146.879 | F117: 6.1071 | G117: 0 | H117: 21.0238 | I117: 0 | J117: 5.28367e-06 | K117: 724.704 | L117: 0
A118: Time non CUDA non hash: | B118: 152.485 | C118: 152.306 | D118: 152.29 | E118: 152.061 | F118: 6.396 | G118: 0 | H118: 21.3825 | I118: 0 | J118: 4.99644e-06 | K118: 724.704 | L118: 0
A119: Time non CUDA non hash: | B119: 147.441 | C119: 147.263 | D119: 147.246 | E119: 147.041 | F119: 6.6556 | G119: 0 | H119: 21.2951 | I119: 0 | J119: 9.53693e-08 | K119: 724.704 | L119: 0
A120: Time non CUDA non hash: | B120: 149.809 | C120: 149.627 | D120: 149.609 | E120: 149.361 | F120: 6.0512 | G120: 0 | H120: 21.3806 | I120: 0 | J120: 3.68981e-09 | K120: 724.704 | L120: 0
A121: Time non CUDA non hash: | B121: 147.937 | C121: 147.755 | D121: 147.739 | E121: 147.515 | F121: 5.908 | G121: 0 | H121: 20.7725 | I121: 0 | J121: 5.11364e-09 | K121: 724.704 | L121: 0
A122: Time non CUDA non hash: | B122: 146.92 | C122: 146.758 | D122: 146.741 | E122: 146.521 | F122: 5.8048 | G122: 0 | H122: 21.5332 | I122: 0 | J122: 1.70158e-06 | K122: 724.704 | L122: 0
A123: Time non CUDA non hash: | B123: 146.696 | C123: 146.537 | D123: 146.519 | E123: 146.178 | F123: 6.4202 | G123: 0 | H123: 20.8858 | I123: 0 | J123: 4.00512e-06 | K123: 724.704 | L123: 0
A124: Time non CUDA non hash: | B124: 146.657 | C124: 146.474 | D124: 146.458 | E124: 146.233 | F124: 6.1048 | G124: 0 | H124: 20.5786 | I124: 0 | J124: 3.72701e-07 | K124: 724.704 | L124: 0
...

Sheet 42clangOMP40
A1: Max threads OMP : 12 OpenMP version: 201307 :OpenMP 4,0 (2013) active
A2: PARAMETR_SIZE: 42 | B2: PARAMETR_SIZE_ONE_X: 21 | C2: MAX_VALUE_SIZE: 5 | D2: NAME_FILE_GRAPH: Parametr_Graph/test42,txt | E2: ANT_SIZE: 500 | F2: KOL_ITERATION: 500 | G2: KOL_PROGON_STATISTICS: 50 | H2: PARAMETR_Q: 1 | I2: PARAMETR_RO: 0,999 | J2: TYPE_ACO: 1 | K2: ACOCCyN_KOL_ITERATION: 50, MAX_PARAMETR_VALUE_TO_MIN_OPT: 1, HASH_TABLE_SIZE: 67108864, MAX_PROBES: 10000, MAX_THREAD_CUDA: 512, CPU_RANDOM: 0, KOL_THREAD_CPU_ANT: 12, CONST_RANDOM: 100000, MAX_CONST: 8000, OPTIMIZE: OPTIMIZE_MAX | L2: FUNCTION: GO_ALG_MINMAX: 1(1, 1000)
A3: Time non CUDA_time | B3: 344.354 | C3: 245.838 | D3: 245.82 | E3: 245.557 | F3: 6.2086 | G3: 111.327 | H3: 21.0149 | I3: 15.3854 | J3: 59.5245 | K3: 117.155 | L3: 1.03237e-05 | M3: 724.704 | N3: 0
A4: Time non CUDA_time | B4: 339.246 | C4: 245 | D4: 244.978 | E4: 244.714 | F4: 5.9969 | G4: 110.473 | H4: 20.8164 | I4: 15.3361 | J4: 58.9507 | K4: 117.226 | L4: 3.7087e-06 | M4: 724.704 | N4: 0
A5: Time non CUDA_time | B5: 333.206 | C5: 241.549 | D5: 241.529 | E5: 241.261 | F5: 6.054 | G5: 108.998 | H5: 20.4726 | I5: 15.1467 | J5: 58.2682 | K5: 115.538 | L5: 6.85364e-06 | M5: 724.704 | N5: 0
A6: Time non CUDA_time | B6: 342.458 | C6: 242.211 | D6: 242.192 | E6: 241.932 | F6: 5.9621 | G6: 109.225 | H6: 20.6205 | I6: 15.1325 | J6: 58.198 | K6: 115.982 | L6: 5.57773e-08 | M6: 724.704 | N6: 0
A7: Time non CUDA_time | B7: 334.225 | C7: 246.971 | D7: 246.952 | E7: 246.671 | F7: 6.079 | G7: 111.996 | H7: 21.1004 | I7: 15.5252 | J7: 59.7981 | K7: 117.636 | L7: 1.53084e-06 | M7: 724.704 | N7: 0
A8: Time non CUDA_time | B8: 348.038 | C8: 246.184 | D8: 246.163 | E8: 245.89 | F8: 6.0068 | G8: 111.78 | H8: 20.7809 | I8: 15.3024 | J8: 60.3969 | K8: 117.239 | L8: 8.64583e-07 | M8: 724.704 | N8: 0
A9: Time non CUDA_time | B9: 330.002 | C9: 243.574 | D9: 243.554 | E9: 243.294 | F9: 6.0844 | G9: 110.569 | H9: 20.6494 | I9: 15.1982 | J9: 59.5196 | K9: 115.906 | L9: 2.3392e-06 | M9: 724.704 | N9: 0
A10: Time non CUDA_time | B10: 343 | C10: 246.373 | D10: 246.354 | E10: 246.079 | F10: 6.0274 | G10: 112.314 | H10: 20.7273 | I10: 15.3303 | J10: 60.8806 | K10: 116.841 | L10: 1.63453e-06 | M10: 724.704 | N10: 0
A11: Time non CUDA_time | B11: 334.266 | C11: 241.521 | D11: 241.501 | E11: 241.236 | F11: 6.0075 | G11: 108.308 | H11: 20.6128 | I11: 15.1527 | J11: 57.301 | K11: 116.017 | L11: 6.81695e-07 | M11: 724.704 | N11: 0
A12: Time non CUDA_time | B12: 338.172 | C12: 244.028 | D12: 244.008 | E12: 243.732 | F12: 5.9514 | G12: 110.925 | H12: 20.4576 | I12: 15.1174 | J12: 60.2362 | K12: 116.058 | L12: 2.84063e-06 | M12: 724.704 | N12: 0
A13: Time non CUDA_time | B13: 356.291 | C13: 249.661 | D13: 249.64 | E13: 249.359 | F13: 6.1479 | G13: 113.823 | H13: 21.2299 | I13: 15.6872 | J13: 61.3931 | K13: 118.34 | L13: 6.5833e-06 | M13: 724.704 | N13: 0
A14: Time non CUDA_time | B14: 341.016 | C14: 252.18 | D14: 252.157 | E14: 251.873 | F14: 6.1721 | G14: 114.288 | H14: 21.7242 | I14: 15.6427 | J14: 61.2483 | K14: 120.295 | L14: 2.62946e-07 | M14: 724.702 | N14: 0
... A57: Time non CUDA_time | B57: 335.782 | C57: 244.692 | D57: 244.67 | E57: 244.403 | F57: 5.9088 | G57: 110.809 | H57: 20.8513 | I57: 15.4528 | J57: 59.234 | K57: 116.838 | L57: 5.73212e-07 | M57: 724.704 | N57: 0
A58: Time non CUDA_time: | B58: 17249.48 | C58: sec
A59: Time non CUDA | B59: 268.166 | C59: 0 | D59: 0 | E59: 0 | F59: 0 | G59: 0 | H59: 0 | I59: 0 | J59: 0 | K59: 7.98033e-06 | L59: 724.704 | M59: 0
A60: Time non CUDA | B60: 277.118 | C60: 0 | D60: 0 | E60: 0 | F60: 0 | G60: 0 | H60: 0 | I60: 0 | J60: 0 | K60: 9.65853e-06 | L60: 724.704 | M60: 0
A61: Time non CUDA | B61: 271.205 | C61: 0 | D61: 0 | E61: 0 | F61: 0 | G61: 0 | H61: 0 | I61: 0 | J61: 0 | K61: 1.37589e-07 | L61: 724.704 | M61: 0
A62: Time non CUDA | B62: 268.918 | C62: 0 | D62: 0 | E62: 0 | F62: 0 | G62: 0 | H62: 0 | I62: 0 | J62: 0 | K62: 4.6981e-07 | L62: 724.704 | M62: 0
A63: Time non CUDA | B63: 268.955 | C63: 0 | D63: 0 | E63: 0 | F63: 0 | G63: 0 | H63: 0 | I63: 0 | J63: 0 | K63: 5.61502e-08 | L63: 724.704 | M63: 0
A64: Time non CUDA | B64: 272.325 | C64: 0 | D64: 0 | E64: 0 | F64: 0 | G64: 0 | H64: 0 | I64: 0 | J64: 0 | K64: 7.55103e-07 | L64: 724.704 | M64: 0
A65: Time non CUDA | B65: 275.039 | C65: 0 | D65: 0 | E65: 0 | F65: 0 | G65: 0 | H65: 0 | I65: 0 | J65: 0 | K65: 8.376e-06 | L65: 724.702 | M65: 0
A66: Time non CUDA | B66: 265.087 | C66: 0 | D66: 0 | E66: 0 | F66: 0 | G66: 0 | H66: 0 | I66: 0 | J66: 0 | K66: 3.81533e-09 | L66: 724.702 | M66: 0
A67: Time non CUDA | B67: 268.833 | C67: 0 | D67: 0 | E67: 0 | F67: 0 | G67: 0 | H67: 0 | I67: 0 | J67: 0 | K67: 6.6478e-10 | L67: 724.704 | M67: 0
A68: Time non CUDA | B68: 270.341 | C68: 0 | D68: 0 | E68: 0 | F68: 0 | G68: 0 | H68: 0 | I68: 0 | J68: 0 | K68: 7.35076e-09 | L68: 724.703 | M68: 0
A69: Time non CUDA | B69: 274.479 | C69: 0 | D69: 0 | E69: 0 | F69: 0 | G69: 0 | H69: 0 | I69: 0 | J69: 0 | K69: 9.39576e-06 | L69: 724.704 | M69: 0
A70: Time non CUDA | B70: 271.378 | C70: 0 | D70: 0 | E70: 0 | F70: 0 | G70: 0 | H70: 0 | I70: 0 | J70: 0 | K70: 1.67602e-06 | L70: 724.704 | M70: 0
... A113: Time non CUDA | B113: 273.582 | C113: 0 | D113: 0 | E113: 0 | F113: 0 | G113: 0 | H113: 0 | I113: 0 | J113: 0 | K113: 4.05377e-06 | L113: 724.704 | M113: 0
A114: Time non CUDA: | B114: 13971.625 | C114: sec
A115: Time non CUDA non hash: | B115: 151.21 | C115: 150.984 | D115: 150.967 | E115: 150.783 | F115: 7.903 | G115: 0 | H115: 21.4203 | I115: 0 | J115: 2.50923e-05 | K115: 724.703 | L115: 0
A116: Time non CUDA non hash: | B116: 145.424 | C116: 145.272 | D116: 145.254 | E116: 145.009 | F116: 5.8928 | G116: 0 | H116: 21.2618 | I116: 0 | J116: 2.60989e-06 | K116: 724.704 | L116: 0
A117: Time non CUDA non hash: | B117: 143.844 | C117: 143.684 | D117: 143.668 | E117: 143.452 | F117: 5.9683 | G117: 0 | H117: 20.9263 | I117: 0 | J117: 7.83243e-08 | K117: 724.704 | L117: 0
A118: Time non CUDA non hash: | B118: 146.233 | C118: 146.075 | D118: 146.058 | E118: 145.841 | F118: 5.9023 | G118: 0 | H118: 21.0004 | I118: 0 | J118: 7.69182e-07 | K118: 724.704 | L118: 0
A119: Time non CUDA non hash: | B119: 144.883 | C119: 144.723 | D119: 144.707 | E119: 144.496 | F119: 5.8079 | G119: 0 | H119: 20.8298 | I119: 0 | J119: 9.05241e-07 | K119: 724.704 | L119: 0
A120: Time non CUDA non hash: | B120: 144.819 | C120: 144.661 | D120: 144.643 | E120: 144.432 | F120: 6.2416 | G120: 0 | H120: 20.9419 | I120: 0 | J120: 1.90093e-07 | K120: 724.704 | L120: 0
A121: Time non CUDA non hash: | B121: 145.605 | C121: 145.445 | D121: 145.429 | E121: 145.217 | F121: 5.7764 | G121: 0 | H121: 20.8895 | I121: 0 | J121: 1.6556e-07 | K121: 724.704 | L121: 0
A122: Time non CUDA non hash: | B122: 150.793 | C122: 150.633 | D122: 150.614 | E122: 150.358 | F122: 6.0052 | G122: 0 | H122: 21.7897 | I122: 0 | J122: 3.417e-05 | K122: 724.704 | L122: 0
A123: Time non CUDA non hash: | B123: 144.941 | C123: 144.789 | D123: 144.775 | E123: 144.562 | F123: 5.7748 | G123: 0 | H123: 20.7543 | I123: 0 | J123: 9.24172e-07 | K123: 724.703 | L123: 0
A124: Time non CUDA non hash: | B124: 149.202 | C124: 149.04 | D124: 149.021 | E124: 148.795 | F124: 5.9158 | G124: 0 | H124: 21.8839 | I124: 0 | J124: 8.88907e-06 | K124: 724.704 | L124: 0
...

Sheet 42clangOMP45
A1: Max threads OMP : 12 OpenMP version: 201511 :OpenMP 4,5 (2015) optimal
A2: PARAMETR_SIZE: 42 | B2: PARAMETR_SIZE_ONE_X: 21 | C2: MAX_VALUE_SIZE: 5 | D2: NAME_FILE_GRAPH: Parametr_Graph/test42,txt | E2: ANT_SIZE: 500 | F2: KOL_ITERATION: 500 | G2: KOL_PROGON_STATISTICS: 50 | H2: PARAMETR_Q: 1 | I2: PARAMETR_RO: 0,999 | J2: TYPE_ACO: 1 | K2: ACOCCyN_KOL_ITERATION: 50, MAX_PARAMETR_VALUE_TO_MIN_OPT: 1, HASH_TABLE_SIZE: 67108864, MAX_PROBES: 10000, MAX_THREAD_CUDA: 512, CPU_RANDOM: 0, KOL_THREAD_CPU_ANT: 12, CONST_RANDOM: 100000, MAX_CONST: 8000, OPTIMIZE: OPTIMIZE_MAX | L2: FUNCTION: GO_ALG_MINMAX: 1(1, 1000)
A3: Time non CUDA_time | B3: 339.134 | C3: 247.385 | D3: 247.358 | E3: 247.116 | F3: 5.9101 | G3: 111.811 | H3: 21.1996 | I3: 15.3943 | J3: 59.8204 | K3: 118.38 | L3: 2.64414e-07 | M3: 724.704 | N3: 0
A4: Time non CUDA_time | B4: 337.32 | C4: 247.085 | D4: 247.065 | E4: 246.832 | F4: 5.7126 | G4: 112.072 | H4: 20.7806 | I4: 15.2477 | J4: 60.4269 | K4: 118.267 | L4: 1.87591e-07 | M4: 724.704 | N4: 0
A5: Time non CUDA_time | B5: 329.839 | C5: 242.768 | D5: 242.751 | E5: 242.494 | F5: 5.9967 | G5: 107.829 | H5: 20.9905 | I5: 15.2266 | J5: 56.2947 | K5: 117.438 | L5: 6.91405e-07 | M5: 724.704 | N5: 0
A6: Time non CUDA_time | B6: 348.87 | C6: 249.11 | D6: 249.089 | E6: 248.861 | F6: 5.881 | G6: 111.124 | H6: 21.6905 | I6: 15.5078 | J6: 58.5679 | K6: 120.708 | L6: 2.75827e-09 | M6: 724.704 | N6: 0
A7: Time non CUDA_time | B7: 339.601 | C7: 246.866 | D7: 246.847 | E7: 246.615 | F7: 5.8096 | G7: 111.745 | H7: 21.1346 | I7: 15.3651 | J7: 59.7109 | K7: 118.27 | L7: 8.17271e-08 | M7: 724.704 | N7: 0
A8: Time non CUDA_time | B8: 332.156 | C8: 244.125 | D8: 244.107 | E8: 243.877 | F8: 6.0572 | G8: 109.789 | H8: 21.3819 | I8: 15.1753 | J8: 57.748 | K8: 117.211 | L8: 3.5805e-06 | M8: 724.704 | N8: 0
A9: Time non CUDA_time | B9: 339.361 | C9: 250.881 | D9: 250.86 | E9: 250.617 | F9: 5.9765 | G9: 113.658 | H9: 21.7295 | I9: 16.0634 | J9: 60.1066 | K9: 119.454 | L9: 7.68102e-08 | M9: 724.704 | N9: 0
A10: Time non CUDA_time | B10: 342.382 | C10: 249.892 | D10: 249.87 | E10: 249.63 | F10: 5.7874 | G10: 114.721 | H10: 21.8749 | I10: 15.7133 | J10: 61.5506 | K10: 118.194 | L10: 2.91672e-06 | M10: 724.704 | N10: 0
A11: Time non CUDA_time | B11: 333.688 | C11: 244.922 | D11: 244.904 | E11: 244.675 | F11: 5.7057 | G11: 109.959 | H11: 21.4126 | I11: 15.2237 | J11: 58.1759 | K11: 117.834 | L11: 3.66536e-10 | M11: 724.704 | N11: 0
A12: Time non CUDA_time | B12: 334.933 | C12: 248.57 | D12: 248.552 | E12: 248.325 | F12: 6.0162 | G12: 110.792 | H12: 21.3666 | I12: 15.6234 | J12: 57.8615 | K12: 120.263 | L12: 1.24805e-08 | M12: 724.704 | N12: 0
A13: Time non CUDA_time | B13: 337.856 | C13: 242.859 | D13: 242.841 | E13: 242.616 | F13: 6.0327 | G13: 108.948 | H13: 20.9922 | I13: 15.3401 | J13: 57.2494 | K13: 116.611 | L13: 6.74725e-07 | M13: 724.703 | N13: 0
A14: Time non CUDA_time | B14: 328.733 | C14: 241.801 | D14: 241.782 | E14: 241.554 | F14: 5.6385 | G14: 107.411 | H14: 20.8462 | I14: 15.1043 | J14: 55.4281 | K14: 117.449 | L14: 4.31389e-08 | M14: 724.704 | N14: 0
... A57: Time non CUDA_time | B57: 335.964 | C57: 245.311 | D57: 245.293 | E57: 245.071 | F57: 5.6948 | G57: 110.468 | H57: 21.772 | I57: 15.1286 | J57: 58.1852 | K57: 118.097 | L57: 7.28611e-08 | M57: 724.704 | N57: 0
A58: Time non CUDA_time: | B58: 17068.02 | C58: sec
A59: Time non CUDA | B59: 270.595 | C59: 0 | D59: 0 | E59: 0 | F59: 0 | G59: 0 | H59: 0 | I59: 0 | J59: 0 | K59: 9.32903e-06 | L59: 724.704 | M59: 0
A60: Time non CUDA | B60: 277.714 | C60: 0 | D60: 0 | E60: 0 | F60: 0 | G60: 0 | H60: 0 | I60: 0 | J60: 0 | K60: 6.14e-07 | L60: 724.703 | M60: 0
A61: Time non CUDA | B61: 271.273 | C61: 0 | D61: 0 | E61: 0 | F61: 0 | G61: 0 | H61: 0 | I61: 0 | J61: 0 | K61: 3.97282e-06 | L61: 724.703 | M61: 0
A62: Time non CUDA | B62: 270.588 | C62: 0 | D62: 0 | E62: 0 | F62: 0 | G62: 0 | H62: 0 | I62: 0 | J62: 0 | K62: 2.72784e-07 | L62: 724.704 | M62: 0
A63: Time non CUDA | B63: 267.692 | C63: 0 | D63: 0 | E63: 0 | F63: 0 | G63: 0 | H63: 0 | I63: 0 | J63: 0 | K63: 4.02384e-06 | L63: 724.704 | M63: 0
A64: Time non CUDA | B64: 265.783 | C64: 0 | D64: 0 | E64: 0 | F64: 0 | G64: 0 | H64: 0 | I64: 0 | J64: 0 | K64: 1.3249e-07 | L64: 724.704 | M64: 0
A65: Time non CUDA | B65: 271.729 | C65: 0 | D65: 0 | E65: 0 | F65: 0 | G65: 0 | H65: 0 | I65: 0 | J65: 0 | K65: 2.95926e-08 | L65: 724.704 | M65: 0
A66: Time non CUDA | B66: 268.188 | C66: 0 | D66: 0 | E66: 0 | F66: 0 | G66: 0 | H66: 0 | I66: 0 | J66: 0 | K66: 5.3658e-07 | L66: 724.704 | M66: 0
A67: Time non CUDA | B67: 279.226 | C67: 0 | D67: 0 | E67: 0 | F67: 0 | G67: 0 | H67: 0 | I67: 0 | J67: 0 | K67: 1.40921e-07 | L67: 724.703 | M67: 0
A68: Time non CUDA | B68: 274.077 | C68: 0 | D68: 0 | E68: 0 | F68: 0 | G68: 0 | H68: 0 | I68: 0 | J68: 0 | K68: 1.06588e-07 | L68: 724.704 | M68: 0
A69: Time non CUDA | B69: 275.495 | C69: 0 | D69: 0 | E69: 0 | F69: 0 | G69: 0 | H69: 0 | I69: 0 | J69: 0 | K69: 1.7789e-06 | L69: 724.704 | M69: 0
A70: Time non CUDA | B70: 267.795 | C70: 0 | D70: 0 | E70: 0 | F70: 0 | G70: 0 | H70: 0 | I70: 0 | J70: 0 | K70: 2.90641e-06 | L70: 724.703 | M70: 0
... A113: Time non CUDA | B113: 274.772 | C113: 0 | D113: 0 | E113: 0 | F113: 0 | G113: 0 | H113: 0 | I113: 0 | J113: 0 | K113: 1.56922e-05 | L113: 724.704 | M113: 0
A114: Time non CUDA: | B114: 13837.357 | C114: sec
A115: Time non CUDA non hash: | B115: 152.606 | C115: 152.458 | D115: 152.443 | E115: 152.212 | F115: 6.3647 | G115: 0 | H115: 21.7332 | I115: 0 | J115: 7.86447e-07 | K115: 724.699 | L115: 0
A116: Time non CUDA non hash: | B116: 149.652 | C116: 149.514 | D116: 149.499 | E116: 149.271 | F116: 6.169 | G116: 0 | H116: 21.0968 | I116: 0 | J116: 2.46453e-07 | K116: 724.704 | L116: 0
A117: Time non CUDA non hash: | B117: 149.199 | C117: 149.047 | D117: 149.032 | E117: 148.805 | F117: 6.4431 | G117: 0 | H117: 21.698 | I117: 0 | J117: 1.20474e-06 | K117: 724.704 | L117: 0
A118: Time non CUDA non hash: | B118: 150.281 | C118: 150.129 | D118: 150.112 | E118: 149.882 | F118: 6.1431 | G118: 0 | H118: 21.6702 | I118: 0 | J118: 7.72739e-07 | K118: 724.704 | L118: 0
A119: Time non CUDA non hash: | B119: 150.38 | C119: 150.226 | D119: 150.208 | E119: 149.984 | F119: 6.436 | G119: 0 | H119: 21.9694 | I119: 0 | J119: 4.60507e-06 | K119: 724.704 | L119: 0
A120: Time non CUDA non hash: | B120: 150.164 | C120: 150.014 | D120: 149.998 | E120: 149.774 | F120: 6.1687 | G120: 0 | H120: 21.9969 | I120: 0 | J120: 4.78952e-07 | K120: 724.704 | L120: 0
A121: Time non CUDA non hash: | B121: 149.752 | C121: 149.619 | D121: 149.601 | E121: 149.381 | F121: 6.6781 | G121: 0 | H121: 21.4481 | I121: 0 | J121: 6.2939e-09 | K121: 724.704 | L121: 0
A122: Time non CUDA non hash: | B122: 153.344 | C122: 153.209 | D122: 153.192 | E122: 152.957 | F122: 6.9501 | G122: 0 | H122: 21.6025 | I122: 0 | J122: 1.16356e-06 | K122: 724.704 | L122: 0
A123: Time non CUDA non hash: | B123: 146.674 | C123: 146.537 | D123: 146.521 | E123: 146.299 | F123: 6.1117 | G123: 0 | H123: 21.546 | I123: 0 | J123: 1.27093e-08 | K123: 724.704 | L123: 0
A124: Time non CUDA non hash: | B124: 154.662 | C124: 154.507 | D124: 154.49 | E124: 154.256 | F124: 6.2634 | G124: 0 | H124: 23.5838 | I124: 0 | J124: 4.08318e-05 | K124: 724.704 | L124: 0
...

Sheet 42clangOMP50
A1: Max threads OMP : 12 OpenMP version: 201811 :OpenMP 5,0 (2018) active
A2: PARAMETR_SIZE: 42 | B2: PARAMETR_SIZE_ONE_X: 21 | C2: MAX_VALUE_SIZE: 5 | D2: NAME_FILE_GRAPH: Parametr_Graph/test42,txt | E2: ANT_SIZE: 500 | F2: KOL_ITERATION: 500 | G2: KOL_PROGON_STATISTICS: 50 | H2: PARAMETR_Q: 1 | I2: PARAMETR_RO: 0,999 | J2: TYPE_ACO: 1 | K2: ACOCCyN_KOL_ITERATION: 50, MAX_PARAMETR_VALUE_TO_MIN_OPT: 1, HASH_TABLE_SIZE: 67108864, MAX_PROBES: 10000, MAX_THREAD_CUDA: 512, CPU_RANDOM: 0, KOL_THREAD_CPU_ANT: 12, CONST_RANDOM: 100000, MAX_CONST: 8000, OPTIMIZE: OPTIMIZE_MAX | L2: FUNCTION: GO_ALG_MINMAX: 1(1, 1000)
A3: Time non CUDA_time | B3: 334.311 | C3: 246.947 | D3: 246.927 | E3: 246.702 | F3: 5.9837 | G3: 111.301 | H3: 21.2891 | I3: 15.5174 | J3: 58.9786 | K3: 118.525 | L3: 7.45254e-08 | M3: 724.704 | N3: 0
A4: Time non CUDA_time | B4: 343.393 | C4: 252.548 | D4: 252.53 | E4: 252.293 | F4: 5.976 | G4: 115.584 | H4: 21.183 | I4: 15.574 | J4: 63.5084 | K4: 119.867 | L4: 2.62557e-06 | M4: 724.704 | N4: 0
A5: Time non CUDA_time | B5: 361.327 | C5: 248.646 | D5: 248.62 | E5: 248.391 | F5: 5.9559 | G5: 114.474 | H5: 20.7899 | I5: 15.192 | J5: 63.1435 | K5: 117.113 | L5: 3.01223e-06 | M5: 724.704 | N5: 0
A6: Time non CUDA_time | B6: 350.489 | C6: 248.675 | D6: 248.656 | E6: 248.438 | F6: 5.8263 | G6: 112.933 | H6: 20.9987 | I6: 15.4512 | J6: 60.9226 | K6: 118.748 | L6: 2.26882e-09 | M6: 724.704 | N6: 0
A7: Time non CUDA_time | B7: 339.688 | C7: 253.479 | D7: 253.455 | E7: 253.228 | F7: 5.8032 | G7: 117.245 | H7: 20.9486 | I7: 15.6726 | J7: 65.0819 | K7: 119.1 | L7: 4.72763e-06 | M7: 724.704 | N7: 0
A8: Time non CUDA_time | B8: 340.554 | C8: 255.267 | D8: 255.241 | E8: 255.014 | F8: 5.9499 | G8: 119.335 | H8: 21.1051 | I8: 15.3185 | J8: 67.4468 | K8: 118.77 | L8: 1.38985e-06 | M8: 724.704 | N8: 0
A9: Time non CUDA_time | B9: 333.812 | C9: 250.984 | D9: 250.965 | E9: 250.74 | F9: 5.725 | G9: 116.125 | H9: 21.1653 | I9: 15.5253 | J9: 63.9935 | K9: 118.026 | L9: 7.59461e-06 | M9: 724.704 | N9: 0
A10: Time non CUDA_time | B10: 334.025 | C10: 248.689 | D10: 248.668 | E10: 248.479 | F10: 5.8966 | G10: 113.163 | H10: 21.3527 | I10: 15.2144 | J10: 61.1622 | K10: 118.659 | L10: 5.57493e-10 | M10: 724.703 | N10: 0
A11: Time non CUDA_time | B11: 341.727 | C11: 248.163 | D11: 248.143 | E11: 247.952 | F11: 5.8923 | G11: 112.282 | H11: 20.8427 | I11: 15.6869 | J11: 60.4777 | K11: 118.948 | L11: 4.69412e-08 | M11: 724.704 | N11: 0
A12: Time non CUDA_time | B12: 347.573 | C12: 243.14 | D12: 243.121 | E12: 242.891 | F12: 5.736 | G12: 108.126 | H12: 20.756 | I12: 15.3786 | J12: 56.8591 | K12: 118.095 | L12: 2.77817e-06 | M12: 724.704 | N12: 0
A13: Time non CUDA_time | B13: 331.633 | C13: 247.226 | D13: 247.207 | E13: 246.989 | F13: 5.8495 | G13: 110.513 | H13: 20.8177 | I13: 15.2661 | J13: 58.944 | K13: 119.791 | L13: 1.09306e-09 | M13: 724.704 | N13: 0
A14: Time non CUDA_time | B14: 342.138 | C14: 257.557 | D14: 257.53 | E14: 257.304 | F14: 5.9145 | G14: 121.048 | H14: 21.0117 | I14: 15.8288 | J14: 68.7359 | K14: 119.165 | L14: 4.16546e-08 | M14: 724.704 | N14: 0
... A57: Time non CUDA_time | B57: 343.707 | C57: 259.768 | D57: 259.746 | E57: 259.513 | F57: 5.7583 | G57: 121.804 | H57: 21.5377 | I57: 15.8013 | J57: 68.6914 | K57: 121.117 | L57: 3.05907e-06 | M57: 724.703 | N57: 0
A58: Time non CUDA_time: | B58: 17287.632 | C58: sec
A59: Time non CUDA | B59: 281.165 | C59: 0 | D59: 0 | E59: 0 | F59: 0 | G59: 0 | H59: 0 | I59: 0 | J59: 0 | K59: 1.98509e-06 | L59: 724.704 | M59: 0
A60: Time non CUDA | B60: 266.47 | C60: 0 | D60: 0 | E60: 0 | F60: 0 | G60: 0 | H60: 0 | I60: 0 | J60: 0 | K60: 4.38786e-07 | L60: 724.704 | M60: 0
A61: Time non CUDA | B61: 281.368 | C61: 0 | D61: 0 | E61: 0 | F61: 0 | G61: 0 | H61: 0 | I61: 0 | J61: 0 | K61: 8.8184e-06 | L61: 724.702 | M61: 0
A62: Time non CUDA | B62: 274.371 | C62: 0 | D62: 0 | E62: 0 | F62: 0 | G62: 0 | H62: 0 | I62: 0 | J62: 0 | K62: 4.19206e-06 | L62: 724.704 | M62: 0
A63: Time non CUDA | B63: 271.913 | C63: 0 | D63: 0 | E63: 0 | F63: 0 | G63: 0 | H63: 0 | I63: 0 | J63: 0 | K63: 1.13194e-06 | L63: 724.704 | M63: 0
A64: Time non CUDA | B64: 297.601 | C64: 0 | D64: 0 | E64: 0 | F64: 0 | G64: 0 | H64: 0 | I64: 0 | J64: 0 | K64: 5.07916e-07 | L64: 724.703 | M64: 0
A65: Time non CUDA | B65: 276.857 | C65: 0 | D65: 0 | E65: 0 | F65: 0 | G65: 0 | H65: 0 | I65: 0 | J65: 0 | K65: 1.20097e-08 | L65: 724.704 | M65: 0
A66: Time non CUDA | B66: 265.531 | C66: 0 | D66: 0 | E66: 0 | F66: 0 | G66: 0 | H66: 0 | I66: 0 | J66: 0 | K66: 2.03305e-06 | L66: 724.704 | M66: 0
A67: Time non CUDA | B67: 266.329 | C67: 0 | D67: 0 | E67: 0 | F67: 0 | G67: 0 | H67: 0 | I67: 0 | J67: 0 | K67: 2.74376e-07 | L67: 724.704 | M67: 0
A68: Time non CUDA | B68: 283.319 | C68: 0 | D68: 0 | E68: 0 | F68: 0 | G68: 0 | H68: 0 | I68: 0 | J68: 0 | K68: 1.06565e-05 | L68: 724.702 | M68: 0
A69: Time non CUDA | B69: 286.023 | C69: 0 | D69: 0 | E69: 0 | F69: 0 | G69: 0 | H69: 0 | I69: 0 | J69: 0 | K69: 3.62215e-07 | L69: 724.704 | M69: 0
A70: Time non CUDA | B70: 266.175 | C70: 0 | D70: 0 | E70: 0 | F70: 0 | G70: 0 | H70: 0 | I70: 0 | J70: 0 | K70: 5.36732e-08 | L70: 724.704 | M70: 0
... A113: Time non CUDA | B113: 272.919 | C113: 0 | D113: 0 | E113: 0 | F113: 0 | G113: 0 | H113: 0 | I113: 0 | J113: 0 | K113: 3.9931e-08 | L113: 724.704 | M113: 0
A114: Time non CUDA: | B114: 13842.979 | C114: sec
A115: Time non CUDA non hash: | B115: 147.991 | C115: 147.794 | D115: 147.777 | E115: 147.558 | F115: 6.0916 | G115: 0 | H115: 20.8977 | I115: 0 | J115: 5.75526e-09 | K115: 724.704 | L115: 0
A116: Time non CUDA non hash: | B116: 148.694 | C116: 148.506 | D116: 148.49 | E116: 148.26 | F116: 6.235 | G116: 0 | H116: 21.3158 | I116: 0 | J116: 1.65679e-07 | K116: 724.704 | L116: 0
A117: Time non CUDA non hash: | B117: 159.533 | C117: 159.351 | D117: 159.334 | E117: 158.958 | F117: 6.7941 | G117: 0 | H117: 22.5059 | I117: 0 | J117: 4.61381e-07 | K117: 724.704 | L117: 0
A118: Time non CUDA non hash: | B118: 146.807 | C118: 146.659 | D118: 146.642 | E118: 146.424 | F118: 6.2877 | G118: 0 | H118: 21.0469 | I118: 0 | J118: 1.26161e-07 | K118: 724.704 | L118: 0
A119: Time non CUDA non hash: | B119: 147.867 | C119: 147.714 | D119: 147.697 | E119: 147.472 | F119: 6.1306 | G119: 0 | H119: 21.5737 | I119: 0 | J119: 1.25422e-06 | K119: 724.703 | L119: 0
A120: Time non CUDA non hash: | B120: 148.127 | C120: 147.97 | D120: 147.954 | E120: 147.728 | F120: 6.2014 | G120: 0 | H120: 21.0028 | I120: 0 | J120: 7.84668e-07 | K120: 724.704 | L120: 0
A121: Time non CUDA non hash: | B121: 147.546 | C121: 147.396 | D121: 147.382 | E121: 147.161 | F121: 6.0889 | G121: 0 | H121: 21.1823 | I121: 0 | J121: 6.46551e-07 | K121: 724.704 | L121: 0
A122: Time non CUDA non hash: | B122: 157.205 | C122: 157.058 | D122: 157.04 | E122: 156.808 | F122: 6.1916 | G122: 0 | H122: 21.0446 | I122: 0 | J122: 1.18832e-07 | K122: 724.704 | L122: 0
A123: Time non CUDA non hash: | B123: 152.068 | C123: 151.908 | D123: 151.891 | E123: 151.67 | F123: 6.3756 | G123: 0 | H123: 21.5146 | I123: 0 | J123: 5.84493e-07 | K123: 724.704 | L123: 0
A124: Time non CUDA non hash: | B124: 149.655 | C124: 149.232 | D124: 149.213 | E124: 148.975 | F124: 6.3213 | G124: 0 | H124: 21.1137 | I124: 0 | J124: 5.48719e-07 | K124: 724.704 | L124: 0
...

Sheet 42clangOMP51
A1: Max threads OMP : 12 OpenMP version: 202011 :OpenMP 5,0 (2018) active
A2: PARAMETR_SIZE: 42 | B2: PARAMETR_SIZE_ONE_X: 21 | C2: MAX_VALUE_SIZE: 5 | D2: NAME_FILE_GRAPH: Parametr_Graph/test42,txt | E2: ANT_SIZE: 500 | F2: KOL_ITERATION: 500 | G2: KOL_PROGON_STATISTICS: 50 | H2: PARAMETR_Q: 1 | I2: PARAMETR_RO: 0,999 | J2: TYPE_ACO: 1 | K2: ACOCCyN_KOL_ITERATION: 50, MAX_PARAMETR_VALUE_TO_MIN_OPT: 1, HASH_TABLE_SIZE: 67108864, MAX_PROBES: 10000, MAX_THREAD_CUDA: 512, CPU_RANDOM: 0, KOL_THREAD_CPU_ANT: 12, CONST_RANDOM: 100000, MAX_CONST: 8000, OPTIMIZE: OPTIMIZE_MAX | L2: FUNCTION: GO_ALG_MINMAX: 1(1, 1000)
A3: Time non CUDA_time | B3: 339.507 | C3: 249.386 | D3: 249.364 | E3: 249.147 | F3: 5.8647 | G3: 113.169 | H3: 21.2589 | I3: 15.5663 | J3: 60.9191 | K3: 119.24 | L3: 3.44165e-08 | M3: 724.704 | N3: 0
A4: Time non CUDA_time | B4: 337.418 | C4: 247.481 | D4: 247.463 | E4: 247.249 | F4: 5.8774 | G4: 112.194 | H4: 20.5361 | I4: 15.2536 | J4: 60.8328 | K4: 118.123 | L4: 2.0298e-06 | M4: 724.704 | N4: 0
A5: Time non CUDA_time | B5: 340.568 | C5: 253.882 | D5: 253.861 | E5: 253.627 | F5: 5.8801 | G5: 114.954 | H5: 21.397 | I5: 15.9214 | J5: 61.1267 | K5: 121.649 | L5: 2.81415e-08 | M5: 724.704 | N5: 0
A6: Time non CUDA_time | B6: 359.387 | C6: 248.355 | D6: 248.332 | E6: 248.108 | F6: 5.9197 | G6: 113.978 | H6: 21.0567 | I6: 15.2971 | J6: 62.3317 | K6: 117.36 | L6: 7.03127e-06 | M6: 724.703 | N6: 0
A7: Time non CUDA_time | B7: 339.617 | C7: 247.149 | D7: 247.13 | E7: 246.918 | F7: 6.1549 | G7: 110.322 | H7: 21.4648 | I7: 15.466 | J7: 58.271 | K7: 119.747 | L7: 6.98391e-06 | M7: 724.704 | N7: 0
A8: Time non CUDA_time | B8: 338.323 | C8: 250.484 | D8: 250.465 | E8: 250.18 | F8: 6.0235 | G8: 112.387 | H8: 21.3018 | I8: 15.5149 | J8: 59.9887 | K8: 120.641 | L8: 5.95837e-05 | M8: 724.704 | N8: 0
A9: Time non CUDA_time | B9: 337.224 | C9: 252.784 | D9: 252.76 | E9: 252.518 | F9: 5.8278 | G9: 116.024 | H9: 21.2862 | I9: 15.3219 | J9: 63.9981 | K9: 119.754 | L9: 1.05552e-08 | M9: 724.703 | N9: 0
A10: Time non CUDA_time | B10: 331.753 | C10: 245.873 | D10: 245.853 | E10: 245.64 | F10: 5.7584 | G10: 110.916 | H10: 20.9276 | I10: 15.2144 | J10: 59.465 | K10: 118.141 | L10: 3.86837e-07 | M10: 724.703 | N10: 0
A11: Time non CUDA_time | B11: 333.138 | C11: 249.456 | D11: 249.437 | E11: 249.212 | F11: 5.8518 | G11: 113.057 | H11: 21.1429 | I11: 15.5586 | J11: 60.6719 | K11: 119.221 | L11: 4.03662e-06 | M11: 724.704 | N11: 0
A12: Time non CUDA_time | B12: 351.212 | C12: 250.01 | D12: 249.99 | E12: 249.773 | F12: 5.7586 | G12: 113.127 | H12: 20.9064 | I12: 15.8822 | J12: 61.1613 | K12: 120.084 | L12: 3.10101e-07 | M12: 724.704 | N12: 0
A13: Time non CUDA_time | B13: 331.542 | C13: 243.692 | D13: 243.672 | E13: 243.46 | F13: 5.7408 | G13: 109.241 | H13: 20.9327 | I13: 15.3137 | J13: 57.7087 | K13: 117.698 | L13: 3.94905e-07 | M13: 724.704 | N13: 0
A14: Time non CUDA_time | B14: 343.973 | C14: 252.11 | D14: 252.087 | E14: 251.857 | F14: 6.0264 | G14: 114.157 | H14: 21.7842 | I14: 15.9465 | J14: 60.8649 | K14: 120.403 | L14: 1.45501e-06 | M14: 724.704 | N14: 0
... A57: Time non CUDA_time | B57: 336.74 | C57: 246.363 | D57: 246.348 | E57: 246.134 | F57: 6.0207 | G57: 110.066 | H57: 20.9538 | I57: 15.4082 | J57: 57.9501 | K57: 119.022 | L57: 1.26394e-06 | M57: 724.704 | N57: 0
A58: Time non CUDA_time: | B58: 17134.564 | C58: sec
A59: Time non CUDA | B59: 275.677 | C59: 0 | D59: 0 | E59: 0 | F59: 0 | G59: 0 | H59: 0 | I59: 0 | J59: 0 | K59: 2.34198e-06 | L59: 724.704 | M59: 0
A60: Time non CUDA | B60: 278.757 | C60: 0 | D60: 0 | E60: 0 | F60: 0 | G60: 0 | H60: 0 | I60: 0 | J60: 0 | K60: 2.63634e-08 | L60: 724.704 | M60: 0
A61: Time non CUDA | B61: 267.292 | C61: 0 | D61: 0 | E61: 0 | F61: 0 | G61: 0 | H61: 0 | I61: 0 | J61: 0 | K61: 7.38851e-06 | L61: 724.704 | M61: 0
A62: Time non CUDA | B62: 267.192 | C62: 0 | D62: 0 | E62: 0 | F62: 0 | G62: 0 | H62: 0 | I62: 0 | J62: 0 | K62: 8.28732e-06 | L62: 724.704 | M62: 0
A63: Time non CUDA | B63: 279.44 | C63: 0 | D63: 0 | E63: 0 | F63: 0 | G63: 0 | H63: 0 | I63: 0 | J63: 0 | K63: 4.81329e-08 | L63: 724.702 | M63: 0
A64: Time non CUDA | B64: 265.225 | C64: 0 | D64: 0 | E64: 0 | F64: 0 | G64: 0 | H64: 0 | I64: 0 | J64: 0 | K64: 1.08874e-07 | L64: 724.704 | M64: 0
A65: Time non CUDA | B65: 260.793 | C65: 0 | D65: 0 | E65: 0 | F65: 0 | G65: 0 | H65: 0 | I65: 0 | J65: 0 | K65: 5.44342e-07 | L65: 724.704 | M65: 0
A66: Time non CUDA | B66: 277.129 | C66: 0 | D66: 0 | E66: 0 | F66: 0 | G66: 0 | H66: 0 | I66: 0 | J66: 0 | K66: 1.75795e-05 | L66: 724.704 | M66: 0
A67: Time non CUDA | B67: 283.277 | C67: 0 | D67: 0 | E67: 0 | F67: 0 | G67: 0 | H67: 0 | I67: 0 | J67: 0 | K67: 1.03186e-05 | L67: 724.704 | M67: 0
A68: Time non CUDA | B68: 270.487 | C68: 0 | D68: 0 | E68: 0 | F68: 0 | G68: 0 | H68: 0 | I68: 0 | J68: 0 | K68: 1.2767e-08 | L68: 724.704 | M68: 0
A69: Time non CUDA | B69: 262.586 | C69: 0 | D69: 0 | E69: 0 | F69: 0 | G69: 0 | H69: 0 | I69: 0 | J69: 0 | K69: 1.43933e-07 | L69: 724.704 | M69: 0
A70: Time non CUDA | B70: 277.459 | C70: 0 | D70: 0 | E70: 0 | F70: 0 | G70: 0 | H70: 0 | I70: 0 | J70: 0 | K70: 3.14432e-06 | L70: 724.704 | M70: 0
... A113: Time non CUDA | B113: 268.325 | C113: 0 | D113: 0 | E113: 0 | F113: 0 | G113: 0 | H113: 0 | I113: 0 | J113: 0 | K113: 1.43543e-06 | L113: 724.704 | M113: 0
A114: Time non CUDA: | B114: 13641.578 | C114: sec
A115: Time non CUDA non hash: | B115: 150.643 | C115: 150.483 | D115: 150.461 | E115: 150.182 | F115: 6.3086 | G115: 0 | H115: 21.8507 | I115: 0 | J115: 9.7099e-08 | K115: 724.704 | L115: 0
A116: Time non CUDA non hash: | B116: 147.218 | C116: 147.064 | D116: 147.046 | E116: 146.778 | F116: 6.4052 | G116: 0 | H116: 21.1817 | I116: 0 | J116: 5.02389e-09 | K116: 724.703 | L116: 0
A117: Time non CUDA non hash: | B117: 150.648 | C117: 150.492 | D117: 150.476 | E117: 150.2 | F117: 6.5539 | G117: 0 | H117: 22.4131 | I117: 0 | J117: 6.34274e-07 | K117: 724.704 | L117: 0
A118: Time non CUDA non hash: | B118: 147.745 | C118: 147.593 | D118: 147.577 | E118: 147.309 | F118: 6.224 | G118: 0 | H118: 20.9779 | I118: 0 | J118: 9.9724e-09 | K118: 724.704 | L118: 0
A119: Time non CUDA non hash: | B119: 148.108 | C119: 147.956 | D119: 147.941 | E119: 147.676 | F119: 6.2459 | G119: 0 | H119: 20.7466 | I119: 0 | J119: 3.46701e-07 | K119: 724.701 | L119: 0
A120: Time non CUDA non hash: | B120: 147.492 | C120: 147.341 | D120: 147.325 | E120: 147.056 | F120: 6.0454 | G120: 0 | H120: 21.0619 | I120: 0 | J120: 2.59144e-06 | K120: 724.703 | L120: 0
A121: Time non CUDA non hash: | B121: 149.396 | C121: 149.244 | D121: 149.227 | E121: 148.952 | F121: 6.1571 | G121: 0 | H121: 21.1841 | I121: 0 | J121: 4.67222e-08 | K121: 724.704 | L121: 0
A122: Time non CUDA non hash: | B122: 147.033 | C122: 146.872 | D122: 146.854 | E122: 146.588 | F122: 6.0321 | G122: 0 | H122: 21.6405 | I122: 0 | J122: 2.06635e-06 | K122: 724.703 | L122: 0
A123: Time non CUDA non hash: | B123: 148.297 | C123: 148.139 | D123: 148.123 | E123: 147.849 | F123: 6.2564 | G123: 0 | H123: 21.1478 | I123: 0 | J123: 1.58802e-08 | K123: 724.704 | L123: 0
A124: Time non CUDA non hash: | B124: 147.052 | C124: 146.887 | D124: 146.872 | E124: 146.603 | F124: 6.1108 | G124: 0 | H124: 21.2288 | I124: 0 | J124: 1.88593e-08 | K124: 724.704 | L124: 0
...

Sheet 42clangOMP52
A1: Max threads OMP : 12 OpenMP version: 202111 :OpenMP 5,1 (2021) active
A2: PARAMETR_SIZE: 42 | B2: PARAMETR_SIZE_ONE_X: 21 | C2: MAX_VALUE_SIZE: 5 | D2: NAME_FILE_GRAPH: Parametr_Graph/test42,txt | E2: ANT_SIZE: 500 | F2: KOL_ITERATION: 500 | G2: KOL_PROGON_STATISTICS: 50 | H2: PARAMETR_Q: 1 | I2: PARAMETR_RO: 0,999 | J2: TYPE_ACO: 1 | K2: ACOCCyN_KOL_ITERATION: 50, MAX_PARAMETR_VALUE_TO_MIN_OPT: 1, HASH_TABLE_SIZE: 67108864, MAX_PROBES: 10000, MAX_THREAD_CUDA: 512, CPU_RANDOM: 0, KOL_THREAD_CPU_ANT: 12, CONST_RANDOM: 100000, MAX_CONST: 8000, OPTIMIZE: OPTIMIZE_MAX | L2: FUNCTION: GO_ALG_MINMAX: 1(1, 1000)
A3: Time non CUDA_time | B3: 336.737 | C3: 246.981 | D3: 246.961 | E3: 246.676 | F3: 5.8312 | G3: 110.509 | H3: 21.0045 | I3: 15.4408 | J3: 58.5299 | K3: 119.277 | L3: 3.23402e-07 | M3: 724.703 | N3: 0
A4: Time non CUDA_time | B4: 334.017 | C4: 242.184 | D4: 242.165 | E4: 241.907 | F4: 5.9124 | G4: 108.241 | H4: 20.7661 | I4: 15.2385 | J4: 56.8632 | K4: 116.845 | L4: 1.58886e-06 | M4: 724.704 | N4: 0
A5: Time non CUDA_time | B5: 342.223 | C5: 250.246 | D5: 250.227 | E5: 250.001 | F5: 5.984 | G5: 111.957 | H5: 21.5092 | I5: 15.5329 | J5: 59.3933 | K5: 121.118 | L5: 2.23325e-06 | M5: 724.704 | N5: 0
A6: Time non CUDA_time | B6: 334.002 | C6: 242.379 | D6: 242.363 | E6: 242.087 | F6: 6.3336 | G6: 107.651 | H6: 20.8613 | I6: 15.1892 | J6: 56.4722 | K6: 117.237 | L6: 1.36889e-06 | M6: 724.703 | N6: 0
A7: Time non CUDA_time | B7: 334.025 | C7: 243.25 | D7: 243.233 | E7: 242.887 | F7: 6.0118 | G7: 108.062 | H7: 21.0094 | I7: 15.3343 | J7: 56.3334 | K7: 117.955 | L7: 2.58167e-05 | M7: 724.704 | N7: 0
A8: Time non CUDA_time | B8: 330.363 | C8: 244.438 | D8: 244.419 | E8: 244.138 | F8: 5.6477 | G8: 109.154 | H8: 20.9555 | I8: 15.5516 | J8: 57.1253 | K8: 118.439 | L8: 1.50655e-07 | M8: 724.704 | N8: 0
A9: Time non CUDA_time | B9: 333.701 | C9: 245.11 | D9: 245.09 | E9: 244.819 | F9: 5.6939 | G9: 111.05 | H9: 21.0336 | I9: 15.282 | J9: 59.3965 | K9: 117.258 | L9: 3.88414e-07 | M9: 724.704 | N9: 0
A10: Time non CUDA_time | B10: 334.33 | C10: 244.311 | D10: 244.29 | E10: 244.02 | F10: 5.9664 | G10: 110.456 | H10: 21.0398 | I10: 15.3174 | J10: 58.9399 | K10: 116.909 | L10: 6.85489e-05 | M10: 724.704 | N10: 0
A11: Time non CUDA_time | B11: 336.771 | C11: 246.263 | D11: 246.243 | E11: 245.993 | F11: 5.9634 | G11: 110.188 | H11: 21.1253 | I11: 15.274 | J11: 58.3677 | K11: 118.774 | L11: 5.07092e-08 | M11: 724.704 | N11: 0
A12: Time non CUDA_time | B12: 336.035 | C12: 241.667 | D12: 241.649 | E12: 241.375 | F12: 5.7942 | G12: 107.361 | H12: 21.0644 | I12: 15.2599 | J12: 55.8354 | K12: 117.44 | L12: 1.85358e-06 | M12: 724.703 | N12: 0
A13: Time non CUDA_time | B13: 331.833 | C13: 245.881 | D13: 245.862 | E13: 245.585 | F13: 5.787 | G13: 111.463 | H13: 20.8528 | I13: 15.2591 | J13: 59.9555 | K13: 117.38 | L13: 2.58485e-08 | M13: 724.702 | N13: 0
A14: Time non CUDA_time | B14: 343.334 | C14: 244.622 | D14: 244.604 | E14: 244.326 | F14: 5.9275 | G14: 108.754 | H14: 20.8563 | I14: 15.2361 | J14: 57.2905 | K14: 118.809 | L14: 1.68861e-06 | M14: 724.703 | N14: 0
... A57: Time non CUDA_time | B57: 335.5 | C57: 247.432 | D57: 247.413 | E57: 247.133 | F57: 5.7767 | G57: 110.482 | H57: 21.6255 | I57: 16.0996 | J57: 57.4113 | K57: 119.95 | L57: 1.04077e-06 | M57: 724.704 | N57: 0
A58: Time non CUDA_time: | B58: 17101.908 | C58: sec
A59: Time non CUDA | B59: 270.553 | C59: 0 | D59: 0 | E59: 0 | F59: 0 | G59: 0 | H59: 0 | I59: 0 | J59: 0 | K59: 8.86757e-07 | L59: 724.704 | M59: 0
A60: Time non CUDA | B60: 294.041 | C60: 0 | D60: 0 | E60: 0 | F60: 0 | G60: 0 | H60: 0 | I60: 0 | J60: 0 | K60: 1.38757e-07 | L60: 724.704 | M60: 0
A61: Time non CUDA | B61: 265.638 | C61: 0 | D61: 0 | E61: 0 | F61: 0 | G61: 0 | H61: 0 | I61: 0 | J61: 0 | K61: 2.01072e-06 | L61: 724.704 | M61: 0
A62: Time non CUDA | B62: 289.772 | C62: 0 | D62: 0 | E62: 0 | F62: 0 | G62: 0 | H62: 0 | I62: 0 | J62: 0 | K62: 3.59606e-09 | L62: 724.704 | M62: 0
A63: Time non CUDA | B63: 268.652 | C63: 0 | D63: 0 | E63: 0 | F63: 0 | G63: 0 | H63: 0 | I63: 0 | J63: 0 | K63: 4.97889e-07 | L63: 724.704 | M63: 0
A64: Time non CUDA | B64: 267.279 | C64: 0 | D64: 0 | E64: 0 | F64: 0 | G64: 0 | H64: 0 | I64: 0 | J64: 0 | K64: 4.45132e-06 | L64: 724.704 | M64: 0
A65: Time non CUDA | B65: 266.414 | C65: 0 | D65: 0 | E65: 0 | F65: 0 | G65: 0 | H65: 0 | I65: 0 | J65: 0 | K65: 1.238e-06 | L65: 724.704 | M65: 0
A66: Time non CUDA | B66: 272.381 | C66: 0 | D66: 0 | E66: 0 | F66: 0 | G66: 0 | H66: 0 | I66: 0 | J66: 0 | K66: 5.32232e-07 | L66: 724.704 | M66: 0
A67: Time non CUDA | B67: 262.99 | C67: 0 | D67: 0 | E67: 0 | F67: 0 | G67: 0 | H67: 0 | I67: 0 | J67: 0 | K67: 7.55858e-07 | L67: 724.704 | M67: 0
A68: Time non CUDA | B68: 276.605 | C68: 0 | D68: 0 | E68: 0 | F68: 0 | G68: 0 | H68: 0 | I68: 0 | J68: 0 | K68: 1.09316e-10 | L68: 724.703 | M68: 0
A69: Time non CUDA | B69: 270.797 | C69: 0 | D69: 0 | E69: 0 | F69: 0 | G69: 0 | H69: 0 | I69: 0 | J69: 0 | K69: 7.85638e-10 | L69: 724.704 | M69: 0
A70: Time non CUDA | B70: 273.778 | C70: 0 | D70: 0 | E70: 0 | F70: 0 | G70: 0 | H70: 0 | I70: 0 | J70: 0 | K70: 4.88536e-07 | L70: 724.704 | M70: 0
... A113: Time non CUDA | B113: 288.987 | C113: 0 | D113: 0 | E113: 0 | F113: 0 | G113: 0 | H113: 0 | I113: 0 | J113: 0 | K113: 7.04681e-08 | L113: 724.704 | M113: 0
A114: Time non CUDA: | B114: 13610.919 | C114: sec
A115: Time non CUDA non hash: | B115: 148.936 | C115: 148.776 | D115: 148.761 | E115: 148.486 | F115: 5.9183 | G115: 0 | H115: 20.8965 | I115: 0 | J115: 1.06825e-05 | K115: 724.704 | L115: 0
A116: Time non CUDA non hash: | B116: 149.425 | C116: 149.271 | D116: 149.252 | E116: 148.981 | F116: 5.8243 | G116: 0 | H116: 20.9904 | I116: 0 | J116: 4.59947e-06 | K116: 724.704 | L116: 0
A117: Time non CUDA non hash: | B117: 146.652 | C117: 146.502 | D117: 146.485 | E117: 146.216 | F117: 5.7339 | G117: 0 | H117: 21.3657 | I117: 0 | J117: 2.71969e-08 | K117: 724.704 | L117: 0
A118: Time non CUDA non hash: | B118: 146.217 | C118: 146.068 | D118: 146.052 | E118: 145.786 | F118: 5.9626 | G118: 0 | H118: 20.8676 | I118: 0 | J118: 1.67635e-05 | K118: 724.704 | L118: 0
A119: Time non CUDA non hash: | B119: 145.788 | C119: 145.639 | D119: 145.624 | E119: 145.285 | F119: 5.9182 | G119: 0 | H119: 21.2351 | I119: 0 | J119: 1.11504e-07 | K119: 724.704 | L119: 0
A120: Time non CUDA non hash: | B120: 145.688 | C120: 145.536 | D120: 145.519 | E120: 145.253 | F120: 6.0919 | G120: 0 | H120: 20.7906 | I120: 0 | J120: 4.26468e-07 | K120: 724.703 | L120: 0
A121: Time non CUDA non hash: | B121: 149.959 | C121: 149.809 | D121: 149.791 | E121: 149.519 | F121: 5.9304 | G121: 0 | H121: 21.19 | I121: 0 | J121: 1.9161e-06 | K121: 724.704 | L121: 0
A122: Time non CUDA non hash: | B122: 147.531 | C122: 147.378 | D122: 147.36 | E122: 147.092 | F122: 5.9019 | G122: 0 | H122: 21.6303 | I122: 0 | J122: 5.98728e-09 | K122: 724.704 | L122: 0
A123: Time non CUDA non hash: | B123: 156.962 | C123: 156.808 | D123: 156.791 | E123: 156.512 | F123: 7.9672 | G123: 0 | H123: 21.1501 | I123: 0 | J123: 6.12784e-08 | K123: 724.704 | L123: 0
A124: Time non CUDA non hash: | B124: 147.888 | C124: 147.743 | D124: 147.726 | E124: 147.457 | F124: 5.7658 | G124: 0 | H124: 21.6174 | I124: 0 | J124: 1.1956e-07 | K124: 724.704 | L124: 0
...

Sheet 42clangOMP60
A1: Max threads OMP : 12 OpenMP version: 202411 :OpenMP 5,2 (2023) active
A2: PARAMETR_SIZE: 42 | B2: PARAMETR_SIZE_ONE_X: 21 | C2: MAX_VALUE_SIZE: 5 | D2: NAME_FILE_GRAPH: Parametr_Graph/test42,txt | E2: ANT_SIZE: 500 | F2: KOL_ITERATION: 500 | G2: KOL_PROGON_STATISTICS: 50 | H2: PARAMETR_Q: 1 | I2: PARAMETR_RO: 0,999 | J2: TYPE_ACO: 1 | K2: ACOCCyN_KOL_ITERATION: 50, MAX_PARAMETR_VALUE_TO_MIN_OPT: 1, HASH_TABLE_SIZE: 67108864, MAX_PROBES: 10000, MAX_THREAD_CUDA: 512, CPU_RANDOM: 0, KOL_THREAD_CPU_ANT: 12, CONST_RANDOM: 100000, MAX_CONST: 8000, OPTIMIZE: OPTIMIZE_MAX | L2: FUNCTION: GO_ALG_MINMAX: 1(1, 1000)
A3: Time non CUDA_time | B3: 336.483 | C3: 243.54 | D3: 243.523 | E3: 243.229 | F3: 5.9031 | G3: 107.889 | H3: 20.9122 | I3: 15.2571 | J3: 56.3301 | K3: 118.395 | L3: 6.36094e-07 | M3: 724.704 | N3: 0
A4: Time non CUDA_time | B4: 354.985 | C4: 247.696 | D4: 247.678 | E4: 247.408 | F4: 6.0346 | G4: 111.438 | H4: 21.2876 | I4: 15.7305 | J4: 59.1042 | K4: 118.954 | L4: 2.93799e-07 | M4: 724.703 | N4: 0
A5: Time non CUDA_time | B5: 334.136 | C5: 248.68 | D5: 248.662 | E5: 248.42 | F5: 6.2467 | G5: 112.281 | H5: 20.9594 | I5: 15.2989 | J5: 60.7703 | K5: 118.999 | L5: 4.35113e-08 | M5: 724.704 | N5: 0
A6: Time non CUDA_time | B6: 336.661 | C6: 244.376 | D6: 244.36 | E6: 244.092 | F6: 6.1071 | G6: 108.226 | H6: 21.225 | I6: 15.1459 | J6: 56.4534 | K6: 118.801 | L6: 2.67692e-12 | M6: 724.704 | N6: 0
A7: Time non CUDA_time | B7: 341.112 | C7: 252.683 | D7: 252.662 | E7: 252.388 | F7: 6.3278 | G7: 115.266 | H7: 21.7852 | I7: 16.4909 | J7: 61.2537 | K7: 119.826 | L7: 2.90148e-06 | M7: 724.704 | N7: 0
A8: Time non CUDA_time | B8: 343.797 | C8: 254.143 | D8: 254.125 | E8: 253.853 | F8: 6.014 | G8: 117.395 | H8: 20.814 | I8: 15.226 | J8: 65.8008 | K8: 119.434 | L8: 7.82899e-07 | M8: 724.704 | N8: 0
A9: Time non CUDA_time | B9: 341.112 | C9: 252.037 | D9: 252.017 | E9: 251.748 | F9: 5.9085 | G9: 113.427 | H9: 22.5196 | I9: 15.7034 | J9: 58.3854 | K9: 121.558 | L9: 3.67782e-07 | M9: 724.703 | N9: 0
A10: Time non CUDA_time | B10: 342.638 | C10: 252.079 | D10: 252.062 | E10: 251.779 | F10: 6.266 | G10: 113.594 | H10: 21.2714 | I10: 15.5982 | J10: 61.0448 | K10: 120.684 | L10: 2.13672e-07 | M10: 724.699 | N10: 0
A11: Time non CUDA_time | B11: 331.937 | C11: 244.248 | D11: 244.229 | E11: 243.963 | F11: 5.955 | G11: 109.594 | H11: 20.6827 | I11: 15.2978 | J11: 58.4254 | K11: 117.509 | L11: 5.46423e-07 | M11: 724.704 | N11: 0
A12: Time non CUDA_time | B12: 336.231 | C12: 249.126 | D12: 249.108 | E12: 248.763 | F12: 5.9507 | G12: 111.334 | H12: 20.8958 | I12: 16.0795 | J12: 58.9425 | K12: 120.471 | L12: 1.36671e-07 | M12: 724.704 | N12: 0
A13: Time non CUDA_time | B13: 334.576 | C13: 249.126 | D13: 249.107 | E13: 248.837 | F13: 6.0285 | G13: 112.016 | H13: 20.7177 | I13: 15.3007 | J13: 60.8142 | K13: 119.7 | L13: 1.04507e-06 | M13: 724.703 | N13: 0
A14: Time non CUDA_time | B14: 337.913 | C14: 243.043 | D14: 243.025 | E14: 242.758 | F14: 6.2014 | G14: 108.238 | H14: 20.5827 | I14: 15.1462 | J14: 57.3631 | K14: 117.531 | L14: 1.56624e-07 | M14: 724.703 | N14: 0
... A57: Time non CUDA_time | B57: 341.213 | C57: 253.12 | D57: 253.102 | E57: 252.831 | F57: 5.8672 | G57: 115.249 | H57: 21.5491 | I57: 15.5081 | J57: 62.28 | K57: 120.873 | L57: 4.39985e-06 | M57: 724.704 | N57: 0
A58: Time non CUDA_time: | B58: 17116.352 | C58: sec
A59: Time non CUDA | B59: 262.098 | C59: 0 | D59: 0 | E59: 0 | F59: 0 | G59: 0 | H59: 0 | I59: 0 | J59: 0 | K59: 1.93855e-07 | L59: 724.704 | M59: 0
A60: Time non CUDA | B60: 269.265 | C60: 0 | D60: 0 | E60: 0 | F60: 0 | G60: 0 | H60: 0 | I60: 0 | J60: 0 | K60: 2.48663e-06 | L60: 724.704 | M60: 0
A61: Time non CUDA | B61: 271.833 | C61: 0 | D61: 0 | E61: 0 | F61: 0 | G61: 0 | H61: 0 | I61: 0 | J61: 0 | K61: 9.02931e-09 | L61: 724.704 | M61: 0
A62: Time non CUDA | B62: 269.736 | C62: 0 | D62: 0 | E62: 0 | F62: 0 | G62: 0 | H62: 0 | I62: 0 | J62: 0 | K62: 2.68637e-06 | L62: 724.704 | M62: 0
A63: Time non CUDA | B63: 266.904 | C63: 0 | D63: 0 | E63: 0 | F63: 0 | G63: 0 | H63: 0 | I63: 0 | J63: 0 | K63: 9.5368e-06 | L63: 724.704 | M63: 0
A64: Time non CUDA | B64: 266.358 | C64: 0 | D64: 0 | E64: 0 | F64: 0 | G64: 0 | H64: 0 | I64: 0 | J64: 0 | K64: 1.88317e-08 | L64: 724.704 | M64: 0
A65: Time non CUDA | B65: 282.281 | C65: 0 | D65: 0 | E65: 0 | F65: 0 | G65: 0 | H65: 0 | I65: 0 | J65: 0 | K65: 2.53952e-06 | L65: 724.704 | M65: 0
A66: Time non CUDA | B66: 285.373 | C66: 0 | D66: 0 | E66: 0 | F66: 0 | G66: 0 | H66: 0 | I66: 0 | J66: 0 | K66: 5.084e-06 | L66: 724.704 | M66: 0
A67: Time non CUDA | B67: 262.744 | C67: 0 | D67: 0 | E67: 0 | F67: 0 | G67: 0 | H67: 0 | I67: 0 | J67: 0 | K67: 4.56588e-07 | L67: 724.704 | M67: 0
A68: Time non CUDA | B68: 272.892 | C68: 0 | D68: 0 | E68: 0 | F68: 0 | G68: 0 | H68: 0 | I68: 0 | J68: 0 | K68: 2.24168e-08 | L68: 724.704 | M68: 0
A69: Time non CUDA | B69: 265.781 | C69: 0 | D69: 0 | E69: 0 | F69: 0 | G69: 0 | H69: 0 | I69: 0 | J69: 0 | K69: 4.81918e-08 | L69: 724.704 | M69: 0
A70: Time non CUDA | B70: 266.692 | C70: 0 | D70: 0 | E70: 0 | F70: 0 | G70: 0 | H70: 0 | I70: 0 | J70: 0 | K70: 8.05021e-07 | L70: 724.703 | M70: 0
... A113: Time non CUDA | B113: 277.673 | C113: 0 | D113: 0 | E113: 0 | F113: 0 | G113: 0 | H113: 0 | I113: 0 | J113: 0 | K113: 1.30273e-06 | L113: 724.703 | M113: 0
A114: Time non CUDA: | B114: 13643.444 | C114: sec
A115: Time non CUDA non hash: | B115: 147.585 | C115: 147.431 | D115: 147.415 | E115: 147.149 | F115: 5.9381 | G115: 0 | H115: 20.8138 | I115: 0 | J115: 1.52765e-06 | K115: 724.704 | L115: 0
A116: Time non CUDA non hash: | B116: 149.254 | C116: 149.101 | D116: 149.086 | E116: 148.824 | F116: 5.6434 | G116: 0 | H116: 21.316 | I116: 0 | J116: 6.09412e-08 | K116: 724.704 | L116: 0
A117: Time non CUDA non hash: | B117: 148.815 | C117: 148.665 | D117: 148.649 | E117: 148.386 | F117: 5.7878 | G117: 0 | H117: 21.2297 | I117: 0 | J117: 9.5411e-06 | K117: 724.704 | L117: 0
A118: Time non CUDA non hash: | B118: 151.744 | C118: 151.592 | D118: 151.571 | E118: 151.3 | F118: 6.6977 | G118: 0 | H118: 21.2838 | I118: 0 | J118: 4.64151e-07 | K118: 724.704 | L118: 0
A119: Time non CUDA non hash: | B119: 146.851 | C119: 146.693 | D119: 146.676 | E119: 146.415 | F119: 5.6343 | G119: 0 | H119: 20.8229 | I119: 0 | J119: 7.4054e-08 | K119: 724.703 | L119: 0
A120: Time non CUDA non hash: | B120: 150.824 | C120: 150.672 | D120: 150.652 | E120: 150.412 | F120: 5.7402 | G120: 0 | H120: 21.3246 | I120: 0 | J120: 2.06265e-07 | K120: 724.703 | L120: 0
A121: Time non CUDA non hash: | B121: 146.945 | C121: 146.453 | D121: 146.438 | E121: 146.176 | F121: 5.6724 | G121: 0 | H121: 20.7996 | I121: 0 | J121: 1.97057e-06 | K121: 724.704 | L121: 0
A122: Time non CUDA non hash: | B122: 148.997 | C122: 148.847 | D122: 148.832 | E122: 148.569 | F122: 5.6507 | G122: 0 | H122: 20.6768 | I122: 0 | J122: 3.64635e-07 | K122: 724.704 | L122: 0
A123: Time non CUDA non hash: | B123: 148.395 | C123: 148.242 | D123: 148.225 | E123: 147.964 | F123: 5.7871 | G123: 0 | H123: 20.686 | I123: 0 | J123: 2.20023e-07 | K123: 724.701 | L123: 0
A124: Time non CUDA non hash: | B124: 148.377 | C124: 148.224 | D124: 148.206 | E124: 147.946 | F124: 6.355 | G124: 0 | H124: 21.0895 | I124: 0 | J124: 7.31579e-07 | K124: 724.703 | L124: 0
...

Sheet 42gccOMP40
A1: Max threads OMP : 12 OpenMP version: 201511 :OpenMP 4,5 (2015) optimal
A2: PARAMETR_SIZE: 42 | B2: PARAMETR_SIZE_ONE_X: 21 | C2: MAX_VALUE_SIZE: 5 | D2: NAME_FILE_GRAPH: Parametr_Graph/test42,txt | E2: ANT_SIZE: 500 | F2: KOL_ITERATION: 500 | G2: KOL_PROGON_STATISTICS: 50 | H2: PARAMETR_Q: 1 | I2: PARAMETR_RO: 0,999 | J2: TYPE_ACO: 1 | K2: ACOCCyN_KOL_ITERATION: 50, MAX_PARAMETR_VALUE_TO_MIN_OPT: 1, HASH_TABLE_SIZE: 67108864, MAX_PROBES: 10000, MAX_THREAD_CUDA: 512, CPU_RANDOM: 0, KOL_THREAD_CPU_ANT: 12, CONST_RANDOM: 100000, MAX_CONST: 8000, OPTIMIZE: OPTIMIZE_MAX | L2: FUNCTION: GO_ALG_MINMAX: 1(1, 1000)
A3: Time non CUDA_time | B3: 469.138 | C3: 366.518 | D3: 366.491 | E3: 366.209 | F3: 7.407 | G3: 157.578 | H3: 52.807 | I3: 16.594 | J3: 60.95 | K3: 183.154 | L3: 3.01274e-09 | M3: 724.704 | N3: 0
A4: Time non CUDA_time | B4: 464.978 | C4: 374.63 | D4: 374.603 | E4: 374.31 | F4: 7.505 | G4: 161.848 | H4: 53.595 | I4: 16.962 | J4: 62.993 | K4: 186.195 | L4: 1.3853e-05 | M4: 724.704 | N4: 0
A5: Time non CUDA_time | B5: 459.714 | C5: 366.363 | D5: 366.34 | E5: 366.056 | F5: 7.13 | G5: 157.251 | H5: 51.735 | I5: 16.67 | J5: 61.517 | K5: 183.752 | L5: 2.43406e-07 | M5: 724.704 | N5: 25
A6: Time non CUDA_time | B6: 463.561 | C6: 370.853 | D6: 370.819 | E6: 370.522 | F6: 7.945 | G6: 158.938 | H6: 52.881 | I6: 17.208 | J6: 61.657 | K6: 185.439 | L6: 1.42685e-07 | M6: 724.704 | N6: 0
A7: Time non CUDA_time | B7: 468.957 | C7: 376.095 | D7: 376.055 | E7: 375.784 | F7: 7.319 | G7: 160.144 | H7: 52.3 | I7: 16.852 | J7: 63.441 | K7: 187.605 | L7: 4.68912e-07 | M7: 724.704 | N7: 0
A8: Time non CUDA_time | B8: 459.383 | C8: 368.664 | D8: 368.627 | E8: 368.073 | F8: 7.198 | G8: 157.987 | H8: 51.796 | I8: 17.185 | J8: 61.535 | K8: 184.684 | L8: 4.43868e-08 | M8: 724.704 | N8: 0
A9: Time non CUDA_time | B9: 454.882 | C9: 364.365 | D9: 364.334 | E9: 364.057 | F9: 7.331 | G9: 156.396 | H9: 51.639 | I9: 16.86 | J9: 61.276 | K9: 182.138 | L9: 1.60429e-07 | M9: 724.704 | N9: 0
A10: Time non CUDA_time | B10: 463.591 | C10: 369.369 | D10: 369.331 | E10: 369.051 | F10: 7.52 | G10: 157.811 | H10: 52.142 | I10: 16.313 | J10: 62.34 | K10: 185.496 | L10: 8.42559e-08 | M10: 724.704 | N10: 0
A11: Time non CUDA_time | B11: 453.653 | C11: 365.999 | D11: 365.966 | E11: 365.692 | F11: 7.063 | G11: 157.055 | H11: 52.298 | I11: 16.44 | J11: 61.615 | K11: 183.682 | L11: 5.69863e-06 | M11: 724.698 | N11: 0
A12: Time non CUDA_time | B12: 460.993 | C12: 364.827 | D12: 364.792 | E12: 364.515 | F12: 7.551 | G12: 154.703 | H12: 51.495 | I12: 16.453 | J12: 60.021 | K12: 184.282 | L12: 4.85558e-07 | M12: 724.703 | N12: 0
A13: Time non CUDA_time | B13: 458.397 | C13: 367.878 | D13: 367.849 | E13: 367.579 | F13: 7.436 | G13: 157.226 | H13: 51.24 | I13: 16.727 | J13: 62.677 | K13: 185.106 | L13: 3.00666e-07 | M13: 724.704 | N13: 0
A14: Time non CUDA_time | B14: 451.457 | C14: 363.876 | D14: 363.844 | E14: 363.578 | F14: 7.314 | G14: 155.35 | H14: 52.051 | I14: 16.622 | J14: 59.838 | K14: 183.16 | L14: 1.0142e-05 | M14: 724.704 | N14: 0
... A57: Time non CUDA_time | B57: 452.869 | C57: 362.863 | D57: 362.837 | E57: 362.548 | F57: 7.106 | G57: 154.006 | H57: 51.266 | I57: 16.491 | J57: 59.385 | K57: 183.679 | L57: 7.11969e-07 | M57: 724.704 | N57: 0
A58: Time non CUDA_time: | B58: 23157.089 | C58: sec
A59: Time non CUDA | B59: 371.398 | C59: 0 | D59: 0 | E59: 0 | F59: 0 | G59: 0 | H59: 0 | I59: 0 | J59: 0 | K59: 7.16756e-06 | L59: 724.704 | M59: 0
A60: Time non CUDA | B60: 371.921 | C60: 0 | D60: 0 | E60: 0 | F60: 0 | G60: 0 | H60: 0 | I60: 0 | J60: 0 | K60: 2.88141e-07 | L60: 724.704 | M60: 0
A61: Time non CUDA | B61: 375.637 | C61: 0 | D61: 0 | E61: 0 | F61: 0 | G61: 0 | H61: 0 | I61: 0 | J61: 0 | K61: 1.03106e-08 | L61: 724.704 | M61: 0
A62: Time non CUDA | B62: 375.207 | C62: 0 | D62: 0 | E62: 0 | F62: 0 | G62: 0 | H62: 0 | I62: 0 | J62: 0 | K62: 2.15955e-06 | L62: 724.704 | M62: 0
A63: Time non CUDA | B63: 369.253 | C63: 0 | D63: 0 | E63: 0 | F63: 0 | G63: 0 | H63: 0 | I63: 0 | J63: 0 | K63: 1.21513e-06 | L63: 724.704 | M63: 0
A64: Time non CUDA | B64: 375.494 | C64: 0 | D64: 0 | E64: 0 | F64: 0 | G64: 0 | H64: 0 | I64: 0 | J64: 0 | K64: 6.95742e-07 | L64: 724.704 | M64: 0
A65: Time non CUDA | B65: 371.003 | C65: 0 | D65: 0 | E65: 0 | F65: 0 | G65: 0 | H65: 0 | I65: 0 | J65: 0 | K65: 2.81494e-08 | L65: 724.704 | M65: 0
A66: Time non CUDA | B66: 372.631 | C66: 0 | D66: 0 | E66: 0 | F66: 0 | G66: 0 | H66: 0 | I66: 0 | J66: 0 | K66: 4.53724e-06 | L66: 724.704 | M66: 208
A67: Time non CUDA | B67: 383.818 | C67: 0 | D67: 0 | E67: 0 | F67: 0 | G67: 0 | H67: 0 | I67: 0 | J67: 0 | K67: 7.08959e-06 | L67: 724.699 | M67: 138
A68: Time non CUDA | B68: 372.959 | C68: 0 | D68: 0 | E68: 0 | F68: 0 | G68: 0 | H68: 0 | I68: 0 | J68: 0 | K68: 1.65969e-06 | L68: 724.703 | M68: 0
A69: Time non CUDA | B69: 378.887 | C69: 0 | D69: 0 | E69: 0 | F69: 0 | G69: 0 | H69: 0 | I69: 0 | J69: 0 | K69: 7.43366e-07 | L69: 724.704 | M69: 0
A70: Time non CUDA | B70: 375.17 | C70: 0 | D70: 0 | E70: 0 | F70: 0 | G70: 0 | H70: 0 | I70: 0 | J70: 0 | K70: 1.04672e-05 | L70: 724.704 | M70: 0
... A113: Time non CUDA | B113: 377.149 | C113: 0 | D113: 0 | E113: 0 | F113: 0 | G113: 0 | H113: 0 | I113: 0 | J113: 0 | K113: 7.81409e-08 | L113: 724.703 | M113: 82
A114: Time non CUDA: | B114: 18989.357 | C114: sec
A115: Time non CUDA non hash: | B115: 240.403 | C115: 239.95 | D115: 239.921 | E115: 239.635 | F115: 6.979 | G115: 0 | H115: 51.629 | I115: 0 | J115: 3.27008e-05 | K115: 724.704 | L115: 0
A116: Time non CUDA non hash: | B116: 241.515 | C116: 241.065 | D116: 241.047 | E116: 240.777 | F116: 7.078 | G116: 0 | H116: 52.193 | I116: 0 | J116: 3.84269e-05 | K116: 724.704 | L116: 0
A117: Time non CUDA non hash: | B117: 244.197 | C117: 243.746 | D117: 243.715 | E117: 243.438 | F117: 7.549 | G117: 0 | H117: 52.756 | I117: 0 | J117: 1.2521e-06 | K117: 724.704 | L117: 0
A118: Time non CUDA non hash: | B118: 242.236 | C118: 241.787 | D118: 241.746 | E118: 241.491 | F118: 7.099 | G118: 0 | H118: 52.352 | I118: 0 | J118: 1.21466e-05 | K118: 724.704 | L118: 0
A119: Time non CUDA non hash: | B119: 240.3 | C119: 239.848 | D119: 239.813 | E119: 239.534 | F119: 7.02 | G119: 0 | H119: 51.475 | I119: 0 | J119: 2.10712e-06 | K119: 724.704 | L119: 0
A120: Time non CUDA non hash: | B120: 249.623 | C120: 249.169 | D120: 249.139 | E120: 248.86 | F120: 7.394 | G120: 0 | H120: 54.19 | I120: 0 | J120: 9.56498e-07 | K120: 724.704 | L120: 0
A121: Time non CUDA non hash: | B121: 240.309 | C121: 239.85 | D121: 239.825 | E121: 239.056 | F121: 7.124 | G121: 0 | H121: 51.298 | I121: 0 | J121: 4.1216e-05 | K121: 724.704 | L121: 0
A122: Time non CUDA non hash: | B122: 240.752 | C122: 240.297 | D122: 240.276 | E122: 239.971 | F122: 7.117 | G122: 0 | H122: 51.366 | I122: 0 | J122: 7.13812e-07 | K122: 724.704 | L122: 0
A123: Time non CUDA non hash: | B123: 240.623 | C123: 240.105 | D123: 240.075 | E123: 239.802 | F123: 7.058 | G123: 0 | H123: 51.676 | I123: 0 | J123: 2.36864e-06 | K123: 724.704 | L123: 0
A124: Time non CUDA non hash: | B124: 246.358 | C124: 245.903 | D124: 245.871 | E124: 245.581 | F124: 7.003 | G124: 0 | H124: 51.74 | I124: 0 | J124: 1.57955e-07 | K124: 724.704 | L124: 0
...

Sheet 42vssOMP20
A1: Max threads OMP : 12 OpenMP version: 200203 :OpenMP 2,0 (2002) outdated
A2: PARAMETR_SIZE: 42 | B2: PARAMETR_SIZE_ONE_X: 21 | C2: MAX_VALUE_SIZE: 5 | D2: NAME_FILE_GRAPH: Parametr_Graph/test42,txt | E2: ANT_SIZE: 500 | F2: KOL_ITERATION: 500 | G2: KOL_PROGON_STATISTICS: 50 | H2: PARAMETR_Q: 1 | I2: PARAMETR_RO: 0,999 | J2: TYPE_ACO: 1 | K2: ACOCCyN_KOL_ITERATION: 50, MAX_PARAMETR_VALUE_TO_MIN_OPT: 1, HASH_TABLE_SIZE: 67108864, MAX_PROBES: 10000, MAX_THREAD_CUDA: 512, CPU_RANDOM: 0, KOL_THREAD_CPU_ANT: 12, CONST_RANDOM: 100000, MAX_CONST: 8000, OPTIMIZE: OPTIMIZE_MAX | L2: FUNCTION: GO_ALG_MINMAX: 1(1, 1000)
A3: Time non CUDA_time | B3: 1133.77 | C3: 752.719 | D3: 752.565 | E3: 751.513 | F3: 26.7827 | G3: 198.218 | H3: 52.2422 | I3: 23.0629 | J3: 76.6402 | K3: 494.222 | L3: 2.12491e-06 | M3: 724.704 | N3: 0
A4: Time non CUDA_time | B4: 1106.8 | C4: 726.306 | D4: 726.205 | E4: 725.319 | F4: 26.2655 | G4: 190.62 | H4: 48.8806 | I4: 22.5642 | J4: 72.0754 | K4: 477.507 | L4: 1.07788e-05 | M4: 724.702 | N4: 0
A5: Time non CUDA_time | B5: 1118.48 | C5: 741.915 | D5: 741.792 | E5: 740.903 | F5: 26.1055 | G5: 193.263 | H5: 50.8523 | I5: 21.9875 | J5: 73.4555 | K5: 489.515 | L5: 1.79888e-08 | M5: 724.704 | N5: 0
A6: Time non CUDA_time | B6: 1117.88 | C6: 750.075 | D6: 749.955 | E6: 748.943 | F6: 26.4197 | G6: 196.483 | H6: 51.2293 | I6: 23.714 | J6: 75.4162 | K6: 494.138 | L6: 8.02501e-07 | M6: 724.704 | N6: 0
A7: Time non CUDA_time | B7: 1124.65 | C7: 763.669 | D7: 763.466 | E7: 762.491 | F7: 29.5008 | G7: 201.748 | H7: 51.3946 | I7: 25.1206 | J7: 75.2504 | K7: 497.655 | L7: 1.35132e-06 | M7: 724.704 | N7: 0
