Workbook

Sheet 42p stat
A2: CUDA Time | B2: 1 | C2: 25 | D2: Duration Mean: | E2: 0 | F2: 0 | G2: GPU Time 1 Mean: | H2: 32.196781 | I2: 0.196426 | J2: GPU Time 2 Mean: | K2: 31.416984 | L2: 0.195027 | M2: GPU Time 3 Mean: | N2: 15.024374 | O2: 0.197796 | P2: GPU Time 4 Mean: | Q2: 0 | R2: 0 | S2: GPU Time 5 Mean: | T2: 0 | U2: 0 | V2: GPU Time 6 Mean: | W2: 0 | X2: 0 | Y2: GPU Time 7 Mean: | Z2: 0 | AA2: 0 | AB2: GPU Time 8 Mean: | AC2: 0 | AD2: 0 | AE2: Global Min Mean: | AF2: 1 | AG2: 0 | AH2: Global Max Mean: | AI2: 1 | AJ2: 0 | AK2: Hash Fail Count Mean: | AL2: 0 | AM2: 0
A3: CUDA Time | B3: 2 | C3: 50 | D3: Duration Mean: | E3: 0 | F3: 0 | G3: GPU Time 1 Mean: | H3: 64.643411 | I3: 0.872845 | J3: GPU Time 2 Mean: | K3: 63.094764 | L3: 0.866023 | M3: GPU Time 3 Mean: | N3: 30.304138 | O3: 0.867471 | P3: GPU Time 4 Mean: | Q3: 0 | R3: 0 | S3: GPU Time 5 Mean: | T3: 0 | U3: 0 | V3: GPU Time 6 Mean: | W3: 0 | X3: 0 | Y3: GPU Time 7 Mean: | Z3: 0 | AA3: 0 | AB3: GPU Time 8 Mean: | AC3: 0 | AD3: 0 | AE3: Global Min Mean: | AF3: 1 | AG3: 0 | AH3: Global Max Mean: | AI3: 1 | AJ3: 0 | AK3: Hash Fail Count Mean: | AL3: 0 | AM3: 0
A4: CUDA Time | B4: 3 | C4: 75 | D4: Duration Mean: | E4: 0 | F4: 0 | G4: GPU Time 1 Mean: | H4: 97.087052 | I4: 2.014795 | J4: GPU Time 2 Mean: | K4: 94.769308 | L4: 1.997889 | M4: GPU Time 3 Mean: | N4: 45.584918 | O4: 1.993685 | P4: GPU Time 4 Mean: | Q4: 0 | R4: 0 | S4: GPU Time 5 Mean: | T4: 0 | U4: 0 | V4: GPU Time 6 Mean: | W4: 0 | X4: 0 | Y4: GPU Time 7 Mean: | Z4: 0 | AA4: 0 | AB4: GPU Time 8 Mean: | AC4: 0 | AD4: 0 | AE4: Global Min Mean: | AF4: 1 | AG4: 0 | AH4: Global Max Mean: | AI4: 1 | AJ4: 0 | AK4: Hash Fail Count Mean: | AL4: 0 | AM4: 0
A5: CUDA Time | B5: 4 | C5: 100 | D5: Duration Mean: | E5: 0 | F5: 0 | G5: GPU Time 1 Mean: | H5: 129.52116 | I5: 3.632116 | J5: GPU Time 2 Mean: | K5: 126.43448 | L5: 3.6026 | M5: GPU Time 3 Mean: | N5: 60.854596 | O5: 3.601491 | P5: GPU Time 4 Mean: | Q5: 0 | R5: 0 | S5: GPU Time 5 Mean: | T5: 0 | U5: 0 | V5: GPU Time 6 Mean: | W5: 0 | X5: 0 | Y5: GPU Time 7 Mean: | Z5: 0 | AA5: 0 | AB5: GPU Time 8 Mean: | AC5: 0 | AD5: 0 | AE5: Global Min Mean: | AF5: 1 | AG5: 0 | AH5: Global Max Mean: | AI5: 1 | AJ5: 0 | AK5: Hash Fail Count Mean: | AL5: 0 | AM5: 0
A6: CUDA Time | B6: 5 | C6: 125 | D6: Duration Mean: | E6: 0 | F6: 0 | G6: GPU Time 1 Mean: | H6: 161.95398 | I6: 5.691973 | J6: GPU Time 2 Mean: | K6: 158.09868 | L6: 5.64738 | M6: GPU Time 3 Mean: | N6: 76.129403 | O6: 5.63395 | P6: GPU Time 4 Mean: | Q6: 0 | R6: 0 | S6: GPU Time 5 Mean: | T6: 0 | U6: 0 | V6: GPU Time 6 Mean: | W6: 0 | X6: 0 | Y6: GPU Time 7 Mean: | Z6: 0 | AA6: 0 | AB6: GPU Time 8 Mean: | AC6: 0 | AD6: 0 | AE6: Global Min Mean: | AF6: 1 | AG6: 0 | AH6: Global Max Mean: | AI6: 1 | AJ6: 0 | AK6: Hash Fail Count Mean: | AL6: 0 | AM6: 0
A7: CUDA Time | B7: 6 | C7: 150 | D7: Duration Mean: | E7: 0 | F7: 0 | G7: GPU Time 1 Mean: | H7: 194.3952 | I7: 8.160048 | J7: GPU Time 2 Mean: | K7: 189.77149 | L7: 8.097353 | M7: GPU Time 3 Mean: | N7: 91.411419 | O7: 8.098481 | P7: GPU Time 4 Mean: | Q7: 0 | R7: 0 | S7: GPU Time 5 Mean: | T7: 0 | U7: 0 | V7: GPU Time 6 Mean: | W7: 0 | X7: 0 | Y7: GPU Time 7 Mean: | Z7: 0 | AA7: 0 | AB7: GPU Time 8 Mean: | AC7: 0 | AD7: 0 | AE7: Global Min Mean: | AF7: 1 | AG7: 0 | AH7: Global Max Mean: | AI7: 1 | AJ7: 0 | AK7: Hash Fail Count Mean: | AL7: 0 | AM7: 0
A8: CUDA Time | B8: 7 | C8: 175 | D8: Duration Mean: | E8: 0 | F8: 0 | G8: GPU Time 1 Mean: | H8: 226.84572 | I8: 11.187972 | J8: GPU Time 2 Mean: | K8: 221.45351 | L8: 11.103501 | M8: GPU Time 3 Mean: | N8: 106.69525 | O8: 11.095977 | P8: GPU Time 4 Mean: | Q8: 0 | R8: 0 | S8: GPU Time 5 Mean: | T8: 0 | U8: 0 | V8: GPU Time 6 Mean: | W8: 0 | X8: 0 | Y8: GPU Time 7 Mean: | Z8: 0 | AA8: 0 | AB8: GPU Time 8 Mean: | AC8: 0 | AD8: 0 | AE8: Global Min Mean: | AF8: 1 | AG8: 0 | AH8: Global Max Mean: | AI8: 1 | AJ8: 0 | AK8: Hash Fail Count Mean: | AL8: 0 | AM8: 0
A9: CUDA Time | B9: 8 | C9: 200 | D9: Duration Mean: | E9: 0 | F9: 0 | G9: GPU Time 1 Mean: | H9: 259.29349 | I9: 14.634299 | J9: GPU Time 2 Mean: | K9: 253.13243 | L9: 14.524621 | M9: GPU Time 3 Mean: | N9: 121.98276 | O9: 14.515367 | P9: GPU Time 4 Mean: | Q9: 0 | R9: 0 | S9: GPU Time 5 Mean: | T9: 0 | U9: 0 | V9: GPU Time 6 Mean: | W9: 0 | X9: 0 | Y9: GPU Time 7 Mean: | Z9: 0 | AA9: 0 | AB9: GPU Time 8 Mean: | AC9: 0 | AD9: 0 | AE9: Global Min Mean: | AF9: 1 | AG9: 0 | AH9: Global Max Mean: | AI9: 1 | AJ9: 0 | AK9: Hash Fail Count Mean: | AL9: 0 | AM9: 0
A10: CUDA Time | B10: 9 | C10: 225 | D10: Duration Mean: | E10: 0 | F10: 0 | G10: GPU Time 1 Mean: | H10: 291.74005 | I10: 18.714495 | J10: GPU Time 2 Mean: | K10: 284.81018 | L10: 18.572465 | M10: GPU Time 3 Mean: | N10: 137.26694 | O10: 18.528915 | P10: GPU Time 4 Mean: | Q10: 0 | R10: 0 | S10: GPU Time 5 Mean: | T10: 0 | U10: 0 | V10: GPU Time 6 Mean: | W10: 0 | X10: 0 | Y10: GPU Time 7 Mean: | Z10: 0 | AA10: 0 | AB10: GPU Time 8 Mean: | AC10: 0 | AD10: 0 | AE10: Global Min Mean: | AF10: 1 | AG10: 0 | AH10: Global Max Mean: | AI10: 1 | AJ10: 0 | AK10: Hash Fail Count Mean: | AL10: 0 | AM10: 0
A11: CUDA Time | B11: 10 | C11: 250 | D11: Duration Mean: | E11: 0 | F11: 0 | G11: GPU Time 1 Mean: | H11: 324.16648 | I11: 23.157378 | J11: GPU Time 2 Mean: | K11: 316.46827 | L11: 22.983311 | M11: GPU Time 3 Mean: | N11: 152.53519 | O11: 22.90259 | P11: GPU Time 4 Mean: | Q11: 0 | R11: 0 | S11: GPU Time 5 Mean: | T11: 0 | U11: 0 | V11: GPU Time 6 Mean: | W11: 0 | X11: 0 | Y11: GPU Time 7 Mean: | Z11: 0 | AA11: 0 | AB11: GPU Time 8 Mean: | AC11: 0 | AD11: 0 | AE11: Global Min Mean: | AF11: 1 | AG11: 0 | AH11: Global Max Mean: | AI11: 1 | AJ11: 0 | AK11: Hash Fail Count Mean: | AL11: 0 | AM11: 0
A12: CUDA Time | B12: 11 | C12: 275 | D12: Duration Mean: | E12: 0 | F12: 0 | G12: GPU Time 1 Mean: | H12: 356.59915 | I12: 28.070592 | J12: GPU Time 2 Mean: | K12: 348.13193 | L12: 27.864274 | M12: GPU Time 3 Mean: | N12: 167.80549 | O12: 27.755626 | P12: GPU Time 4 Mean: | Q12: 0 | R12: 0 | S12: GPU Time 5 Mean: | T12: 0 | U12: 0 | V12: GPU Time 6 Mean: | W12: 0 | X12: 0 | Y12: GPU Time 7 Mean: | Z12: 0 | AA12: 0 | AB12: GPU Time 8 Mean: | AC12: 0 | AD12: 0 | AE12: Global Min Mean: | AF12: 1 | AG12: 0 | AH12: Global Max Mean: | AI12: 1 | AJ12: 0 | AK12: Hash Fail Count Mean: | AL12: 0 | AM12: 0
A13: CUDA Time | B13: 12 | C13: 300 | D13: Duration Mean: | E13: 0 | F13: 0 | G13: GPU Time 1 Mean: | H13: 389.04224 | I13: 33.408515 | J13: GPU Time 2 Mean: | K13: 379.80566 | L13: 33.156073 | M13: GPU Time 3 Mean: | N13: 183.08217 | O13: 33.032025 | P13: GPU Time 4 Mean: | Q13: 0 | R13: 0 | S13: GPU Time 5 Mean: | T13: 0 | U13: 0 | V13: GPU Time 6 Mean: | W13: 0 | X13: 0 | Y13: GPU Time 7 Mean: | Z13: 0 | AA13: 0 | AB13: GPU Time 8 Mean: | AC13: 0 | AD13: 0 | AE13: Global Min Mean: | AF13: 1 | AG13: 0 | AH13: Global Max Mean: | AI13: 1 | AJ13: 0 | AK13: Hash Fail Count Mean: | AL13: 0 | AM13: 0
... A361: CUDA opt_one_GPU ant | B361: 20 | C361: 500 | D361: Duration Mean: | E361: 0 | F361: 0 | G361: GPU Time 1 Mean: | H361: 0 | I361: 0 | J361: GPU Time 2 Mean: | K361: 0 | L361: 0 | M361: GPU Time 3 Mean: | N361: 0 | O361: 0 | P361: GPU Time 4 Mean: | Q361: 0 | R361: 0 | S361: GPU Time 5 Mean: | T361: 0 | U361: 0 | V361: GPU Time 6 Mean: | W361: 0 | X361: 0 | Y361: GPU Time 7 Mean: | Z361: 0 | AA361: 0 | AB361: GPU Time 8 Mean: | AC361: 0 | AD361: 0 | AE361: Global Min Mean: | AF361: 0 | AG361: 0 | AH361: Global Max Mean: | AI361: 0 | AJ361: 0 | AK361: Hash Fail Count Mean: | AL361: 0 | AM361: 0
A363: CUDA opt_one_GPU ant local
A364: CUDA opt_one_GPU ant local
A365: CUDA opt_one_GPU ant local
A366: CUDA opt_one_GPU ant local
A367: CUDA opt_one_GPU ant local
A368: CUDA opt_one_GPU ant local
A369: CUDA opt_one_GPU ant local
A370: CUDA opt_one_GPU ant local
A371: CUDA opt_one_GPU ant local
A372: CUDA opt_one_GPU ant local
A373: CUDA opt_one_GPU ant local
A374: CUDA opt_one_GPU ant local
... A381: CUDA opt_one_GPU ant local
A382: non CUDA Time | B382: 1 | C382: 25 | D382: Duration Mean: | E382: 0 | F382: 0 | G382: GPU Time 1 Mean: | H382: 137.20026 | I382: 0.014472 | J382: GPU Time 2 Mean: | K382: 137.07602 | L382: 0.014598 | M382: GPU Time 3 Mean: | N382: 6.23686 | O382: 0.000469 | P382: GPU Time 4 Mean: | Q382: 31.379678 | R382: 0.006756 | S382: GPU Time 5 Mean: | T382: 4.287558 | U382: 0.000163 | V382: GPU Time 6 Mean: | W382: 4.142682 | X382: 6.6e-05 | Y382: GPU Time 7 Mean: | Z382: 18.709029 | AA382: 0.006273 | AB382: GPU Time 8 Mean: | AC382: 96.435027 | AD382: 0.00836 | AE382: Global Min Mean: | AF382: 0.001236 | AG382: 0 | AH382: Global Max Mean: | AI382: 0.995934 | AJ382: 2e-06 | AK382: Hash Fail Count Mean: | AL382: 0 | AM382: 0
A383: non CUDA Time | B383: 2 | C383: 50 | D383: Duration Mean: | E383: 0 | F383: 0 | G383: GPU Time 1 Mean: | H383: 274.58335 | I383: 0.039711 | J383: GPU Time 2 Mean: | K383: 274.33742 | L383: 0.039833 | M383: GPU Time 3 Mean: | N383: 12.473683 | O383: 0.001176 | P383: GPU Time 4 Mean: | Q383: 63.07492 | R383: 0.012661 | S383: GPU Time 5 Mean: | T383: 8.548075 | U383: 0.000216 | V383: GPU Time 6 Mean: | W383: 8.280435 | X383: 0.000107 | Y383: GPU Time 7 Mean: | Z383: 37.767686 | AA383: 0.01257 | AB383: GPU Time 8 Mean: | AC383: 192.74943 | AD383: 0.027876 | AE383: Global Min Mean: | AF383: 0.001231 | AG383: 0 | AH383: Global Max Mean: | AI383: 0.996671 | AJ383: 3e-06 | AK383: Hash Fail Count Mean: | AL383: 0 | AM383: 0
A384: non CUDA Time | B384: 3 | C384: 75 | D384: Duration Mean: | E384: 0 | F384: 0 | G384: GPU Time 1 Mean: | H384: 412.00034 | I384: 0.081293 | J384: GPU Time 2 Mean: | K384: 411.63196 | L384: 0.081439 | M384: GPU Time 3 Mean: | N384: 18.726124 | O384: 0.00206 | P384: GPU Time 4 Mean: | Q384: 94.812746 | R384: 0.018944 | S384: GPU Time 5 Mean: | T384: 12.819685 | U384: 0.00026 | V384: GPU Time 6 Mean: | W384: 12.419868 | X384: 0.000142 | Y384: GPU Time 7 Mean: | Z384: 56.86023 | AA384: 0.01798 | AB384: GPU Time 8 Mean: | AC384: 289.0614 | AD384: 0.060212 | AE384: Global Min Mean: | AF384: 0.001231 | AG384: 0 | AH384: Global Max Mean: | AI384: 0.997654 | AJ384: 3e-06 | AK384: Hash Fail Count Mean: | AL384: 0 | AM384: 0
A385: non CUDA Time | B385: 4 | C385: 100 | D385: Duration Mean: | E385: 0 | F385: 0 | G385: GPU Time 1 Mean: | H385: 549.38811 | I385: 0.125949 | J385: GPU Time 2 Mean: | K385: 548.89677 | L385: 0.125974 | M385: GPU Time 3 Mean: | N385: 24.972109 | O385: 0.002775 | P385: GPU Time 4 Mean: | Q385: 126.52699 | R385: 0.028032 | S385: GPU Time 5 Mean: | T385: 17.09386 | U385: 0.000334 | V385: GPU Time 6 Mean: | W385: 16.561936 | X385: 0.000186 | Y385: GPU Time 7 Mean: | Z385: 75.913452 | AA385: 0.027996 | AB385: GPU Time 8 Mean: | AC385: 385.40497 | AD385: 0.101241 | AE385: Global Min Mean: | AF385: 0.00123 | AG385: 0 | AH385: Global Max Mean: | AI385: 0.998071 | AJ385: 2e-06 | AK385: Hash Fail Count Mean: | AL385: 0 | AM385: 0
A386: non CUDA Time | B386: 5 | C386: 125 | D386: Duration Mean: | E386: 0 | F386: 0 | G386: GPU Time 1 Mean: | H386: 686.78494 | I386: 0.206791 | J386: GPU Time 2 Mean: | K386: 686.17096 | L386: 0.206632 | M386: GPU Time 3 Mean: | N386: 31.215261 | O386: 0.003799 | P386: GPU Time 4 Mean: | Q386: 158.24345 | R386: 0.052535 | S386: GPU Time 5 Mean: | T386: 21.369573 | U386: 0.000538 | V386: GPU Time 6 Mean: | W386: 20.70716 | X386: 0.000239 | Y386: GPU Time 7 Mean: | Z386: 94.98531 | AA386: 0.0532 | AB386: GPU Time 8 Mean: | AC386: 481.73506 | AD386: 0.148397 | AE386: Global Min Mean: | AF386: 0.00123 | AG386: 0 | AH386: Global Max Mean: | AI386: 0.998295 | AJ386: 2e-06 | AK386: Hash Fail Count Mean: | AL386: 0.18 | AM386: 1.5876
A387: non CUDA Time | B387: 6 | C387: 150 | D387: Duration Mean: | E387: 0 | F387: 0 | G387: GPU Time 1 Mean: | H387: 824.23282 | I387: 0.264989 | J387: GPU Time 2 Mean: | K387: 823.49604 | L387: 0.264953 | M387: GPU Time 3 Mean: | N387: 37.462879 | O387: 0.004977 | P387: GPU Time 4 Mean: | Q387: 189.98894 | R387: 0.039903 | S387: GPU Time 5 Mean: | T387: 25.645143 | U387: 0.000708 | V387: GPU Time 6 Mean: | W387: 24.853595 | X387: 0.000242 | Y387: GPU Time 7 Mean: | Z387: 114.08674 | AA387: 0.040777 | AB387: GPU Time 8 Mean: | AC387: 578.01152 | AD387: 0.219942 | AE387: Global Min Mean: | AF387: 0.00123 | AG387: 0 | AH387: Global Max Mean: | AI387: 0.998588 | AJ387: 2e-06 | AK387: Hash Fail Count Mean: | AL387: 0.18 | AM387: 1.5876
A388: non CUDA Time | B388: 7 | C388: 175 | D388: Duration Mean: | E388: 0 | F388: 0 | G388: GPU Time 1 Mean: | H388: 961.5913 | I388: 0.497363 | J388: GPU Time 2 Mean: | K388: 960.73151 | L388: 0.497613 | M388: GPU Time 3 Mean: | N388: 43.706064 | O388: 0.006497 | P388: GPU Time 4 Mean: | Q388: 221.65697 | R388: 0.140737 | S388: GPU Time 5 Mean: | T388: 29.921496 | U388: 0.000843 | V388: GPU Time 6 Mean: | W388: 29.000756 | X388: 0.000287 | Y388: GPU Time 7 Mean: | Z388: 133.10952 | AA388: 0.144827 | AB388: GPU Time 8 Mean: | AC388: 674.24777 | AD388: 0.280058 | AE388: Global Min Mean: | AF388: 0.00123 | AG388: 0 | AH388: Global Max Mean: | AI388: 0.998799 | AJ388: 1e-06 | AK388: Hash Fail Count Mean: | AL388: 0.18 | AM388: 1.5876
A389: non CUDA Time | B389: 8 | C389: 200 | D389: Duration Mean: | E389: 0 | F389: 0 | G389: GPU Time 1 Mean: | H389: 1099.0151 | I389: 0.484376 | J389: GPU Time 2 Mean: | K389: 1098.0325 | L389: 0.484485 | M389: GPU Time 3 Mean: | N389: 49.948224 | O389: 0.007908 | P389: GPU Time 4 Mean: | Q389: 253.39892 | R389: 0.090204 | S389: GPU Time 5 Mean: | T389: 34.194152 | U389: 0.000871 | V389: GPU Time 6 Mean: | W389: 33.145692 | X389: 0.000359 | Y389: GPU Time 7 Mean: | Z389: 152.20909 | AA389: 0.093551 | AB389: GPU Time 8 Mean: | AC389: 770.47705 | AD389: 0.354458 | AE389: Global Min Mean: | AF389: 0.00123 | AG389: 0 | AH389: Global Max Mean: | AI389: 0.998934 | AJ389: 1e-06 | AK389: Hash Fail Count Mean: | AL389: 0.18 | AM389: 1.5876
A390: non CUDA Time | B390: 9 | C390: 225 | D390: Duration Mean: | E390: 0 | F390: 0 | G390: GPU Time 1 Mean: | H390: 1236.4574 | I390: 0.542909 | J390: GPU Time 2 Mean: | K390: 1235.3521 | L390: 0.542558 | M390: GPU Time 3 Mean: | N390: 56.188114 | O390: 0.008973 | P390: GPU Time 4 Mean: | Q390: 285.17271 | R390: 0.064355 | S390: GPU Time 5 Mean: | T390: 38.460914 | U390: 0.000962 | V390: GPU Time 6 Mean: | W390: 37.283513 | X390: 0.000432 | Y390: GPU Time 7 Mean: | Z390: 171.31969 | AA390: 0.070929 | AB390: GPU Time 8 Mean: | AC390: 866.71566 | AD390: 0.433732 | AE390: Global Min Mean: | AF390: 0.00123 | AG390: 0 | AH390: Global Max Mean: | AI390: 0.999123 | AJ390: 1e-06 | AK390: Hash Fail Count Mean: | AL390: 0.18 | AM390: 1.5876
A391: non CUDA Time | B391: 10 | C391: 250 | D391: Duration Mean: | E391: 0 | F391: 0 | G391: GPU Time 1 Mean: | H391: 1373.8897 | I391: 0.584616 | J391: GPU Time 2 Mean: | K391: 1372.6617 | L391: 0.583637 | M391: GPU Time 3 Mean: | N391: 62.431064 | O391: 0.010263 | P391: GPU Time 4 Mean: | Q391: 316.92664 | R391: 0.065051 | S391: GPU Time 5 Mean: | T391: 42.72949 | U391: 0.001068 | V391: GPU Time 6 Mean: | W391: 41.419313 | X391: 0.000585 | Y391: GPU Time 7 Mean: | Z391: 190.41049 | AA391: 0.068299 | AB391: GPU Time 8 Mean: | AC391: 962.96334 | AD391: 0.513604 | AE391: Global Min Mean: | AF391: 0.00123 | AG391: 0 | AH391: Global Max Mean: | AI391: 0.999167 | AJ391: 1e-06 | AK391: Hash Fail Count Mean: | AL391: 4.06 | AM391: 737.8564
A392: non CUDA Time | B392: 11 | C392: 275 | D392: Duration Mean: | E392: 0 | F392: 0 | G392: GPU Time 1 Mean: | H392: 1511.3348 | I392: 0.699689 | J392: GPU Time 2 Mean: | K392: 1509.9841 | L392: 0.698923 | M392: GPU Time 3 Mean: | N392: 68.670974 | O392: 0.012527 | P392: GPU Time 4 Mean: | Q392: 348.70461 | R392: 0.070614 | S392: GPU Time 5 Mean: | T392: 46.999493 | U392: 0.001145 | V392: GPU Time 6 Mean: | W392: 45.556641 | X392: 0.000665 | Y392: GPU Time 7 Mean: | Z392: 209.52142 | AA392: 0.072956 | AB392: GPU Time 8 Mean: | AC392: 1059.1997 | AD392: 0.628176 | AE392: Global Min Mean: | AF392: 0.00123 | AG392: 0 | AH392: Global Max Mean: | AI392: 0.999233 | AJ392: 1e-06 | AK392: Hash Fail Count Mean: | AL392: 4.06 | AM392: 737.8564
A393: non CUDA Time | B393: 12 | C393: 300 | D393: Duration Mean: | E393: 0 | F393: 0 | G393: GPU Time 1 Mean: | H393: 1648.8048 | I393: 0.842482 | J393: GPU Time 2 Mean: | K393: 1647.3315 | L393: 0.841565 | M393: GPU Time 3 Mean: | N393: 74.913761 | O393: 0.013793 | P393: GPU Time 4 Mean: | Q393: 380.49443 | R393: 0.085125 | S393: GPU Time 5 Mean: | T393: 51.269151 | U393: 0.001126 | V393: GPU Time 6 Mean: | W393: 49.697415 | X393: 0.000782 | Y393: GPU Time 7 Mean: | Z393: 228.64207 | AA393: 0.086363 | AB393: GPU Time 8 Mean: | AC393: 1155.4456 | AD393: 0.766586 | AE393: Global Min Mean: | AF393: 0.00123 | AG393: 0 | AH393: Global Max Mean: | AI393: 0.999286 | AJ393: 1e-06 | AK393: Hash Fail Count Mean: | AL393: 4.06 | AM393: 737.8564
... A781: CUDA opt ant par global | B781: 20 | C781: 500 | D781: Duration Mean: | E781: 0 | F781: 0 | G781: GPU Time 1 Mean: | H781: 436.32768 | I781: 0.063319 | J781: GPU Time 2 Mean: | K781: 144.75265 | L781: 0.015431 | M781: GPU Time 3 Mean: | N781: 0 | O781: 0 | P781: GPU Time 4 Mean: | Q781: 0 | R781: 0 | S781: GPU Time 5 Mean: | T781: 0 | U781: 0 | V781: GPU Time 6 Mean: | W781: 0 | X781: 0 | Y781: GPU Time 7 Mean: | Z781: 0 | AA781: 0 | AB781: GPU Time 8 Mean: | AC781: 0 | AD781: 0 | AE781: Global Min Mean: | AF781: 32767 | AG781: 0 | AH781: Global Max Mean: | AI781: -32767 | AJ781: 0 | AK781: Hash Fail Count Mean: | AL781: 0.24 | AM781: 0.1824

Sheet 42p trace
A1: Device 0: Orin | B1: Max thread in blocks: 1024 | C1: Max thread in blocks by axis: (1024, 1024, 64) | D1: Max blocks by axis: (2147483647, 65535, 65535) | E1: PARAMETR_SIZE: 42 | F1: MAX_VALUE_SIZE: 5 | G1: NAME_FILE_GRAPH: Parametr_Graph/test42,txt | H1: ANT_SIZE: 500 | I1: KOL_ITERATION: 500 | J1: KOL_PROGON_STATISTICS: 50 | K1: PARAMETR_Q: 1 | L1: PARAMETR_RO: 0,999 | M1: HASH_TABLE_SIZE: 10000000 | N1: MAX_PROBES: 10000 | O1: TYPE_ACO: 1 | P1: ACOCCyN_KOL_ITERATION: 50 | Q1: PRINT_INFORMATION: false
A2: Time CUDA Time: | B2: 706.989 | C2: 691.656 | D2: 655.456 | E2: 639.925 | F2: 316.035 | G2: 0 | H2: 316.035 | I2: 1 | J2: 1 | K2: 0
A3: Time CUDA Time: | B3: 703.513 | C3: 683.02 | D3: 646.836 | E3: 631.443 | F3: 303.438 | G3: 0 | H3: 303.438 | I3: 1 | J3: 1 | K3: 0
A4: Time CUDA Time: | B4: 708.87 | C4: 692.485 | D4: 656.588 | E4: 641.283 | F4: 313.452 | G4: 0 | H4: 313.452 | I4: 1 | J4: 1 | K4: 0
A5: Time CUDA Time: | B5: 699.056 | C5: 682.622 | D5: 646.762 | E5: 631.366 | F5: 303.264 | G5: 0 | H5: 303.264 | I5: 1 | J5: 1 | K5: 0
A6: Time CUDA Time: | B6: 694.649 | C6: 678.045 | D6: 641.825 | E6: 626.46 | F6: 298.487 | G6: 0 | H6: 298.487 | I6: 1 | J6: 1 | K6: 0
A7: Time CUDA Time: | B7: 699.714 | C7: 683.35 | D7: 647.447 | E7: 632.096 | F7: 304.236 | G7: 0 | H7: 304.236 | I7: 1 | J7: 1 | K7: 0
A8: Time CUDA Time: | B8: 698.218 | C8: 681.955 | D8: 646.166 | E8: 630.797 | F8: 302.894 | G8: 0 | H8: 302.894 | I8: 1 | J8: 1 | K8: 0
A9: Time CUDA Time: | B9: 706.057 | C9: 689.542 | D9: 653.653 | E9: 638.325 | F9: 310.336 | G9: 0 | H9: 310.336 | I9: 1 | J9: 1 | K9: 0
A10: Time CUDA Time: | B10: 689.361 | C10: 673.209 | D10: 637.313 | E10: 621.997 | F10: 294.289 | G10: 0 | H10: 294.289 | I10: 1 | J10: 1 | K10: 0
A11: Time CUDA Time: | B11: 691.71 | C11: 675.37 | D11: 639.487 | E11: 624.162 | F11: 296.669 | G11: 0 | H11: 296.669 | I11: 1 | J11: 1 | K11: 0
A12: Time CUDA Time: | B12: 697.663 | C12: 681.391 | D12: 645.049 | E12: 629.674 | F12: 302.076 | G12: 0 | H12: 302.076 | I12: 1 | J12: 1 | K12: 0
A13: Time CUDA Time: | B13: 719.513 | C13: 703.299 | D13: 667.567 | E13: 651.878 | F13: 324.293 | G13: 0 | H13: 324.293 | I13: 1 | J13: 1 | K13: 0
... A54: Time CUDA Time: | B54: 691.265 | C54: 674.577 | D54: 638.428 | E54: 623.095 | F54: 295.177 | G54: 0 | H54: 295.177 | I54: 1 | J54: 1 | K54: 0
A55: Time CUDA Time: | B55: 698.476 | C55: 682.161 | D55: 646.478 | E55: 631.131 | F55: 303.294 | G55: 0 | H55: 303.294 | I55: 1 | J55: 1 | K55: 0 | R55: МО | U55: дисп | X55: CI
A56: Time CUDA Time: | B56: 701.883 | C56: 685.629 | D56: 649.659 | E56: 634.286 | F56: 306.391 | G56: 0 | H56: 306.391 | I56: 1 | J56: 1 | K56: 0 | R56: =AVERAGE(B7:B56) -> 700.88278 | S56: =AVERAGE(C7:C56) -> 684.58224 | U56: =_xlfn.VAR.P(B7:B56) -> 93.44924 | V56: =_xlfn.VAR.P(C7:C56) -> 93.903754 | X56: =1.96*SQRT(U56)/50 -> 0.37894306 | Y56: =1.96*SQRT(V56)/50 -> 0.37986348
A57: Time CUDA time: | B57: 35050.812 | C57: sec
A58: Time CUDA: | B58: 705.415 | C58: 0 | D58: 0 | E58: 0 | F58: 0 | G58: 0 | H58: 0 | I58: 1 | J58: 1 | K58: 0
A59: Time CUDA: | B59: 726.961 | C59: 0 | D59: 0 | E59: 0 | F59: 0 | G59: 0 | H59: 0 | I59: 1 | J59: 1 | K59: 0
A60: Time CUDA: | B60: 736.893 | C60: 0 | D60: 0 | E60: 0 | F60: 0 | G60: 0 | H60: 0 | I60: 1 | J60: 1 | K60: 0
A61: Time CUDA: | B61: 731.306 | C61: 0 | D61: 0 | E61: 0 | F61: 0 | G61: 0 | H61: 0 | I61: 1 | J61: 1 | K61: 0
A62: Time CUDA: | B62: 734.388 | C62: 0 | D62: 0 | E62: 0 | F62: 0 | G62: 0 | H62: 0 | I62: 1 | J62: 1 | K62: 0
A63: Time CUDA: | B63: 726.703 | C63: 0 | D63: 0 | E63: 0 | F63: 0 | G63: 0 | H63: 0 | I63: 1 | J63: 1 | K63: 0
A64: Time CUDA: | B64: 721.228 | C64: 0 | D64: 0 | E64: 0 | F64: 0 | G64: 0 | H64: 0 | I64: 1 | J64: 1 | K64: 0
A65: Time CUDA: | B65: 739.302 | C65: 0 | D65: 0 | E65: 0 | F65: 0 | G65: 0 | H65: 0 | I65: 1 | J65: 1 | K65: 0
A66: Time CUDA: | B66: 721.464 | C66: 0 | D66: 0 | E66: 0 | F66: 0 | G66: 0 | H66: 0 | I66: 1 | J66: 1 | K66: 0
A67: Time CUDA: | B67: 716.539 | C67: 0 | D67: 0 | E67: 0 | F67: 0 | G67: 0 | H67: 0 | I67: 1 | J67: 1 | K67: 0
A68: Time CUDA: | B68: 726.833 | C68: 0 | D68: 0 | E68: 0 | F68: 0 | G68: 0 | H68: 0 | I68: 1 | J68: 1 | K68: 0
A69: Time CUDA: | B69: 731.506 | C69: 0 | D69: 0 | E69: 0 | F69: 0 | G69: 0 | H69: 0 | I69: 1 | J69: 1 | K69: 0
... A110: Time CUDA: | B110: 731.831 | C110: 0 | D110: 0 | E110: 0 | F110: 0 | G110: 0 | H110: 0 | I110: 1 | J110: 1 | K110: 0
A111: Time CUDA: | B111: 724.396 | C111: 0 | D111: 0 | E111: 0 | F111: 0 | G111: 0 | H111: 0 | I111: 1 | J111: 1 | K111: 0 | R111: МО | U111: дисп | X111: CI
A112: Time CUDA: | B112: 730.819 | C112: 0 | D112: 0 | E112: 0 | F112: 0 | G112: 0 | H112: 0 | I112: 1 | J112: 1 | K112: 0 | R112: =AVERAGE(B63:B112) -> 727.69708 | S112: =AVERAGE(C63:C112) -> 0 | U112: =_xlfn.VAR.P(B63:B112) -> 106.58589 | V112: =_xlfn.VAR.P(C63:C112) -> 0 | X112: =1.96*SQRT(U112)/50 -> 0.40470254 | Y112: =1.96*SQRT(V112)/50 -> 0
A113: Time CUDA: | B113: 36418.853 | C113: sec
A114: Time CUDA non hash: | B114: 2311.34 | C114: 2309.68 | D114: 2272.07 | E114: 2256.55 | F114: 303.398 | G114: 1 | H114: 1 | I114: 0
A115: Time CUDA non hash: | B115: 2446.37 | C115: 2445.18 | D115: 2407.45 | E115: 2388.94 | F115: 372.86 | G115: 1 | H115: 1 | I115: 0
A116: Time CUDA non hash: | B116: 2860.19 | C116: 2858.74 | D116: 2779.34 | E116: 2753.12 | F116: 566.253 | G116: 1 | H116: 1 | I116: 0
A117: Time CUDA non hash: | B117: 2922 | C117: 2920.29 | D117: 2837.12 | E117: 2808.98 | F117: 566.237 | G117: 1 | H117: 1 | I117: 0
A118: Time CUDA non hash: | B118: 2947.27 | C118: 2945.4 | D118: 2879.85 | E118: 2851.86 | F118: 604.406 | G118: 1 | H118: 1 | I118: 0
A119: Time CUDA non hash: | B119: 2952.78 | C119: 2950.95 | D119: 2885 | E119: 2857.02 | F119: 608.668 | G119: 1 | H119: 1 | I119: 0
A120: Time CUDA non hash: | B120: 2941.91 | C120: 2940.22 | D120: 2843.64 | E120: 2815.71 | F120: 575.215 | G120: 1 | H120: 1 | I120: 0
...

Sheet 42 end
D2: T_start | E2: T_Delt | F2: T1 | G2: T2 | H2: T3
A3: 1 | C3: =OFFSET('42p stat'!$A$1,A3*20,0) -> CUDA Time | D3: =OFFSET('42p trace'!$R$56,(A3-1)*56,0)-OFFSET('42p trace'!$S$56,(A3-1)*56,0) -> 16.30054 | E3: =OFFSET('42p trace'!$S$56,(A3-1)*56,0)-OFFSET('42p stat'!$H$1,A3*20,0) -> 35.986337 | F3: =OFFSET('42p stat'!$H$1,A3*20,0)-OFFSET('42p stat'!$K$1,A3*20,0) -> 15.385473 | G3: =OFFSET('42p stat'!$K$1,A3*20,0)-OFFSET('42p stat'!$N$1,A3*20,0) -> 327.87679 | H3: =OFFSET('42p stat'!$N$1,A3*20,0) -> 305.33364
A4: 1 | C4: =OFFSET('42p stat'!$A$1,A4*20,0) -> CUDA Time | D4: =OFFSET('42p trace'!$U$56,(A4-1)*56,0) -> 93.44924 | E4: =OFFSET('42p trace'!$V$56,(A4-1)*56,0) -> 93.903754 | F4: =OFFSET('42p stat'!$H$1,A4*20,1) -> 94.455915 | G4: =OFFSET('42p stat'!$K$1,A4*20,1) -> 93.746646 | H4: =OFFSET('42p stat'!$N$1,A4*20,1) -> 93.519511
A5: 2 | C5: =OFFSET('42p stat'!$A$1,A5*20,0) -> CUDA | D5: =OFFSET('42p trace'!$R$56,(A5-1)*56,0)-OFFSET('42p trace'!$S$56,(A5-1)*56,0) -> 727.69708 | E5: =OFFSET('42p trace'!$S$56,(A5-1)*56,0)-OFFSET('42p stat'!$H$1,A5*20,0) -> 0 | F5: =OFFSET('42p stat'!$H$1,A5*20,0)-OFFSET('42p stat'!$K$1,A5*20,0) -> 0 | G5: =OFFSET('42p stat'!$K$1,A5*20,0)-OFFSET('42p stat'!$N$1,A5*20,0) -> 0 | H5: =OFFSET('42p stat'!$N$1,A5*20,0) -> 0
A6: 2 | C6: =OFFSET('42p stat'!$A$1,A6*20,0) -> CUDA | D6: =OFFSET('42p trace'!$U$56,(A6-1)*56,0) -> 106.58589 | E6: =OFFSET('42p trace'!$V$56,(A6-1)*56,0) -> 0 | F6: =OFFSET('42p stat'!$H$1,A6*20,1) -> 0 | G6: =OFFSET('42p stat'!$K$1,A6*20,1) -> 0 | H6: =OFFSET('42p stat'!$N$1,A6*20,1) -> 0
A7: 3 | C7: =OFFSET('42p stat'!$A$1,A7*20,0) -> CUDA non hash | D7: =OFFSET('42p trace'!$R$56,(A7-1)*56,0)-OFFSET('42p trace'!$S$56,(A7-1)*56,0) -> 1.7196 | E7: =OFFSET('42p trace'!$S$56,(A7-1)*56,0)-OFFSET('42p stat'!$H$1,A7*20,0) -> 89.566318 | F7: =OFFSET('42p stat'!$H$1,A7*20,0)-OFFSET('42p stat'!$K$1,A7*20,0) -> 28.030967 | G7: =OFFSET('42p stat'!$K$1,A7*20,0)-OFFSET('42p stat'!$N$1,A7*20,0) -> 2241.4456 | H7: =OFFSET('42p stat'!$N$1,A7*20,0) -> 594.64732
A8: 3 | C8: =OFFSET('42p stat'!$A$1,A8*20,0) -> CUDA non hash | D8: =OFFSET('42p trace'!$U$56,(A8-1)*56,0) -> 424.57193 | E8: =OFFSET('42p trace'!$V$56,(A8-1)*56,0) -> 424.36393 | F8: =OFFSET('42p stat'!$H$1,A8*20,1) -> 405.72798 | G8: =OFFSET('42p stat'!$K$1,A8*20,1) -> 404.79683 | H8: =OFFSET('42p stat'!$N$1,A8*20,1) -> 393.16623
A9: 4 | C9: =OFFSET('42p stat'!$A$1,A9*20,0) -> CUDA ant | D9: =OFFSET('42p trace'!$R$56,(A9-1)*56,0)-OFFSET('42p trace'!$S$56,(A9-1)*56,0) -> 16.4351 | E9: =OFFSET('42p trace'!$S$56,(A9-1)*56,0)-OFFSET('42p stat'!$H$1,A9*20,0) -> 36.016446 | F9: =OFFSET('42p stat'!$H$1,A9*20,0)-OFFSET('42p stat'!$K$1,A9*20,0) -> 19.608907 | G9: =OFFSET('42p stat'!$K$1,A9*20,0)-OFFSET('42p stat'!$N$1,A9*20,0) -> 127.653 | H9: =OFFSET('42p stat'!$N$1,A9*20,0) -> 347.00732
A10: 4 | C10: =OFFSET('42p stat'!$A$1,A10*20,0) -> CUDA ant | D10: =OFFSET('42p trace'!$U$56,(A10-1)*56,0) -> 8.0951522 | E10: =OFFSET('42p trace'!$V$56,(A10-1)*56,0) -> 7.7988559 | F10: =OFFSET('42p stat'!$H$1,A10*20,1) -> 7.687903 | G10: =OFFSET('42p stat'!$K$1,A10*20,1) -> 7.696488 | H10: =OFFSET('42p stat'!$N$1,A10*20,1) -> 7.672362
A11: 5 | C11: =OFFSET('42p stat'!$A$1,A11*20,0) -> CUDA ant par | D11: =OFFSET('42p trace'!$R$56,(A11-1)*56,0)-OFFSET('42p trace'!$S$56,(A11-1)*56,0) -> 16.54152 | E11: =OFFSET('42p trace'!$S$56,(A11-1)*56,0)-OFFSET('42p stat'!$H$1,A11*20,0) -> 35.913695 | F11: =OFFSET('42p stat'!$H$1,A11*20,0)-OFFSET('42p stat'!$K$1,A11*20,0) -> 15.442489 | G11: =OFFSET('42p stat'!$K$1,A11*20,0)-OFFSET('42p stat'!$N$1,A11*20,0) -> 127.7868 | H11: =OFFSET('42p stat'!$N$1,A11*20,0) -> 300.90713
A12: 5 | C12: =OFFSET('42p stat'!$A$1,A12*20,0) -> CUDA ant par | D12: =OFFSET('42p trace'!$U$56,(A12-1)*56,0) -> 0.12218143 | E12: =OFFSET('42p trace'!$V$56,(A12-1)*56,0) -> 0.074531386 | F12: =OFFSET('42p stat'!$H$1,A12*20,1) -> 0.059966 | G12: =OFFSET('42p stat'!$K$1,A12*20,1) -> 0.058228 | H12: =OFFSET('42p stat'!$N$1,A12*20,1) -> 0.024391
A13: 6 | C13: =OFFSET('42p stat'!$A$1,A13*20,0) -> CUDA ant non hash | D13: =OFFSET('42p trace'!$R$56,(A13-1)*56,0)-OFFSET('42p trace'!$S$56,(A13-1)*56,0) -> 16.67042 | E13: =OFFSET('42p trace'!$S$56,(A13-1)*56,0)-OFFSET('42p stat'!$H$1,A13*20,0) -> 35.940147 | F13: =OFFSET('42p stat'!$H$1,A13*20,0)-OFFSET('42p stat'!$K$1,A13*20,0) -> 19.569468 | G13: =OFFSET('42p stat'!$K$1,A13*20,0)-OFFSET('42p stat'!$N$1,A13*20,0) -> 96.593672 | H13: =OFFSET('42p stat'!$N$1,A13*20,0) -> 346.39669
A14: 6 | C14: =OFFSET('42p stat'!$A$1,A14*20,0) -> CUDA ant non hash | D14: =OFFSET('42p trace'!$U$56,(A14-1)*56,0) -> 7.8365036 | E14: =OFFSET('42p trace'!$V$56,(A14-1)*56,0) -> 7.7620559 | F14: =OFFSET('42p stat'!$H$1,A14*20,1) -> 7.711735 | G14: =OFFSET('42p stat'!$K$1,A14*20,1) -> 7.735126 | H14: =OFFSET('42p stat'!$N$1,A14*20,1) -> 7.760416
A15: 7 | C15: =OFFSET('42p stat'!$A$1,A15*20,0) -> CUDA ant add CPU Time | D15: =OFFSET('42p trace'!$R$56,(A15-1)*56,0)-OFFSET('42p trace'!$S$56,(A15-1)*56,0) -> 17.13512 | E15: =OFFSET('42p trace'!$S$56,(A15-1)*56,0)-OFFSET('42p stat'!$H$1,A15*20,0) -> 308.75334 | F15: =OFFSET('42p stat'!$H$1,A15*20,0)-OFFSET('42p stat'!$K$1,A15*20,0) -> 2.265325 | G15: =OFFSET('42p stat'!$K$1,A15*20,0)-OFFSET('42p stat'!$N$1,A15*20,0) -> 202.07982 | H15: =OFFSET('42p stat'!$N$1,A15*20,0) -> 123.44107
A16: 7 | C16: =OFFSET('42p stat'!$A$1,A16*20,0) -> CUDA ant add CPU Time | D16: =OFFSET('42p trace'!$U$56,(A16-1)*56,0) -> 1.7924289 | E16: =OFFSET('42p trace'!$V$56,(A16-1)*56,0) -> 1.5996432 | F16: =OFFSET('42p stat'!$H$1,A16*20,1) -> 0.496936 | G16: =OFFSET('42p stat'!$K$1,A16*20,1) -> 0.682811 | H16: =OFFSET('42p stat'!$N$1,A16*20,1) -> 0.005081
A17: 8 | C17: =OFFSET('42p stat'!$A$1,A17*20,0) -> CUDA ant add CPU | D17: =OFFSET('42p trace'!$R$56,(A17-1)*56,0)-OFFSET('42p trace'!$S$56,(A17-1)*56,0) -> 638.64558 | E17: =OFFSET('42p trace'!$S$56,(A17-1)*56,0)-OFFSET('42p stat'!$H$1,A17*20,0) -> 0 | F17: =OFFSET('42p stat'!$H$1,A17*20,0)-OFFSET('42p stat'!$K$1,A17*20,0) -> 0 | G17: =OFFSET('42p stat'!$K$1,A17*20,0)-OFFSET('42p stat'!$N$1,A17*20,0) -> 0 | H17: =OFFSET('42p stat'!$N$1,A17*20,0) -> 0
A18: 8 | C18: =OFFSET('42p stat'!$A$1,A18*20,0) -> CUDA ant add CPU | D18: =OFFSET('42p trace'!$U$56,(A18-1)*56,0) -> 2.2310228 | E18: =OFFSET('42p trace'!$V$56,(A18-1)*56,0) -> 0 | F18: =OFFSET('42p stat'!$H$1,A18*20,1) -> 0 | G18: =OFFSET('42p stat'!$K$1,A18*20,1) -> 0 | H18: =OFFSET('42p stat'!$N$1,A18*20,1) -> 0
A19: 9 | C19: =OFFSET('42p stat'!$A$1,A19*20,0) -> CUDA ant add CPU non hash | D19: =OFFSET('42p trace'!$R$56,(A19-1)*56,0)-OFFSET('42p trace'!$S$56,(A19-1)*56,0) -> 17.84836 | E19: =OFFSET('42p trace'!$S$56,(A19-1)*56,0)-OFFSET('42p stat'!$H$1,A19*20,0) -> 336.75326 | F19: =OFFSET('42p stat'!$H$1,A19*20,0)-OFFSET('42p stat'!$K$1,A19*20,0) -> 2.11423 | G19: =OFFSET('42p stat'!$K$1,A19*20,0)-OFFSET('42p stat'!$N$1,A19*20,0) -> 184.93332 | H19: =OFFSET('42p stat'!$N$1,A19*20,0) -> 123.27213
A20: 9 | C20: =OFFSET('42p stat'!$A$1,A20*20,0) -> CUDA ant add CPU non hash | D20: =OFFSET('42p trace'!$U$56,(A20-1)*56,0) -> 620.10098 | E20: =OFFSET('42p trace'!$V$56,(A20-1)*56,0) -> 596.67717 | F20: =OFFSET('42p stat'!$H$1,A20*20,1) -> 71.905505 | G20: =OFFSET('42p stat'!$K$1,A20*20,1) -> 71.864339 | H20: =OFFSET('42p stat'!$N$1,A20*20,1) -> 0.007668
A21: 10 | C21: =OFFSET('42p stat'!$A$1,A21*20,0) -> CUDA ant add CPU12 | D21: =OFFSET('42p trace'!$R$56,(A21-1)*56,0)-OFFSET('42p trace'!$S$56,(A21-1)*56,0) -> 51.5926 | E21: =OFFSET('42p trace'!$S$56,(A21-1)*56,0)-OFFSET('42p stat'!$H$1,A21*20,0) -> 9.211581 | F21: =OFFSET('42p stat'!$H$1,A21*20,0)-OFFSET('42p stat'!$K$1,A21*20,0) -> 28.08417 | G21: =OFFSET('42p stat'!$K$1,A21*20,0)-OFFSET('42p stat'!$N$1,A21*20,0) -> 2950.8278 | H21: =OFFSET('42p stat'!$N$1,A21*20,0) -> 601.08268
A22: 10 | C22: =OFFSET('42p stat'!$A$1,A22*20,0) -> CUDA ant add CPU12 | D22: =OFFSET('42p trace'!$U$56,(A22-1)*56,0) -> 34.669003 | E22: =OFFSET('42p trace'!$V$56,(A22-1)*56,0) -> 32.934028 | F22: =OFFSET('42p stat'!$H$1,A22*20,1) -> 32.72886 | G22: =OFFSET('42p stat'!$K$1,A22*20,1) -> 32.743511 | H22: =OFFSET('42p stat'!$N$1,A22*20,1) -> 0.388133
A23: 11 | C23: =OFFSET('42p stat'!$A$1,A23*20,0) -> CUDA opt | D23: =OFFSET('42p trace'!$R$56,(A23-1)*56,0)-OFFSET('42p trace'!$S$56,(A23-1)*56,0) -> 725.44534 | E23: =OFFSET('42p trace'!$S$56,(A23-1)*56,0)-OFFSET('42p stat'!$H$1,A23*20,0) -> 0 | F23: =OFFSET('42p stat'!$H$1,A23*20,0)-OFFSET('42p stat'!$K$1,A23*20,0) -> 0 | G23: =OFFSET('42p stat'!$K$1,A23*20,0)-OFFSET('42p stat'!$N$1,A23*20,0) -> 0 | H23: =OFFSET('42p stat'!$N$1,A23*20,0) -> 0
A24: 11 | C24: =OFFSET('42p stat'!$A$1,A24*20,0) -> CUDA opt | D24: =OFFSET('42p trace'!$U$56,(A24-1)*56,0) -> 149.51335 | E24: =OFFSET('42p trace'!$V$56,(A24-1)*56,0) -> 0 | F24: =OFFSET('42p stat'!$H$1,A24*20,1) -> 0 | G24: =OFFSET('42p stat'!$K$1,A24*20,1) -> 0 | H24: =OFFSET('42p stat'!$N$1,A24*20,1) -> 0
A25: 12 | C25: =OFFSET('42p stat'!$A$1,A25*20,0) -> CUDA opt Time | D25: =OFFSET('42p trace'!$R$56,(A25-1)*56,0)-OFFSET('42p trace'!$S$56,(A25-1)*56,0) -> 17.4517 | E25: =OFFSET('42p trace'!$S$56,(A25-1)*56,0)-OFFSET('42p stat'!$H$1,A25*20,0) -> 35.350388 | F25: =OFFSET('42p stat'!$H$1,A25*20,0)-OFFSET('42p stat'!$K$1,A25*20,0) -> 319.02557 | G25: =OFFSET('42p stat'!$K$1,A25*20,0)-OFFSET('42p stat'!$N$1,A25*20,0) -> 328.43317 | H25: =OFFSET('42p stat'!$N$1,A25*20,0) -> 0
A26: 12 | C26: =OFFSET('42p stat'!$A$1,A26*20,0) -> CUDA opt Time | D26: =OFFSET('42p trace'!$U$56,(A26-1)*56,0) -> 137.00832 | E26: =OFFSET('42p trace'!$V$56,(A26-1)*56,0) -> 135.9693 | F26: =OFFSET('42p stat'!$H$1,A26*20,1) -> 135.29772 | G26: =OFFSET('42p stat'!$K$1,A26*20,1) -> 0.021221 | H26: =OFFSET('42p stat'!$N$1,A26*20,1) -> 0
A27: 13 | C27: =OFFSET('42p stat'!$A$1,A27*20,0) -> CUDA opt non hash | D27: =OFFSET('42p trace'!$R$56,(A27-1)*56,0)-OFFSET('42p trace'!$S$56,(A27-1)*56,0) -> 1.85504 | E27: =OFFSET('42p trace'!$S$56,(A27-1)*56,0)-OFFSET('42p stat'!$H$1,A27*20,0) -> 35.207596 | F27: =OFFSET('42p stat'!$H$1,A27*20,0)-OFFSET('42p stat'!$K$1,A27*20,0) -> 312.07708 | G27: =OFFSET('42p stat'!$K$1,A27*20,0)-OFFSET('42p stat'!$N$1,A27*20,0) -> 176.00861 | H27: =OFFSET('42p stat'!$N$1,A27*20,0) -> 0
A28: 13 | C28: =OFFSET('42p stat'!$A$1,A28*20,0) -> CUDA opt non hash | D28: =OFFSET('42p trace'!$U$56,(A28-1)*56,0) -> 86.204173 | E28: =OFFSET('42p trace'!$V$56,(A28-1)*56,0) -> 85.088052 | F28: =OFFSET('42p stat'!$H$1,A28*20,1) -> 85.153428 | G28: =OFFSET('42p stat'!$K$1,A28*20,1) -> 0.013061 | H28: =OFFSET('42p stat'!$N$1,A28*20,1) -> 0
K29: 1.96 | L29: 50
D30: T_start | E30: T_Delt | F30: T1 | G30: T2 | H30: T3 | J30: summ | K30: 2 этап/ общее | L30: ДИ
A31: 1 | C31: =OFFSET('42p stat'!$A$1,A31*20,0) -> CUDA Time | D31: =OFFSET('42p trace'!$R$56,(A31-1)*56,0)-OFFSET('42p trace'!$S$56,(A31-1)*56,0) -> 16.30054 | E31: =OFFSET('42p trace'!$S$56,(A31-1)*56,0)-OFFSET('42p stat'!$H$1,A31*20,0) -> 35.986337 | F31: =OFFSET('42p stat'!$H$1,A31*20,0)-OFFSET('42p stat'!$K$1,A31*20,0) -> 15.385473 | G31: =OFFSET('42p stat'!$K$1,A31*20,0)-OFFSET('42p stat'!$N$1,A31*20,0) -> 327.87679 | H31: =OFFSET('42p stat'!$N$1,A31*20,0) -> 305.33364 | J31: =SUM(E31:H31) -> 684.58224 | K31: =G31/J31 -> 0.47894434 | L31: =$K$29*POWER(K31,2)*SQRT(G138/(POWER(G31,2)*$L$29)+J138/(POWER(J31,2)*$L$29)) -> 0.0027517104
A32: 2 | C32: =OFFSET('42p stat'!$A$1,A32*20,0) -> CUDA | D32: =OFFSET('42p trace'!$R$56,(A32-1)*56,0)-OFFSET('42p trace'!$S$56,(A32-1)*56,0) -> 727.69708 | E32: =OFFSET('42p trace'!$S$56,(A32-1)*56,0)-OFFSET('42p stat'!$H$1,A32*20,0) -> 0 | F32: =OFFSET('42p stat'!$H$1,A32*20,0)-OFFSET('42p stat'!$K$1,A32*20,0) -> 0 | G32: =OFFSET('42p stat'!$K$1,A32*20,0)-OFFSET('42p stat'!$N$1,A32*20,0) -> 0 | H32: =OFFSET('42p stat'!$N$1,A32*20,0) -> 0 | J32: =SUM(D32:H32) -> 727.69708 | K32: =G32/J32 -> 0 | L32: =$K$29*POWER(K32,2)*SQRT(G139/(POWER(G32,2)*$L$29)+J139/(POWER(J32,2)*$L$29)) -> #DIV/0!
A33: 3 | C33: =OFFSET('42p stat'!$A$1,A33*20,0) -> CUDA non hash | D33: =OFFSET('42p trace'!$R$56,(A33-1)*56,0)-OFFSET('42p trace'!$S$56,(A33-1)*56,0) -> 1.7196 | E33: =OFFSET('42p trace'!$S$56,(A33-1)*56,0)-OFFSET('42p stat'!$H$1,A33*20,0) -> 89.566318 | F33: =OFFSET('42p stat'!$H$1,A33*20,0)-OFFSET('42p stat'!$K$1,A33*20,0) -> 28.030967 | G33: =OFFSET('42p stat'!$K$1,A33*20,0)-OFFSET('42p stat'!$N$1,A33*20,0) -> 2241.4456 | H33: =OFFSET('42p stat'!$N$1,A33*20,0) -> 594.64732 | J33: =SUM(E33:H33) -> 2953.6902 | K33: =G33/J33 -> 0.75886279 | L33: =$K$29*POWER(K33,2)*SQRT(G140/(POWER(G33,2)*$L$29)+J140/(POWER(J33,2)*$L$29)) -> 0.0028368551
A34: 4 | C34: =OFFSET('42p stat'!$A$1,A34*20,0) -> CUDA ant | D34: =OFFSET('42p trace'!$R$56,(A34-1)*56,0)-OFFSET('42p trace'!$S$56,(A34-1)*56,0) -> 16.4351 | E34: =OFFSET('42p trace'!$S$56,(A34-1)*56,0)-OFFSET('42p stat'!$H$1,A34*20,0) -> 36.016446 | F34: =OFFSET('42p stat'!$H$1,A34*20,0)-OFFSET('42p stat'!$K$1,A34*20,0) -> 19.608907 | G34: =OFFSET('42p stat'!$K$1,A34*20,0)-OFFSET('42p stat'!$N$1,A34*20,0) -> 127.653 | H34: =OFFSET('42p stat'!$N$1,A34*20,0) -> 347.00732 | J34: =SUM(E34:H34) -> 530.28568 | K34: =G34/J34 -> 0.24072497 | L34: =$K$29*POWER(K34,2)*SQRT(G141/(POWER(G34,2)*$L$29)+J141/(POWER(J34,2)*$L$29)) -> 0.00039698397
A35: 5 | C35: =OFFSET('42p stat'!$A$1,A35*20,0) -> CUDA ant par | D35: =OFFSET('42p trace'!$R$56,(A35-1)*56,0)-OFFSET('42p trace'!$S$56,(A35-1)*56,0) -> 16.54152 | E35: =OFFSET('42p trace'!$S$56,(A35-1)*56,0)-OFFSET('42p stat'!$H$1,A35*20,0) -> 35.913695 | F35: =OFFSET('42p stat'!$H$1,A35*20,0)-OFFSET('42p stat'!$K$1,A35*20,0) -> 15.442489 | G35: =OFFSET('42p stat'!$K$1,A35*20,0)-OFFSET('42p stat'!$N$1,A35*20,0) -> 127.7868 | H35: =OFFSET('42p stat'!$N$1,A35*20,0) -> 300.90713 | J35: =SUM(E35:H35) -> 480.05012 | K35: =E35/J35 -> 0.074812386 | L35: =$K$29*POWER(K35,2)*SQRT(E142/(POWER(E35,2)*$L$29)+J142/(POWER(J35,2)*$L$29)) -> 1.1942385e-05
A36: 6 | C36: =OFFSET('42p stat'!$A$1,A36*20,0) -> CUDA ant non hash | D36: =OFFSET('42p trace'!$R$56,(A36-1)*56,0)-OFFSET('42p trace'!$S$56,(A36-1)*56,0) -> 16.67042 | E36: =OFFSET('42p trace'!$S$56,(A36-1)*56,0)-OFFSET('42p stat'!$H$1,A36*20,0) -> 35.940147 | F36: =OFFSET('42p stat'!$H$1,A36*20,0)-OFFSET('42p stat'!$K$1,A36*20,0) -> 19.569468 | G36: =OFFSET('42p stat'!$K$1,A36*20,0)-OFFSET('42p stat'!$N$1,A36*20,0) -> 96.593672 | H36: =OFFSET('42p stat'!$N$1,A36*20,0) -> 346.39669 | J36: =SUM(E36:H36) -> 498.49998 | K36: =E36/J36 -> 0.072096587 | L36: =$K$29*POWER(K36,2)*SQRT(E143/(POWER(E36,2)*$L$29)+J143/(POWER(J36,2)*$L$29)) -> 0.00011313054
A37: 7 | C37: =OFFSET('42p stat'!$A$1,A37*20,0) -> CUDA ant add CPU Time | D37: =OFFSET('42p trace'!$R$56,(A37-1)*56,0)-OFFSET('42p trace'!$S$56,(A37-1)*56,0) -> 17.13512 | E37: =OFFSET('42p trace'!$S$56,(A37-1)*56,0)-OFFSET('42p stat'!$H$1,A37*20,0) -> 308.75334 | F37: =OFFSET('42p stat'!$H$1,A37*20,0)-OFFSET('42p stat'!$K$1,A37*20,0) -> 2.265325 | G37: =OFFSET('42p stat'!$K$1,A37*20,0)-OFFSET('42p stat'!$N$1,A37*20,0) -> 202.07982 | H37: =OFFSET('42p stat'!$N$1,A37*20,0) -> 123.44107 | J37: =SUM(E37:H37) -> 636.53956 | K37: =G37/J37 -> 0.31746624 | L37: =$K$29*POWER(K37,2)*SQRT(G144/(POWER(G37,2)*$L$29)+J144/(POWER(J37,2)*$L$29)) -> 0.00014786789
A38: 8 | C38: =OFFSET('42p stat'!$A$1,A38*20,0) -> CUDA ant add CPU | D38: =OFFSET('42p trace'!$R$56,(A38-1)*56,0)-OFFSET('42p trace'!$S$56,(A38-1)*56,0) -> 638.64558 | E38: =OFFSET('42p trace'!$S$56,(A38-1)*56,0)-OFFSET('42p stat'!$H$1,A38*20,0) -> 0 | F38: =OFFSET('42p stat'!$H$1,A38*20,0)-OFFSET('42p stat'!$K$1,A38*20,0) -> 0 | G38: =OFFSET('42p stat'!$K$1,A38*20,0)-OFFSET('42p stat'!$N$1,A38*20,0) -> 0 | H38: =OFFSET('42p stat'!$N$1,A38*20,0) -> 0 | J38: =SUM(D38:H38) -> 638.64558 | K38: =G38/J38 -> 0 | L38: =$K$29*POWER(K38,2)*SQRT(G145/(POWER(G38,2)*$L$29)+J145/(POWER(J38,2)*$L$29)) -> #DIV/0!
A39: 9 | C39: =OFFSET('42p stat'!$A$1,A39*20,0) -> CUDA ant add CPU non hash | D39: =OFFSET('42p trace'!$R$56,(A39-1)*56,0)-OFFSET('42p trace'!$S$56,(A39-1)*56,0) -> 17.84836 | E39: =OFFSET('42p trace'!$S$56,(A39-1)*56,0)-OFFSET('42p stat'!$H$1,A39*20,0) -> 336.75326 | F39: =OFFSET('42p stat'!$H$1,A39*20,0)-OFFSET('42p stat'!$K$1,A39*20,0) -> 2.11423 | G39: =OFFSET('42p stat'!$K$1,A39*20,0)-OFFSET('42p stat'!$N$1,A39*20,0) -> 184.93332 | H39: =OFFSET('42p stat'!$N$1,A39*20,0) -> 123.27213 | J39: =SUM(E39:H39) -> 647.07294 | K39: =G39/J39 -> 0.2857998 | L39: =$K$29*POWER(K39,2)*SQRT(G146/(POWER(G39,2)*$L$29)+J146/(POWER(J39,2)*$L$29)) -> 0.0016561561
A40: 10 | C40: =OFFSET('42p stat'!$A$1,A40*20,0) -> CUDA ant add CPU12 | D40: =OFFSET('42p trace'!$R$56,(A40-1)*56,0)-OFFSET('42p trace'!$S$56,(A40-1)*56,0) -> 51.5926 | E40: =OFFSET('42p trace'!$S$56,(A40-1)*56,0)-OFFSET('42p stat'!$H$1,A40*20,0) -> 9.211581 | F40: =OFFSET('42p stat'!$H$1,A40*20,0)-OFFSET('42p stat'!$K$1,A40*20,0) -> 28.08417 | G40: =OFFSET('42p stat'!$K$1,A40*20,0)-OFFSET('42p stat'!$N$1,A40*20,0) -> 2950.8278 | H40: =OFFSET('42p stat'!$N$1,A40*20,0) -> 601.08268 | J40: =SUM(E40:H40) -> 3589.2062 | K40: =G40/J40 -> 0.82213938 | L40: =$K$29*POWER(K40,2)*SQRT(G147/(POWER(G40,2)*$L$29)+J147/(POWER(J40,2)*$L$29)) -> 0.00070402512
A41: 11 | C41: =OFFSET('42p stat'!$A$1,A41*20,0) -> CUDA opt | D41: =OFFSET('42p trace'!$R$56,(A41-1)*56,0)-OFFSET('42p trace'!$S$56,(A41-1)*56,0) -> 725.44534 | E41: =OFFSET('42p trace'!$S$56,(A41-1)*56,0)-OFFSET('42p stat'!$H$1,A41*20,0) -> 0 | F41: =OFFSET('42p stat'!$H$1,A41*20,0)-OFFSET('42p stat'!$K$1,A41*20,0) -> 0 | G41: =OFFSET('42p stat'!$K$1,A41*20,0)-OFFSET('42p stat'!$N$1,A41*20,0) -> 0 | H41: =OFFSET('42p stat'!$N$1,A41*20,0) -> 0 | J41: =SUM(D41:H41) -> 725.44534 | K41: =G41/J41 -> 0 | L41: =$K$29*POWER(K41,2)*SQRT(G148/(POWER(G41,2)*$L$29)+J148/(POWER(J41,2)*$L$29)) -> #DIV/0!
...

Sheet 84p stat
A2: CUDA Time | B2: 1 | C2: 25 | D2: Duration Mean: | E2: 0 | F2: 0 | G2: GPU Time 1 Mean: | H2: 68.049543 | I2: 0.009553 | J2: GPU Time 2 Mean: | K2: 67.223416 | L2: 0.009743 | M2: GPU Time 3 Mean: | N2: 24.962459 | O2: 0.006185 | P2: GPU Time 4 Mean: | Q2: 0 | R2: 0 | S2: GPU Time 5 Mean: | T2: 0 | U2: 0 | V2: GPU Time 6 Mean: | W2: 0 | X2: 0 | Y2: GPU Time 7 Mean: | Z2: 0 | AA2: 0 | AB2: GPU Time 8 Mean: | AC2: 0 | AD2: 0 | AE2: Global Min Mean: | AF2: 1 | AG2: 0 | AH2: Global Max Mean: | AI2: 1 | AJ2: 0 | AK2: Hash Fail Count Mean: | AL2: 0 | AM2: 0
A3: CUDA Time | B3: 2 | C3: 50 | D3: Duration Mean: | E3: 0 | F3: 0 | G3: GPU Time 1 Mean: | H3: 136.48763 | I3: 0.04117 | J3: GPU Time 2 Mean: | K3: 134.84649 | L3: 0.041665 | M3: GPU Time 3 Mean: | N3: 50.321358 | O3: 0.02947 | P3: GPU Time 4 Mean: | Q3: 0 | R3: 0 | S3: GPU Time 5 Mean: | T3: 0 | U3: 0 | V3: GPU Time 6 Mean: | W3: 0 | X3: 0 | Y3: GPU Time 7 Mean: | Z3: 0 | AA3: 0 | AB3: GPU Time 8 Mean: | AC3: 0 | AD3: 0 | AE3: Global Min Mean: | AF3: 1 | AG3: 0 | AH3: Global Max Mean: | AI3: 1 | AJ3: 0 | AK3: Hash Fail Count Mean: | AL3: 0 | AM3: 0
A4: CUDA Time | B4: 3 | C4: 75 | D4: Duration Mean: | E4: 0 | F4: 0 | G4: GPU Time 1 Mean: | H4: 204.93665 | I4: 0.094655 | J4: GPU Time 2 Mean: | K4: 202.4806 | L4: 0.095049 | M4: GPU Time 3 Mean: | N4: 75.689963 | O4: 0.065687 | P4: GPU Time 4 Mean: | Q4: 0 | R4: 0 | S4: GPU Time 5 Mean: | T4: 0 | U4: 0 | V4: GPU Time 6 Mean: | W4: 0 | X4: 0 | Y4: GPU Time 7 Mean: | Z4: 0 | AA4: 0 | AB4: GPU Time 8 Mean: | AC4: 0 | AD4: 0 | AE4: Global Min Mean: | AF4: 1 | AG4: 0 | AH4: Global Max Mean: | AI4: 1 | AJ4: 0 | AK4: Hash Fail Count Mean: | AL4: 0 | AM4: 0
A5: CUDA Time | B5: 4 | C5: 100 | D5: Duration Mean: | E5: 0 | F5: 0 | G5: GPU Time 1 Mean: | H5: 273.39616 | I5: 0.15693 | J5: GPU Time 2 Mean: | K5: 270.12556 | L5: 0.157349 | M5: GPU Time 3 Mean: | N5: 101.06614 | O5: 0.111512 | P5: GPU Time 4 Mean: | Q5: 0 | R5: 0 | S5: GPU Time 5 Mean: | T5: 0 | U5: 0 | V5: GPU Time 6 Mean: | W5: 0 | X5: 0 | Y5: GPU Time 7 Mean: | Z5: 0 | AA5: 0 | AB5: GPU Time 8 Mean: | AC5: 0 | AD5: 0 | AE5: Global Min Mean: | AF5: 1 | AG5: 0 | AH5: Global Max Mean: | AI5: 1 | AJ5: 0 | AK5: Hash Fail Count Mean: | AL5: 0 | AM5: 0
A6: CUDA Time | B6: 5 | C6: 125 | D6: Duration Mean: | E6: 0 | F6: 0 | G6: GPU Time 1 Mean: | H6: 341.84893 | I6: 0.239391 | J6: GPU Time 2 Mean: | K6: 337.76347 | L6: 0.239324 | M6: GPU Time 3 Mean: | N6: 126.44168 | O6: 0.168038 | P6: GPU Time 4 Mean: | Q6: 0 | R6: 0 | S6: GPU Time 5 Mean: | T6: 0 | U6: 0 | V6: GPU Time 6 Mean: | W6: 0 | X6: 0 | Y6: GPU Time 7 Mean: | Z6: 0 | AA6: 0 | AB6: GPU Time 8 Mean: | AC6: 0 | AD6: 0 | AE6: Global Min Mean: | AF6: 1 | AG6: 0 | AH6: Global Max Mean: | AI6: 1 | AJ6: 0 | AK6: Hash Fail Count Mean: | AL6: 0 | AM6: 0
A7: CUDA Time | B7: 6 | C7: 150 | D7: Duration Mean: | E7: 0 | F7: 0 | G7: GPU Time 1 Mean: | H7: 410.3097 | I7: 0.333003 | J7: GPU Time 2 Mean: | K7: 405.40994 | L7: 0.332794 | M7: GPU Time 3 Mean: | N7: 151.82066 | O7: 0.234588 | P7: GPU Time 4 Mean: | Q7: 0 | R7: 0 | S7: GPU Time 5 Mean: | T7: 0 | U7: 0 | V7: GPU Time 6 Mean: | W7: 0 | X7: 0 | Y7: GPU Time 7 Mean: | Z7: 0 | AA7: 0 | AB7: GPU Time 8 Mean: | AC7: 0 | AD7: 0 | AE7: Global Min Mean: | AF7: 1 | AG7: 0 | AH7: Global Max Mean: | AI7: 1 | AJ7: 0 | AK7: Hash Fail Count Mean: | AL7: 0 | AM7: 0
A8: CUDA Time | B8: 7 | C8: 175 | D8: Duration Mean: | E8: 0 | F8: 0 | G8: GPU Time 1 Mean: | H8: 478.76427 | I8: 0.43161 | J8: GPU Time 2 Mean: | K8: 473.05034 | L8: 0.431245 | M8: GPU Time 3 Mean: | N8: 177.19088 | O8: 0.313783 | P8: GPU Time 4 Mean: | Q8: 0 | R8: 0 | S8: GPU Time 5 Mean: | T8: 0 | U8: 0 | V8: GPU Time 6 Mean: | W8: 0 | X8: 0 | Y8: GPU Time 7 Mean: | Z8: 0 | AA8: 0 | AB8: GPU Time 8 Mean: | AC8: 0 | AD8: 0 | AE8: Global Min Mean: | AF8: 1 | AG8: 0 | AH8: Global Max Mean: | AI8: 1 | AJ8: 0 | AK8: Hash Fail Count Mean: | AL8: 0 | AM8: 0
A9: CUDA Time | B9: 8 | C9: 200 | D9: Duration Mean: | E9: 0 | F9: 0 | G9: GPU Time 1 Mean: | H9: 547.22754 | I9: 0.553168 | J9: GPU Time 2 Mean: | K9: 540.6988 | L9: 0.552419 | M9: GPU Time 3 Mean: | N9: 202.57209 | O9: 0.402984 | P9: GPU Time 4 Mean: | Q9: 0 | R9: 0 | S9: GPU Time 5 Mean: | T9: 0 | U9: 0 | V9: GPU Time 6 Mean: | W9: 0 | X9: 0 | Y9: GPU Time 7 Mean: | Z9: 0 | AA9: 0 | AB9: GPU Time 8 Mean: | AC9: 0 | AD9: 0 | AE9: Global Min Mean: | AF9: 1 | AG9: 0 | AH9: Global Max Mean: | AI9: 1 | AJ9: 0 | AK9: Hash Fail Count Mean: | AL9: 0 | AM9: 0
A10: CUDA Time | B10: 9 | C10: 225 | D10: Duration Mean: | E10: 0 | F10: 0 | G10: GPU Time 1 Mean: | H10: 615.67997 | I10: 0.693831 | J10: GPU Time 2 Mean: | K10: 608.33634 | L10: 0.692217 | M10: GPU Time 3 Mean: | N10: 227.94406 | O10: 0.506875 | P10: GPU Time 4 Mean: | Q10: 0 | R10: 0 | S10: GPU Time 5 Mean: | T10: 0 | U10: 0 | V10: GPU Time 6 Mean: | W10: 0 | X10: 0 | Y10: GPU Time 7 Mean: | Z10: 0 | AA10: 0 | AB10: GPU Time 8 Mean: | AC10: 0 | AD10: 0 | AE10: Global Min Mean: | AF10: 1 | AG10: 0 | AH10: Global Max Mean: | AI10: 1 | AJ10: 0 | AK10: Hash Fail Count Mean: | AL10: 0 | AM10: 0
A11: CUDA Time | B11: 10 | C11: 250 | D11: Duration Mean: | E11: 0 | F11: 0 | G11: GPU Time 1 Mean: | H11: 684.14929 | I11: 0.837224 | J11: GPU Time 2 Mean: | K11: 675.9907 | L11: 0.835858 | M11: GPU Time 3 Mean: | N11: 253.31819 | O11: 0.618121 | P11: GPU Time 4 Mean: | Q11: 0 | R11: 0 | S11: GPU Time 5 Mean: | T11: 0 | U11: 0 | V11: GPU Time 6 Mean: | W11: 0 | X11: 0 | Y11: GPU Time 7 Mean: | Z11: 0 | AA11: 0 | AB11: GPU Time 8 Mean: | AC11: 0 | AD11: 0 | AE11: Global Min Mean: | AF11: 1 | AG11: 0 | AH11: Global Max Mean: | AI11: 1 | AJ11: 0 | AK11: Hash Fail Count Mean: | AL11: 0 | AM11: 0
A12: CUDA Time | B12: 11 | C12: 275 | D12: Duration Mean: | E12: 0 | F12: 0 | G12: GPU Time 1 Mean: | H12: 752.59265 | I12: 1.003417 | J12: GPU Time 2 Mean: | K12: 743.61937 | L12: 1.002128 | M12: GPU Time 3 Mean: | N12: 278.68952 | O12: 0.741286 | P12: GPU Time 4 Mean: | Q12: 0 | R12: 0 | S12: GPU Time 5 Mean: | T12: 0 | U12: 0 | V12: GPU Time 6 Mean: | W12: 0 | X12: 0 | Y12: GPU Time 7 Mean: | Z12: 0 | AA12: 0 | AB12: GPU Time 8 Mean: | AC12: 0 | AD12: 0 | AE12: Global Min Mean: | AF12: 1 | AG12: 0 | AH12: Global Max Mean: | AI12: 1 | AJ12: 0 | AK12: Hash Fail Count Mean: | AL12: 0 | AM12: 0
A13: CUDA Time | B13: 12 | C13: 300 | D13: Duration Mean: | E13: 0 | F13: 0 | G13: GPU Time 1 Mean: | H13: 821.02764 | I13: 1.185282 | J13: GPU Time 2 Mean: | K13: 811.23973 | L13: 1.18347 | M13: GPU Time 3 Mean: | N13: 304.05492 | O13: 0.883132 | P13: GPU Time 4 Mean: | Q13: 0 | R13: 0 | S13: GPU Time 5 Mean: | T13: 0 | U13: 0 | V13: GPU Time 6 Mean: | W13: 0 | X13: 0 | Y13: GPU Time 7 Mean: | Z13: 0 | AA13: 0 | AB13: GPU Time 8 Mean: | AC13: 0 | AD13: 0 | AE13: Global Min Mean: | AF13: 1 | AG13: 0 | AH13: Global Max Mean: | AI13: 1 | AJ13: 0 | AK13: Hash Fail Count Mean: | AL13: 0 | AM13: 0
... A321: CUDA opt ant par | B321: 20 | C321: 500 | D321: Duration Mean: | E321: 0 | F321: 0 | G321: GPU Time 1 Mean: | H321: 576.71305 | I321: 9.819416 | J321: GPU Time 2 Mean: | K321: 245.33112 | L321: 0.05127 | M321: GPU Time 3 Mean: | N321: 0 | O321: 0 | P321: GPU Time 4 Mean: | Q321: 0 | R321: 0 | S321: GPU Time 5 Mean: | T321: 0 | U321: 0 | V321: GPU Time 6 Mean: | W321: 0 | X321: 0 | Y321: GPU Time 7 Mean: | Z321: 0 | AA321: 0 | AB321: GPU Time 8 Mean: | AC321: 0 | AD321: 0 | AE321: Global Min Mean: | AF321: 32767 | AG321: 0 | AH321: Global Max Mean: | AI321: -32767 | AJ321: 0 | AK321: Hash Fail Count Mean: | AL321: 0.24 | AM321: 0.2224
A322: CUDA opt_one_GPU
A323: CUDA opt_one_GPU
A324: CUDA opt_one_GPU
A325: CUDA opt_one_GPU
A326: CUDA opt_one_GPU
A327: CUDA opt_one_GPU
A328: CUDA opt_one_GPU
A329: CUDA opt_one_GPU
A330: CUDA opt_one_GPU
A331: CUDA opt_one_GPU
A332: CUDA opt_one_GPU
A333: CUDA opt_one_GPU
... A381: CUDA opt_one_GPU ant local
A382: non CUDA Time | B382: 1 | C382: 25 | D382: Duration Mean: | E382: 0 | F382: 0 | G382: GPU Time 1 Mean: | H382: 253.05907 | I382: 0.049348 | J382: GPU Time 2 Mean: | K382: 252.81616 | L382: 0.0493 | M382: GPU Time 3 Mean: | N382: 12.344873 | O382: 0.000723 | P382: GPU Time 4 Mean: | Q382: 40.583515 | R382: 0.007124 | S382: GPU Time 5 Mean: | T382: 6.697556 | U382: 0.000137 | V382: GPU Time 6 Mean: | W382: 6.772295 | X382: 0.000593 | Y382: GPU Time 7 Mean: | Z382: 22.887747 | AA382: 0.006487 | AB382: GPU Time 8 Mean: | AC382: 196.83024 | AD382: 0.036614 | AE382: Global Min Mean: | AF382: 0.006295 | AG382: 1.6e-05 | AH382: Global Max Mean: | AI382: 0.99491 | AJ382: 0 | AK382: Hash Fail Count Mean: | AL382: 0 | AM382: 0
A383: non CUDA Time | B383: 2 | C383: 50 | D383: Duration Mean: | E383: 0 | F383: 0 | G383: GPU Time 1 Mean: | H383: 505.78106 | I383: 0.131887 | J383: GPU Time 2 Mean: | K383: 505.29713 | L383: 0.131832 | M383: GPU Time 3 Mean: | N383: 24.695187 | O383: 0.001133 | P383: GPU Time 4 Mean: | Q383: 81.460942 | R383: 0.009506 | S383: GPU Time 5 Mean: | T383: 13.368757 | U383: 0.000232 | V383: GPU Time 6 Mean: | W383: 13.531297 | X383: 0.000903 | Y383: GPU Time 7 Mean: | Z383: 46.110717 | AA383: 0.009578 | AB383: GPU Time 8 Mean: | AC383: 393.04784 | AD383: 0.10768 | AE383: Global Min Mean: | AF383: 0.003784 | AG383: 9e-06 | AH383: Global Max Mean: | AI383: 0.995045 | AJ383: 0 | AK383: Hash Fail Count Mean: | AL383: 0 | AM383: 0
A384: non CUDA Time | B384: 3 | C384: 75 | D384: Duration Mean: | E384: 0 | F384: 0 | G384: GPU Time 1 Mean: | H384: 758.48502 | I384: 0.264938 | J384: GPU Time 2 Mean: | K384: 757.75998 | L384: 0.264514 | M384: GPU Time 3 Mean: | N384: 37.033512 | O384: 0.001315 | P384: GPU Time 4 Mean: | Q384: 122.35597 | R384: 0.040364 | S384: GPU Time 5 Mean: | T384: 20.043978 | U384: 0.000438 | V384: GPU Time 6 Mean: | W384: 20.288634 | X384: 0.00125 | Y384: GPU Time 7 Mean: | Z384: 69.349425 | AA384: 0.045816 | AB384: GPU Time 8 Mean: | AC384: 589.22907 | AD384: 0.272434 | AE384: Global Min Mean: | AF384: 0.003164 | AG384: 7e-06 | AH384: Global Max Mean: | AI384: 0.995074 | AJ384: 0 | AK384: Hash Fail Count Mean: | AL384: 0 | AM384: 0
A385: non CUDA Time | B385: 4 | C385: 100 | D385: Duration Mean: | E385: 0 | F385: 0 | G385: GPU Time 1 Mean: | H385: 1011.2279 | I385: 0.528292 | J385: GPU Time 2 Mean: | K385: 1010.2616 | L385: 0.526851 | M385: GPU Time 3 Mean: | N385: 49.38018 | O385: 0.001993 | P385: GPU Time 4 Mean: | Q385: 163.28037 | R385: 0.019835 | S385: GPU Time 5 Mean: | T385: 26.712908 | U385: 0.000492 | V385: GPU Time 6 Mean: | W385: 27.046673 | X385: 0.001453 | Y385: GPU Time 7 Mean: | Z385: 92.645345 | AA385: 0.019999 | AB385: GPU Time 8 Mean: | AC385: 785.36701 | AD385: 0.440902 | AE385: Global Min Mean: | AF385: 0.002538 | AG385: 5e-06 | AH385: Global Max Mean: | AI385: 0.995095 | AJ385: 0 | AK385: Hash Fail Count Mean: | AL385: 0 | AM385: 0
A386: non CUDA Time | B386: 5 | C386: 125 | D386: Duration Mean: | E386: 0 | F386: 0 | G386: GPU Time 1 Mean: | H386: 1264.0114 | I386: 0.716535 | J386: GPU Time 2 Mean: | K386: 1262.804 | L386: 0.715095 | M386: GPU Time 3 Mean: | N386: 61.720699 | O386: 0.003205 | P386: GPU Time 4 Mean: | Q386: 204.26898 | R386: 0.059928 | S386: GPU Time 5 Mean: | T386: 33.381314 | U386: 0.000612 | V386: GPU Time 6 Mean: | W386: 33.808733 | X386: 0.001733 | Y386: GPU Time 7 Mean: | Z386: 116.01103 | AA386: 0.057215 | AB386: GPU Time 8 Mean: | AC386: 981.4853 | AD386: 0.514466 | AE386: Global Min Mean: | AF386: 0.002204 | AG386: 3e-06 | AH386: Global Max Mean: | AI386: 0.995107 | AJ386: 0 | AK386: Hash Fail Count Mean: | AL386: 0 | AM386: 0
A387: non CUDA Time | B387: 6 | C387: 150 | D387: Duration Mean: | E387: 0 | F387: 0 | G387: GPU Time 1 Mean: | H387: 1516.7982 | I387: 1.01322 | J387: GPU Time 2 Mean: | K387: 1515.3503 | L387: 1.01121 | M387: GPU Time 3 Mean: | N387: 74.065132 | O387: 0.004875 | P387: GPU Time 4 Mean: | Q387: 245.27742 | R387: 0.101249 | S387: GPU Time 5 Mean: | T387: 40.055673 | U387: 0.000611 | V387: GPU Time 6 Mean: | W387: 40.577036 | X387: 0.001867 | Y387: GPU Time 7 Mean: | Z387: 139.40484 | AA387: 0.092241 | AB387: GPU Time 8 Mean: | AC387: 1177.5557 | AD387: 0.650383 | AE387: Global Min Mean: | AF387: 0.001764 | AG387: 1e-06 | AH387: Global Max Mean: | AI387: 0.995108 | AJ387: 0 | AK387: Hash Fail Count Mean: | AL387: 0.6 | AM387: 17.64
A388: non CUDA Time | B388: 7 | C388: 175 | D388: Duration Mean: | E388: 0 | F388: 0 | G388: GPU Time 1 Mean: | H388: 1769.563 | I388: 1.20367 | J388: GPU Time 2 Mean: | K388: 1767.8741 | L388: 1.201746 | M388: GPU Time 3 Mean: | N388: 86.406881 | O388: 0.005084 | P388: GPU Time 4 Mean: | Q388: 286.30361 | R388: 0.157913 | S388: GPU Time 5 Mean: | T388: 46.731666 | U388: 0.000804 | V388: GPU Time 6 Mean: | W388: 47.350334 | X388: 0.00236 | Y388: GPU Time 7 Mean: | Z388: 162.80227 | AA388: 0.147961 | AB388: GPU Time 8 Mean: | AC388: 1373.5954 | AD388: 0.730037 | AE388: Global Min Mean: | AF388: 0.001689 | AG388: 1e-06 | AH388: Global Max Mean: | AI388: 0.995109 | AJ388: 0 | AK388: Hash Fail Count Mean: | AL388: 0.6 | AM388: 17.64
A389: non CUDA Time | B389: 8 | C389: 200 | D389: Duration Mean: | E389: 0 | F389: 0 | G389: GPU Time 1 Mean: | H389: 2022.3069 | I389: 1.563745 | J389: GPU Time 2 Mean: | K389: 2020.3768 | L389: 1.561202 | M389: GPU Time 3 Mean: | N389: 98.74511 | O389: 0.007112 | P389: GPU Time 4 Mean: | Q389: 327.30497 | R389: 0.259538 | S389: GPU Time 5 Mean: | T389: 53.406131 | U389: 0.001247 | V389: GPU Time 6 Mean: | W389: 54.1198 | X389: 0.002495 | Y389: GPU Time 7 Mean: | Z389: 186.17798 | AA389: 0.240955 | AB389: GPU Time 8 Mean: | AC389: 1569.6443 | AD389: 0.888926 | AE389: Global Min Mean: | AF389: 0.001573 | AG389: 0 | AH389: Global Max Mean: | AI389: 0.995111 | AJ389: 0 | AK389: Hash Fail Count Mean: | AL389: 0.6 | AM389: 17.64
A390: non CUDA Time | B390: 9 | C390: 225 | D390: Duration Mean: | E390: 0 | F390: 0 | G390: GPU Time 1 Mean: | H390: 2275.0821 | I390: 1.84872 | J390: GPU Time 2 Mean: | K390: 2272.9111 | L390: 1.845487 | M390: GPU Time 3 Mean: | N390: 111.08125 | O390: 0.007722 | P390: GPU Time 4 Mean: | Q390: 368.33305 | R390: 0.301898 | S390: GPU Time 5 Mean: | T390: 60.080644 | U390: 0.001535 | V390: GPU Time 6 Mean: | W390: 60.893183 | X390: 0.002624 | Y390: GPU Time 7 Mean: | Z390: 209.57502 | AA390: 0.285863 | AB390: GPU Time 8 Mean: | AC390: 1765.7009 | AD390: 1.089889 | AE390: Global Min Mean: | AF390: 0.001544 | AG390: 0 | AH390: Global Max Mean: | AI390: 0.995114 | AJ390: 0 | AK390: Hash Fail Count Mean: | AL390: 0.74 | AM390: 18.4324
A391: non CUDA Time | B391: 10 | C391: 250 | D391: Duration Mean: | E391: 0 | F391: 0 | G391: GPU Time 1 Mean: | H391: 2527.8633 | I391: 2.061242 | J391: GPU Time 2 Mean: | K391: 2525.4513 | L391: 2.058606 | M391: GPU Time 3 Mean: | N391: 123.41396 | O391: 0.008275 | P391: GPU Time 4 Mean: | Q391: 409.38251 | R391: 0.308204 | S391: GPU Time 5 Mean: | T391: 66.742935 | U391: 0.001728 | V391: GPU Time 6 Mean: | W391: 67.646143 | X391: 0.002533 | Y391: GPU Time 7 Mean: | Z391: 232.99765 | AA391: 0.291924 | AB391: GPU Time 8 Mean: | AC391: 1961.7466 | AD391: 1.260246 | AE391: Global Min Mean: | AF391: 0.001498 | AG391: 0 | AH391: Global Max Mean: | AI391: 0.995114 | AJ391: 0 | AK391: Hash Fail Count Mean: | AL391: 1.92 | AM391: 84.9136
A392: non CUDA Time | B392: 11 | C392: 275 | D392: Duration Mean: | E392: 0 | F392: 0 | G392: GPU Time 1 Mean: | H392: 2780.6205 | I392: 2.309577 | J392: GPU Time 2 Mean: | K392: 2777.9678 | L392: 2.306657 | M392: GPU Time 3 Mean: | N392: 135.74649 | O392: 0.009113 | P392: GPU Time 4 Mean: | Q392: 450.42228 | R392: 0.335328 | S392: GPU Time 5 Mean: | T392: 73.393948 | U392: 0.002077 | V392: GPU Time 6 Mean: | W392: 74.38467 | X392: 0.002854 | Y392: GPU Time 7 Mean: | Z392: 256.40889 | AA392: 0.302842 | AB392: GPU Time 8 Mean: | AC392: 2157.7816 | AD392: 1.409141 | AE392: Global Min Mean: | AF392: 0.001475 | AG392: 0 | AH392: Global Max Mean: | AI392: 0.995114 | AJ392: 0 | AK392: Hash Fail Count Mean: | AL392: 1.92 | AM392: 84.9136
A393: non CUDA Time | B393: 12 | C393: 300 | D393: Duration Mean: | E393: 0 | F393: 0 | G393: GPU Time 1 Mean: | H393: 3033.4094 | I393: 2.438925 | J393: GPU Time 2 Mean: | K393: 3030.516 | L393: 2.43565 | M393: GPU Time 3 Mean: | N393: 148.08074 | O393: 0.010139 | P393: GPU Time 4 Mean: | Q393: 491.46979 | R393: 0.355388 | S393: GPU Time 5 Mean: | T393: 80.047809 | U393: 0.002509 | V393: GPU Time 6 Mean: | W393: 81.124062 | X393: 0.002686 | Y393: GPU Time 7 Mean: | Z393: 279.80977 | AA393: 0.314557 | AB393: GPU Time 8 Mean: | AC393: 2353.8415 | AD393: 1.57164 | AE393: Global Min Mean: | AF393: 0.001441 | AG393: 0 | AH393: Global Max Mean: | AI393: 0.995114 | AJ393: 0 | AK393: Hash Fail Count Mean: | AL393: 1.92 | AM393: 84.9136
... A781: CUDA opt ant par global | B781: 20 | C781: 500 | D781: Duration Mean: | E781: 0 | F781: 0 | G781: GPU Time 1 Mean: | H781: 585.78612 | I781: 5.305156 | J781: GPU Time 2 Mean: | K781: 274.67111 | L781: 0.031129 | M781: GPU Time 3 Mean: | N781: 0 | O781: 0 | P781: GPU Time 4 Mean: | Q781: 0 | R781: 0 | S781: GPU Time 5 Mean: | T781: 0 | U781: 0 | V781: GPU Time 6 Mean: | W781: 0 | X781: 0 | Y781: GPU Time 7 Mean: | Z781: 0 | AA781: 0 | AB781: GPU Time 8 Mean: | AC781: 0 | AD781: 0 | AE781: Global Min Mean: | AF781: 32767 | AG781: 0 | AH781: Global Max Mean: | AI781: -32767 | AJ781: 0 | AK781: Hash Fail Count Mean: | AL781: 0.2 | AM781: 0.2

Sheet 84p trace
A1: Device 0: Orin | B1: Max thread in blocks: 1024 | C1: Max thread in blocks by axis: (1024, 1024, 64) | D1: Max blocks by axis: (2147483647, 65535, 65535) | E1: PARAMETR_SIZE: 84 | F1: MAX_VALUE_SIZE: 5 | G1: NAME_FILE_GRAPH: Parametr_Graph/test84,txt | H1: ANT_SIZE: 500 | I1: KOL_ITERATION: 500 | J1: KOL_PROGON_STATISTICS: 50 | K1: PARAMETR_Q: 1 | L1: PARAMETR_RO: 0,999 | M1: HASH_TABLE_SIZE: 10000000 | N1: MAX_PROBES: 10000 | O1: TYPE_ACO: 1 | P1: ACOCCyN_KOL_ITERATION: 50 | Q1: PRINT_INFORMATION: false
A2: Time CUDA Time: | B2: 1448.28 | C2: 1422.47 | D2: 1384.85 | E2: 1368.06 | F2: 512.658 | G2: 0 | H2: 512.658 | I2: 1 | J2: 1 | K2: 0
A3: Time CUDA Time: | B3: 1421.04 | C3: 1403.23 | D3: 1366.64 | E3: 1350.24 | F3: 506.534 | G3: 0 | H3: 506.534 | I3: 1 | J3: 1 | K3: 0
A4: Time CUDA Time: | B4: 1420.42 | C4: 1402.29 | D4: 1366.12 | E4: 1349.77 | F4: 505.027 | G4: 0 | H4: 505.027 | I4: 1 | J4: 1 | K4: 0
A5: Time CUDA Time: | B5: 1424.2 | C5: 1406.42 | D5: 1370.38 | E5: 1354.06 | F5: 509.494 | G5: 0 | H5: 509.494 | I5: 1 | J5: 1 | K5: 0
A6: Time CUDA Time: | B6: 1424.54 | C6: 1406.5 | D6: 1370.19 | E6: 1353.85 | F6: 508.99 | G6: 0 | H6: 508.99 | I6: 1 | J6: 1 | K6: 0
A7: Time CUDA Time: | B7: 1419.93 | C7: 1402.62 | D7: 1366.75 | E7: 1350.44 | F7: 506.407 | G7: 0 | H7: 506.407 | I7: 1 | J7: 1 | K7: 0
A8: Time CUDA Time: | B8: 1421.59 | C8: 1404 | D8: 1368 | E8: 1351.7 | F8: 506.919 | G8: 0 | H8: 506.919 | I8: 1 | J8: 1 | K8: 0
