Workbook

Sheet Лист1
A1: OpenMP version: 202011 | B1: AVX2 optimization enabled | C1: PARAMETR_SIZE: 42 | D1: MAX_VALUE_SIZE: 4 | E1: SET_PARAMETR_SIZE_ONE_X: 21 | F1: ANT_SIZE: 500 | G1: MAX_THREAD_CUDA: 512 | H1: NAME_FILE_GRAPH: Parametr_Graph/test42_4,txt | I1: KOL_ITERATION: 500 | J1: KOL_PROGREV: 5 | K1: KOL_PROGON_STATISTICS: 10 | L1: PARAMETR_RO: 0,999 | M1: PARAMETR_Q: 1 | N1: PRINT_INFORMATION: 0 | O1: MAX_PARAMETR_VALUE_TO_MIN_OPT: 1 | P1: OPTIMIZE: OPTIMIZE_MAX | Q1: FUNCTION: SHAFFERA | R1: HASH_TABLE_SIZE: 67108864 | S1: ZERO_HASH_RESULT: -1 | T1: ZERO_HASH: 18446744073709551615 | U1: MAX_PROBES: 10000 | V1: KOL_STAT_LEVEL: 20 | W1: TYPE_ACO: 1 | X1: ACOCCyN_KOL_ITERATION: 50 | Y1: CPU_RANDOM: 0 | Z1: KOL_THREAD_CPU_ANT: 12 | AA1: CONST_AVX: 4 | AB1: CONST_RANDOM: 100000 | AC1: MAX_CONST: 8000 | AD1: BIN_SEARCH: 0 | AE1: GO_ALG_MINMAX: 1 | AF1: PAR_MAX_ALG_MINMAX: 1000 | AG1: PAR_MIN_ALG_MINMAX: 1
A2: 1 | B2: 164.127 | C2: 0.23103 | D2: 157.184 | E2: 6.18393 | F2: 80.0854 | G2: 13.2451 | H2: 0 | I2: 99.992 | J2: 0 | K2: 0.00123005 | M2: 269789 | N2: 0.538628 | O2: 247446 | P2: 384.082 | Q2: 64309.1 | R2: 1755.7
A3: 2 | B3: 113.962 | C3: 5.59065 | D3: 93.2689 | E3: 14.5446 | F3: 78.2243 | G3: 13.1639 | H3: 0 | I3: 49.9928 | J3: 0 | K3: 0.00123005 | M3: 129906 | N3: 312.749 | O3: 87016.6 | P3: 2115.87 | Q3: 61216.8 | R3: 1733.36
A4: 3 | B4: 105.005 | C4: 6.2918 | D4: 82.4966 | E4: 15.6455 | F4: 78.3185 | G4: 13.2411 | H4: 0 | I4: 33.3287 | J4: 0 | K4: 0.00123005 | M4: 110280 | N4: 395.986 | O4: 68074.2 | P4: 2450.01 | Q4: 61342.6 | R4: 1753.29
A5: 4 | B5: 105.102 | C5: 6.38611 | D5: 81.832 | E5: 16.328 | F5: 78.7816 | G5: 13.147 | H5: 0 | I5: 24.9965 | J5: 0 | K5: 0.00123005 | M5: 110672 | N5: 410.136 | O5: 67233.9 | P5: 2668.43 | Q5: 62088.4 | R5: 1728.62
A6: 5 | B6: 113.309 | C6: 7.5425 | D6: 87.6266 | E6: 17.5808 | F6: 80.3605 | G6: 13.4997 | H6: 0 | I6: 19.9973 | J6: 0 | K6: 0.00123005 | M6: 128452 | N6: 579.709 | O6: 76847.5 | P6: 3128.69 | Q6: 64721.7 | R6: 1823.16
A7: 6 | B7: 112.434 | C7: 9.37304 | D7: 81.1401 | E7: 21.3647 | F7: 78.6601 | G7: 13.1701 | H7: 0 | I7: 16.6648 | J7: 0 | K7: 0.00123005 | M7: 126446 | N7: 879.054 | O7: 65850.3 | P7: 4574.51 | Q7: 61875.8 | R7: 1734.57
A8: 7 | B8: 116.217 | C8: 10.2591 | D8: 82.6465 | E8: 22.7484 | F8: 80.9255 | G8: 13.2957 | H8: 0 | I8: 14.2841 | J8: 0 | K8: 0.00123005 | M8: 135203 | N8: 1054.55 | O8: 68379.2 | P8: 5192.32 | Q8: 65546 | R8: 1768.24
A9: 8 | B9: 112.537 | C9: 11.1433 | D9: 76.196 | E9: 24.6382 | F9: 82.7582 | G9: 13.471 | H9: 0 | I9: 12.4986 | J9: 0 | K9: 0.00123006 | M9: 126673 | N9: 1246 | O9: 58121.8 | P9: 6090.83 | Q9: 68527.1 | R9: 1814.85
A10: 9 | B10: 113.69 | C10: 11.1845 | D10: 77.0949 | E10: 24.8511 | F10: 80.8479 | G10: 13.1828 | H10: 0 | I10: 11.1099 | J10: 0 | K10: 0.00123005 | M10: 129379 | N10: 1252.53 | O10: 59549.3 | P10: 6177.98 | Q10: 65373.8 | R10: 1737.9
A11: 10 | B11: 123.048 | C11: 11.4553 | D11: 84.6951 | E11: 26.3342 | F11: 82.7834 | G11: 13.5335 | H11: 0 | I11: 9.99896 | J11: 0 | K11: 0.00123005 | M11: 151458 | N11: 1313.75 | O11: 71789.1 | P11: 6940.38 | Q11: 68538.3 | R11: 1831.73
A12: 11 | B12: 124.104 | C12: 12.4419 | D12: 83.2964 | E12: 27.8036 | F12: 82.189 | G12: 13.4672 | H12: 0 | I12: 9.08995 | J12: 0 | K12: 0.00123005 | M12: 154151 | N12: 1550.24 | O12: 69490.1 | P12: 7735.7 | Q12: 67561.6 | R12: 1813.84
A13: 12 | B13: 121.148 | C13: 12.4276 | D13: 79.5503 | E13: 28.6017 | F13: 83.3523 | G13: 13.575 | H13: 0 | I13: 8.33244 | J13: 0 | K13: 0.00123005 | M13: 146873 | N13: 1550.98 | O13: 63422.3 | P13: 8190.34 | Q13: 69546.5 | R13: 1844.64
A14: OpenMP version: 202011 | B14: AVX2 optimization enabled | C14: PARAMETR_SIZE: 84 | D14: MAX_VALUE_SIZE: 4 | E14: SET_PARAMETR_SIZE_ONE_X: 21 | F14: ANT_SIZE: 500 | G14: MAX_THREAD_CUDA: 512 | H14: NAME_FILE_GRAPH: Parametr_Graph/test84_4,txt | I14: KOL_ITERATION: 500 | J14: KOL_PROGREV: 5 | K14: KOL_PROGON_STATISTICS: 10 | L14: PARAMETR_RO: 0,999 | M14: PARAMETR_Q: 1 | N14: PRINT_INFORMATION: 0 | O14: MAX_PARAMETR_VALUE_TO_MIN_OPT: 1 | P14: OPTIMIZE: OPTIMIZE_MAX | Q14: FUNCTION: SHAFFERA | R14: HASH_TABLE_SIZE: 67108864 | S14: ZERO_HASH_RESULT: -1 | T14: ZERO_HASH: 18446744073709551615 | U14: MAX_PROBES: 10000 | V14: KOL_STAT_LEVEL: 20 | W14: TYPE_ACO: 1 | X14: ACOCCyN_KOL_ITERATION: 50 | Y14: CPU_RANDOM: 0 | Z14: KOL_THREAD_CPU_ANT: 12 | AA14: CONST_AVX: 4 | AB14: CONST_RANDOM: 100000 | AC14: MAX_CONST: 8000 | AD14: BIN_SEARCH: 0 | AE14: GO_ALG_MINMAX: 1 | AF14: PAR_MAX_ALG_MINMAX: 1000 | AG14: PAR_MIN_ALG_MINMAX: 1
A15: 1 | B15: 249.153 | C15: 0.35708 | D15: 237.061 | E15: 11.2201 | F15: 113.084 | G15: 14.6055 | H15: 0 | I15: 99.9953 | J15: 0 | K15: 0.00123019 | M15: 621145 | N15: 1.28788 | O15: 562318 | P15: 1260.04 | Q15: 127998 | R15: 2134.13
A16: 2 | B16: 159.387 | C16: 5.72352 | D16: 135.719 | E16: 17.3841 | F16: 110.148 | G16: 14.5241 | H16: 0 | I16: 49.9961 | J16: 0 | K16: 0.00123006 | M16: 254321 | N16: 328.548 | O16: 184390 | P16: 3026.55 | Q16: 121539 | R16: 2111
A17: 3 | B17: 136.035 | C17: 6.71144 | D17: 110.376 | E17: 18.3574 | F17: 112.49 | G17: 14.9208 | H17: 0 | I17: 33.33 | J17: 0 | K17: 0.00123016 | M17: 185237 | N17: 451.261 | O17: 122028 | P17: 3380.25 | Q17: 126554 | R17: 2226.36
A18: 4 | B18: 135.074 | C18: 6.67049 | D18: 109.084 | E18: 18.7608 | F18: 112.843 | G18: 14.9219 | H18: 0 | I18: 24.9975 | J18: 0 | K18: 0.00123005 | M18: 184732 | N18: 455.722 | O18: 121669 | P18: 3521.17 | Q18: 127349 | R18: 2226.73
A19: 5 | B19: 149.93 | C19: 7.29504 | D19: 121.751 | E19: 20.3197 | F19: 112.367 | G19: 14.9894 | H19: 0 | I19: 19.9981 | J19: 0 | K19: 0.00123006 | M19: 224857 | N19: 532.404 | O19: 148284 | P19: 4135.32 | Q19: 126294 | R19: 2246.97
A20: 6 | B20: 142.059 | C20: 9.39174 | D20: 108.553 | E20: 23.551 | F20: 115.451 | G20: 15.1077 | H20: 0 | I20: 16.6651 | J20: 0 | K20: 0.00123005 | M20: 201840 | N20: 883.454 | O20: 117868 | P20: 5551.77 | Q20: 133500 | R20: 2283.07
A21: 7 | B21: 138.502 | C21: 10.2021 | D21: 101.885 | E21: 25.85 | F21: 118.271 | G21: 15.3136 | H21: 0 | I21: 14.2843 | J21: 0 | K21: 0.00123008 | M21: 191998 | N21: 1045.11 | O21: 104056 | P21: 6700.8 | Q21: 140998 | R21: 2351.25
A22: 8 | B22: 133.752 | C22: 11.0007 | D22: 96.1769 | E22: 26.0192 | F22: 123.615 | G22: 15.6518 | H22: 0 | I22: 12.4989 | J22: 0 | K22: 0.00123005 | M22: 178962 | N22: 1211.93 | O22: 92564.1 | P22: 6774.09 | Q22: 153019 | R22: 2451.09
A23: 9 | B23: 134.918 | C23: 12.6517 | D23: 93.5346 | E23: 28.1758 | F23: 127.84 | G23: 15.8921 | H23: 0 | I23: 11.1101 | J23: 0 | K23: 0.00123005 | M23: 182260 | N23: 1604.65 | O23: 87732.8 | P23: 7940.33 | Q23: 163461 | R23: 2525.82
A24: 10 | B24: 153.179 | C24: 11.7233 | D24: 111.619 | E24: 29.2705 | F24: 127.124 | G24: 15.946 | H24: 0 | I24: 9.99918 | J24: 0 | K24: 0.00123016 | M24: 234857 | N24: 1377.25 | O24: 124901 | P24: 8576.58 | Q24: 161644 | R24: 2542.99
A25: 11 | B25: 149.924 | C25: 12.1413 | D25: 107.201 | E25: 30.0102 | F25: 127.171 | G25: 15.8812 | H25: 0 | I25: 9.09014 | J25: 0 | K25: 0.00123005 | M25: 225855 | N25: 1478.99 | O25: 116063 | P25: 9014.38 | Q25: 161858 | R25: 2522.47
A26: 12 | B26: 150.131 | C26: 12.6003 | D26: 104.49 | E26: 32.4713 | F26: 134.678 | G26: 16.4918 | H26: 0 | I26: 8.33261 | J26: 0 | K26: 0.00123006 | M26: 225677 | N26: 1589.91 | O26: 109411 | P26: 10553 | Q26: 181626 | R26: 2721.28
A27: OpenMP version: 202011 | B27: AVX2 optimization enabled | C27: PARAMETR_SIZE: 168 | D27: MAX_VALUE_SIZE: 4 | E27: SET_PARAMETR_SIZE_ONE_X: 21 | F27: ANT_SIZE: 500 | G27: MAX_THREAD_CUDA: 512 | H27: NAME_FILE_GRAPH: Parametr_Graph/test168_4,txt | I27: KOL_ITERATION: 500 | J27: KOL_PROGREV: 5 | K27: KOL_PROGON_STATISTICS: 10 | L27: PARAMETR_RO: 0,999 | M27: PARAMETR_Q: 1 | N27: PRINT_INFORMATION: 0 | O27: MAX_PARAMETR_VALUE_TO_MIN_OPT: 1 | P27: OPTIMIZE: OPTIMIZE_MAX | Q27: FUNCTION: SHAFFERA | R27: HASH_TABLE_SIZE: 67108864 | S27: ZERO_HASH_RESULT: -1 | T27: ZERO_HASH: 18446744073709551615 | U27: MAX_PROBES: 10000 | V27: KOL_STAT_LEVEL: 20 | W27: TYPE_ACO: 1 | X27: ACOCCyN_KOL_ITERATION: 50 | Y27: CPU_RANDOM: 0 | Z27: KOL_THREAD_CPU_ANT: 12 | AA27: CONST_AVX: 4 | AB27: CONST_RANDOM: 100000 | AC27: MAX_CONST: 8000 | AD27: BIN_SEARCH: 0 | AE27: GO_ALG_MINMAX: 1 | AF27: PAR_MAX_ALG_MINMAX: 1000 | AG27: PAR_MIN_ALG_MINMAX: 1
A28: 1 | B28: 427.773 | C28: 0.57782 | D28: 403.08 | E28: 23.6103 | F28: 188.846 | G28: 16.5972 | H28: 0 | I28: 99.9971 | J28: 0 | K28: 0.00461954 | M28: 1830170 | N28: 3.34094 | O28: 1624920 | P28: 5601.84 | Q28: 356696 | R28: 2755.21
A29: 2 | B29: 255.032 | C29: 6.49802 | D29: 222.894 | E29: 25.0852 | F29: 190.459 | G29: 16.8658 | H29: 0 | I29: 49.9973 | J29: 0 | K29: 0.00123636 | M29: 650999 | N29: 429.202 | O29: 497287 | P29: 6298.9 | Q29: 362964 | R29: 2846.84
A30: 3 | B30: 203.559 | C30: 7.28825 | D30: 171.787 | E30: 23.9138 | F30: 198.015 | G30: 17.7943 | H30: 0 | I30: 33.3305 | J30: 0 | K30: 0.0102852 | M30: 414518 | N30: 532.588 | O30: 295227 | P30: 5719.85 | Q30: 392317 | R30: 3170.87
A31: 4 | B31: 183.655 | C31: 7.52334 | D31: 152.149 | E31: 23.4191 | F31: 196.757 | G31: 17.463 | H31: 0 | I31: 24.9982 | J31: 0 | K31: 0.00141318 | M31: 339133 | N31: 568.772 | O31: 233360 | P31: 5486.26 | Q31: 387266 | R31: 3049.75
A32: 5 | B32: 225.757 | C32: 8.2279 | D32: 189.969 | E32: 26.9872 | F32: 201.343 | G32: 17.8349 | H32: 0 | I32: 19.9988 | J32: 0 | K32: 0.00263968 | M32: 509758 | N32: 687.442 | O32: 360980 | P32: 7290.14 | Q32: 406806 | R32: 3184.86
A33: 6 | B33: 206.923 | C33: 10.102 | D33: 165.247 | E33: 31.0092 | F33: 203.554 | G33: 17.9435 | H33: 0 | I33: 16.6656 | J33: 0 | K33: 0.00143546 | M33: 428241 | N33: 1040.82 | O33: 273155 | P33: 9641.74 | Q33: 416588 | R33: 3226.18
A34: 7 | B34: 197.952 | C34: 11.2321 | D34: 153.108 | E34: 33.0455 | F34: 217.586 | G34: 18.7828 | H34: 0 | I34: 14.2847 | J34: 0 | K34: 0.00145411 | M34: 392016 | N34: 1270.99 | O34: 234719 | P34: 11041.9 | Q34: 478287 | R34: 3545.95
A35: 8 | B35: 185.693 | C35: 11.4584 | D35: 141.148 | E35: 32.5207 | F35: 212.758 | G35: 18.5717 | H35: 0 | I35: 12.4991 | J35: 0 | K35: 0.00123082 | M35: 344939 | N35: 1321.1 | O35: 199297 | P35: 10585.8 | Q35: 452776 | R35: 3449.61
A36: 9 | B36: 183.492 | C36: 12.5202 | D36: 137.834 | E36: 32.5724 | F36: 220.18 | G36: 19.038 | H36: 0 | I36: 11.1101 | J36: 0 | K36: 0.00319665 | M36: 336756 | N36: 1568.49 | O36: 190051 | P36: 10616 | Q36: 484837 | R36: 3624.66
A37: 10 | B37: 189.588 | C37: 12.6275 | D37: 141.519 | E37: 34.8722 | F37: 226.073 | G37: 19.2995 | H37: 0 | I37: 9.99928 | J37: 0 | K37: 0.00124052 | M37: 359929 | N37: 1595.25 | O37: 200804 | P37: 12162.4 | Q37: 511193 | R37: 3725.02
A38: 11 | B38: 217.066 | C38: 12.9154 | D38: 165.984 | E38: 37.5929 | F38: 227.207 | G38: 19.4544 | H38: 0 | I38: 9.09038 | J38: 0 | K38: 0.0108907 | M38: 471425 | N38: 1669.49 | O38: 275715 | P38: 14139.8 | Q38: 516278 | R38: 3785.59
A39: 12 | B39: 205.062 | C39: 12.4464 | D39: 152.359 | E39: 39.6752 | F39: 231.974 | G39: 19.8465 | H39: 0 | I39: 8.33281 | J39: 0 | K39: 0.00144772 | M39: 421920 | N39: 1558.86 | O39: 233763 | P39: 15761.2 | Q39: 538195 | R39: 3942.8
A40: OpenMP version: 202011 | B40: AVX2 optimization enabled | C40: PARAMETR_SIZE: 336 | D40: MAX_VALUE_SIZE: 4 | E40: SET_PARAMETR_SIZE_ONE_X: 21 | F40: ANT_SIZE: 500 | G40: MAX_THREAD_CUDA: 512 | H40: NAME_FILE_GRAPH: Parametr_Graph/test336_4,txt | I40: KOL_ITERATION: 500 | J40: KOL_PROGREV: 5 | K40: KOL_PROGON_STATISTICS: 10 | L40: PARAMETR_RO: 0,999 | M40: PARAMETR_Q: 1 | N40: PRINT_INFORMATION: 0 | O40: MAX_PARAMETR_VALUE_TO_MIN_OPT: 1 | P40: OPTIMIZE: OPTIMIZE_MAX | Q40: FUNCTION: SHAFFERA | R40: HASH_TABLE_SIZE: 67108864 | S40: ZERO_HASH_RESULT: -1 | T40: ZERO_HASH: 18446744073709551615 | U40: MAX_PROBES: 10000 | V40: KOL_STAT_LEVEL: 20 | W40: TYPE_ACO: 1 | X40: ACOCCyN_KOL_ITERATION: 50 | Y40: CPU_RANDOM: 0 | Z40: KOL_THREAD_CPU_ANT: 12 | AA40: CONST_AVX: 4 | AB40: CONST_RANDOM: 100000 | AC40: MAX_CONST: 8000 | AD40: BIN_SEARCH: 0 | AE40: GO_ALG_MINMAX: 1 | AF40: PAR_MAX_ALG_MINMAX: 1000 | AG40: PAR_MIN_ALG_MINMAX: 1
...

Sheet Лист2
B1: 13
B3: 1
B4: 0 | C4: 1 | D4: 2 | E4: 3 | F4: 4 | G4: 5 | H4: 6 | I4: 7 | J4: 8 | K4: 9 | L4: 10 | M4: 11 | N4: 12 | O4: 13 | P4: 14 | Q4: 15
B5: 42 | C5: =B5*2 -> 84 | D5: =C5*2 -> 168 | E5: =D5*2 -> 336 | F5: =E5*2 -> 672 | G5: =F5*2 -> 1344 | H5: =G5*2 -> 2688 | I5: =H5*2 -> 5376 | J5: =I5*2 -> 10752 | ... Q5: =P5*2 -> 1376256
A6: 1 | B6: =OFFSET(Лист1!$A$1,B$4*$B$1+$A6,$B$3) -> 164.127 | C6: =OFFSET(Лист1!$A$1,C$4*$B$1+$A6,$B$3) -> 249.153 | D6: =OFFSET(Лист1!$A$1,D$4*$B$1+$A6,$B$3) -> 427.773 | E6: =OFFSET(Лист1!$A$1,E$4*$B$1+$A6,$B$3) -> 795.077 | F6: =OFFSET(Лист1!$A$1,F$4*$B$1+$A6,$B$3) -> 1549.54 | G6: =OFFSET(Лист1!$A$1,G$4*$B$1+$A6,$B$3) -> 3082.79 | H6: =OFFSET(Лист1!$A$1,H$4*$B$1+$A6,$B$3) -> 6152.24 | I6: =OFFSET(Лист1!$A$1,I$4*$B$1+$A6,$B$3) -> 12334.6 | ... Q6: =OFFSET(Лист1!$A$1,Q$4*$B$1+$A6,$B$3) -> 0
A7: 2 | B7: =OFFSET(Лист1!$A$1,B$4*$B$1+$A7,$B$3) -> 113.962 | C7: =OFFSET(Лист1!$A$1,C$4*$B$1+$A7,$B$3) -> 159.387 | D7: =OFFSET(Лист1!$A$1,D$4*$B$1+$A7,$B$3) -> 255.032 | E7: =OFFSET(Лист1!$A$1,E$4*$B$1+$A7,$B$3) -> 441.125 | F7: =OFFSET(Лист1!$A$1,F$4*$B$1+$A7,$B$3) -> 827.551 | G7: =OFFSET(Лист1!$A$1,G$4*$B$1+$A7,$B$3) -> 1641.97 | H7: =OFFSET(Лист1!$A$1,H$4*$B$1+$A7,$B$3) -> 3227.23 | I7: =OFFSET(Лист1!$A$1,I$4*$B$1+$A7,$B$3) -> 6442.45 | ... Q7: =OFFSET(Лист1!$A$1,Q$4*$B$1+$A7,$B$3) -> 0
A8: 3 | B8: =OFFSET(Лист1!$A$1,B$4*$B$1+$A8,$B$3) -> 105.005 | C8: =OFFSET(Лист1!$A$1,C$4*$B$1+$A8,$B$3) -> 136.035 | D8: =OFFSET(Лист1!$A$1,D$4*$B$1+$A8,$B$3) -> 203.559 | E8: =OFFSET(Лист1!$A$1,E$4*$B$1+$A8,$B$3) -> 335.478 | F8: =OFFSET(Лист1!$A$1,F$4*$B$1+$A8,$B$3) -> 614.085 | G8: =OFFSET(Лист1!$A$1,G$4*$B$1+$A8,$B$3) -> 1178.78 | H8: =OFFSET(Лист1!$A$1,H$4*$B$1+$A8,$B$3) -> 2296.01 | I8: =OFFSET(Лист1!$A$1,I$4*$B$1+$A8,$B$3) -> 4517.11 | ... Q8: =OFFSET(Лист1!$A$1,Q$4*$B$1+$A8,$B$3) -> 0
A9: 4 | B9: =OFFSET(Лист1!$A$1,B$4*$B$1+$A9,$B$3) -> 105.102 | C9: =OFFSET(Лист1!$A$1,C$4*$B$1+$A9,$B$3) -> 135.074 | D9: =OFFSET(Лист1!$A$1,D$4*$B$1+$A9,$B$3) -> 183.655 | E9: =OFFSET(Лист1!$A$1,E$4*$B$1+$A9,$B$3) -> 338.271 | F9: =OFFSET(Лист1!$A$1,F$4*$B$1+$A9,$B$3) -> 525.257 | G9: =OFFSET(Лист1!$A$1,G$4*$B$1+$A9,$B$3) -> 952.672 | H9: =OFFSET(Лист1!$A$1,H$4*$B$1+$A9,$B$3) -> 1770.46 | I9: =OFFSET(Лист1!$A$1,I$4*$B$1+$A9,$B$3) -> 3685.39 | ... Q9: =OFFSET(Лист1!$A$1,Q$4*$B$1+$A9,$B$3) -> 0
A10: 5 | B10: =OFFSET(Лист1!$A$1,B$4*$B$1+$A10,$B$3) -> 113.309 | C10: =OFFSET(Лист1!$A$1,C$4*$B$1+$A10,$B$3) -> 149.93 | D10: =OFFSET(Лист1!$A$1,D$4*$B$1+$A10,$B$3) -> 225.757 | E10: =OFFSET(Лист1!$A$1,E$4*$B$1+$A10,$B$3) -> 408.81 | F10: =OFFSET(Лист1!$A$1,F$4*$B$1+$A10,$B$3) -> 706.044 | G10: =OFFSET(Лист1!$A$1,G$4*$B$1+$A10,$B$3) -> 1284.9 | H10: =OFFSET(Лист1!$A$1,H$4*$B$1+$A10,$B$3) -> 2118.73 | I10: =OFFSET(Лист1!$A$1,I$4*$B$1+$A10,$B$3) -> 3992.87 | ... Q10: =OFFSET(Лист1!$A$1,Q$4*$B$1+$A10,$B$3) -> 0
A11: 6 | B11: =OFFSET(Лист1!$A$1,B$4*$B$1+$A11,$B$3) -> 112.434 | C11: =OFFSET(Лист1!$A$1,C$4*$B$1+$A11,$B$3) -> 142.059 | D11: =OFFSET(Лист1!$A$1,D$4*$B$1+$A11,$B$3) -> 206.923 | E11: =OFFSET(Лист1!$A$1,E$4*$B$1+$A11,$B$3) -> 348.197 | F11: =OFFSET(Лист1!$A$1,F$4*$B$1+$A11,$B$3) -> 624.342 | G11: =OFFSET(Лист1!$A$1,G$4*$B$1+$A11,$B$3) -> 1146.95 | H11: =OFFSET(Лист1!$A$1,H$4*$B$1+$A11,$B$3) -> 1995.63 | I11: =OFFSET(Лист1!$A$1,I$4*$B$1+$A11,$B$3) -> 3693.85 | ... Q11: =OFFSET(Лист1!$A$1,Q$4*$B$1+$A11,$B$3) -> 0
A12: 7 | B12: =OFFSET(Лист1!$A$1,B$4*$B$1+$A12,$B$3) -> 116.217 | C12: =OFFSET(Лист1!$A$1,C$4*$B$1+$A12,$B$3) -> 138.502 | D12: =OFFSET(Лист1!$A$1,D$4*$B$1+$A12,$B$3) -> 197.952 | E12: =OFFSET(Лист1!$A$1,E$4*$B$1+$A12,$B$3) -> 314.657 | F12: =OFFSET(Лист1!$A$1,F$4*$B$1+$A12,$B$3) -> 572.008 | G12: =OFFSET(Лист1!$A$1,G$4*$B$1+$A12,$B$3) -> 1046.86 | H12: =OFFSET(Лист1!$A$1,H$4*$B$1+$A12,$B$3) -> 1878.01 | I12: =OFFSET(Лист1!$A$1,I$4*$B$1+$A12,$B$3) -> 3380.73 | ... Q12: =OFFSET(Лист1!$A$1,Q$4*$B$1+$A12,$B$3) -> 0
A13: 8 | B13: =OFFSET(Лист1!$A$1,B$4*$B$1+$A13,$B$3) -> 112.537 | C13: =OFFSET(Лист1!$A$1,C$4*$B$1+$A13,$B$3) -> 133.752 | D13: =OFFSET(Лист1!$A$1,D$4*$B$1+$A13,$B$3) -> 185.693 | E13: =OFFSET(Лист1!$A$1,E$4*$B$1+$A13,$B$3) -> 289.397 | F13: =OFFSET(Лист1!$A$1,F$4*$B$1+$A13,$B$3) -> 514.515 | G13: =OFFSET(Лист1!$A$1,G$4*$B$1+$A13,$B$3) -> 949.892 | H13: =OFFSET(Лист1!$A$1,H$4*$B$1+$A13,$B$3) -> 1633.94 | I13: =OFFSET(Лист1!$A$1,I$4*$B$1+$A13,$B$3) -> 3048.34 | ... Q13: =OFFSET(Лист1!$A$1,Q$4*$B$1+$A13,$B$3) -> 0
A14: 9 | B14: =OFFSET(Лист1!$A$1,B$4*$B$1+$A14,$B$3) -> 113.69 | C14: =OFFSET(Лист1!$A$1,C$4*$B$1+$A14,$B$3) -> 134.918 | D14: =OFFSET(Лист1!$A$1,D$4*$B$1+$A14,$B$3) -> 183.492 | E14: =OFFSET(Лист1!$A$1,E$4*$B$1+$A14,$B$3) -> 277.909 | F14: =OFFSET(Лист1!$A$1,F$4*$B$1+$A14,$B$3) -> 483.873 | G14: =OFFSET(Лист1!$A$1,G$4*$B$1+$A14,$B$3) -> 888.905 | H14: =OFFSET(Лист1!$A$1,H$4*$B$1+$A14,$B$3) -> 1512.91 | I14: =OFFSET(Лист1!$A$1,I$4*$B$1+$A14,$B$3) -> 3097.13 | ... Q14: =OFFSET(Лист1!$A$1,Q$4*$B$1+$A14,$B$3) -> 0
A15: 10 | B15: =OFFSET(Лист1!$A$1,B$4*$B$1+$A15,$B$3) -> 123.048 | C15: =OFFSET(Лист1!$A$1,C$4*$B$1+$A15,$B$3) -> 153.179 | D15: =OFFSET(Лист1!$A$1,D$4*$B$1+$A15,$B$3) -> 189.588 | E15: =OFFSET(Лист1!$A$1,E$4*$B$1+$A15,$B$3) -> 271.396 | F15: =OFFSET(Лист1!$A$1,F$4*$B$1+$A15,$B$3) -> 483.989 | G15: =OFFSET(Лист1!$A$1,G$4*$B$1+$A15,$B$3) -> 866.918 | H15: =OFFSET(Лист1!$A$1,H$4*$B$1+$A15,$B$3) -> 1468.35 | I15: =OFFSET(Лист1!$A$1,I$4*$B$1+$A15,$B$3) -> 2768.35 | ... Q15: =OFFSET(Лист1!$A$1,Q$4*$B$1+$A15,$B$3) -> 0
A16: 11 | B16: =OFFSET(Лист1!$A$1,B$4*$B$1+$A16,$B$3) -> 124.104 | C16: =OFFSET(Лист1!$A$1,C$4*$B$1+$A16,$B$3) -> 149.924 | D16: =OFFSET(Лист1!$A$1,D$4*$B$1+$A16,$B$3) -> 217.066 | E16: =OFFSET(Лист1!$A$1,E$4*$B$1+$A16,$B$3) -> 326.859 | F16: =OFFSET(Лист1!$A$1,F$4*$B$1+$A16,$B$3) -> 530.483 | G16: =OFFSET(Лист1!$A$1,G$4*$B$1+$A16,$B$3) -> 820.407 | H16: =OFFSET(Лист1!$A$1,H$4*$B$1+$A16,$B$3) -> 1674.09 | I16: =OFFSET(Лист1!$A$1,I$4*$B$1+$A16,$B$3) -> 2777.01 | ... Q16: =OFFSET(Лист1!$A$1,Q$4*$B$1+$A16,$B$3) -> 0
A17: 12 | B17: =OFFSET(Лист1!$A$1,B$4*$B$1+$A17,$B$3) -> 121.148 | C17: =OFFSET(Лист1!$A$1,C$4*$B$1+$A17,$B$3) -> 150.131 | D17: =OFFSET(Лист1!$A$1,D$4*$B$1+$A17,$B$3) -> 205.062 | E17: =OFFSET(Лист1!$A$1,E$4*$B$1+$A17,$B$3) -> 322.762 | F17: =OFFSET(Лист1!$A$1,F$4*$B$1+$A17,$B$3) -> 537.973 | G17: =OFFSET(Лист1!$A$1,G$4*$B$1+$A17,$B$3) -> 805.278 | H17: =OFFSET(Лист1!$A$1,H$4*$B$1+$A17,$B$3) -> 1546.39 | I17: =OFFSET(Лист1!$A$1,I$4*$B$1+$A17,$B$3) -> 2599.94 | ... Q17: =OFFSET(Лист1!$A$1,Q$4*$B$1+$A17,$B$3) -> 0
B20: 42 | C20: =B20*2 -> 84 | D20: =C20*2 -> 168 | E20: =D20*2 -> 336 | F20: =E20*2 -> 672 | G20: =F20*2 -> 1344 | H20: =G20*2 -> 2688 | I20: =H20*2 -> 5376 | J20: =I20*2 -> 10752 | ... Q20: =P20*2 -> 1376256
A21: 1 | B21: =B6/B$5 -> 3.9077857 | C21: =C6/C$5 -> 2.9661071 | D21: =D6/D$5 -> 2.5462679 | E21: =E6/E$5 -> 2.3663006 | F21: =F6/F$5 -> 2.3058631 | G21: =G6/G$5 -> 2.2937426 | H21: =H6/H$5 -> 2.2887798 | I21: =I6/I$5 -> 2.2943824 | ... Q21: =Q6/Q$5 -> 0
A22: 2 | B22: =B7/B$5 -> 2.713381 | C22: =C7/C$5 -> 1.8974643 | D22: =D7/D$5 -> 1.5180476 | E22: =E7/E$5 -> 1.312872 | F22: =F7/F$5 -> 1.2314747 | G22: =G7/G$5 -> 1.2217039 | H22: =H7/H$5 -> 1.2006064 | I22: =I7/I$5 -> 1.1983724 | ... Q22: =Q7/Q$5 -> 0
A23: 3 | B23: =B8/B$5 -> 2.500119 | C23: =C8/C$5 -> 1.6194643 | D23: =D8/D$5 -> 1.2116607 | E23: =E8/E$5 -> 0.99844643 | F23: =F8/F$5 -> 0.91381696 | G23: =G8/G$5 -> 0.87706845 | H23: =H8/H$5 -> 0.85417039 | I23: =I8/I$5 -> 0.84023624 | ... Q23: =Q8/Q$5 -> 0
A24: 4 | B24: =B9/B$5 -> 2.5024286 | C24: =C9/C$5 -> 1.6080238 | D24: =D9/D$5 -> 1.0931845 | E24: =E9/E$5 -> 1.0067589 | F24: =F9/F$5 -> 0.78163244 | G24: =G9/G$5 -> 0.70883333 | H24: =H9/H$5 -> 0.65865327 | I24: =I9/I$5 -> 0.68552641 | ... Q24: =Q9/Q$5 -> 0
A25: 5 | B25: =B10/B$5 -> 2.6978333 | C25: =C10/C$5 -> 1.784881 | D25: =D10/D$5 -> 1.3437917 | E25: =E10/E$5 -> 1.2166964 | F25: =F10/F$5 -> 1.0506607 | G25: =G10/G$5 -> 0.95602679 | H25: =H10/H$5 -> 0.78821801 | I25: =I10/I$5 -> 0.74272135 | ... Q25: =Q10/Q$5 -> 0
A26: 6 | B26: =B11/B$5 -> 2.677 | C26: =C11/C$5 -> 1.6911786 | D26: =D11/D$5 -> 1.2316845 | E26: =E11/E$5 -> 1.0363006 | F26: =F11/F$5 -> 0.92908036 | G26: =G11/G$5 -> 0.85338542 | H26: =H11/H$5 -> 0.74242188 | I26: =I11/I$5 -> 0.68710007 | ... Q26: =Q11/Q$5 -> 0
A27: 7 | B27: =B12/B$5 -> 2.7670714 | C27: =C12/C$5 -> 1.6488333 | D27: =D12/D$5 -> 1.1782857 | E27: =E12/E$5 -> 0.93647917 | F27: =F12/F$5 -> 0.85120238 | G27: =G12/G$5 -> 0.77891369 | H27: =H12/H$5 -> 0.69866443 | I27: =I12/I$5 -> 0.62885603 | ... Q27: =Q12/Q$5 -> 0
A28: 8 | B28: =B13/B$5 -> 2.6794524 | C28: =C13/C$5 -> 1.5922857 | D28: =D13/D$5 -> 1.1053155 | E28: =E13/E$5 -> 0.8613006 | F28: =F13/F$5 -> 0.76564732 | G28: =G13/G$5 -> 0.70676488 | H28: =H13/H$5 -> 0.60786458 | I28: =I13/I$5 -> 0.56702753 | ... Q28: =Q13/Q$5 -> 0
A29: 9 | B29: =B14/B$5 -> 2.7069048 | C29: =C14/C$5 -> 1.6061667 | D29: =D14/D$5 -> 1.0922143 | E29: =E14/E$5 -> 0.82711012 | F29: =F14/F$5 -> 0.72004911 | G29: =G14/G$5 -> 0.66138765 | H29: =H14/H$5 -> 0.56283854 | I29: =I14/I$5 -> 0.57610305 | ... Q29: =Q14/Q$5 -> 0
A30: 10 | B30: =B15/B$5 -> 2.9297143 | C30: =C15/C$5 -> 1.8235595 | D30: =D15/D$5 -> 1.1285 | E30: =E15/E$5 -> 0.80772619 | F30: =F15/F$5 -> 0.72022173 | G30: =G15/G$5 -> 0.64502827 | H30: =H15/H$5 -> 0.54626116 | I30: =I15/I$5 -> 0.51494606 | ... Q30: =Q15/Q$5 -> 0
A31: 11 | B31: =B16/B$5 -> 2.9548571 | C31: =C16/C$5 -> 1.7848095 | D31: =D16/D$5 -> 1.2920595 | E31: =E16/E$5 -> 0.97279464 | F31: =F16/F$5 -> 0.78940923 | G31: =G16/G$5 -> 0.61042188 | H31: =H16/H$5 -> 0.62280134 | I31: =I16/I$5 -> 0.51655692 | ... Q31: =Q16/Q$5 -> 0
A32: 12 | B32: =B17/B$5 -> 2.8844762 | C32: =C17/C$5 -> 1.7872738 | D32: =D17/D$5 -> 1.2206071 | E32: =E17/E$5 -> 0.96060119 | F32: =F17/F$5 -> 0.80055506 | G32: =G17/G$5 -> 0.59916518 | H32: =H17/H$5 -> 0.5752939 | I32: =I17/I$5 -> 0.48361979 | ... Q32: =Q17/Q$5 -> 0
