Workbook

Sheet Itog
C1: Node= | D1: 4 | F1: 42 | G1: =F1*2 -> 84 | H1: =G1*2 -> 168 | I1: =H1*2 -> 336 | J1: =I1*2 -> 672 | K1: =J1*2 -> 1344 | L1: =K1*2 -> 2688 | M1: =L1*2 -> 5376 | N1: =M1*2 -> 10752 | ... X1: =W1*2 -> 11010048 | Z1: 1 | AA1: << "Time=" << metrics.total_time_ms << "ms "
B2: 1 | E2: 51 | F2: 0 | G2: 49 | K2: const | M2: shared | Z2: 2 | AA2: << "Kernel=" << metrics.kernel_time_ms << "ms "
B3: 42clangOMP31 | C3: ANT node | D3: ANT all | E3: 0 | F3: 1 | Z3: 3 | AA3: << "Probabilities=" << metrics.computeProbabilities_time_ms << "ms "
A4: 0 | B4: 1 | C4: 64 | D4: =C4*$D$1 -> 256 | E4: =OFFSET('t42'!$A$1,$B$2+($B4-1)*$E$2+$A4,E$3) -> Run MPI Combined Run0 | F4: =AVERAGE(OFFSET('t42'!$A$1,$B$2+($B4-1)*$E$2+$F$2+$A4,F$3):OFFSET('t42'!$A$1,$B$2+($B4-1)*$E$2+$F$2+$G$2+$A4,F$3)) -> 62.451232 | G4: =AVERAGE(OFFSET('t84'!$A$1,$B$2+($B4-1)*$E$2+$F$2+$A4,F$3):OFFSET('t84'!$A$1,$B$2+($B4-1)*$E$2+$F$2+$G$2+$A4,F$3)) -> 69.661746 | H4: =AVERAGE(OFFSET('t168'!$A$1,$B$2+($B4-1)*$E$2+$F$2+$A4,F$3):OFFSET('t168'!$A$1,$B$2+($B4-1)*$E$2+$F$2+$G$2+$A4,F$3)) -> 85.86672 | I4: =AVERAGE(OFFSET('t336'!$A$1,$B$2+($B4-1)*$E$2+$F$2+$A4,F$3):OFFSET('t336'!$A$1,$B$2+($B4-1)*$E$2+$F$2+$G$2+$A4,F$3)) -> 112.96721 | J4: =AVERAGE(OFFSET('t672'!$A$1,$B$2+($B4-1)*$E$2+$F$2+$A4,F$3):OFFSET('t672'!$A$1,$B$2+($B4-1)*$E$2+$F$2+$G$2+$A4,F$3)) -> 171.1344 | K4: =AVERAGE(OFFSET('t1344'!$A$1,$B$2+($B4-1)*$E$2+$F$2+$A4,F$3):OFFSET('t1344'!$A$1,$B$2+($B4-1)*$E$2+$F$2+$G$2+$A4,F$3)) -> 278.25462 | L4: =AVERAGE(OFFSET('t2688'!$A$1,$B$2+($B4-1)*$E$2+$F$2+$A4,F$3):OFFSET('t2688'!$A$1,$B$2+($B4-1)*$E$2+$F$2+$G$2+$A4,F$3)) -> 508.96188 | M4: =AVERAGE(OFFSET('t5376'!$A$1,$B$2+($B4-1)*$E$2+$F$2+$A4,F$3):OFFSET('t5376'!$A$1,$B$2+($B4-1)*$E$2+$F$2+$G$2+$A4,F$3)) -> 922.25812 | N4: =AVERAGE(OFFSET('t10752'!$A$1,$B$2+($B4-1)*$E$2+$F$2+$A4,F$3):OFFSET('t10752'!$A$1,$B$2+($B4-1)*$E$2+$F$2+$G$2+$A4,F$3)) -> 1774.8392 | O4: =AVERAGE(OFFSET('t21504'!$A$1,$B$2+($B4-1)*$E$2+$F$2+$A4,F$3):OFFSET('t21504'!$A$1,$B$2+($B4-1)*$E$2+$F$2+$G$2+$A4,F$3)) -> 3567.8072 | P4: =AVERAGE(OFFSET('t43008'!$A$1,$B$2+($B4-1)*$E$2+$F$2+$A4,F$3):OFFSET('t43008'!$A$1,$B$2+($B4-1)*$E$2+$F$2+$G$2+$A4,F$3)) -> 6973.6632 | Q4: =AVERAGE(OFFSET('t86016'!$A$1,$B$2+($B4-1)*$E$2+$F$2+$A4,F$3):OFFSET('t86016'!$A$1,$B$2+($B4-1)*$E$2+$F$2+$G$2+$A4,F$3)) -> 14374.394 | R4: =AVERAGE(OFFSET('t172032'!$A$1,$B$2+($B4-1)*$E$2+$F$2+$A4,F$3):OFFSET('t172032'!$A$1,$B$2+($B4-1)*$E$2+$F$2+$G$2+$A4,F$3)) -> 29681.238 | S4: =AVERAGE(OFFSET('t344064'!$A$1,$B$2+($B4-1)*$E$2+$F$2+$A4,F$3):OFFSET('t344064'!$A$1,$B$2+($B4-1)*$E$2+$F$2+$G$2+$A4,F$3)) -> 64336.632 | T4: =AVERAGE(OFFSET('t688128'!$A$1,$B$2+($B4-1)*$E$2+$F$2+$A4,F$3):OFFSET('t688128'!$A$1,$B$2+($B4-1)*$E$2+$F$2+$G$2+$A4,F$3)) -> 109438.72 | U4: =AVERAGE(OFFSET(t1376256!$A$1,$B$2+($B4-1)*$E$2+$F$2+$A4,F$3):OFFSET(t1376256!$A$1,$B$2+($B4-1)*$E$2+$F$2+$G$2+$A4,F$3)) -> 285036.94 | Z4: 4 | AA4: << "Ant=" << metrics.antColonyOptimization_time_ms << "ms "
B5: 2 | C5: =C4*2 -> 128 | D5: =C5*$D$1 -> 512 | E5: =OFFSET('t42'!$A$1,$B$2+($B5-1)*$E$2+$A4,E$3) -> Run MPI Combined Run0 | F5: =AVERAGE(OFFSET('t42'!$A$1,$B$2+($B5-1)*$E$2+$F$2+$A4+1,F$3):OFFSET('t42'!$A$1,$B$2+($B5-1)*$E$2+$F$2+$G$2+$A4,F$3)) -> 62.812129 | G5: =AVERAGE(OFFSET('t84'!$A$1,$B$2+($B5-1)*$E$2+$F$2+$A4+1,F$3):OFFSET('t84'!$A$1,$B$2+($B5-1)*$E$2+$F$2+$G$2+$A4,F$3)) -> 70.296963 | H5: =AVERAGE(OFFSET('t168'!$A$1,$B$2+($B5-1)*$E$2+$F$2+$A4+1,F$3):OFFSET('t168'!$A$1,$B$2+($B5-1)*$E$2+$F$2+$G$2+$A4,F$3)) -> 87.1522 | I5: =AVERAGE(OFFSET('t336'!$A$1,$B$2+($B5-1)*$E$2+$F$2+$A4+1,F$3):OFFSET('t336'!$A$1,$B$2+($B5-1)*$E$2+$F$2+$G$2+$A4,F$3)) -> 115.07722 | J5: =AVERAGE(OFFSET('t672'!$A$1,$B$2+($B5-1)*$E$2+$F$2+$A4+1,F$3):OFFSET('t672'!$A$1,$B$2+($B5-1)*$E$2+$F$2+$G$2+$A4,F$3)) -> 169.89186 | K5: =AVERAGE(OFFSET('t1344'!$A$1,$B$2+($B5-1)*$E$2+$F$2+$A4+1,F$3):OFFSET('t1344'!$A$1,$B$2+($B5-1)*$E$2+$F$2+$G$2+$A4,F$3)) -> 277.03498 | L5: =AVERAGE(OFFSET('t2688'!$A$1,$B$2+($B5-1)*$E$2+$F$2+$A4+1,F$3):OFFSET('t2688'!$A$1,$B$2+($B5-1)*$E$2+$F$2+$G$2+$A4,F$3)) -> 530.41469 | M5: =AVERAGE(OFFSET('t5376'!$A$1,$B$2+($B5-1)*$E$2+$F$2+$A4+1,F$3):OFFSET('t5376'!$A$1,$B$2+($B5-1)*$E$2+$F$2+$G$2+$A4,F$3)) -> 959.38943 | N5: =AVERAGE(OFFSET('t10752'!$A$1,$B$2+($B5-1)*$E$2+$F$2+$A4+1,F$3):OFFSET('t10752'!$A$1,$B$2+($B5-1)*$E$2+$F$2+$G$2+$A4,F$3)) -> 1885.6086 | O5: =AVERAGE(OFFSET('t21504'!$A$1,$B$2+($B5-1)*$E$2+$F$2+$A4+1,F$3):OFFSET('t21504'!$A$1,$B$2+($B5-1)*$E$2+$F$2+$G$2+$A4,F$3)) -> 3773.0784 | P5: =AVERAGE(OFFSET('t43008'!$A$1,$B$2+($B5-1)*$E$2+$F$2+$A4+1,F$3):OFFSET('t43008'!$A$1,$B$2+($B5-1)*$E$2+$F$2+$G$2+$A4,F$3)) -> 7251.4914 | Q5: =AVERAGE(OFFSET('t86016'!$A$1,$B$2+($B5-1)*$E$2+$F$2+$A4+1,F$3):OFFSET('t86016'!$A$1,$B$2+($B5-1)*$E$2+$F$2+$G$2+$A4,F$3)) -> 15313.755 | R5: =AVERAGE(OFFSET('t172032'!$A$1,$B$2+($B5-1)*$E$2+$F$2+$A4+1,F$3):OFFSET('t172032'!$A$1,$B$2+($B5-1)*$E$2+$F$2+$G$2+$A4,F$3)) -> 31180.727 | S5: =AVERAGE(OFFSET('t344064'!$A$1,$B$2+($B5-1)*$E$2+$F$2+$A4+1,F$3):OFFSET('t344064'!$A$1,$B$2+($B5-1)*$E$2+$F$2+$G$2+$A4,F$3)) -> 69680.002 | T5: =AVERAGE(OFFSET('t688128'!$A$1,$B$2+($B5-1)*$E$2+$F$2+$A4+1,F$3):OFFSET('t688128'!$A$1,$B$2+($B5-1)*$E$2+$F$2+$G$2+$A4,F$3)) -> 118010.61 | U5: =AVERAGE(OFFSET(t1376256!$A$1,$B$2+($B5-1)*$E$2+$F$2+$A4+1,F$3):OFFSET(t1376256!$A$1,$B$2+($B5-1)*$E$2+$F$2+$G$2+$A4,F$3)) -> 307911.06 | Z5: 5 | AA5: << "Update=" << metrics.updatePheromones_time_ms << "ms "
A6: 0 | B6: 3 | C6: =C5*2 -> 256 | D6: =C6*$D$1 -> 1024 | E6: =OFFSET('t42'!$A$1,$B$2+($B6-1)*$E$2+$A6,E$3) -> Run MPI Combined Run0 | F6: =AVERAGE(OFFSET('t42'!$A$1,$B$2+($B6-1)*$E$2+$F$2+$A6,F$3):OFFSET('t42'!$A$1,$B$2+($B6-1)*$E$2+$F$2+$G$2+$A6,F$3)) -> 62.957284 | G6: =AVERAGE(OFFSET('t84'!$A$1,$B$2+($B6-1)*$E$2+$F$2+$A6,F$3):OFFSET('t84'!$A$1,$B$2+($B6-1)*$E$2+$F$2+$G$2+$A6,F$3)) -> 74.213382 | H6: =AVERAGE(OFFSET('t168'!$A$1,$B$2+($B6-1)*$E$2+$F$2+$A6,F$3):OFFSET('t168'!$A$1,$B$2+($B6-1)*$E$2+$F$2+$G$2+$A6,F$3)) -> 88.833834 | I6: =AVERAGE(OFFSET('t336'!$A$1,$B$2+($B6-1)*$E$2+$F$2+$A6,F$3):OFFSET('t336'!$A$1,$B$2+($B6-1)*$E$2+$F$2+$G$2+$A6,F$3)) -> 116.134 | J6: =AVERAGE(OFFSET('t672'!$A$1,$B$2+($B6-1)*$E$2+$F$2+$A6,F$3):OFFSET('t672'!$A$1,$B$2+($B6-1)*$E$2+$F$2+$G$2+$A6,F$3)) -> 178.8378 | K6: =AVERAGE(OFFSET('t1344'!$A$1,$B$2+($B6-1)*$E$2+$F$2+$A6,F$3):OFFSET('t1344'!$A$1,$B$2+($B6-1)*$E$2+$F$2+$G$2+$A6,F$3)) -> 290.9529 | L6: =AVERAGE(OFFSET('t2688'!$A$1,$B$2+($B6-1)*$E$2+$F$2+$A6,F$3):OFFSET('t2688'!$A$1,$B$2+($B6-1)*$E$2+$F$2+$G$2+$A6,F$3)) -> 550.7111 | M6: =AVERAGE(OFFSET('t5376'!$A$1,$B$2+($B6-1)*$E$2+$F$2+$A6,F$3):OFFSET('t5376'!$A$1,$B$2+($B6-1)*$E$2+$F$2+$G$2+$A6,F$3)) -> 1061.7183 | N6: =AVERAGE(OFFSET('t10752'!$A$1,$B$2+($B6-1)*$E$2+$F$2+$A6,F$3):OFFSET('t10752'!$A$1,$B$2+($B6-1)*$E$2+$F$2+$G$2+$A6,F$3)) -> 1913.1262 | O6: =AVERAGE(OFFSET('t21504'!$A$1,$B$2+($B6-1)*$E$2+$F$2+$A6,F$3):OFFSET('t21504'!$A$1,$B$2+($B6-1)*$E$2+$F$2+$G$2+$A6,F$3)) -> 4089.147 | P6: =AVERAGE(OFFSET('t43008'!$A$1,$B$2+($B6-1)*$E$2+$F$2+$A6,F$3):OFFSET('t43008'!$A$1,$B$2+($B6-1)*$E$2+$F$2+$G$2+$A6,F$3)) -> 8089.1922 | Q6: =AVERAGE(OFFSET('t86016'!$A$1,$B$2+($B6-1)*$E$2+$F$2+$A6,F$3):OFFSET('t86016'!$A$1,$B$2+($B6-1)*$E$2+$F$2+$G$2+$A6,F$3)) -> 17125.084 | R6: =AVERAGE(OFFSET('t172032'!$A$1,$B$2+($B6-1)*$E$2+$F$2+$A6,F$3):OFFSET('t172032'!$A$1,$B$2+($B6-1)*$E$2+$F$2+$G$2+$A6,F$3)) -> 36530.88 | S6: =AVERAGE(OFFSET('t344064'!$A$1,$B$2+($B6-1)*$E$2+$F$2+$A6,F$3):OFFSET('t344064'!$A$1,$B$2+($B6-1)*$E$2+$F$2+$G$2+$A6,F$3)) -> 84068.218 | T6: =AVERAGE(OFFSET('t688128'!$A$1,$B$2+($B6-1)*$E$2+$F$2+$A6,F$3):OFFSET('t688128'!$A$1,$B$2+($B6-1)*$E$2+$F$2+$G$2+$A6,F$3)) -> 144314.76 | U6: =AVERAGE(OFFSET(t1376256!$A$1,$B$2+($B6-1)*$E$2+$F$2+$A6,F$3):OFFSET(t1376256!$A$1,$B$2+($B6-1)*$E$2+$F$2+$G$2+$A6,F$3)) -> 376330.14 | Z6: 6 | AA6: << "Memory=" << metrics.memory_time_ms << "ms "
B7: 4 | C7: =C6*2 -> 512 | D7: =C7*$D$1 -> 2048 | E7: =OFFSET('t42'!$A$1,$B$2+($B7-1)*$E$2+$A6,E$3) -> Run MPI Combined Run0 | F7: =AVERAGE(OFFSET('t42'!$A$1,$B$2+($B7-1)*$E$2+$F$2+$A6+1,F$3):OFFSET('t42'!$A$1,$B$2+($B7-1)*$E$2+$F$2+$G$2+$A6,F$3)) -> 65.781865 | G7: =AVERAGE(OFFSET('t84'!$A$1,$B$2+($B7-1)*$E$2+$F$2+$A6+1,F$3):OFFSET('t84'!$A$1,$B$2+($B7-1)*$E$2+$F$2+$G$2+$A6,F$3)) -> 76.01778 | H7: =AVERAGE(OFFSET('t168'!$A$1,$B$2+($B7-1)*$E$2+$F$2+$A6+1,F$3):OFFSET('t168'!$A$1,$B$2+($B7-1)*$E$2+$F$2+$G$2+$A6,F$3)) -> 91.326729 | I7: =AVERAGE(OFFSET('t336'!$A$1,$B$2+($B7-1)*$E$2+$F$2+$A6+1,F$3):OFFSET('t336'!$A$1,$B$2+($B7-1)*$E$2+$F$2+$G$2+$A6,F$3)) -> 123.54996 | J7: =AVERAGE(OFFSET('t672'!$A$1,$B$2+($B7-1)*$E$2+$F$2+$A6+1,F$3):OFFSET('t672'!$A$1,$B$2+($B7-1)*$E$2+$F$2+$G$2+$A6,F$3)) -> 187.59065 | K7: =AVERAGE(OFFSET('t1344'!$A$1,$B$2+($B7-1)*$E$2+$F$2+$A6+1,F$3):OFFSET('t1344'!$A$1,$B$2+($B7-1)*$E$2+$F$2+$G$2+$A6,F$3)) -> 314.18288 | L7: =AVERAGE(OFFSET('t2688'!$A$1,$B$2+($B7-1)*$E$2+$F$2+$A6+1,F$3):OFFSET('t2688'!$A$1,$B$2+($B7-1)*$E$2+$F$2+$G$2+$A6,F$3)) -> 604.99424 | M7: =AVERAGE(OFFSET('t5376'!$A$1,$B$2+($B7-1)*$E$2+$F$2+$A6+1,F$3):OFFSET('t5376'!$A$1,$B$2+($B7-1)*$E$2+$F$2+$G$2+$A6,F$3)) -> 1199.2224 | N7: =AVERAGE(OFFSET('t10752'!$A$1,$B$2+($B7-1)*$E$2+$F$2+$A6+1,F$3):OFFSET('t10752'!$A$1,$B$2+($B7-1)*$E$2+$F$2+$G$2+$A6,F$3)) -> 2372.5845 | O7: =AVERAGE(OFFSET('t21504'!$A$1,$B$2+($B7-1)*$E$2+$F$2+$A6+1,F$3):OFFSET('t21504'!$A$1,$B$2+($B7-1)*$E$2+$F$2+$G$2+$A6,F$3)) -> 4884.4151 | P7: =AVERAGE(OFFSET('t43008'!$A$1,$B$2+($B7-1)*$E$2+$F$2+$A6+1,F$3):OFFSET('t43008'!$A$1,$B$2+($B7-1)*$E$2+$F$2+$G$2+$A6,F$3)) -> 10278.776 | Q7: =AVERAGE(OFFSET('t86016'!$A$1,$B$2+($B7-1)*$E$2+$F$2+$A6+1,F$3):OFFSET('t86016'!$A$1,$B$2+($B7-1)*$E$2+$F$2+$G$2+$A6,F$3)) -> 22326.859 | R7: =AVERAGE(OFFSET('t172032'!$A$1,$B$2+($B7-1)*$E$2+$F$2+$A6+1,F$3):OFFSET('t172032'!$A$1,$B$2+($B7-1)*$E$2+$F$2+$G$2+$A6,F$3)) -> 47675.682 | S7: =AVERAGE(OFFSET('t344064'!$A$1,$B$2+($B7-1)*$E$2+$F$2+$A6+1,F$3):OFFSET('t344064'!$A$1,$B$2+($B7-1)*$E$2+$F$2+$G$2+$A6,F$3)) -> 99357.8 | T7: =AVERAGE(OFFSET('t688128'!$A$1,$B$2+($B7-1)*$E$2+$F$2+$A6+1,F$3):OFFSET('t688128'!$A$1,$B$2+($B7-1)*$E$2+$F$2+$G$2+$A6,F$3)) -> 196864.35 | U7: =AVERAGE(OFFSET(t1376256!$A$1,$B$2+($B7-1)*$E$2+$F$2+$A6+1,F$3):OFFSET(t1376256!$A$1,$B$2+($B7-1)*$E$2+$F$2+$G$2+$A6,F$3)) -> 487888.92 | Z7: 7 | AA7: << "HitRate=" << (100.0 * metrics.hash_hits / (metrics.hash_hits + metrics.hash_misses)) << "% "
A8: 0 | B8: 5 | C8: =C7*2 -> 1024 | D8: =C8*$D$1 -> 4096 | E8: =OFFSET('t42'!$A$1,$B$2+($B8-1)*$E$2+$A8,E$3) -> Run MPI Combined Run0 | F8: =AVERAGE(OFFSET('t42'!$A$1,$B$2+($B8-1)*$E$2+$F$2+$A8,F$3):OFFSET('t42'!$A$1,$B$2+($B8-1)*$E$2+$F$2+$G$2+$A8,F$3)) -> 72.618676 | G8: =AVERAGE(OFFSET('t84'!$A$1,$B$2+($B8-1)*$E$2+$F$2+$A8,F$3):OFFSET('t84'!$A$1,$B$2+($B8-1)*$E$2+$F$2+$G$2+$A8,F$3)) -> 82.114138 | H8: =AVERAGE(OFFSET('t168'!$A$1,$B$2+($B8-1)*$E$2+$F$2+$A8,F$3):OFFSET('t168'!$A$1,$B$2+($B8-1)*$E$2+$F$2+$G$2+$A8,F$3)) -> 100.88328 | I8: =AVERAGE(OFFSET('t336'!$A$1,$B$2+($B8-1)*$E$2+$F$2+$A8,F$3):OFFSET('t336'!$A$1,$B$2+($B8-1)*$E$2+$F$2+$G$2+$A8,F$3)) -> 134.73684 | J8: =AVERAGE(OFFSET('t672'!$A$1,$B$2+($B8-1)*$E$2+$F$2+$A8,F$3):OFFSET('t672'!$A$1,$B$2+($B8-1)*$E$2+$F$2+$G$2+$A8,F$3)) -> 208.08508 | K8: =AVERAGE(OFFSET('t1344'!$A$1,$B$2+($B8-1)*$E$2+$F$2+$A8,F$3):OFFSET('t1344'!$A$1,$B$2+($B8-1)*$E$2+$F$2+$G$2+$A8,F$3)) -> 340.67256 | L8: =AVERAGE(OFFSET('t2688'!$A$1,$B$2+($B8-1)*$E$2+$F$2+$A8,F$3):OFFSET('t2688'!$A$1,$B$2+($B8-1)*$E$2+$F$2+$G$2+$A8,F$3)) -> 680.91122 | M8: =AVERAGE(OFFSET('t5376'!$A$1,$B$2+($B8-1)*$E$2+$F$2+$A8,F$3):OFFSET('t5376'!$A$1,$B$2+($B8-1)*$E$2+$F$2+$G$2+$A8,F$3)) -> 1575.231 | N8: =AVERAGE(OFFSET('t10752'!$A$1,$B$2+($B8-1)*$E$2+$F$2+$A8,F$3):OFFSET('t10752'!$A$1,$B$2+($B8-1)*$E$2+$F$2+$G$2+$A8,F$3)) -> 2995.5258 | O8: =AVERAGE(OFFSET('t21504'!$A$1,$B$2+($B8-1)*$E$2+$F$2+$A8,F$3):OFFSET('t21504'!$A$1,$B$2+($B8-1)*$E$2+$F$2+$G$2+$A8,F$3)) -> 6459.2932 | P8: =AVERAGE(OFFSET('t43008'!$A$1,$B$2+($B8-1)*$E$2+$F$2+$A8,F$3):OFFSET('t43008'!$A$1,$B$2+($B8-1)*$E$2+$F$2+$G$2+$A8,F$3)) -> 14135.734 | Q8: =AVERAGE(OFFSET('t86016'!$A$1,$B$2+($B8-1)*$E$2+$F$2+$A8,F$3):OFFSET('t86016'!$A$1,$B$2+($B8-1)*$E$2+$F$2+$G$2+$A8,F$3)) -> 32275.626 | R8: =AVERAGE(OFFSET('t172032'!$A$1,$B$2+($B8-1)*$E$2+$F$2+$A8,F$3):OFFSET('t172032'!$A$1,$B$2+($B8-1)*$E$2+$F$2+$G$2+$A8,F$3)) -> 72288.886 | S8: =AVERAGE(OFFSET('t344064'!$A$1,$B$2+($B8-1)*$E$2+$F$2+$A8,F$3):OFFSET('t344064'!$A$1,$B$2+($B8-1)*$E$2+$F$2+$G$2+$A8,F$3)) -> 142543.8 | T8: =AVERAGE(OFFSET('t688128'!$A$1,$B$2+($B8-1)*$E$2+$F$2+$A8,F$3):OFFSET('t688128'!$A$1,$B$2+($B8-1)*$E$2+$F$2+$G$2+$A8,F$3)) -> 308900.06 | U8: =AVERAGE(OFFSET(t1376256!$A$1,$B$2+($B8-1)*$E$2+$F$2+$A8,F$3):OFFSET(t1376256!$A$1,$B$2+($B8-1)*$E$2+$F$2+$G$2+$A8,F$3)) -> #DIV/0! | Z8: 8 | AA8: << "Occupancy=" << metrics.occupancy << "% "
B9: 6 | C9: =C8*2 -> 2048 | D9: =C9*$D$1 -> 8192 | E9: =OFFSET('t42'!$A$1,$B$2+($B9-1)*$E$2+$A8,E$3) -> Run MPI Combined Run0 | F9: =AVERAGE(OFFSET('t42'!$A$1,$B$2+($B9-1)*$E$2+$F$2+$A8+1,F$3):OFFSET('t42'!$A$1,$B$2+($B9-1)*$E$2+$F$2+$G$2+$A8,F$3)) -> 81.608943 | G9: =AVERAGE(OFFSET('t84'!$A$1,$B$2+($B9-1)*$E$2+$F$2+$A8+1,F$3):OFFSET('t84'!$A$1,$B$2+($B9-1)*$E$2+$F$2+$G$2+$A8,F$3)) -> 95.161286 | H9: =AVERAGE(OFFSET('t168'!$A$1,$B$2+($B9-1)*$E$2+$F$2+$A8+1,F$3):OFFSET('t168'!$A$1,$B$2+($B9-1)*$E$2+$F$2+$G$2+$A8,F$3)) -> 113.5228 | I9: =AVERAGE(OFFSET('t336'!$A$1,$B$2+($B9-1)*$E$2+$F$2+$A8+1,F$3):OFFSET('t336'!$A$1,$B$2+($B9-1)*$E$2+$F$2+$G$2+$A8,F$3)) -> 148.26169 | J9: =AVERAGE(OFFSET('t672'!$A$1,$B$2+($B9-1)*$E$2+$F$2+$A8+1,F$3):OFFSET('t672'!$A$1,$B$2+($B9-1)*$E$2+$F$2+$G$2+$A8,F$3)) -> 238.20776 | K9: =AVERAGE(OFFSET('t1344'!$A$1,$B$2+($B9-1)*$E$2+$F$2+$A8+1,F$3):OFFSET('t1344'!$A$1,$B$2+($B9-1)*$E$2+$F$2+$G$2+$A8,F$3)) -> 425.89494 | L9: =AVERAGE(OFFSET('t2688'!$A$1,$B$2+($B9-1)*$E$2+$F$2+$A8+1,F$3):OFFSET('t2688'!$A$1,$B$2+($B9-1)*$E$2+$F$2+$G$2+$A8,F$3)) -> 879.51916 | M9: =AVERAGE(OFFSET('t5376'!$A$1,$B$2+($B9-1)*$E$2+$F$2+$A8+1,F$3):OFFSET('t5376'!$A$1,$B$2+($B9-1)*$E$2+$F$2+$G$2+$A8,F$3)) -> 2176.7022 | N9: =AVERAGE(OFFSET('t10752'!$A$1,$B$2+($B9-1)*$E$2+$F$2+$A8+1,F$3):OFFSET('t10752'!$A$1,$B$2+($B9-1)*$E$2+$F$2+$G$2+$A8,F$3)) -> 4221.8537 | O9: =AVERAGE(OFFSET('t21504'!$A$1,$B$2+($B9-1)*$E$2+$F$2+$A8+1,F$3):OFFSET('t21504'!$A$1,$B$2+($B9-1)*$E$2+$F$2+$G$2+$A8,F$3)) -> 9511.6949 | P9: =AVERAGE(OFFSET('t43008'!$A$1,$B$2+($B9-1)*$E$2+$F$2+$A8+1,F$3):OFFSET('t43008'!$A$1,$B$2+($B9-1)*$E$2+$F$2+$G$2+$A8,F$3)) -> 22150.62 | Q9: =AVERAGE(OFFSET('t86016'!$A$1,$B$2+($B9-1)*$E$2+$F$2+$A8+1,F$3):OFFSET('t86016'!$A$1,$B$2+($B9-1)*$E$2+$F$2+$G$2+$A8,F$3)) -> 51832.412 | R9: =AVERAGE(OFFSET('t172032'!$A$1,$B$2+($B9-1)*$E$2+$F$2+$A8+1,F$3):OFFSET('t172032'!$A$1,$B$2+($B9-1)*$E$2+$F$2+$G$2+$A8,F$3)) -> 111458.53 | S9: =AVERAGE(OFFSET('t344064'!$A$1,$B$2+($B9-1)*$E$2+$F$2+$A8+1,F$3):OFFSET('t344064'!$A$1,$B$2+($B9-1)*$E$2+$F$2+$G$2+$A8,F$3)) -> 230747.53 | T9: =AVERAGE(OFFSET('t688128'!$A$1,$B$2+($B9-1)*$E$2+$F$2+$A8+1,F$3):OFFSET('t688128'!$A$1,$B$2+($B9-1)*$E$2+$F$2+$G$2+$A8,F$3)) -> #DIV/0! | U9: =AVERAGE(OFFSET(t1376256!$A$1,$B$2+($B9-1)*$E$2+$F$2+$A8+1,F$3):OFFSET(t1376256!$A$1,$B$2+($B9-1)*$E$2+$F$2+$G$2+$A8,F$3)) -> #DIV/0! | Z9: 9 | AA9: << "memory_throughput_gbs=" << metrics.memory_throughput_gbs << " "
A10: 0 | B10: 7 | C10: =C9*2 -> 4096 | D10: =C10*$D$1 -> 16384 | E10: =OFFSET('t42'!$A$1,$B$2+($B10-1)*$E$2+$A10,E$3) -> Run MPI Combined Run0 | F10: =AVERAGE(OFFSET('t42'!$A$1,$B$2+($B10-1)*$E$2+$F$2+$A10,F$3):OFFSET('t42'!$A$1,$B$2+($B10-1)*$E$2+$F$2+$G$2+$A10,F$3)) -> 100.86914 | G10: =AVERAGE(OFFSET('t84'!$A$1,$B$2+($B10-1)*$E$2+$F$2+$A10,F$3):OFFSET('t84'!$A$1,$B$2+($B10-1)*$E$2+$F$2+$G$2+$A10,F$3)) -> 125.06818 | H10: =AVERAGE(OFFSET('t168'!$A$1,$B$2+($B10-1)*$E$2+$F$2+$A10,F$3):OFFSET('t168'!$A$1,$B$2+($B10-1)*$E$2+$F$2+$G$2+$A10,F$3)) -> 135.06582 | I10: =AVERAGE(OFFSET('t336'!$A$1,$B$2+($B10-1)*$E$2+$F$2+$A10,F$3):OFFSET('t336'!$A$1,$B$2+($B10-1)*$E$2+$F$2+$G$2+$A10,F$3)) -> 186.6747 | J10: =AVERAGE(OFFSET('t672'!$A$1,$B$2+($B10-1)*$E$2+$F$2+$A10,F$3):OFFSET('t672'!$A$1,$B$2+($B10-1)*$E$2+$F$2+$G$2+$A10,F$3)) -> 308.0332 | K10: =AVERAGE(OFFSET('t1344'!$A$1,$B$2+($B10-1)*$E$2+$F$2+$A10,F$3):OFFSET('t1344'!$A$1,$B$2+($B10-1)*$E$2+$F$2+$G$2+$A10,F$3)) -> 587.33758 | L10: =AVERAGE(OFFSET('t2688'!$A$1,$B$2+($B10-1)*$E$2+$F$2+$A10,F$3):OFFSET('t2688'!$A$1,$B$2+($B10-1)*$E$2+$F$2+$G$2+$A10,F$3)) -> 1294.9156 | M10: =AVERAGE(OFFSET('t5376'!$A$1,$B$2+($B10-1)*$E$2+$F$2+$A10,F$3):OFFSET('t5376'!$A$1,$B$2+($B10-1)*$E$2+$F$2+$G$2+$A10,F$3)) -> 3117.4404 | N10: =AVERAGE(OFFSET('t10752'!$A$1,$B$2+($B10-1)*$E$2+$F$2+$A10,F$3):OFFSET('t10752'!$A$1,$B$2+($B10-1)*$E$2+$F$2+$G$2+$A10,F$3)) -> 6418.643 | O10: =AVERAGE(OFFSET('t21504'!$A$1,$B$2+($B10-1)*$E$2+$F$2+$A10,F$3):OFFSET('t21504'!$A$1,$B$2+($B10-1)*$E$2+$F$2+$G$2+$A10,F$3)) -> 15088.486 | P10: =AVERAGE(OFFSET('t43008'!$A$1,$B$2+($B10-1)*$E$2+$F$2+$A10,F$3):OFFSET('t43008'!$A$1,$B$2+($B10-1)*$E$2+$F$2+$G$2+$A10,F$3)) -> 36393.932 | Q10: =AVERAGE(OFFSET('t86016'!$A$1,$B$2+($B10-1)*$E$2+$F$2+$A10,F$3):OFFSET('t86016'!$A$1,$B$2+($B10-1)*$E$2+$F$2+$G$2+$A10,F$3)) -> 85100.412 | R10: =AVERAGE(OFFSET('t172032'!$A$1,$B$2+($B10-1)*$E$2+$F$2+$A10,F$3):OFFSET('t172032'!$A$1,$B$2+($B10-1)*$E$2+$F$2+$G$2+$A10,F$3)) -> 193980.12 | S10: =AVERAGE(OFFSET('t344064'!$A$1,$B$2+($B10-1)*$E$2+$F$2+$A10,F$3):OFFSET('t344064'!$A$1,$B$2+($B10-1)*$E$2+$F$2+$G$2+$A10,F$3)) -> #DIV/0! | T10: =AVERAGE(OFFSET('t688128'!$A$1,$B$2+($B10-1)*$E$2+$F$2+$A10,F$3):OFFSET('t688128'!$A$1,$B$2+($B10-1)*$E$2+$F$2+$G$2+$A10,F$3)) -> #DIV/0! | U10: =AVERAGE(OFFSET(t1376256!$A$1,$B$2+($B10-1)*$E$2+$F$2+$A10,F$3):OFFSET(t1376256!$A$1,$B$2+($B10-1)*$E$2+$F$2+$G$2+$A10,F$3)) -> #DIV/0! | Z10: 10 | AA10: << "MIN=" << metrics.min_fitness << " "
B11: 8 | C11: =C10*2 -> 8192 | D11: =C11*$D$1 -> 32768 | E11: =OFFSET('t42'!$A$1,$B$2+($B11-1)*$E$2+$A10,E$3) -> Run MPI Combined Run0 | F11: =AVERAGE(OFFSET('t42'!$A$1,$B$2+($B11-1)*$E$2+$F$2+$A10+1,F$3):OFFSET('t42'!$A$1,$B$2+($B11-1)*$E$2+$F$2+$G$2+$A10,F$3)) -> 146.34141 | G11: =AVERAGE(OFFSET('t84'!$A$1,$B$2+($B11-1)*$E$2+$F$2+$A10+1,F$3):OFFSET('t84'!$A$1,$B$2+($B11-1)*$E$2+$F$2+$G$2+$A10,F$3)) -> 188.11402 | H11: =AVERAGE(OFFSET('t168'!$A$1,$B$2+($B11-1)*$E$2+$F$2+$A10+1,F$3):OFFSET('t168'!$A$1,$B$2+($B11-1)*$E$2+$F$2+$G$2+$A10,F$3)) -> 178.88043 | I11: =AVERAGE(OFFSET('t336'!$A$1,$B$2+($B11-1)*$E$2+$F$2+$A10+1,F$3):OFFSET('t336'!$A$1,$B$2+($B11-1)*$E$2+$F$2+$G$2+$A10,F$3)) -> 258.24145 | J11: =AVERAGE(OFFSET('t672'!$A$1,$B$2+($B11-1)*$E$2+$F$2+$A10+1,F$3):OFFSET('t672'!$A$1,$B$2+($B11-1)*$E$2+$F$2+$G$2+$A10,F$3)) -> 456.98865 | K11: =AVERAGE(OFFSET('t1344'!$A$1,$B$2+($B11-1)*$E$2+$F$2+$A10+1,F$3):OFFSET('t1344'!$A$1,$B$2+($B11-1)*$E$2+$F$2+$G$2+$A10,F$3)) -> 895.75778 | L11: =AVERAGE(OFFSET('t2688'!$A$1,$B$2+($B11-1)*$E$2+$F$2+$A10+1,F$3):OFFSET('t2688'!$A$1,$B$2+($B11-1)*$E$2+$F$2+$G$2+$A10,F$3)) -> 2041.1712 | M11: =AVERAGE(OFFSET('t5376'!$A$1,$B$2+($B11-1)*$E$2+$F$2+$A10+1,F$3):OFFSET('t5376'!$A$1,$B$2+($B11-1)*$E$2+$F$2+$G$2+$A10,F$3)) -> 4853.541 | N11: =AVERAGE(OFFSET('t10752'!$A$1,$B$2+($B11-1)*$E$2+$F$2+$A10+1,F$3):OFFSET('t10752'!$A$1,$B$2+($B11-1)*$E$2+$F$2+$G$2+$A10,F$3)) -> 9706.0994 | O11: =AVERAGE(OFFSET('t21504'!$A$1,$B$2+($B11-1)*$E$2+$F$2+$A10+1,F$3):OFFSET('t21504'!$A$1,$B$2+($B11-1)*$E$2+$F$2+$G$2+$A10,F$3)) -> 25068.551 | P11: =AVERAGE(OFFSET('t43008'!$A$1,$B$2+($B11-1)*$E$2+$F$2+$A10+1,F$3):OFFSET('t43008'!$A$1,$B$2+($B11-1)*$E$2+$F$2+$G$2+$A10,F$3)) -> 60984.263 | Q11: =AVERAGE(OFFSET('t86016'!$A$1,$B$2+($B11-1)*$E$2+$F$2+$A10+1,F$3):OFFSET('t86016'!$A$1,$B$2+($B11-1)*$E$2+$F$2+$G$2+$A10,F$3)) -> 148673.14 | R11: =AVERAGE(OFFSET('t172032'!$A$1,$B$2+($B11-1)*$E$2+$F$2+$A10+1,F$3):OFFSET('t172032'!$A$1,$B$2+($B11-1)*$E$2+$F$2+$G$2+$A10,F$3)) -> #DIV/0! | S11: =AVERAGE(OFFSET('t344064'!$A$1,$B$2+($B11-1)*$E$2+$F$2+$A10+1,F$3):OFFSET('t344064'!$A$1,$B$2+($B11-1)*$E$2+$F$2+$G$2+$A10,F$3)) -> #DIV/0! | T11: =AVERAGE(OFFSET('t688128'!$A$1,$B$2+($B11-1)*$E$2+$F$2+$A10+1,F$3):OFFSET('t688128'!$A$1,$B$2+($B11-1)*$E$2+$F$2+$G$2+$A10,F$3)) -> #DIV/0! | U11: =AVERAGE(OFFSET(t1376256!$A$1,$B$2+($B11-1)*$E$2+$F$2+$A10+1,F$3):OFFSET(t1376256!$A$1,$B$2+($B11-1)*$E$2+$F$2+$G$2+$A10,F$3)) -> #DIV/0! | Z11: 11 | AA11: << "MAX=" << metrics.max_fitness << " "
A12: 0 | B12: 9 | C12: =C11*2 -> 16384 | D12: =C12*$D$1 -> 65536 | E12: =OFFSET('t42'!$A$1,$B$2+($B12-1)*$E$2+$A12,E$3) -> Run MPI Combined Run0 | F12: =AVERAGE(OFFSET('t42'!$A$1,$B$2+($B12-1)*$E$2+$F$2+$A12,F$3):OFFSET('t42'!$A$1,$B$2+($B12-1)*$E$2+$F$2+$G$2+$A12,F$3)) -> 236.44888 | G12: =AVERAGE(OFFSET('t84'!$A$1,$B$2+($B12-1)*$E$2+$F$2+$A12,F$3):OFFSET('t84'!$A$1,$B$2+($B12-1)*$E$2+$F$2+$G$2+$A12,F$3)) -> 312.72938 | H12: =AVERAGE(OFFSET('t168'!$A$1,$B$2+($B12-1)*$E$2+$F$2+$A12,F$3):OFFSET('t168'!$A$1,$B$2+($B12-1)*$E$2+$F$2+$G$2+$A12,F$3)) -> 274.79304 | I12: =AVERAGE(OFFSET('t336'!$A$1,$B$2+($B12-1)*$E$2+$F$2+$A12,F$3):OFFSET('t336'!$A$1,$B$2+($B12-1)*$E$2+$F$2+$G$2+$A12,F$3)) -> 397.69988 | J12: =AVERAGE(OFFSET('t672'!$A$1,$B$2+($B12-1)*$E$2+$F$2+$A12,F$3):OFFSET('t672'!$A$1,$B$2+($B12-1)*$E$2+$F$2+$G$2+$A12,F$3)) -> 742.08906 | K12: =AVERAGE(OFFSET('t1344'!$A$1,$B$2+($B12-1)*$E$2+$F$2+$A12,F$3):OFFSET('t1344'!$A$1,$B$2+($B12-1)*$E$2+$F$2+$G$2+$A12,F$3)) -> 1511.6984 | L12: =AVERAGE(OFFSET('t2688'!$A$1,$B$2+($B12-1)*$E$2+$F$2+$A12,F$3):OFFSET('t2688'!$A$1,$B$2+($B12-1)*$E$2+$F$2+$G$2+$A12,F$3)) -> 3612.4114 | M12: =AVERAGE(OFFSET('t5376'!$A$1,$B$2+($B12-1)*$E$2+$F$2+$A12,F$3):OFFSET('t5376'!$A$1,$B$2+($B12-1)*$E$2+$F$2+$G$2+$A12,F$3)) -> 8226.0066 | N12: =AVERAGE(OFFSET('t10752'!$A$1,$B$2+($B12-1)*$E$2+$F$2+$A12,F$3):OFFSET('t10752'!$A$1,$B$2+($B12-1)*$E$2+$F$2+$G$2+$A12,F$3)) -> 16000.728 | O12: =AVERAGE(OFFSET('t21504'!$A$1,$B$2+($B12-1)*$E$2+$F$2+$A12,F$3):OFFSET('t21504'!$A$1,$B$2+($B12-1)*$E$2+$F$2+$G$2+$A12,F$3)) -> 42512.684 | P12: =AVERAGE(OFFSET('t43008'!$A$1,$B$2+($B12-1)*$E$2+$F$2+$A12,F$3):OFFSET('t43008'!$A$1,$B$2+($B12-1)*$E$2+$F$2+$G$2+$A12,F$3)) -> 106086.06 | Q12: =AVERAGE(OFFSET('t86016'!$A$1,$B$2+($B12-1)*$E$2+$F$2+$A12,F$3):OFFSET('t86016'!$A$1,$B$2+($B12-1)*$E$2+$F$2+$G$2+$A12,F$3)) -> #DIV/0! | R12: =AVERAGE(OFFSET('t172032'!$A$1,$B$2+($B12-1)*$E$2+$F$2+$A12,F$3):OFFSET('t172032'!$A$1,$B$2+($B12-1)*$E$2+$F$2+$G$2+$A12,F$3)) -> #DIV/0! | S12: =AVERAGE(OFFSET('t344064'!$A$1,$B$2+($B12-1)*$E$2+$F$2+$A12,F$3):OFFSET('t344064'!$A$1,$B$2+($B12-1)*$E$2+$F$2+$G$2+$A12,F$3)) -> #DIV/0! | T12: =AVERAGE(OFFSET('t688128'!$A$1,$B$2+($B12-1)*$E$2+$F$2+$A12,F$3):OFFSET('t688128'!$A$1,$B$2+($B12-1)*$E$2+$F$2+$G$2+$A12,F$3)) -> #DIV/0! | U12: =AVERAGE(OFFSET(t1376256!$A$1,$B$2+($B12-1)*$E$2+$F$2+$A12,F$3):OFFSET(t1376256!$A$1,$B$2+($B12-1)*$E$2+$F$2+$G$2+$A12,F$3)) -> #DIV/0!
B13: 10 | C13: =C12*2 -> 32768 | D13: =C13*$D$1 -> 131072 | E13: =OFFSET('t42'!$A$1,$B$2+($B13-1)*$E$2+$A12,E$3) -> 0 | F13: =AVERAGE(OFFSET('t42'!$A$1,$B$2+($B13-1)*$E$2+$F$2+$A12+1,F$3):OFFSET('t42'!$A$1,$B$2+($B13-1)*$E$2+$F$2+$G$2+$A12,F$3)) -> #DIV/0! | G13: =AVERAGE(OFFSET('t84'!$A$1,$B$2+($B13-1)*$E$2+$F$2+$A12+1,F$3):OFFSET('t84'!$A$1,$B$2+($B13-1)*$E$2+$F$2+$G$2+$A12,F$3)) -> #DIV/0! | H13: =AVERAGE(OFFSET('t168'!$A$1,$B$2+($B13-1)*$E$2+$F$2+$A12+1,F$3):OFFSET('t168'!$A$1,$B$2+($B13-1)*$E$2+$F$2+$G$2+$A12,F$3)) -> #DIV/0! | I13: =AVERAGE(OFFSET('t336'!$A$1,$B$2+($B13-1)*$E$2+$F$2+$A12+1,F$3):OFFSET('t336'!$A$1,$B$2+($B13-1)*$E$2+$F$2+$G$2+$A12,F$3)) -> #DIV/0! | J13: =AVERAGE(OFFSET('t672'!$A$1,$B$2+($B13-1)*$E$2+$F$2+$A12+1,F$3):OFFSET('t672'!$A$1,$B$2+($B13-1)*$E$2+$F$2+$G$2+$A12,F$3)) -> #DIV/0! | K13: =AVERAGE(OFFSET('t1344'!$A$1,$B$2+($B13-1)*$E$2+$F$2+$A12+1,F$3):OFFSET('t1344'!$A$1,$B$2+($B13-1)*$E$2+$F$2+$G$2+$A12,F$3)) -> #DIV/0! | L13: =AVERAGE(OFFSET('t2688'!$A$1,$B$2+($B13-1)*$E$2+$F$2+$A12+1,F$3):OFFSET('t2688'!$A$1,$B$2+($B13-1)*$E$2+$F$2+$G$2+$A12,F$3)) -> #DIV/0! | M13: =AVERAGE(OFFSET('t5376'!$A$1,$B$2+($B13-1)*$E$2+$F$2+$A12+1,F$3):OFFSET('t5376'!$A$1,$B$2+($B13-1)*$E$2+$F$2+$G$2+$A12,F$3)) -> #DIV/0! | N13: =AVERAGE(OFFSET('t10752'!$A$1,$B$2+($B13-1)*$E$2+$F$2+$A12+1,F$3):OFFSET('t10752'!$A$1,$B$2+($B13-1)*$E$2+$F$2+$G$2+$A12,F$3)) -> #DIV/0! | O13: =AVERAGE(OFFSET('t21504'!$A$1,$B$2+($B13-1)*$E$2+$F$2+$A12+1,F$3):OFFSET('t21504'!$A$1,$B$2+($B13-1)*$E$2+$F$2+$G$2+$A12,F$3)) -> #DIV/0! | P13: =AVERAGE(OFFSET('t43008'!$A$1,$B$2+($B13-1)*$E$2+$F$2+$A12+1,F$3):OFFSET('t43008'!$A$1,$B$2+($B13-1)*$E$2+$F$2+$G$2+$A12,F$3)) -> #DIV/0! | Q13: =AVERAGE(OFFSET('t86016'!$A$1,$B$2+($B13-1)*$E$2+$F$2+$A12+1,F$3):OFFSET('t86016'!$A$1,$B$2+($B13-1)*$E$2+$F$2+$G$2+$A12,F$3)) -> #DIV/0! | R13: =AVERAGE(OFFSET('t172032'!$A$1,$B$2+($B13-1)*$E$2+$F$2+$A12+1,F$3):OFFSET('t172032'!$A$1,$B$2+($B13-1)*$E$2+$F$2+$G$2+$A12,F$3)) -> #DIV/0! | S13: =AVERAGE(OFFSET('t344064'!$A$1,$B$2+($B13-1)*$E$2+$F$2+$A12+1,F$3):OFFSET('t344064'!$A$1,$B$2+($B13-1)*$E$2+$F$2+$G$2+$A12,F$3)) -> #DIV/0! | T13: =AVERAGE(OFFSET('t688128'!$A$1,$B$2+($B13-1)*$E$2+$F$2+$A12+1,F$3):OFFSET('t688128'!$A$1,$B$2+($B13-1)*$E$2+$F$2+$G$2+$A12,F$3)) -> #DIV/0! | U13: =AVERAGE(OFFSET(t1376256!$A$1,$B$2+($B13-1)*$E$2+$F$2+$A12+1,F$3):OFFSET(t1376256!$A$1,$B$2+($B13-1)*$E$2+$F$2+$G$2+$A12,F$3)) -> #DIV/0!
A14: 0 | B14: 11 | C14: =C13*2 -> 65536 | D14: =C14*$D$1 -> 262144 | E14: =OFFSET('t42'!$A$1,$B$2+($B14-1)*$E$2+$A14,E$3) -> 0 | F14: =AVERAGE(OFFSET('t42'!$A$1,$B$2+($B14-1)*$E$2+$F$2+$A14,F$3):OFFSET('t42'!$A$1,$B$2+($B14-1)*$E$2+$F$2+$G$2+$A14,F$3)) -> #DIV/0! | G14: =AVERAGE(OFFSET('t84'!$A$1,$B$2+($B14-1)*$E$2+$F$2+$A14,F$3):OFFSET('t84'!$A$1,$B$2+($B14-1)*$E$2+$F$2+$G$2+$A14,F$3)) -> #DIV/0! | H14: =AVERAGE(OFFSET('t168'!$A$1,$B$2+($B14-1)*$E$2+$F$2+$A14,F$3):OFFSET('t168'!$A$1,$B$2+($B14-1)*$E$2+$F$2+$G$2+$A14,F$3)) -> #DIV/0! | I14: =AVERAGE(OFFSET('t336'!$A$1,$B$2+($B14-1)*$E$2+$F$2+$A14,F$3):OFFSET('t336'!$A$1,$B$2+($B14-1)*$E$2+$F$2+$G$2+$A14,F$3)) -> #DIV/0! | J14: =AVERAGE(OFFSET('t672'!$A$1,$B$2+($B14-1)*$E$2+$F$2+$A14,F$3):OFFSET('t672'!$A$1,$B$2+($B14-1)*$E$2+$F$2+$G$2+$A14,F$3)) -> #DIV/0! | K14: =AVERAGE(OFFSET('t1344'!$A$1,$B$2+($B14-1)*$E$2+$F$2+$A14,F$3):OFFSET('t1344'!$A$1,$B$2+($B14-1)*$E$2+$F$2+$G$2+$A14,F$3)) -> #DIV/0! | L14: =AVERAGE(OFFSET('t2688'!$A$1,$B$2+($B14-1)*$E$2+$F$2+$A14,F$3):OFFSET('t2688'!$A$1,$B$2+($B14-1)*$E$2+$F$2+$G$2+$A14,F$3)) -> #DIV/0! | M14: =AVERAGE(OFFSET('t5376'!$A$1,$B$2+($B14-1)*$E$2+$F$2+$A14,F$3):OFFSET('t5376'!$A$1,$B$2+($B14-1)*$E$2+$F$2+$G$2+$A14,F$3)) -> #DIV/0! | N14: =AVERAGE(OFFSET('t10752'!$A$1,$B$2+($B14-1)*$E$2+$F$2+$A14,F$3):OFFSET('t10752'!$A$1,$B$2+($B14-1)*$E$2+$F$2+$G$2+$A14,F$3)) -> #DIV/0! | O14: =AVERAGE(OFFSET('t21504'!$A$1,$B$2+($B14-1)*$E$2+$F$2+$A14,F$3):OFFSET('t21504'!$A$1,$B$2+($B14-1)*$E$2+$F$2+$G$2+$A14,F$3)) -> #DIV/0! | P14: =AVERAGE(OFFSET('t43008'!$A$1,$B$2+($B14-1)*$E$2+$F$2+$A14,F$3):OFFSET('t43008'!$A$1,$B$2+($B14-1)*$E$2+$F$2+$G$2+$A14,F$3)) -> #DIV/0! | Q14: =AVERAGE(OFFSET('t86016'!$A$1,$B$2+($B14-1)*$E$2+$F$2+$A14,F$3):OFFSET('t86016'!$A$1,$B$2+($B14-1)*$E$2+$F$2+$G$2+$A14,F$3)) -> #DIV/0! | R14: =AVERAGE(OFFSET('t172032'!$A$1,$B$2+($B14-1)*$E$2+$F$2+$A14,F$3):OFFSET('t172032'!$A$1,$B$2+($B14-1)*$E$2+$F$2+$G$2+$A14,F$3)) -> #DIV/0! | S14: =AVERAGE(OFFSET('t344064'!$A$1,$B$2+($B14-1)*$E$2+$F$2+$A14,F$3):OFFSET('t344064'!$A$1,$B$2+($B14-1)*$E$2+$F$2+$G$2+$A14,F$3)) -> #DIV/0! | T14: =AVERAGE(OFFSET('t688128'!$A$1,$B$2+($B14-1)*$E$2+$F$2+$A14,F$3):OFFSET('t688128'!$A$1,$B$2+($B14-1)*$E$2+$F$2+$G$2+$A14,F$3)) -> #DIV/0! | U14: =AVERAGE(OFFSET(t1376256!$A$1,$B$2+($B14-1)*$E$2+$F$2+$A14,F$3):OFFSET(t1376256!$A$1,$B$2+($B14-1)*$E$2+$F$2+$G$2+$A14,F$3)) -> #DIV/0!
B15: 12 | C15: =C14*2 -> 131072 | D15: =C15*$D$1 -> 524288 | E15: =OFFSET('t42'!$A$1,$B$2+($B15-1)*$E$2+$A14,E$3) -> 0 | F15: =AVERAGE(OFFSET('t42'!$A$1,$B$2+($B15-1)*$E$2+$F$2+$A14+1,F$3):OFFSET('t42'!$A$1,$B$2+($B15-1)*$E$2+$F$2+$G$2+$A14,F$3)) -> #DIV/0! | G15: =AVERAGE(OFFSET('t84'!$A$1,$B$2+($B15-1)*$E$2+$F$2+$A14+1,F$3):OFFSET('t84'!$A$1,$B$2+($B15-1)*$E$2+$F$2+$G$2+$A14,F$3)) -> #DIV/0! | H15: =AVERAGE(OFFSET('t168'!$A$1,$B$2+($B15-1)*$E$2+$F$2+$A14+1,F$3):OFFSET('t168'!$A$1,$B$2+($B15-1)*$E$2+$F$2+$G$2+$A14,F$3)) -> #DIV/0! | I15: =AVERAGE(OFFSET('t336'!$A$1,$B$2+($B15-1)*$E$2+$F$2+$A14+1,F$3):OFFSET('t336'!$A$1,$B$2+($B15-1)*$E$2+$F$2+$G$2+$A14,F$3)) -> #DIV/0! | J15: =AVERAGE(OFFSET('t672'!$A$1,$B$2+($B15-1)*$E$2+$F$2+$A14+1,F$3):OFFSET('t672'!$A$1,$B$2+($B15-1)*$E$2+$F$2+$G$2+$A14,F$3)) -> #DIV/0! | K15: =AVERAGE(OFFSET('t1344'!$A$1,$B$2+($B15-1)*$E$2+$F$2+$A14+1,F$3):OFFSET('t1344'!$A$1,$B$2+($B15-1)*$E$2+$F$2+$G$2+$A14,F$3)) -> #DIV/0! | L15: =AVERAGE(OFFSET('t2688'!$A$1,$B$2+($B15-1)*$E$2+$F$2+$A14+1,F$3):OFFSET('t2688'!$A$1,$B$2+($B15-1)*$E$2+$F$2+$G$2+$A14,F$3)) -> #DIV/0! | M15: =AVERAGE(OFFSET('t5376'!$A$1,$B$2+($B15-1)*$E$2+$F$2+$A14+1,F$3):OFFSET('t5376'!$A$1,$B$2+($B15-1)*$E$2+$F$2+$G$2+$A14,F$3)) -> #DIV/0! | N15: =AVERAGE(OFFSET('t10752'!$A$1,$B$2+($B15-1)*$E$2+$F$2+$A14+1,F$3):OFFSET('t10752'!$A$1,$B$2+($B15-1)*$E$2+$F$2+$G$2+$A14,F$3)) -> #DIV/0! | O15: =AVERAGE(OFFSET('t21504'!$A$1,$B$2+($B15-1)*$E$2+$F$2+$A14+1,F$3):OFFSET('t21504'!$A$1,$B$2+($B15-1)*$E$2+$F$2+$G$2+$A14,F$3)) -> #DIV/0! | P15: =AVERAGE(OFFSET('t43008'!$A$1,$B$2+($B15-1)*$E$2+$F$2+$A14+1,F$3):OFFSET('t43008'!$A$1,$B$2+($B15-1)*$E$2+$F$2+$G$2+$A14,F$3)) -> #DIV/0! | Q15: =AVERAGE(OFFSET('t86016'!$A$1,$B$2+($B15-1)*$E$2+$F$2+$A14+1,F$3):OFFSET('t86016'!$A$1,$B$2+($B15-1)*$E$2+$F$2+$G$2+$A14,F$3)) -> #DIV/0! | R15: =AVERAGE(OFFSET('t172032'!$A$1,$B$2+($B15-1)*$E$2+$F$2+$A14+1,F$3):OFFSET('t172032'!$A$1,$B$2+($B15-1)*$E$2+$F$2+$G$2+$A14,F$3)) -> #DIV/0! | S15: =AVERAGE(OFFSET('t344064'!$A$1,$B$2+($B15-1)*$E$2+$F$2+$A14+1,F$3):OFFSET('t344064'!$A$1,$B$2+($B15-1)*$E$2+$F$2+$G$2+$A14,F$3)) -> #DIV/0! | T15: =AVERAGE(OFFSET('t688128'!$A$1,$B$2+($B15-1)*$E$2+$F$2+$A14+1,F$3):OFFSET('t688128'!$A$1,$B$2+($B15-1)*$E$2+$F$2+$G$2+$A14,F$3)) -> #DIV/0! | U15: =AVERAGE(OFFSET(t1376256!$A$1,$B$2+($B15-1)*$E$2+$F$2+$A14+1,F$3):OFFSET(t1376256!$A$1,$B$2+($B15-1)*$E$2+$F$2+$G$2+$A14,F$3)) -> #DIV/0!
A16: 0 | B16: 13 | C16: =C15*2 -> 262144 | D16: =C16*$D$1 -> 1048576 | E16: =OFFSET('t42'!$A$1,$B$2+($B16-1)*$E$2+$A16,E$3) -> 0 | F16: =AVERAGE(OFFSET('t42'!$A$1,$B$2+($B16-1)*$E$2+$F$2+$A16,F$3):OFFSET('t42'!$A$1,$B$2+($B16-1)*$E$2+$F$2+$G$2+$A16,F$3)) -> #DIV/0! | G16: =AVERAGE(OFFSET('t84'!$A$1,$B$2+($B16-1)*$E$2+$F$2+$A16,F$3):OFFSET('t84'!$A$1,$B$2+($B16-1)*$E$2+$F$2+$G$2+$A16,F$3)) -> #DIV/0! | H16: =AVERAGE(OFFSET('t168'!$A$1,$B$2+($B16-1)*$E$2+$F$2+$A16,F$3):OFFSET('t168'!$A$1,$B$2+($B16-1)*$E$2+$F$2+$G$2+$A16,F$3)) -> #DIV/0! | I16: =AVERAGE(OFFSET('t336'!$A$1,$B$2+($B16-1)*$E$2+$F$2+$A16,F$3):OFFSET('t336'!$A$1,$B$2+($B16-1)*$E$2+$F$2+$G$2+$A16,F$3)) -> #DIV/0! | J16: =AVERAGE(OFFSET('t672'!$A$1,$B$2+($B16-1)*$E$2+$F$2+$A16,F$3):OFFSET('t672'!$A$1,$B$2+($B16-1)*$E$2+$F$2+$G$2+$A16,F$3)) -> #DIV/0! | K16: =AVERAGE(OFFSET('t1344'!$A$1,$B$2+($B16-1)*$E$2+$F$2+$A16,F$3):OFFSET('t1344'!$A$1,$B$2+($B16-1)*$E$2+$F$2+$G$2+$A16,F$3)) -> #DIV/0! | L16: =AVERAGE(OFFSET('t2688'!$A$1,$B$2+($B16-1)*$E$2+$F$2+$A16,F$3):OFFSET('t2688'!$A$1,$B$2+($B16-1)*$E$2+$F$2+$G$2+$A16,F$3)) -> #DIV/0! | M16: =AVERAGE(OFFSET('t5376'!$A$1,$B$2+($B16-1)*$E$2+$F$2+$A16,F$3):OFFSET('t5376'!$A$1,$B$2+($B16-1)*$E$2+$F$2+$G$2+$A16,F$3)) -> #DIV/0! | N16: =AVERAGE(OFFSET('t10752'!$A$1,$B$2+($B16-1)*$E$2+$F$2+$A16,F$3):OFFSET('t10752'!$A$1,$B$2+($B16-1)*$E$2+$F$2+$G$2+$A16,F$3)) -> #DIV/0! | O16: =AVERAGE(OFFSET('t21504'!$A$1,$B$2+($B16-1)*$E$2+$F$2+$A16,F$3):OFFSET('t21504'!$A$1,$B$2+($B16-1)*$E$2+$F$2+$G$2+$A16,F$3)) -> #DIV/0! | P16: =AVERAGE(OFFSET('t43008'!$A$1,$B$2+($B16-1)*$E$2+$F$2+$A16,F$3):OFFSET('t43008'!$A$1,$B$2+($B16-1)*$E$2+$F$2+$G$2+$A16,F$3)) -> #DIV/0! | Q16: =AVERAGE(OFFSET('t86016'!$A$1,$B$2+($B16-1)*$E$2+$F$2+$A16,F$3):OFFSET('t86016'!$A$1,$B$2+($B16-1)*$E$2+$F$2+$G$2+$A16,F$3)) -> #DIV/0! | R16: =AVERAGE(OFFSET('t172032'!$A$1,$B$2+($B16-1)*$E$2+$F$2+$A16,F$3):OFFSET('t172032'!$A$1,$B$2+($B16-1)*$E$2+$F$2+$G$2+$A16,F$3)) -> #DIV/0! | S16: =AVERAGE(OFFSET('t344064'!$A$1,$B$2+($B16-1)*$E$2+$F$2+$A16,F$3):OFFSET('t344064'!$A$1,$B$2+($B16-1)*$E$2+$F$2+$G$2+$A16,F$3)) -> #DIV/0! | T16: =AVERAGE(OFFSET('t688128'!$A$1,$B$2+($B16-1)*$E$2+$F$2+$A16,F$3):OFFSET('t688128'!$A$1,$B$2+($B16-1)*$E$2+$F$2+$G$2+$A16,F$3)) -> #DIV/0! | U16: =AVERAGE(OFFSET(t1376256!$A$1,$B$2+($B16-1)*$E$2+$F$2+$A16,F$3):OFFSET(t1376256!$A$1,$B$2+($B16-1)*$E$2+$F$2+$G$2+$A16,F$3)) -> #DIV/0!
B17: 14 | C17: =C16*2 -> 524288 | D17: =C17*$D$1 -> 2097152 | E17: =OFFSET('t42'!$A$1,$B$2+($B17-1)*$E$2+$A16,E$3) -> 0 | F17: =AVERAGE(OFFSET('t42'!$A$1,$B$2+($B17-1)*$E$2+$F$2+$A16+1,F$3):OFFSET('t42'!$A$1,$B$2+($B17-1)*$E$2+$F$2+$G$2+$A16,F$3)) -> #DIV/0! | G17: =AVERAGE(OFFSET('t84'!$A$1,$B$2+($B17-1)*$E$2+$F$2+$A16+1,F$3):OFFSET('t84'!$A$1,$B$2+($B17-1)*$E$2+$F$2+$G$2+$A16,F$3)) -> #DIV/0! | H17: =AVERAGE(OFFSET('t168'!$A$1,$B$2+($B17-1)*$E$2+$F$2+$A16+1,F$3):OFFSET('t168'!$A$1,$B$2+($B17-1)*$E$2+$F$2+$G$2+$A16,F$3)) -> #DIV/0! | I17: =AVERAGE(OFFSET('t336'!$A$1,$B$2+($B17-1)*$E$2+$F$2+$A16+1,F$3):OFFSET('t336'!$A$1,$B$2+($B17-1)*$E$2+$F$2+$G$2+$A16,F$3)) -> #DIV/0! | J17: =AVERAGE(OFFSET('t672'!$A$1,$B$2+($B17-1)*$E$2+$F$2+$A16+1,F$3):OFFSET('t672'!$A$1,$B$2+($B17-1)*$E$2+$F$2+$G$2+$A16,F$3)) -> #DIV/0! | K17: =AVERAGE(OFFSET('t1344'!$A$1,$B$2+($B17-1)*$E$2+$F$2+$A16+1,F$3):OFFSET('t1344'!$A$1,$B$2+($B17-1)*$E$2+$F$2+$G$2+$A16,F$3)) -> #DIV/0! | L17: =AVERAGE(OFFSET('t2688'!$A$1,$B$2+($B17-1)*$E$2+$F$2+$A16+1,F$3):OFFSET('t2688'!$A$1,$B$2+($B17-1)*$E$2+$F$2+$G$2+$A16,F$3)) -> #DIV/0! | M17: =AVERAGE(OFFSET('t5376'!$A$1,$B$2+($B17-1)*$E$2+$F$2+$A16+1,F$3):OFFSET('t5376'!$A$1,$B$2+($B17-1)*$E$2+$F$2+$G$2+$A16,F$3)) -> #DIV/0! | N17: =AVERAGE(OFFSET('t10752'!$A$1,$B$2+($B17-1)*$E$2+$F$2+$A16+1,F$3):OFFSET('t10752'!$A$1,$B$2+($B17-1)*$E$2+$F$2+$G$2+$A16,F$3)) -> #DIV/0! | O17: =AVERAGE(OFFSET('t21504'!$A$1,$B$2+($B17-1)*$E$2+$F$2+$A16+1,F$3):OFFSET('t21504'!$A$1,$B$2+($B17-1)*$E$2+$F$2+$G$2+$A16,F$3)) -> #DIV/0! | P17: =AVERAGE(OFFSET('t43008'!$A$1,$B$2+($B17-1)*$E$2+$F$2+$A16+1,F$3):OFFSET('t43008'!$A$1,$B$2+($B17-1)*$E$2+$F$2+$G$2+$A16,F$3)) -> #DIV/0! | Q17: =AVERAGE(OFFSET('t86016'!$A$1,$B$2+($B17-1)*$E$2+$F$2+$A16+1,F$3):OFFSET('t86016'!$A$1,$B$2+($B17-1)*$E$2+$F$2+$G$2+$A16,F$3)) -> #DIV/0! | R17: =AVERAGE(OFFSET('t172032'!$A$1,$B$2+($B17-1)*$E$2+$F$2+$A16+1,F$3):OFFSET('t172032'!$A$1,$B$2+($B17-1)*$E$2+$F$2+$G$2+$A16,F$3)) -> #DIV/0! | S17: =AVERAGE(OFFSET('t344064'!$A$1,$B$2+($B17-1)*$E$2+$F$2+$A16+1,F$3):OFFSET('t344064'!$A$1,$B$2+($B17-1)*$E$2+$F$2+$G$2+$A16,F$3)) -> #DIV/0! | T17: =AVERAGE(OFFSET('t688128'!$A$1,$B$2+($B17-1)*$E$2+$F$2+$A16+1,F$3):OFFSET('t688128'!$A$1,$B$2+($B17-1)*$E$2+$F$2+$G$2+$A16,F$3)) -> #DIV/0! | U17: =AVERAGE(OFFSET(t1376256!$A$1,$B$2+($B17-1)*$E$2+$F$2+$A16+1,F$3):OFFSET(t1376256!$A$1,$B$2+($B17-1)*$E$2+$F$2+$G$2+$A16,F$3)) -> #DIV/0!
A18: 0 | B18: 15 | C18: =C17*2 -> 1048576 | D18: =C18*$D$1 -> 4194304 | E18: =OFFSET('t42'!$A$1,$B$2+($B18-1)*$E$2+$A18,E$3) -> 0 | F18: =AVERAGE(OFFSET('t42'!$A$1,$B$2+($B18-1)*$E$2+$F$2+$A18,F$3):OFFSET('t42'!$A$1,$B$2+($B18-1)*$E$2+$F$2+$G$2+$A18,F$3)) -> #DIV/0! | G18: =AVERAGE(OFFSET('t84'!$A$1,$B$2+($B18-1)*$E$2+$F$2+$A18,F$3):OFFSET('t84'!$A$1,$B$2+($B18-1)*$E$2+$F$2+$G$2+$A18,F$3)) -> #DIV/0! | H18: =AVERAGE(OFFSET('t168'!$A$1,$B$2+($B18-1)*$E$2+$F$2+$A18,F$3):OFFSET('t168'!$A$1,$B$2+($B18-1)*$E$2+$F$2+$G$2+$A18,F$3)) -> #DIV/0! | I18: =AVERAGE(OFFSET('t336'!$A$1,$B$2+($B18-1)*$E$2+$F$2+$A18,F$3):OFFSET('t336'!$A$1,$B$2+($B18-1)*$E$2+$F$2+$G$2+$A18,F$3)) -> #DIV/0! | J18: =AVERAGE(OFFSET('t672'!$A$1,$B$2+($B18-1)*$E$2+$F$2+$A18,F$3):OFFSET('t672'!$A$1,$B$2+($B18-1)*$E$2+$F$2+$G$2+$A18,F$3)) -> #DIV/0! | K18: =AVERAGE(OFFSET('t1344'!$A$1,$B$2+($B18-1)*$E$2+$F$2+$A18,F$3):OFFSET('t1344'!$A$1,$B$2+($B18-1)*$E$2+$F$2+$G$2+$A18,F$3)) -> #DIV/0! | L18: =AVERAGE(OFFSET('t2688'!$A$1,$B$2+($B18-1)*$E$2+$F$2+$A18,F$3):OFFSET('t2688'!$A$1,$B$2+($B18-1)*$E$2+$F$2+$G$2+$A18,F$3)) -> #DIV/0! | M18: =AVERAGE(OFFSET('t5376'!$A$1,$B$2+($B18-1)*$E$2+$F$2+$A18,F$3):OFFSET('t5376'!$A$1,$B$2+($B18-1)*$E$2+$F$2+$G$2+$A18,F$3)) -> #DIV/0! | N18: =AVERAGE(OFFSET('t10752'!$A$1,$B$2+($B18-1)*$E$2+$F$2+$A18,F$3):OFFSET('t10752'!$A$1,$B$2+($B18-1)*$E$2+$F$2+$G$2+$A18,F$3)) -> #DIV/0! | O18: =AVERAGE(OFFSET('t21504'!$A$1,$B$2+($B18-1)*$E$2+$F$2+$A18,F$3):OFFSET('t21504'!$A$1,$B$2+($B18-1)*$E$2+$F$2+$G$2+$A18,F$3)) -> #DIV/0! | P18: =AVERAGE(OFFSET('t43008'!$A$1,$B$2+($B18-1)*$E$2+$F$2+$A18,F$3):OFFSET('t43008'!$A$1,$B$2+($B18-1)*$E$2+$F$2+$G$2+$A18,F$3)) -> #DIV/0! | Q18: =AVERAGE(OFFSET('t86016'!$A$1,$B$2+($B18-1)*$E$2+$F$2+$A18,F$3):OFFSET('t86016'!$A$1,$B$2+($B18-1)*$E$2+$F$2+$G$2+$A18,F$3)) -> #DIV/0! | R18: =AVERAGE(OFFSET('t172032'!$A$1,$B$2+($B18-1)*$E$2+$F$2+$A18,F$3):OFFSET('t172032'!$A$1,$B$2+($B18-1)*$E$2+$F$2+$G$2+$A18,F$3)) -> #DIV/0! | S18: =AVERAGE(OFFSET('t344064'!$A$1,$B$2+($B18-1)*$E$2+$F$2+$A18,F$3):OFFSET('t344064'!$A$1,$B$2+($B18-1)*$E$2+$F$2+$G$2+$A18,F$3)) -> #DIV/0! | T18: =AVERAGE(OFFSET('t688128'!$A$1,$B$2+($B18-1)*$E$2+$F$2+$A18,F$3):OFFSET('t688128'!$A$1,$B$2+($B18-1)*$E$2+$F$2+$G$2+$A18,F$3)) -> #DIV/0! | U18: =AVERAGE(OFFSET(t1376256!$A$1,$B$2+($B18-1)*$E$2+$F$2+$A18,F$3):OFFSET(t1376256!$A$1,$B$2+($B18-1)*$E$2+$F$2+$G$2+$A18,F$3)) -> #DIV/0!
B19: 16 | C19: =C18*2 -> 2097152 | D19: =C19*$D$1 -> 8388608 | E19: =OFFSET('t42'!$A$1,$B$2+($B19-1)*$E$2+$A18,E$3) -> 0 | F19: =AVERAGE(OFFSET('t42'!$A$1,$B$2+($B19-1)*$E$2+$F$2+$A18+1,F$3):OFFSET('t42'!$A$1,$B$2+($B19-1)*$E$2+$F$2+$G$2+$A18,F$3)) -> #DIV/0! | G19: =AVERAGE(OFFSET('t84'!$A$1,$B$2+($B19-1)*$E$2+$F$2+$A18+1,F$3):OFFSET('t84'!$A$1,$B$2+($B19-1)*$E$2+$F$2+$G$2+$A18,F$3)) -> #DIV/0! | H19: =AVERAGE(OFFSET('t168'!$A$1,$B$2+($B19-1)*$E$2+$F$2+$A18+1,F$3):OFFSET('t168'!$A$1,$B$2+($B19-1)*$E$2+$F$2+$G$2+$A18,F$3)) -> #DIV/0! | I19: =AVERAGE(OFFSET('t336'!$A$1,$B$2+($B19-1)*$E$2+$F$2+$A18+1,F$3):OFFSET('t336'!$A$1,$B$2+($B19-1)*$E$2+$F$2+$G$2+$A18,F$3)) -> #DIV/0! | J19: =AVERAGE(OFFSET('t672'!$A$1,$B$2+($B19-1)*$E$2+$F$2+$A18+1,F$3):OFFSET('t672'!$A$1,$B$2+($B19-1)*$E$2+$F$2+$G$2+$A18,F$3)) -> #DIV/0! | K19: =AVERAGE(OFFSET('t1344'!$A$1,$B$2+($B19-1)*$E$2+$F$2+$A18+1,F$3):OFFSET('t1344'!$A$1,$B$2+($B19-1)*$E$2+$F$2+$G$2+$A18,F$3)) -> #DIV/0! | L19: =AVERAGE(OFFSET('t2688'!$A$1,$B$2+($B19-1)*$E$2+$F$2+$A18+1,F$3):OFFSET('t2688'!$A$1,$B$2+($B19-1)*$E$2+$F$2+$G$2+$A18,F$3)) -> #DIV/0! | M19: =AVERAGE(OFFSET('t5376'!$A$1,$B$2+($B19-1)*$E$2+$F$2+$A18+1,F$3):OFFSET('t5376'!$A$1,$B$2+($B19-1)*$E$2+$F$2+$G$2+$A18,F$3)) -> #DIV/0! | N19: =AVERAGE(OFFSET('t10752'!$A$1,$B$2+($B19-1)*$E$2+$F$2+$A18+1,F$3):OFFSET('t10752'!$A$1,$B$2+($B19-1)*$E$2+$F$2+$G$2+$A18,F$3)) -> #DIV/0! | O19: =AVERAGE(OFFSET('t21504'!$A$1,$B$2+($B19-1)*$E$2+$F$2+$A18+1,F$3):OFFSET('t21504'!$A$1,$B$2+($B19-1)*$E$2+$F$2+$G$2+$A18,F$3)) -> #DIV/0! | P19: =AVERAGE(OFFSET('t43008'!$A$1,$B$2+($B19-1)*$E$2+$F$2+$A18+1,F$3):OFFSET('t43008'!$A$1,$B$2+($B19-1)*$E$2+$F$2+$G$2+$A18,F$3)) -> #DIV/0! | Q19: =AVERAGE(OFFSET('t86016'!$A$1,$B$2+($B19-1)*$E$2+$F$2+$A18+1,F$3):OFFSET('t86016'!$A$1,$B$2+($B19-1)*$E$2+$F$2+$G$2+$A18,F$3)) -> #DIV/0! | R19: =AVERAGE(OFFSET('t172032'!$A$1,$B$2+($B19-1)*$E$2+$F$2+$A18+1,F$3):OFFSET('t172032'!$A$1,$B$2+($B19-1)*$E$2+$F$2+$G$2+$A18,F$3)) -> #DIV/0! | S19: =AVERAGE(OFFSET('t344064'!$A$1,$B$2+($B19-1)*$E$2+$F$2+$A18+1,F$3):OFFSET('t344064'!$A$1,$B$2+($B19-1)*$E$2+$F$2+$G$2+$A18,F$3)) -> #DIV/0! | T19: =AVERAGE(OFFSET('t688128'!$A$1,$B$2+($B19-1)*$E$2+$F$2+$A18+1,F$3):OFFSET('t688128'!$A$1,$B$2+($B19-1)*$E$2+$F$2+$G$2+$A18,F$3)) -> #DIV/0! | U19: =AVERAGE(OFFSET(t1376256!$A$1,$B$2+($B19-1)*$E$2+$F$2+$A18+1,F$3):OFFSET(t1376256!$A$1,$B$2+($B19-1)*$E$2+$F$2+$G$2+$A18,F$3)) -> #DIV/0!
A20: 0 | B20: 17 | C20: =C19*2 -> 4194304 | D20: =C20*$D$1 -> 16777216 | E20: =OFFSET('t42'!$A$1,$B$2+($B20-1)*$E$2+$A20,E$3) -> 0 | F20: =AVERAGE(OFFSET('t42'!$A$1,$B$2+($B20-1)*$E$2+$F$2+$A20,F$3):OFFSET('t42'!$A$1,$B$2+($B20-1)*$E$2+$F$2+$G$2+$A20,F$3)) -> #DIV/0! | G20: =AVERAGE(OFFSET('t84'!$A$1,$B$2+($B20-1)*$E$2+$F$2+$A20,F$3):OFFSET('t84'!$A$1,$B$2+($B20-1)*$E$2+$F$2+$G$2+$A20,F$3)) -> #DIV/0! | H20: =AVERAGE(OFFSET('t168'!$A$1,$B$2+($B20-1)*$E$2+$F$2+$A20,F$3):OFFSET('t168'!$A$1,$B$2+($B20-1)*$E$2+$F$2+$G$2+$A20,F$3)) -> #DIV/0! | I20: =AVERAGE(OFFSET('t336'!$A$1,$B$2+($B20-1)*$E$2+$F$2+$A20,F$3):OFFSET('t336'!$A$1,$B$2+($B20-1)*$E$2+$F$2+$G$2+$A20,F$3)) -> #DIV/0! | J20: =AVERAGE(OFFSET('t672'!$A$1,$B$2+($B20-1)*$E$2+$F$2+$A20,F$3):OFFSET('t672'!$A$1,$B$2+($B20-1)*$E$2+$F$2+$G$2+$A20,F$3)) -> #DIV/0! | K20: =AVERAGE(OFFSET('t1344'!$A$1,$B$2+($B20-1)*$E$2+$F$2+$A20,F$3):OFFSET('t1344'!$A$1,$B$2+($B20-1)*$E$2+$F$2+$G$2+$A20,F$3)) -> #DIV/0! | L20: =AVERAGE(OFFSET('t2688'!$A$1,$B$2+($B20-1)*$E$2+$F$2+$A20,F$3):OFFSET('t2688'!$A$1,$B$2+($B20-1)*$E$2+$F$2+$G$2+$A20,F$3)) -> #DIV/0! | M20: =AVERAGE(OFFSET('t5376'!$A$1,$B$2+($B20-1)*$E$2+$F$2+$A20,F$3):OFFSET('t5376'!$A$1,$B$2+($B20-1)*$E$2+$F$2+$G$2+$A20,F$3)) -> #DIV/0! | N20: =AVERAGE(OFFSET('t10752'!$A$1,$B$2+($B20-1)*$E$2+$F$2+$A20,F$3):OFFSET('t10752'!$A$1,$B$2+($B20-1)*$E$2+$F$2+$G$2+$A20,F$3)) -> #DIV/0! | O20: =AVERAGE(OFFSET('t21504'!$A$1,$B$2+($B20-1)*$E$2+$F$2+$A20,F$3):OFFSET('t21504'!$A$1,$B$2+($B20-1)*$E$2+$F$2+$G$2+$A20,F$3)) -> #DIV/0! | P20: =AVERAGE(OFFSET('t43008'!$A$1,$B$2+($B20-1)*$E$2+$F$2+$A20,F$3):OFFSET('t43008'!$A$1,$B$2+($B20-1)*$E$2+$F$2+$G$2+$A20,F$3)) -> #DIV/0! | Q20: =AVERAGE(OFFSET('t86016'!$A$1,$B$2+($B20-1)*$E$2+$F$2+$A20,F$3):OFFSET('t86016'!$A$1,$B$2+($B20-1)*$E$2+$F$2+$G$2+$A20,F$3)) -> #DIV/0! | R20: =AVERAGE(OFFSET('t172032'!$A$1,$B$2+($B20-1)*$E$2+$F$2+$A20,F$3):OFFSET('t172032'!$A$1,$B$2+($B20-1)*$E$2+$F$2+$G$2+$A20,F$3)) -> #DIV/0! | S20: =AVERAGE(OFFSET('t344064'!$A$1,$B$2+($B20-1)*$E$2+$F$2+$A20,F$3):OFFSET('t344064'!$A$1,$B$2+($B20-1)*$E$2+$F$2+$G$2+$A20,F$3)) -> #DIV/0! | T20: =AVERAGE(OFFSET('t688128'!$A$1,$B$2+($B20-1)*$E$2+$F$2+$A20,F$3):OFFSET('t688128'!$A$1,$B$2+($B20-1)*$E$2+$F$2+$G$2+$A20,F$3)) -> #DIV/0! | U20: =AVERAGE(OFFSET(t1376256!$A$1,$B$2+($B20-1)*$E$2+$F$2+$A20,F$3):OFFSET(t1376256!$A$1,$B$2+($B20-1)*$E$2+$F$2+$G$2+$A20,F$3)) -> #DIV/0!
B21: 18 | C21: =C20*2 -> 8388608 | D21: =C21*$D$1 -> 33554432 | E21: =OFFSET('t42'!$A$1,$B$2+($B21-1)*$E$2+$A20,E$3) -> 0 | F21: =AVERAGE(OFFSET('t42'!$A$1,$B$2+($B21-1)*$E$2+$F$2+$A20+1,F$3):OFFSET('t42'!$A$1,$B$2+($B21-1)*$E$2+$F$2+$G$2+$A20,F$3)) -> #DIV/0! | G21: =AVERAGE(OFFSET('t84'!$A$1,$B$2+($B21-1)*$E$2+$F$2+$A20+1,F$3):OFFSET('t84'!$A$1,$B$2+($B21-1)*$E$2+$F$2+$G$2+$A20,F$3)) -> #DIV/0! | H21: =AVERAGE(OFFSET('t168'!$A$1,$B$2+($B21-1)*$E$2+$F$2+$A20+1,F$3):OFFSET('t168'!$A$1,$B$2+($B21-1)*$E$2+$F$2+$G$2+$A20,F$3)) -> #DIV/0! | I21: =AVERAGE(OFFSET('t336'!$A$1,$B$2+($B21-1)*$E$2+$F$2+$A20+1,F$3):OFFSET('t336'!$A$1,$B$2+($B21-1)*$E$2+$F$2+$G$2+$A20,F$3)) -> #DIV/0! | J21: =AVERAGE(OFFSET('t672'!$A$1,$B$2+($B21-1)*$E$2+$F$2+$A20+1,F$3):OFFSET('t672'!$A$1,$B$2+($B21-1)*$E$2+$F$2+$G$2+$A20,F$3)) -> #DIV/0! | K21: =AVERAGE(OFFSET('t1344'!$A$1,$B$2+($B21-1)*$E$2+$F$2+$A20+1,F$3):OFFSET('t1344'!$A$1,$B$2+($B21-1)*$E$2+$F$2+$G$2+$A20,F$3)) -> #DIV/0! | L21: =AVERAGE(OFFSET('t2688'!$A$1,$B$2+($B21-1)*$E$2+$F$2+$A20+1,F$3):OFFSET('t2688'!$A$1,$B$2+($B21-1)*$E$2+$F$2+$G$2+$A20,F$3)) -> #DIV/0! | M21: =AVERAGE(OFFSET('t5376'!$A$1,$B$2+($B21-1)*$E$2+$F$2+$A20+1,F$3):OFFSET('t5376'!$A$1,$B$2+($B21-1)*$E$2+$F$2+$G$2+$A20,F$3)) -> #DIV/0! | N21: =AVERAGE(OFFSET('t10752'!$A$1,$B$2+($B21-1)*$E$2+$F$2+$A20+1,F$3):OFFSET('t10752'!$A$1,$B$2+($B21-1)*$E$2+$F$2+$G$2+$A20,F$3)) -> #DIV/0! | O21: =AVERAGE(OFFSET('t21504'!$A$1,$B$2+($B21-1)*$E$2+$F$2+$A20+1,F$3):OFFSET('t21504'!$A$1,$B$2+($B21-1)*$E$2+$F$2+$G$2+$A20,F$3)) -> #DIV/0! | P21: =AVERAGE(OFFSET('t43008'!$A$1,$B$2+($B21-1)*$E$2+$F$2+$A20+1,F$3):OFFSET('t43008'!$A$1,$B$2+($B21-1)*$E$2+$F$2+$G$2+$A20,F$3)) -> #DIV/0! | Q21: =AVERAGE(OFFSET('t86016'!$A$1,$B$2+($B21-1)*$E$2+$F$2+$A20+1,F$3):OFFSET('t86016'!$A$1,$B$2+($B21-1)*$E$2+$F$2+$G$2+$A20,F$3)) -> #DIV/0! | R21: =AVERAGE(OFFSET('t172032'!$A$1,$B$2+($B21-1)*$E$2+$F$2+$A20+1,F$3):OFFSET('t172032'!$A$1,$B$2+($B21-1)*$E$2+$F$2+$G$2+$A20,F$3)) -> #DIV/0! | S21: =AVERAGE(OFFSET('t344064'!$A$1,$B$2+($B21-1)*$E$2+$F$2+$A20+1,F$3):OFFSET('t344064'!$A$1,$B$2+($B21-1)*$E$2+$F$2+$G$2+$A20,F$3)) -> #DIV/0! | T21: =AVERAGE(OFFSET('t688128'!$A$1,$B$2+($B21-1)*$E$2+$F$2+$A20+1,F$3):OFFSET('t688128'!$A$1,$B$2+($B21-1)*$E$2+$F$2+$G$2+$A20,F$3)) -> #DIV/0! | U21: =AVERAGE(OFFSET(t1376256!$A$1,$B$2+($B21-1)*$E$2+$F$2+$A20+1,F$3):OFFSET(t1376256!$A$1,$B$2+($B21-1)*$E$2+$F$2+$G$2+$A20,F$3)) -> #DIV/0!
A22: 0 | B22: 19 | C22: =C21*2 -> 16777216 | D22: =C22*$D$1 -> 67108864 | E22: =OFFSET('t42'!$A$1,$B$2+($B22-1)*$E$2+$A22,E$3) -> 0 | F22: =AVERAGE(OFFSET('t42'!$A$1,$B$2+($B22-1)*$E$2+$F$2+$A22,F$3):OFFSET('t42'!$A$1,$B$2+($B22-1)*$E$2+$F$2+$G$2+$A22,F$3)) -> #DIV/0! | G22: =AVERAGE(OFFSET('t84'!$A$1,$B$2+($B22-1)*$E$2+$F$2+$A22,F$3):OFFSET('t84'!$A$1,$B$2+($B22-1)*$E$2+$F$2+$G$2+$A22,F$3)) -> #DIV/0! | H22: =AVERAGE(OFFSET('t168'!$A$1,$B$2+($B22-1)*$E$2+$F$2+$A22,F$3):OFFSET('t168'!$A$1,$B$2+($B22-1)*$E$2+$F$2+$G$2+$A22,F$3)) -> #DIV/0! | I22: =AVERAGE(OFFSET('t336'!$A$1,$B$2+($B22-1)*$E$2+$F$2+$A22,F$3):OFFSET('t336'!$A$1,$B$2+($B22-1)*$E$2+$F$2+$G$2+$A22,F$3)) -> #DIV/0! | J22: =AVERAGE(OFFSET('t672'!$A$1,$B$2+($B22-1)*$E$2+$F$2+$A22,F$3):OFFSET('t672'!$A$1,$B$2+($B22-1)*$E$2+$F$2+$G$2+$A22,F$3)) -> #DIV/0! | K22: =AVERAGE(OFFSET('t1344'!$A$1,$B$2+($B22-1)*$E$2+$F$2+$A22,F$3):OFFSET('t1344'!$A$1,$B$2+($B22-1)*$E$2+$F$2+$G$2+$A22,F$3)) -> #DIV/0! | L22: =AVERAGE(OFFSET('t2688'!$A$1,$B$2+($B22-1)*$E$2+$F$2+$A22,F$3):OFFSET('t2688'!$A$1,$B$2+($B22-1)*$E$2+$F$2+$G$2+$A22,F$3)) -> #DIV/0! | M22: =AVERAGE(OFFSET('t5376'!$A$1,$B$2+($B22-1)*$E$2+$F$2+$A22,F$3):OFFSET('t5376'!$A$1,$B$2+($B22-1)*$E$2+$F$2+$G$2+$A22,F$3)) -> #DIV/0! | N22: =AVERAGE(OFFSET('t10752'!$A$1,$B$2+($B22-1)*$E$2+$F$2+$A22,F$3):OFFSET('t10752'!$A$1,$B$2+($B22-1)*$E$2+$F$2+$G$2+$A22,F$3)) -> #DIV/0! | O22: =AVERAGE(OFFSET('t21504'!$A$1,$B$2+($B22-1)*$E$2+$F$2+$A22,F$3):OFFSET('t21504'!$A$1,$B$2+($B22-1)*$E$2+$F$2+$G$2+$A22,F$3)) -> #DIV/0! | P22: =AVERAGE(OFFSET('t43008'!$A$1,$B$2+($B22-1)*$E$2+$F$2+$A22,F$3):OFFSET('t43008'!$A$1,$B$2+($B22-1)*$E$2+$F$2+$G$2+$A22,F$3)) -> #DIV/0! | Q22: =AVERAGE(OFFSET('t86016'!$A$1,$B$2+($B22-1)*$E$2+$F$2+$A22,F$3):OFFSET('t86016'!$A$1,$B$2+($B22-1)*$E$2+$F$2+$G$2+$A22,F$3)) -> #DIV/0! | R22: =AVERAGE(OFFSET('t172032'!$A$1,$B$2+($B22-1)*$E$2+$F$2+$A22,F$3):OFFSET('t172032'!$A$1,$B$2+($B22-1)*$E$2+$F$2+$G$2+$A22,F$3)) -> #DIV/0! | S22: =AVERAGE(OFFSET('t344064'!$A$1,$B$2+($B22-1)*$E$2+$F$2+$A22,F$3):OFFSET('t344064'!$A$1,$B$2+($B22-1)*$E$2+$F$2+$G$2+$A22,F$3)) -> #DIV/0! | T22: =AVERAGE(OFFSET('t688128'!$A$1,$B$2+($B22-1)*$E$2+$F$2+$A22,F$3):OFFSET('t688128'!$A$1,$B$2+($B22-1)*$E$2+$F$2+$G$2+$A22,F$3)) -> #DIV/0! | U22: =AVERAGE(OFFSET(t1376256!$A$1,$B$2+($B22-1)*$E$2+$F$2+$A22,F$3):OFFSET(t1376256!$A$1,$B$2+($B22-1)*$E$2+$F$2+$G$2+$A22,F$3)) -> #DIV/0!
B23: 20 | C23: =C22*2 -> 33554432 | D23: =C23*$D$1 -> 134217728 | E23: =OFFSET('t42'!$A$1,$B$2+($B23-1)*$E$2+$A22,E$3) -> 0 | F23: =AVERAGE(OFFSET('t42'!$A$1,$B$2+($B23-1)*$E$2+$F$2+$A22+1,F$3):OFFSET('t42'!$A$1,$B$2+($B23-1)*$E$2+$F$2+$G$2+$A22,F$3)) -> #DIV/0! | G23: =AVERAGE(OFFSET('t84'!$A$1,$B$2+($B23-1)*$E$2+$F$2+$A22+1,F$3):OFFSET('t84'!$A$1,$B$2+($B23-1)*$E$2+$F$2+$G$2+$A22,F$3)) -> #DIV/0! | H23: =AVERAGE(OFFSET('t168'!$A$1,$B$2+($B23-1)*$E$2+$F$2+$A22+1,F$3):OFFSET('t168'!$A$1,$B$2+($B23-1)*$E$2+$F$2+$G$2+$A22,F$3)) -> #DIV/0! | I23: =AVERAGE(OFFSET('t336'!$A$1,$B$2+($B23-1)*$E$2+$F$2+$A22+1,F$3):OFFSET('t336'!$A$1,$B$2+($B23-1)*$E$2+$F$2+$G$2+$A22,F$3)) -> #DIV/0! | J23: =AVERAGE(OFFSET('t672'!$A$1,$B$2+($B23-1)*$E$2+$F$2+$A22+1,F$3):OFFSET('t672'!$A$1,$B$2+($B23-1)*$E$2+$F$2+$G$2+$A22,F$3)) -> #DIV/0! | K23: =AVERAGE(OFFSET('t1344'!$A$1,$B$2+($B23-1)*$E$2+$F$2+$A22+1,F$3):OFFSET('t1344'!$A$1,$B$2+($B23-1)*$E$2+$F$2+$G$2+$A22,F$3)) -> #DIV/0! | L23: =AVERAGE(OFFSET('t2688'!$A$1,$B$2+($B23-1)*$E$2+$F$2+$A22+1,F$3):OFFSET('t2688'!$A$1,$B$2+($B23-1)*$E$2+$F$2+$G$2+$A22,F$3)) -> #DIV/0! | M23: =AVERAGE(OFFSET('t5376'!$A$1,$B$2+($B23-1)*$E$2+$F$2+$A22+1,F$3):OFFSET('t5376'!$A$1,$B$2+($B23-1)*$E$2+$F$2+$G$2+$A22,F$3)) -> #DIV/0! | N23: =AVERAGE(OFFSET('t10752'!$A$1,$B$2+($B23-1)*$E$2+$F$2+$A22+1,F$3):OFFSET('t10752'!$A$1,$B$2+($B23-1)*$E$2+$F$2+$G$2+$A22,F$3)) -> #DIV/0! | O23: =AVERAGE(OFFSET('t21504'!$A$1,$B$2+($B23-1)*$E$2+$F$2+$A22+1,F$3):OFFSET('t21504'!$A$1,$B$2+($B23-1)*$E$2+$F$2+$G$2+$A22,F$3)) -> #DIV/0! | P23: =AVERAGE(OFFSET('t43008'!$A$1,$B$2+($B23-1)*$E$2+$F$2+$A22+1,F$3):OFFSET('t43008'!$A$1,$B$2+($B23-1)*$E$2+$F$2+$G$2+$A22,F$3)) -> #DIV/0! | Q23: =AVERAGE(OFFSET('t86016'!$A$1,$B$2+($B23-1)*$E$2+$F$2+$A22+1,F$3):OFFSET('t86016'!$A$1,$B$2+($B23-1)*$E$2+$F$2+$G$2+$A22,F$3)) -> #DIV/0! | R23: =AVERAGE(OFFSET('t172032'!$A$1,$B$2+($B23-1)*$E$2+$F$2+$A22+1,F$3):OFFSET('t172032'!$A$1,$B$2+($B23-1)*$E$2+$F$2+$G$2+$A22,F$3)) -> #DIV/0! | S23: =AVERAGE(OFFSET('t344064'!$A$1,$B$2+($B23-1)*$E$2+$F$2+$A22+1,F$3):OFFSET('t344064'!$A$1,$B$2+($B23-1)*$E$2+$F$2+$G$2+$A22,F$3)) -> #DIV/0! | T23: =AVERAGE(OFFSET('t688128'!$A$1,$B$2+($B23-1)*$E$2+$F$2+$A22+1,F$3):OFFSET('t688128'!$A$1,$B$2+($B23-1)*$E$2+$F$2+$G$2+$A22,F$3)) -> #DIV/0! | U23: =AVERAGE(OFFSET(t1376256!$A$1,$B$2+($B23-1)*$E$2+$F$2+$A22+1,F$3):OFFSET(t1376256!$A$1,$B$2+($B23-1)*$E$2+$F$2+$G$2+$A22,F$3)) -> #DIV/0!
A24: 0 | B24: 21 | E24: =OFFSET('t42'!$A$1,$B$2+($B24-1)*$E$2+$A24,E$3) -> 0 | F24: =AVERAGE(OFFSET('t42'!$A$1,$B$2+($B24-1)*$E$2+$F$2+$A24,F$3):OFFSET('t42'!$A$1,$B$2+($B24-1)*$E$2+$F$2+$G$2+$A24,F$3)) -> #DIV/0! | G24: =AVERAGE(OFFSET('t84'!$A$1,$B$2+($B24-1)*$E$2+$F$2+$A24,F$3):OFFSET('t84'!$A$1,$B$2+($B24-1)*$E$2+$F$2+$G$2+$A24,F$3)) -> #DIV/0! | H24: =AVERAGE(OFFSET('t168'!$A$1,$B$2+($B24-1)*$E$2+$F$2+$A24,F$3):OFFSET('t168'!$A$1,$B$2+($B24-1)*$E$2+$F$2+$G$2+$A24,F$3)) -> #DIV/0! | I24: =AVERAGE(OFFSET('t336'!$A$1,$B$2+($B24-1)*$E$2+$F$2+$A24,F$3):OFFSET('t336'!$A$1,$B$2+($B24-1)*$E$2+$F$2+$G$2+$A24,F$3)) -> #DIV/0! | J24: =AVERAGE(OFFSET('t672'!$A$1,$B$2+($B24-1)*$E$2+$F$2+$A24,F$3):OFFSET('t672'!$A$1,$B$2+($B24-1)*$E$2+$F$2+$G$2+$A24,F$3)) -> #DIV/0! | K24: =AVERAGE(OFFSET('t1344'!$A$1,$B$2+($B24-1)*$E$2+$F$2+$A24,F$3):OFFSET('t1344'!$A$1,$B$2+($B24-1)*$E$2+$F$2+$G$2+$A24,F$3)) -> #DIV/0! | L24: =AVERAGE(OFFSET('t2688'!$A$1,$B$2+($B24-1)*$E$2+$F$2+$A24,F$3):OFFSET('t2688'!$A$1,$B$2+($B24-1)*$E$2+$F$2+$G$2+$A24,F$3)) -> #DIV/0! | M24: =AVERAGE(OFFSET('t5376'!$A$1,$B$2+($B24-1)*$E$2+$F$2+$A24,F$3):OFFSET('t5376'!$A$1,$B$2+($B24-1)*$E$2+$F$2+$G$2+$A24,F$3)) -> #DIV/0! | N24: =AVERAGE(OFFSET('t10752'!$A$1,$B$2+($B24-1)*$E$2+$F$2+$A24,F$3):OFFSET('t10752'!$A$1,$B$2+($B24-1)*$E$2+$F$2+$G$2+$A24,F$3)) -> #DIV/0! | O24: =AVERAGE(OFFSET('t21504'!$A$1,$B$2+($B24-1)*$E$2+$F$2+$A24,F$3):OFFSET('t21504'!$A$1,$B$2+($B24-1)*$E$2+$F$2+$G$2+$A24,F$3)) -> #DIV/0! | P24: =AVERAGE(OFFSET('t43008'!$A$1,$B$2+($B24-1)*$E$2+$F$2+$A24,F$3):OFFSET('t43008'!$A$1,$B$2+($B24-1)*$E$2+$F$2+$G$2+$A24,F$3)) -> #DIV/0! | Q24: =AVERAGE(OFFSET('t86016'!$A$1,$B$2+($B24-1)*$E$2+$F$2+$A24,F$3):OFFSET('t86016'!$A$1,$B$2+($B24-1)*$E$2+$F$2+$G$2+$A24,F$3)) -> #DIV/0! | R24: =AVERAGE(OFFSET('t172032'!$A$1,$B$2+($B24-1)*$E$2+$F$2+$A24,F$3):OFFSET('t172032'!$A$1,$B$2+($B24-1)*$E$2+$F$2+$G$2+$A24,F$3)) -> #DIV/0! | S24: =AVERAGE(OFFSET('t344064'!$A$1,$B$2+($B24-1)*$E$2+$F$2+$A24,F$3):OFFSET('t344064'!$A$1,$B$2+($B24-1)*$E$2+$F$2+$G$2+$A24,F$3)) -> #DIV/0! | T24: =AVERAGE(OFFSET('t688128'!$A$1,$B$2+($B24-1)*$E$2+$F$2+$A24,F$3):OFFSET('t688128'!$A$1,$B$2+($B24-1)*$E$2+$F$2+$G$2+$A24,F$3)) -> #DIV/0! | U24: =AVERAGE(OFFSET(t1376256!$A$1,$B$2+($B24-1)*$E$2+$F$2+$A24,F$3):OFFSET(t1376256!$A$1,$B$2+($B24-1)*$E$2+$F$2+$G$2+$A24,F$3)) -> #DIV/0!
B25: 22 | E25: =OFFSET('t42'!$A$1,$B$2+($B25-1)*$E$2+$A24,E$3) -> 0 | F25: =AVERAGE(OFFSET('t42'!$A$1,$B$2+($B25-1)*$E$2+$F$2+$A24+1,F$3):OFFSET('t42'!$A$1,$B$2+($B25-1)*$E$2+$F$2+$G$2+$A24,F$3)) -> #DIV/0! | G25: =AVERAGE(OFFSET('t84'!$A$1,$B$2+($B25-1)*$E$2+$F$2+$A24+1,F$3):OFFSET('t84'!$A$1,$B$2+($B25-1)*$E$2+$F$2+$G$2+$A24,F$3)) -> #DIV/0! | H25: =AVERAGE(OFFSET('t168'!$A$1,$B$2+($B25-1)*$E$2+$F$2+$A24+1,F$3):OFFSET('t168'!$A$1,$B$2+($B25-1)*$E$2+$F$2+$G$2+$A24,F$3)) -> #DIV/0! | I25: =AVERAGE(OFFSET('t336'!$A$1,$B$2+($B25-1)*$E$2+$F$2+$A24+1,F$3):OFFSET('t336'!$A$1,$B$2+($B25-1)*$E$2+$F$2+$G$2+$A24,F$3)) -> #DIV/0! | J25: =AVERAGE(OFFSET('t672'!$A$1,$B$2+($B25-1)*$E$2+$F$2+$A24+1,F$3):OFFSET('t672'!$A$1,$B$2+($B25-1)*$E$2+$F$2+$G$2+$A24,F$3)) -> #DIV/0! | K25: =AVERAGE(OFFSET('t1344'!$A$1,$B$2+($B25-1)*$E$2+$F$2+$A24+1,F$3):OFFSET('t1344'!$A$1,$B$2+($B25-1)*$E$2+$F$2+$G$2+$A24,F$3)) -> #DIV/0! | L25: =AVERAGE(OFFSET('t2688'!$A$1,$B$2+($B25-1)*$E$2+$F$2+$A24+1,F$3):OFFSET('t2688'!$A$1,$B$2+($B25-1)*$E$2+$F$2+$G$2+$A24,F$3)) -> #DIV/0! | M25: =AVERAGE(OFFSET('t5376'!$A$1,$B$2+($B25-1)*$E$2+$F$2+$A24+1,F$3):OFFSET('t5376'!$A$1,$B$2+($B25-1)*$E$2+$F$2+$G$2+$A24,F$3)) -> #DIV/0! | N25: =AVERAGE(OFFSET('t10752'!$A$1,$B$2+($B25-1)*$E$2+$F$2+$A24+1,F$3):OFFSET('t10752'!$A$1,$B$2+($B25-1)*$E$2+$F$2+$G$2+$A24,F$3)) -> #DIV/0! | O25: =AVERAGE(OFFSET('t21504'!$A$1,$B$2+($B25-1)*$E$2+$F$2+$A24+1,F$3):OFFSET('t21504'!$A$1,$B$2+($B25-1)*$E$2+$F$2+$G$2+$A24,F$3)) -> #DIV/0! | P25: =AVERAGE(OFFSET('t43008'!$A$1,$B$2+($B25-1)*$E$2+$F$2+$A24+1,F$3):OFFSET('t43008'!$A$1,$B$2+($B25-1)*$E$2+$F$2+$G$2+$A24,F$3)) -> #DIV/0! | Q25: =AVERAGE(OFFSET('t86016'!$A$1,$B$2+($B25-1)*$E$2+$F$2+$A24+1,F$3):OFFSET('t86016'!$A$1,$B$2+($B25-1)*$E$2+$F$2+$G$2+$A24,F$3)) -> #DIV/0! | R25: =AVERAGE(OFFSET('t172032'!$A$1,$B$2+($B25-1)*$E$2+$F$2+$A24+1,F$3):OFFSET('t172032'!$A$1,$B$2+($B25-1)*$E$2+$F$2+$G$2+$A24,F$3)) -> #DIV/0! | S25: =AVERAGE(OFFSET('t344064'!$A$1,$B$2+($B25-1)*$E$2+$F$2+$A24+1,F$3):OFFSET('t344064'!$A$1,$B$2+($B25-1)*$E$2+$F$2+$G$2+$A24,F$3)) -> #DIV/0! | T25: =AVERAGE(OFFSET('t688128'!$A$1,$B$2+($B25-1)*$E$2+$F$2+$A24+1,F$3):OFFSET('t688128'!$A$1,$B$2+($B25-1)*$E$2+$F$2+$G$2+$A24,F$3)) -> #DIV/0! | U25: =AVERAGE(OFFSET(t1376256!$A$1,$B$2+($B25-1)*$E$2+$F$2+$A24+1,F$3):OFFSET(t1376256!$A$1,$B$2+($B25-1)*$E$2+$F$2+$G$2+$A24,F$3)) -> #DIV/0!
F29: 42 | G29: =F29*2 -> 84 | H29: =G29*2 -> 168 | I29: =H29*2 -> 336 | J29: =I29*2 -> 672 | K29: =J29*2 -> 1344 | L29: =K29*2 -> 2688 | M29: =L29*2 -> 5376 | N29: =M29*2 -> 10752 | ... X29: =W29*2 -> 11010048
E30: =D4 -> 256 | F30: =F4/F$1 -> 1.4869341 | G30: =G4/G$1 -> 0.8293065 | H30: =H4/H$1 -> 0.51111143 | I30: =I4/I$1 -> 0.33621194 | J30: =J4/J$1 -> 0.25466429 | K30: =K4/K$1 -> 0.20703469 | L30: =L4/L$1 -> 0.18934594 | M30: =M4/M$1 -> 0.17155099 | ... X30: =X4/X$1 -> 0
E31: =D5 -> 512 | F31: =F5/F$1 -> 1.4955269 | G31: =G5/G$1 -> 0.83686861 | H31: =H5/H$1 -> 0.5187631 | I31: =I5/I$1 -> 0.34249172 | J31: =J5/J$1 -> 0.25281526 | K31: =K5/K$1 -> 0.20612722 | L31: =L5/L$1 -> 0.1973269 | M31: =M5/M$1 -> 0.17845786 | ... X31: =X5/X$1 -> 0
E32: =D6 -> 1024 | F32: =F6/F$1 -> 1.498983 | G32: =G6/G$1 -> 0.88349264 | H32: =H6/H$1 -> 0.52877282 | I32: =I6/I$1 -> 0.3456369 | J32: =J6/J$1 -> 0.26612768 | K32: =K6/K$1 -> 0.21648281 | L32: =L6/L$1 -> 0.20487764 | M32: =M6/M$1 -> 0.19749225 | ... X32: =X6/X$1 -> 0
E33: =D7 -> 2048 | F33: =F7/F$1 -> 1.5662349 | G33: =G7/G$1 -> 0.90497357 | H33: =H7/H$1 -> 0.54361148 | I33: =I7/I$1 -> 0.36770821 | J33: =J7/J$1 -> 0.27915276 | K33: =K7/K$1 -> 0.23376702 | L33: =L7/L$1 -> 0.22507226 | M33: =M7/M$1 -> 0.22306965 | ... X33: =X7/X$1 -> 0
E34: =D8 -> 4096 | F34: =F8/F$1 -> 1.7290161 | G34: =G8/G$1 -> 0.97754926 | H34: =H8/H$1 -> 0.60049571 | I34: =I8/I$1 -> 0.4010025 | J34: =J8/J$1 -> 0.30965042 | K34: =K8/K$1 -> 0.25347661 | L34: =L8/L$1 -> 0.25331519 | M34: =M8/M$1 -> 0.29301172 | ... X34: =X8/X$1 -> 0
E35: =D9 -> 8192 | F35: =F9/F$1 -> 1.9430701 | G35: =G9/G$1 -> 1.1328724 | H35: =H9/H$1 -> 0.67573093 | I35: =I9/I$1 -> 0.44125504 | J35: =J9/J$1 -> 0.35447583 | K35: =K9/K$1 -> 0.31688612 | L35: =L9/L$1 -> 0.32720207 | M35: =M9/M$1 -> 0.40489253 | ... X35: =X9/X$1 -> 0
E36: =D10 -> 16384 | F36: =F10/F$1 -> 2.4016462 | G36: =G10/G$1 -> 1.4889069 | H36: =H10/H$1 -> 0.80396321 | I36: =I10/I$1 -> 0.55557946 | J36: =J10/J$1 -> 0.45838274 | K36: =K10/K$1 -> 0.43700713 | L36: =L10/L$1 -> 0.48173943 | M36: =M10/M$1 -> 0.57988103 | ... X36: =X10/X$1 -> 0
E37: =D11 -> 32768 | F37: =F11/F$1 -> 3.4843192 | G37: =G11/G$1 -> 2.2394526 | H37: =H11/H$1 -> 1.0647645 | I37: =I11/I$1 -> 0.76857574 | J37: =J11/J$1 -> 0.68004264 | K37: =K11/K$1 -> 0.66648644 | L37: =L11/L$1 -> 0.75936429 | M37: =M11/M$1 -> 0.90281641 | ... X37: =X11/X$1 -> 0
E38: =D12 -> 65536 | F38: =F12/F$1 -> 5.6297352 | G38: =G12/G$1 -> 3.7229688 | H38: =H12/H$1 -> 1.6356729 | I38: =I12/I$1 -> 1.1836306 | J38: =J12/J$1 -> 1.1042992 | K38: =K12/K$1 -> 1.1247756 | L38: =L12/L$1 -> 1.3439031 | M38: =M12/M$1 -> 1.5301352 | ... X38: =X12/X$1 -> 0
E39: =D13 -> 131072 | F39: =F13/F$1 -> #DIV/0! | G39: =G13/G$1 -> #DIV/0! | H39: =H13/H$1 -> #DIV/0! | I39: =I13/I$1 -> #DIV/0! | J39: =J13/J$1 -> #DIV/0! | K39: =K13/K$1 -> #DIV/0! | L39: =L13/L$1 -> #DIV/0! | M39: =M13/M$1 -> #DIV/0! | ... X39: =X13/X$1 -> 0
E40: =D14 -> 262144 | F40: =F14/F$1 -> #DIV/0! | G40: =G14/G$1 -> #DIV/0! | H40: =H14/H$1 -> #DIV/0! | I40: =I14/I$1 -> #DIV/0! | J40: =J14/J$1 -> #DIV/0! | K40: =K14/K$1 -> #DIV/0! | L40: =L14/L$1 -> #DIV/0! | M40: =M14/M$1 -> #DIV/0! | ... X40: =X14/X$1 -> 0
E41: =D15 -> 524288 | F41: =F15/F$1 -> #DIV/0! | G41: =G15/G$1 -> #DIV/0! | H41: =H15/H$1 -> #DIV/0! | I41: =I15/I$1 -> #DIV/0! | J41: =J15/J$1 -> #DIV/0! | K41: =K15/K$1 -> #DIV/0! | L41: =L15/L$1 -> #DIV/0! | M41: =M15/M$1 -> #DIV/0! | ... X41: =X15/X$1 -> 0
... E49: =D23 -> 134217728 | F49: =F23/F$1 -> #DIV/0! | G49: =G23/G$1 -> #DIV/0! | H49: =H23/H$1 -> #DIV/0! | I49: =I23/I$1 -> #DIV/0! | J49: =J23/J$1 -> #DIV/0! | K49: =K23/K$1 -> #DIV/0! | L49: =L23/L$1 -> #DIV/0! | M49: =M23/M$1 -> #DIV/0! | ... X49: =X23/X$1 -> 0
F53: 42 | G53: =F53*2 -> 84 | H53: =G53*2 -> 168 | I53: =H53*2 -> 336 | J53: =I53*2 -> 672 | K53: =J53*2 -> 1344 | L53: =K53*2 -> 2688 | M53: =L53*2 -> 5376 | N53: =M53*2 -> 10752 | ... X53: =W53*2 -> 11010048
...

Sheet t42
