Workbook

Sheet Itog
A1: 109 | O1: =OFFSET('1050LAPTOP'!$C$1,A4-1,0) -> CUDA opt ant par Const | Y1: 3
E2: 2 | F2: 4 | G2: 8 | H2: 16 | I2: 32 | J2: 64 | K2: 128 | Q2: 2 | R2: 4 | S2: 8 | T2: 16 | U2: 32 | V2: 64 | W2: 128 | Y2: 32
E3: 42 | F3: 84 | G3: 168 | H3: 336 | I3: 672 | J3: 1344 | K3: 2688 | Q3: 42 | R3: 84 | S3: 168 | T3: 336 | U3: 672 | V3: 1344 | W3: 2688 | Y3: 65
A4: 47 | B4: =OFFSET('1050LAPTOP'!$C$1,A4-1,0) -> CUDA opt ant par Const | C4: Classic ACO | D4: МО | E4: =OFFSET('1050LAPTOP'!D$1,$A5-1,0) -> 14722.332 | F4: =OFFSET('1050LAPTOP'!E$1,$A5-1,0) -> 27364.668 | G4: =OFFSET('1050LAPTOP'!F$1,$A5-1,0) -> 52186.786 | H4: =OFFSET('1050LAPTOP'!G$1,$A5-1,0) -> 103402.44 | I4: =OFFSET('1050LAPTOP'!H$1,$A5-1,0) -> 207103.36 | J4: =OFFSET('1050LAPTOP'!I$1,$A5-1,0) -> 410463.68 | K4: =OFFSET('1050LAPTOP'!J$1,$A5-1,0) -> 835652.72 | N4: 768 | O4: i5-8300H + 1050 Ti | P4: МО | Q4: =OFFSET('1050LAPTOP'!D$1,$A$4-1,0) -> 26.173686 | R4: =OFFSET('1050LAPTOP'!E$1,$A$4-1,0) -> 18.161883 | S4: =OFFSET('1050LAPTOP'!F$1,$A$4-1,0) -> 14.080918 | T4: =OFFSET('1050LAPTOP'!G$1,$A$4-1,0) -> 12.342671 | U4: =OFFSET('1050LAPTOP'!H$1,$A$4-1,0) -> 11.374037 | V4: =OFFSET('1050LAPTOP'!I$1,$A$4-1,0) -> 10.799607 | W4: =OFFSET('1050LAPTOP'!J$1,$A$4-1,0) -> 0
A5: 3 | B5: =OFFSET('1050LAPTOP'!$C$1,A5-1,0) -> Classic ACO | D5: ДИ | E5: =OFFSET('1050LAPTOP'!D$1,$A5-1+$A$1,0) -> 1653.828 | F5: =OFFSET('1050LAPTOP'!E$1,$A5-1+$A$1,0) -> 1627.9611 | G5: =OFFSET('1050LAPTOP'!F$1,$A5-1+$A$1,0) -> 455.93194 | H5: =OFFSET('1050LAPTOP'!G$1,$A5-1+$A$1,0) -> 504.89508 | I5: =OFFSET('1050LAPTOP'!H$1,$A5-1+$A$1,0) -> 448.41431 | J5: =OFFSET('1050LAPTOP'!I$1,$A5-1+$A$1,0) -> 922.85496 | K5: =OFFSET('1050LAPTOP'!J$1,$A5-1+$A$1,0) -> 15568.28 | P5: ДИ | Q5: =OFFSET('1050LAPTOP'!D$1,$A$4-1+$A$1,0) -> 0 | R5: =OFFSET('1050LAPTOP'!E$1,$A$4-1+$A$1,0) -> 0 | S5: =OFFSET('1050LAPTOP'!F$1,$A$4-1+$A$1,0) -> 0 | T5: =OFFSET('1050LAPTOP'!G$1,$A$4-1+$A$1,0) -> 0 | U5: =OFFSET('1050LAPTOP'!H$1,$A$4-1+$A$1,0) -> 0 | V5: =OFFSET('1050LAPTOP'!I$1,$A$4-1+$A$1,0) -> 0 | W5: =OFFSET('1050LAPTOP'!J$1,$A$4-1+$A$1,0) -> 0 | AA5: =Q5/Q$3 -> 0 | AB5: =R5/R$3 -> 0 | AC5: =S5/S$3 -> 0 | AD5: =T5/T$3 -> 0 | AE5: =U5/U$3 -> 0 | AF5: =V5/V$3 -> 0 | AG5: =W5/W$3 -> 0
A6: 4 | B6: =OFFSET('1050LAPTOP'!$C$1,A6-1,0) -> CUDA Time | C6: Matrix ACO | D6: МО | E6: =OFFSET('1050LAPTOP'!D$1,$A6-1,0) -> 3230.6196 | F6: =OFFSET('1050LAPTOP'!E$1,$A6-1,0) -> 8165.289 | G6: =OFFSET('1050LAPTOP'!F$1,$A6-1,0) -> 30570.496 | H6: =OFFSET('1050LAPTOP'!G$1,$A6-1,0) -> 118797.04 | I6: =OFFSET('1050LAPTOP'!H$1,$A6-1,0) -> 0 | J6: =OFFSET('1050LAPTOP'!I$1,$A6-1,0) -> 0 | K6: =OFFSET('1050LAPTOP'!J$1,$A6-1,0) -> 0 | N6: 768 | O6: i5-9400F + 1050 Ti | P6: МО | Q6: =OFFSET('1050COMP'!D$1,$A$4-1,0) -> 28.121576 | R6: =OFFSET('1050COMP'!E$1,$A$4-1,0) -> 20.16201 | S6: =OFFSET('1050COMP'!F$1,$A$4-1,0) -> 15.655456 | T6: =OFFSET('1050COMP'!G$1,$A$4-1,0) -> 11.975468 | U6: =OFFSET('1050COMP'!H$1,$A$4-1,0) -> 14.06894 | V6: =OFFSET('1050COMP'!I$1,$A$4-1,0) -> 12.370853 | W6: =OFFSET('1050COMP'!J$1,$A$4-1,0) -> #DIV/0!
D7: ДИ | E7: =OFFSET('1050LAPTOP'!D$1,$A6-1+$A$1,0) -> 1125.084 | F7: =OFFSET('1050LAPTOP'!E$1,$A6-1+$A$1,0) -> 136.09953 | G7: =OFFSET('1050LAPTOP'!F$1,$A6-1+$A$1,0) -> 572.23754 | H7: =OFFSET('1050LAPTOP'!G$1,$A6-1+$A$1,0) -> 274.45102 | I7: =OFFSET('1050LAPTOP'!H$1,$A6-1+$A$1,0) -> 296.30706 | J7: =OFFSET('1050LAPTOP'!I$1,$A6-1+$A$1,0) -> 2317.0873 | K7: =OFFSET('1050LAPTOP'!J$1,$A6-1+$A$1,0) -> 0 | P7: ДИ | Q7: =OFFSET('1050COMP'!D$1,$A$4-1+$A$1,0) -> 0 | R7: =OFFSET('1050COMP'!E$1,$A$4-1+$A$1,0) -> 0 | S7: =OFFSET('1050COMP'!F$1,$A$4-1+$A$1,0) -> 0 | T7: =OFFSET('1050COMP'!G$1,$A$4-1+$A$1,0) -> 0 | U7: =OFFSET('1050COMP'!H$1,$A$4-1+$A$1,0) -> 0 | V7: =OFFSET('1050COMP'!I$1,$A$4-1+$A$1,0) -> 0 | W7: =OFFSET('1050COMP'!J$1,$A$4-1+$A$1,0) -> 0 | AA7: =Q7/Q$3 -> 0 | AB7: =R7/R$3 -> 0 | AC7: =S7/S$3 -> 0 | AD7: =T7/T$3 -> 0 | AE7: =U7/U$3 -> 0 | AF7: =V7/V$3 -> 0 | AG7: =W7/W$3 -> 0
A8: 5 | B8: =OFFSET('1050LAPTOP'!$C$1,A8-1,0) -> CUDA ant | C8: Matrix ACO + OMP | D8: МО | E8: =OFFSET('1050LAPTOP'!D$1,$A8-1,0) -> 1112.299 | F8: =OFFSET('1050LAPTOP'!E$1,$A8-1,0) -> 1566.9034 | G8: =OFFSET('1050LAPTOP'!F$1,$A8-1,0) -> 2500.6766 | H8: =OFFSET('1050LAPTOP'!G$1,$A8-1,0) -> 5049.3438 | I8: =OFFSET('1050LAPTOP'!H$1,$A8-1,0) -> 9900.7614 | J8: =OFFSET('1050LAPTOP'!I$1,$A8-1,0) -> 19017.788 | K8: =OFFSET('1050LAPTOP'!J$1,$A8-1,0) -> 38230.252 | N8: 3840 | O8: i5-12450H + 3060 Laptop | P8: МО | Q8: =OFFSET('3060LAPTOP'!D$1,$A$4-1,0) -> 16.463778 | R8: =OFFSET('3060LAPTOP'!E$1,$A$4-1,0) -> 10.364808 | S8: =OFFSET('3060LAPTOP'!F$1,$A$4-1,0) -> 7.5058357 | T8: =OFFSET('3060LAPTOP'!G$1,$A$4-1,0) -> 6.0141119 | U8: =OFFSET('3060LAPTOP'!H$1,$A$4-1,0) -> 5.444361 | V8: =OFFSET('3060LAPTOP'!I$1,$A$4-1,0) -> 5.0426147 | W8: =OFFSET('3060LAPTOP'!J$1,$A$4-1,0) -> 0
D9: ДИ | E9: =OFFSET('1050LAPTOP'!D$1,$A8-1+$A$1,0) -> 1160.0956 | F9: =OFFSET('1050LAPTOP'!E$1,$A8-1+$A$1,0) -> 1544.2069 | G9: =OFFSET('1050LAPTOP'!F$1,$A8-1+$A$1,0) -> 336.66432 | H9: =OFFSET('1050LAPTOP'!G$1,$A8-1+$A$1,0) -> 419.13916 | I9: =OFFSET('1050LAPTOP'!H$1,$A8-1+$A$1,0) -> 602.74156 | J9: =OFFSET('1050LAPTOP'!I$1,$A8-1+$A$1,0) -> 2990.9431 | K9: =OFFSET('1050LAPTOP'!J$1,$A8-1+$A$1,0) -> 20096.162 | P9: ДИ | Q9: =OFFSET('3060LAPTOP'!D$1,$A$4-1+$A$1,0) -> 0 | R9: =OFFSET('3060LAPTOP'!E$1,$A$4-1+$A$1,0) -> 108.8113 | S9: =OFFSET('3060LAPTOP'!F$1,$A$4-1+$A$1,0) -> 317.37808 | T9: =OFFSET('3060LAPTOP'!G$1,$A$4-1+$A$1,0) -> 730.1457 | U9: =OFFSET('3060LAPTOP'!H$1,$A$4-1+$A$1,0) -> 124595.32 | V9: =OFFSET('3060LAPTOP'!I$1,$A$4-1+$A$1,0) -> 18364.408 | W9: =OFFSET('3060LAPTOP'!J$1,$A$4-1+$A$1,0) -> 36667.405 | AA9: =Q9/Q$3 -> 0 | AB9: =R9/R$3 -> 1.2953726 | AC9: =S9/S$3 -> 1.8891552 | AD9: =T9/T$3 -> 2.1730527 | AE9: =U9/U$3 -> 185.40971 | AF9: =V9/V$3 -> 13.663994 | AG9: =W9/W$3 -> 13.641148
A10: 6 | B10: =OFFSET('1050LAPTOP'!$C$1,A10-1,0) -> CUDA ant par | C10: Transp Matrix ACO | D10: МО | E10: =OFFSET('1050LAPTOP'!D$1,$A10-1,0) -> 1105.3332 | F10: =OFFSET('1050LAPTOP'!E$1,$A10-1,0) -> 1534.082 | G10: =OFFSET('1050LAPTOP'!F$1,$A10-1,0) -> 2406.023 | H10: =OFFSET('1050LAPTOP'!G$1,$A10-1,0) -> 4137.362 | I10: =OFFSET('1050LAPTOP'!H$1,$A10-1,0) -> 7671.3552 | J10: =OFFSET('1050LAPTOP'!I$1,$A10-1,0) -> 14430.712 | K10: =OFFSET('1050LAPTOP'!J$1,$A10-1,0) -> 28317.03 | N10: 3584 | O10: i5-13600K + 3060 | P10: МО | Q10: =OFFSET('3060COMP Kaf'!D$1,$A$4-1,0) -> 17.550789 | R10: =OFFSET('3060COMP Kaf'!E$1,$A$4-1,0) -> 11.310579 | S10: =OFFSET('3060COMP Kaf'!F$1,$A$4-1,0) -> 7.7968905 | T10: =OFFSET('3060COMP Kaf'!G$1,$A$4-1,0) -> 6.2520815 | U10: =OFFSET('3060COMP Kaf'!H$1,$A$4-1,0) -> 5.9163143 | V10: =OFFSET('3060COMP Kaf'!I$1,$A$4-1,0) -> 5.2853024 | W10: =OFFSET('3060COMP Kaf'!J$1,$A$4-1,0) -> #DIV/0!
D11: ДИ | E11: =OFFSET('1050LAPTOP'!D$1,$A10-1+$A$1,0) -> #DIV/0! | F11: =OFFSET('1050LAPTOP'!E$1,$A10-1+$A$1,0) -> 633.42138 | G11: =OFFSET('1050LAPTOP'!F$1,$A10-1+$A$1,0) -> 330.30755 | H11: =OFFSET('1050LAPTOP'!G$1,$A10-1+$A$1,0) -> 301.94667 | I11: =OFFSET('1050LAPTOP'!H$1,$A10-1+$A$1,0) -> 4014.3246 | J11: =OFFSET('1050LAPTOP'!I$1,$A10-1+$A$1,0) -> 5734.0441 | K11: =OFFSET('1050LAPTOP'!J$1,$A10-1+$A$1,0) -> 1545.8799 | P11: ДИ | Q11: =OFFSET('3060COMP Kaf'!D$1,$A$4-1+$A$1,0) -> 0 | R11: =OFFSET('3060COMP Kaf'!E$1,$A$4-1+$A$1,0) -> 39.598018 | S11: =OFFSET('3060COMP Kaf'!F$1,$A$4-1+$A$1,0) -> 39.503278 | T11: =OFFSET('3060COMP Kaf'!G$1,$A$4-1+$A$1,0) -> 71.002016 | U11: =OFFSET('3060COMP Kaf'!H$1,$A$4-1+$A$1,0) -> 202.09293 | V11: =OFFSET('3060COMP Kaf'!I$1,$A$4-1+$A$1,0) -> 499.80582 | W11: =OFFSET('3060COMP Kaf'!J$1,$A$4-1+$A$1,0) -> 727.92469 | AA11: =Q11/Q$3 -> 0 | AB11: =R11/R$3 -> 0.47140498 | AC11: =S11/S$3 -> 0.23513856 | AD11: =T11/T$3 -> 0.21131552 | AE11: =U11/U$3 -> 0.30073353 | AF11: =V11/V$3 -> 0.37187933 | AG11: =W11/W$3 -> 0.27080531
A12: 7 | B12: =OFFSET('1050LAPTOP'!$C$1,A12-1,0) -> CUDA opt | C12: Transp Matrix ACO + AVX | D12: МО | E12: =OFFSET('1050LAPTOP'!D$1,$A12-1,0) -> 3244.532 | F12: =OFFSET('1050LAPTOP'!E$1,$A12-1,0) -> 8200.7432 | G12: =OFFSET('1050LAPTOP'!F$1,$A12-1,0) -> 30655.228 | H12: =OFFSET('1050LAPTOP'!G$1,$A12-1,0) -> 119025.24 | I12: =OFFSET('1050LAPTOP'!H$1,$A12-1,0) -> 0 | J12: =OFFSET('1050LAPTOP'!I$1,$A12-1,0) -> 0 | K12: =OFFSET('1050LAPTOP'!J$1,$A12-1,0) -> 0 | N12: 4352 | O12: AMD Ryzen 5 7500F 6 + 4060TI | P12: МО | Q12: =OFFSET('4060COMP'!D$1,$A$4-1,0) -> 12.092298 | R12: =OFFSET('4060COMP'!E$1,$A$4-1,0) -> 7.5542731 | S12: =OFFSET('4060COMP'!F$1,$A$4-1,0) -> 5.3284601 | T12: =OFFSET('4060COMP'!G$1,$A$4-1,0) -> 4.2659202 | U12: =OFFSET('4060COMP'!H$1,$A$4-1,0) -> 3.7373798 | V12: =OFFSET('4060COMP'!I$1,$A$4-1,0) -> 3.4747632 | W12: =OFFSET('4060COMP'!J$1,$A$4-1,0) -> 0
D13: ДИ | E13: =OFFSET('1050LAPTOP'!D$1,$A12-1+$A$1,0) -> 322.78392 | F13: =OFFSET('1050LAPTOP'!E$1,$A12-1+$A$1,0) -> 239.33621 | G13: =OFFSET('1050LAPTOP'!F$1,$A12-1+$A$1,0) -> 363.12767 | H13: =OFFSET('1050LAPTOP'!G$1,$A12-1+$A$1,0) -> 682.78439 | I13: =OFFSET('1050LAPTOP'!H$1,$A12-1+$A$1,0) -> 1087793.1 | J13: =OFFSET('1050LAPTOP'!I$1,$A12-1+$A$1,0) -> 626616.7 | K13: =OFFSET('1050LAPTOP'!J$1,$A12-1+$A$1,0) -> 20370.716 | P13: ДИ | Q13: =OFFSET('4060COMP'!D$1,$A$4-1+$A$1,0) -> 0 | R13: =OFFSET('4060COMP'!E$1,$A$4-1+$A$1,0) -> 259.53063 | S13: =OFFSET('4060COMP'!F$1,$A$4-1+$A$1,0) -> 616.71731 | T13: =OFFSET('4060COMP'!G$1,$A$4-1+$A$1,0) -> 3560.7066 | U13: =OFFSET('4060COMP'!H$1,$A$4-1+$A$1,0) -> 57100.636 | V13: =OFFSET('4060COMP'!I$1,$A$4-1+$A$1,0) -> 13831.197 | W13: =OFFSET('4060COMP'!J$1,$A$4-1+$A$1,0) -> 19720658 | AA13: =Q13/Q$3 -> 0 | AB13: =R13/R$3 -> 3.0896503 | AC13: =S13/S$3 -> 3.6709364 | AD13: =T13/T$3 -> 10.597341 | AE13: =U13/U$3 -> 84.971184 | AF13: =V13/V$3 -> 10.291069 | AG13: =W13/W$3 -> 7336.5544
A14: 8 | B14: =OFFSET('1050LAPTOP'!$C$1,A14-1,0) -> CUDA opt ant | C14: Transp Matrix ACO + AVX + OPM | D14: МО | E14: =OFFSET('1050LAPTOP'!D$1,$A14-1,0) -> 1111.0204 | F14: =OFFSET('1050LAPTOP'!E$1,$A14-1,0) -> 1562.7406 | G14: =OFFSET('1050LAPTOP'!F$1,$A14-1,0) -> 2477.3718 | H14: =OFFSET('1050LAPTOP'!G$1,$A14-1,0) -> 5021.7652 | I14: =OFFSET('1050LAPTOP'!H$1,$A14-1,0) -> 9885.4504 | J14: =OFFSET('1050LAPTOP'!I$1,$A14-1,0) -> 19083.762 | K14: =OFFSET('1050LAPTOP'!J$1,$A14-1,0) -> 38204.806 | N14: 1024 | O14: Jetson Orin | P14: МО | Q14: =OFFSET(JETSON!D$1,$A$4-1,0) -> 10.506158 | R14: =OFFSET(JETSON!E$1,$A$4-1,0) -> 6.8151676 | S14: =OFFSET(JETSON!F$1,$A$4-1,0) -> 4.9888018 | T14: =OFFSET(JETSON!G$1,$A$4-1,0) -> 4.2645345 | U14: =OFFSET(JETSON!H$1,$A$4-1,0) -> 4.205383 | V14: =OFFSET(JETSON!I$1,$A$4-1,0) -> 3.8692 | W14: =OFFSET(JETSON!J$1,$A$4-1,0) -> 0
D15: ДИ | E15: =OFFSET('1050LAPTOP'!D$1,$A14-1+$A$1,0) -> 263.99015 | F15: =OFFSET('1050LAPTOP'!E$1,$A14-1+$A$1,0) -> 131.70371 | G15: =OFFSET('1050LAPTOP'!F$1,$A14-1+$A$1,0) -> 346.02492 | H15: =OFFSET('1050LAPTOP'!G$1,$A14-1+$A$1,0) -> 1621.1023 | I15: =OFFSET('1050LAPTOP'!H$1,$A14-1+$A$1,0) -> 530.49904 | J15: =OFFSET('1050LAPTOP'!I$1,$A14-1+$A$1,0) -> 664.23416 | K15: =OFFSET('1050LAPTOP'!J$1,$A14-1+$A$1,0) -> 753568.69 | P15: ДИ | Q15: =OFFSET(JETSON!D$1,$A$4-1+$A$1,0) -> 0 | R15: =OFFSET(JETSON!E$1,$A$4-1+$A$1,0) -> 259.53063 | S15: =OFFSET(JETSON!F$1,$A$4-1+$A$1,0) -> 616.71731 | T15: =OFFSET(JETSON!G$1,$A$4-1+$A$1,0) -> 3560.7066 | U15: =OFFSET(JETSON!H$1,$A$4-1+$A$1,0) -> 57100.636 | V15: =OFFSET(JETSON!I$1,$A$4-1+$A$1,0) -> 13831.197 | W15: =OFFSET(JETSON!J$1,$A$4-1+$A$1,0) -> 19720658
A16: 12 | B16: =OFFSET('1050LAPTOP'!$C$1,A16-1,0) -> CUDA opt_one_GPU ant local | D16: МО | E16: =OFFSET('1050LAPTOP'!D$1,$A16-1,0) -> 1469.1822 | F16: =OFFSET('1050LAPTOP'!E$1,$A16-1,0) -> 2883.3024 | G16: =OFFSET('1050LAPTOP'!F$1,$A16-1,0) -> 5688.8598 | H16: =OFFSET('1050LAPTOP'!G$1,$A16-1,0) -> 11485.506 | I16: =OFFSET('1050LAPTOP'!H$1,$A16-1,0) -> 23062.244 | J16: =OFFSET('1050LAPTOP'!I$1,$A16-1,0) -> 46032.586 | K16: =OFFSET('1050LAPTOP'!J$1,$A16-1,0) -> 92249.118 | N16: 5120 | O16: Tesla V100 | P16: МО | Q16: =OFFSET(REA!D$1,$A$4-1,0) -> 3.3409729 | R16: =OFFSET(REA!E$1,$A$4-1,0) -> 2.118965 | S16: =OFFSET(REA!F$1,$A$4-1,0) -> 1.5079782 | T16: =OFFSET(REA!G$1,$A$4-1,0) -> 1.2961796 | U16: =OFFSET(REA!H$1,$A$4-1,0) -> 1.3406399 | V16: =OFFSET(REA!I$1,$A$4-1,0) -> 1.2379494 | W16: =OFFSET(REA!J$1,$A$4-1,0) -> 0
D17: ДИ | E17: =OFFSET('1050LAPTOP'!D$1,$A16-1+$A$1,0) -> 2 | F17: =OFFSET('1050LAPTOP'!E$1,$A16-1+$A$1,0) -> 4 | G17: =OFFSET('1050LAPTOP'!F$1,$A16-1+$A$1,0) -> 8 | H17: =OFFSET('1050LAPTOP'!G$1,$A16-1+$A$1,0) -> 16 | I17: =OFFSET('1050LAPTOP'!H$1,$A16-1+$A$1,0) -> 32 | J17: =OFFSET('1050LAPTOP'!I$1,$A16-1+$A$1,0) -> 64 | K17: =OFFSET('1050LAPTOP'!J$1,$A16-1+$A$1,0) -> 128 | P17: ДИ | Q17: =OFFSET(REA!D$1,$A$4-1+$A$1,0) -> 0 | R17: =OFFSET(REA!E$1,$A$4-1+$A$1,0) -> 113.63023 | S17: =OFFSET(REA!F$1,$A$4-1+$A$1,0) -> 1100.334 | T17: =OFFSET(REA!G$1,$A$4-1+$A$1,0) -> 975.64003 | U17: =OFFSET(REA!H$1,$A$4-1+$A$1,0) -> 64976.078 | V17: =OFFSET(REA!I$1,$A$4-1+$A$1,0) -> 12178.92 | W17: =OFFSET(REA!J$1,$A$4-1+$A$1,0) -> 19055708
A18: 13 | B18: =OFFSET('1050LAPTOP'!$C$1,A18-1,0) -> CUDA Const | D18: МО | E18: =OFFSET('1050LAPTOP'!D$1,$A18-1,0) -> 3190.673 | F18: =OFFSET('1050LAPTOP'!E$1,$A18-1,0) -> 8273.887 | G18: =OFFSET('1050LAPTOP'!F$1,$A18-1,0) -> 30350.504 | H18: =OFFSET('1050LAPTOP'!G$1,$A18-1,0) -> 119486.92 | I18: =OFFSET('1050LAPTOP'!H$1,$A18-1,0) -> 0 | J18: =OFFSET('1050LAPTOP'!I$1,$A18-1,0) -> 0 | K18: =OFFSET('1050LAPTOP'!J$1,$A18-1,0) -> 0
D19: ДИ | E19: =OFFSET('1050LAPTOP'!D$1,$A18-1+$A$1,0) -> 42 | F19: =OFFSET('1050LAPTOP'!E$1,$A18-1+$A$1,0) -> 84 | G19: =OFFSET('1050LAPTOP'!F$1,$A18-1+$A$1,0) -> 168 | H19: =OFFSET('1050LAPTOP'!G$1,$A18-1+$A$1,0) -> 336 | I19: =OFFSET('1050LAPTOP'!H$1,$A18-1+$A$1,0) -> 672 | J19: =OFFSET('1050LAPTOP'!I$1,$A18-1+$A$1,0) -> 1344 | K19: =OFFSET('1050LAPTOP'!J$1,$A18-1+$A$1,0) -> 2688
A20: 3 | B20: =OFFSET('1050LAPTOP'!$C$1,A20-1,0) -> Classic ACO | C20: Classic ACO | D20: МО | E20: =OFFSET('1050COMP'!D$1,$A20-1,0) -> 13775.68 | F20: =OFFSET('1050COMP'!E$1,$A20-1,0) -> 24819.016 | G20: =OFFSET('1050COMP'!F$1,$A20-1,0) -> 47399.626 | H20: =OFFSET('1050COMP'!G$1,$A20-1,0) -> 96405.03 | I20: =OFFSET('1050COMP'!H$1,$A20-1,0) -> 197567.46 | J20: =OFFSET('1050COMP'!I$1,$A20-1,0) -> 376437.82 | K20: =OFFSET('1050COMP'!J$1,$A20-1,0) -> 762594.84
D21: ДИ | E21: =OFFSET('1050COMP'!D$1,$A20-1+$A$1,0) -> 167.51601 | F21: =OFFSET('1050COMP'!E$1,$A20-1+$A$1,0) -> 558.86906 | G21: =OFFSET('1050COMP'!F$1,$A20-1+$A$1,0) -> 333.57509 | H21: =OFFSET('1050COMP'!G$1,$A20-1+$A$1,0) -> 2851.7375 | I21: =OFFSET('1050COMP'!H$1,$A20-1+$A$1,0) -> 42269.478 | J21: =OFFSET('1050COMP'!I$1,$A20-1+$A$1,0) -> 133384.94 | K21: =OFFSET('1050COMP'!J$1,$A20-1+$A$1,0) -> 120448.13
A22: 4 | B22: =OFFSET('1050LAPTOP'!$C$1,A22-1,0) -> CUDA Time | C22: Matrix ACO | D22: МО | E22: =OFFSET('1050COMP'!D$1,$A22-1,0) -> 3659.4322 | F22: =OFFSET('1050COMP'!E$1,$A22-1,0) -> 9339.9226 | G22: =OFFSET('1050COMP'!F$1,$A22-1,0) -> 35373.252 | H22: =OFFSET('1050COMP'!G$1,$A22-1,0) -> 133771.86 | I22: =OFFSET('1050COMP'!H$1,$A22-1,0) -> 0 | J22: =OFFSET('1050COMP'!I$1,$A22-1,0) -> 0 | K22: =OFFSET('1050COMP'!J$1,$A22-1,0) -> 0
D23: ДИ | E23: =OFFSET('1050COMP'!D$1,$A22-1+$A$1,0) -> 175.77523 | F23: =OFFSET('1050COMP'!E$1,$A22-1+$A$1,0) -> 1101.8355 | G23: =OFFSET('1050COMP'!F$1,$A22-1+$A$1,0) -> 358.98442 | H23: =OFFSET('1050COMP'!G$1,$A22-1+$A$1,0) -> 2861.326 | I23: =OFFSET('1050COMP'!H$1,$A22-1+$A$1,0) -> 10029.955 | J23: =OFFSET('1050COMP'!I$1,$A22-1+$A$1,0) -> 60318.787 | K23: =OFFSET('1050COMP'!J$1,$A22-1+$A$1,0) -> 0
A24: 5 | B24: =OFFSET('1050LAPTOP'!$C$1,A24-1,0) -> CUDA ant | C24: Matrix ACO + OMP | D24: МО | E24: =OFFSET('1050COMP'!D$1,$A24-1,0) -> 1205.171 | F24: =OFFSET('1050COMP'!E$1,$A24-1,0) -> 1720.4454 | G24: =OFFSET('1050COMP'!F$1,$A24-1,0) -> 2777.4122 | H24: =OFFSET('1050COMP'!G$1,$A24-1,0) -> 5562.0442 | I24: =OFFSET('1050COMP'!H$1,$A24-1,0) -> 9529.4334 | J24: =OFFSET('1050COMP'!I$1,$A24-1,0) -> 22207.712 | K24: =OFFSET('1050COMP'!J$1,$A24-1,0) -> 38945.372
D25: ДИ | E25: =OFFSET('1050COMP'!D$1,$A24-1+$A$1,0) -> 495.63241 | F25: =OFFSET('1050COMP'!E$1,$A24-1+$A$1,0) -> 96.572213 | G25: =OFFSET('1050COMP'!F$1,$A24-1+$A$1,0) -> 714.41987 | H25: =OFFSET('1050COMP'!G$1,$A24-1+$A$1,0) -> 3748.9964 | I25: =OFFSET('1050COMP'!H$1,$A24-1+$A$1,0) -> 20129.773 | J25: =OFFSET('1050COMP'!I$1,$A24-1+$A$1,0) -> 2800422.8 | K25: =OFFSET('1050COMP'!J$1,$A24-1+$A$1,0) -> 220418.78
A26: 6 | B26: =OFFSET('1050LAPTOP'!$C$1,A26-1,0) -> CUDA ant par | C26: Transp Matrix ACO | D26: МО | E26: =OFFSET('1050COMP'!D$1,$A26-1,0) -> 1193.4462 | F26: =OFFSET('1050COMP'!E$1,$A26-1,0) -> 1718.7074 | G26: =OFFSET('1050COMP'!F$1,$A26-1,0) -> 2621.5022 | H26: =OFFSET('1050COMP'!G$1,$A26-1,0) -> 4581.1512 | I26: =OFFSET('1050COMP'!H$1,$A26-1,0) -> 7371.8842 | J26: =OFFSET('1050COMP'!I$1,$A26-1,0) -> 15329.056 | K26: =OFFSET('1050COMP'!J$1,$A26-1,0) -> 29967.086
D27: ДИ | E27: =OFFSET('1050COMP'!D$1,$A26-1+$A$1,0) -> #DIV/0! | F27: =OFFSET('1050COMP'!E$1,$A26-1+$A$1,0) -> 440.22115 | G27: =OFFSET('1050COMP'!F$1,$A26-1+$A$1,0) -> 1116.0679 | H27: =OFFSET('1050COMP'!G$1,$A26-1+$A$1,0) -> 7097.6774 | I27: =OFFSET('1050COMP'!H$1,$A26-1+$A$1,0) -> 6993.6841 | J27: =OFFSET('1050COMP'!I$1,$A26-1+$A$1,0) -> 52919.376 | K27: =OFFSET('1050COMP'!J$1,$A26-1+$A$1,0) -> 7423274.5
A28: 7 | B28: =OFFSET('1050LAPTOP'!$C$1,A28-1,0) -> CUDA opt | C28: Transp Matrix ACO + AVX | D28: МО | E28: =OFFSET('1050COMP'!D$1,$A28-1,0) -> 3604.9408 | F28: =OFFSET('1050COMP'!E$1,$A28-1,0) -> 9478.3754 | G28: =OFFSET('1050COMP'!F$1,$A28-1,0) -> 35015.916 | H28: =OFFSET('1050COMP'!G$1,$A28-1,0) -> 133849.2 | I28: =OFFSET('1050COMP'!H$1,$A28-1,0) -> 0 | J28: =OFFSET('1050COMP'!I$1,$A28-1,0) -> 0 | K28: =OFFSET('1050COMP'!J$1,$A28-1,0) -> 0
D29: ДИ | E29: =OFFSET('1050COMP'!D$1,$A28-1+$A$1,0) -> 919.66779 | F29: =OFFSET('1050COMP'!E$1,$A28-1+$A$1,0) -> 1645.8781 | G29: =OFFSET('1050COMP'!F$1,$A28-1+$A$1,0) -> 20295.817 | H29: =OFFSET('1050COMP'!G$1,$A28-1+$A$1,0) -> 7997.4668 | I29: =OFFSET('1050COMP'!H$1,$A28-1+$A$1,0) -> 4124999.4 | J29: =OFFSET('1050COMP'!I$1,$A28-1+$A$1,0) -> 2418842.9 | K29: =OFFSET('1050COMP'!J$1,$A28-1+$A$1,0) -> 3236315.9
A30: 8 | B30: =OFFSET('1050LAPTOP'!$C$1,A30-1,0) -> CUDA opt ant | C30: Transp Matrix ACO + AVX + OPM | D30: МО | E30: =OFFSET('1050COMP'!D$1,$A30-1,0) -> 1181.9466 | F30: =OFFSET('1050COMP'!E$1,$A30-1,0) -> 1592.6038 | G30: =OFFSET('1050COMP'!F$1,$A30-1,0) -> 2740.828 | H30: =OFFSET('1050COMP'!G$1,$A30-1,0) -> 5504.5884 | I30: =OFFSET('1050COMP'!H$1,$A30-1,0) -> 11476.146 | J30: =OFFSET('1050COMP'!I$1,$A30-1,0) -> 21936.874 | K30: =OFFSET('1050COMP'!J$1,$A30-1,0) -> 42614.86
D31: ДИ | E31: =OFFSET('1050COMP'!D$1,$A30-1+$A$1,0) -> 273.95643 | F31: =OFFSET('1050COMP'!E$1,$A30-1+$A$1,0) -> 118.83993 | G31: =OFFSET('1050COMP'!F$1,$A30-1+$A$1,0) -> 391.80991 | H31: =OFFSET('1050COMP'!G$1,$A30-1+$A$1,0) -> 484.12666 | I31: =OFFSET('1050COMP'!H$1,$A30-1+$A$1,0) -> 55338.3 | J31: =OFFSET('1050COMP'!I$1,$A30-1+$A$1,0) -> 124228.53 | K31: =OFFSET('1050COMP'!J$1,$A30-1+$A$1,0) -> 225953.76
A32: 12 | B32: =OFFSET('1050LAPTOP'!$C$1,A32-1,0) -> CUDA opt_one_GPU ant local | D32: МО | E32: =OFFSET('1050COMP'!D$1,$A32-1,0) -> 1703.0858 | F32: =OFFSET('1050COMP'!E$1,$A32-1,0) -> 3238.8466 | G32: =OFFSET('1050COMP'!F$1,$A32-1,0) -> 6387.8326 | H32: =OFFSET('1050COMP'!G$1,$A32-1,0) -> 11126.67 | I32: =OFFSET('1050COMP'!H$1,$A32-1,0) -> 24205.906 | J32: =OFFSET('1050COMP'!I$1,$A32-1,0) -> 51402.416 | K32: =OFFSET('1050COMP'!J$1,$A32-1,0) -> 189955.16
D33: ДИ | E33: =OFFSET('1050COMP'!D$1,$A32-1+$A$1,0) -> 2 | F33: =OFFSET('1050COMP'!E$1,$A32-1+$A$1,0) -> 4 | G33: =OFFSET('1050COMP'!F$1,$A32-1+$A$1,0) -> 8 | H33: =OFFSET('1050COMP'!G$1,$A32-1+$A$1,0) -> 16 | I33: =OFFSET('1050COMP'!H$1,$A32-1+$A$1,0) -> 32 | J33: =OFFSET('1050COMP'!I$1,$A32-1+$A$1,0) -> 64 | K33: =OFFSET('1050COMP'!J$1,$A32-1+$A$1,0) -> 128
A34: 13 | B34: =OFFSET('1050LAPTOP'!$C$1,A34-1,0) -> CUDA Const | D34: МО | E34: =OFFSET('1050COMP'!D$1,$A34-1,0) -> 3582.0978 | F34: =OFFSET('1050COMP'!E$1,$A34-1,0) -> 9321.176 | G34: =OFFSET('1050COMP'!F$1,$A34-1,0) -> 35222.21 | H34: =OFFSET('1050COMP'!G$1,$A34-1,0) -> 140931.94 | I34: =OFFSET('1050COMP'!H$1,$A34-1,0) -> 0 | J34: =OFFSET('1050COMP'!I$1,$A34-1,0) -> 0 | K34: =OFFSET('1050COMP'!J$1,$A34-1,0) -> #DIV/0!
D35: ДИ | E35: =OFFSET('1050COMP'!D$1,$A34-1+$A$1,0) -> 42 | F35: =OFFSET('1050COMP'!E$1,$A34-1+$A$1,0) -> 84 | G35: =OFFSET('1050COMP'!F$1,$A34-1+$A$1,0) -> 168 | H35: =OFFSET('1050COMP'!G$1,$A34-1+$A$1,0) -> 336 | I35: =OFFSET('1050COMP'!H$1,$A34-1+$A$1,0) -> 672 | J35: =OFFSET('1050COMP'!I$1,$A34-1+$A$1,0) -> 1344 | K35: =OFFSET('1050COMP'!J$1,$A34-1+$A$1,0) -> 2688
A36: 3 | B36: =OFFSET('1050LAPTOP'!$C$1,A36-1,0) -> Classic ACO | C36: Classic ACO | D36: МО | E36: =OFFSET('3060LAPTOP'!D$1,$A36-1,0) -> 6732.0454 | F36: =OFFSET('3060LAPTOP'!E$1,$A36-1,0) -> 12795.57 | G36: =OFFSET('3060LAPTOP'!F$1,$A36-1,0) -> 24112.532 | H36: =OFFSET('3060LAPTOP'!G$1,$A36-1,0) -> 46059.344 | I36: =OFFSET('3060LAPTOP'!H$1,$A36-1,0) -> 91907.946 | J36: =OFFSET('3060LAPTOP'!I$1,$A36-1,0) -> 184408.08 | K36: =OFFSET('3060LAPTOP'!J$1,$A36-1,0) -> 367570.34
D37: ДИ | E37: =OFFSET('3060LAPTOP'!D$1,$A36-1+$A$1,0) -> 654.08437 | F37: =OFFSET('3060LAPTOP'!E$1,$A36-1+$A$1,0) -> 189.00614 | G37: =OFFSET('3060LAPTOP'!F$1,$A36-1+$A$1,0) -> 410.69644 | H37: =OFFSET('3060LAPTOP'!G$1,$A36-1+$A$1,0) -> 192.55158 | I37: =OFFSET('3060LAPTOP'!H$1,$A36-1+$A$1,0) -> 1097.4957 | J37: =OFFSET('3060LAPTOP'!I$1,$A36-1+$A$1,0) -> 1697.1609 | K37: =OFFSET('3060LAPTOP'!J$1,$A36-1+$A$1,0) -> 2883.1276
A38: 4 | B38: =OFFSET('1050LAPTOP'!$C$1,A38-1,0) -> CUDA Time | C38: Matrix ACO | D38: МО | E38: =OFFSET('3060LAPTOP'!D$1,$A38-1,0) -> 602.02756 | F38: =OFFSET('3060LAPTOP'!E$1,$A38-1,0) -> 916.12924 | G38: =OFFSET('3060LAPTOP'!F$1,$A38-1,0) -> 2494.2466 | H38: =OFFSET('3060LAPTOP'!G$1,$A38-1,0) -> 7974.9374 | I38: =OFFSET('3060LAPTOP'!H$1,$A38-1,0) -> 0 | J38: =OFFSET('3060LAPTOP'!I$1,$A38-1,0) -> 0 | K38: =OFFSET('3060LAPTOP'!J$1,$A38-1,0) -> 0
D39: ДИ | E39: =OFFSET('3060LAPTOP'!D$1,$A38-1+$A$1,0) -> 335.21385 | F39: =OFFSET('3060LAPTOP'!E$1,$A38-1+$A$1,0) -> 217.73231 | G39: =OFFSET('3060LAPTOP'!F$1,$A38-1+$A$1,0) -> 420.80216 | H39: =OFFSET('3060LAPTOP'!G$1,$A38-1+$A$1,0) -> 620.64085 | I39: =OFFSET('3060LAPTOP'!H$1,$A38-1+$A$1,0) -> 1051.4756 | J39: =OFFSET('3060LAPTOP'!I$1,$A38-1+$A$1,0) -> 954.60624 | K39: =OFFSET('3060LAPTOP'!J$1,$A38-1+$A$1,0) -> 6787.9659
A40: 5 | B40: =OFFSET('1050LAPTOP'!$C$1,A40-1,0) -> CUDA ant | C40: Matrix ACO + OMP | D40: МО | E40: =OFFSET('3060LAPTOP'!D$1,$A40-1,0) -> 682.94254 | F40: =OFFSET('3060LAPTOP'!E$1,$A40-1,0) -> 883.29402 | G40: =OFFSET('3060LAPTOP'!F$1,$A40-1,0) -> 1272.4982 | H40: =OFFSET('3060LAPTOP'!G$1,$A40-1,0) -> 2115.9988 | I40: =OFFSET('3060LAPTOP'!H$1,$A40-1,0) -> 4199.7956 | J40: =OFFSET('3060LAPTOP'!I$1,$A40-1,0) -> 8039.9226 | K40: =OFFSET('3060LAPTOP'!J$1,$A40-1,0) -> 15961.626
...

Sheet Лист6
B1: Время на один слой
B2: Кол-во параметров | D2: 2 | E2: 4 | F2: 8 | G2: 16 | H2: 32 | I2: 64 | J2: 128
B3: Кол-во слоев | D3: 42 | E3: 84 | F3: 168 | G3: 336 | H3: 672 | I3: 1344 | J3: 2688
B4: №ПК | C4: Модификация | E4: 24819.016 | F4: 47399.626 | G4: 96405.03 | H4: 197567.46 | I4: 376437.82 | J4: 762594.84
B5: 1 | C5: Оптимальная модификация + константная память | D5: 3.2481948 | E5: 1.9694345 | F5: 1.3827494 | G5: 1.1119045 | H5: 1.0460879 | I5: 0.98114926
C6: Оптимальная модификация | D6: 3.4567848 | E6: 2.1487233 | F6: 1.5472823 | G6: 1.2777742 | H6: 1.1424396 | I6: 1.0914406 | J6: 1.0816226
B7: 2 | C7: Оптимальная модификация | D7: 11.320642 | E7: 7.2921748 | F7: 4.9514361 | G7: 4.2319589 | H7: 4.3339223 | I7: 4.0660653 | J7: 3.8898996
C8: Оптимальная модификация + константная память | D8: 10.506158 | E8: 6.8151676 | F8: 4.9888018 | G8: 4.2645345 | H8: 4.205383 | I8: 3.8692
B9: 3 | C9: AVX модификация на CPU для специального графа | D9: 6.1213733 | E9: 5.2558355 | F9: 4.8710343 | G9: 4.6119679 | H9: 4.6773801 | I9: 4.4763162 | J9: 4.4181778
C10: Оптимальная модификация | D10: 12.069419 | E10: 7.5693745 | F10: 5.3006436 | G10: 4.2725804 | H10: 3.9004244 | I10: 3.5251216 | J10: 3.3135952
B11: 4 | C11: Гетерогенная модификация с ускорением AVX для транспонированных матриц | E11: 6.6712202 | F11: 6.1012405 | G11: 6.0988774 | H11: 6.0148679 | I11: 5.7999379 | J11: 5.7420871
C12: Классическая модификация | D12: 17.611209 | E12: 11.356823 | F12: 7.9716226 | G12: 6.5702655 | H12: 5.9145568 | I12: 5.328956 | J12: 5.0635223
B13: 5 | C13: Гетерогенная модификация + глобальная память | D13: 7.5174395 | E13: 6.32883 | F13: 6.0188106 | G13: 5.8658863 | H13: 5.9742804 | I13: 5.9088244 | J13: 5.8770699
C14: Классическая модификация + глобальная память | D14: 16.56786 | E14: 10.577261 | F14: 7.5519631 | G14: 6.0176732 | H14: 5.4531393 | I14: 5.0731603 | J14: 4.8821615
B15: 6 | C15: AVX модификация на CPU для специального графа | D15: 13.942815 | E15: 13.027674 | F15: 12.621856 | G15: 12.463424 | H15: 14.070862 | I15: 14.205199 | J15: 14.514687
C16: Классическая модификация | D16: 28.415386 | E16: 20.460802 | F16: 15.60418 | G16: 13.634379 | H16: 10.970066 | I16: 11.405548 | J16: 11.148469
B17: 7 | C17: Гетерогенная модификация | D17: 14.710277 | E17: 13.397912 | F17: 12.94479 | G17: 12.804571 | H17: 12.803035 | I17: 12.692134 | J17: 12.803296
C18: Оптимальная модификация | D18: 26.263262 | E18: 18.236271 | F18: 14.151738 | G18: 12.300308 | H18: 11.403068 | I18: 10.804997 | J18: 10.535009
B22: Кол-во параметров | D22: 2 | E22: 4 | F22: 8 | G22: 16 | H22: 32 | I22: 64 | J22: 128
B23: Кол-во слоев | D23: 42 | E23: 84 | F23: 168 | G23: 336 | H23: 672 | I23: 1344 | J23: 2688
B24: №ПК | C24: Алгоритм | E24: 24819.016 | F24: 47399.626 | G24: 96405.03 | H24: 197567.46 | I24: 376437.82 | J24: 762594.84
B25: 1 | C25: CUDA opt ant Const | D25: 3.2481948 | E25: 1.9694345 | F25: 1.3827494 | G25: 1.1119045 | H25: 1.0460879 | I25: 0.98114926
C26: CUDA opt ant | D26: 3.4567848 | E26: 2.1487233 | F26: 1.5472823 | G26: 1.2777742 | H26: 1.1424396 | I26: 1.0914406 | J26: 1.0816226
B27: 2 | C27: CUDA opt ant par | D27: 11.320642 | E27: 7.2921748 | F27: 4.9514361 | G27: 4.2319589 | H27: 4.3339223 | I27: 4.0660653 | J27: 3.8898996
C28: CUDA opt ant par Const | D28: 10.506158 | E28: 6.8151676 | F28: 4.9888018 | G28: 4.2645345 | H28: 4.205383 | I28: 3.8692
B29: 3 | C29: Time non CUDA AVX add CPU time 4 | D29: 6.1213733 | E29: 5.2558355 | F29: 4.8710343 | G29: 4.6119679 | H29: 4.6773801 | I29: 4.4763162 | J29: 4.4181778
C30: CUDA opt ant par | D30: 12.069419 | E30: 7.5693745 | F30: 5.3006436 | G30: 4.2725804 | H30: 3.9004244 | I30: 3.5251216 | J30: 3.3135952
B31: 4 | C31: CUDA ant add CPU_AVX_transp | E31: 6.6712202 | F31: 6.1012405 | G31: 6.0988774 | H31: 6.0148679 | I31: 5.7999379 | J31: 5.7420871
C32: CUDA ant par | D32: 17.611209 | E32: 11.356823 | F32: 7.9716226 | G32: 6.5702655 | H32: 5.9145568 | I32: 5.328956 | J32: 5.0635223
B33: 5 | C33: CUDA ant add CPU Time global | D33: 7.5174395 | E33: 6.32883 | F33: 6.0188106 | G33: 5.8658863 | H33: 5.9742804 | I33: 5.9088244 | J33: 5.8770699
C34: CUDA ant par global | D34: 16.56786 | E34: 10.577261 | F34: 7.5519631 | G34: 6.0176732 | H34: 5.4531393 | I34: 5.0731603 | J34: 4.8821615
B35: 6 | C35: Time non CUDA AVX add CPU time 4 | D35: 13.942815 | E35: 13.027674 | F35: 12.621856 | G35: 12.463424 | H35: 14.070862 | I35: 14.205199 | J35: 14.514687
C36: CUDA ant par | D36: 28.415386 | E36: 20.460802 | F36: 15.60418 | G36: 13.634379 | H36: 10.970066 | I36: 11.405548 | J36: 11.148469
B37: 7 | C37: CUDA ant add CPU Time | D37: 14.710277 | E37: 13.397912 | F37: 12.94479 | G37: 12.804571 | H37: 12.803035 | I37: 12.692134 | J37: 12.803296
C38: CUDA opt ant par | D38: 26.263262 | E38: 18.236271 | F38: 14.151738 | G38: 12.300308 | H38: 11.403068 | I38: 10.804997 | J38: 10.535009

Sheet 1050LAPTOP
B1: 1.96 | C1: 50 | D1: 2 | E1: 4 | F1: 8 | G1: 16 | H1: 32 | I1: 64 | J1: 128 | K1: 256 | L1: 512 | M1: 8th Gen Intel Core i5-8300H 2.30 GHz (8Gb ОЗУ)
B2: МО | D2: 42 | E2: 84 | F2: 168 | G2: 336 | H2: 672 | I2: 1344 | J2: 2688 | K2: 5376 | L2: 10752
A3: 1 | C3: Classic ACO | D3: 14722.332 | E3: 27364.668 | F3: 52186.786 | G3: 103402.44 | H3: 207103.36 | I3: 410463.68 | J3: 835652.72
C4: CUDA Time | D4: 3230.6196 | E4: 8165.289 | F4: 30570.496 | G4: 118797.04
C5: CUDA ant | D5: 1112.299 | E5: 1566.9034 | F5: 2500.6766 | G5: 5049.3438 | H5: 9900.7614 | I5: 19017.788 | J5: 38230.252
C6: CUDA ant par | D6: 1105.3332 | E6: 1534.082 | F6: 2406.023 | G6: 4137.362 | H6: 7671.3552 | I6: 14430.712 | J6: 28317.03
C7: CUDA opt | D7: 3244.532 | E7: 8200.7432 | F7: 30655.228 | G7: 119025.24
C8: CUDA opt ant | D8: 1111.0204 | E8: 1562.7406 | F8: 2477.3718 | G8: 5021.7652 | H8: 9885.4504 | I8: 19083.762 | J8: 38204.806
C9: CUDA opt ant par | D9: 1103.057 | E9: 1531.8468 | F9: 2377.492 | G9: 4132.9034 | H9: 7662.8618 | I9: 14521.916 | J9: 28318.104
C10: CUDA opt_one_GPU | D10: 5423.7868 | E10: 10850.081 | F10: 22314.346 | G10: 168792.9
C11: CUDA opt_one_GPU ant | D11: 25581.912 | E11: 50984.616 | F11: 100711.2 | G11: 204126.84 | H11: 410280.3 | I11: 818514.44 | J11: 1641214.8
C12: CUDA opt_one_GPU ant local | D12: 1469.1822 | E12: 2883.3024 | F12: 5688.8598 | G12: 11485.506 | H12: 23062.244 | I12: 46032.586 | J12: 92249.118
C13: CUDA Const | D13: 3190.673 | E13: 8273.887 | F13: 30350.504 | G13: 119486.92
C14: CUDA ant Const | D14: 1105.2298 | E14: 1555.804 | F14: 2462.9948 | G14: 5043.8376 | H14: 9881.8038 | I14: 19149.42
C15: CUDA ant par Const | D15: 1098.4588 | E15: 1531.6032 | F15: 2369.2894 | G15: 4146.0518 | H15: 7643.7788 | I15: 14518.13
C16: CUDA opt Const | D16: 3214.2402 | E16: 8200.29 | F16: 30600.758 | G16: 119547.66
C17: CUDA opt ant Const | D17: 1101.6596 | E17: 1552.5856 | F17: 2461.925 | G17: 5022.8434 | H17: 9877.6114 | I17: 19134.142
C18: CUDA opt ant par Const | D18: 1099.2948 | E18: 1525.5982 | F18: 2365.5942 | G18: 4147.1374 | H18: 7643.353 | I18: 14514.672
C19: CUDA ant par global | D19: 1104.2956 | E19: 1545.4242 | F19: 2415.4076 | G19: 4158.5218 | H19: 7708.6514 | I19: 14499.326 | J19: 28467.788
C20: CUDA opt ant par global | D20: 1104.131 | E20: 1543.8896 | F20: 2386.4508 | G20: 4153.6434 | H20: 7707.5954 | I20: 14593.086 | J20: 28466.538
C21: CUDA ant add CPU Time | D21: 617.83162 | E21: 1125.4246 | F21: 2174.7248 | G21: 4302.336 | H21: 8603.6396 | I21: 17058.228 | J21: 34415.26
C22: CUDA ant add CPU Const | D22: 605.95326 | E22: 1100.7724 | F22: 2148.444 | G22: 4327.3866 | H22: 8631.0026 | I22: 17150.22
C23: CUDA ant add CPU Time global | D23: 614.67082 | E23: 1128.616 | F23: 2188.4864 | G23: 4322.1868 | H23: 8653.2058 | I23: 17085.644 | J23: 34593.732
C24: CUDA ant add CPU_AVX_transp Time | D24: 0 | E24: 1138.901 | F24: 2203.575 | G24: 4345.2346 | H24: 8611.4828 | I24: 17137.144 | J24: 34192.436
C25: CUDA ant add CPU12 | D25: 1512.212 | E25: 2659.6366 | F25: 5207.7542 | G25: 10304.526 | H25: 20485.6 | I25: 30668.098 | J25: 53579.62
C26: Time non CUDA AVX time 4 | D26: 1017.3776 | E26: 1889.2708 | F26: 3627.0554 | G26: 7084.2338 | H26: 14040.434 | I26: 27472.934 | J26: 52973.284
C27: Time non CUDA AVX add CPU time 4 | D27: 627.14738 | E27: 1153.4844 | F27: 2244.2572 | G27: 4419.377 | H27: 8817.8194 | I27: 17479.466 | J27: 35108.804
C30: 6 | D30: 2 | E30: 4 | F30: 8 | G30: 16 | H30: 32 | I30: 64 | J30: 128 | K30: 256 | L30: 512
D31: 42 | E31: 84 | F31: 168 | G31: 336 | H31: 672 | I31: 1344 | J31: 2688 | K31: 5376 | L31: 10752
C32: Classic ACO | D32: =D3/D$2 -> 350.53171 | E32: =E3/E$2 -> 325.76986 | F32: =F3/F$2 -> 310.63563 | G32: =G3/G$2 -> 307.74536 | H32: =H3/H$2 -> 308.18952 | I32: =I3/I$2 -> 305.40452 | J32: =J3/J$2 -> 310.88271 | K32: =K3/K$2 -> 0 | L32: =L3/L$2 -> 0
C33: CUDA Time | D33: =D4/D$2 -> 76.919514 | E33: =E4/E$2 -> 97.205821 | F33: =F4/F$2 -> 181.96724 | G33: =G4/G$2 -> 353.56262 | H33: =H4/H$2 -> 0 | I33: =I4/I$2 -> 0 | J33: =J4/J$2 -> 0 | K33: =K4/K$2 -> 0 | L33: =L4/L$2 -> 0
C34: CUDA ant | D34: =D5/D$2 -> 26.48331 | E34: =E5/E$2 -> 18.653612 | F34: =F5/F$2 -> 14.88498 | G34: =G5/G$2 -> 15.027809 | H34: =H5/H$2 -> 14.733276 | I34: =I5/I$2 -> 14.15014 | J34: =J5/J$2 -> 14.222564 | K34: =K5/K$2 -> 0 | L34: =L5/L$2 -> 0
C35: CUDA ant par | D35: =D6/D$2 -> 26.317457 | E35: =E6/E$2 -> 18.262881 | F35: =F6/F$2 -> 14.321565 | G35: =G6/G$2 -> 12.313577 | H35: =H6/H$2 -> 11.415707 | I35: =I6/I$2 -> 10.737137 | J35: =J6/J$2 -> 10.534609 | K35: =K6/K$2 -> 0 | L35: =L6/L$2 -> 0
C36: CUDA opt | D36: =D7/D$2 -> 77.250762 | E36: =E7/E$2 -> 97.627895 | F36: =F7/F$2 -> 182.4716 | G36: =G7/G$2 -> 354.24179 | H36: =H7/H$2 -> 0 | I36: =I7/I$2 -> 0 | J36: =J7/J$2 -> 0 | K36: =K7/K$2 -> 0 | L36: =L7/L$2 -> 0
C37: CUDA opt ant | D37: =D8/D$2 -> 26.452867 | E37: =E8/E$2 -> 18.604055 | F37: =F8/F$2 -> 14.746261 | G37: =G8/G$2 -> 14.94573 | H37: =H8/H$2 -> 14.710492 | I37: =I8/I$2 -> 14.199228 | J37: =J8/J$2 -> 14.213097 | K37: =K8/K$2 -> 0 | L37: =L8/L$2 -> 0
C38: CUDA opt ant par | D38: =D9/D$2 -> 26.263262 | E38: =E9/E$2 -> 18.236271 | F38: =F9/F$2 -> 14.151738 | G38: =G9/G$2 -> 12.300308 | H38: =H9/H$2 -> 11.403068 | I38: =I9/I$2 -> 10.804997 | J38: =J9/J$2 -> 10.535009 | K38: =K9/K$2 -> 0 | L38: =L9/L$2 -> 0
C39: CUDA opt_one_GPU | D39: =D10/D$2 -> 129.13778 | E39: =E10/E$2 -> 129.16764 | F39: =F10/F$2 -> 132.82349 | G39: =G10/G$2 -> 502.35982 | H39: =H10/H$2 -> 0 | I39: =I10/I$2 -> 0 | J39: =J10/J$2 -> 0 | K39: =K10/K$2 -> 0 | L39: =L10/L$2 -> 0
C40: CUDA opt_one_GPU ant | D40: =D11/D$2 -> 609.09314 | E40: =E11/E$2 -> 606.95971 | F40: =F11/F$2 -> 599.47143 | G40: =G11/G$2 -> 607.52036 | H40: =H11/H$2 -> 610.53616 | I40: =I11/I$2 -> 609.01372 | J40: =J11/J$2 -> 610.57098 | K40: =K11/K$2 -> 0 | L40: =L11/L$2 -> 0
C41: CUDA opt_one_GPU ant local | D41: =D12/D$2 -> 34.980529 | E41: =E12/E$2 -> 34.325029 | F41: =F12/F$2 -> 33.862261 | G41: =G12/G$2 -> 34.183054 | H41: =H12/H$2 -> 34.318815 | I41: =I12/I$2 -> 34.250436 | J41: =J12/J$2 -> 34.318868 | K41: =K12/K$2 -> 0 | L41: =L12/L$2 -> 0
C42: CUDA Const | D42: =D13/D$2 -> 75.968405 | E42: =E13/E$2 -> 98.498655 | F42: =F13/F$2 -> 180.65776 | G42: =G13/G$2 -> 355.61583 | H42: =H13/H$2 -> 0 | I42: =I13/I$2 -> 0 | J42: =J13/J$2 -> 0 | K42: =K13/K$2 -> 0 | L42: =L13/L$2 -> 0
...

Sheet 1050COMP
B1: 1.96 | C1: 50 | D1: 2 | E1: 4 | F1: 8 | G1: 16 | H1: 32 | I1: 64 | J1: 128 | K1: 256 | L1: 512 | M1: 9th Gen Intel Core i5-9400F 2.90 GHz (16Gb ОЗУ),
B2: МО | D2: 42 | E2: 84 | F2: 168 | G2: 336 | H2: 672 | I2: 1344 | J2: 2688 | K2: 5376 | L2: 10752
A3: 1 | C3: Classic ACO | D3: 13775.68 | E3: 24819.016 | F3: 47399.626 | G3: 96405.03 | H3: 197567.46 | I3: 376437.82 | J3: 762594.84
C4: CUDA Time | D4: 3659.4322 | E4: 9339.9226 | F4: 35373.252 | G4: 133771.86
C5: CUDA ant | D5: 1205.171 | E5: 1720.4454 | F5: 2777.4122 | G5: 5562.0442 | H5: 9529.4334 | I5: 22207.712 | J5: 38945.372
C6: CUDA ant par | D6: 1193.4462 | E6: 1718.7074 | F6: 2621.5022 | G6: 4581.1512 | H6: 7371.8842 | I6: 15329.056 | J6: 29967.086
C7: CUDA opt | D7: 3604.9408 | E7: 9478.3754 | F7: 35015.916 | G7: 133849.2
C8: CUDA opt ant | D8: 1181.9466 | E8: 1592.6038 | F8: 2740.828 | G8: 5504.5884 | H8: 11476.146 | I8: 21936.874 | J8: 42614.86
C9: CUDA opt ant par | D9: 1188.5088 | E9: 1564.9252 | F9: 2627.7358 | G9: 4576.1182 | H9: 9043.0616 | I9: 17174.572 | J9: 32164.586
C10: CUDA opt_one_GPU | D10: 5996.6822 | E10: 10388.759 | F10: 25658.662 | G10: 191956.08
C11: CUDA opt_one_GPU ant | D11: 29850.118 | E11: 56742.516 | F11: 114161.2 | G11: 231832.44 | H11: 433399.84 | I11: 921568.96 | J11: 1752741.2
C12: CUDA opt_one_GPU ant local | D12: 1703.0858 | E12: 3238.8466 | F12: 6387.8326 | G12: 11126.67 | H12: 24205.906 | I12: 51402.416 | J12: 189955.16
C13: CUDA Const | D13: 3582.0978 | E13: 9321.176 | F13: 35222.21 | G13: 140931.94 | J13: #DIV/0!
C14: CUDA ant Const | D14: 1198.7844 | E14: 1685.7338 | F14: 2736.6656 | G14: 5809.5368 | H14: 11665.926 | I14: 22066.966 | J14: #DIV/0!
C15: CUDA ant par Const | D15: 1201.7132 | E15: 1666.8358 | F15: 2658.8206 | G15: 4790.7862 | H15: 9009.8438 | I15: 16641.204 | J15: #DIV/0!
C16: CUDA opt Const | D16: 3561.421 | E16: 9327.857 | F16: 35469.58 | G16: 116863.72 | J16: #DIV/0!
C17: CUDA opt ant Const | D17: 1196.1116 | E17: 1724.5872 | F17: 2729.0976 | G17: 4861.7164 | H17: 11861.754 | I17: 22054.342 | J17: #DIV/0!
C18: CUDA opt ant par Const | D18: 1181.1062 | E18: 1693.6088 | F18: 2630.1166 | G18: 4023.7572 | H18: 9454.3274 | I18: 16626.426 | J18: #DIV/0!
C19: CUDA ant par global | D19: 1205.47 | E19: 1686.3086 | F19: 2651.783 | G19: 4571.1628 | H19: 8694.7538 | I19: 16569.436 | J19: 30830.606
C20: CUDA opt ant par global | D20: 1188.4956 | E20: 1654.3996 | F20: 2652.3568 | G20: 4619.6548 | H20: 8539.7484 | I20: 17284.052 | J20: 31651.7
C21: CUDA ant add CPU Time | D21: 621.49762 | E21: 1148.686 | F21: 2232.367 | G21: 4529.7836 | H21: 9484.4038 | I21: 19648.39 | J21: 36474.402
C22: CUDA ant add CPU Const | D22: 620.47406 | E22: 1149.12 | F22: 2235.8514 | G22: 4777.7546 | H22: 9736.995 | I22: 18839.554 | J22: #DIV/0!
C23: CUDA ant add CPU Time global | D23: 628.01006 | E23: 1159.1122 | F23: 2251.028 | G23: 4546.8504 | H23: 9397.42 | I23: 18911.85 | J23: 36767.928
C24: CUDA ant add CPU_AVX_transp Time | D24: #DIV/0! | E24: 1191.7366 | F24: 2306.617 | G24: 4894.3002 | H24: 9785.159 | I24: 18785.994 | J24: 57289.882
C25: CUDA ant add CPU12 | D25: 1858.168 | E25: 2420.109 | F25: 4527.1802 | G25: 8310.85 | H25: 15832.002 | I25: 27962.48 | J25: 51638.59
C26: Time non CUDA AVX time 4 | D26: 980.75398 | E26: 1822.0432 | F26: 3521.0432 | G26: 6913.7884 | H26: 14600.704 | I26: 27769.686 | J26: 53720.156
C27: Time non CUDA AVX add CPU time 4 | D27: 585.59822 | E27: 1094.3246 | F27: 2120.4718 | G27: 4187.7104 | H27: 9455.6194 | I27: 19091.788 | J27: 39015.478
C30: 6 | D30: 2 | E30: 4 | F30: 8 | G30: 16 | H30: 32 | I30: 64 | J30: 128 | K30: 256 | L30: 512
D31: 42 | E31: 84 | F31: 168 | G31: 336 | H31: 672 | I31: 1344 | J31: 2688 | K31: 5376 | L31: 10752
C32: Classic ACO | D32: =D3/D$2 -> 327.99238 | E32: =E3/E$2 -> 295.46448 | F32: =F3/F$2 -> 282.14063 | G32: =G3/G$2 -> 286.91973 | H32: =H3/H$2 -> 293.9992 | I32: =I3/I$2 -> 280.08766 | J32: =J3/J$2 -> 283.70344 | K32: =K3/K$2 -> 0 | L32: =L3/L$2 -> 0
C33: CUDA Time | D33: =D4/D$2 -> 87.129338 | E33: =E4/E$2 -> 111.18955 | F33: =F4/F$2 -> 210.55507 | G33: =G4/G$2 -> 398.13054 | H33: =H4/H$2 -> 0 | I33: =I4/I$2 -> 0 | J33: =J4/J$2 -> 0 | K33: =K4/K$2 -> 0 | L33: =L4/L$2 -> 0
C34: CUDA ant | D34: =D5/D$2 -> 28.694548 | E34: =E5/E$2 -> 20.481493 | F34: =F5/F$2 -> 16.532215 | G34: =G5/G$2 -> 16.553703 | H34: =H5/H$2 -> 14.180704 | I34: =I5/I$2 -> 16.523595 | J34: =J5/J$2 -> 14.488606 | K34: =K5/K$2 -> 0 | L34: =L5/L$2 -> 0
C35: CUDA ant par | D35: =D6/D$2 -> 28.415386 | E35: =E6/E$2 -> 20.460802 | F35: =F6/F$2 -> 15.60418 | G35: =G6/G$2 -> 13.634379 | H35: =H6/H$2 -> 10.970066 | I35: =I6/I$2 -> 11.405548 | J35: =J6/J$2 -> 11.148469 | K35: =K6/K$2 -> 0 | L35: =L6/L$2 -> 0
C36: CUDA opt Time | D36: =D7/D$2 -> 85.831924 | E36: =E7/E$2 -> 112.8378 | F36: =F7/F$2 -> 208.42807 | G36: =G7/G$2 -> 398.36071 | H36: =H7/H$2 -> 0 | I36: =I7/I$2 -> 0 | J36: =J7/J$2 -> 0 | K36: =K7/K$2 -> 0 | L36: =L7/L$2 -> 0
C37: CUDA opt ant | D37: =D8/D$2 -> 28.141586 | E37: =E8/E$2 -> 18.959569 | F37: =F8/F$2 -> 16.314452 | G37: =G8/G$2 -> 16.382704 | H37: =H8/H$2 -> 17.077599 | I37: =I8/I$2 -> 16.322079 | J37: =J8/J$2 -> 15.853743 | K37: =K8/K$2 -> 0 | L37: =L8/L$2 -> 0
C38: CUDA opt ant par | D38: =D9/D$2 -> 28.297829 | E38: =E9/E$2 -> 18.630062 | F38: =F9/F$2 -> 15.641285 | G38: =G9/G$2 -> 13.619399 | H38: =H9/H$2 -> 13.456937 | I38: =I9/I$2 -> 12.778699 | J38: =J9/J$2 -> 11.965992 | K38: =K9/K$2 -> 0 | L38: =L9/L$2 -> 0
C39: CUDA opt_one_GPU | D39: =D10/D$2 -> 142.77815 | E39: =E10/E$2 -> 123.6757 | F39: =F10/F$2 -> 152.73013 | G39: =G10/G$2 -> 571.29786 | H39: =H10/H$2 -> 0 | I39: =I10/I$2 -> 0 | J39: =J10/J$2 -> 0 | K39: =K10/K$2 -> 0 | L39: =L10/L$2 -> 0
C40: CUDA opt_one_GPU ant | D40: =D11/D$2 -> 710.7171 | E40: =E11/E$2 -> 675.50614 | F40: =F11/F$2 -> 679.53095 | G40: =G11/G$2 -> 689.9775 | H40: =H11/H$2 -> 644.94024 | I40: =I11/I$2 -> 685.69119 | J40: =J11/J$2 -> 652.06146 | K40: =K11/K$2 -> 0 | L40: =L11/L$2 -> 0
C41: CUDA opt_one_GPU ant local | D41: =D12/D$2 -> 40.549662 | E41: =E12/E$2 -> 38.557698 | F41: =F12/F$2 -> 38.022813 | G41: =G12/G$2 -> 33.115089 | H41: =H12/H$2 -> 36.020693 | I41: =I12/I$2 -> 38.245845 | J41: =J12/J$2 -> 70.667842 | K41: =K12/K$2 -> 0 | L41: =L12/L$2 -> 0
C42: CUDA Const | D42: =D13/D$2 -> 85.288043 | E42: =E13/E$2 -> 110.96638 | F42: =F13/F$2 -> 209.65601 | G42: =G13/G$2 -> 419.4403 | H42: =H13/H$2 -> 0 | I42: =I13/I$2 -> 0 | J42: =J13/J$2 -> #DIV/0! | K42: =K13/K$2 -> 0 | L42: =L13/L$2 -> 0
...

Sheet 3060COMP Kaf
B1: 1.96 | C1: 50 | D1: 2 | E1: 4 | F1: 8 | G1: 16 | H1: 32 | I1: 64 | J1: 128 | K1: 256 | L1: 512
B2: МО | D2: 42 | E2: 84 | F2: 168 | G2: 336 | H2: 672 | I2: 1344 | J2: 2688 | K2: 5376 | L2: 10752
A3: 1 | C3: Classic ACO | D3: 5875.1582 | E3: 10771.412 | F3: 26160.066 | G3: 39471.228 | H3: 77695.884 | I3: 153183.06 | J3: 307026.62
C4: CUDA Time | D4: 659.45638 | E4: 974.61908 | F4: 2602.1698 | G4: 8768.361
C5: CUDA ant | D5: 736.79894 | E5: 951.97772 | F5: 1349.0594 | G5: 2210.5108 | H5: 4436.7684 | I5: 8167.5768 | J5: 16175.518
C6: CUDA ant par | D6: 739.67078 | E6: 953.97314 | F6: 1339.2326 | G6: 2207.6092 | H6: 3974.5822 | I6: 7162.1168 | J6: 13610.748
C7: CUDA opt Time | D7: 660.26748 | E7: 975.45584 | F7: 2598.6858 | G7: 8764.6256
C8: CUDA opt ant | D8: 737.98146 | E8: 940.65504 | F8: 1338.6938 | G8: 2208.9828 | H8: 4492.0946 | I8: 8202.1734 | J8: 16914.278
C9: CUDA opt ant par | D9: 736.75002 | E9: 940.7367 | F9: 1327.4454 | G9: 2199.6678 | H9: 4003.4428 | I9: 7153.5668 | J9: 13618.982
C10: CUDA opt_one_GPU | D10: 1812.1012 | E10: 2665.7836 | F10: 18683.677 | G10: 16337.164 | I10: #DIV/0! | J10: #DIV/0!
C11: CUDA opt_one_GPU ant | D11: 20501.294 | E11: 41987.94 | F11: 83325.52 | G11: 167914.96 | H11: 345659.38 | I11: #DIV/0! | J11: #DIV/0!
C12: CUDA opt_one_GPU ant local | D12: 1075.2234 | E12: 2212.56 | F12: 4386.9946 | G12: 8828.2146 | H12: 18276.95 | I12: #DIV/0! | J12: #DIV/0!
C13: CUDA Const | D13: 657.61942 | E13: 995.75938 | F13: 2552.9068 | G13: 8528.4406 | J13: #DIV/0!
C14: CUDA ant Const | D14: 735.1442 | E14: 963.16294 | F14: 1324.481 | G14: 2133.4768 | H14: 4478.8074 | I14: 8118.0616 | J14: #DIV/0!
C15: CUDA ant par Const | D15: 735.1329 | E15: 965.74456 | F15: 1312.1178 | G15: 2104.2544 | H15: 3984.552 | I15: 7103.4708 | J15: #DIV/0!
C16: CUDA opt Const | D16: 658.24748 | E16: 986.70974 | F16: 2551.6206 | G16: 8539.2294 | J16: #DIV/0!
C17: CUDA opt ant Const | D17: 730.80316 | E17: 956.3684 | F17: 1323.8334 | G17: 2122.5644 | H17: 4471.84 | I17: 8145.9328 | J17: #DIV/0!
C18: CUDA opt ant par Const | D18: 737.13314 | E18: 950.0886 | F18: 1309.8776 | G18: 2100.6994 | H18: 3975.7632 | I18: 7103.4464 | J18: #DIV/0!
C19: CUDA ant par global
C20: CUDA opt ant par global
C21: CUDA ant add CPU | D21: 322.68932 | E21: 566.05552 | F21: 1058.8452 | G21: 2135.684 | H21: 4303.4986 | I21: 8174.5442 | J21: 16018.514
C22: CUDA ant add CPU Const | D22: 360.00486 | E22: 743.0137 | F22: 1037.3918 | G22: 1992.259 | H22: 4173.8776 | I22: 8166.725 | J22: #DIV/0!
C23: CUDA ant add CPU Time global
C24: CUDA ant add CPU_AVX_transp | D24: #DIV/0! | E24: 560.3825 | F24: 1025.0084 | G24: 2049.2228 | H24: 4041.9912 | I24: 7795.1166 | J24: 15434.73
C25: CUDA ant add CPU12 | D25: 939.67486 | E25: 1388.7272 | F25: 2797.8444 | G25: 5044.6312 | H25: 9471.6298 | I25: 18078.732 | J25: 27833.844
C26: Time non CUDA AVX time 4 | D26: 496.9724 | E26: 864.94588 | F26: 1599.1574 | G26: 3061.0534 | H26: 6094.9754 | I26: 12117.154 | J26: #DIV/0!
C27: Time non CUDA AVX add CPU time 4 | D27: 369.48456 | E27: 602.6023 | F27: 1072.0266 | G27: 2077.2694 | H27: 4173.0254 | I27: 8534.347 | J27: #DIV/0!
C30: 6 | D30: 2 | E30: 4 | F30: 8 | G30: 16 | H30: 32 | I30: 64 | J30: 128 | K30: 256 | L30: 512
D31: 42 | E31: 84 | F31: 168 | G31: 336 | H31: 672 | I31: 1344 | J31: 2688 | K31: 5376 | L31: 10752
C32: Classic ACO | D32: =D3/D$2 -> 139.88472 | E32: =E3/E$2 -> 128.2311 | F32: =F3/F$2 -> 155.71468 | G32: =G3/G$2 -> 117.47389 | H32: =H3/H$2 -> 115.61888 | I32: =I3/I$2 -> 113.97549 | J32: =J3/J$2 -> 114.22121 | K32: =K3/K$2 -> 0 | L32: =L3/L$2 -> 0
C33: CUDA Time | D33: =D4/D$2 -> 15.701342 | E33: =E4/E$2 -> 11.602608 | F33: =F4/F$2 -> 15.489106 | G33: =G4/G$2 -> 26.096313 | H33: =H4/H$2 -> 0 | I33: =I4/I$2 -> 0 | J33: =J4/J$2 -> 0 | K33: =K4/K$2 -> 0 | L33: =L4/L$2 -> 0
C34: CUDA ant | D34: =D5/D$2 -> 17.542832 | E34: =E5/E$2 -> 11.333068 | F34: =F5/F$2 -> 8.0301155 | G34: =G5/G$2 -> 6.5789012 | H34: =H5/H$2 -> 6.6023339 | I34: =I5/I$2 -> 6.0770661 | J34: =J5/J$2 -> 6.0176778 | K34: =K5/K$2 -> 0 | L34: =L5/L$2 -> 0
C35: CUDA ant par | D35: =D6/D$2 -> 17.611209 | E35: =E6/E$2 -> 11.356823 | F35: =F6/F$2 -> 7.9716226 | G35: =G6/G$2 -> 6.5702655 | H35: =H6/H$2 -> 5.9145568 | I35: =I6/I$2 -> 5.328956 | J35: =J6/J$2 -> 5.0635223 | K35: =K6/K$2 -> 0 | L35: =L6/L$2 -> 0
C36: CUDA opt Time | D36: =D7/D$2 -> 15.720654 | E36: =E7/E$2 -> 11.61257 | F36: =F7/F$2 -> 15.468368 | G36: =G7/G$2 -> 26.085195 | H36: =H7/H$2 -> 0 | I36: =I7/I$2 -> 0 | J36: =J7/J$2 -> 0 | K36: =K7/K$2 -> 0 | L36: =L7/L$2 -> 0
C37: CUDA opt ant | D37: =D8/D$2 -> 17.570987 | E37: =E8/E$2 -> 11.198274 | F37: =F8/F$2 -> 7.9684155 | G37: =G8/G$2 -> 6.5743536 | H37: =H8/H$2 -> 6.6846646 | I37: =I8/I$2 -> 6.1028076 | J37: =J8/J$2 -> 6.2925141 | K37: =K8/K$2 -> 0 | L37: =L8/L$2 -> 0
C38: CUDA opt ant par | D38: =D9/D$2 -> 17.541667 | E38: =E9/E$2 -> 11.199246 | F38: =F9/F$2 -> 7.9014607 | G38: =G9/G$2 -> 6.5466304 | H38: =H9/H$2 -> 5.9575042 | I38: =I9/I$2 -> 5.3225943 | J38: =J9/J$2 -> 5.0665856 | K38: =K9/K$2 -> 0 | L38: =L9/L$2 -> 0
C39: CUDA opt_one_GPU | D39: =D10/D$2 -> 43.145267 | E39: =E10/E$2 -> 31.735519 | F39: =F10/F$2 -> 111.21236 | G39: =G10/G$2 -> 48.622512 | H39: =H10/H$2 -> 0 | I39: =I10/I$2 -> #DIV/0! | J39: =J10/J$2 -> #DIV/0! | K39: =K10/K$2 -> 0 | L39: =L10/L$2 -> 0
C40: CUDA opt_one_GPU ant | D40: =D11/D$2 -> 488.12605 | E40: =E11/E$2 -> 499.85643 | F40: =F11/F$2 -> 495.98524 | G40: =G11/G$2 -> 499.7469 | H40: =H11/H$2 -> 514.37408 | I40: =I11/I$2 -> #DIV/0! | J40: =J11/J$2 -> #DIV/0! | K40: =K11/K$2 -> 0 | L40: =L11/L$2 -> 0
C41: CUDA opt_one_GPU ant local | D41: =D12/D$2 -> 25.600557 | E41: =E12/E$2 -> 26.34 | F41: =F12/F$2 -> 26.113063 | G41: =G12/G$2 -> 26.274448 | H41: =H12/H$2 -> 27.197842 | I41: =I12/I$2 -> #DIV/0! | J41: =J12/J$2 -> #DIV/0! | K41: =K12/K$2 -> 0 | L41: =L12/L$2 -> 0
C42: CUDA Const | D42: =D13/D$2 -> 15.657605 | E42: =E13/E$2 -> 11.854278 | F42: =F13/F$2 -> 15.195874 | G42: =G13/G$2 -> 25.382264 | H42: =H13/H$2 -> 0 | I42: =I13/I$2 -> 0 | J42: =J13/J$2 -> #DIV/0! | K42: =K13/K$2 -> 0 | L42: =L13/L$2 -> 0
...

Sheet 3060LAPTOP
B1: 1.96 | C1: 50 | D1: 2 | E1: 4 | F1: 8 | G1: 16 | H1: 32 | I1: 64 | J1: 128 | K1: 256 | L1: 512 | M1: 12th Gen Intel(R) Core(TM) i5-12450H 2.00 GHz
B2: МО | D2: 42 | E2: 84 | F2: 168 | G2: 336 | H2: 672 | I2: 1344 | J2: 2688 | K2: 5376 | L2: 10752 | M2: 16,0 ГБ (доступно: 15,7 ГБ)
A3: 1 | C3: Classic ACO | D3: 6732.0454 | E3: 12795.57 | F3: 24112.532 | G3: 46059.344 | H3: 91907.946 | I3: 184408.08 | J3: 367570.34
C4: CUDA Time | D4: 602.02756 | E4: 916.12924 | F4: 2494.2466 | G4: 7974.9374
C5: CUDA ant | D5: 682.94254 | E5: 883.29402 | F5: 1272.4982 | G5: 2115.9988 | H5: 4199.7956 | I5: 8039.9226 | J5: 15961.626
C6: CUDA ant par | D6: 701.2333 | E6: 891.2481 | F6: 1267.7214 | G6: 2061.9694 | H6: 3765.8012 | I6: 7191.5302 | J6: 13626.968
C7: CUDA opt Time | D7: 616.45874 | E7: 926.26502 | F7: 2512.3228 | G7: 7989.6568
C8: CUDA opt ant | D8: 702.30982 | E8: 884.50074 | F8: 1275.471 | G8: 2112.4066 | H8: 4260.4548 | I8: 8042.1618 | J8: 15982.66
C9: CUDA opt ant par | D9: 678.05698 | E9: 889.98908 | F9: 1277.9308 | G9: 2061.6282 | H9: 3775.5272 | I9: 7188.3614 | J9: 13638.666
C10: CUDA opt_one_GPU | D10: 1741.6024 | E10: 2556.7884 | F10: 13890.751 | G10: 14775.812
C11: CUDA opt_one_GPU ant | D11: 19848.524 | E11: 39737.916 | F11: 80165.326 | G11: 161035.52 | H11: 324793.52 | I11: 646981.78 | J11: 1288508.4
C12: CUDA opt_one_GPU ant local | D12: 1052.6186 | E12: 2068.7274 | F12: 4224.1412 | G12: 8412.2148 | H12: 17360.922 | I12: 34022.14 | J12: 91296.23
C13: CUDA Const | D13: 597.6633 | E13: 905.70018 | F13: 2478.1706 | G13: 7898.8652
C14: CUDA ant Const | D14: 676.94802 | E14: 871.44982 | F14: 1263.1996 | G14: 2061.6228 | H14: 4230.7204 | I14: 7728.6802
C15: CUDA ant par Const | D15: 683.7667 | E15: 879.88922 | F15: 1247.2268 | G15: 2046.3764 | H15: 3799.744 | I15: 6779.9826
C16: CUDA opt Const | D16: 607.84376 | E16: 914.01154 | F16: 2485.1992 | G16: 7915.297
C17: CUDA opt ant Const | D17: 685.26216 | E17: 869.14464 | F17: 1256.723 | G17: 2064.6824 | H17: 4139.9786 | I17: 7798.3312
C18: CUDA opt ant par Const | D18: 691.47868 | E18: 870.6439 | F18: 1260.9804 | G18: 2020.7416 | H18: 3658.6106 | I18: 6777.2742
C19: CUDA ant par global | D19: 695.85012 | E19: 888.4899 | F19: 1268.7298 | G19: 2021.9382 | H19: 3664.5096 | I19: 6818.3274 | J19: 13123.25
C20: CUDA opt ant par global | D20: 690.54556 | E20: 873.0558 | F20: 1256.7892 | G20: 2023.796 | H20: 3666.4728 | I20: 6814.1784 | J20: 13132.234
C21: CUDA ant add CPU | D21: 320.60224 | E21: 573.33996 | F21: 1089.6978 | G21: 2122.6612 | H21: 4315.1708 | I21: 8536.6304 | J21: 16876.298
C22: CUDA ant add CPU Const | D22: 300.95566 | E22: 525.43118 | F22: 971.50002 | G22: 2146.0228 | H22: 4249.0002 | I22: 7883.411
C23: CUDA ant add CPU Time global | D23: 315.73246 | E23: 531.62172 | F23: 1011.1602 | G23: 1970.9378 | H23: 4014.7164 | I23: 7941.46 | J23: 15797.564
C24: CUDA ant add CPU_AVX_transp | D24: #DIV/0! | E24: 573.73596 | F24: 1002.7777 | G24: 1954.2058 | H24: 3930.811 | I24: 7862.3826 | J24: 15532.908
C25: CUDA ant add CPU12 | D25: 1001.4925 | E25: 1662.8522 | F25: 3342.1846 | G25: 6069.6134 | H25: 11814.46 | I25: 21886.496 | J25: 36632.952
C26: Time non CUDA AVX time 4 | D26: 573.63522 | E26: 1033.2558 | F26: 1921.5246 | G26: 3649.9786 | H26: 7160.9678 | I26: 14267.314 | J26: 27570.592
C27: Time non CUDA AVX add CPU time 4 | D27: 312.6066 | E27: 548.42256 | F27: 1018.1729 | G27: 2016.2662 | H27: 4164.2594 | I27: 8335.7698 | J27: 16520.026
C30: 6 | D30: 2 | E30: 4 | F30: 8 | G30: 16 | H30: 32 | I30: 64 | J30: 128 | K30: 256 | L30: 512
D31: 42 | E31: 84 | F31: 168 | G31: 336 | H31: 672 | I31: 1344 | J31: 2688 | K31: 5376 | L31: 10752
C32: Classic ACO | D32: =D3/D$2 -> 160.2868 | E32: =E3/E$2 -> 152.32821 | F32: =F3/F$2 -> 143.52698 | G32: =G3/G$2 -> 137.08138 | H32: =H3/H$2 -> 136.76778 | I32: =I3/I$2 -> 137.20839 | J32: =J3/J$2 -> 136.74492 | K32: =K3/K$2 -> 0 | L32: =L3/L$2 -> 0
C33: CUDA Time | D33: =D4/D$2 -> 14.33399 | E33: =E4/E$2 -> 10.9063 | F33: =F4/F$2 -> 14.846706 | G33: =G4/G$2 -> 23.734933 | H33: =H4/H$2 -> 0 | I33: =I4/I$2 -> 0 | J33: =J4/J$2 -> 0 | K33: =K4/K$2 -> 0 | L33: =L4/L$2 -> 0
C34: CUDA ant | D34: =D5/D$2 -> 16.260537 | E34: =E5/E$2 -> 10.515405 | F34: =F5/F$2 -> 7.574394 | G34: =G5/G$2 -> 6.2976155 | H34: =H5/H$2 -> 6.2496958 | I34: =I5/I$2 -> 5.9820853 | J34: =J5/J$2 -> 5.9381049 | K34: =K5/K$2 -> 0 | L34: =L5/L$2 -> 0
C35: CUDA ant par | D35: =D6/D$2 -> 16.696031 | E35: =E6/E$2 -> 10.610096 | F35: =F6/F$2 -> 7.5459607 | G35: =G6/G$2 -> 6.1368137 | H35: =H6/H$2 -> 5.6038708 | I35: =I6/I$2 -> 5.3508409 | J35: =J6/J$2 -> 5.0695565 | K35: =K6/K$2 -> 0 | L35: =L6/L$2 -> 0
C36: CUDA opt Time | D36: =D7/D$2 -> 14.677589 | E36: =E7/E$2 -> 11.026965 | F36: =F7/F$2 -> 14.954302 | G36: =G7/G$2 -> 23.77874 | H36: =H7/H$2 -> 0 | I36: =I7/I$2 -> 0 | J36: =J7/J$2 -> 0 | K36: =K7/K$2 -> 0 | L36: =L7/L$2 -> 0
C37: CUDA opt ant | D37: =D8/D$2 -> 16.721662 | E37: =E8/E$2 -> 10.529771 | F37: =F8/F$2 -> 7.5920893 | G37: =G8/G$2 -> 6.2869244 | H37: =H8/H$2 -> 6.3399625 | I37: =I8/I$2 -> 5.9837513 | J37: =J8/J$2 -> 5.9459301 | K37: =K8/K$2 -> 0 | L37: =L8/L$2 -> 0
C38: CUDA opt ant par | D38: =D9/D$2 -> 16.144214 | E38: =E9/E$2 -> 10.595108 | F38: =F9/F$2 -> 7.606731 | G38: =G9/G$2 -> 6.1357982 | H38: =H9/H$2 -> 5.618344 | I38: =I9/I$2 -> 5.3484832 | J38: =J9/J$2 -> 5.0739085 | K38: =K9/K$2 -> 0 | L38: =L9/L$2 -> 0
C39: CUDA opt_one_GPU | D39: =D10/D$2 -> 41.466724 | E39: =E10/E$2 -> 30.437957 | F39: =F10/F$2 -> 82.683039 | G39: =G10/G$2 -> 43.975631 | H39: =H10/H$2 -> 0 | I39: =I10/I$2 -> 0 | J39: =J10/J$2 -> 0 | K39: =K10/K$2 -> 0 | L39: =L10/L$2 -> 0
C40: CUDA opt_one_GPU ant | D40: =D11/D$2 -> 472.5839 | E40: =E11/E$2 -> 473.07043 | F40: =F11/F$2 -> 477.17456 | G40: =G11/G$2 -> 479.27238 | H40: =H11/H$2 -> 483.32369 | I40: =I11/I$2 -> 481.38525 | J40: =J11/J$2 -> 479.3558 | K40: =K11/K$2 -> 0 | L40: =L11/L$2 -> 0
C41: CUDA opt_one_GPU ant local | D41: =D12/D$2 -> 25.062348 | E41: =E12/E$2 -> 24.627707 | F41: =F12/F$2 -> 25.143698 | G41: =G12/G$2 -> 25.036354 | H41: =H12/H$2 -> 25.834705 | I41: =I12/I$2 -> 25.314092 | J41: =J12/J$2 -> 33.964371 | K41: =K12/K$2 -> 0 | L41: =L12/L$2 -> 0
C42: CUDA Const | D42: =D13/D$2 -> 14.230079 | E42: =E13/E$2 -> 10.782145 | F42: =F13/F$2 -> 14.751015 | G42: =G13/G$2 -> 23.508527 | H42: =H13/H$2 -> 0 | I42: =I13/I$2 -> 0 | J42: =J13/J$2 -> 0 | K42: =K13/K$2 -> 0 | L42: =L13/L$2 -> 0
...

Sheet Лист8
A1: 29 | B1: 120 | E1: 2 | F1: 4 | G1: 8 | H1: 16 | I1: 32 | J1: 64 | K1: 128 | Q1: 2 | R1: 4 | S1: 8 | T1: 16 | U1: 32 | V1: 64 | W1: 128
B2: 3060 | E2: 42 | F2: 84 | G2: 168 | H2: 336 | I2: 672 | J2: 1344 | K2: 2688 | Q2: 42 | R2: 84 | S2: 168 | T2: 336 | U2: 672 | V2: 1344 | W2: 2688
A3: 10 | B3: =OFFSET('1050LAPTOP'!$C$1,A3-1,0) -> CUDA opt_one_GPU | C3: MatrixACO_Global | D3: МО | E3: =OFFSET('3060LAPTOP'!D$1,$A3-1+$A$1,0) -> 41.466724 | F3: =OFFSET('3060LAPTOP'!E$1,$A3-1+$A$1,0) -> 30.437957 | G3: =OFFSET('3060LAPTOP'!F$1,$A3-1+$A$1,0) -> 82.683039 | H3: =OFFSET('3060LAPTOP'!G$1,$A3-1+$A$1,0) -> 43.975631 | I3: =OFFSET('3060LAPTOP'!H$1,$A3-1+$A$1,0) -> 0 | J3: =OFFSET('3060LAPTOP'!I$1,$A3-1+$A$1,0) -> 0 | K3: =OFFSET('3060LAPTOP'!J$1,$A3-1+$A$1,0) -> 0 | O3: MatrixACO_Global | P3: МО | Q3: 41.466724 | R3: 30.437957 | S3: 82.683039 | T3: 43.975631
D4: ДИ | E4: =OFFSET('3060LAPTOP'!D$1,$A3-1+$B$1,0) -> 3.2249785 | F4: =OFFSET('3060LAPTOP'!E$1,$A3-1+$B$1,0) -> 3.9900213 | G4: =OFFSET('3060LAPTOP'!F$1,$A3-1+$B$1,0)/G$2 -> 19.674787 | H4: =OFFSET('3060LAPTOP'!G$1,$A3-1+$B$1,0)/H$2 -> 0.037428997 | I4: =OFFSET('3060LAPTOP'!H$1,$A3-1+$B$1,0)/I$2 -> 0.00076183771 | J4: =OFFSET('3060LAPTOP'!I$1,$A3-1+$B$1,0)/J$2 -> 0.00039553715 | K4: =OFFSET('3060LAPTOP'!J$1,$A3-1+$B$1,0)/K$2 -> 0.00045823185 | P4: ДИ | Q4: 0.076785202 | R4: 0.047500254 | S4: 19.674787 | T4: 0.037428997
A5: 11 | B5: =OFFSET('1050LAPTOP'!$C$1,A5-1,0) -> CUDA opt_one_GPU ant | C5: MatrixACO_Layer _Global | D5: МО | E5: =OFFSET('3060LAPTOP'!D$1,$A5-1+$A$1,0) -> 472.5839 | F5: =OFFSET('3060LAPTOP'!E$1,$A5-1+$A$1,0) -> 473.07043 | G5: =OFFSET('3060LAPTOP'!F$1,$A5-1+$A$1,0) -> 477.17456 | H5: =OFFSET('3060LAPTOP'!G$1,$A5-1+$A$1,0) -> 479.27238 | I5: =OFFSET('3060LAPTOP'!H$1,$A5-1+$A$1,0) -> 483.32369 | J5: =OFFSET('3060LAPTOP'!I$1,$A5-1+$A$1,0) -> 481.38525 | K5: =OFFSET('3060LAPTOP'!J$1,$A5-1+$A$1,0) -> 479.3558 | O5: MatrixACO_Layer _Global | P5: МО | Q5: 472.5839 | R5: 473.07043 | S5: 477.17456 | T5: 479.27238 | U5: 483.32369 | V5: 481.38525 | W5: 479.3558
D6: ДИ | E6: =OFFSET('3060LAPTOP'!D$1,$A5-1+$B$1,0)/E$2 -> 0.08996618 | F6: =OFFSET('3060LAPTOP'!E$1,$A5-1+$B$1,0)/F$2 -> 0.33742802 | G6: =OFFSET('3060LAPTOP'!F$1,$A5-1+$B$1,0)/G$2 -> 0.13181741 | H6: =OFFSET('3060LAPTOP'!G$1,$A5-1+$B$1,0)/H$2 -> 0.06098063 | I6: =OFFSET('3060LAPTOP'!H$1,$A5-1+$B$1,0)/I$2 -> 4.3308458 | J6: =OFFSET('3060LAPTOP'!I$1,$A5-1+$B$1,0)/J$2 -> 0.38302029 | K6: =OFFSET('3060LAPTOP'!J$1,$A5-1+$B$1,0)/K$2 -> 0.57676995 | P6: ДИ | Q6: 0.08996618 | R6: 0.33742802 | S6: 0.13181741 | T6: 0.06098063 | U6: 4.3308458 | V6: 0.38302029 | W6: 0.57676995
A7: 12 | B7: =OFFSET('1050LAPTOP'!$C$1,A7-1,0) -> CUDA opt_one_GPU ant local | C7: MatrixACO_Layer _Local | D7: МО | E7: =OFFSET('3060LAPTOP'!D$1,$A7-1+$A$1,0) -> 25.062348 | F7: =OFFSET('3060LAPTOP'!E$1,$A7-1+$A$1,0) -> 24.627707 | G7: =OFFSET('3060LAPTOP'!F$1,$A7-1+$A$1,0) -> 25.143698 | H7: =OFFSET('3060LAPTOP'!G$1,$A7-1+$A$1,0) -> 25.036354 | I7: =OFFSET('3060LAPTOP'!H$1,$A7-1+$A$1,0) -> 25.834705 | J7: =OFFSET('3060LAPTOP'!I$1,$A7-1+$A$1,0) -> 25.314092 | K7: =OFFSET('3060LAPTOP'!J$1,$A7-1+$A$1,0) -> 33.964371 | O7: MatrixACO_Layer _Local | P7: МО | Q7: 25.062348 | R7: 24.627707 | S7: 25.143698 | T7: 25.036354 | U7: 25.834705 | V7: 25.314092 | W7: 33.964371
D8: ДИ | E8: =OFFSET('3060LAPTOP'!D$1,$A7-1+$B$1,0)/E$2 -> 0.0089795291 | F8: =OFFSET('3060LAPTOP'!E$1,$A7-1+$B$1,0)/F$2 -> 0.0063036061 | G8: =OFFSET('3060LAPTOP'!F$1,$A7-1+$B$1,0)/G$2 -> 0.0067257441 | H8: =OFFSET('3060LAPTOP'!G$1,$A7-1+$B$1,0)/H$2 -> 0.028800908 | I8: =OFFSET('3060LAPTOP'!H$1,$A7-1+$B$1,0)/I$2 -> 0.014096379 | J8: =OFFSET('3060LAPTOP'!I$1,$A7-1+$B$1,0)/J$2 -> 0.0069773522 | K8: =OFFSET('3060LAPTOP'!J$1,$A7-1+$B$1,0)/K$2 -> 0.013607193 | P8: ДИ | Q8: 0.0089795291 | R8: 0.0063036061 | S8: 0.0067257441 | T8: 0.028800908 | U8: 0.014096379 | V8: 0.0069773522 | W8: 0.013607193
A9: 4 | B9: =OFFSET('1050LAPTOP'!$C$1,A9-1,0) -> CUDA Time | C9: MatrixACO_Basic _Standart | D9: МО | E9: =OFFSET('3060LAPTOP'!D$1,$A9-1+$A$1,0) -> 14.33399 | F9: =OFFSET('3060LAPTOP'!E$1,$A9-1+$A$1,0) -> 10.9063 | G9: =OFFSET('3060LAPTOP'!F$1,$A9-1+$A$1,0) -> 14.846706 | H9: =OFFSET('3060LAPTOP'!G$1,$A9-1+$A$1,0) -> 23.734933 | I9: =OFFSET('3060LAPTOP'!H$1,$A9-1+$A$1,0) -> 0 | J9: =OFFSET('3060LAPTOP'!I$1,$A9-1+$A$1,0) -> 0 | K9: =OFFSET('3060LAPTOP'!J$1,$A9-1+$A$1,0) -> 0 | O9: MatrixACO_Basic _Standart | P9: МО | Q9: 14.33399 | R9: 10.9063 | S9: 14.846706 | T9: 23.734933
D10: ДИ | E10: =OFFSET('3060LAPTOP'!D$1,$A9-1+$B$1,0)/E$2 -> 0.074849804 | F10: =OFFSET('3060LAPTOP'!E$1,$A9-1+$B$1,0)/F$2 -> 0.020738749 | G10: =OFFSET('3060LAPTOP'!F$1,$A9-1+$B$1,0)/G$2 -> 0.028624502 | H10: =OFFSET('3060LAPTOP'!G$1,$A9-1+$B$1,0)/H$2 -> 0.028333125 | I10: =OFFSET('3060LAPTOP'!H$1,$A9-1+$B$1,0)/I$2 -> 0 | J10: =OFFSET('3060LAPTOP'!I$1,$A9-1+$B$1,0)/J$2 -> 0 | K10: =OFFSET('3060LAPTOP'!J$1,$A9-1+$B$1,0)/K$2 -> 0 | P10: ДИ | Q10: 0.074849804 | R10: 0.020738749 | S10: 0.028624502 | T10: 0.028333125
A11: 6 | B11: =OFFSET('1050LAPTOP'!$C$1,A11-1,0) -> CUDA ant par | C11: MatrixACO_Basic _Agent | D11: МО | E11: =OFFSET('3060LAPTOP'!D$1,$A11-1+$A$1,0) -> 16.696031 | F11: =OFFSET('3060LAPTOP'!E$1,$A11-1+$A$1,0) -> 10.610096 | G11: =OFFSET('3060LAPTOP'!F$1,$A11-1+$A$1,0) -> 7.5459607 | H11: =OFFSET('3060LAPTOP'!G$1,$A11-1+$A$1,0) -> 6.1368137 | I11: =OFFSET('3060LAPTOP'!H$1,$A11-1+$A$1,0) -> 5.6038708 | J11: =OFFSET('3060LAPTOP'!I$1,$A11-1+$A$1,0) -> 5.3508409 | K11: =OFFSET('3060LAPTOP'!J$1,$A11-1+$A$1,0) -> 5.0695565 | O11: MatrixACO_Basic _Agent | P11: МО | Q11: 16.696031 | R11: 10.610096 | S11: 7.5459607 | T11: 6.1368137 | U11: 5.6038708 | V11: 5.3508409 | W11: 5.0695565
D12: ДИ | E12: =OFFSET('3060LAPTOP'!D$1,$A11-1+$B$1,0)/E$2 -> 0.040523634 | F12: =OFFSET('3060LAPTOP'!E$1,$A11-1+$B$1,0)/F$2 -> 0.018544335 | G12: =OFFSET('3060LAPTOP'!F$1,$A11-1+$B$1,0)/G$2 -> 0.0063717605 | H12: =OFFSET('3060LAPTOP'!G$1,$A11-1+$B$1,0)/H$2 -> 0.0038484927 | I12: =OFFSET('3060LAPTOP'!H$1,$A11-1+$B$1,0)/I$2 -> 0.0039055704 | J12: =OFFSET('3060LAPTOP'!I$1,$A11-1+$B$1,0)/J$2 -> 0.0013635986 | K12: =OFFSET('3060LAPTOP'!J$1,$A11-1+$B$1,0)/K$2 -> 0.00068063077 | P12: ДИ | Q12: 0.040523634 | R12: 0.018544335 | S12: 0.0063717605 | T12: 0.0038484927 | U12: 0.0039055704 | V12: 0.0013635986 | W12: 0.00068063077
