Workbook

Sheet Ускорение 100
C3: 50 | D3: 2 | E3: 4 | F3: 8 | G3: 16 | H3: 32 | I3: 64 | J3: 128
D4: 42 | E4: 84 | F4: 168 | G4: 336 | H4: 672 | I4: 1344 | J4: 2688
C5: non CUDA Time | D5: 11.898648 | E5: 12.202972 | F5: 12.161524 | G5: 12.16129 | H5: 11.988787 | I5: 12.276108 | J5: 12.168533
C6: omp | D6: 12.522805 | E6: 12.666325 | F6: 12.428722 | G6: 12.068474 | H6: 11.765758 | I6: 12.168237 | J6: 12.215631
C7: non CUDA AVX Time
C8: non CUDA AVX_OMP Time
C9: non CUDA transp Time | D9: 11.84306 | E9: 12.147658 | F9: 12.187638 | G9: 11.973437 | H9: 12.339089 | I9: 12.491909 | J9: 12.150987
C10: non CUDA transp_AVX Time | E10: 11.646125 | F10: 11.791034 | G10: 11.611334 | H10: 12.35973 | I10: 12.423243 | J10: 11.509245
C11: non CUDA transp_AVX_OMP Time | E11: 11.631643 | F11: 11.717524 | G11: 11.623149 | H11: 12.047251 | I11: 12.425263 | J11: 12.199688
C13: non CUDA Time | D13: 21.982995 | E13: 21.178685 | F13: 21.084799 | G13: 23.334354
C14: omp | D14: 23.631074 | E14: 19.592533 | F14: 21.319516 | G14: 23.305328
C15: non CUDA AVX Time | D15: 21.533306 | E15: 19.015856 | F15: 20.967085 | G15: 22.907659
C16: non CUDA AVX_OMP Time | D16: 23.609328 | E16: 21.11319 | F16: 23.855822 | G16: 21.463483
C17: non CUDA transp Time | D17: 22.006121 | E17: 18.915999 | F17: 21.746068 | G17: 20.180879
C18: non CUDA transp_AVX Time | D18: 20.574076 | E18: 18.600917 | F18: 21.512144 | G18: 20.108297
C19: non CUDA transp_AVX_OMP Time | D19: 20.752167 | E19: 18.566846 | F19: 21.548396 | G19: 20.070018
C21: non CUDA Time | D21: 19.437135 | E21: 23.997491 | F21: 28.436593 | G21: 29.620767
C22: omp | D22: 34.271531 | E22: 36.336281 | F22: 35.918625 | G22: 34.567598
C23: non CUDA AVX Time | D23: 19.635403 | E23: 23.324759 | F23: 28.373104 | G23: 29.57483
C24: non CUDA AVX_OMP Time | D24: 36.901551 | E24: 35.749189 | F24: 36.537769 | G24: 36.021229
C25: non CUDA transp Time | D25: 30.724548 | E25: 31.852202 | F25: 32.662681 | G25: 29.779546
C26: non CUDA transp_AVX Time | E26: 31.396539 | F26: 32.01716 | G26: 29.563027
C27: non CUDA transp_AVX_OMP Time | E27: 31.686685 | F27: 32.297767 | G27: 29.665998
C29: non CUDA Time | D29: 33.443643 | E29: 47.852694 | F29: 33.054009
C30: omp | D30: 45.956693 | E30: 47.479874 | F30: 48.966941
C31: non CUDA AVX Time | D31: 33.794018 | E31: 47.950971 | F31: 33.248451
C32: non CUDA AVX_OMP Time | E32: 23.803123 | F32: 49.767563
C33: non CUDA transp Time | E33: 23.962748 | F33: 18.339941
C34: non CUDA transp_AVX Time | D34: 22.303212 | E34: 24.080051 | F34: 18.67207
C35: non CUDA transp_AVX_OMP Time | D35: 22.226257 | E35: 24.107846 | F35: 18.830258

Sheet Ускорение
C3: Количество параметров | D3: 2 | E3: 4 | F3: 8 | G3: 16 | H3: 32 | I3: 64 | J3: 128 | M3: Количество параметров | N3: 2 | O3: 4 | P3: 8 | Q3: 16 | R3: 32 | S3: 64 | T3: 128
C4: Количество слоев | D4: 42 | E4: 84 | F4: 168 | G4: 336 | H4: 672 | I4: 1344 | J4: 2688 | M4: Количество слоев | N4: 42 | O4: 84 | P4: 168 | Q4: 336 | R4: 672 | S4: 1344 | T4: 2688
C5: Матричный ACO | D5: 14.534282 | E5: 14.742948 | F5: 14.518772 | G5: 14.565905 | H5: 14.802014 | I5: 15.03086 | J5: 15.657087 | M5: Матричный ACO | N5: 7.0908056 | O5: 7.0305005 | P5: 6.8192447 | Q5: 6.8772192 | R5: 8.0036313 | S5: 6.7722447 | T5: 7.1765932
C6: Матричный ACO + OMP | D6: 15.630633 | E6: 15.494684 | F6: 15.064535 | G6: 14.984987 | H6: 14.881814 | I6: 15.18169 | J6: 15.922771 | M6: Матричный ACO + OMP | N6: 7.5021448 | O6: 7.2515123 | P6: 6.9723451 | Q6: 6.9449167 | R6: 8.1243314 | S6: 7.1569495 | T6: 7.1323597
C7: Транспонированный матричный ACO | D7: 14.627786 | E7: 14.921165 | F7: 14.853376 | G7: 15.008914 | H7: 14.859125 | I7: 15.166802 | J7: 15.996095 | M7: Транспонированный матричный ACO | N7: 7.0972838 | O7: 6.9867111 | P7: 6.837988 | Q7: 6.8537543 | R7: 8.025932 | S7: 7.1018688 | T7: 7.1112809
C8: Транспонированный матричный ACO + AVX | E8: 14.50428 | F8: 14.424749 | G8: 14.559636 | H8: 14.464994 | I8: 14.491351 | J8: 15.368498 | M8: Транспонированный матричный ACO + AVX | O8: 5.3774738 | P8: 5.2974162 | Q8: 5.4169876 | R8: 6.5580668 | S8: 6.4844296 | T8: 6.405612
C9: Транспонированный матричный ACO + AVX + OMP | E9: 14.354502 | F9: 14.424979 | G9: 14.568367 | H9: 14.428003 | I9: 14.484914 | J9: 15.363133 | M9: Транспонированный матричный ACO + AVX + OMP | O9: 5.397005 | P9: 5.3324099 | Q9: 5.4187196 | R9: 6.5656938 | S9: 6.4791978 | T9: 6.2362373
C10: Матричный ACO + AVX + OMP + специальный граф | D10: 14.470863 | E10: 14.484249 | F10: 14.388197 | G10: 14.596136 | H10: 14.750496 | I10: 14.940657 | J10: 15.774984 | M10: Матричный ACO + AVX + OMP + специальный граф | N10: 5.5549882 | O10: 5.4679325 | P10: 5.4163407 | Q10: 5.5235373 | R10: 7.0022093 | S10: 6.3783191 | T10: 5.9653353
C12: non CUDA Time | D12: 13.488689 | E12: 13.233665 | F12: 13.144581 | G12: 13.565861 | H12: 13.762197 | I12: 13.51959 | J12: 13.881868
C13: omp | D13: 14.709432 | E13: 13.817211 | F13: 13.469744 | G13: 13.533619 | H13: 13.655965 | I13: 13.445448 | J13: 14.101019
C14: non CUDA transp Time | D14: 13.921695 | E14: 13.384579 | F14: 13.361316 | G14: 13.598045 | H14: 13.751032 | I14: 13.619507 | J14: 14.263893
C15: non CUDA transp_AVX Time | E15: 13.01456 | F15: 12.987403 | G15: 13.114596 | H15: 13.405729 | I15: 13.060143 | J15: 13.789662
C16: non CUDA transp_AVX_OMP Time | E16: 12.99949 | F16: 12.996861 | G16: 13.132517 | H16: 13.372633 | I16: 13.068005 | J16: 13.787305
C17: Time non CUDA AVX time 4 | D17: 14.04601 | E17: 13.62153 | F17: 13.461813 | G17: 13.943879 | H17: 13.531365 | I17: 13.55571 | J17: 14.195693
C19: non CUDA Time | D19: 12.058184 | E19: 12.15933 | F19: 15.784538 | G19: 12.330576 | H19: 12.780951 | I19: 11.930766 | J19: 12.125269
C20: omp | D20: 12.914742 | E20: 12.54979 | F20: 16.210475 | G20: 12.504401 | H20: 12.953669 | I20: 11.979672 | J20: 12.25493
C21: non CUDA transp Time | D21: 11.895545 | E21: 12.020309 | F21: 15.80453 | G21: 12.384312 | H21: 12.922284 | I21: 12.043599 | J21: 12.395528
C22: non CUDA transp_AVX Time | E22: 11.77579 | F22: 15.577606 | G22: 12.246982 | H22: 12.732155 | I22: 11.972232 | J22: 12.332738
C23: non CUDA transp_AVX_OMP Time | E23: 11.80497 | F23: 15.567342 | G23: 12.250132 | H23: 12.720244 | I23: 11.971241 | J23: 12.332526
C24: Time non CUDA AVX time 4 | D24: 11.8219 | E24: 12.453279 | F24: 16.358656 | G24: 12.894655 | H24: 13.444227 | I24: 12.641835 | J24: 13.1
C26: non CUDA Time | D26: 11.898648 | E26: 12.202972 | F26: 12.161524 | G26: 12.16129 | H26: 11.988787 | I26: 12.276108 | J26: 12.168533
C27: omp | D27: 12.522805 | E27: 12.666325 | F27: 12.428722 | G27: 12.068474 | H27: 11.765758 | I27: 12.168237 | J27: 12.215631
C28: non CUDA transp Time | D28: 11.84306 | E28: 12.147658 | F28: 12.187638 | G28: 11.973437 | H28: 12.339089 | I28: 12.491909 | J28: 12.150987
C29: non CUDA transp_AVX Time | E29: 11.646125 | F29: 11.791034 | G29: 11.611334 | H29: 12.35973 | I29: 12.423243 | J29: 11.509245
C30: non CUDA transp_AVX_OMP Time | E30: 11.631643 | F30: 11.717524 | G30: 11.623149 | H30: 12.047251 | I30: 12.425263 | J30: 12.199688
C31: Time non CUDA AVX time 4 | D31: 10.264582 | E31: 11.401323 | F31: 11.69221 | G31: 11.982197 | H31: 11.884575 | I31: 12.573581 | J31: 12.998158
C33: non CUDA Time | D33: 7.0908056 | E33: 7.0305005 | F33: 6.8192447 | G33: 6.8772192 | H33: 8.0036313 | I33: 6.7722447 | J33: 7.1765932
C34: omp | D34: 7.5021448 | E34: 7.2515123 | F34: 6.9723451 | G34: 6.9449167 | H34: 8.1243314 | I34: 7.1569495 | J34: 7.1323597
C35: non CUDA transp Time | D35: 7.0972838 | E35: 6.9867111 | F35: 6.837988 | G35: 6.8537543 | H35: 8.025932 | I35: 7.1018688 | J35: 7.1112809
C36: non CUDA transp_AVX Time | E36: 5.3774738 | F36: 5.2974162 | G36: 5.4169876 | H36: 6.5580668 | I36: 6.4844296 | J36: 6.405612
C37: non CUDA transp_AVX_OMP Time | E37: 5.397005 | F37: 5.3324099 | G37: 5.4187196 | H37: 6.5656938 | I37: 6.4791978 | J37: 6.2362373
C38: Time non CUDA AVX time 4 | D38: 5.5549882 | E38: 5.4679325 | F38: 5.4163407 | G38: 5.5235373 | H38: 7.0022093 | I38: 6.3783191 | J38: 5.9653353

Sheet Itog_100
A1: 109 | O1: =OFFSET('3060LAPTOP 100'!$C$1,A4-1,0) -> non CUDA AVX Time | Y1: 3
E2: 2 | F2: 4 | G2: 8 | H2: 16 | I2: 32 | J2: 64 | K2: 128 | Q2: 2 | R2: 4 | S2: 8 | T2: 16 | U2: 32 | V2: 64 | W2: 128 | Y2: 32
E3: 42 | F3: 84 | G3: 168 | H3: 336 | I3: 672 | J3: 1344 | K3: 2688 | Q3: 42 | R3: 84 | S3: 168 | T3: 336 | U3: 672 | V3: 1344 | W3: 2688 | Y3: 57
A4: 60 | B4: =OFFSET('3060LAPTOP 100'!$C$1,A4-1,0) -> non CUDA AVX Time | C4: Classic ACO | D4: МО | E4: =OFFSET('3060LAPTOP 10'!D$1,$A5-1,0) -> 6732.0454 | F4: =OFFSET('3060LAPTOP 10'!E$1,$A5-1,0) -> 12795.57 | G4: =OFFSET('3060LAPTOP 10'!F$1,$A5-1,0) -> 24112.532 | H4: =OFFSET('3060LAPTOP 10'!G$1,$A5-1,0) -> 46059.344 | I4: =OFFSET('3060LAPTOP 10'!H$1,$A5-1,0) -> 91907.946 | J4: =OFFSET('3060LAPTOP 10'!I$1,$A5-1,0) -> 184408.08 | K4: =OFFSET('3060LAPTOP 10'!J$1,$A5-1,0) -> 367570.34 | O4: 5 | P4: МО | Q4: =OFFSET('3060LAPTOP 10'!D$1,$A$4-1,0) -> 0 | R4: =OFFSET('3060LAPTOP 10'!E$1,$A$4-1,0) -> 0 | S4: =OFFSET('3060LAPTOP 10'!F$1,$A$4-1,0) -> 0 | T4: =OFFSET('3060LAPTOP 10'!G$1,$A$4-1,0) -> 0 | U4: =OFFSET('3060LAPTOP 10'!H$1,$A$4-1,0) -> 0 | V4: =OFFSET('3060LAPTOP 10'!I$1,$A$4-1,0) -> 0 | W4: =OFFSET('3060LAPTOP 10'!J$1,$A$4-1,0) -> 0
A5: 3 | B5: =OFFSET('3060LAPTOP 10'!$C$1,A5-1,0) -> Classic ACO | D5: ДИ | E5: =OFFSET('3060LAPTOP 10'!D$1,$A5-1+$A$1,0) -> 29.72261 | F5: =OFFSET('3060LAPTOP 10'!E$1,$A5-1+$A$1,0) -> 17.261082 | G5: =OFFSET('3060LAPTOP 10'!F$1,$A5-1+$A$1,0) -> 98.029302 | H5: =OFFSET('3060LAPTOP 10'!G$1,$A5-1+$A$1,0) -> 48.18692 | I5: =OFFSET('3060LAPTOP 10'!H$1,$A5-1+$A$1,0) -> 512.6278 | J5: =OFFSET('3060LAPTOP 10'!I$1,$A5-1+$A$1,0) -> 775.06198 | K5: =OFFSET('3060LAPTOP 10'!J$1,$A5-1+$A$1,0) -> 1357.5707 | P5: ДИ | Q5: =OFFSET('3060LAPTOP 10'!D$1,$A$4-1+$A$1,0) -> 0 | R5: =OFFSET('3060LAPTOP 10'!E$1,$A$4-1+$A$1,0) -> 0 | S5: =OFFSET('3060LAPTOP 10'!F$1,$A$4-1+$A$1,0) -> 0 | T5: =OFFSET('3060LAPTOP 10'!G$1,$A$4-1+$A$1,0) -> 0 | U5: =OFFSET('3060LAPTOP 10'!H$1,$A$4-1+$A$1,0) -> 0 | V5: =OFFSET('3060LAPTOP 10'!I$1,$A$4-1+$A$1,0) -> 0 | W5: =OFFSET('3060LAPTOP 10'!J$1,$A$4-1+$A$1,0) -> 0
A6: 4 | B6: =OFFSET('3060LAPTOP 10'!$C$1,A6-1,0) -> non CUDA Time | C6: Matrix ACO | D6: МО | E6: =OFFSET('3060LAPTOP 10'!D$1,$A6-1,0) -> 565.78236 | F6: =OFFSET('3060LAPTOP 10'!E$1,$A6-1,0) -> 1048.5618 | G6: =OFFSET('3060LAPTOP 10'!F$1,$A6-1,0) -> 1982.69 | H6: =OFFSET('3060LAPTOP 10'!G$1,$A6-1,0) -> 3787.3732 | I6: =OFFSET('3060LAPTOP 10'!H$1,$A6-1,0) -> 7666.159 | J6: =OFFSET('3060LAPTOP 10'!I$1,$A6-1,0) -> 15021.706 | K6: =OFFSET('3060LAPTOP 10'!J$1,$A6-1,0) -> 30206.626 | O6: 100 | P6: МО | Q6: =OFFSET('3060LAPTOP 100'!D$1,$A$4-1,0) -> 15.925028 | R6: =OFFSET('3060LAPTOP 100'!E$1,$A$4-1,0) -> 19.213642 | S6: =OFFSET('3060LAPTOP 100'!F$1,$A$4-1,0) -> 20.89692 | T6: =OFFSET('3060LAPTOP 100'!G$1,$A$4-1,0) -> 21.533306 | U6: =OFFSET('3060LAPTOP 100'!H$1,$A$4-1,0) -> 19.015856 | V6: =OFFSET('3060LAPTOP 100'!I$1,$A$4-1,0) -> 20.967085 | W6: =OFFSET('3060LAPTOP 100'!J$1,$A$4-1,0) -> 22.907659
D7: ДИ | E7: =OFFSET('3060LAPTOP 10'!D$1,$A6-1+$A$1,0) -> 4.162287 | F7: =OFFSET('3060LAPTOP 10'!E$1,$A6-1+$A$1,0) -> 4.1114063 | G7: =OFFSET('3060LAPTOP 10'!F$1,$A6-1+$A$1,0) -> 9.9600752 | H7: =OFFSET('3060LAPTOP 10'!G$1,$A6-1+$A$1,0) -> 10.371022 | I7: =OFFSET('3060LAPTOP 10'!H$1,$A6-1+$A$1,0) -> 60.114895 | J7: =OFFSET('3060LAPTOP 10'!I$1,$A6-1+$A$1,0) -> 32.345265 | K7: =OFFSET('3060LAPTOP 10'!J$1,$A6-1+$A$1,0) -> 64.000996 | P7: ДИ | Q7: =OFFSET('3060LAPTOP 100'!D$1,$A$4-1+$A$1,0) -> 0 | R7: =OFFSET('3060LAPTOP 100'!E$1,$A$4-1+$A$1,0) -> 0 | S7: =OFFSET('3060LAPTOP 100'!F$1,$A$4-1+$A$1,0) -> 0 | T7: =OFFSET('3060LAPTOP 100'!G$1,$A$4-1+$A$1,0) -> 0 | U7: =OFFSET('3060LAPTOP 100'!H$1,$A$4-1+$A$1,0) -> 0 | V7: =OFFSET('3060LAPTOP 100'!I$1,$A$4-1+$A$1,0) -> 0 | W7: =OFFSET('3060LAPTOP 100'!J$1,$A$4-1+$A$1,0) -> 0
A8: 5 | B8: =OFFSET('3060LAPTOP 10'!$C$1,A8-1,0) -> omp | C8: Matrix ACO + OMP | D8: МО | E8: =OFFSET('3060LAPTOP 10'!D$1,$A8-1,0) -> 537.58286 | F8: =OFFSET('3060LAPTOP 10'!E$1,$A8-1,0) -> 1010.2038 | G8: =OFFSET('3060LAPTOP 10'!F$1,$A8-1,0) -> 1940.0652 | H8: =OFFSET('3060LAPTOP 10'!G$1,$A8-1,0) -> 3816.501 | I8: =OFFSET('3060LAPTOP 10'!H$1,$A8-1,0) -> 7811.4766 | J8: =OFFSET('3060LAPTOP 10'!I$1,$A8-1,0) -> 15154.872 | K8: =OFFSET('3060LAPTOP 10'!J$1,$A8-1,0) -> 30090.164 | O8: 1000 | P8: МО | Q8: =OFFSET('3060LAPTOP 1000'!D$1,$A$4-1,0) -> 19.635403 | R8: =OFFSET('3060LAPTOP 1000'!E$1,$A$4-1,0) -> 23.324759 | S8: =OFFSET('3060LAPTOP 1000'!F$1,$A$4-1,0) -> 28.373104 | T8: =OFFSET('3060LAPTOP 1000'!G$1,$A$4-1,0) -> 29.57483
D9: ДИ | E9: =OFFSET('3060LAPTOP 10'!D$1,$A8-1+$A$1,0) -> 4.5095966 | F9: =OFFSET('3060LAPTOP 10'!E$1,$A8-1+$A$1,0) -> 2.6951641 | G9: =OFFSET('3060LAPTOP 10'!F$1,$A8-1+$A$1,0) -> 2.3080237 | H9: =OFFSET('3060LAPTOP 10'!G$1,$A8-1+$A$1,0) -> 8.7723176 | I9: =OFFSET('3060LAPTOP 10'!H$1,$A8-1+$A$1,0) -> 17.021157 | J9: =OFFSET('3060LAPTOP 10'!I$1,$A8-1+$A$1,0) -> 24.822803 | K9: =OFFSET('3060LAPTOP 10'!J$1,$A8-1+$A$1,0) -> 31.215446 | P9: ДИ | Q9: =OFFSET('3060LAPTOP 1000'!D$1,$A$4-1+$A$1,0) -> 0 | R9: =OFFSET('3060LAPTOP 1000'!E$1,$A$4-1+$A$1,0) -> 0 | S9: =OFFSET('3060LAPTOP 1000'!F$1,$A$4-1+$A$1,0) -> 0 | T9: =OFFSET('3060LAPTOP 1000'!G$1,$A$4-1+$A$1,0) -> 0
A10: 6 | B10: =OFFSET('3060LAPTOP 10'!$C$1,A10-1,0) -> 0 | D10: МО | E10: =OFFSET('3060LAPTOP 10'!D$1,$A10-1,0) -> 0 | F10: =OFFSET('3060LAPTOP 10'!E$1,$A10-1,0) -> 0 | G10: =OFFSET('3060LAPTOP 10'!F$1,$A10-1,0) -> 0 | H10: =OFFSET('3060LAPTOP 10'!G$1,$A10-1,0) -> 0 | I10: =OFFSET('3060LAPTOP 10'!H$1,$A10-1,0) -> 0 | J10: =OFFSET('3060LAPTOP 10'!I$1,$A10-1,0) -> 0 | K10: =OFFSET('3060LAPTOP 10'!J$1,$A10-1,0) -> 0 | O10: 10000 | P10: МО | Q10: =OFFSET('3060LAPTOP 10000'!D$1,$A$4-1,0) -> 33.794018 | R10: =OFFSET('3060LAPTOP 10000'!E$1,$A$4-1,0) -> 47.950971 | S10: =OFFSET('3060LAPTOP 10000'!F$1,$A$4-1,0) -> 33.248451
D11: ДИ | E11: =OFFSET('3060LAPTOP 10'!D$1,$A10-1+$A$1,0) -> 0 | F11: =OFFSET('3060LAPTOP 10'!E$1,$A10-1+$A$1,0) -> 0 | G11: =OFFSET('3060LAPTOP 10'!F$1,$A10-1+$A$1,0) -> 0 | H11: =OFFSET('3060LAPTOP 10'!G$1,$A10-1+$A$1,0) -> 0 | I11: =OFFSET('3060LAPTOP 10'!H$1,$A10-1+$A$1,0) -> 0 | J11: =OFFSET('3060LAPTOP 10'!I$1,$A10-1+$A$1,0) -> 0 | K11: =OFFSET('3060LAPTOP 10'!J$1,$A10-1+$A$1,0) -> 0 | P11: ДИ | Q11: =OFFSET('3060LAPTOP 10000'!D$1,$A$4-1+$A$1,0) -> 0 | R11: =OFFSET('3060LAPTOP 10000'!E$1,$A$4-1+$A$1,0) -> 0 | S11: =OFFSET('3060LAPTOP 10000'!F$1,$A$4-1+$A$1,0) -> 0
A12: 7 | B12: =OFFSET('3060LAPTOP 10'!$C$1,A12-1,0) -> 0 | D12: МО | E12: =OFFSET('3060LAPTOP 10'!D$1,$A12-1,0) -> 0 | F12: =OFFSET('3060LAPTOP 10'!E$1,$A12-1,0) -> 0 | G12: =OFFSET('3060LAPTOP 10'!F$1,$A12-1,0) -> 0 | H12: =OFFSET('3060LAPTOP 10'!G$1,$A12-1,0) -> 0 | I12: =OFFSET('3060LAPTOP 10'!H$1,$A12-1,0) -> 0 | J12: =OFFSET('3060LAPTOP 10'!I$1,$A12-1,0) -> 0 | K12: =OFFSET('3060LAPTOP 10'!J$1,$A12-1,0) -> 0
D13: ДИ | E13: =OFFSET('3060LAPTOP 10'!D$1,$A12-1+$A$1,0) -> 0 | F13: =OFFSET('3060LAPTOP 10'!E$1,$A12-1+$A$1,0) -> 0 | G13: =OFFSET('3060LAPTOP 10'!F$1,$A12-1+$A$1,0) -> 0 | H13: =OFFSET('3060LAPTOP 10'!G$1,$A12-1+$A$1,0) -> 0 | I13: =OFFSET('3060LAPTOP 10'!H$1,$A12-1+$A$1,0) -> 0 | J13: =OFFSET('3060LAPTOP 10'!I$1,$A12-1+$A$1,0) -> 0 | K13: =OFFSET('3060LAPTOP 10'!J$1,$A12-1+$A$1,0) -> 0
A14: 8 | B14: =OFFSET('3060LAPTOP 10'!$C$1,A14-1,0) -> non CUDA transp Time | C14: Transp Matrix ACO | D14: МО | E14: =OFFSET('3060LAPTOP 10'!D$1,$A14-1,0) -> 568.438 | F14: =OFFSET('3060LAPTOP 10'!E$1,$A14-1,0) -> 1053.3364 | G14: =OFFSET('3060LAPTOP 10'!F$1,$A14-1,0) -> 1978.4418 | H14: =OFFSET('3060LAPTOP 10'!G$1,$A14-1,0) -> 3846.794 | I14: =OFFSET('3060LAPTOP 10'!H$1,$A14-1,0) -> 7448.5196 | J14: =OFFSET('3060LAPTOP 10'!I$1,$A14-1,0) -> 14762.202 | K14: =OFFSET('3060LAPTOP 10'!J$1,$A14-1,0) -> 30250.246
D15: ДИ | E15: =OFFSET('3060LAPTOP 10'!D$1,$A14-1+$A$1,0) -> 1.8204707 | F15: =OFFSET('3060LAPTOP 10'!E$1,$A14-1+$A$1,0) -> 3.8753483 | G15: =OFFSET('3060LAPTOP 10'!F$1,$A14-1+$A$1,0) -> 4.5432578 | H15: =OFFSET('3060LAPTOP 10'!G$1,$A14-1+$A$1,0) -> 10.662725 | I15: =OFFSET('3060LAPTOP 10'!H$1,$A14-1+$A$1,0) -> 54.370394 | J15: =OFFSET('3060LAPTOP 10'!I$1,$A14-1+$A$1,0) -> 42.063281 | K15: =OFFSET('3060LAPTOP 10'!J$1,$A14-1+$A$1,0) -> 267.89042
A16: 9 | B16: =OFFSET('3060LAPTOP 10'!$C$1,A16-1,0) -> non CUDA transp_AVX Time | C16: Transp Matrix ACO + AVX | D16: МО | E16: =OFFSET('3060LAPTOP 10'!D$1,$A16-1,0) -> 0 | F16: =OFFSET('3060LAPTOP 10'!E$1,$A16-1,0) -> 1098.6976 | G16: =OFFSET('3060LAPTOP 10'!F$1,$A16-1,0) -> 2044.9888 | H16: =OFFSET('3060LAPTOP 10'!G$1,$A16-1,0) -> 3966.7574 | I16: =OFFSET('3060LAPTOP 10'!H$1,$A16-1,0) -> 7436.0804 | J16: =OFFSET('3060LAPTOP 10'!I$1,$A16-1,0) -> 14843.796 | K16: =OFFSET('3060LAPTOP 10'!J$1,$A16-1,0) -> 31936.964
D17: ДИ | E17: =OFFSET('3060LAPTOP 10'!D$1,$A16-1+$A$1,0) -> #DIV/0! | F17: =OFFSET('3060LAPTOP 10'!E$1,$A16-1+$A$1,0) -> 2.8504952 | G17: =OFFSET('3060LAPTOP 10'!F$1,$A16-1+$A$1,0) -> 5.3846166 | H17: =OFFSET('3060LAPTOP 10'!G$1,$A16-1+$A$1,0) -> 8.9149103 | I17: =OFFSET('3060LAPTOP 10'!H$1,$A16-1+$A$1,0) -> 24.151619 | J17: =OFFSET('3060LAPTOP 10'!I$1,$A16-1+$A$1,0) -> 35.840002 | K17: =OFFSET('3060LAPTOP 10'!J$1,$A16-1+$A$1,0) -> 374.98378
A18: 10 | B18: =OFFSET('3060LAPTOP 10'!$C$1,A18-1,0) -> non CUDA transp_AVX_OMP Time | C18: Transp Matrix ACO + AVX + OPM | D18: МО | E18: =OFFSET('3060LAPTOP 10'!D$1,$A18-1,0) -> 0 | F18: =OFFSET('3060LAPTOP 10'!E$1,$A18-1,0) -> 1100.0656 | G18: =OFFSET('3060LAPTOP 10'!F$1,$A18-1,0) -> 2057.818 | H18: =OFFSET('3060LAPTOP 10'!G$1,$A18-1,0) -> 3962.725 | I18: =OFFSET('3060LAPTOP 10'!H$1,$A18-1,0) -> 7628.956 | J18: =OFFSET('3060LAPTOP 10'!I$1,$A18-1,0) -> 14841.382 | K18: =OFFSET('3060LAPTOP 10'!J$1,$A18-1,0) -> 30129.486
D19: ДИ | E19: =OFFSET('3060LAPTOP 10'!D$1,$A18-1+$A$1,0) -> #DIV/0! | F19: =OFFSET('3060LAPTOP 10'!E$1,$A18-1+$A$1,0) -> 2.8913993 | G19: =OFFSET('3060LAPTOP 10'!F$1,$A18-1+$A$1,0) -> 4.938096 | H19: =OFFSET('3060LAPTOP 10'!G$1,$A18-1+$A$1,0) -> 7.4898968 | I19: =OFFSET('3060LAPTOP 10'!H$1,$A18-1+$A$1,0) -> 97.841238 | J19: =OFFSET('3060LAPTOP 10'!I$1,$A18-1+$A$1,0) -> 37.562936 | K19: =OFFSET('3060LAPTOP 10'!J$1,$A18-1+$A$1,0) -> 53.077585
A20: 3 | B20: =OFFSET('3060LAPTOP 100'!$C$1,A20-1,0) -> Classic ACO | C20: Classic ACO | D20: МО | E20: =OFFSET('3060LAPTOP 100'!D$1,$A20-1,0) -> 6150.9388 | F20: =OFFSET('3060LAPTOP 100'!E$1,$A20-1,0) -> 11699.452 | G20: =OFFSET('3060LAPTOP 100'!F$1,$A20-1,0) -> 21907.942 | H20: =OFFSET('3060LAPTOP 100'!G$1,$A20-1,0) -> 42192.442 | I20: =OFFSET('3060LAPTOP 100'!H$1,$A20-1,0) -> 84585.998 | J20: =OFFSET('3060LAPTOP 100'!I$1,$A20-1,0) -> 167119.54 | K20: =OFFSET('3060LAPTOP 100'!J$1,$A20-1,0) -> 334990.88
D21: ДИ | E21: =OFFSET('3060LAPTOP 100'!D$1,$A20-1+$A$1,0) -> 79.627185 | F21: =OFFSET('3060LAPTOP 100'!E$1,$A20-1+$A$1,0) -> 103.75779 | G21: =OFFSET('3060LAPTOP 100'!F$1,$A20-1+$A$1,0) -> 548.80687 | H21: =OFFSET('3060LAPTOP 100'!G$1,$A20-1+$A$1,0) -> 104.07401 | I21: =OFFSET('3060LAPTOP 100'!H$1,$A20-1+$A$1,0) -> 495.75429 | J21: =OFFSET('3060LAPTOP 100'!I$1,$A20-1+$A$1,0) -> 117.81389 | K21: =OFFSET('3060LAPTOP 100'!J$1,$A20-1+$A$1,0) -> 363.76748
A22: 4 | B22: =OFFSET('3060LAPTOP 100'!$C$1,A22-1,0) -> non CUDA Time | C22: Matrix ACO | D22: МО | E22: =OFFSET('3060LAPTOP 100'!D$1,$A22-1,0) -> 377.87502 | F22: =OFFSET('3060LAPTOP 100'!E$1,$A22-1,0) -> 628.52904 | G22: =OFFSET('3060LAPTOP 100'!F$1,$A22-1,0) -> 1019.9844 | H22: =OFFSET('3060LAPTOP 100'!G$1,$A22-1,0) -> 1919.3218 | I22: =OFFSET('3060LAPTOP 100'!H$1,$A22-1,0) -> 3993.9212 | J22: =OFFSET('3060LAPTOP 100'!I$1,$A22-1,0) -> 7926.0674 | K22: =OFFSET('3060LAPTOP 100'!J$1,$A22-1,0) -> 14356.124
D23: ДИ | E23: =OFFSET('3060LAPTOP 100'!D$1,$A22-1+$A$1,0) -> 11.311722 | F23: =OFFSET('3060LAPTOP 100'!E$1,$A22-1+$A$1,0) -> 11.570179 | G23: =OFFSET('3060LAPTOP 100'!F$1,$A22-1+$A$1,0) -> 11.157862 | H23: =OFFSET('3060LAPTOP 100'!G$1,$A22-1+$A$1,0) -> 12.959429 | I23: =OFFSET('3060LAPTOP 100'!H$1,$A22-1+$A$1,0) -> 26.157707 | J23: =OFFSET('3060LAPTOP 100'!I$1,$A22-1+$A$1,0) -> 44.148906 | K23: =OFFSET('3060LAPTOP 100'!J$1,$A22-1+$A$1,0) -> 67.453153
A24: 5 | B24: =OFFSET('3060LAPTOP 100'!$C$1,A24-1,0) -> omp | C24: Matrix ACO + OMP | D24: МО | E24: =OFFSET('3060LAPTOP 100'!D$1,$A24-1,0) -> 292.0631 | F24: =OFFSET('3060LAPTOP 100'!E$1,$A24-1,0) -> 525.01036 | G24: =OFFSET('3060LAPTOP 100'!F$1,$A24-1,0) -> 921.35106 | H24: =OFFSET('3060LAPTOP 100'!G$1,$A24-1,0) -> 1785.4644 | I24: =OFFSET('3060LAPTOP 100'!H$1,$A24-1,0) -> 4317.2568 | J24: =OFFSET('3060LAPTOP 100'!I$1,$A24-1,0) -> 7838.8054 | K24: =OFFSET('3060LAPTOP 100'!J$1,$A24-1,0) -> 14374.004
D25: ДИ | E25: =OFFSET('3060LAPTOP 100'!D$1,$A24-1+$A$1,0) -> 1.5476465 | F25: =OFFSET('3060LAPTOP 100'!E$1,$A24-1+$A$1,0) -> 7.1101134 | G25: =OFFSET('3060LAPTOP 100'!F$1,$A24-1+$A$1,0) -> 4.056149 | H25: =OFFSET('3060LAPTOP 100'!G$1,$A24-1+$A$1,0) -> 7.3240946 | I25: =OFFSET('3060LAPTOP 100'!H$1,$A24-1+$A$1,0) -> 68.173488 | J25: =OFFSET('3060LAPTOP 100'!I$1,$A24-1+$A$1,0) -> 39.789862 | K25: =OFFSET('3060LAPTOP 100'!J$1,$A24-1+$A$1,0) -> 39.506517
A26: 6 | B26: =OFFSET('3060LAPTOP 100'!$C$1,A26-1,0) -> non CUDA AVX Time | C26: Matrix ACO + AVX | D26: МО | E26: =OFFSET('3060LAPTOP 100'!D$1,$A26-1,0) -> 386.24352 | F26: =OFFSET('3060LAPTOP 100'!E$1,$A26-1,0) -> 608.9138 | G26: =OFFSET('3060LAPTOP 100'!F$1,$A26-1,0) -> 1048.3814 | H26: =OFFSET('3060LAPTOP 100'!G$1,$A26-1,0) -> 1959.4038 | I26: =OFFSET('3060LAPTOP 100'!H$1,$A26-1,0) -> 4448.1824 | J26: =OFFSET('3060LAPTOP 100'!I$1,$A26-1,0) -> 7970.5664 | K26: =OFFSET('3060LAPTOP 100'!J$1,$A26-1,0) -> 14623.532
D27: ДИ | E27: =OFFSET('3060LAPTOP 100'!D$1,$A26-1+$A$1,0) -> 3.2499856 | F27: =OFFSET('3060LAPTOP 100'!E$1,$A26-1+$A$1,0) -> 3.3119198 | G27: =OFFSET('3060LAPTOP 100'!F$1,$A26-1+$A$1,0) -> 8.3815579 | H27: =OFFSET('3060LAPTOP 100'!G$1,$A26-1+$A$1,0) -> 8.4971803 | I27: =OFFSET('3060LAPTOP 100'!H$1,$A26-1+$A$1,0) -> 14.832656 | J27: =OFFSET('3060LAPTOP 100'!I$1,$A26-1+$A$1,0) -> 40.630595 | K27: =OFFSET('3060LAPTOP 100'!J$1,$A26-1+$A$1,0) -> 47.600011
A28: 7 | B28: =OFFSET('3060LAPTOP 100'!$C$1,A28-1,0) -> non CUDA AVX_OMP Time | C28: Matrix ACO + AVX + OMP | D28: МО | E28: =OFFSET('3060LAPTOP 100'!D$1,$A28-1,0) -> 261.53294 | F28: =OFFSET('3060LAPTOP 100'!E$1,$A28-1,0) -> 472.43312 | G28: =OFFSET('3060LAPTOP 100'!F$1,$A28-1,0) -> 878.0744 | H28: =OFFSET('3060LAPTOP 100'!G$1,$A28-1,0) -> 1787.109 | I28: =OFFSET('3060LAPTOP 100'!H$1,$A28-1,0) -> 4006.3106 | J28: =OFFSET('3060LAPTOP 100'!I$1,$A28-1,0) -> 7005.3984 | K28: =OFFSET('3060LAPTOP 100'!J$1,$A28-1,0) -> 15607.48
D29: ДИ | E29: =OFFSET('3060LAPTOP 100'!D$1,$A28-1+$A$1,0) -> 1.3801452 | F29: =OFFSET('3060LAPTOP 100'!E$1,$A28-1+$A$1,0) -> 1.7078183 | G29: =OFFSET('3060LAPTOP 100'!F$1,$A28-1+$A$1,0) -> 1.7094217 | H29: =OFFSET('3060LAPTOP 100'!G$1,$A28-1+$A$1,0) -> 3.9946456 | I29: =OFFSET('3060LAPTOP 100'!H$1,$A28-1+$A$1,0) -> 16.975104 | J29: =OFFSET('3060LAPTOP 100'!I$1,$A28-1+$A$1,0) -> 32.606325 | K29: =OFFSET('3060LAPTOP 100'!J$1,$A28-1+$A$1,0) -> 53.502234
A30: 8 | B30: =OFFSET('3060LAPTOP 100'!$C$1,A30-1,0) -> non CUDA transp Time | C30: Transp Matrix ACO | D30: МО | E30: =OFFSET('3060LAPTOP 100'!D$1,$A30-1,0) -> 361.17894 | F30: =OFFSET('3060LAPTOP 100'!E$1,$A30-1,0) -> 600.7946 | G30: =OFFSET('3060LAPTOP 100'!F$1,$A30-1,0) -> 1048.018 | H30: =OFFSET('3060LAPTOP 100'!G$1,$A30-1,0) -> 1917.3048 | I30: =OFFSET('3060LAPTOP 100'!H$1,$A30-1,0) -> 4471.6644 | J30: =OFFSET('3060LAPTOP 100'!I$1,$A30-1,0) -> 7685.0462 | K30: =OFFSET('3060LAPTOP 100'!J$1,$A30-1,0) -> 16599.42
D31: ДИ | E31: =OFFSET('3060LAPTOP 100'!D$1,$A30-1+$A$1,0) -> 3.4910542 | F31: =OFFSET('3060LAPTOP 100'!E$1,$A30-1+$A$1,0) -> 5.8646902 | G31: =OFFSET('3060LAPTOP 100'!F$1,$A30-1+$A$1,0) -> 12.606187 | H31: =OFFSET('3060LAPTOP 100'!G$1,$A30-1+$A$1,0) -> 4.9558833 | I31: =OFFSET('3060LAPTOP 100'!H$1,$A30-1+$A$1,0) -> 16.655409 | J31: =OFFSET('3060LAPTOP 100'!I$1,$A30-1+$A$1,0) -> 14.958921 | K31: =OFFSET('3060LAPTOP 100'!J$1,$A30-1+$A$1,0) -> 29.110331
A32: 9 | B32: =OFFSET('3060LAPTOP 100'!$C$1,A32-1,0) -> non CUDA transp_AVX Time | C32: Transp Matrix ACO + AVX | D32: МО | E32: =OFFSET('3060LAPTOP 100'!D$1,$A32-1,0) -> 394.9219 | F32: =OFFSET('3060LAPTOP 100'!E$1,$A32-1,0) -> 633.21774 | G32: =OFFSET('3060LAPTOP 100'!F$1,$A32-1,0) -> 1081.4722 | H32: =OFFSET('3060LAPTOP 100'!G$1,$A32-1,0) -> 2050.7576 | I32: =OFFSET('3060LAPTOP 100'!H$1,$A32-1,0) -> 4547.41 | J32: =OFFSET('3060LAPTOP 100'!I$1,$A32-1,0) -> 7768.6138 | K32: =OFFSET('3060LAPTOP 100'!J$1,$A32-1,0) -> 16659.336
D33: ДИ | E33: =OFFSET('3060LAPTOP 100'!D$1,$A32-1+$A$1,0) -> 3.828803 | F33: =OFFSET('3060LAPTOP 100'!E$1,$A32-1+$A$1,0) -> 4.9582398 | G33: =OFFSET('3060LAPTOP 100'!F$1,$A32-1+$A$1,0) -> 6.2008624 | H33: =OFFSET('3060LAPTOP 100'!G$1,$A32-1+$A$1,0) -> 5.564167 | I33: =OFFSET('3060LAPTOP 100'!H$1,$A32-1+$A$1,0) -> 12.872022 | J33: =OFFSET('3060LAPTOP 100'!I$1,$A32-1+$A$1,0) -> 25.412145 | K33: =OFFSET('3060LAPTOP 100'!J$1,$A32-1+$A$1,0) -> 32.512805
A34: 10 | B34: =OFFSET('3060LAPTOP 100'!$C$1,A34-1,0) -> non CUDA transp_AVX_OMP Time | C34: Transp Matrix ACO + AVX + OPM | D34: МО | E34: =OFFSET('3060LAPTOP 100'!D$1,$A34-1,0) -> 393.51114 | F34: =OFFSET('3060LAPTOP 100'!E$1,$A34-1,0) -> 632.0437 | G34: =OFFSET('3060LAPTOP 100'!F$1,$A34-1,0) -> 1095.9862 | H34: =OFFSET('3060LAPTOP 100'!G$1,$A34-1,0) -> 2033.1584 | I34: =OFFSET('3060LAPTOP 100'!H$1,$A34-1,0) -> 4555.7548 | J34: =OFFSET('3060LAPTOP 100'!I$1,$A34-1,0) -> 7755.5442 | K34: =OFFSET('3060LAPTOP 100'!J$1,$A34-1,0) -> 16691.11
D35: ДИ | E35: =OFFSET('3060LAPTOP 100'!D$1,$A34-1+$A$1,0) -> 4.0252017 | F35: =OFFSET('3060LAPTOP 100'!E$1,$A34-1+$A$1,0) -> 3.6597519 | G35: =OFFSET('3060LAPTOP 100'!F$1,$A34-1+$A$1,0) -> 8.0015198 | H35: =OFFSET('3060LAPTOP 100'!G$1,$A34-1+$A$1,0) -> 5.5888277 | I35: =OFFSET('3060LAPTOP 100'!H$1,$A34-1+$A$1,0) -> 13.120159 | J35: =OFFSET('3060LAPTOP 100'!I$1,$A34-1+$A$1,0) -> 15.502058 | K35: =OFFSET('3060LAPTOP 100'!J$1,$A34-1+$A$1,0) -> 26.473442
A36: 3 | B36: =OFFSET('3060LAPTOP 1000'!$C$1,A36-1,0) -> Classic ACO | C36: Classic ACO | D36: МО | E36: =OFFSET('3060LAPTOP 1000'!D$1,$A36-1,0) -> 24196.248 | F36: =OFFSET('3060LAPTOP 1000'!E$1,$A36-1,0) -> 47270.152 | G36: =OFFSET('3060LAPTOP 1000'!F$1,$A36-1,0) -> 94088.622 | H36: =OFFSET('3060LAPTOP 1000'!G$1,$A36-1,0) -> 187213.28 | I36: =OFFSET('3060LAPTOP 1000'!H$1,$A36-1,0) -> 0 | J36: =OFFSET('3060LAPTOP 1000'!I$1,$A36-1,0) -> 0 | K36: =OFFSET('3060LAPTOP 1000'!J$1,$A36-1,0) -> 0
D37: ДИ | E37: =OFFSET('3060LAPTOP 1000'!D$1,$A36-1+$A$1,0) -> 147.55029 | F37: =OFFSET('3060LAPTOP 1000'!E$1,$A36-1+$A$1,0) -> 126.61606 | G37: =OFFSET('3060LAPTOP 1000'!F$1,$A36-1+$A$1,0) -> 654.50318 | H37: =OFFSET('3060LAPTOP 1000'!G$1,$A36-1+$A$1,0) -> 303.97216 | I37: =OFFSET('3060LAPTOP 1000'!H$1,$A36-1+$A$1,0) -> 0 | J37: =OFFSET('3060LAPTOP 1000'!I$1,$A36-1+$A$1,0) -> 0 | K37: =OFFSET('3060LAPTOP 1000'!J$1,$A36-1+$A$1,0) -> 0
A38: 4 | B38: =OFFSET('3060LAPTOP 1000'!$C$1,A38-1,0) -> non CUDA Time | C38: Matrix ACO | D38: МО | E38: =OFFSET('3060LAPTOP 1000'!D$1,$A38-1,0) -> 1244.8464 | F38: =OFFSET('3060LAPTOP 1000'!E$1,$A38-1,0) -> 1969.7956 | G38: =OFFSET('3060LAPTOP 1000'!F$1,$A38-1,0) -> 3308.7164 | H38: =OFFSET('3060LAPTOP 1000'!G$1,$A38-1,0) -> 6320.3386 | I38: =OFFSET('3060LAPTOP 1000'!H$1,$A38-1,0) -> 0 | J38: =OFFSET('3060LAPTOP 1000'!I$1,$A38-1,0) -> 0 | K38: =OFFSET('3060LAPTOP 1000'!J$1,$A38-1,0) -> 0
D39: ДИ | E39: =OFFSET('3060LAPTOP 1000'!D$1,$A38-1+$A$1,0) -> 10.366439 | F39: =OFFSET('3060LAPTOP 1000'!E$1,$A38-1+$A$1,0) -> 11.484492 | G39: =OFFSET('3060LAPTOP 1000'!F$1,$A38-1+$A$1,0) -> 23.807976 | H39: =OFFSET('3060LAPTOP 1000'!G$1,$A38-1+$A$1,0) -> 33.315389 | I39: =OFFSET('3060LAPTOP 1000'!H$1,$A38-1+$A$1,0) -> 0 | J39: =OFFSET('3060LAPTOP 1000'!I$1,$A38-1+$A$1,0) -> 0 | K39: =OFFSET('3060LAPTOP 1000'!J$1,$A38-1+$A$1,0) -> 0
A40: 5 | B40: =OFFSET('3060LAPTOP 1000'!$C$1,A40-1,0) -> omp | C40: Matrix ACO + OMP | D40: МО | E40: =OFFSET('3060LAPTOP 1000'!D$1,$A40-1,0) -> 706.01596 | F40: =OFFSET('3060LAPTOP 1000'!E$1,$A40-1,0) -> 1300.9078 | G40: =OFFSET('3060LAPTOP 1000'!F$1,$A40-1,0) -> 2619.494 | H40: =OFFSET('3060LAPTOP 1000'!G$1,$A40-1,0) -> 5415.8602 | I40: =OFFSET('3060LAPTOP 1000'!H$1,$A40-1,0) -> 0 | J40: =OFFSET('3060LAPTOP 1000'!I$1,$A40-1,0) -> 0 | K40: =OFFSET('3060LAPTOP 1000'!J$1,$A40-1,0) -> 0
...

Sheet Itog
A1: 109 | O1: =OFFSET('1050LAPTOP'!$C$1,A4-1,0) -> non CUDA Time | Y1: 3
E2: 2 | F2: 4 | G2: 8 | H2: 16 | I2: 32 | J2: 64 | K2: 128 | Q2: 2 | R2: 4 | S2: 8 | T2: 16 | U2: 32 | V2: 64 | W2: 128 | Y2: 32
E3: 42 | F3: 84 | G3: 168 | H3: 336 | I3: 672 | J3: 1344 | K3: 2688 | Q3: 42 | R3: 84 | S3: 168 | T3: 336 | U3: 672 | V3: 1344 | W3: 2688 | Y3: 57
A4: 4 | B4: =OFFSET('1050LAPTOP'!$C$1,A4-1,0) -> non CUDA Time | C4: Classic ACO | D4: МО | E4: =OFFSET('1050LAPTOP'!D$1,$A5-1,0) -> 14722.332 | F4: =OFFSET('1050LAPTOP'!E$1,$A5-1,0) -> 27364.668 | G4: =OFFSET('1050LAPTOP'!F$1,$A5-1,0) -> 52186.786 | H4: =OFFSET('1050LAPTOP'!G$1,$A5-1,0) -> 103402.44 | I4: =OFFSET('1050LAPTOP'!H$1,$A5-1,0) -> 207103.36 | J4: =OFFSET('1050LAPTOP'!I$1,$A5-1,0) -> 410463.68 | K4: =OFFSET('1050LAPTOP'!J$1,$A5-1,0) -> 835652.72 | O4: i5-8300H | P4: МО | Q4: =OFFSET('1050LAPTOP'!D$1,$A$4-1,0) -> 1012.9384 | R4: =OFFSET('1050LAPTOP'!E$1,$A$4-1,0) -> 1856.1192 | S4: =OFFSET('1050LAPTOP'!F$1,$A$4-1,0) -> 3594.4352 | T4: =OFFSET('1050LAPTOP'!G$1,$A$4-1,0) -> 7098.9368 | U4: =OFFSET('1050LAPTOP'!H$1,$A$4-1,0) -> 13991.566 | V4: =OFFSET('1050LAPTOP'!I$1,$A$4-1,0) -> 27308.064 | W4: =OFFSET('1050LAPTOP'!J$1,$A$4-1,0) -> 53372.172
A5: 3 | B5: =OFFSET('1050LAPTOP'!$C$1,A5-1,0) -> Classic ACO | D5: ДИ | E5: =OFFSET('1050LAPTOP'!D$1,$A5-1+$A$1,0) -> 22.860765 | F5: =OFFSET('1050LAPTOP'!E$1,$A5-1+$A$1,0) -> 51.041297 | G5: =OFFSET('1050LAPTOP'!F$1,$A5-1+$A$1,0) -> 76.375325 | H5: =OFFSET('1050LAPTOP'!G$1,$A5-1+$A$1,0) -> 162.45697 | I5: =OFFSET('1050LAPTOP'!H$1,$A5-1+$A$1,0) -> 3688.3616 | J5: =OFFSET('1050LAPTOP'!I$1,$A5-1+$A$1,0) -> 581.6763 | K5: =OFFSET('1050LAPTOP'!J$1,$A5-1+$A$1,0) -> 2479.4143 | P5: ДИ | Q5: =OFFSET('1050LAPTOP'!D$1,$A$4-1+$A$1,0) -> 2.9942752 | R5: =OFFSET('1050LAPTOP'!E$1,$A$4-1+$A$1,0) -> 2.9249996 | S5: =OFFSET('1050LAPTOP'!F$1,$A$4-1+$A$1,0) -> 6.463698 | T5: =OFFSET('1050LAPTOP'!G$1,$A$4-1+$A$1,0) -> 6.1107565 | U5: =OFFSET('1050LAPTOP'!H$1,$A$4-1+$A$1,0) -> 8.2559854 | V5: =OFFSET('1050LAPTOP'!I$1,$A$4-1+$A$1,0) -> 36.485382 | W5: =OFFSET('1050LAPTOP'!J$1,$A$4-1+$A$1,0) -> 132.16204 | AA5: =Q5/Q$3 -> 0.071292268 | AB5: =R5/R$3 -> 0.034821424 | AC5: =S5/S$3 -> 0.038474393 | AD5: =T5/T$3 -> 0.018186775 | AE5: =U5/U$3 -> 0.012285693 | AF5: =V5/V$3 -> 0.027146862 | AG5: =W5/W$3 -> 0.049167424
A6: 4 | B6: =OFFSET('1050LAPTOP'!$C$1,A6-1,0) -> non CUDA Time | C6: Matrix ACO | D6: МО | E6: =OFFSET('1050LAPTOP'!D$1,$A6-1,0) -> 1012.9384 | F6: =OFFSET('1050LAPTOP'!E$1,$A6-1,0) -> 1856.1192 | G6: =OFFSET('1050LAPTOP'!F$1,$A6-1,0) -> 3594.4352 | H6: =OFFSET('1050LAPTOP'!G$1,$A6-1,0) -> 7098.9368 | I6: =OFFSET('1050LAPTOP'!H$1,$A6-1,0) -> 13991.566 | J6: =OFFSET('1050LAPTOP'!I$1,$A6-1,0) -> 27308.064 | K6: =OFFSET('1050LAPTOP'!J$1,$A6-1,0) -> 53372.172 | O6: i5-9400F | P6: МО | Q6: =OFFSET('1050COMP'!D$1,$A$4-1,0) -> 1021.2764 | R6: =OFFSET('1050COMP'!E$1,$A$4-1,0) -> 1875.4454 | S6: =OFFSET('1050COMP'!F$1,$A$4-1,0) -> 3606.0204 | T6: =OFFSET('1050COMP'!G$1,$A$4-1,0) -> 7106.4438 | U6: =OFFSET('1050COMP'!H$1,$A$4-1,0) -> 14355.808 | V6: =OFFSET('1050COMP'!I$1,$A$4-1,0) -> 27843.878 | W6: =OFFSET('1050COMP'!J$1,$A$4-1,0) -> 54934.598
D7: ДИ | E7: =OFFSET('1050LAPTOP'!D$1,$A6-1+$A$1,0) -> 2.9942752 | F7: =OFFSET('1050LAPTOP'!E$1,$A6-1+$A$1,0) -> 2.9249996 | G7: =OFFSET('1050LAPTOP'!F$1,$A6-1+$A$1,0) -> 6.463698 | H7: =OFFSET('1050LAPTOP'!G$1,$A6-1+$A$1,0) -> 6.1107565 | I7: =OFFSET('1050LAPTOP'!H$1,$A6-1+$A$1,0) -> 8.2559854 | J7: =OFFSET('1050LAPTOP'!I$1,$A6-1+$A$1,0) -> 36.485382 | K7: =OFFSET('1050LAPTOP'!J$1,$A6-1+$A$1,0) -> 132.16204 | P7: ДИ | Q7: =OFFSET('1050COMP'!D$1,$A$4-1+$A$1,0) -> 10.942156 | R7: =OFFSET('1050COMP'!E$1,$A$4-1+$A$1,0) -> 9.9698891 | S7: =OFFSET('1050COMP'!F$1,$A$4-1+$A$1,0) -> 8.1186352 | T7: =OFFSET('1050COMP'!G$1,$A$4-1+$A$1,0) -> 21.800474 | U7: =OFFSET('1050COMP'!H$1,$A$4-1+$A$1,0) -> 22.947848 | V7: =OFFSET('1050COMP'!I$1,$A$4-1+$A$1,0) -> 48.483806 | W7: =OFFSET('1050COMP'!J$1,$A$4-1+$A$1,0) -> 125.33519 | AA7: =Q7/Q$3 -> 0.26052753 | AB7: =R7/R$3 -> 0.11868916 | AC7: =S7/S$3 -> 0.04832521 | AD7: =T7/T$3 -> 0.064882362 | AE7: =U7/U$3 -> 0.034148583 | AF7: =V7/V$3 -> 0.03607426 | AG7: =W7/W$3 -> 0.046627675
A8: 5 | B8: =OFFSET('1050LAPTOP'!$C$1,A8-1,0) -> omp | C8: Matrix ACO + OMP | D8: МО | E8: =OFFSET('1050LAPTOP'!D$1,$A8-1,0) -> 941.88968 | F8: =OFFSET('1050LAPTOP'!E$1,$A8-1,0) -> 1766.0682 | G8: =OFFSET('1050LAPTOP'!F$1,$A8-1,0) -> 3464.2148 | H8: =OFFSET('1050LAPTOP'!G$1,$A8-1,0) -> 6900.4026 | I8: =OFFSET('1050LAPTOP'!H$1,$A8-1,0) -> 13916.54 | J8: =OFFSET('1050LAPTOP'!I$1,$A8-1,0) -> 27036.758 | K8: =OFFSET('1050LAPTOP'!J$1,$A8-1,0) -> 52481.614 | O8: i5-12450H | P8: МО | Q8: =OFFSET('3060LAPTOP'!D$1,$A$4-1,0) -> 565.78236 | R8: =OFFSET('3060LAPTOP'!E$1,$A$4-1,0) -> 1048.5618 | S8: =OFFSET('3060LAPTOP'!F$1,$A$4-1,0) -> 1982.69 | T8: =OFFSET('3060LAPTOP'!G$1,$A$4-1,0) -> 3787.3732 | U8: =OFFSET('3060LAPTOP'!H$1,$A$4-1,0) -> 7666.159 | V8: =OFFSET('3060LAPTOP'!I$1,$A$4-1,0) -> 15021.706 | W8: =OFFSET('3060LAPTOP'!J$1,$A$4-1,0) -> 30206.626
D9: ДИ | E9: =OFFSET('1050LAPTOP'!D$1,$A8-1+$A$1,0) -> 1.9251445 | F9: =OFFSET('1050LAPTOP'!E$1,$A8-1+$A$1,0) -> 2.0250624 | G9: =OFFSET('1050LAPTOP'!F$1,$A8-1+$A$1,0) -> 3.9001184 | H9: =OFFSET('1050LAPTOP'!G$1,$A8-1+$A$1,0) -> 6.1884083 | I9: =OFFSET('1050LAPTOP'!H$1,$A8-1+$A$1,0) -> 10.866151 | J9: =OFFSET('1050LAPTOP'!I$1,$A8-1+$A$1,0) -> 23.752386 | K9: =OFFSET('1050LAPTOP'!J$1,$A8-1+$A$1,0) -> 66.672073 | P9: ДИ | Q9: =OFFSET('3060LAPTOP'!D$1,$A$4-1+$A$1,0) -> 4.162287 | R9: =OFFSET('3060LAPTOP'!E$1,$A$4-1+$A$1,0) -> 4.1114063 | S9: =OFFSET('3060LAPTOP'!F$1,$A$4-1+$A$1,0) -> 9.9600752 | T9: =OFFSET('3060LAPTOP'!G$1,$A$4-1+$A$1,0) -> 10.371022 | U9: =OFFSET('3060LAPTOP'!H$1,$A$4-1+$A$1,0) -> 60.114895 | V9: =OFFSET('3060LAPTOP'!I$1,$A$4-1+$A$1,0) -> 32.345265 | W9: =OFFSET('3060LAPTOP'!J$1,$A$4-1+$A$1,0) -> 64.000996 | AA9: =Q9/Q$3 -> 0.099102072 | AB9: =R9/R$3 -> 0.048945313 | AC9: =S9/S$3 -> 0.059286162 | AD9: =T9/T$3 -> 0.030866137 | AE9: =U9/U$3 -> 0.089456688 | AF9: =V9/V$3 -> 0.024066417 | AG9: =W9/W$3 -> 0.023809894
A10: 6 | B10: =OFFSET('1050LAPTOP'!$C$1,A10-1,0) -> non CUDA transp Time | C10: Transp Matrix ACO | D10: МО | E10: =OFFSET('1050LAPTOP'!D$1,$A10-1,0) -> 1006.4635 | F10: =OFFSET('1050LAPTOP'!E$1,$A10-1,0) -> 1833.9498 | G10: =OFFSET('1050LAPTOP'!F$1,$A10-1,0) -> 3513.463 | H10: =OFFSET('1050LAPTOP'!G$1,$A10-1,0) -> 6889.402 | I10: =OFFSET('1050LAPTOP'!H$1,$A10-1,0) -> 13937.79 | J10: =OFFSET('1050LAPTOP'!I$1,$A10-1,0) -> 27063.298 | K10: =OFFSET('1050LAPTOP'!J$1,$A10-1,0) -> 52241.044 | O10: i5-13600K | P10: МО | Q10: =OFFSET('3060COMP Kaf'!D$1,$A$4-1,0) -> 487.2341 | R10: =OFFSET('3060COMP Kaf'!E$1,$A$4-1,0) -> 885.85572 | S10: =OFFSET('3060COMP Kaf'!F$1,$A$4-1,0) -> 1657.3222 | T10: =OFFSET('3060COMP Kaf'!G$1,$A$4-1,0) -> 3201.0856 | U10: =OFFSET('3060COMP Kaf'!H$1,$A$4-1,0) -> 6411.2784 | V10: =OFFSET('3060COMP Kaf'!I$1,$A$4-1,0) -> 12839.332 | W10: =OFFSET('3060COMP Kaf'!J$1,$A$4-1,0) -> 25321.222
D11: ДИ | E11: =OFFSET('1050LAPTOP'!D$1,$A10-1+$A$1,0) -> 2.0435451 | F11: =OFFSET('1050LAPTOP'!E$1,$A10-1+$A$1,0) -> 2.0129872 | G11: =OFFSET('1050LAPTOP'!F$1,$A10-1+$A$1,0) -> 3.9960318 | H11: =OFFSET('1050LAPTOP'!G$1,$A10-1+$A$1,0) -> 7.77098 | I11: =OFFSET('1050LAPTOP'!H$1,$A10-1+$A$1,0) -> 10.28843 | J11: =OFFSET('1050LAPTOP'!I$1,$A10-1+$A$1,0) -> 23.459914 | K11: =OFFSET('1050LAPTOP'!J$1,$A10-1+$A$1,0) -> 32.116369 | P11: ДИ | Q11: =OFFSET('3060COMP Kaf'!D$1,$A$4-1+$A$1,0) -> 0.77081041 | R11: =OFFSET('3060COMP Kaf'!E$1,$A$4-1+$A$1,0) -> 1.3447363 | S11: =OFFSET('3060COMP Kaf'!F$1,$A$4-1+$A$1,0) -> 1.4473374 | T11: =OFFSET('3060COMP Kaf'!G$1,$A$4-1+$A$1,0) -> 2.2182249 | U11: =OFFSET('3060COMP Kaf'!H$1,$A$4-1+$A$1,0) -> 16.837503 | V11: =OFFSET('3060COMP Kaf'!I$1,$A$4-1+$A$1,0) -> 5.9068434 | W11: =OFFSET('3060COMP Kaf'!J$1,$A$4-1+$A$1,0) -> 29.785563 | AA11: =Q11/Q$3 -> 0.018352629 | AB11: =R11/R$3 -> 0.016008765 | AC11: =S11/S$3 -> 0.0086151034 | AD11: =T11/T$3 -> 0.0066018598 | AE11: =U11/U$3 -> 0.025055808 | AF11: =V11/V$3 -> 0.0043949727 | AG11: =W11/W$3 -> 0.011080938
A12: 7 | B12: =OFFSET('1050LAPTOP'!$C$1,A12-1,0) -> non CUDA transp_AVX Time | C12: Transp Matrix ACO + AVX | D12: МО | E12: =OFFSET('1050LAPTOP'!D$1,$A12-1,0) -> 0 | F12: =OFFSET('1050LAPTOP'!E$1,$A12-1,0) -> 1886.6616 | G12: =OFFSET('1050LAPTOP'!F$1,$A12-1,0) -> 3617.8644 | H12: =OFFSET('1050LAPTOP'!G$1,$A12-1,0) -> 7101.9936 | I12: =OFFSET('1050LAPTOP'!H$1,$A12-1,0) -> 14317.556 | J12: =OFFSET('1050LAPTOP'!I$1,$A12-1,0) -> 28324.736 | K12: =OFFSET('1050LAPTOP'!J$1,$A12-1,0) -> 54374.392 | O12: AMD Ryzen 5 7500F 6 | P12: МО | Q12: =OFFSET('4060COMP'!D$1,$A$4-1,0) -> 886.85582 | R12: =OFFSET('4060COMP'!E$1,$A$4-1,0) -> 1627.4022 | S12: =OFFSET('4060COMP'!F$1,$A$4-1,0) -> 3159.8702 | T12: =OFFSET('4060COMP'!G$1,$A$4-1,0) -> 6191.9178 | U12: =OFFSET('4060COMP'!H$1,$A$4-1,0) -> 12286.098 | V12: =OFFSET('4060COMP'!I$1,$A$4-1,0) -> 25340.31 | W12: =OFFSET('4060COMP'!J$1,$A$4-1,0) -> 46545.16
D13: ДИ | E13: =OFFSET('1050LAPTOP'!D$1,$A12-1+$A$1,0) -> 0 | F13: =OFFSET('1050LAPTOP'!E$1,$A12-1+$A$1,0) -> 2.4833301 | G13: =OFFSET('1050LAPTOP'!F$1,$A12-1+$A$1,0) -> 3.9616577 | H13: =OFFSET('1050LAPTOP'!G$1,$A12-1+$A$1,0) -> 6.5308311 | I13: =OFFSET('1050LAPTOP'!H$1,$A12-1+$A$1,0) -> 13.142034 | J13: =OFFSET('1050LAPTOP'!I$1,$A12-1+$A$1,0) -> 17.497841 | K13: =OFFSET('1050LAPTOP'!J$1,$A12-1+$A$1,0) -> 19.868159 | P13: ДИ | Q13: =OFFSET('4060COMP'!D$1,$A$4-1+$A$1,0) -> 3.9258114 | R13: =OFFSET('4060COMP'!E$1,$A$4-1+$A$1,0) -> 2.9705663 | S13: =OFFSET('4060COMP'!F$1,$A$4-1+$A$1,0) -> 39.888174 | T13: =OFFSET('4060COMP'!G$1,$A$4-1+$A$1,0) -> 7.577911 | U13: =OFFSET('4060COMP'!H$1,$A$4-1+$A$1,0) -> 25.186138 | V13: =OFFSET('4060COMP'!I$1,$A$4-1+$A$1,0) -> 86.386279 | W13: =OFFSET('4060COMP'!J$1,$A$4-1+$A$1,0) -> 62.364672 | AA13: =Q13/Q$3 -> 0.093471701 | AB13: =R13/R$3 -> 0.035363885 | AC13: =S13/S$3 -> 0.23742961 | AD13: =T13/T$3 -> 0.022553307 | AE13: =U13/U$3 -> 0.037479372 | AF13: =V13/V$3 -> 0.064275505 | AG13: =W13/W$3 -> 0.023201143
A14: 8 | B14: =OFFSET('1050LAPTOP'!$C$1,A14-1,0) -> non CUDA transp_AVX_OMP Time | C14: Transp Matrix ACO + AVX + OPM | D14: МО | E14: =OFFSET('1050LAPTOP'!D$1,$A14-1,0) -> 0 | F14: =OFFSET('1050LAPTOP'!E$1,$A14-1,0) -> 1906.3474 | G14: =OFFSET('1050LAPTOP'!F$1,$A14-1,0) -> 3617.8066 | H14: =OFFSET('1050LAPTOP'!G$1,$A14-1,0) -> 7097.737 | I14: =OFFSET('1050LAPTOP'!H$1,$A14-1,0) -> 14354.264 | J14: =OFFSET('1050LAPTOP'!I$1,$A14-1,0) -> 28337.322 | K14: =OFFSET('1050LAPTOP'!J$1,$A14-1,0) -> 54393.38
D15: ДИ | E15: =OFFSET('1050LAPTOP'!D$1,$A14-1+$A$1,0) -> 0 | F15: =OFFSET('1050LAPTOP'!E$1,$A14-1+$A$1,0) -> 15.006069 | G15: =OFFSET('1050LAPTOP'!F$1,$A14-1+$A$1,0) -> 3.795444 | H15: =OFFSET('1050LAPTOP'!G$1,$A14-1+$A$1,0) -> 7.0860255 | I15: =OFFSET('1050LAPTOP'!H$1,$A14-1+$A$1,0) -> 37.701812 | J15: =OFFSET('1050LAPTOP'!I$1,$A14-1+$A$1,0) -> 22.04841 | K15: =OFFSET('1050LAPTOP'!J$1,$A14-1+$A$1,0) -> 25.805086
A16: 12 | B16: =OFFSET('1050LAPTOP'!$C$1,A16-1,0) -> Time non CUDA AVX time 4 | D16: МО | E16: =OFFSET('1050LAPTOP'!D$1,$A16-1,0) -> 1017.3776 | F16: =OFFSET('1050LAPTOP'!E$1,$A16-1,0) -> 1889.2708 | G16: =OFFSET('1050LAPTOP'!F$1,$A16-1,0) -> 3627.0554 | H16: =OFFSET('1050LAPTOP'!G$1,$A16-1,0) -> 7084.2338 | I16: =OFFSET('1050LAPTOP'!H$1,$A16-1,0) -> 14040.434 | J16: =OFFSET('1050LAPTOP'!I$1,$A16-1,0) -> 27472.934 | K16: =OFFSET('1050LAPTOP'!J$1,$A16-1,0) -> 52973.284
D17: ДИ | E17: =OFFSET('1050LAPTOP'!D$1,$A16-1+$A$1,0) -> 4.5036531 | F17: =OFFSET('1050LAPTOP'!E$1,$A16-1+$A$1,0) -> 3.1810469 | G17: =OFFSET('1050LAPTOP'!F$1,$A16-1+$A$1,0) -> 5.1561407 | H17: =OFFSET('1050LAPTOP'!G$1,$A16-1+$A$1,0) -> 11.160311 | I17: =OFFSET('1050LAPTOP'!H$1,$A16-1+$A$1,0) -> 6.3843013 | J17: =OFFSET('1050LAPTOP'!I$1,$A16-1+$A$1,0) -> 7.1438392 | K17: =OFFSET('1050LAPTOP'!J$1,$A16-1+$A$1,0) -> 240.62043
A18: 13 | B18: =OFFSET('1050LAPTOP'!$C$1,A18-1,0) -> Time non CUDA AVX add CPU time 4 | D18: МО | E18: =OFFSET('1050LAPTOP'!D$1,$A18-1,0) -> 627.14738 | F18: =OFFSET('1050LAPTOP'!E$1,$A18-1,0) -> 1153.4844 | G18: =OFFSET('1050LAPTOP'!F$1,$A18-1,0) -> 2244.2572 | H18: =OFFSET('1050LAPTOP'!G$1,$A18-1,0) -> 4419.377 | I18: =OFFSET('1050LAPTOP'!H$1,$A18-1,0) -> 8817.8194 | J18: =OFFSET('1050LAPTOP'!I$1,$A18-1,0) -> 17479.466 | K18: =OFFSET('1050LAPTOP'!J$1,$A18-1,0) -> 35108.804
D19: ДИ | E19: =OFFSET('1050LAPTOP'!D$1,$A18-1+$A$1,0) -> 4.1153896 | F19: =OFFSET('1050LAPTOP'!E$1,$A18-1+$A$1,0) -> 3.6116291 | G19: =OFFSET('1050LAPTOP'!F$1,$A18-1+$A$1,0) -> 6.3078417 | H19: =OFFSET('1050LAPTOP'!G$1,$A18-1+$A$1,0) -> 3.1527106 | I19: =OFFSET('1050LAPTOP'!H$1,$A18-1+$A$1,0) -> 15.940904 | J19: =OFFSET('1050LAPTOP'!I$1,$A18-1+$A$1,0) -> 34.110952 | K19: =OFFSET('1050LAPTOP'!J$1,$A18-1+$A$1,0) -> 65.010018
A20: 3 | B20: =OFFSET('1050LAPTOP'!$C$1,A20-1,0) -> Classic ACO | C20: Classic ACO | D20: МО | E20: =OFFSET('1050COMP'!D$1,$A20-1,0) -> 13775.68 | F20: =OFFSET('1050COMP'!E$1,$A20-1,0) -> 24819.016 | G20: =OFFSET('1050COMP'!F$1,$A20-1,0) -> 47399.626 | H20: =OFFSET('1050COMP'!G$1,$A20-1,0) -> 96405.03 | I20: =OFFSET('1050COMP'!H$1,$A20-1,0) -> 197567.46 | J20: =OFFSET('1050COMP'!I$1,$A20-1,0) -> 376437.82 | K20: =OFFSET('1050COMP'!J$1,$A20-1,0) -> 762594.84
D21: ДИ | E21: =OFFSET('1050COMP'!D$1,$A20-1+$A$1,0) -> 48.452723 | F21: =OFFSET('1050COMP'!E$1,$A20-1+$A$1,0) -> 5.5245303 | G21: =OFFSET('1050COMP'!F$1,$A20-1+$A$1,0) -> 73.476724 | H21: =OFFSET('1050COMP'!G$1,$A20-1+$A$1,0) -> 120.92401 | I21: =OFFSET('1050COMP'!H$1,$A20-1+$A$1,0) -> 4278.2049 | J21: =OFFSET('1050COMP'!I$1,$A20-1+$A$1,0) -> 465.43416 | K21: =OFFSET('1050COMP'!J$1,$A20-1+$A$1,0) -> 10015.793
A22: 4 | B22: =OFFSET('1050LAPTOP'!$C$1,A22-1,0) -> non CUDA Time | C22: Matrix ACO | D22: МО | E22: =OFFSET('1050COMP'!D$1,$A22-1,0) -> 1021.2764 | F22: =OFFSET('1050COMP'!E$1,$A22-1,0) -> 1875.4454 | G22: =OFFSET('1050COMP'!F$1,$A22-1,0) -> 3606.0204 | H22: =OFFSET('1050COMP'!G$1,$A22-1,0) -> 7106.4438 | I22: =OFFSET('1050COMP'!H$1,$A22-1,0) -> 14355.808 | J22: =OFFSET('1050COMP'!I$1,$A22-1,0) -> 27843.878 | K22: =OFFSET('1050COMP'!J$1,$A22-1,0) -> 54934.598
D23: ДИ | E23: =OFFSET('1050COMP'!D$1,$A22-1+$A$1,0) -> 10.942156 | F23: =OFFSET('1050COMP'!E$1,$A22-1+$A$1,0) -> 9.9698891 | G23: =OFFSET('1050COMP'!F$1,$A22-1+$A$1,0) -> 8.1186352 | H23: =OFFSET('1050COMP'!G$1,$A22-1+$A$1,0) -> 21.800474 | I23: =OFFSET('1050COMP'!H$1,$A22-1+$A$1,0) -> 22.947848 | J23: =OFFSET('1050COMP'!I$1,$A22-1+$A$1,0) -> 48.483806 | K23: =OFFSET('1050COMP'!J$1,$A22-1+$A$1,0) -> 125.33519
A24: 5 | B24: =OFFSET('1050LAPTOP'!$C$1,A24-1,0) -> omp | C24: Matrix ACO + OMP | D24: МО | E24: =OFFSET('1050COMP'!D$1,$A24-1,0) -> 936.52016 | F24: =OFFSET('1050COMP'!E$1,$A24-1,0) -> 1796.2392 | G24: =OFFSET('1050COMP'!F$1,$A24-1,0) -> 3518.97 | H24: =OFFSET('1050COMP'!G$1,$A24-1,0) -> 7123.3738 | I24: =OFFSET('1050COMP'!H$1,$A24-1,0) -> 14467.484 | J24: =OFFSET('1050COMP'!I$1,$A24-1,0) -> 27997.418 | K24: =OFFSET('1050COMP'!J$1,$A24-1,0) -> 54080.832
D25: ДИ | E25: =OFFSET('1050COMP'!D$1,$A24-1+$A$1,0) -> 0.59577326 | F25: =OFFSET('1050COMP'!E$1,$A24-1+$A$1,0) -> 49.48419 | G25: =OFFSET('1050COMP'!F$1,$A24-1+$A$1,0) -> 9.1284333 | H25: =OFFSET('1050COMP'!G$1,$A24-1+$A$1,0) -> 14.493007 | I25: =OFFSET('1050COMP'!H$1,$A24-1+$A$1,0) -> 54.046573 | J25: =OFFSET('1050COMP'!I$1,$A24-1+$A$1,0) -> 50.116801 | K25: =OFFSET('1050COMP'!J$1,$A24-1+$A$1,0) -> 138.28386
A26: 6 | B26: =OFFSET('1050LAPTOP'!$C$1,A26-1,0) -> non CUDA transp Time | C26: Transp Matrix ACO | D26: МО | E26: =OFFSET('1050COMP'!D$1,$A26-1,0) -> 989.51166 | F26: =OFFSET('1050COMP'!E$1,$A26-1,0) -> 1854.2994 | G26: =OFFSET('1050COMP'!F$1,$A26-1,0) -> 3547.5268 | H26: =OFFSET('1050COMP'!G$1,$A26-1,0) -> 7089.6244 | I26: =OFFSET('1050COMP'!H$1,$A26-1,0) -> 14367.464 | J26: =OFFSET('1050COMP'!I$1,$A26-1,0) -> 27639.606 | K26: =OFFSET('1050COMP'!J$1,$A26-1,0) -> 53463.302
D27: ДИ | E27: =OFFSET('1050COMP'!D$1,$A26-1+$A$1,0) -> 1.7307591 | F27: =OFFSET('1050COMP'!E$1,$A26-1+$A$1,0) -> 6.0922639 | G27: =OFFSET('1050COMP'!F$1,$A26-1+$A$1,0) -> 11.048366 | H27: =OFFSET('1050COMP'!G$1,$A26-1+$A$1,0) -> 17.982643 | I27: =OFFSET('1050COMP'!H$1,$A26-1+$A$1,0) -> 39.631228 | J27: =OFFSET('1050COMP'!I$1,$A26-1+$A$1,0) -> 119.26054 | K27: =OFFSET('1050COMP'!J$1,$A26-1+$A$1,0) -> 142.74903
A28: 7 | B28: =OFFSET('1050LAPTOP'!$C$1,A28-1,0) -> non CUDA transp_AVX Time | C28: Transp Matrix ACO + AVX | D28: МО | E28: =OFFSET('1050COMP'!D$1,$A28-1,0) -> 0 | F28: =OFFSET('1050COMP'!E$1,$A28-1,0) -> 1907.0192 | G28: =OFFSET('1050COMP'!F$1,$A28-1,0) -> 3649.6616 | H28: =OFFSET('1050COMP'!G$1,$A28-1,0) -> 7350.9722 | I28: =OFFSET('1050COMP'!H$1,$A28-1,0) -> 14737.54 | J28: =OFFSET('1050COMP'!I$1,$A28-1,0) -> 28823.408 | K28: =OFFSET('1050COMP'!J$1,$A28-1,0) -> 55301.924
D29: ДИ | E29: =OFFSET('1050COMP'!D$1,$A28-1+$A$1,0) -> 0 | F29: =OFFSET('1050COMP'!E$1,$A28-1+$A$1,0) -> 5.4446488 | G29: =OFFSET('1050COMP'!F$1,$A28-1+$A$1,0) -> 10.738091 | H29: =OFFSET('1050COMP'!G$1,$A28-1+$A$1,0) -> 32.820993 | I29: =OFFSET('1050COMP'!H$1,$A28-1+$A$1,0) -> 43.205466 | J29: =OFFSET('1050COMP'!I$1,$A28-1+$A$1,0) -> 48.2447 | K29: =OFFSET('1050COMP'!J$1,$A28-1+$A$1,0) -> 116.84553
A30: 8 | B30: =OFFSET('1050LAPTOP'!$C$1,A30-1,0) -> non CUDA transp_AVX_OMP Time | C30: Transp Matrix ACO + AVX + OPM | D30: МО | E30: =OFFSET('1050COMP'!D$1,$A30-1,0) -> 0 | F30: =OFFSET('1050COMP'!E$1,$A30-1,0) -> 1909.23 | G30: =OFFSET('1050COMP'!F$1,$A30-1,0) -> 3647.0058 | H30: =OFFSET('1050COMP'!G$1,$A30-1,0) -> 7340.941 | I30: =OFFSET('1050COMP'!H$1,$A30-1,0) -> 14774.014 | J30: =OFFSET('1050COMP'!I$1,$A30-1,0) -> 28806.066 | K30: =OFFSET('1050COMP'!J$1,$A30-1,0) -> 55311.378
D31: ДИ | E31: =OFFSET('1050COMP'!D$1,$A30-1+$A$1,0) -> 0 | F31: =OFFSET('1050COMP'!E$1,$A30-1+$A$1,0) -> 4.9507283 | G31: =OFFSET('1050COMP'!F$1,$A30-1+$A$1,0) -> 9.6056265 | H31: =OFFSET('1050COMP'!G$1,$A30-1+$A$1,0) -> 22.250767 | I31: =OFFSET('1050COMP'!H$1,$A30-1+$A$1,0) -> 78.156294 | J31: =OFFSET('1050COMP'!I$1,$A30-1+$A$1,0) -> 44.072032 | K31: =OFFSET('1050COMP'!J$1,$A30-1+$A$1,0) -> 116.33897
A32: 12 | B32: =OFFSET('1050LAPTOP'!$C$1,A32-1,0) -> Time non CUDA AVX time 4 | D32: МО | E32: =OFFSET('1050COMP'!D$1,$A32-1,0) -> 980.75398 | F32: =OFFSET('1050COMP'!E$1,$A32-1,0) -> 1822.0432 | G32: =OFFSET('1050COMP'!F$1,$A32-1,0) -> 3521.0432 | H32: =OFFSET('1050COMP'!G$1,$A32-1,0) -> 6913.7884 | I32: =OFFSET('1050COMP'!H$1,$A32-1,0) -> 14600.704 | J32: =OFFSET('1050COMP'!I$1,$A32-1,0) -> 27769.686 | K32: =OFFSET('1050COMP'!J$1,$A32-1,0) -> 53720.156
D33: ДИ | E33: =OFFSET('1050COMP'!D$1,$A32-1+$A$1,0) -> 4.5878776 | F33: =OFFSET('1050COMP'!E$1,$A32-1+$A$1,0) -> 9.7863638 | G33: =OFFSET('1050COMP'!F$1,$A32-1+$A$1,0) -> 5.4866692 | H33: =OFFSET('1050COMP'!G$1,$A32-1+$A$1,0) -> 6.0988867 | I33: =OFFSET('1050COMP'!H$1,$A32-1+$A$1,0) -> 65.205462 | J33: =OFFSET('1050COMP'!I$1,$A32-1+$A$1,0) -> 97.697116 | K33: =OFFSET('1050COMP'!J$1,$A32-1+$A$1,0) -> 131.75917
A34: 13 | B34: =OFFSET('1050LAPTOP'!$C$1,A34-1,0) -> Time non CUDA AVX add CPU time 4 | D34: МО | E34: =OFFSET('1050COMP'!D$1,$A34-1,0) -> 585.59822 | F34: =OFFSET('1050COMP'!E$1,$A34-1,0) -> 1094.3246 | G34: =OFFSET('1050COMP'!F$1,$A34-1,0) -> 2120.4718 | H34: =OFFSET('1050COMP'!G$1,$A34-1,0) -> 4187.7104 | I34: =OFFSET('1050COMP'!H$1,$A34-1,0) -> 9455.6194 | J34: =OFFSET('1050COMP'!I$1,$A34-1,0) -> 19091.788 | K34: =OFFSET('1050COMP'!J$1,$A34-1,0) -> 39015.478
D35: ДИ | E35: =OFFSET('1050COMP'!D$1,$A34-1+$A$1,0) -> 1.0386446 | F35: =OFFSET('1050COMP'!E$1,$A34-1+$A$1,0) -> 3.0217064 | G35: =OFFSET('1050COMP'!F$1,$A34-1+$A$1,0) -> 4.0730745 | H35: =OFFSET('1050COMP'!G$1,$A34-1+$A$1,0) -> 1.8340224 | I35: =OFFSET('1050COMP'!H$1,$A34-1+$A$1,0) -> 53.129504 | J35: =OFFSET('1050COMP'!I$1,$A34-1+$A$1,0) -> 54.545261 | K35: =OFFSET('1050COMP'!J$1,$A34-1+$A$1,0) -> 97.365495
A36: 3 | B36: =OFFSET('1050LAPTOP'!$C$1,A36-1,0) -> Classic ACO | C36: Classic ACO | D36: МО | E36: =OFFSET('3060LAPTOP'!D$1,$A36-1,0) -> 6732.0454 | F36: =OFFSET('3060LAPTOP'!E$1,$A36-1,0) -> 12795.57 | G36: =OFFSET('3060LAPTOP'!F$1,$A36-1,0) -> 24112.532 | H36: =OFFSET('3060LAPTOP'!G$1,$A36-1,0) -> 46059.344 | I36: =OFFSET('3060LAPTOP'!H$1,$A36-1,0) -> 91907.946 | J36: =OFFSET('3060LAPTOP'!I$1,$A36-1,0) -> 184408.08 | K36: =OFFSET('3060LAPTOP'!J$1,$A36-1,0) -> 367570.34
D37: ДИ | E37: =OFFSET('3060LAPTOP'!D$1,$A36-1+$A$1,0) -> 29.72261 | F37: =OFFSET('3060LAPTOP'!E$1,$A36-1+$A$1,0) -> 17.261082 | G37: =OFFSET('3060LAPTOP'!F$1,$A36-1+$A$1,0) -> 98.029302 | H37: =OFFSET('3060LAPTOP'!G$1,$A36-1+$A$1,0) -> 48.18692 | I37: =OFFSET('3060LAPTOP'!H$1,$A36-1+$A$1,0) -> 512.6278 | J37: =OFFSET('3060LAPTOP'!I$1,$A36-1+$A$1,0) -> 775.06198 | K37: =OFFSET('3060LAPTOP'!J$1,$A36-1+$A$1,0) -> 1357.5707
A38: 4 | B38: =OFFSET('1050LAPTOP'!$C$1,A38-1,0) -> non CUDA Time | C38: Matrix ACO | D38: МО | E38: =OFFSET('3060LAPTOP'!D$1,$A38-1,0) -> 565.78236 | F38: =OFFSET('3060LAPTOP'!E$1,$A38-1,0) -> 1048.5618 | G38: =OFFSET('3060LAPTOP'!F$1,$A38-1,0) -> 1982.69 | H38: =OFFSET('3060LAPTOP'!G$1,$A38-1,0) -> 3787.3732 | I38: =OFFSET('3060LAPTOP'!H$1,$A38-1,0) -> 7666.159 | J38: =OFFSET('3060LAPTOP'!I$1,$A38-1,0) -> 15021.706 | K38: =OFFSET('3060LAPTOP'!J$1,$A38-1,0) -> 30206.626
D39: ДИ | E39: =OFFSET('3060LAPTOP'!D$1,$A38-1+$A$1,0) -> 4.162287 | F39: =OFFSET('3060LAPTOP'!E$1,$A38-1+$A$1,0) -> 4.1114063 | G39: =OFFSET('3060LAPTOP'!F$1,$A38-1+$A$1,0) -> 9.9600752 | H39: =OFFSET('3060LAPTOP'!G$1,$A38-1+$A$1,0) -> 10.371022 | I39: =OFFSET('3060LAPTOP'!H$1,$A38-1+$A$1,0) -> 60.114895 | J39: =OFFSET('3060LAPTOP'!I$1,$A38-1+$A$1,0) -> 32.345265 | K39: =OFFSET('3060LAPTOP'!J$1,$A38-1+$A$1,0) -> 64.000996
A40: 5 | B40: =OFFSET('1050LAPTOP'!$C$1,A40-1,0) -> omp | C40: Matrix ACO + OMP | D40: МО | E40: =OFFSET('3060LAPTOP'!D$1,$A40-1,0) -> 537.58286 | F40: =OFFSET('3060LAPTOP'!E$1,$A40-1,0) -> 1010.2038 | G40: =OFFSET('3060LAPTOP'!F$1,$A40-1,0) -> 1940.0652 | H40: =OFFSET('3060LAPTOP'!G$1,$A40-1,0) -> 3816.501 | I40: =OFFSET('3060LAPTOP'!H$1,$A40-1,0) -> 7811.4766 | J40: =OFFSET('3060LAPTOP'!I$1,$A40-1,0) -> 15154.872 | K40: =OFFSET('3060LAPTOP'!J$1,$A40-1,0) -> 30090.164
...

Sheet Лист1

Sheet 1050LAPTOP
B1: 1.96 | C1: 50 | D1: 2 | E1: 4 | F1: 8 | G1: 16 | H1: 32 | I1: 64 | J1: 128 | K1: 256 | L1: 512 | M1: 8th Gen Intel Core i5-8300H 2.30 GHz (8Gb ОЗУ)
B2: МО | D2: 42 | E2: 84 | F2: 168 | G2: 336 | H2: 672 | I2: 1344 | J2: 2688 | K2: 5376 | L2: 10752
A3: 1 | C3: Classic ACO | D3: 14722.332 | E3: 27364.668 | F3: 52186.786 | G3: 103402.44 | H3: 207103.36 | I3: 410463.68 | J3: 835652.72
C4: non CUDA Time | D4: 1012.9384 | E4: 1856.1192 | F4: 3594.4352 | G4: 7098.9368 | H4: 13991.566 | I4: 27308.064 | J4: 53372.172
C5: omp | D5: 941.88968 | E5: 1766.0682 | F5: 3464.2148 | G5: 6900.4026 | H5: 13916.54 | I5: 27036.758 | J5: 52481.614
C6: non CUDA transp Time | D6: 1006.4635 | E6: 1833.9498 | F6: 3513.463 | G6: 6889.402 | H6: 13937.79 | I6: 27063.298 | J6: 52241.044
C7: non CUDA transp_AVX Time | D7: 0 | E7: 1886.6616 | F7: 3617.8644 | G7: 7101.9936 | H7: 14317.556 | I7: 28324.736 | J7: 54374.392
C8: non CUDA transp_AVX_OMP Time | D8: 0 | E8: 1906.3474 | F8: 3617.8066 | G8: 7097.737 | H8: 14354.264 | I8: 28337.322 | J8: 54393.38
C9: CUDA ant add CPU Time | D9: 617.83162 | E9: 1125.4246 | F9: 2174.7248 | G9: 4302.336 | H9: 8603.6396 | I9: 17058.228 | J9: 34415.26
C10: CUDA ant add CPU12 | D10: 1512.212 | E10: 2659.6366 | F10: 5207.7542 | G10: 10304.526 | H10: 20485.6 | I10: 30668.098 | J10: 53579.62
C11: CUDA ant add CPU_AVX_transp Time | D11: 0 | E11: 1138.901 | F11: 2203.575 | G11: 4345.2346 | H11: 8611.4828 | I11: 17137.144 | J11: 34192.436
C12: Time non CUDA AVX time 4 | D12: 1017.3776 | E12: 1889.2708 | F12: 3627.0554 | G12: 7084.2338 | H12: 14040.434 | I12: 27472.934 | J12: 52973.284
C13: Time non CUDA AVX add CPU time 4 | D13: 627.14738 | E13: 1153.4844 | F13: 2244.2572 | G13: 4419.377 | H13: 8817.8194 | I13: 17479.466 | J13: 35108.804
C30: 6 | D30: 2 | E30: 4 | F30: 8 | G30: 16 | H30: 32 | I30: 64 | J30: 128 | K30: 256 | L30: 512
D31: 42 | E31: 84 | F31: 168 | G31: 336 | H31: 672 | I31: 1344 | J31: 2688 | K31: 5376 | L31: 10752
C32: Classic ACO | D32: =D3/D$2 -> 350.53171 | E32: =E3/E$2 -> 325.76986 | F32: =F3/F$2 -> 310.63563 | G32: =G3/G$2 -> 307.74536 | H32: =H3/H$2 -> 308.18952 | I32: =I3/I$2 -> 305.40452 | J32: =J3/J$2 -> 310.88271 | K32: =K3/K$2 -> 0 | L32: =L3/L$2 -> 0
C33: non CUDA Time | D33: =D4/D$2 -> 24.117581 | E33: =E4/E$2 -> 22.096657 | F33: =F4/F$2 -> 21.395448 | G33: =G4/G$2 -> 21.127788 | H33: =H4/H$2 -> 20.820783 | I33: =I4/I$2 -> 20.3185 | J33: =J4/J$2 -> 19.855719 | K33: =K4/K$2 -> 0 | L33: =L4/L$2 -> 0
C34: omp | D34: =D5/D$2 -> 22.425945 | E34: =E5/E$2 -> 21.024621 | F34: =F5/F$2 -> 20.620326 | G34: =G5/G$2 -> 20.536912 | H34: =H5/H$2 -> 20.709137 | I34: =I5/I$2 -> 20.116635 | J34: =J5/J$2 -> 19.52441 | K34: =K5/K$2 -> 0 | L34: =L5/L$2 -> 0
C35: non CUDA transp Time | D35: =D6/D$2 -> 23.963416 | E35: =E6/E$2 -> 21.832736 | F35: =F6/F$2 -> 20.91347 | G35: =G6/G$2 -> 20.504173 | H35: =H6/H$2 -> 20.740759 | I35: =I6/I$2 -> 20.136382 | J35: =J6/J$2 -> 19.434912 | K35: =K6/K$2 -> 0 | L35: =L6/L$2 -> 0
C36: non CUDA transp_AVX Time | E36: =E7/E$2 -> 22.460257 | F36: =F7/F$2 -> 21.534907 | G36: =G7/G$2 -> 21.136886 | H36: =H7/H$2 -> 21.305887 | I36: =I7/I$2 -> 21.074952 | J36: =J7/J$2 -> 20.228568 | K36: =K7/K$2 -> 0 | L36: =L7/L$2 -> 0
C37: non CUDA transp_AVX_OMP Time | E37: =E8/E$2 -> 22.694612 | F37: =F8/F$2 -> 21.534563 | G37: =G8/G$2 -> 21.124217 | H37: =H8/H$2 -> 21.360512 | I37: =I8/I$2 -> 21.084317 | J37: =J8/J$2 -> 20.235632 | K37: =K8/K$2 -> 0 | L37: =L8/L$2 -> 0
C38: CUDA ant add CPU Time | D38: =D9/D$2 -> 14.710277 | E38: =E9/E$2 -> 13.397912 | F38: =F9/F$2 -> 12.94479 | G38: =G9/G$2 -> 12.804571 | H38: =H9/H$2 -> 12.803035 | I38: =I9/I$2 -> 12.692134 | J38: =J9/J$2 -> 12.803296 | K38: =K9/K$2 -> 0 | L38: =L9/L$2 -> 0
C39: CUDA ant add CPU12 | D39: =D10/D$2 -> 36.005048 | E39: =E10/E$2 -> 31.66234 | F39: =F10/F$2 -> 30.998537 | G39: =G10/G$2 -> 30.668232 | H39: =H10/H$2 -> 30.484524 | I39: =I10/I$2 -> 22.818525 | J39: =J10/J$2 -> 19.932894 | K39: =K10/K$2 -> 0 | L39: =L10/L$2 -> 0
C40: CUDA ant add CPU_AVX_transp Time | E40: =E11/E$2 -> 13.558345 | F40: =F11/F$2 -> 13.116518 | G40: =G11/G$2 -> 12.932246 | H40: =H11/H$2 -> 12.814707 | I40: =I11/I$2 -> 12.750851 | J40: =J11/J$2 -> 12.7204 | K40: =K11/K$2 -> 0 | L40: =L11/L$2 -> 0
C41: Time non CUDA AVX time 4 | D41: =D12/D$2 -> 24.223276 | E41: =E12/E$2 -> 22.491319 | F41: =F12/F$2 -> 21.589615 | G41: =G12/G$2 -> 21.084029 | H41: =H12/H$2 -> 20.893503 | I41: =I12/I$2 -> 20.441171 | J41: =J12/J$2 -> 19.707323
C42: Time non CUDA AVX add CPU time 4 | D42: =D13/D$2 -> 14.93208 | E42: =E13/E$2 -> 13.731957 | F42: =F13/F$2 -> 13.358674 | G42: =G13/G$2 -> 13.152908 | H42: =H13/H$2 -> 13.121755 | I42: =I13/I$2 -> 13.005555 | J42: =J13/J$2 -> 13.061311
C55: 50 | D55: 2 | E55: 4 | F55: 8 | G55: 16 | H55: 32 | I55: 64 | J55: 128 | K55: 256 | L55: 512
D56: 42 | E56: 84 | F56: 168 | G56: 336 | H56: 672 | I56: 1344 | J56: 2688 | K56: 5376 | L56: 10752
C57: Classic ACO | D57: =D$3/D3 -> 1 | E57: =E$3/E3 -> 1 | F57: =F$3/F3 -> 1 | G57: =G$3/G3 -> 1 | H57: =H$3/H3 -> 1 | I57: =I$3/I3 -> 1 | J57: =J$3/J3 -> 1 | K57: =K$3/K3 -> #DIV/0! | L57: =L$3/L3 -> #DIV/0!
C58: non CUDA Time | D58: =D$3/D4 -> 14.534282 | E58: =E$3/E4 -> 14.742948 | F58: =F$3/F4 -> 14.518772 | G58: =G$3/G4 -> 14.565905 | H58: =H$3/H4 -> 14.802014 | I58: =I$3/I4 -> 15.03086 | J58: =J$3/J4 -> 15.657087 | K58: =K$3/K4 -> #DIV/0! | L58: =L$3/L4 -> #DIV/0!
C59: omp | D59: =D$3/D5 -> 15.630633 | E59: =E$3/E5 -> 15.494684 | F59: =F$3/F5 -> 15.064535 | G59: =G$3/G5 -> 14.984987 | H59: =H$3/H5 -> 14.881814 | I59: =I$3/I5 -> 15.18169 | J59: =J$3/J5 -> 15.922771
C60: non CUDA transp Time | D60: =D$3/D6 -> 14.627786 | E60: =E$3/E6 -> 14.921165 | F60: =F$3/F6 -> 14.853376 | G60: =G$3/G6 -> 15.008914 | H60: =H$3/H6 -> 14.859125 | I60: =I$3/I6 -> 15.166802 | J60: =J$3/J6 -> 15.996095 | K60: =K$3/K6 -> #DIV/0! | L60: =L$3/L6 -> #DIV/0!
C61: non CUDA transp_AVX Time | E61: =E$3/E7 -> 14.50428 | F61: =F$3/F7 -> 14.424749 | G61: =G$3/G7 -> 14.559636 | H61: =H$3/H7 -> 14.464994 | I61: =I$3/I7 -> 14.491351 | J61: =J$3/J7 -> 15.368498
C62: non CUDA transp_AVX_OMP Time | E62: =E$3/E8 -> 14.354502 | F62: =F$3/F8 -> 14.424979 | G62: =G$3/G8 -> 14.568367 | H62: =H$3/H8 -> 14.428003 | I62: =I$3/I8 -> 14.484914 | J62: =J$3/J8 -> 15.363133
C63: CUDA ant add CPU Time | D63: =D$3/D9 -> 23.829036 | E63: =E$3/E9 -> 24.314972 | F63: =F$3/F9 -> 23.996961 | G63: =G$3/G9 -> 24.034022 | H63: =H$3/H9 -> 24.071599 | I63: =I$3/I9 -> 24.062504 | J63: =J$3/J9 -> 24.281459 | K63: =K$3/K9 -> #DIV/0! | L63: =L$3/L9 -> #DIV/0!
C64: CUDA ant add CPU12 | D64: =D$3/D10 -> 9.735627 | E64: =E$3/E10 -> 10.288875 | F64: =F$3/F10 -> 10.020977 | G64: =G$3/G10 -> 10.034662 | H64: =H$3/H10 -> 10.109704 | I64: =I$3/I10 -> 13.384061 | J64: =J$3/J10 -> 15.596466 | K64: =K$3/K10 -> #DIV/0! | L64: =L$3/L10 -> #DIV/0!
C65: CUDA ant add CPU_AVX_transp Time | E65: =E$3/E11 -> 24.027258 | F65: =F$3/F11 -> 23.682782 | G65: =G$3/G11 -> 23.796745 | H65: =H$3/H11 -> 24.049675 | I65: =I$3/I11 -> 23.951697 | J65: =J$3/J11 -> 24.439695
C66: Time non CUDA AVX time 4 | D66: =D$3/D12 -> 14.470863 | E66: =E$3/E12 -> 14.484249 | F66: =F$3/F12 -> 14.388197 | G66: =G$3/G12 -> 14.596136 | H66: =H$3/H12 -> 14.750496 | I66: =I$3/I12 -> 14.940657 | J66: =J$3/J12 -> 15.774984
C67: Time non CUDA AVX add CPU time 4 | D67: =D$3/D13 -> 23.475075 | E67: =E$3/E13 -> 23.723483 | F67: =F$3/F13 -> 23.253478 | G67: =G$3/G13 -> 23.397515 | H67: =H$3/H13 -> 23.486913 | I67: =I$3/I13 -> 23.482621 | J67: =J$3/J13 -> 23.8018
C86: Дисперсия
...

Sheet 1050COMP
B1: 1.96 | C1: 50 | D1: 2 | E1: 4 | F1: 8 | G1: 16 | H1: 32 | I1: 64 | J1: 128 | K1: 256 | L1: 512 | M1: 9th Gen Intel Core i5-9400F 2.90 GHz (16Gb ОЗУ),
B2: МО | D2: 42 | E2: 84 | F2: 168 | G2: 336 | H2: 672 | I2: 1344 | J2: 2688 | K2: 5376 | L2: 10752
A3: 1 | C3: Classic ACO | D3: 13775.68 | E3: 24819.016 | F3: 47399.626 | G3: 96405.03 | H3: 197567.46 | I3: 376437.82 | J3: 762594.84
C4: non CUDA Time | D4: 1021.2764 | E4: 1875.4454 | F4: 3606.0204 | G4: 7106.4438 | H4: 14355.808 | I4: 27843.878 | J4: 54934.598
C5: omp | D5: 936.52016 | E5: 1796.2392 | F5: 3518.97 | G5: 7123.3738 | H5: 14467.484 | I5: 27997.418 | J5: 54080.832
C6: non CUDA transp Time | D6: 989.51166 | E6: 1854.2994 | F6: 3547.5268 | G6: 7089.6244 | H6: 14367.464 | I6: 27639.606 | J6: 53463.302
C7: non CUDA transp_AVX Time | E7: 1907.0192 | F7: 3649.6616 | G7: 7350.9722 | H7: 14737.54 | I7: 28823.408 | J7: 55301.924
C8: non CUDA transp_AVX_OMP Time | E8: 1909.23 | F8: 3647.0058 | G8: 7340.941 | H8: 14774.014 | I8: 28806.066 | J8: 55311.378
C9: CUDA ant add CPU Time | D9: 621.49762 | E9: 1148.686 | F9: 2232.367 | G9: 4529.7836 | H9: 9484.4038 | I9: 19648.39 | J9: 36474.402
C10: CUDA ant add CPU12 | D10: 1858.168 | E10: 2420.109 | F10: 4527.1802 | G10: 8310.85 | H10: 15832.002 | I10: 27962.48 | J10: 51638.59
C11: CUDA ant add CPU_AVX_transp Time | E11: 1191.7366 | F11: 2306.617 | G11: 4894.3002 | H11: 9785.159 | I11: 18785.994 | J11: 57289.882
C12: Time non CUDA AVX time 4 | D12: 980.75398 | E12: 1822.0432 | F12: 3521.0432 | G12: 6913.7884 | H12: 14600.704 | I12: 27769.686 | J12: 53720.156
C13: Time non CUDA AVX add CPU time 4 | D13: 585.59822 | E13: 1094.3246 | F13: 2120.4718 | G13: 4187.7104 | H13: 9455.6194 | I13: 19091.788 | J13: 39015.478
C30: 6 | D30: 2 | E30: 4 | F30: 8 | G30: 16 | H30: 32 | I30: 64 | J30: 128 | K30: 256 | L30: 512
D31: 42 | E31: 84 | F31: 168 | G31: 336 | H31: 672 | I31: 1344 | J31: 2688 | K31: 5376 | L31: 10752
