Workbook

Sheet 42p stat
A2: CUDA Time | B2: 1 | C2: 25 | D2: Duration Mean: | E2: 0 | F2: 0 | G2: GPU Time 1 Mean: | H2: 386.53794 | I2: 2.09325 | J2: GPU Time 2 Mean: | K2: 385.0516 | L2: 1.955683 | M2: GPU Time 3 Mean: | N2: 17.801709 | O2: 0.003968 | P2: GPU Time 4 Mean: | Q2: 0 | R2: 0 | S2: GPU Time 5 Mean: | T2: 0 | U2: 0 | V2: GPU Time 6 Mean: | W2: 0 | X2: 0 | Y2: GPU Time 7 Mean: | Z2: 0 | AA2: 0 | AB2: GPU Time 8 Mean: | AC2: 0 | AD2: 0 | AE2: Global Min Mean: | AF2: 1 | AG2: 0 | AH2: Global Max Mean: | AI2: 1 | AJ2: 0 | AK2: Hash Fail Count Mean: | AL2: 0 | AM2: 0
A3: CUDA Time | B3: 2 | C3: 50 | D3: Duration Mean: | E3: 0 | F3: 0 | G3: GPU Time 1 Mean: | H3: 773.05815 | I3: 8.481642 | J3: GPU Time 2 Mean: | K3: 770.09287 | L3: 7.866207 | M3: GPU Time 3 Mean: | N3: 35.603427 | O3: 0.015464 | P3: GPU Time 4 Mean: | Q3: 0 | R3: 0 | S3: GPU Time 5 Mean: | T3: 0 | U3: 0 | V3: GPU Time 6 Mean: | W3: 0 | X3: 0 | Y3: GPU Time 7 Mean: | Z3: 0 | AA3: 0 | AB3: GPU Time 8 Mean: | AC3: 0 | AD3: 0 | AE3: Global Min Mean: | AF3: 1 | AG3: 0 | AH3: Global Max Mean: | AI3: 1 | AJ3: 0 | AK3: Hash Fail Count Mean: | AL3: 0 | AM3: 0
A4: CUDA Time | B4: 3 | C4: 75 | D4: Duration Mean: | E4: 0 | F4: 0 | G4: GPU Time 1 Mean: | H4: 1159.5895 | I4: 19.071536 | J4: GPU Time 2 Mean: | K4: 1155.1391 | L4: 17.739904 | M4: GPU Time 3 Mean: | N4: 53.404667 | O4: 0.034409 | P4: GPU Time 4 Mean: | Q4: 0 | R4: 0 | S4: GPU Time 5 Mean: | T4: 0 | U4: 0 | V4: GPU Time 6 Mean: | W4: 0 | X4: 0 | Y4: GPU Time 7 Mean: | Z4: 0 | AA4: 0 | AB4: GPU Time 8 Mean: | AC4: 0 | AD4: 0 | AE4: Global Min Mean: | AF4: 1 | AG4: 0 | AH4: Global Max Mean: | AI4: 1 | AJ4: 0 | AK4: Hash Fail Count Mean: | AL4: 0 | AM4: 0
A5: CUDA Time | B5: 4 | C5: 100 | D5: Duration Mean: | E5: 0 | F5: 0 | G5: GPU Time 1 Mean: | H5: 1546.1119 | I5: 33.973166 | J5: GPU Time 2 Mean: | K5: 1540.1868 | L5: 31.658061 | M5: GPU Time 3 Mean: | N5: 71.207392 | O5: 0.061212 | P5: GPU Time 4 Mean: | Q5: 0 | R5: 0 | S5: GPU Time 5 Mean: | T5: 0 | U5: 0 | V5: GPU Time 6 Mean: | W5: 0 | X5: 0 | Y5: GPU Time 7 Mean: | Z5: 0 | AA5: 0 | AB5: GPU Time 8 Mean: | AC5: 0 | AD5: 0 | AE5: Global Min Mean: | AF5: 1 | AG5: 0 | AH5: Global Max Mean: | AI5: 1 | AJ5: 0 | AK5: Hash Fail Count Mean: | AL5: 0 | AM5: 0
A6: CUDA Time | B6: 5 | C6: 125 | D6: Duration Mean: | E6: 0 | F6: 0 | G6: GPU Time 1 Mean: | H6: 1932.643 | I6: 53.111879 | J6: GPU Time 2 Mean: | K6: 1925.2337 | L6: 49.499845 | M6: GPU Time 3 Mean: | N6: 89.008901 | O6: 0.095782 | P6: GPU Time 4 Mean: | Q6: 0 | R6: 0 | S6: GPU Time 5 Mean: | T6: 0 | U6: 0 | V6: GPU Time 6 Mean: | W6: 0 | X6: 0 | Y6: GPU Time 7 Mean: | Z6: 0 | AA6: 0 | AB6: GPU Time 8 Mean: | AC6: 0 | AD6: 0 | AE6: Global Min Mean: | AF6: 1 | AG6: 0 | AH6: Global Max Mean: | AI6: 1 | AJ6: 0 | AK6: Hash Fail Count Mean: | AL6: 0 | AM6: 0
A7: CUDA Time | B7: 6 | C7: 150 | D7: Duration Mean: | E7: 0 | F7: 0 | G7: GPU Time 1 Mean: | H7: 2319.2309 | I7: 75.928983 | J7: GPU Time 2 Mean: | K7: 2310.289 | L7: 71.338084 | M7: GPU Time 3 Mean: | N7: 106.80972 | O7: 0.137724 | P7: GPU Time 4 Mean: | Q7: 0 | R7: 0 | S7: GPU Time 5 Mean: | T7: 0 | U7: 0 | V7: GPU Time 6 Mean: | W7: 0 | X7: 0 | Y7: GPU Time 7 Mean: | Z7: 0 | AA7: 0 | AB7: GPU Time 8 Mean: | AC7: 0 | AD7: 0 | AE7: Global Min Mean: | AF7: 1 | AG7: 0 | AH7: Global Max Mean: | AI7: 1 | AJ7: 0 | AK7: Hash Fail Count Mean: | AL7: 0 | AM7: 0
A8: CUDA Time | B8: 7 | C8: 175 | D8: Duration Mean: | E8: 0 | F8: 0 | G8: GPU Time 1 Mean: | H8: 2705.773 | I8: 103.31385 | J8: GPU Time 2 Mean: | K8: 2695.338 | L8: 97.113734 | M8: GPU Time 3 Mean: | N8: 124.61137 | O8: 0.187866 | P8: GPU Time 4 Mean: | Q8: 0 | R8: 0 | S8: GPU Time 5 Mean: | T8: 0 | U8: 0 | V8: GPU Time 6 Mean: | W8: 0 | X8: 0 | Y8: GPU Time 7 Mean: | Z8: 0 | AA8: 0 | AB8: GPU Time 8 Mean: | AC8: 0 | AD8: 0 | AE8: Global Min Mean: | AF8: 1 | AG8: 0 | AH8: Global Max Mean: | AI8: 1 | AJ8: 0 | AK8: Hash Fail Count Mean: | AL8: 0 | AM8: 0
A9: CUDA Time | B9: 8 | C9: 200 | D9: Duration Mean: | E9: 0 | F9: 0 | G9: GPU Time 1 Mean: | H9: 3092.3049 | I9: 134.95811 | J9: GPU Time 2 Mean: | K9: 3080.3883 | L9: 126.84346 | M9: GPU Time 3 Mean: | N9: 142.41338 | O9: 0.244917 | P9: GPU Time 4 Mean: | Q9: 0 | R9: 0 | S9: GPU Time 5 Mean: | T9: 0 | U9: 0 | V9: GPU Time 6 Mean: | W9: 0 | X9: 0 | Y9: GPU Time 7 Mean: | Z9: 0 | AA9: 0 | AB9: GPU Time 8 Mean: | AC9: 0 | AD9: 0 | AE9: Global Min Mean: | AF9: 1 | AG9: 0 | AH9: Global Max Mean: | AI9: 1 | AJ9: 0 | AK9: Hash Fail Count Mean: | AL9: 0 | AM9: 0
A10: CUDA Time | B10: 9 | C10: 225 | D10: Duration Mean: | E10: 0 | F10: 0 | G10: GPU Time 1 Mean: | H10: 3478.8361 | I10: 170.91866 | J10: GPU Time 2 Mean: | K10: 3465.4395 | L10: 160.62738 | M10: GPU Time 3 Mean: | N10: 160.21437 | O10: 0.309492 | P10: GPU Time 4 Mean: | Q10: 0 | R10: 0 | S10: GPU Time 5 Mean: | T10: 0 | U10: 0 | V10: GPU Time 6 Mean: | W10: 0 | X10: 0 | Y10: GPU Time 7 Mean: | Z10: 0 | AA10: 0 | AB10: GPU Time 8 Mean: | AC10: 0 | AD10: 0 | AE10: Global Min Mean: | AF10: 1 | AG10: 0 | AH10: Global Max Mean: | AI10: 1 | AJ10: 0 | AK10: Hash Fail Count Mean: | AL10: 0 | AM10: 0
A11: CUDA Time | B11: 10 | C11: 250 | D11: Duration Mean: | E11: 0 | F11: 0 | G11: GPU Time 1 Mean: | H11: 3865.3893 | I11: 210.83109 | J11: GPU Time 2 Mean: | K11: 3850.4974 | L11: 198.29923 | M11: GPU Time 3 Mean: | N11: 178.01702 | O11: 0.382312 | P11: GPU Time 4 Mean: | Q11: 0 | R11: 0 | S11: GPU Time 5 Mean: | T11: 0 | U11: 0 | V11: GPU Time 6 Mean: | W11: 0 | X11: 0 | Y11: GPU Time 7 Mean: | Z11: 0 | AA11: 0 | AB11: GPU Time 8 Mean: | AC11: 0 | AD11: 0 | AE11: Global Min Mean: | AF11: 1 | AG11: 0 | AH11: Global Max Mean: | AI11: 1 | AJ11: 0 | AK11: Hash Fail Count Mean: | AL11: 0 | AM11: 0
A12: CUDA Time | B12: 11 | C12: 275 | D12: Duration Mean: | E12: 0 | F12: 0 | G12: GPU Time 1 Mean: | H12: 4251.9301 | I12: 254.85933 | J12: GPU Time 2 Mean: | K12: 4235.5517 | L12: 239.95853 | M12: GPU Time 3 Mean: | N12: 195.81879 | O12: 0.462784 | P12: GPU Time 4 Mean: | Q12: 0 | R12: 0 | S12: GPU Time 5 Mean: | T12: 0 | U12: 0 | V12: GPU Time 6 Mean: | W12: 0 | X12: 0 | Y12: GPU Time 7 Mean: | Z12: 0 | AA12: 0 | AB12: GPU Time 8 Mean: | AC12: 0 | AD12: 0 | AE12: Global Min Mean: | AF12: 1 | AG12: 0 | AH12: Global Max Mean: | AI12: 1 | AJ12: 0 | AK12: Hash Fail Count Mean: | AL12: 0 | AM12: 0
A13: CUDA Time | B13: 12 | C13: 300 | D13: Duration Mean: | E13: 0 | F13: 0 | G13: GPU Time 1 Mean: | H13: 4638.4879 | I13: 303.09449 | J13: GPU Time 2 Mean: | K13: 4620.6146 | L13: 285.68196 | M13: GPU Time 3 Mean: | N13: 213.62043 | O13: 0.551105 | P13: GPU Time 4 Mean: | Q13: 0 | R13: 0 | S13: GPU Time 5 Mean: | T13: 0 | U13: 0 | V13: GPU Time 6 Mean: | W13: 0 | X13: 0 | Y13: GPU Time 7 Mean: | Z13: 0 | AA13: 0 | AB13: GPU Time 8 Mean: | AC13: 0 | AD13: 0 | AE13: Global Min Mean: | AF13: 1 | AG13: 0 | AH13: Global Max Mean: | AI13: 1 | AJ13: 0 | AK13: Hash Fail Count Mean: | AL13: 0 | AM13: 0
... A1181: CUDA opt ant par | B1181: 20 | C1181: 500 | D1181: Duration Mean: | E1181: 0 | F1181: 0 | G1181: GPU Time 1 Mean: | H1181: 676.00823 | I1181: 0.415945 | J1181: GPU Time 2 Mean: | K1181: 229.08458 | L1181: 0.001306 | M1181: GPU Time 3 Mean: | N1181: 0 | O1181: 0 | P1181: GPU Time 4 Mean: | Q1181: 0 | R1181: 0 | S1181: GPU Time 5 Mean: | T1181: 0 | U1181: 0 | V1181: GPU Time 6 Mean: | W1181: 0 | X1181: 0 | Y1181: GPU Time 7 Mean: | Z1181: 0 | AA1181: 0 | AB1181: GPU Time 8 Mean: | AC1181: 0 | AD1181: 0 | AE1181: Global Min Mean: | AF1181: 32767 | AG1181: 0 | AH1181: Global Max Mean: | AI1181: -32767 | AJ1181: 0 | AK1181: Hash Fail Count Mean: | AL1181: 0 | AM1181: 0

Sheet 42p trace
A1: Device 0: NVIDIA GeForce RTX 3060 Laptop GPU | B1: Max thread in blocks: 1024 Total Global Memory: 6143,5 MB Shared Memory per Block: 49152 bytes Constant Memory: 65536 bytes Registers per Block: 65536 Warp Size: 32 Compute Capability: 8,6 Can Map Host Memory: Yes Clock Rate: 1425 MHz L2 Cache Size: 3145728 bytes Multiprocessor Count: 30 | C1: Max thread in blocks by axis: (1024, 1024, 64) | D1: Max blocks by axis: (2147483647, 65535, 65535) | E1: PARAMETR_SIZE: 336 | F1: PARAMETR_SIZE_ONE_X: 21 | G1: MAX_VALUE_SIZE: 5 | H1: NAME_FILE_GRAPH: Parametr_Graph/test336,txt | I1: ANT_SIZE: 500 | J1: KOL_ITERATION: 500 | K1: KOL_PROGON_STATISTICS: 50 | L1: PARAMETR_Q: 1 | M1: PARAMETR_RO: 0,999 | N1: TYPE_ACO: 1 | O1: ACOCCyN_KOL_ITERATION: 50 | P1: FUNCTION: SHAFFERA
A2: Time CUDA Time: | B2: 8730.12 | C2: 7841.72 | D2: 7744.96 | E2: 7710.12 | F2: 357.41 | G2: 0 | H2: 357.41 | I2: 1 | J2: 1 | K2: 0
A3: Time CUDA Time: | B3: 7767.07 | C3: 7757.79 | D3: 7664.68 | E3: 7631.4 | F3: 354.497 | G3: 0 | H3: 354.497 | I3: 1 | J3: 1 | K3: 0
A4: Time CUDA Time: | B4: 7773.37 | C4: 7764.1 | D4: 7670.92 | E4: 7639.14 | F4: 354.643 | G4: 0 | H4: 354.643 | I4: 1 | J4: 1 | K4: 0
A5: Time CUDA Time: | B5: 7788.66 | C5: 7778.82 | D5: 7696.36 | E5: 7664.05 | F5: 355.001 | G5: 0 | H5: 355.001 | I5: 1 | J5: 1 | K5: 0
A6: Time CUDA Time: | B6: 7787.81 | C6: 7778.41 | D6: 7697.37 | E6: 7664.4 | F6: 355.035 | G6: 0 | H6: 355.035 | I6: 1 | J6: 1 | K6: 0
A7: Time CUDA Time: | B7: 7784.77 | C7: 7775.34 | D7: 7696.62 | E7: 7663.68 | F7: 355.054 | G7: 0 | H7: 355.054 | I7: 1 | J7: 1 | K7: 0
A8: Time CUDA Time: | B8: 7792.52 | C8: 7782.81 | D8: 7691.91 | E8: 7663.21 | F8: 355.017 | G8: 0 | H8: 355.017 | I8: 1 | J8: 1 | K8: 0
A9: Time CUDA Time: | B9: 7791.82 | C9: 7782.46 | D9: 7693.31 | E9: 7663.01 | F9: 355.003 | G9: 0 | H9: 355.003 | I9: 1 | J9: 1 | K9: 0
A10: Time CUDA Time: | B10: 7792.26 | C10: 7782.54 | D10: 7691.94 | E10: 7662.98 | F10: 355.013 | G10: 0 | H10: 355.013 | I10: 1 | J10: 1 | K10: 0
A11: Time CUDA Time: | B11: 7793.79 | C11: 7784.07 | D11: 7692.91 | E11: 7662.98 | F11: 354.975 | G11: 0 | H11: 354.975 | I11: 1 | J11: 1 | K11: 0
A12: Time CUDA Time: | B12: 7798.62 | C12: 7789.47 | D12: 7699.03 | E12: 7669.38 | F12: 355.058 | G12: 0 | H12: 355.058 | I12: 1 | J12: 1 | K12: 0
A13: Time CUDA Time: | B13: 7816.31 | C13: 7806.51 | D13: 7716.88 | E13: 7688.55 | F13: 355.341 | G13: 0 | H13: 355.341 | I13: 1 | J13: 1 | K13: 0
... A54: Time CUDA Time: | B54: 7876.31 | C54: 7864.33 | D54: 7771.38 | E54: 7742.49 | F54: 358.033 | G54: 0 | H54: 358.033 | I54: 1 | J54: 1 | K54: 0
A55: Time CUDA Time: | B55: 7876.12 | C55: 7864.46 | D55: 7771.6 | E55: 7742.43 | F55: 357.846 | G55: 0 | H55: 357.846 | I55: 1 | J55: 1 | K55: 0 | R55: МО | U55: дисп | X55: CI
A56: Time CUDA Time: | B56: 7878.32 | C56: 7866 | D56: 7771.58 | E56: 7742.53 | F56: 357.805 | G56: 0 | H56: 357.805 | I56: 1 | J56: 1 | K56: 0 | R56: =AVERAGE(B7:B56) -> 7828.2978 | S56: =AVERAGE(C7:C56) -> 7818.6338 | U56: =_xlfn.VAR.P(B7:B56) -> 940.97641 | V56: =_xlfn.VAR.P(C7:C56) -> 920.71229 | X56: =1.96*SQRT(U56)/50 -> 1.2024733 | Y56: =1.96*SQRT(V56)/50 -> 1.1894551
A57: Time CUDA time: | B57: 391571.74 | C57: sec
A58: Time CUDA ant par: | B58: 2035.05 | C58: 2023.33 | D58: 1981.91 | E58: 1954.41 | F58: 443.341 | G58: 0.0560092 | H58: 0.931663 | I58: 0
A59: Time CUDA ant par: | B59: 2036.88 | C59: 2025.25 | D59: 1981.6 | E59: 1954.04 | F59: 443.196 | G59: 0.0544409 | H59: 0.958756 | I59: 0
A60: Time CUDA ant par: | B60: 2037.45 | C60: 2024.41 | D60: 1981.38 | E60: 1954.16 | F60: 443.191 | G60: 0.0539097 | H60: 0.931804 | I60: 0
A61: Time CUDA ant par: | B61: 2034.68 | C61: 2023.01 | D61: 1981.32 | E61: 1954.13 | F61: 443.223 | G61: 0.0539956 | H61: 0.931825 | I61: 0
A62: Time CUDA ant par: | B62: 2035.99 | C62: 2024.09 | D62: 1981.53 | E62: 1954.27 | F62: 443.229 | G62: 0.0567785 | H62: 0.931835 | I62: 0
A63: Time CUDA ant par: | B63: 2038.08 | C63: 2028.43 | D63: 1982.58 | E63: 1954.2 | F63: 443.216 | G63: 0.0555479 | H63: 0.931728 | I63: 0
A64: Time CUDA ant par: | B64: 2019.78 | C64: 2008.56 | D64: 1969.41 | E64: 1942.84 | F64: 440.621 | G64: 0.0613343 | H64: 0.931826 | I64: 0
A65: Time CUDA ant par: | B65: 2020.33 | C65: 2008.41 | D65: 1966.51 | E65: 1939.37 | F65: 439.859 | G65: 0.0832557 | H65: 0.958452 | I65: 0
A66: Time CUDA ant par: | B66: 2020.12 | C66: 2008.47 | D66: 1966.55 | E66: 1939.59 | F66: 439.896 | G66: 0.0789526 | H66: 0.93182 | I66: 0
A67: Time CUDA ant par: | B67: 2018.89 | C67: 2009.63 | D67: 1966.85 | E67: 1939.58 | F67: 439.893 | G67: 0.0832745 | H67: 0.932768 | I67: 0
A68: Time CUDA ant par: | B68: 2020.56 | C68: 2008.26 | D68: 1966.52 | E68: 1939.45 | F68: 439.875 | G68: 0.063296 | H68: 0.931809 | I68: 0
A69: Time CUDA ant par: | B69: 2019.99 | C69: 2008.09 | D69: 1966.53 | E69: 1939.51 | F69: 439.9 | G69: 0.0756248 | H69: 0.931641 | I69: 0
... A110: Time CUDA ant par: | B110: 2028.81 | C110: 2018.92 | D110: 1967.26 | E110: 1939.66 | F110: 439.936 | G110: 0.0571507 | H110: 0.931751 | I110: 0
A111: Time CUDA ant par: | B111: 2041.39 | C111: 2032.37 | D111: 1969.35 | E111: 1939.66 | F111: 439.883 | G111: 0.0626461 | H111: 0.943861 | I111: 0 | R111: МО | U111: дисп | X111: CI
A112: Time CUDA ant par: | B112: 2045.62 | C112: 2036.17 | D112: 1967.45 | E112: 1939.49 | F112: 439.896 | G112: 0.0546546 | H112: 0.931834 | I112: 0 | R112: =AVERAGE(B63:B112) -> 2023.2886 | S112: =AVERAGE(C63:C112) -> 2013.0414 | U112: =_xlfn.VAR.P(B63:B112) -> 45.259968 | V112: =_xlfn.VAR.P(C63:C112) -> 48.51026 | X112: =1.96*SQRT(U112)/50 -> 0.26372007 | Y112: =1.96*SQRT(V112)/50 -> 0.27302528
A113: Time CUDA ant par: | B113: 101364.78 | C113: sec
A114: Time CUDA ant add CPU Time: | B114: 2015.55 | C114: 2006.13 | D114: 1969.33 | E114: 1966.65 | F114: 336.812 | G114: 0.0622509 | H114: 0.931799 | I114: 0
A115: Time CUDA ant add CPU Time: | B115: 2009.58 | C115: 2000.22 | D115: 1962.79 | E115: 1966.39 | F115: 338.284 | G115: 0.0566437 | H115: 0.931835 | I115: 0
A116: Time CUDA ant add CPU Time: | B116: 2016.53 | C116: 2007.42 | D116: 1968.93 | E116: 1966.16 | F116: 335.75 | G116: 0.0547874 | H116: 0.931836 | I116: 0
A117: Time CUDA ant add CPU Time: | B117: 2015.94 | C117: 2006.65 | D117: 1971.93 | E117: 1968.27 | F117: 337.587 | G117: 0.074315 | H117: 0.948247 | I117: 0
A118: Time CUDA ant add CPU Time: | B118: 2002.16 | C118: 1992.87 | D118: 1959.53 | E118: 1960.03 | F118: 338.77 | G118: 0.0601529 | H118: 0.947095 | I118: 0
A119: Time CUDA ant add CPU Time: | B119: 2019.37 | C119: 2009.55 | D119: 1966.01 | E119: 1976.55 | F119: 345.004 | G119: 0.060251 | H119: 0.931737 | I119: 0
A120: Time CUDA ant add CPU Time: | B120: 2006.17 | C120: 1996.83 | D120: 1959.9 | E120: 1958.64 | F120: 329.976 | G120: 0.0543244 | H120: 0.931813 | I120: 0
...

Sheet 42 end
D2: T_start | E2: T_Delt | F2: T1 | G2: T2 | H2: T3
A3: 1 | C3: =OFFSET('42p stat'!$A$1,A3*20,0) -> CUDA Time | D3: =OFFSET('42p trace'!$R$56,(A3-1)*56,0)-OFFSET('42p trace'!$S$56,(A3-1)*56,0) -> 9.664 | E3: =OFFSET('42p trace'!$S$56,(A3-1)*56,0)-OFFSET('42p stat'!$H$1,A3*20,0) -> 87.402482 | F3: =OFFSET('42p stat'!$H$1,A3*20,0)-OFFSET('42p stat'!$K$1,A3*20,0) -> 29.659668 | G3: =OFFSET('42p stat'!$K$1,A3*20,0)-OFFSET('42p stat'!$N$1,A3*20,0) -> 7345.5206 | H3: =OFFSET('42p stat'!$N$1,A3*20,0) -> 356.05104
A4: 1 | C4: =OFFSET('42p stat'!$A$1,A4*20,0) -> CUDA Time | D4: =OFFSET('42p trace'!$U$56,(A4-1)*56,0) -> 940.97641 | E4: =OFFSET('42p trace'!$V$56,(A4-1)*56,0) -> 920.71229 | F4: =OFFSET('42p stat'!$H$1,A4*20,1) -> 827.31765 | G4: =OFFSET('42p stat'!$K$1,A4*20,1) -> 782.57434 | H4: =OFFSET('42p stat'!$N$1,A4*20,1) -> 1.523558
A5: 2 | C5: =OFFSET('42p stat'!$A$1,A5*20,0) -> CUDA ant par | D5: =OFFSET('42p trace'!$R$56,(A5-1)*56,0)-OFFSET('42p trace'!$S$56,(A5-1)*56,0) -> 10.2472 | E5: =OFFSET('42p trace'!$S$56,(A5-1)*56,0)-OFFSET('42p stat'!$H$1,A5*20,0) -> 45.059984 | F5: =OFFSET('42p stat'!$H$1,A5*20,0)-OFFSET('42p stat'!$K$1,A5*20,0) -> 27.976372 | G5: =OFFSET('42p stat'!$K$1,A5*20,0)-OFFSET('42p stat'!$N$1,A5*20,0) -> 1500.0074 | H5: =OFFSET('42p stat'!$N$1,A5*20,0) -> 439.99769
A6: 2 | C6: =OFFSET('42p stat'!$A$1,A6*20,0) -> CUDA ant par | D6: =OFFSET('42p trace'!$U$56,(A6-1)*56,0) -> 45.259968 | E6: =OFFSET('42p trace'!$V$56,(A6-1)*56,0) -> 48.51026 | F6: =OFFSET('42p stat'!$H$1,A6*20,1) -> 5.797522 | G6: =OFFSET('42p stat'!$K$1,A6*20,1) -> 4.326119 | H6: =OFFSET('42p stat'!$N$1,A6*20,1) -> 0.222084
A7: 3 | C7: =OFFSET('42p stat'!$A$1,A7*20,0) -> CUDA ant add CPU Time | D7: =OFFSET('42p trace'!$R$56,(A7-1)*56,0)-OFFSET('42p trace'!$S$56,(A7-1)*56,0) -> 9.3022 | E7: =OFFSET('42p trace'!$S$56,(A7-1)*56,0)-OFFSET('42p stat'!$H$1,A7*20,0) -> 38.409078 | F7: =OFFSET('42p stat'!$H$1,A7*20,0)-OFFSET('42p stat'!$K$1,A7*20,0) -> -4.31896 | G7: =OFFSET('42p stat'!$K$1,A7*20,0)-OFFSET('42p stat'!$N$1,A7*20,0) -> 1625.1839 | H7: =OFFSET('42p stat'!$N$1,A7*20,0) -> 338.65558
A8: 3 | C8: =OFFSET('42p stat'!$A$1,A8*20,0) -> CUDA ant add CPU Time | D8: =OFFSET('42p trace'!$U$56,(A8-1)*56,0) -> 135.81267 | E8: =OFFSET('42p trace'!$V$56,(A8-1)*56,0) -> 133.45536 | F8: =OFFSET('42p stat'!$H$1,A8*20,1) -> 133.57545 | G8: =OFFSET('42p stat'!$K$1,A8*20,1) -> 80.0546 | H8: =OFFSET('42p stat'!$N$1,A8*20,1) -> 36.033029
A9: 4 | C9: =OFFSET('42p stat'!$A$1,A9*20,0) -> CUDA opt Time | D9: =OFFSET('42p trace'!$R$56,(A9-1)*56,0)-OFFSET('42p trace'!$S$56,(A9-1)*56,0) -> 9.6816 | E9: =OFFSET('42p trace'!$S$56,(A9-1)*56,0)-OFFSET('42p stat'!$H$1,A9*20,0) -> 93.422541 | F9: =OFFSET('42p stat'!$H$1,A9*20,0)-OFFSET('42p stat'!$K$1,A9*20,0) -> 392.11903 | G9: =OFFSET('42p stat'!$K$1,A9*20,0)-OFFSET('42p stat'!$N$1,A9*20,0) -> 7383.976 | H9: =OFFSET('42p stat'!$N$1,A9*20,0) -> 0
A10: 4 | C10: =OFFSET('42p stat'!$A$1,A10*20,0) -> CUDA opt Time | D10: =OFFSET('42p trace'!$U$56,(A10-1)*56,0) -> 58.524995 | E10: =OFFSET('42p trace'!$V$56,(A10-1)*56,0) -> 58.19687 | F10: =OFFSET('42p stat'!$H$1,A10*20,1) -> 45.498332 | G10: =OFFSET('42p stat'!$K$1,A10*20,1) -> 41.514512 | H10: =OFFSET('42p stat'!$N$1,A10*20,1) -> 0
A11: 5 | C11: =OFFSET('42p stat'!$A$1,A11*20,0) -> CUDA opt ant | D11: =OFFSET('42p trace'!$R$56,(A11-1)*56,0)-OFFSET('42p trace'!$S$56,(A11-1)*56,0) -> 9.477 | E11: =OFFSET('42p trace'!$S$56,(A11-1)*56,0)-OFFSET('42p stat'!$H$1,A11*20,0) -> 43.826678 | F11: =OFFSET('42p stat'!$H$1,A11*20,0)-OFFSET('42p stat'!$K$1,A11*20,0) -> 469.25925 | G11: =OFFSET('42p stat'!$K$1,A11*20,0)-OFFSET('42p stat'!$N$1,A11*20,0) -> 1545.5507 | H11: =OFFSET('42p stat'!$N$1,A11*20,0) -> 0
A12: 5 | C12: =OFFSET('42p stat'!$A$1,A12*20,0) -> CUDA opt ant | D12: =OFFSET('42p trace'!$U$56,(A12-1)*56,0) -> 33.510891 | E12: =OFFSET('42p trace'!$V$56,(A12-1)*56,0) -> 34.28931 | F12: =OFFSET('42p stat'!$H$1,A12*20,1) -> 42.750338 | G12: =OFFSET('42p stat'!$K$1,A12*20,1) -> 26.424057 | H12: =OFFSET('42p stat'!$N$1,A12*20,1) -> 0
A13: 6 | C13: =OFFSET('42p stat'!$A$1,A13*20,0) -> CUDA opt ant par | D13: =OFFSET('42p trace'!$R$56,(A13-1)*56,0)-OFFSET('42p trace'!$S$56,(A13-1)*56,0) -> 9.463 | E13: =OFFSET('42p trace'!$S$56,(A13-1)*56,0)-OFFSET('42p stat'!$H$1,A13*20,0) -> 47.793731 | F13: =OFFSET('42p stat'!$H$1,A13*20,0)-OFFSET('42p stat'!$K$1,A13*20,0) -> 466.8382 | G13: =OFFSET('42p stat'!$K$1,A13*20,0)-OFFSET('42p stat'!$N$1,A13*20,0) -> 1499.4253 | H13: =OFFSET('42p stat'!$N$1,A13*20,0) -> 0
A14: 6 | C14: =OFFSET('42p stat'!$A$1,A14*20,0) -> CUDA opt ant par | D14: =OFFSET('42p trace'!$U$56,(A14-1)*56,0) -> 26.520826 | E14: =OFFSET('42p trace'!$V$56,(A14-1)*56,0) -> 26.04072 | F14: =OFFSET('42p stat'!$H$1,A14*20,1) -> 1.757347 | G14: =OFFSET('42p stat'!$K$1,A14*20,1) -> 0.018233 | H14: =OFFSET('42p stat'!$N$1,A14*20,1) -> 0
A15: 7 | C15: =OFFSET('42p stat'!$A$1,A15*20,0) -> non CUDA Time | D15: =OFFSET('42p trace'!$R$56,(A15-1)*56,0)-OFFSET('42p trace'!$S$56,(A15-1)*56,0) -> 66.085 | E15: =OFFSET('42p trace'!$S$56,(A15-1)*56,0)-OFFSET('42p stat'!$H$1,A15*20,0) -> 0.130058 | F15: =OFFSET('42p stat'!$H$1,A15*20,0)-OFFSET('42p stat'!$K$1,A15*20,0) -> 6.068788 | G15: =OFFSET('42p stat'!$K$1,A15*20,0)-OFFSET('42p stat'!$N$1,A15*20,0) -> 3537.9692 | H15: =OFFSET('42p stat'!$N$1,A15*20,0) -> 280.25292
A16: 7 | C16: =OFFSET('42p stat'!$A$1,A16*20,0) -> non CUDA Time | D16: =OFFSET('42p trace'!$U$56,(A16-1)*56,0) -> 1399.0469 | E16: =OFFSET('42p trace'!$V$56,(A16-1)*56,0) -> 1330.5534 | F16: =OFFSET('42p stat'!$H$1,A16*20,1) -> 1330.004 | G16: =OFFSET('42p stat'!$K$1,A16*20,1) -> 1323.7467 | H16: =OFFSET('42p stat'!$N$1,A16*20,1) -> 12.518395
A17: 8 | C17: =OFFSET('42p stat'!$A$1,A17*20,0) -> Classic ACO | D17: =OFFSET('42p trace'!$R$56,(A17-1)*56,0)-OFFSET('42p trace'!$S$56,(A17-1)*56,0) -> 4926.032 | E17: =OFFSET('42p trace'!$S$56,(A17-1)*56,0)-OFFSET('42p stat'!$H$1,A17*20,0) -> 158.12936 | F17: =OFFSET('42p stat'!$H$1,A17*20,0)-OFFSET('42p stat'!$K$1,A17*20,0) -> 15.129688 | G17: =OFFSET('42p stat'!$K$1,A17*20,0)-OFFSET('42p stat'!$N$1,A17*20,0) -> 45461.14 | H17: =OFFSET('42p stat'!$N$1,A17*20,0) -> 860.27729
A18: 8 | C18: =OFFSET('42p stat'!$A$1,A18*20,0) -> Classic ACO | D18: =OFFSET('42p trace'!$U$56,(A18-1)*56,0) -> 108605.39 | E18: =OFFSET('42p trace'!$V$56,(A18-1)*56,0) -> 86584.612 | F18: =OFFSET('42p stat'!$H$1,A18*20,1) -> 84088.843 | G18: =OFFSET('42p stat'!$K$1,A18*20,1) -> 84009.291 | H18: =OFFSET('42p stat'!$N$1,A18*20,1) -> 33.19657
A19: 9 | C19: =OFFSET('42p stat'!$A$1,A19*20,0) -> omp | D19: =OFFSET('42p trace'!$R$56,(A19-1)*56,0)-OFFSET('42p trace'!$S$56,(A19-1)*56,0) -> 65.2472 | E19: =OFFSET('42p trace'!$S$56,(A19-1)*56,0)-OFFSET('42p stat'!$H$1,A19*20,0) -> 0.127642 | F19: =OFFSET('42p stat'!$H$1,A19*20,0)-OFFSET('42p stat'!$K$1,A19*20,0) -> 5.928082 | G19: =OFFSET('42p stat'!$K$1,A19*20,0)-OFFSET('42p stat'!$N$1,A19*20,0) -> 3502.2859 | H19: =OFFSET('42p stat'!$N$1,A19*20,0) -> 269.89154
A20: 9 | C20: =OFFSET('42p stat'!$A$1,A20*20,0) -> omp | D20: =OFFSET('42p trace'!$U$56,(A20-1)*56,0) -> 191.14522 | E20: =OFFSET('42p trace'!$V$56,(A20-1)*56,0) -> 194.72628 | F20: =OFFSET('42p stat'!$H$1,A20*20,1) -> 194.62458 | G20: =OFFSET('42p stat'!$K$1,A20*20,1) -> 193.6891 | H20: =OFFSET('42p stat'!$N$1,A20*20,1) -> 3.478465
A21: 10 | C21: =OFFSET('42p stat'!$A$1,A21*20,0) -> non CUDA transp Time | D21: =OFFSET('42p trace'!$R$56,(A21-1)*56,0)-OFFSET('42p trace'!$S$56,(A21-1)*56,0) -> 65.8818 | E21: =OFFSET('42p trace'!$S$56,(A21-1)*56,0)-OFFSET('42p stat'!$H$1,A21*20,0) -> 0.126812 | F21: =OFFSET('42p stat'!$H$1,A21*20,0)-OFFSET('42p stat'!$K$1,A21*20,0) -> 8.31423 | G21: =OFFSET('42p stat'!$K$1,A21*20,0)-OFFSET('42p stat'!$N$1,A21*20,0) -> 3545.0774 | H21: =OFFSET('42p stat'!$N$1,A21*20,0) -> 252.77396
A22: 10 | C22: =OFFSET('42p stat'!$A$1,A22*20,0) -> non CUDA transp Time | D22: =OFFSET('42p trace'!$U$56,(A22-1)*56,0) -> 426.60625 | E22: =OFFSET('42p trace'!$V$56,(A22-1)*56,0) -> 446.54765 | F22: =OFFSET('42p stat'!$H$1,A22*20,1) -> 446.21919 | G22: =OFFSET('42p stat'!$K$1,A22*20,1) -> 440.27908 | H22: =OFFSET('42p stat'!$N$1,A22*20,1) -> 35.66168
A23: 11 | C23: =OFFSET('42p stat'!$A$1,A23*20,0) -> non CUDA transp_AVX Time | D23: =OFFSET('42p trace'!$R$56,(A23-1)*56,0)-OFFSET('42p trace'!$S$56,(A23-1)*56,0) -> 65.977 | E23: =OFFSET('42p trace'!$S$56,(A23-1)*56,0)-OFFSET('42p stat'!$H$1,A23*20,0) -> 0.13396 | F23: =OFFSET('42p stat'!$H$1,A23*20,0)-OFFSET('42p stat'!$K$1,A23*20,0) -> 7.40459 | G23: =OFFSET('42p stat'!$K$1,A23*20,0)-OFFSET('42p stat'!$N$1,A23*20,0) -> 3592.1915 | H23: =OFFSET('42p stat'!$N$1,A23*20,0) -> 283.71639
A24: 11 | C24: =OFFSET('42p stat'!$A$1,A24*20,0) -> non CUDA transp_AVX Time | D24: =OFFSET('42p trace'!$U$56,(A24-1)*56,0) -> 395.93107 | E24: =OFFSET('42p trace'!$V$56,(A24-1)*56,0) -> 403.25413 | F24: =OFFSET('42p stat'!$H$1,A24*20,1) -> 402.71958 | G24: =OFFSET('42p stat'!$K$1,A24*20,1) -> 395.34321 | H24: =OFFSET('42p stat'!$N$1,A24*20,1) -> 85.570767
A25: 12 | C25: =OFFSET('42p stat'!$A$1,A25*20,0) -> non CUDA transp_AVX_OMP Time | D25: =OFFSET('42p trace'!$R$56,(A25-1)*56,0)-OFFSET('42p trace'!$S$56,(A25-1)*56,0) -> 66.0206 | E25: =OFFSET('42p trace'!$S$56,(A25-1)*56,0)-OFFSET('42p stat'!$H$1,A25*20,0) -> 0.123762 | F25: =OFFSET('42p stat'!$H$1,A25*20,0)-OFFSET('42p stat'!$K$1,A25*20,0) -> 7.268704 | G25: =OFFSET('42p stat'!$K$1,A25*20,0)-OFFSET('42p stat'!$N$1,A25*20,0) -> 3592.1909 | H25: =OFFSET('42p stat'!$N$1,A25*20,0) -> 281.77306
A26: 12 | C26: =OFFSET('42p stat'!$A$1,A26*20,0) -> non CUDA transp_AVX_OMP Time | D26: =OFFSET('42p trace'!$U$56,(A26-1)*56,0) -> 399.96893 | E26: =OFFSET('42p trace'!$V$56,(A26-1)*56,0) -> 409.81851 | F26: =OFFSET('42p stat'!$H$1,A26*20,1) -> 409.57284 | G26: =OFFSET('42p stat'!$K$1,A26*20,1) -> 403.80651 | H26: =OFFSET('42p stat'!$N$1,A26*20,1) -> 85.482491
A27: 13 | C27: =OFFSET('42p stat'!$A$1,A27*20,0) -> CUDA ant add CPU_AVX_transp Time | D27: =OFFSET('42p trace'!$R$56,(A27-1)*56,0)-OFFSET('42p trace'!$S$56,(A27-1)*56,0) -> 13.8128 | E27: =OFFSET('42p trace'!$S$56,(A27-1)*56,0)-OFFSET('42p stat'!$H$1,A27*20,0) -> 27.952784 | F27: =OFFSET('42p stat'!$H$1,A27*20,0)-OFFSET('42p stat'!$K$1,A27*20,0) -> 6.290891 | G27: =OFFSET('42p stat'!$K$1,A27*20,0)-OFFSET('42p stat'!$N$1,A27*20,0) -> 1602.1602 | H27: =OFFSET('42p stat'!$N$1,A27*20,0) -> 296.41793
A28: 13 | C28: =OFFSET('42p stat'!$A$1,A28*20,0) -> CUDA ant add CPU_AVX_transp Time | D28: =OFFSET('42p trace'!$U$56,(A28-1)*56,0) -> 136.92603 | E28: =OFFSET('42p trace'!$V$56,(A28-1)*56,0) -> 138.15743 | F28: =OFFSET('42p stat'!$H$1,A28*20,1) -> 88.340936 | G28: =OFFSET('42p stat'!$K$1,A28*20,1) -> 78.048129 | H28: =OFFSET('42p stat'!$N$1,A28*20,1) -> 32.52074
K29: 1.96 | L29: 50
D30: T_start | E30: T_Delt | F30: T1 | G30: T2 | H30: T3 | J30: summ | K30: 2 этап/ общее | L30: ДИ
A31: 1 | C31: =OFFSET('42p stat'!$A$1,A31*20,0) -> CUDA Time | D31: =OFFSET('42p trace'!$R$56,(A31-1)*56,0)-OFFSET('42p trace'!$S$56,(A31-1)*56,0) -> 9.664 | E31: =OFFSET('42p trace'!$S$56,(A31-1)*56,0)-OFFSET('42p stat'!$H$1,A31*20,0) -> 87.402482 | F31: =OFFSET('42p stat'!$H$1,A31*20,0)-OFFSET('42p stat'!$K$1,A31*20,0) -> 29.659668 | G31: =OFFSET('42p stat'!$K$1,A31*20,0)-OFFSET('42p stat'!$N$1,A31*20,0) -> 7345.5206 | H31: =OFFSET('42p stat'!$N$1,A31*20,0) -> 356.05104 | J31: =SUM(E31:H31) -> 7818.6338 | K31: =G31/J31 -> 0.93948902 | L31: =$K$29*POWER(K31,2)*SQRT(G178/(POWER(G31,2)*$L$29)+J178/(POWER(J31,2)*$L$29)) -> 0.0020661108
A32: 2 | C32: =OFFSET('42p stat'!$A$1,A32*20,0) -> CUDA ant par | D32: =OFFSET('42p trace'!$R$56,(A32-1)*56,0)-OFFSET('42p trace'!$S$56,(A32-1)*56,0) -> 10.2472 | E32: =OFFSET('42p trace'!$S$56,(A32-1)*56,0)-OFFSET('42p stat'!$H$1,A32*20,0) -> 45.059984 | F32: =OFFSET('42p stat'!$H$1,A32*20,0)-OFFSET('42p stat'!$K$1,A32*20,0) -> 27.976372 | G32: =OFFSET('42p stat'!$K$1,A32*20,0)-OFFSET('42p stat'!$N$1,A32*20,0) -> 1500.0074 | H32: =OFFSET('42p stat'!$N$1,A32*20,0) -> 439.99769 | J32: =SUM(D32:H32) -> 2023.2886 | K32: =G32/J32 -> 0.74137093 | L32: =$K$29*POWER(K32,2)*SQRT(G179/(POWER(G32,2)*$L$29)+J179/(POWER(J32,2)*$L$29)) -> 0.0007968342
A33: 3 | C33: =OFFSET('42p stat'!$A$1,A33*20,0) -> CUDA ant add CPU Time | D33: =OFFSET('42p trace'!$R$56,(A33-1)*56,0)-OFFSET('42p trace'!$S$56,(A33-1)*56,0) -> 9.3022 | E33: =OFFSET('42p trace'!$S$56,(A33-1)*56,0)-OFFSET('42p stat'!$H$1,A33*20,0) -> 38.409078 | F33: =OFFSET('42p stat'!$H$1,A33*20,0)-OFFSET('42p stat'!$K$1,A33*20,0) -> -4.31896 | G33: =OFFSET('42p stat'!$K$1,A33*20,0)-OFFSET('42p stat'!$N$1,A33*20,0) -> 1625.1839 | H33: =OFFSET('42p stat'!$N$1,A33*20,0) -> 338.65558 | J33: =SUM(E33:H33) -> 1997.9296 | K33: =G33/J33 -> 0.81343402 | L33: =$K$29*POWER(K33,2)*SQRT(G180/(POWER(G33,2)*$L$29)+J180/(POWER(J33,2)*$L$29)) -> 0.0023221915
A34: 4 | C34: =OFFSET('42p stat'!$A$1,A34*20,0) -> CUDA opt Time | D34: =OFFSET('42p trace'!$R$56,(A34-1)*56,0)-OFFSET('42p trace'!$S$56,(A34-1)*56,0) -> 9.6816 | E34: =OFFSET('42p trace'!$S$56,(A34-1)*56,0)-OFFSET('42p stat'!$H$1,A34*20,0) -> 93.422541 | F34: =OFFSET('42p stat'!$H$1,A34*20,0)-OFFSET('42p stat'!$K$1,A34*20,0) -> 392.11903 | G34: =OFFSET('42p stat'!$K$1,A34*20,0)-OFFSET('42p stat'!$N$1,A34*20,0) -> 7383.976 | H34: =OFFSET('42p stat'!$N$1,A34*20,0) -> 0 | J34: =SUM(E34:H34) -> 7869.5176 | K34: =G34/J34 -> 0.93830097 | L34: =$K$29*POWER(K34,2)*SQRT(G181/(POWER(G34,2)*$L$29)+J181/(POWER(J34,2)*$L$29)) -> 0.0004911878
A35: 5 | C35: =OFFSET('42p stat'!$A$1,A35*20,0) -> CUDA opt ant | D35: =OFFSET('42p trace'!$R$56,(A35-1)*56,0)-OFFSET('42p trace'!$S$56,(A35-1)*56,0) -> 9.477 | E35: =OFFSET('42p trace'!$S$56,(A35-1)*56,0)-OFFSET('42p stat'!$H$1,A35*20,0) -> 43.826678 | F35: =OFFSET('42p stat'!$H$1,A35*20,0)-OFFSET('42p stat'!$K$1,A35*20,0) -> 469.25925 | G35: =OFFSET('42p stat'!$K$1,A35*20,0)-OFFSET('42p stat'!$N$1,A35*20,0) -> 1545.5507 | H35: =OFFSET('42p stat'!$N$1,A35*20,0) -> 0 | J35: =SUM(E35:H35) -> 2058.6366 | K35: =G35/J35 -> 0.75076421 | L35: =$K$29*POWER(K35,2)*SQRT(E182/(POWER(E35,2)*$L$29)+J182/(POWER(J35,2)*$L$29)) -> 0.020893529
A36: 6 | C36: =OFFSET('42p stat'!$A$1,A36*20,0) -> CUDA opt ant par | D36: =OFFSET('42p trace'!$R$56,(A36-1)*56,0)-OFFSET('42p trace'!$S$56,(A36-1)*56,0) -> 9.463 | E36: =OFFSET('42p trace'!$S$56,(A36-1)*56,0)-OFFSET('42p stat'!$H$1,A36*20,0) -> 47.793731 | F36: =OFFSET('42p stat'!$H$1,A36*20,0)-OFFSET('42p stat'!$K$1,A36*20,0) -> 466.8382 | G36: =OFFSET('42p stat'!$K$1,A36*20,0)-OFFSET('42p stat'!$N$1,A36*20,0) -> 1499.4253 | H36: =OFFSET('42p stat'!$N$1,A36*20,0) -> 0 | J36: =SUM(E36:H36) -> 2014.0572 | K36: =G36/J36 -> 0.74447998 | L36: =$K$29*POWER(K36,2)*SQRT(E183/(POWER(E36,2)*$L$29)+J183/(POWER(J36,2)*$L$29)) -> 0.016412989
A37: 7 | C37: =OFFSET('42p stat'!$A$1,A37*20,0) -> non CUDA Time | D37: =OFFSET('42p trace'!$R$56,(A37-1)*56,0)-OFFSET('42p trace'!$S$56,(A37-1)*56,0) -> 66.085 | E37: =OFFSET('42p trace'!$S$56,(A37-1)*56,0)-OFFSET('42p stat'!$H$1,A37*20,0) -> 0.130058 | F37: =OFFSET('42p stat'!$H$1,A37*20,0)-OFFSET('42p stat'!$K$1,A37*20,0) -> 6.068788 | G37: =OFFSET('42p stat'!$K$1,A37*20,0)-OFFSET('42p stat'!$N$1,A37*20,0) -> 3537.9692 | H37: =OFFSET('42p stat'!$N$1,A37*20,0) -> 280.25292 | J37: =SUM(E37:H37) -> 3824.421 | K37: =G37/J37 -> 0.92509931 | L37: =$K$29*POWER(K37,2)*SQRT(G184/(POWER(G37,2)*$L$29)+J184/(POWER(J37,2)*$L$29)) -> 0.0051682638
A38: 8 | C38: =OFFSET('42p stat'!$A$1,A38*20,0) -> Classic ACO | D38: =OFFSET('42p trace'!$R$56,(A38-1)*56,0)-OFFSET('42p trace'!$S$56,(A38-1)*56,0) -> 4926.032 | E38: =OFFSET('42p trace'!$S$56,(A38-1)*56,0)-OFFSET('42p stat'!$H$1,A38*20,0) -> 158.12936 | F38: =OFFSET('42p stat'!$H$1,A38*20,0)-OFFSET('42p stat'!$K$1,A38*20,0) -> 15.129688 | G38: =OFFSET('42p stat'!$K$1,A38*20,0)-OFFSET('42p stat'!$N$1,A38*20,0) -> 45461.14 | H38: =OFFSET('42p stat'!$N$1,A38*20,0) -> 860.27729 | J38: =SUM(D38:H38) -> 51420.708 | K38: =G38/J38 -> 0.88410178 | L38: =$K$29*POWER(K38,2)*SQRT(G185/(POWER(G38,2)*$L$29)+J185/(POWER(J38,2)*$L$29)) -> 0.0028910515
A39: 9 | C39: =OFFSET('42p stat'!$A$1,A39*20,0) -> omp | D39: =OFFSET('42p trace'!$R$56,(A39-1)*56,0)-OFFSET('42p trace'!$S$56,(A39-1)*56,0) -> 65.2472 | E39: =OFFSET('42p trace'!$S$56,(A39-1)*56,0)-OFFSET('42p stat'!$H$1,A39*20,0) -> 0.127642 | F39: =OFFSET('42p stat'!$H$1,A39*20,0)-OFFSET('42p stat'!$K$1,A39*20,0) -> 5.928082 | G39: =OFFSET('42p stat'!$K$1,A39*20,0)-OFFSET('42p stat'!$N$1,A39*20,0) -> 3502.2859 | H39: =OFFSET('42p stat'!$N$1,A39*20,0) -> 269.89154 | J39: =SUM(E39:H39) -> 3778.2332 | K39: =G39/J39 -> 0.92696394 | L39: =$K$29*POWER(K39,2)*SQRT(G186/(POWER(G39,2)*$L$29)+J186/(POWER(J39,2)*$L$29)) -> 0.0019965266
A40: 10 | C40: =OFFSET('42p stat'!$A$1,A40*20,0) -> non CUDA transp Time | D40: =OFFSET('42p trace'!$R$56,(A40-1)*56,0)-OFFSET('42p trace'!$S$56,(A40-1)*56,0) -> 65.8818 | E40: =OFFSET('42p trace'!$S$56,(A40-1)*56,0)-OFFSET('42p stat'!$H$1,A40*20,0) -> 0.126812 | F40: =OFFSET('42p stat'!$H$1,A40*20,0)-OFFSET('42p stat'!$K$1,A40*20,0) -> 8.31423 | G40: =OFFSET('42p stat'!$K$1,A40*20,0)-OFFSET('42p stat'!$N$1,A40*20,0) -> 3545.0774 | H40: =OFFSET('42p stat'!$N$1,A40*20,0) -> 252.77396 | J40: =SUM(E40:H40) -> 3806.2924 | K40: =G40/J40 -> 0.93137285 | L40: =$K$29*POWER(K40,2)*SQRT(G187/(POWER(G40,2)*$L$29)+J187/(POWER(J40,2)*$L$29)) -> 0.0030314501
A41: 11 | C41: =OFFSET('42p stat'!$A$1,A41*20,0) -> non CUDA transp_AVX Time | D41: =OFFSET('42p trace'!$R$56,(A41-1)*56,0)-OFFSET('42p trace'!$S$56,(A41-1)*56,0) -> 65.977 | E41: =OFFSET('42p trace'!$S$56,(A41-1)*56,0)-OFFSET('42p stat'!$H$1,A41*20,0) -> 0.13396 | F41: =OFFSET('42p stat'!$H$1,A41*20,0)-OFFSET('42p stat'!$K$1,A41*20,0) -> 7.40459 | G41: =OFFSET('42p stat'!$K$1,A41*20,0)-OFFSET('42p stat'!$N$1,A41*20,0) -> 3592.1915 | H41: =OFFSET('42p stat'!$N$1,A41*20,0) -> 283.71639 | J41: =SUM(D41:H41) -> 3949.4234 | K41: =G41/J41 -> 0.90954833 | L41: =$K$29*POWER(K41,2)*SQRT(G188/(POWER(G41,2)*$L$29)+J188/(POWER(J41,2)*$L$29)) -> 0.002698898
...

Sheet 84p stat
A2: CUDA Time | B2: 1 | C2: 25 | D2: Duration Mean: | E2: 0 | F2: 0 | G2: GPU Time 1 Mean: | H2: 774.03241 | I2: 3.533422 | J2: GPU Time 2 Mean: | K2: 772.38738 | L2: 3.575741 | M2: GPU Time 3 Mean: | N2: 35.653375 | O2: 0.009701 | P2: GPU Time 4 Mean: | Q2: 0 | R2: 0 | S2: GPU Time 5 Mean: | T2: 0 | U2: 0 | V2: GPU Time 6 Mean: | W2: 0 | X2: 0 | Y2: GPU Time 7 Mean: | Z2: 0 | AA2: 0 | AB2: GPU Time 8 Mean: | AC2: 0 | AD2: 0 | AE2: Global Min Mean: | AF2: 1 | AG2: 0 | AH2: Global Max Mean: | AI2: 1 | AJ2: 0 | AK2: Hash Fail Count Mean: | AL2: 0 | AM2: 0
A3: CUDA Time | B3: 2 | C3: 50 | D3: Duration Mean: | E3: 0 | F3: 0 | G3: GPU Time 1 Mean: | H3: 1548.0552 | I3: 14.264774 | J3: GPU Time 2 Mean: | K3: 1544.7685 | L3: 14.307768 | M3: GPU Time 3 Mean: | N3: 71.306167 | O3: 0.03803 | P3: GPU Time 4 Mean: | Q3: 0 | R3: 0 | S3: GPU Time 5 Mean: | T3: 0 | U3: 0 | V3: GPU Time 6 Mean: | W3: 0 | X3: 0 | Y3: GPU Time 7 Mean: | Z3: 0 | AA3: 0 | AB3: GPU Time 8 Mean: | AC3: 0 | AD3: 0 | AE3: Global Min Mean: | AF3: 1 | AG3: 0 | AH3: Global Max Mean: | AI3: 1 | AJ3: 0 | AK3: Hash Fail Count Mean: | AL3: 0 | AM3: 0
A4: CUDA Time | B4: 3 | C4: 75 | D4: Duration Mean: | E4: 0 | F4: 0 | G4: GPU Time 1 Mean: | H4: 2322.0739 | I4: 32.244951 | J4: GPU Time 2 Mean: | K4: 2317.1558 | L4: 32.153304 | M4: GPU Time 3 Mean: | N4: 106.96004 | O4: 0.085243 | P4: GPU Time 4 Mean: | Q4: 0 | R4: 0 | S4: GPU Time 5 Mean: | T4: 0 | U4: 0 | V4: GPU Time 6 Mean: | W4: 0 | X4: 0 | Y4: GPU Time 7 Mean: | Z4: 0 | AA4: 0 | AB4: GPU Time 8 Mean: | AC4: 0 | AD4: 0 | AE4: Global Min Mean: | AF4: 1 | AG4: 0 | AH4: Global Max Mean: | AI4: 1 | AJ4: 0 | AK4: Hash Fail Count Mean: | AL4: 0 | AM4: 0
A5: CUDA Time | B5: 4 | C5: 100 | D5: Duration Mean: | E5: 0 | F5: 0 | G5: GPU Time 1 Mean: | H5: 3096.0992 | I5: 57.136123 | J5: GPU Time 2 Mean: | K5: 3089.5573 | L5: 57.000026 | M5: GPU Time 3 Mean: | N5: 142.61418 | O5: 0.150817 | P5: GPU Time 4 Mean: | Q5: 0 | R5: 0 | S5: GPU Time 5 Mean: | T5: 0 | U5: 0 | V5: GPU Time 6 Mean: | W5: 0 | X5: 0 | Y5: GPU Time 7 Mean: | Z5: 0 | AA5: 0 | AB5: GPU Time 8 Mean: | AC5: 0 | AD5: 0 | AE5: Global Min Mean: | AF5: 1 | AG5: 0 | AH5: Global Max Mean: | AI5: 1 | AJ5: 0 | AK5: Hash Fail Count Mean: | AL5: 0 | AM5: 0
A6: CUDA Time | B6: 5 | C6: 125 | D6: Duration Mean: | E6: 0 | F6: 0 | G6: GPU Time 1 Mean: | H6: 3870.2383 | I6: 85.046265 | J6: GPU Time 2 Mean: | K6: 3862.0684 | L6: 84.632646 | M6: GPU Time 3 Mean: | N6: 178.27412 | O6: 0.224444 | P6: GPU Time 4 Mean: | Q6: 0 | R6: 0 | S6: GPU Time 5 Mean: | T6: 0 | U6: 0 | V6: GPU Time 6 Mean: | W6: 0 | X6: 0 | Y6: GPU Time 7 Mean: | Z6: 0 | AA6: 0 | AB6: GPU Time 8 Mean: | AC6: 0 | AD6: 0 | AE6: Global Min Mean: | AF6: 1 | AG6: 0 | AH6: Global Max Mean: | AI6: 1 | AJ6: 0 | AK6: Hash Fail Count Mean: | AL6: 0 | AM6: 0
A7: CUDA Time | B7: 6 | C7: 150 | D7: Duration Mean: | E7: 0 | F7: 0 | G7: GPU Time 1 Mean: | H7: 4644.389 | I7: 119.18917 | J7: GPU Time 2 Mean: | K7: 4634.5858 | L7: 118.54928 | M7: GPU Time 3 Mean: | N7: 213.93373 | O7: 0.315216 | P7: GPU Time 4 Mean: | Q7: 0 | R7: 0 | S7: GPU Time 5 Mean: | T7: 0 | U7: 0 | V7: GPU Time 6 Mean: | W7: 0 | X7: 0 | Y7: GPU Time 7 Mean: | Z7: 0 | AA7: 0 | AB7: GPU Time 8 Mean: | AC7: 0 | AD7: 0 | AE7: Global Min Mean: | AF7: 1 | AG7: 0 | AH7: Global Max Mean: | AI7: 1 | AJ7: 0 | AK7: Hash Fail Count Mean: | AL7: 0 | AM7: 0
A8: CUDA Time | B8: 7 | C8: 175 | D8: Duration Mean: | E8: 0 | F8: 0 | G8: GPU Time 1 Mean: | H8: 5418.5531 | I8: 159.40052 | J8: GPU Time 2 Mean: | K8: 5407.1097 | L8: 158.64175 | M8: GPU Time 3 Mean: | N8: 249.59357 | O8: 0.421921 | P8: GPU Time 4 Mean: | Q8: 0 | R8: 0 | S8: GPU Time 5 Mean: | T8: 0 | U8: 0 | V8: GPU Time 6 Mean: | W8: 0 | X8: 0 | Y8: GPU Time 7 Mean: | Z8: 0 | AA8: 0 | AB8: GPU Time 8 Mean: | AC8: 0 | AD8: 0 | AE8: Global Min Mean: | AF8: 1 | AG8: 0 | AH8: Global Max Mean: | AI8: 1 | AJ8: 0 | AK8: Hash Fail Count Mean: | AL8: 0 | AM8: 0
A9: CUDA Time | B9: 8 | C9: 200 | D9: Duration Mean: | E9: 0 | F9: 0 | G9: GPU Time 1 Mean: | H9: 6192.7172 | I9: 206.69705 | J9: GPU Time 2 Mean: | K9: 6179.6362 | L9: 205.13276 | M9: GPU Time 3 Mean: | N9: 285.25246 | O9: 0.545086 | P9: GPU Time 4 Mean: | Q9: 0 | R9: 0 | S9: GPU Time 5 Mean: | T9: 0 | U9: 0 | V9: GPU Time 6 Mean: | W9: 0 | X9: 0 | Y9: GPU Time 7 Mean: | Z9: 0 | AA9: 0 | AB9: GPU Time 8 Mean: | AC9: 0 | AD9: 0 | AE9: Global Min Mean: | AF9: 1 | AG9: 0 | AH9: Global Max Mean: | AI9: 1 | AJ9: 0 | AK9: Hash Fail Count Mean: | AL9: 0 | AM9: 0
A10: CUDA Time | B10: 9 | C10: 225 | D10: Duration Mean: | E10: 0 | F10: 0 | G10: GPU Time 1 Mean: | H10: 6966.929 | I10: 260.38645 | J10: GPU Time 2 Mean: | K10: 6952.1693 | L10: 257.94292 | M10: GPU Time 3 Mean: | N10: 320.91194 | O10: 0.685078 | P10: GPU Time 4 Mean: | Q10: 0 | R10: 0 | S10: GPU Time 5 Mean: | T10: 0 | U10: 0 | V10: GPU Time 6 Mean: | W10: 0 | X10: 0 | Y10: GPU Time 7 Mean: | Z10: 0 | AA10: 0 | AB10: GPU Time 8 Mean: | AC10: 0 | AD10: 0 | AE10: Global Min Mean: | AF10: 1 | AG10: 0 | AH10: Global Max Mean: | AI10: 1 | AJ10: 0 | AK10: Hash Fail Count Mean: | AL10: 0 | AM10: 0
A11: CUDA Time | B11: 10 | C11: 250 | D11: Duration Mean: | E11: 0 | F11: 0 | G11: GPU Time 1 Mean: | H11: 7741.0947 | I11: 319.71802 | J11: GPU Time 2 Mean: | K11: 7724.7074 | L11: 316.79376 | M11: GPU Time 3 Mean: | N11: 356.57032 | O11: 0.84196 | P11: GPU Time 4 Mean: | Q11: 0 | R11: 0 | S11: GPU Time 5 Mean: | T11: 0 | U11: 0 | V11: GPU Time 6 Mean: | W11: 0 | X11: 0 | Y11: GPU Time 7 Mean: | Z11: 0 | AA11: 0 | AB11: GPU Time 8 Mean: | AC11: 0 | AD11: 0 | AE11: Global Min Mean: | AF11: 1 | AG11: 0 | AH11: Global Max Mean: | AI11: 1 | AJ11: 0 | AK11: Hash Fail Count Mean: | AL11: 0 | AM11: 0
A12: CUDA Time | B12: 11 | C12: 275 | D12: Duration Mean: | E12: 0 | F12: 0 | G12: GPU Time 1 Mean: | H12: 8515.3297 | I12: 385.14309 | J12: GPU Time 2 Mean: | K12: 8497.2551 | L12: 382.0995 | M12: GPU Time 3 Mean: | N12: 392.23034 | O12: 1.013787 | P12: GPU Time 4 Mean: | Q12: 0 | R12: 0 | S12: GPU Time 5 Mean: | T12: 0 | U12: 0 | V12: GPU Time 6 Mean: | W12: 0 | X12: 0 | Y12: GPU Time 7 Mean: | Z12: 0 | AA12: 0 | AB12: GPU Time 8 Mean: | AC12: 0 | AD12: 0 | AE12: Global Min Mean: | AF12: 1 | AG12: 0 | AH12: Global Max Mean: | AI12: 1 | AJ12: 0 | AK12: Hash Fail Count Mean: | AL12: 0 | AM12: 0
A13: CUDA Time | B13: 12 | C13: 300 | D13: Duration Mean: | E13: 0 | F13: 0 | G13: GPU Time 1 Mean: | H13: 9289.5126 | I13: 457.1399 | J13: GPU Time 2 Mean: | K13: 9269.8081 | L13: 453.4305 | M13: GPU Time 3 Mean: | N13: 427.88953 | O13: 1.199749 | P13: GPU Time 4 Mean: | Q13: 0 | R13: 0 | S13: GPU Time 5 Mean: | T13: 0 | U13: 0 | V13: GPU Time 6 Mean: | W13: 0 | X13: 0 | Y13: GPU Time 7 Mean: | Z13: 0 | AA13: 0 | AB13: GPU Time 8 Mean: | AC13: 0 | AD13: 0 | AE13: Global Min Mean: | AF13: 1 | AG13: 0 | AH13: Global Max Mean: | AI13: 1 | AJ13: 0 | AK13: Hash Fail Count Mean: | AL13: 0 | AM13: 0
... A441: CUDA ant par sort | B441: 20 | C441: 500 | D441: Duration Mean: | E441: 0 | F441: 0 | G441: GPU Time 1 Mean: | H441: 2536.5865 | I441: 0.477619 | J441: GPU Time 2 Mean: | K441: 2500.4842 | L441: 0.016922 | M441: GPU Time 3 Mean: | N441: 875.93986 | O441: 0.00325 | P441: GPU Time 4 Mean: | Q441: 0 | R441: 0 | S441: GPU Time 5 Mean: | T441: 0 | U441: 0 | V441: GPU Time 6 Mean: | W441: 0 | X441: 0 | Y441: GPU Time 7 Mean: | Z441: 0 | AA441: 0 | AB441: GPU Time 8 Mean: | AC441: 0 | AD441: 0 | AE441: Global Min Mean: | AF441: 32767 | AG441: 0 | AH441: Global Max Mean: | AI441: -32767 | AJ441: 0 | AK441: Hash Fail Count Mean: | AL441: 0 | AM441: 0

Sheet 84p trace
A1: Device 0: NVIDIA GeForce RTX 3060 Laptop GPU | B1: Max thread in blocks: 1024 Total Global Memory: 6143,5 MB Shared Memory per Block: 49152 bytes Constant Memory: 65536 bytes Registers per Block: 65536 Warp Size: 32 Compute Capability: 8,6 Can Map Host Memory: Yes Clock Rate: 1425 MHz L2 Cache Size: 3145728 bytes Multiprocessor Count: 30 | C1: Max thread in blocks by axis: (1024, 1024, 64) | D1: Max blocks by axis: (2147483647, 65535, 65535) | E1: PARAMETR_SIZE: 336 | F1: PARAMETR_SIZE_ONE_X: 21 | G1: MAX_VALUE_SIZE: 5 | H1: NAME_FILE_GRAPH: Parametr_Graph/test336,txt | I1: ANT_SIZE: 1000 | J1: KOL_ITERATION: 500 | K1: KOL_PROGON_STATISTICS: 50 | L1: PARAMETR_Q: 1 | M1: PARAMETR_RO: 0,999 | N1: TYPE_ACO: 1 | O1: ACOCCyN_KOL_ITERATION: 50 | P1: FUNCTION: SHAFFERA
A2: Time CUDA Time: | B2: 16103.4 | C2: 15445.1 | D2: 15353.7 | E2: 15319.1 | F2: 708.998 | G2: 0 | H2: 708.998 | I2: 1 | J2: 1 | K2: 0
A3: Time CUDA Time: | B3: 15441.8 | C3: 15431.6 | D3: 15335.6 | E3: 15302.7 | F3: 707.577 | G3: 0 | H3: 707.577 | I3: 1 | J3: 1 | K3: 0
A4: Time CUDA Time: | B4: 15444.4 | C4: 15434.3 | D4: 15337.6 | E4: 15305.1 | F4: 707.625 | G4: 0 | H4: 707.625 | I4: 1 | J4: 1 | K4: 0
A5: Time CUDA Time: | B5: 15465.6 | C5: 15455.5 | D5: 15361.7 | E5: 15328.1 | F5: 707.964 | G5: 0 | H5: 707.964 | I5: 1 | J5: 1 | K5: 0
A6: Time CUDA Time: | B6: 15494.3 | C6: 15484.1 | D6: 15389.2 | E6: 15355.9 | F6: 708.317 | G6: 0 | H6: 708.317 | I6: 1 | J6: 1 | K6: 0
A7: Time CUDA Time: | B7: 15484.7 | C7: 15474.2 | D7: 15387.6 | E7: 15355.4 | F7: 708.296 | G7: 0 | H7: 708.296 | I7: 1 | J7: 1 | K7: 0
A8: Time CUDA Time: | B8: 15495 | C8: 15485.2 | D8: 15387 | E8: 15355.2 | F8: 708.234 | G8: 0 | H8: 708.234 | I8: 1 | J8: 1 | K8: 0
A9: Time CUDA Time: | B9: 15485.6 | C9: 15475.4 | D9: 15386.8 | E9: 15354.9 | F9: 708.259 | G9: 0 | H9: 708.259 | I9: 1 | J9: 1 | K9: 0
A10: Time CUDA Time: | B10: 15487.2 | C10: 15476.8 | D10: 15387.3 | E10: 15354.4 | F10: 708.238 | G10: 0 | H10: 708.238 | I10: 1 | J10: 1 | K10: 0
A11: Time CUDA Time: | B11: 15488.4 | C11: 15478.9 | D11: 15390.1 | E11: 15355.2 | F11: 708.232 | G11: 0 | H11: 708.232 | I11: 1 | J11: 1 | K11: 0
A12: Time CUDA Time: | B12: 15490.1 | C12: 15480.1 | D12: 15387.6 | E12: 15355.4 | F12: 708.277 | G12: 0 | H12: 708.277 | I12: 1 | J12: 1 | K12: 0
A13: Time CUDA Time: | B13: 15575.1 | C13: 15565.2 | D13: 15474.9 | E13: 15443.1 | F13: 712.792 | G13: 0 | H13: 712.792 | I13: 1 | J13: 1 | K13: 0
... A54: Time CUDA Time: | B54: 15592.9 | C54: 15582.5 | D54: 15496.9 | E54: 15464.1 | F54: 713.854 | G54: 0 | H54: 713.854 | I54: 1 | J54: 1 | K54: 0
A55: Time CUDA Time: | B55: 15598 | C55: 15588.2 | D55: 15496.7 | E55: 15463.7 | F55: 713.837 | G55: 0 | H55: 713.837 | I55: 1 | J55: 1 | K55: 0 | R55: МО | U55: дисп | X55: CI
A56: Time CUDA Time: | B56: 15604.4 | C56: 15593.4 | D56: 15496.6 | E56: 15463.6 | F56: 713.836 | G56: 0 | H56: 713.836 | I56: 1 | J56: 1 | K56: 0 | R56: =AVERAGE(B7:B56) -> 15584.634 | S56: =AVERAGE(C7:C56) -> 15574.418 | U56: =_xlfn.VAR.P(B7:B56) -> 1284.723 | V56: =_xlfn.VAR.P(C7:C56) -> 1279.9567 | X56: =1.96*SQRT(U56)/50 -> 1.4050469 | Y56: =1.96*SQRT(V56)/50 -> 1.4024381
A57: Time CUDA time: | B57: 779290.84 | C57: sec
A58: Time CUDA ant par: | B58: 2549.06 | C58: 2539.14 | D58: 2483.34 | E58: 2451.7 | F58: 882.438 | G58: 0.0542287 | H58: 0.931829 | I58: 0
A59: Time CUDA ant par: | B59: 2551.22 | C59: 2537.32 | D59: 2482.86 | E59: 2451.31 | F59: 882.346 | G59: 0.0644604 | H59: 0.958558 | I59: 0
A60: Time CUDA ant par: | B60: 2551.61 | C60: 2535.87 | D60: 2482.85 | E60: 2451.36 | F60: 882.327 | G60: 0.0540895 | H60: 0.930861 | I60: 0
A61: Time CUDA ant par: | B61: 2538.49 | C61: 2524.22 | D61: 2479.53 | E61: 2451.5 | F61: 882.345 | G61: 0.0539825 | H61: 0.931832 | I61: 0
A62: Time CUDA ant par: | B62: 2552.36 | C62: 2538.57 | D62: 2483.14 | E62: 2451.41 | F62: 882.366 | G62: 0.0542993 | H62: 0.93183 | I62: 0
A63: Time CUDA ant par: | B63: 2533.66 | C63: 2519.38 | D63: 2478.7 | E63: 2451.45 | F63: 882.349 | G63: 0.0568099 | H63: 0.931608 | I63: 0
A64: Time CUDA ant par: | B64: 2538.03 | C64: 2523.75 | D64: 2479.25 | E64: 2451.43 | F64: 882.338 | G64: 0.0566913 | H64: 0.931837 | I64: 0
A65: Time CUDA ant par: | B65: 2532.86 | C65: 2518.39 | D65: 2478.43 | E65: 2451.56 | F65: 882.348 | G65: 0.0620742 | H65: 0.956831 | I65: 0
A66: Time CUDA ant par: | B66: 2552.44 | C66: 2538.22 | D66: 2483.63 | E66: 2451.3 | F66: 882.352 | G66: 0.0689381 | H66: 0.957734 | I66: 0
A67: Time CUDA ant par: | B67: 2547.31 | C67: 2534.61 | D67: 2482.42 | E67: 2451.42 | F67: 882.386 | G67: 0.0541843 | H67: 0.941211 | I67: 0
A68: Time CUDA ant par: | B68: 2534.67 | C68: 2519.84 | D68: 2478.98 | E68: 2451.66 | F68: 882.412 | G68: 0.0571245 | H68: 0.95858 | I68: 0
A69: Time CUDA ant par: | B69: 2552.96 | C69: 2538.69 | D69: 2483.23 | E69: 2451.51 | F69: 882.387 | G69: 0.0539387 | H69: 0.942101 | I69: 0
... A110: Time CUDA ant par: | B110: 2526.03 | C110: 2511.07 | D110: 2462.97 | E110: 2433.79 | F110: 875.807 | G110: 0.0540903 | H110: 0.931245 | I110: 0
A111: Time CUDA ant par: | B111: 2523.25 | C111: 2510.56 | D111: 2462.62 | E111: 2434.06 | F111: 875.731 | G111: 0.0605188 | H111: 0.948924 | I111: 0 | R111: МО | U111: дисп | X111: CI
A112: Time CUDA ant par: | B112: 2527.82 | C112: 2513.81 | D112: 2463.14 | E112: 2433.7 | F112: 875.796 | G112: 0.0541333 | H112: 0.931834 | I112: 0 | R112: =AVERAGE(B63:B112) -> 2539.3778 | S112: =AVERAGE(C63:C112) -> 2525.2674 | U112: =_xlfn.VAR.P(B63:B112) -> 51.436229 | V112: =_xlfn.VAR.P(C63:C112) -> 52.961323 | X112: =1.96*SQRT(U112)/50 -> 0.2811387 | Y112: =1.96*SQRT(V112)/50 -> 0.28527616
A113: Time CUDA ant par: | B113: 127072.44 | C113: sec
A114: Time CUDA ant add CPU Time: | B114: 2435.54 | C114: 2420.95 | D114: 2387.05 | E114: 2383.64 | F114: 660.299 | G114: 0.0546762 | H114: 0.947285 | I114: 0
A115: Time CUDA ant add CPU Time: | B115: 2409.44 | C115: 2395.92 | D115: 2360.93 | E115: 2357.77 | F115: 635.09 | G115: 0.0543271 | H115: 0.958909 | I115: 0
A116: Time CUDA ant add CPU Time: | B116: 2439.15 | C116: 2424.35 | D116: 2391.32 | E116: 2387.95 | F116: 664.449 | G116: 0.0545394 | H116: 0.931836 | I116: 0
A117: Time CUDA ant add CPU Time: | B117: 2416.17 | C117: 2401.73 | D117: 2368.96 | E117: 2366.1 | F117: 645.845 | G117: 0.0541316 | H117: 0.931821 | I117: 0
A118: Time CUDA ant add CPU Time: | B118: 2422.81 | C118: 2408.5 | D118: 2377.37 | E118: 2374.81 | F118: 658.271 | G118: 0.0562372 | H118: 0.95658 | I118: 0
A119: Time CUDA ant add CPU Time: | B119: 2387.18 | C119: 2373.35 | D119: 2340.28 | E119: 2338.33 | F119: 622.779 | G119: 0.0539968 | H119: 0.931806 | I119: 0
A120: Time CUDA ant add CPU Time: | B120: 2391.68 | C120: 2377.35 | D120: 2343.56 | E120: 2341.59 | F120: 622.101 | G120: 0.05474 | H120: 0.931403 | I120: 0
...

Sheet 84 end
D2: T_start | E2: T_Delt | F2: T1 | G2: T2 | H2: T3
A3: 1 | C3: =OFFSET('84p stat'!$A$1,A3*20,0) -> CUDA Time | D3: =OFFSET('84p trace'!$R$56,(A3-1)*56,0)-OFFSET('84p trace'!$S$56,(A3-1)*56,0) -> 10.216 | E3: =OFFSET('84p trace'!$S$56,(A3-1)*56,0)-OFFSET('84p stat'!$H$1,A3*20,0) -> 91.044777 | F3: =OFFSET('84p stat'!$H$1,A3*20,0)-OFFSET('84p stat'!$K$1,A3*20,0) -> 32.917813 | G3: =OFFSET('84p stat'!$K$1,A3*20,0)-OFFSET('84p stat'!$N$1,A3*20,0) -> 14737.291 | H3: =OFFSET('84p stat'!$N$1,A3*20,0) -> 713.16409
A4: 1 | C4: =OFFSET('84p stat'!$A$1,A4*20,0) -> CUDA Time | D4: =OFFSET('84p trace'!$U$56,(A4-1)*56,0) -> 1284.723 | E4: =OFFSET('84p trace'!$V$56,(A4-1)*56,0) -> 1279.9567 | F4: =OFFSET('84p stat'!$H$1,A4*20,1) -> 1258.4984 | G4: =OFFSET('84p stat'!$K$1,A4*20,1) -> 1248.868 | H4: =OFFSET('84p stat'!$N$1,A4*20,1) -> 3.307911
A5: 2 | C5: =OFFSET('84p stat'!$A$1,A5*20,0) -> CUDA ant par | D5: =OFFSET('84p trace'!$R$56,(A5-1)*56,0)-OFFSET('84p trace'!$S$56,(A5-1)*56,0) -> 14.1104 | E5: =OFFSET('84p trace'!$S$56,(A5-1)*56,0)-OFFSET('84p stat'!$H$1,A5*20,0) -> 46.137922 | F5: =OFFSET('84p stat'!$H$1,A5*20,0)-OFFSET('84p stat'!$K$1,A5*20,0) -> 28.517828 | G5: =OFFSET('84p stat'!$K$1,A5*20,0)-OFFSET('84p stat'!$N$1,A5*20,0) -> 1568.5515 | H5: =OFFSET('84p stat'!$N$1,A5*20,0) -> 882.06012
A6: 2 | C6: =OFFSET('84p stat'!$A$1,A6*20,0) -> CUDA ant par | D6: =OFFSET('84p trace'!$U$56,(A6-1)*56,0) -> 51.436229 | E6: =OFFSET('84p trace'!$V$56,(A6-1)*56,0) -> 52.961323 | F6: =OFFSET('84p stat'!$H$1,A6*20,1) -> 19.047014 | G6: =OFFSET('84p stat'!$K$1,A6*20,1) -> 17.951238 | H6: =OFFSET('84p stat'!$N$1,A6*20,1) -> 2.522545
A7: 3 | C7: =OFFSET('84p stat'!$A$1,A7*20,0) -> CUDA ant add CPU Time | D7: =OFFSET('84p trace'!$R$56,(A7-1)*56,0)-OFFSET('84p trace'!$S$56,(A7-1)*56,0) -> 14.245 | E7: =OFFSET('84p trace'!$S$56,(A7-1)*56,0)-OFFSET('84p stat'!$H$1,A7*20,0) -> 32.089896 | F7: =OFFSET('84p stat'!$H$1,A7*20,0)-OFFSET('84p stat'!$K$1,A7*20,0) -> 2.901172 | G7: =OFFSET('84p stat'!$K$1,A7*20,0)-OFFSET('84p stat'!$N$1,A7*20,0) -> 1717.4637 | H7: =OFFSET('84p stat'!$N$1,A7*20,0) -> 651.37699
A8: 3 | C8: =OFFSET('84p stat'!$A$1,A8*20,0) -> CUDA ant add CPU Time | D8: =OFFSET('84p trace'!$U$56,(A8-1)*56,0) -> 184.32404 | E8: =OFFSET('84p trace'!$V$56,(A8-1)*56,0) -> 183.74366 | F8: =OFFSET('84p stat'!$H$1,A8*20,1) -> 147.79574 | G8: =OFFSET('84p stat'!$K$1,A8*20,1) -> 139.34703 | H8: =OFFSET('84p stat'!$N$1,A8*20,1) -> 156.78635
A9: 4 | C9: =OFFSET('84p stat'!$A$1,A9*20,0) -> CUDA opt Time | D9: =OFFSET('84p trace'!$R$56,(A9-1)*56,0)-OFFSET('84p trace'!$S$56,(A9-1)*56,0) -> 10.228 | E9: =OFFSET('84p trace'!$S$56,(A9-1)*56,0)-OFFSET('84p stat'!$H$1,A9*20,0) -> 100.34135 | F9: =OFFSET('84p stat'!$H$1,A9*20,0)-OFFSET('84p stat'!$K$1,A9*20,0) -> 746.58973 | G9: =OFFSET('84p stat'!$K$1,A9*20,0)-OFFSET('84p stat'!$N$1,A9*20,0) -> 14753.055 | H9: =OFFSET('84p stat'!$N$1,A9*20,0) -> 0
A10: 4 | C10: =OFFSET('84p stat'!$A$1,A10*20,0) -> CUDA opt Time | D10: =OFFSET('84p trace'!$U$56,(A10-1)*56,0) -> 13.307604 | E10: =OFFSET('84p trace'!$V$56,(A10-1)*56,0) -> 12.988404 | F10: =OFFSET('84p stat'!$H$1,A10*20,1) -> 1.665515 | G10: =OFFSET('84p stat'!$K$1,A10*20,1) -> 0.052079 | H10: =OFFSET('84p stat'!$N$1,A10*20,1) -> 0
A11: 5 | C11: =OFFSET('84p stat'!$A$1,A11*20,0) -> CUDA opt ant | D11: =OFFSET('84p trace'!$R$56,(A11-1)*56,0)-OFFSET('84p trace'!$S$56,(A11-1)*56,0) -> 10.2402 | E11: =OFFSET('84p trace'!$S$56,(A11-1)*56,0)-OFFSET('84p stat'!$H$1,A11*20,0) -> 48.672301 | F11: =OFFSET('84p stat'!$H$1,A11*20,0)-OFFSET('84p stat'!$K$1,A11*20,0) -> 912.00615 | G11: =OFFSET('84p stat'!$K$1,A11*20,0)-OFFSET('84p stat'!$N$1,A11*20,0) -> 1570.3203 | H11: =OFFSET('84p stat'!$N$1,A11*20,0) -> 0
A12: 5 | C12: =OFFSET('84p stat'!$A$1,A12*20,0) -> CUDA opt ant | D12: =OFFSET('84p trace'!$U$56,(A12-1)*56,0) -> 55.928909 | E12: =OFFSET('84p trace'!$V$56,(A12-1)*56,0) -> 56.655587 | F12: =OFFSET('84p stat'!$H$1,A12*20,1) -> 3.678217 | G12: =OFFSET('84p stat'!$K$1,A12*20,1) -> 0.02121 | H12: =OFFSET('84p stat'!$N$1,A12*20,1) -> 0
A13: 6 | C13: =OFFSET('84p stat'!$A$1,A13*20,0) -> CUDA opt ant par | D13: =OFFSET('84p trace'!$R$56,(A13-1)*56,0)-OFFSET('84p trace'!$S$56,(A13-1)*56,0) -> 10.319 | E13: =OFFSET('84p trace'!$S$56,(A13-1)*56,0)-OFFSET('84p stat'!$H$1,A13*20,0) -> 48.443616 | F13: =OFFSET('84p stat'!$H$1,A13*20,0)-OFFSET('84p stat'!$K$1,A13*20,0) -> 903.72871 | G13: =OFFSET('84p stat'!$K$1,A13*20,0)-OFFSET('84p stat'!$N$1,A13*20,0) -> 1561.7001 | H13: =OFFSET('84p stat'!$N$1,A13*20,0) -> 0
A14: 6 | C14: =OFFSET('84p stat'!$A$1,A14*20,0) -> CUDA opt ant par | D14: =OFFSET('84p trace'!$U$56,(A14-1)*56,0) -> 59.798108 | E14: =OFFSET('84p trace'!$V$56,(A14-1)*56,0) -> 61.569222 | F14: =OFFSET('84p stat'!$H$1,A14*20,1) -> 70.260865 | G14: =OFFSET('84p stat'!$K$1,A14*20,1) -> 30.387581 | H14: =OFFSET('84p stat'!$N$1,A14*20,1) -> 0
A15: 7 | C15: =OFFSET('84p stat'!$A$1,A15*20,0) -> non CUDA Time | D15: =OFFSET('84p trace'!$R$56,(A15-1)*56,0)-OFFSET('84p trace'!$S$56,(A15-1)*56,0) -> 66.53 | E15: =OFFSET('84p trace'!$S$56,(A15-1)*56,0)-OFFSET('84p stat'!$H$1,A15*20,0) -> 0.239796 | F15: =OFFSET('84p stat'!$H$1,A15*20,0)-OFFSET('84p stat'!$K$1,A15*20,0) -> 6.455538 | G15: =OFFSET('84p stat'!$K$1,A15*20,0)-OFFSET('84p stat'!$N$1,A15*20,0) -> 7258.4107 | H15: =OFFSET('84p stat'!$N$1,A15*20,0) -> 621.99135
A16: 7 | C16: =OFFSET('84p stat'!$A$1,A16*20,0) -> non CUDA Time | D16: =OFFSET('84p trace'!$U$56,(A16-1)*56,0) -> 40604.124 | E16: =OFFSET('84p trace'!$V$56,(A16-1)*56,0) -> 39759.793 | F16: =OFFSET('84p stat'!$H$1,A16*20,1) -> 39726.22 | G16: =OFFSET('84p stat'!$K$1,A16*20,1) -> 39591.759 | H16: =OFFSET('84p stat'!$N$1,A16*20,1) -> 1084.4759
A17: 8 | C17: =OFFSET('84p stat'!$A$1,A17*20,0) -> Classic ACO | D17: =OFFSET('84p trace'!$R$56,(A17-1)*56,0)-OFFSET('84p trace'!$S$56,(A17-1)*56,0) -> 5120.874 | E17: =OFFSET('84p trace'!$S$56,(A17-1)*56,0)-OFFSET('84p stat'!$H$1,A17*20,0) -> 271.51469 | F17: =OFFSET('84p stat'!$H$1,A17*20,0)-OFFSET('84p stat'!$K$1,A17*20,0) -> 16.437812 | G17: =OFFSET('84p stat'!$K$1,A17*20,0)-OFFSET('84p stat'!$N$1,A17*20,0) -> 93246.948 | H17: =OFFSET('84p stat'!$N$1,A17*20,0) -> 1775.4497
A18: 8 | C18: =OFFSET('84p stat'!$A$1,A18*20,0) -> Classic ACO | D18: =OFFSET('84p trace'!$U$56,(A18-1)*56,0) -> 2413986.3 | E18: =OFFSET('84p trace'!$V$56,(A18-1)*56,0) -> 2079655.8 | F18: =OFFSET('84p stat'!$H$1,A18*20,1) -> 2040408.2 | G18: =OFFSET('84p stat'!$K$1,A18*20,1) -> 2039304.3 | H18: =OFFSET('84p stat'!$N$1,A18*20,1) -> 974.65361
A19: 9 | C19: =OFFSET('84p stat'!$A$1,A19*20,0) -> omp | D19: =OFFSET('84p trace'!$R$56,(A19-1)*56,0)-OFFSET('84p trace'!$S$56,(A19-1)*56,0) -> 67.3616 | E19: =OFFSET('84p trace'!$S$56,(A19-1)*56,0)-OFFSET('84p stat'!$H$1,A19*20,0) -> 0.229282 | F19: =OFFSET('84p stat'!$H$1,A19*20,0)-OFFSET('84p stat'!$K$1,A19*20,0) -> 6.448598 | G19: =OFFSET('84p stat'!$K$1,A19*20,0)-OFFSET('84p stat'!$N$1,A19*20,0) -> 7150.9396 | H19: =OFFSET('84p stat'!$N$1,A19*20,0) -> 592.9601
A20: 9 | C20: =OFFSET('84p stat'!$A$1,A20*20,0) -> omp | D20: =OFFSET('84p trace'!$U$56,(A20-1)*56,0) -> 583.64778 | E20: =OFFSET('84p trace'!$V$56,(A20-1)*56,0) -> 562.20013 | F20: =OFFSET('84p stat'!$H$1,A20*20,1) -> 562.04383 | G20: =OFFSET('84p stat'!$K$1,A20*20,1) -> 561.61353 | H20: =OFFSET('84p stat'!$N$1,A20*20,1) -> 15.307416
A21: 10 | C21: =OFFSET('84p stat'!$A$1,A21*20,0) -> non CUDA transp Time | D21: =OFFSET('84p trace'!$R$56,(A21-1)*56,0)-OFFSET('84p trace'!$S$56,(A21-1)*56,0) -> 66.5814 | E21: =OFFSET('84p trace'!$S$56,(A21-1)*56,0)-OFFSET('84p stat'!$H$1,A21*20,0) -> 0.202928 | F21: =OFFSET('84p stat'!$H$1,A21*20,0)-OFFSET('84p stat'!$K$1,A21*20,0) -> 10.709038 | G21: =OFFSET('84p stat'!$K$1,A21*20,0)-OFFSET('84p stat'!$N$1,A21*20,0) -> 7255.8001 | H21: =OFFSET('84p stat'!$N$1,A21*20,0) -> 518.78993
A22: 10 | C22: =OFFSET('84p stat'!$A$1,A22*20,0) -> non CUDA transp Time | D22: =OFFSET('84p trace'!$U$56,(A22-1)*56,0) -> 633.21409 | E22: =OFFSET('84p trace'!$V$56,(A22-1)*56,0) -> 619.46084 | F22: =OFFSET('84p stat'!$H$1,A22*20,1) -> 619.20089 | G22: =OFFSET('84p stat'!$K$1,A22*20,1) -> 618.3784 | H22: =OFFSET('84p stat'!$N$1,A22*20,1) -> 63.566309
A23: 11 | C23: =OFFSET('84p stat'!$A$1,A23*20,0) -> non CUDA transp_AVX Time | D23: =OFFSET('84p trace'!$R$56,(A23-1)*56,0)-OFFSET('84p trace'!$S$56,(A23-1)*56,0) -> 67.0332 | E23: =OFFSET('84p trace'!$S$56,(A23-1)*56,0)-OFFSET('84p stat'!$H$1,A23*20,0) -> 0.200128 | F23: =OFFSET('84p stat'!$H$1,A23*20,0)-OFFSET('84p stat'!$K$1,A23*20,0) -> 10.155746 | G23: =OFFSET('84p stat'!$K$1,A23*20,0)-OFFSET('84p stat'!$N$1,A23*20,0) -> 7345.9408 | H23: =OFFSET('84p stat'!$N$1,A23*20,0) -> 568.13728
A24: 11 | C24: =OFFSET('84p stat'!$A$1,A24*20,0) -> non CUDA transp_AVX Time | D24: =OFFSET('84p trace'!$U$56,(A24-1)*56,0) -> 3700.954 | E24: =OFFSET('84p trace'!$V$56,(A24-1)*56,0) -> 3663.2113 | F24: =OFFSET('84p stat'!$H$1,A24*20,1) -> 3661.8433 | G24: =OFFSET('84p stat'!$K$1,A24*20,1) -> 3625.9376 | H24: =OFFSET('84p stat'!$N$1,A24*20,1) -> 122.10625
A25: 12 | C25: =OFFSET('84p stat'!$A$1,A25*20,0) -> non CUDA transp_AVX_OMP Time | D25: =OFFSET('84p trace'!$R$56,(A25-1)*56,0)-OFFSET('84p trace'!$S$56,(A25-1)*56,0) -> 66.4526 | E25: =OFFSET('84p trace'!$S$56,(A25-1)*56,0)-OFFSET('84p stat'!$H$1,A25*20,0) -> 0.218072 | F25: =OFFSET('84p stat'!$H$1,A25*20,0)-OFFSET('84p stat'!$K$1,A25*20,0) -> 9.726978 | G25: =OFFSET('84p stat'!$K$1,A25*20,0)-OFFSET('84p stat'!$N$1,A25*20,0) -> 7335.3862 | H25: =OFFSET('84p stat'!$N$1,A25*20,0) -> 575.84534
A26: 12 | C26: =OFFSET('84p stat'!$A$1,A26*20,0) -> non CUDA transp_AVX_OMP Time | D26: =OFFSET('84p trace'!$U$56,(A26-1)*56,0) -> 943.24594 | E26: =OFFSET('84p trace'!$V$56,(A26-1)*56,0) -> 922.58941 | F26: =OFFSET('84p stat'!$H$1,A26*20,1) -> 922.71139 | G26: =OFFSET('84p stat'!$K$1,A26*20,1) -> 916.27521 | H26: =OFFSET('84p stat'!$N$1,A26*20,1) -> 175.37562
A27: 13 | C27: =OFFSET('84p stat'!$A$1,A27*20,0) -> CUDA ant add CPU_AVX_transp Time | D27: =OFFSET('84p trace'!$R$56,(A27-1)*56,0)-OFFSET('84p trace'!$S$56,(A27-1)*56,0) -> 14.8346 | E27: =OFFSET('84p trace'!$S$56,(A27-1)*56,0)-OFFSET('84p stat'!$H$1,A27*20,0) -> 30.770804 | F27: =OFFSET('84p stat'!$H$1,A27*20,0)-OFFSET('84p stat'!$K$1,A27*20,0) -> 4.041656 | G27: =OFFSET('84p stat'!$K$1,A27*20,0)-OFFSET('84p stat'!$N$1,A27*20,0) -> 1714.0013 | H27: =OFFSET('84p stat'!$N$1,A27*20,0) -> 579.87762
A28: 13 | C28: =OFFSET('84p stat'!$A$1,A28*20,0) -> CUDA ant add CPU_AVX_transp Time | D28: =OFFSET('84p trace'!$U$56,(A28-1)*56,0) -> 173.61033 | E28: =OFFSET('84p trace'!$V$56,(A28-1)*56,0) -> 170.76521 | F28: =OFFSET('84p stat'!$H$1,A28*20,1) -> 129.99797 | G28: =OFFSET('84p stat'!$K$1,A28*20,1) -> 126.34491 | H28: =OFFSET('84p stat'!$N$1,A28*20,1) -> 37.578917
K29: 1.96 | L29: 50
D30: T_start | E30: T_Delt | F30: T1 | G30: T2 | H30: T3 | J30: summ | K30: 2 этап/ общее | L30: ДИ
A31: 1 | C31: =OFFSET('84p stat'!$A$1,A31*20,0) -> CUDA Time | D31: =OFFSET('84p trace'!$R$56,(A31-1)*56,0)-OFFSET('84p trace'!$S$56,(A31-1)*56,0) -> 10.216 | E31: =OFFSET('84p trace'!$S$56,(A31-1)*56,0)-OFFSET('84p stat'!$H$1,A31*20,0) -> 91.044777 | F31: =OFFSET('84p stat'!$H$1,A31*20,0)-OFFSET('84p stat'!$K$1,A31*20,0) -> 32.917813 | G31: =OFFSET('84p stat'!$K$1,A31*20,0)-OFFSET('84p stat'!$N$1,A31*20,0) -> 14737.291 | H31: =OFFSET('84p stat'!$N$1,A31*20,0) -> 713.16409 | J31: =SUM(E31:H31) -> 15574.418 | K31: =G31/J31 -> 0.94624989 | L31: =$K$29*POWER(K31,2)*SQRT(G178/(POWER(G31,2)*$L$29)+J178/(POWER(J31,2)*$L$29)) -> 0.0012818213
A32: 2 | C32: =OFFSET('84p stat'!$A$1,A32*20,0) -> CUDA ant par | D32: =OFFSET('84p trace'!$R$56,(A32-1)*56,0)-OFFSET('84p trace'!$S$56,(A32-1)*56,0) -> 14.1104 | E32: =OFFSET('84p trace'!$S$56,(A32-1)*56,0)-OFFSET('84p stat'!$H$1,A32*20,0) -> 46.137922 | F32: =OFFSET('84p stat'!$H$1,A32*20,0)-OFFSET('84p stat'!$K$1,A32*20,0) -> 28.517828 | G32: =OFFSET('84p stat'!$K$1,A32*20,0)-OFFSET('84p stat'!$N$1,A32*20,0) -> 1568.5515 | H32: =OFFSET('84p stat'!$N$1,A32*20,0) -> 882.06012 | J32: =SUM(D32:H32) -> 2539.3778 | K32: =G32/J32 -> 0.61769128 | L32: =$K$29*POWER(K32,2)*SQRT(G179/(POWER(G32,2)*$L$29)+J179/(POWER(J32,2)*$L$29)) -> 0.00057552791
A33: 3 | C33: =OFFSET('84p stat'!$A$1,A33*20,0) -> CUDA ant add CPU Time | D33: =OFFSET('84p trace'!$R$56,(A33-1)*56,0)-OFFSET('84p trace'!$S$56,(A33-1)*56,0) -> 14.245 | E33: =OFFSET('84p trace'!$S$56,(A33-1)*56,0)-OFFSET('84p stat'!$H$1,A33*20,0) -> 32.089896 | F33: =OFFSET('84p stat'!$H$1,A33*20,0)-OFFSET('84p stat'!$K$1,A33*20,0) -> 2.901172 | G33: =OFFSET('84p stat'!$K$1,A33*20,0)-OFFSET('84p stat'!$N$1,A33*20,0) -> 1717.4637 | H33: =OFFSET('84p stat'!$N$1,A33*20,0) -> 651.37699 | J33: =SUM(E33:H33) -> 2403.8318 | K33: =G33/J33 -> 0.71446918 | L33: =$K$29*POWER(K33,2)*SQRT(G180/(POWER(G33,2)*$L$29)+J180/(POWER(J33,2)*$L$29)) -> 0.00193885
