Workbook

Sheet Itog
E1: 42 | F1: =E1*2 -> 84 | G1: =F1*2 -> 168 | H1: =G1*2 -> 336 | I1: =H1*2 -> 672 | J1: =I1*2 -> 1344 | K1: =J1*2 -> 2688 | L1: =K1*2 -> 5376 | M1: =L1*2 -> 10752 | N1: =M1*2 -> 21504 | X1: 1 | Y1: << "Time=" << metrics.total_time_ms << "ms "
B2: 1 | D2: 50 | E2: 0 | F2: 49 | J2: const | L2: shared | X2: 2 | Y2: << "Kernel=" << metrics.kernel_time_ms << "ms "
B3: 42clangOMP31 | D3: 0 | E3: 1 | X3: 3 | Y3: << "Probabilities=" << metrics.computeProbabilities_time_ms << "ms "
A4: 0 | B4: 1 | C4: 32 | D4: =OFFSET('t42'!$A$1,$B$2+($B4-1)*$D$2+$A4,D$3) -> Run Original ACO0 | E4: =AVERAGE(OFFSET('t42'!$A$1,$B$2+($B4-1)*$D$2+$E$2+$A4,E$3):OFFSET('t42'!$A$1,$B$2+($B4-1)*$D$2+$E$2+$F$2+$A4,E$3)) -> 129.34202 | F4: =AVERAGE(OFFSET('t84'!$A$1,$B$2+($B4-1)*$D$2+$E$2+$A4,E$3):OFFSET('t84'!$A$1,$B$2+($B4-1)*$D$2+$E$2+$F$2+$A4,E$3)) -> 149.47686 | G4: =AVERAGE(OFFSET('t168'!$A$1,$B$2+($B4-1)*$D$2+$E$2+$A4,E$3):OFFSET('t168'!$A$1,$B$2+($B4-1)*$D$2+$E$2+$F$2+$A4,E$3)) -> 187.42248 | H4: =AVERAGE(OFFSET('t336'!$A$1,$B$2+($B4-1)*$D$2+$E$2+$A4,E$3):OFFSET('t336'!$A$1,$B$2+($B4-1)*$D$2+$E$2+$F$2+$A4,E$3)) -> 244.43236 | I4: =AVERAGE(OFFSET('t672'!$A$1,$B$2+($B4-1)*$D$2+$E$2+$A4,E$3):OFFSET('t672'!$A$1,$B$2+($B4-1)*$D$2+$E$2+$F$2+$A4,E$3)) -> 283.34354 | J4: =AVERAGE(OFFSET('t1344'!$A$1,$B$2+($B4-1)*$D$2+$E$2+$A4,E$3):OFFSET('t1344'!$A$1,$B$2+($B4-1)*$D$2+$E$2+$F$2+$A4,E$3)) -> 446.92574 | K4: =AVERAGE(OFFSET('t2688'!$A$1,$B$2+($B4-1)*$D$2+$E$2+$A4,E$3):OFFSET('t2688'!$A$1,$B$2+($B4-1)*$D$2+$E$2+$F$2+$A4,E$3)) -> 834.9145 | L4: =AVERAGE(OFFSET('t5376'!$A$1,$B$2+($B4-1)*$D$2+$E$2+$A4,E$3):OFFSET('t5376'!$A$1,$B$2+($B4-1)*$D$2+$E$2+$F$2+$A4,E$3)) -> 2024.1448 | M4: =AVERAGE(OFFSET('t10752'!$A$1,$B$2+($B4-1)*$D$2+$E$2+$A4,E$3):OFFSET('t10752'!$A$1,$B$2+($B4-1)*$D$2+$E$2+$F$2+$A4,E$3)) -> 2828.9626 | N4: =AVERAGE(OFFSET('t21504'!$A$1,$B$2+($B4-1)*$D$2+$E$2+$A4,E$3):OFFSET('t21504'!$A$1,$B$2+($B4-1)*$D$2+$E$2+$F$2+$A4,E$3)) -> 5690.6276 | X4: 4 | Y4: << "Ant=" << metrics.antColonyOptimization_time_ms << "ms "
B5: 2 | D5: =OFFSET('t42'!$A$1,$B$2+($B5-1)*$D$2+$A4,D$3) -> Run Combined Run0 | E5: =AVERAGE(OFFSET('t42'!$A$1,$B$2+($B5-1)*$D$2+$E$2+$A4+1,E$3):OFFSET('t42'!$A$1,$B$2+($B5-1)*$D$2+$E$2+$F$2+$A4,E$3)) -> 102.01439 | F5: =AVERAGE(OFFSET('t84'!$A$1,$B$2+($B5-1)*$D$2+$E$2+$A4+1,E$3):OFFSET('t84'!$A$1,$B$2+($B5-1)*$D$2+$E$2+$F$2+$A4,E$3)) -> 117.0229 | G5: =AVERAGE(OFFSET('t168'!$A$1,$B$2+($B5-1)*$D$2+$E$2+$A4+1,E$3):OFFSET('t168'!$A$1,$B$2+($B5-1)*$D$2+$E$2+$F$2+$A4,E$3)) -> 142.42735 | H5: =AVERAGE(OFFSET('t336'!$A$1,$B$2+($B5-1)*$D$2+$E$2+$A4+1,E$3):OFFSET('t336'!$A$1,$B$2+($B5-1)*$D$2+$E$2+$F$2+$A4,E$3)) -> 194.40171 | I5: =AVERAGE(OFFSET('t672'!$A$1,$B$2+($B5-1)*$D$2+$E$2+$A4+1,E$3):OFFSET('t672'!$A$1,$B$2+($B5-1)*$D$2+$E$2+$F$2+$A4,E$3)) -> 233.76094 | J5: =AVERAGE(OFFSET('t1344'!$A$1,$B$2+($B5-1)*$D$2+$E$2+$A4+1,E$3):OFFSET('t1344'!$A$1,$B$2+($B5-1)*$D$2+$E$2+$F$2+$A4,E$3)) -> 393.19157 | K5: =AVERAGE(OFFSET('t2688'!$A$1,$B$2+($B5-1)*$D$2+$E$2+$A4+1,E$3):OFFSET('t2688'!$A$1,$B$2+($B5-1)*$D$2+$E$2+$F$2+$A4,E$3)) -> 765.35716 | L5: =AVERAGE(OFFSET('t5376'!$A$1,$B$2+($B5-1)*$D$2+$E$2+$A4+1,E$3):OFFSET('t5376'!$A$1,$B$2+($B5-1)*$D$2+$E$2+$F$2+$A4,E$3)) -> 1981.7943 | M5: =AVERAGE(OFFSET('t10752'!$A$1,$B$2+($B5-1)*$D$2+$E$2+$A4+1,E$3):OFFSET('t10752'!$A$1,$B$2+($B5-1)*$D$2+$E$2+$F$2+$A4,E$3)) -> 2797.7298 | N5: =AVERAGE(OFFSET('t21504'!$A$1,$B$2+($B5-1)*$D$2+$E$2+$A4+1,E$3):OFFSET('t21504'!$A$1,$B$2+($B5-1)*$D$2+$E$2+$F$2+$A4,E$3)) -> 5694.1096 | X5: 5 | Y5: << "Update=" << metrics.updatePheromones_time_ms << "ms "
A6: 1 | B6: 3 | C6: 64 | D6: =OFFSET('t42'!$A$1,$B$2+($B6-1)*$D$2+$A6,D$3) -> Run Original ACO0 | E6: =AVERAGE(OFFSET('t42'!$A$1,$B$2+($B6-1)*$D$2+$E$2+$A6,E$3):OFFSET('t42'!$A$1,$B$2+($B6-1)*$D$2+$E$2+$F$2+$A6,E$3)) -> 129.49324 | F6: =AVERAGE(OFFSET('t84'!$A$1,$B$2+($B6-1)*$D$2+$E$2+$A6,E$3):OFFSET('t84'!$A$1,$B$2+($B6-1)*$D$2+$E$2+$F$2+$A6,E$3)) -> 148.77018 | G6: =AVERAGE(OFFSET('t168'!$A$1,$B$2+($B6-1)*$D$2+$E$2+$A6,E$3):OFFSET('t168'!$A$1,$B$2+($B6-1)*$D$2+$E$2+$F$2+$A6,E$3)) -> 186.79726 | H6: =AVERAGE(OFFSET('t336'!$A$1,$B$2+($B6-1)*$D$2+$E$2+$A6,E$3):OFFSET('t336'!$A$1,$B$2+($B6-1)*$D$2+$E$2+$F$2+$A6,E$3)) -> 251.39434 | I6: =AVERAGE(OFFSET('t672'!$A$1,$B$2+($B6-1)*$D$2+$E$2+$A6,E$3):OFFSET('t672'!$A$1,$B$2+($B6-1)*$D$2+$E$2+$F$2+$A6,E$3)) -> 306.06908 | J6: =AVERAGE(OFFSET('t1344'!$A$1,$B$2+($B6-1)*$D$2+$E$2+$A6,E$3):OFFSET('t1344'!$A$1,$B$2+($B6-1)*$D$2+$E$2+$F$2+$A6,E$3)) -> 466.82388 | K6: =AVERAGE(OFFSET('t2688'!$A$1,$B$2+($B6-1)*$D$2+$E$2+$A6,E$3):OFFSET('t2688'!$A$1,$B$2+($B6-1)*$D$2+$E$2+$F$2+$A6,E$3)) -> 831.3716 | L6: =AVERAGE(OFFSET('t5376'!$A$1,$B$2+($B6-1)*$D$2+$E$2+$A6,E$3):OFFSET('t5376'!$A$1,$B$2+($B6-1)*$D$2+$E$2+$F$2+$A6,E$3)) -> 1989.6006 | M6: =AVERAGE(OFFSET('t10752'!$A$1,$B$2+($B6-1)*$D$2+$E$2+$A6,E$3):OFFSET('t10752'!$A$1,$B$2+($B6-1)*$D$2+$E$2+$F$2+$A6,E$3)) -> 3871.6068 | N6: =AVERAGE(OFFSET('t21504'!$A$1,$B$2+($B6-1)*$D$2+$E$2+$A6,E$3):OFFSET('t21504'!$A$1,$B$2+($B6-1)*$D$2+$E$2+$F$2+$A6,E$3)) -> 7760.6148 | X6: 6 | Y6: << "Memory=" << metrics.memory_time_ms << "ms "
B7: 4 | D7: =OFFSET('t42'!$A$1,$B$2+($B7-1)*$D$2+$A6,D$3) -> Run Combined Run0 | E7: =AVERAGE(OFFSET('t42'!$A$1,$B$2+($B7-1)*$D$2+$E$2+$A6+1,E$3):OFFSET('t42'!$A$1,$B$2+($B7-1)*$D$2+$E$2+$F$2+$A6,E$3)) -> 104.56396 | F7: =AVERAGE(OFFSET('t84'!$A$1,$B$2+($B7-1)*$D$2+$E$2+$A6+1,E$3):OFFSET('t84'!$A$1,$B$2+($B7-1)*$D$2+$E$2+$F$2+$A6,E$3)) -> 117.91143 | G7: =AVERAGE(OFFSET('t168'!$A$1,$B$2+($B7-1)*$D$2+$E$2+$A6+1,E$3):OFFSET('t168'!$A$1,$B$2+($B7-1)*$D$2+$E$2+$F$2+$A6,E$3)) -> 141.49339 | H7: =AVERAGE(OFFSET('t336'!$A$1,$B$2+($B7-1)*$D$2+$E$2+$A6+1,E$3):OFFSET('t336'!$A$1,$B$2+($B7-1)*$D$2+$E$2+$F$2+$A6,E$3)) -> 202.06308 | I7: =AVERAGE(OFFSET('t672'!$A$1,$B$2+($B7-1)*$D$2+$E$2+$A6+1,E$3):OFFSET('t672'!$A$1,$B$2+($B7-1)*$D$2+$E$2+$F$2+$A6,E$3)) -> 260.39792 | J7: =AVERAGE(OFFSET('t1344'!$A$1,$B$2+($B7-1)*$D$2+$E$2+$A6+1,E$3):OFFSET('t1344'!$A$1,$B$2+($B7-1)*$D$2+$E$2+$F$2+$A6,E$3)) -> 420.80014 | K7: =AVERAGE(OFFSET('t2688'!$A$1,$B$2+($B7-1)*$D$2+$E$2+$A6+1,E$3):OFFSET('t2688'!$A$1,$B$2+($B7-1)*$D$2+$E$2+$F$2+$A6,E$3)) -> 762.34955 | L7: =AVERAGE(OFFSET('t5376'!$A$1,$B$2+($B7-1)*$D$2+$E$2+$A6+1,E$3):OFFSET('t5376'!$A$1,$B$2+($B7-1)*$D$2+$E$2+$F$2+$A6,E$3)) -> 1952.1457 | M7: =AVERAGE(OFFSET('t10752'!$A$1,$B$2+($B7-1)*$D$2+$E$2+$A6+1,E$3):OFFSET('t10752'!$A$1,$B$2+($B7-1)*$D$2+$E$2+$F$2+$A6,E$3)) -> 3839.5951 | N7: =AVERAGE(OFFSET('t21504'!$A$1,$B$2+($B7-1)*$D$2+$E$2+$A6+1,E$3):OFFSET('t21504'!$A$1,$B$2+($B7-1)*$D$2+$E$2+$F$2+$A6,E$3)) -> 7757.3555 | X7: 7 | Y7: << "HitRate=" << (100.0 * metrics.hash_hits / (metrics.hash_hits + metrics.hash_misses)) << "% "
A8: 2 | B8: 5 | C8: 96 | D8: =OFFSET('t42'!$A$1,$B$2+($B8-1)*$D$2+$A8,D$3) -> Run Original ACO0 | E8: =AVERAGE(OFFSET('t42'!$A$1,$B$2+($B8-1)*$D$2+$E$2+$A8,E$3):OFFSET('t42'!$A$1,$B$2+($B8-1)*$D$2+$E$2+$F$2+$A8,E$3)) -> 128.54004 | F8: =AVERAGE(OFFSET('t84'!$A$1,$B$2+($B8-1)*$D$2+$E$2+$A8,E$3):OFFSET('t84'!$A$1,$B$2+($B8-1)*$D$2+$E$2+$F$2+$A8,E$3)) -> 149.13538 | G8: =AVERAGE(OFFSET('t168'!$A$1,$B$2+($B8-1)*$D$2+$E$2+$A8,E$3):OFFSET('t168'!$A$1,$B$2+($B8-1)*$D$2+$E$2+$F$2+$A8,E$3)) -> 188.17214 | H8: =AVERAGE(OFFSET('t336'!$A$1,$B$2+($B8-1)*$D$2+$E$2+$A8,E$3):OFFSET('t336'!$A$1,$B$2+($B8-1)*$D$2+$E$2+$F$2+$A8,E$3)) -> 251.51452 | I8: =AVERAGE(OFFSET('t672'!$A$1,$B$2+($B8-1)*$D$2+$E$2+$A8,E$3):OFFSET('t672'!$A$1,$B$2+($B8-1)*$D$2+$E$2+$F$2+$A8,E$3)) -> 303.33146 | J8: =AVERAGE(OFFSET('t1344'!$A$1,$B$2+($B8-1)*$D$2+$E$2+$A8,E$3):OFFSET('t1344'!$A$1,$B$2+($B8-1)*$D$2+$E$2+$F$2+$A8,E$3)) -> 466.88156 | K8: =AVERAGE(OFFSET('t2688'!$A$1,$B$2+($B8-1)*$D$2+$E$2+$A8,E$3):OFFSET('t2688'!$A$1,$B$2+($B8-1)*$D$2+$E$2+$F$2+$A8,E$3)) -> 828.95072 | L8: =AVERAGE(OFFSET('t5376'!$A$1,$B$2+($B8-1)*$D$2+$E$2+$A8,E$3):OFFSET('t5376'!$A$1,$B$2+($B8-1)*$D$2+$E$2+$F$2+$A8,E$3)) -> 2190.383 | M8: =AVERAGE(OFFSET('t10752'!$A$1,$B$2+($B8-1)*$D$2+$E$2+$A8,E$3):OFFSET('t10752'!$A$1,$B$2+($B8-1)*$D$2+$E$2+$F$2+$A8,E$3)) -> 5711.2408 | N8: =AVERAGE(OFFSET('t21504'!$A$1,$B$2+($B8-1)*$D$2+$E$2+$A8,E$3):OFFSET('t21504'!$A$1,$B$2+($B8-1)*$D$2+$E$2+$F$2+$A8,E$3)) -> 11867.456 | X8: 8 | Y8: << "Occupancy=" << metrics.occupancy << "% "
B9: 6 | D9: =OFFSET('t42'!$A$1,$B$2+($B9-1)*$D$2+$A8,D$3) -> Run Combined Run0 | E9: =AVERAGE(OFFSET('t42'!$A$1,$B$2+($B9-1)*$D$2+$E$2+$A8+1,E$3):OFFSET('t42'!$A$1,$B$2+($B9-1)*$D$2+$E$2+$F$2+$A8,E$3)) -> 103.16269 | F9: =AVERAGE(OFFSET('t84'!$A$1,$B$2+($B9-1)*$D$2+$E$2+$A8+1,E$3):OFFSET('t84'!$A$1,$B$2+($B9-1)*$D$2+$E$2+$F$2+$A8,E$3)) -> 118.3192 | G9: =AVERAGE(OFFSET('t168'!$A$1,$B$2+($B9-1)*$D$2+$E$2+$A8+1,E$3):OFFSET('t168'!$A$1,$B$2+($B9-1)*$D$2+$E$2+$F$2+$A8,E$3)) -> 142.13573 | H9: =AVERAGE(OFFSET('t336'!$A$1,$B$2+($B9-1)*$D$2+$E$2+$A8+1,E$3):OFFSET('t336'!$A$1,$B$2+($B9-1)*$D$2+$E$2+$F$2+$A8,E$3)) -> 198.71618 | I9: =AVERAGE(OFFSET('t672'!$A$1,$B$2+($B9-1)*$D$2+$E$2+$A8+1,E$3):OFFSET('t672'!$A$1,$B$2+($B9-1)*$D$2+$E$2+$F$2+$A8,E$3)) -> 255.68259 | J9: =AVERAGE(OFFSET('t1344'!$A$1,$B$2+($B9-1)*$D$2+$E$2+$A8+1,E$3):OFFSET('t1344'!$A$1,$B$2+($B9-1)*$D$2+$E$2+$F$2+$A8,E$3)) -> 419.03469 | K9: =AVERAGE(OFFSET('t2688'!$A$1,$B$2+($B9-1)*$D$2+$E$2+$A8+1,E$3):OFFSET('t2688'!$A$1,$B$2+($B9-1)*$D$2+$E$2+$F$2+$A8,E$3)) -> 761.27384 | L9: =AVERAGE(OFFSET('t5376'!$A$1,$B$2+($B9-1)*$D$2+$E$2+$A8+1,E$3):OFFSET('t5376'!$A$1,$B$2+($B9-1)*$D$2+$E$2+$F$2+$A8,E$3)) -> 1938.901 | M9: =AVERAGE(OFFSET('t10752'!$A$1,$B$2+($B9-1)*$D$2+$E$2+$A8+1,E$3):OFFSET('t10752'!$A$1,$B$2+($B9-1)*$D$2+$E$2+$F$2+$A8,E$3)) -> 5675.2184 | N9: =AVERAGE(OFFSET('t21504'!$A$1,$B$2+($B9-1)*$D$2+$E$2+$A8+1,E$3):OFFSET('t21504'!$A$1,$B$2+($B9-1)*$D$2+$E$2+$F$2+$A8,E$3)) -> 11872.647 | X9: 9 | Y9: << "memory_throughput_gbs=" << metrics.memory_throughput_gbs << " "
A10: 3 | B10: 7 | C10: 128 | D10: =OFFSET('t42'!$A$1,$B$2+($B10-1)*$D$2+$A10,D$3) -> Run Original ACO0 | E10: =AVERAGE(OFFSET('t42'!$A$1,$B$2+($B10-1)*$D$2+$E$2+$A10,E$3):OFFSET('t42'!$A$1,$B$2+($B10-1)*$D$2+$E$2+$F$2+$A10,E$3)) -> 128.88728 | F10: =AVERAGE(OFFSET('t84'!$A$1,$B$2+($B10-1)*$D$2+$E$2+$A10,E$3):OFFSET('t84'!$A$1,$B$2+($B10-1)*$D$2+$E$2+$F$2+$A10,E$3)) -> 150.24776 | G10: =AVERAGE(OFFSET('t168'!$A$1,$B$2+($B10-1)*$D$2+$E$2+$A10,E$3):OFFSET('t168'!$A$1,$B$2+($B10-1)*$D$2+$E$2+$F$2+$A10,E$3)) -> 186.81154 | H10: =AVERAGE(OFFSET('t336'!$A$1,$B$2+($B10-1)*$D$2+$E$2+$A10,E$3):OFFSET('t336'!$A$1,$B$2+($B10-1)*$D$2+$E$2+$F$2+$A10,E$3)) -> 249.39814 | I10: =AVERAGE(OFFSET('t672'!$A$1,$B$2+($B10-1)*$D$2+$E$2+$A10,E$3):OFFSET('t672'!$A$1,$B$2+($B10-1)*$D$2+$E$2+$F$2+$A10,E$3)) -> 313.73646 | J10: =AVERAGE(OFFSET('t1344'!$A$1,$B$2+($B10-1)*$D$2+$E$2+$A10,E$3):OFFSET('t1344'!$A$1,$B$2+($B10-1)*$D$2+$E$2+$F$2+$A10,E$3)) -> 468.0841 | K10: =AVERAGE(OFFSET('t2688'!$A$1,$B$2+($B10-1)*$D$2+$E$2+$A10,E$3):OFFSET('t2688'!$A$1,$B$2+($B10-1)*$D$2+$E$2+$F$2+$A10,E$3)) -> 828.66968 | L10: =AVERAGE(OFFSET('t5376'!$A$1,$B$2+($B10-1)*$D$2+$E$2+$A10,E$3):OFFSET('t5376'!$A$1,$B$2+($B10-1)*$D$2+$E$2+$F$2+$A10,E$3)) -> 2084.5314 | M10: =AVERAGE(OFFSET('t10752'!$A$1,$B$2+($B10-1)*$D$2+$E$2+$A10,E$3):OFFSET('t10752'!$A$1,$B$2+($B10-1)*$D$2+$E$2+$F$2+$A10,E$3)) -> 5144.9948 | N10: =AVERAGE(OFFSET('t21504'!$A$1,$B$2+($B10-1)*$D$2+$E$2+$A10,E$3):OFFSET('t21504'!$A$1,$B$2+($B10-1)*$D$2+$E$2+$F$2+$A10,E$3)) -> 11531.442 | X10: 10 | Y10: << "MIN=" << metrics.min_fitness << " "
B11: 8 | D11: =OFFSET('t42'!$A$1,$B$2+($B11-1)*$D$2+$A10,D$3) -> Run Combined Run0 | E11: =AVERAGE(OFFSET('t42'!$A$1,$B$2+($B11-1)*$D$2+$E$2+$A10+1,E$3):OFFSET('t42'!$A$1,$B$2+($B11-1)*$D$2+$E$2+$F$2+$A10,E$3)) -> 104.91618 | F11: =AVERAGE(OFFSET('t84'!$A$1,$B$2+($B11-1)*$D$2+$E$2+$A10+1,E$3):OFFSET('t84'!$A$1,$B$2+($B11-1)*$D$2+$E$2+$F$2+$A10,E$3)) -> 118.97157 | G11: =AVERAGE(OFFSET('t168'!$A$1,$B$2+($B11-1)*$D$2+$E$2+$A10+1,E$3):OFFSET('t168'!$A$1,$B$2+($B11-1)*$D$2+$E$2+$F$2+$A10,E$3)) -> 141.70349 | H11: =AVERAGE(OFFSET('t336'!$A$1,$B$2+($B11-1)*$D$2+$E$2+$A10+1,E$3):OFFSET('t336'!$A$1,$B$2+($B11-1)*$D$2+$E$2+$F$2+$A10,E$3)) -> 197.55608 | I11: =AVERAGE(OFFSET('t672'!$A$1,$B$2+($B11-1)*$D$2+$E$2+$A10+1,E$3):OFFSET('t672'!$A$1,$B$2+($B11-1)*$D$2+$E$2+$F$2+$A10,E$3)) -> 282.95278 | J11: =AVERAGE(OFFSET('t1344'!$A$1,$B$2+($B11-1)*$D$2+$E$2+$A10+1,E$3):OFFSET('t1344'!$A$1,$B$2+($B11-1)*$D$2+$E$2+$F$2+$A10,E$3)) -> 417.788 | K11: =AVERAGE(OFFSET('t2688'!$A$1,$B$2+($B11-1)*$D$2+$E$2+$A10+1,E$3):OFFSET('t2688'!$A$1,$B$2+($B11-1)*$D$2+$E$2+$F$2+$A10,E$3)) -> 761.89537 | L11: =AVERAGE(OFFSET('t5376'!$A$1,$B$2+($B11-1)*$D$2+$E$2+$A10+1,E$3):OFFSET('t5376'!$A$1,$B$2+($B11-1)*$D$2+$E$2+$F$2+$A10,E$3)) -> 1936.0037 | M11: =AVERAGE(OFFSET('t10752'!$A$1,$B$2+($B11-1)*$D$2+$E$2+$A10+1,E$3):OFFSET('t10752'!$A$1,$B$2+($B11-1)*$D$2+$E$2+$F$2+$A10,E$3)) -> 5109.3959 | N11: =AVERAGE(OFFSET('t21504'!$A$1,$B$2+($B11-1)*$D$2+$E$2+$A10+1,E$3):OFFSET('t21504'!$A$1,$B$2+($B11-1)*$D$2+$E$2+$F$2+$A10,E$3)) -> 11514.2 | X11: 11 | Y11: << "MAX=" << metrics.max_fitness << " "
A12: 4 | B12: 9 | C12: 192 | D12: =OFFSET('t42'!$A$1,$B$2+($B12-1)*$D$2+$A12,D$3) -> Run Original ACO0 | E12: =AVERAGE(OFFSET('t42'!$A$1,$B$2+($B12-1)*$D$2+$E$2+$A12,E$3):OFFSET('t42'!$A$1,$B$2+($B12-1)*$D$2+$E$2+$F$2+$A12,E$3)) -> 131.13204 | F12: =AVERAGE(OFFSET('t84'!$A$1,$B$2+($B12-1)*$D$2+$E$2+$A12,E$3):OFFSET('t84'!$A$1,$B$2+($B12-1)*$D$2+$E$2+$F$2+$A12,E$3)) -> 151.67358 | G12: =AVERAGE(OFFSET('t168'!$A$1,$B$2+($B12-1)*$D$2+$E$2+$A12,E$3):OFFSET('t168'!$A$1,$B$2+($B12-1)*$D$2+$E$2+$F$2+$A12,E$3)) -> 187.20472 | H12: =AVERAGE(OFFSET('t336'!$A$1,$B$2+($B12-1)*$D$2+$E$2+$A12,E$3):OFFSET('t336'!$A$1,$B$2+($B12-1)*$D$2+$E$2+$F$2+$A12,E$3)) -> 260.54448 | I12: =AVERAGE(OFFSET('t672'!$A$1,$B$2+($B12-1)*$D$2+$E$2+$A12,E$3):OFFSET('t672'!$A$1,$B$2+($B12-1)*$D$2+$E$2+$F$2+$A12,E$3)) -> 304.0688 | J12: =AVERAGE(OFFSET('t1344'!$A$1,$B$2+($B12-1)*$D$2+$E$2+$A12,E$3):OFFSET('t1344'!$A$1,$B$2+($B12-1)*$D$2+$E$2+$F$2+$A12,E$3)) -> 469.2644 | K12: =AVERAGE(OFFSET('t2688'!$A$1,$B$2+($B12-1)*$D$2+$E$2+$A12,E$3):OFFSET('t2688'!$A$1,$B$2+($B12-1)*$D$2+$E$2+$F$2+$A12,E$3)) -> 827.41974 | L12: =AVERAGE(OFFSET('t5376'!$A$1,$B$2+($B12-1)*$D$2+$E$2+$A12,E$3):OFFSET('t5376'!$A$1,$B$2+($B12-1)*$D$2+$E$2+$F$2+$A12,E$3)) -> 2121.4716 | M12: =AVERAGE(OFFSET('t10752'!$A$1,$B$2+($B12-1)*$D$2+$E$2+$A12,E$3):OFFSET('t10752'!$A$1,$B$2+($B12-1)*$D$2+$E$2+$F$2+$A12,E$3)) -> 8281.2848 | N12: =AVERAGE(OFFSET('t21504'!$A$1,$B$2+($B12-1)*$D$2+$E$2+$A12,E$3):OFFSET('t21504'!$A$1,$B$2+($B12-1)*$D$2+$E$2+$F$2+$A12,E$3)) -> 20903.408
B13: 10 | D13: =OFFSET('t42'!$A$1,$B$2+($B13-1)*$D$2+$A12,D$3) -> Run Combined Run0 | E13: =AVERAGE(OFFSET('t42'!$A$1,$B$2+($B13-1)*$D$2+$E$2+$A12+1,E$3):OFFSET('t42'!$A$1,$B$2+($B13-1)*$D$2+$E$2+$F$2+$A12,E$3)) -> 116.18904 | F13: =AVERAGE(OFFSET('t84'!$A$1,$B$2+($B13-1)*$D$2+$E$2+$A12+1,E$3):OFFSET('t84'!$A$1,$B$2+($B13-1)*$D$2+$E$2+$F$2+$A12,E$3)) -> 119.868 | G13: =AVERAGE(OFFSET('t168'!$A$1,$B$2+($B13-1)*$D$2+$E$2+$A12+1,E$3):OFFSET('t168'!$A$1,$B$2+($B13-1)*$D$2+$E$2+$F$2+$A12,E$3)) -> 141.97618 | H13: =AVERAGE(OFFSET('t336'!$A$1,$B$2+($B13-1)*$D$2+$E$2+$A12+1,E$3):OFFSET('t336'!$A$1,$B$2+($B13-1)*$D$2+$E$2+$F$2+$A12,E$3)) -> 208.22906 | I13: =AVERAGE(OFFSET('t672'!$A$1,$B$2+($B13-1)*$D$2+$E$2+$A12+1,E$3):OFFSET('t672'!$A$1,$B$2+($B13-1)*$D$2+$E$2+$F$2+$A12,E$3)) -> 256.92018 | J13: =AVERAGE(OFFSET('t1344'!$A$1,$B$2+($B13-1)*$D$2+$E$2+$A12+1,E$3):OFFSET('t1344'!$A$1,$B$2+($B13-1)*$D$2+$E$2+$F$2+$A12,E$3)) -> 418.66892 | K13: =AVERAGE(OFFSET('t2688'!$A$1,$B$2+($B13-1)*$D$2+$E$2+$A12+1,E$3):OFFSET('t2688'!$A$1,$B$2+($B13-1)*$D$2+$E$2+$F$2+$A12,E$3)) -> 762.94084 | L13: =AVERAGE(OFFSET('t5376'!$A$1,$B$2+($B13-1)*$D$2+$E$2+$A12+1,E$3):OFFSET('t5376'!$A$1,$B$2+($B13-1)*$D$2+$E$2+$F$2+$A12,E$3)) -> 1937.0567 | M13: =AVERAGE(OFFSET('t10752'!$A$1,$B$2+($B13-1)*$D$2+$E$2+$A12+1,E$3):OFFSET('t10752'!$A$1,$B$2+($B13-1)*$D$2+$E$2+$F$2+$A12,E$3)) -> 8242.4524 | N13: =AVERAGE(OFFSET('t21504'!$A$1,$B$2+($B13-1)*$D$2+$E$2+$A12+1,E$3):OFFSET('t21504'!$A$1,$B$2+($B13-1)*$D$2+$E$2+$F$2+$A12,E$3)) -> 20905.116
A14: 5 | B14: 11 | C14: 256 | D14: =OFFSET('t42'!$A$1,$B$2+($B14-1)*$D$2+$A14,D$3) -> Run Original ACO0 | E14: =AVERAGE(OFFSET('t42'!$A$1,$B$2+($B14-1)*$D$2+$E$2+$A14,E$3):OFFSET('t42'!$A$1,$B$2+($B14-1)*$D$2+$E$2+$F$2+$A14,E$3)) -> 139.3247 | F14: =AVERAGE(OFFSET('t84'!$A$1,$B$2+($B14-1)*$D$2+$E$2+$A14,E$3):OFFSET('t84'!$A$1,$B$2+($B14-1)*$D$2+$E$2+$F$2+$A14,E$3)) -> 150.51338 | G14: =AVERAGE(OFFSET('t168'!$A$1,$B$2+($B14-1)*$D$2+$E$2+$A14,E$3):OFFSET('t168'!$A$1,$B$2+($B14-1)*$D$2+$E$2+$F$2+$A14,E$3)) -> 188.2899 | H14: =AVERAGE(OFFSET('t336'!$A$1,$B$2+($B14-1)*$D$2+$E$2+$A14,E$3):OFFSET('t336'!$A$1,$B$2+($B14-1)*$D$2+$E$2+$F$2+$A14,E$3)) -> 251.4874 | I14: =AVERAGE(OFFSET('t672'!$A$1,$B$2+($B14-1)*$D$2+$E$2+$A14,E$3):OFFSET('t672'!$A$1,$B$2+($B14-1)*$D$2+$E$2+$F$2+$A14,E$3)) -> 305.10372 | J14: =AVERAGE(OFFSET('t1344'!$A$1,$B$2+($B14-1)*$D$2+$E$2+$A14,E$3):OFFSET('t1344'!$A$1,$B$2+($B14-1)*$D$2+$E$2+$F$2+$A14,E$3)) -> 470.03588 | K14: =AVERAGE(OFFSET('t2688'!$A$1,$B$2+($B14-1)*$D$2+$E$2+$A14,E$3):OFFSET('t2688'!$A$1,$B$2+($B14-1)*$D$2+$E$2+$F$2+$A14,E$3)) -> 828.91412 | L14: =AVERAGE(OFFSET('t5376'!$A$1,$B$2+($B14-1)*$D$2+$E$2+$A14,E$3):OFFSET('t5376'!$A$1,$B$2+($B14-1)*$D$2+$E$2+$F$2+$A14,E$3)) -> 2267.01 | M14: =AVERAGE(OFFSET('t10752'!$A$1,$B$2+($B14-1)*$D$2+$E$2+$A14,E$3):OFFSET('t10752'!$A$1,$B$2+($B14-1)*$D$2+$E$2+$F$2+$A14,E$3)) -> 8221.101 | N14: =AVERAGE(OFFSET('t21504'!$A$1,$B$2+($B14-1)*$D$2+$E$2+$A14,E$3):OFFSET('t21504'!$A$1,$B$2+($B14-1)*$D$2+$E$2+$F$2+$A14,E$3)) -> #DIV/0!
B15: 12 | D15: =OFFSET('t42'!$A$1,$B$2+($B15-1)*$D$2+$A14,D$3) -> Run Combined Run0 | E15: =AVERAGE(OFFSET('t42'!$A$1,$B$2+($B15-1)*$D$2+$E$2+$A14+1,E$3):OFFSET('t42'!$A$1,$B$2+($B15-1)*$D$2+$E$2+$F$2+$A14,E$3)) -> 105.12959 | F15: =AVERAGE(OFFSET('t84'!$A$1,$B$2+($B15-1)*$D$2+$E$2+$A14+1,E$3):OFFSET('t84'!$A$1,$B$2+($B15-1)*$D$2+$E$2+$F$2+$A14,E$3)) -> 119.60782 | G15: =AVERAGE(OFFSET('t168'!$A$1,$B$2+($B15-1)*$D$2+$E$2+$A14+1,E$3):OFFSET('t168'!$A$1,$B$2+($B15-1)*$D$2+$E$2+$F$2+$A14,E$3)) -> 142.92063 | H15: =AVERAGE(OFFSET('t336'!$A$1,$B$2+($B15-1)*$D$2+$E$2+$A14+1,E$3):OFFSET('t336'!$A$1,$B$2+($B15-1)*$D$2+$E$2+$F$2+$A14,E$3)) -> 200.65853 | I15: =AVERAGE(OFFSET('t672'!$A$1,$B$2+($B15-1)*$D$2+$E$2+$A14+1,E$3):OFFSET('t672'!$A$1,$B$2+($B15-1)*$D$2+$E$2+$F$2+$A14,E$3)) -> 259.10124 | J15: =AVERAGE(OFFSET('t1344'!$A$1,$B$2+($B15-1)*$D$2+$E$2+$A14+1,E$3):OFFSET('t1344'!$A$1,$B$2+($B15-1)*$D$2+$E$2+$F$2+$A14,E$3)) -> 419.32849 | K15: =AVERAGE(OFFSET('t2688'!$A$1,$B$2+($B15-1)*$D$2+$E$2+$A14+1,E$3):OFFSET('t2688'!$A$1,$B$2+($B15-1)*$D$2+$E$2+$F$2+$A14,E$3)) -> 760.85345 | L15: =AVERAGE(OFFSET('t5376'!$A$1,$B$2+($B15-1)*$D$2+$E$2+$A14+1,E$3):OFFSET('t5376'!$A$1,$B$2+($B15-1)*$D$2+$E$2+$F$2+$A14,E$3)) -> 1941.1078 | M15: =AVERAGE(OFFSET('t10752'!$A$1,$B$2+($B15-1)*$D$2+$E$2+$A14+1,E$3):OFFSET('t10752'!$A$1,$B$2+($B15-1)*$D$2+$E$2+$F$2+$A14,E$3)) -> 8181.6098 | N15: =AVERAGE(OFFSET('t21504'!$A$1,$B$2+($B15-1)*$D$2+$E$2+$A14+1,E$3):OFFSET('t21504'!$A$1,$B$2+($B15-1)*$D$2+$E$2+$F$2+$A14,E$3)) -> #DIV/0!
E16: =E17/21 -> 2 | F16: =F17/21 -> 4 | G16: =G17/21 -> 8 | H16: =H17/21 -> 16 | I16: =I17/21 -> 32 | J16: =J17/21 -> 64 | K16: =K17/21 -> 128 | L16: =L17/21 -> 256 | ... W16: =W17/21 -> 524288
E17: 42 | F17: =E17*2 -> 84 | G17: =F17*2 -> 168 | H17: =G17*2 -> 336 | I17: =H17*2 -> 672 | J17: =I17*2 -> 1344 | K17: =J17*2 -> 2688 | L17: =K17*2 -> 5376 | M17: =L17*2 -> 10752 | ... W17: =V17*2 -> 11010048 | Y17: 42 | Z17: =Y17*2 -> 84 | AA17: =Z17*2 -> 168 | AB17: =AA17*2 -> 336 | AC17: =AB17*2 -> 672 | AD17: =AC17*2 -> 1344 | AE17: =AD17*2 -> 2688 | AF17: =AE17*2 -> 5376 | AG17: =AF17*2 -> 10752 | ... AQ17: =AP17*2 -> 11010048
C18: 3 этапа | D18: 32 | E18: =E4 -> 129.34202 | F18: =F4 -> 149.47686 | G18: =G4 -> 187.42248 | H18: =H4 -> 244.43236 | I18: =I4 -> 283.34354 | J18: =J4 -> 446.92574 | K18: =K4 -> 834.9145 | L18: =L4 -> 2024.1448 | ... N18: =N4 -> 5690.6276 | Y18: =CORREL($D18:$D23,E18:E23) -> 0.81979255 | Z18: =CORREL($D18:$D23,F18:F23) -> 0.74247911 | AA18: =CORREL($D18:$D23,G18:G23) -> 0.41621449 | AB18: =CORREL($D18:$D23,H18:H23) -> 0.57960239 | AC18: =CORREL($D18:$D23,I18:I23) -> 0.47611186 | AD18: =CORREL($D18:$D23,J18:J23) -> 0.67537667 | AE18: =CORREL($D18:$D23,K18:K23) -> -0.73406602 | AF18: =CORREL($D18:$D23,L18:L23) -> 0.79102154 | AG18: =CORREL($D18:$D23,M18:M23) -> 0.94514363
D19: 64 | E19: =E6 -> 129.49324 | F19: =F6 -> 148.77018 | G19: =G6 -> 186.79726 | H19: =H6 -> 251.39434 | I19: =I6 -> 306.06908 | J19: =J6 -> 466.82388 | K19: =K6 -> 831.3716 | L19: =L6 -> 1989.6006 | ... N19: =N6 -> 7760.6148
D20: 96 | E20: =E8 -> 128.54004 | F20: =F8 -> 149.13538 | G20: =G8 -> 188.17214 | H20: =H8 -> 251.51452 | I20: =I8 -> 303.33146 | J20: =J8 -> 466.88156 | K20: =K8 -> 828.95072 | L20: =L8 -> 2190.383 | ... N20: =N8 -> 11867.456
D21: 128 | E21: =E10 -> 128.88728 | F21: =F10 -> 150.24776 | G21: =G10 -> 186.81154 | H21: =H10 -> 249.39814 | I21: =I10 -> 313.73646 | J21: =J10 -> 468.0841 | K21: =K10 -> 828.66968 | L21: =L10 -> 2084.5314 | ... N21: =N10 -> 11531.442
D22: 192 | E22: =E12 -> 131.13204 | F22: =F12 -> 151.67358 | G22: =G12 -> 187.20472 | H22: =H12 -> 260.54448 | I22: =I12 -> 304.0688 | J22: =J12 -> 469.2644 | K22: =K12 -> 827.41974 | L22: =L12 -> 2121.4716 | ... N22: =N12 -> 20903.408
D23: 256 | E23: =E14 -> 139.3247 | F23: =F14 -> 150.51338 | G23: =G14 -> 188.2899 | H23: =H14 -> 251.4874 | I23: =I14 -> 305.10372 | J23: =J14 -> 470.03588 | K23: =K14 -> 828.91412 | L23: =L14 -> 2267.01 | ... N23: =N14 -> #DIV/0!
E27: =E28/21 -> 2 | F27: =F28/21 -> 4 | G27: =G28/21 -> 8 | H27: =H28/21 -> 16 | I27: =I28/21 -> 32 | J27: =J28/21 -> 64 | K27: =K28/21 -> 128 | L27: =L28/21 -> 256 | ... W27: =W28/21 -> 524288
E28: 42 | F28: =E28*2 -> 84 | G28: =F28*2 -> 168 | H28: =G28*2 -> 336 | I28: =H28*2 -> 672 | J28: =I28*2 -> 1344 | K28: =J28*2 -> 2688 | L28: =K28*2 -> 5376 | M28: =L28*2 -> 10752 | ... W28: =V28*2 -> 11010048
C29: 2 этапа | D29: 32 | E29: =E5 -> 102.01439 | F29: =F5 -> 117.0229 | G29: =G5 -> 142.42735 | H29: =H5 -> 194.40171 | I29: =I5 -> 233.76094 | J29: =J5 -> 393.19157 | K29: =K5 -> 765.35716 | L29: =L5 -> 1981.7943 | ... N29: =N5 -> 5694.1096 | Y29: =CORREL($D29:$D34,E29:E34) -> 0.51641468 | Z29: =CORREL($D29:$D34,F29:F34) -> 0.92263588 | AA29: =CORREL($D29:$D34,G29:G34) -> 0.48185514 | AB29: =CORREL($D29:$D34,H29:H34) -> 0.53807162 | AC29: =CORREL($D29:$D34,I29:I34) -> 0.35537791 | AD29: =CORREL($D29:$D34,J29:J34) -> 0.53697507 | AE29: =CORREL($D29:$D34,K29:K34) -> -0.60775373 | AF29: =CORREL($D29:$D34,L29:L34) -> -0.65290487 | AG29: =CORREL($D29:$D34,M29:M34) -> 0.94511762
D30: 64 | E30: =E7 -> 104.56396 | F30: =F7 -> 117.91143 | G30: =G7 -> 141.49339 | H30: =H7 -> 202.06308 | I30: =I7 -> 260.39792 | J30: =J7 -> 420.80014 | K30: =K7 -> 762.34955 | L30: =L7 -> 1952.1457 | ... N30: =N7 -> 7757.3555
D31: 96 | E31: =E9 -> 103.16269 | F31: =F9 -> 118.3192 | G31: =G9 -> 142.13573 | H31: =H9 -> 198.71618 | I31: =I9 -> 255.68259 | J31: =J9 -> 419.03469 | K31: =K9 -> 761.27384 | L31: =L9 -> 1938.901 | ... N31: =N9 -> 11872.647
D32: 128 | E32: =E11 -> 104.91618 | F32: =F11 -> 118.97157 | G32: =G11 -> 141.70349 | H32: =H11 -> 197.55608 | I32: =I11 -> 282.95278 | J32: =J11 -> 417.788 | K32: =K11 -> 761.89537 | L32: =L11 -> 1936.0037 | ... N32: =N11 -> 11514.2
D33: 192 | E33: =E13 -> 116.18904 | F33: =F13 -> 119.868 | G33: =G13 -> 141.97618 | H33: =H13 -> 208.22906 | I33: =I13 -> 256.92018 | J33: =J13 -> 418.66892 | K33: =K13 -> 762.94084 | L33: =L13 -> 1937.0567 | ... N33: =N13 -> 20905.116
D34: 256 | E34: =E15 -> 105.12959 | F34: =F15 -> 119.60782 | G34: =G15 -> 142.92063 | H34: =H15 -> 200.65853 | I34: =I15 -> 259.10124 | J34: =J15 -> 419.32849 | K34: =K15 -> 760.85345 | L34: =L15 -> 1941.1078 | ... N34: =N15 -> #DIV/0!
E37: 42 | F37: =E37*2 -> 84 | G37: =F37*2 -> 168 | H37: =G37*2 -> 336 | I37: =H37*2 -> 672 | J37: =I37*2 -> 1344 | K37: =J37*2 -> 2688 | L37: =K37*2 -> 5376 | M37: =L37*2 -> 10752 | ... W37: =V37*2 -> 11010048
C38: 3 этапа | D38: 32 | E38: =E18/E$17 -> 3.0795719 | F38: =F18/F$17 -> 1.7794864 | G38: =G18/G$17 -> 1.11561 | H38: =H18/H$17 -> 0.72747726 | I38: =I18/I$17 -> 0.42164217 | J38: =J18/J$17 -> 0.33253403 | K38: =K18/K$17 -> 0.31060807 | L38: =L18/L$17 -> 0.37651503 | ... N38: =N18/N$17 -> 0.26463112
D39: 64 | E39: =E19/E$17 -> 3.0831723 | F39: =F19/F$17 -> 1.7710736 | G39: =G19/G$17 -> 1.1118885 | H39: =H19/H$17 -> 0.74819744 | I39: =I19/I$17 -> 0.45545994 | J39: =J19/J$17 -> 0.3473392 | K39: =K19/K$17 -> 0.30929003 | L39: =L19/L$17 -> 0.3700894 | ... N39: =N19/N$17 -> 0.36089169
D40: 96 | E40: =E20/E$17 -> 3.0604771 | F40: =F20/F$17 -> 1.7754212 | G40: =G20/G$17 -> 1.1200723 | H40: =H20/H$17 -> 0.74855512 | I40: =I20/I$17 -> 0.4513861 | J40: =J20/J$17 -> 0.34738211 | K40: =K20/K$17 -> 0.3083894 | L40: =L20/L$17 -> 0.40743731 | ... N40: =N20/N$17 -> 0.55187202
D41: 128 | E41: =E21/E$17 -> 3.0687448 | F41: =F21/F$17 -> 1.7886638 | G41: =G21/G$17 -> 1.1119735 | H41: =H21/H$17 -> 0.74225637 | I41: =I21/I$17 -> 0.46686973 | J41: =J21/J$17 -> 0.34827686 | K41: =K21/K$17 -> 0.30828485 | L41: =L21/L$17 -> 0.38774766 | ... N41: =N21/N$17 -> 0.53624637
D42: 192 | E42: =E22/E$17 -> 3.1221914 | F42: =F22/F$17 -> 1.8056379 | G42: =G22/G$17 -> 1.1143138 | H42: =H22/H$17 -> 0.77543 | I42: =I22/I$17 -> 0.45248333 | J42: =J22/J$17 -> 0.34915506 | K42: =K22/K$17 -> 0.30781984 | L42: =L22/L$17 -> 0.39461897 | ... N42: =N22/N$17 -> 0.97207068
D43: 256 | E43: =E23/E$17 -> 3.3172548 | F43: =F23/F$17 -> 1.791826 | G43: =G23/G$17 -> 1.1207732 | H43: =H23/H$17 -> 0.7484744 | I43: =I23/I$17 -> 0.45402339 | J43: =J23/J$17 -> 0.34972908 | K43: =K23/K$17 -> 0.30837579 | L43: =L23/L$17 -> 0.42169085 | ... N43: =N23/N$17 -> #DIV/0!
E45: 42 | F45: =E45*2 -> 84 | G45: =F45*2 -> 168 | H45: =G45*2 -> 336 | I45: =H45*2 -> 672 | J45: =I45*2 -> 1344 | K45: =J45*2 -> 2688 | L45: =K45*2 -> 5376 | M45: =L45*2 -> 10752 | ... W45: =V45*2 -> 11010048
C46: 2 этапа | D46: 32 | E46: =E29/E$28 -> 2.428914 | F46: =F29/F$28 -> 1.3931297 | G46: =G29/G$28 -> 0.84778183 | H46: =H29/H$28 -> 0.57857653 | I46: =I29/I$28 -> 0.34785854 | J46: =J29/J$28 -> 0.29255325 | K46: =K29/K$28 -> 0.28473109 | L46: =L29/L$28 -> 0.36863733 | ... N46: =N29/N$28 -> 0.26479304
...

Sheet t42
A1: Device 0: NVIDIA GeForce RTX 3060 | B1: Max thread in blocks: 1024 Total Global Memory: 12287,4 MB GPU Global Memory Usage: 0,0887489 MB GPU Global Memory Hash Table: 1024 MB Max PARAMETR_SIZE in GPU Global Memory: 5570990 Shared memory per block: 49152 bytes (48 KB) Shared memory per multiprocessor: 102400 bytes (100 KB) Data size in Shared memory per block: 336 bytes (0,328125 KB) Constant Memory: 65536 bytes Parameter data size (in Constant Memory): 1680 bytes (1,64062 KB) Registers per Block: 65536 Warp Size: 32 Compute Capability: 8,6 Can Map Host Memory: Yes Clock Rate: 1777 MHz L2 Cache Size: 2359296 bytes Multiprocessor Count: 28 | C1: Max thread in blocks by axis: (1024, 1024, 64) | D1: Max blocks by axis: (2147483647, 65535, 65535) | E1: PARAMETR_SIZE: 42 | F1: PARAMETR_SIZE_ONE_X: 21 | G1: MAX_VALUE_SIZE: 5 | H1: NAME_FILE_GRAPH: Parametr_Graph/test42,txt | I1: ANT_SIZE: 500 | J1: KOL_ITERATION: 500 | K1: KOL_PROGON_STATISTICS: 50 | L1: PARAMETR_Q: 1 | M1: PARAMETR_RO: 0,999 | N1: TYPE_ACO: 1 | O1: ACOCCyN_KOL_ITERATION: 50, MAX_PARAMETR_VALUE_TO_MIN_OPT: 1, HASH_TABLE_SIZE: 67108864, MAX_PROBES: 10000, MAX_THREAD_CUDA: 512, CPU_RANDOM: 0, KOL_THREAD_CPU_ANT: 12, CONST_RANDOM: 100000, MAX_CONST: 8192, OPTIMIZE: OPTIMIZE_MIN_1 | P1: FUNCTION: SHAFFERA GO_ALG_MINMAX: 1(1, 1000)
A2: Run Original ACO0 | B2: 127.983 | C2: 108.134 | D2: 2.94085 | E2: 10.8556 | F2: 55.3684 | G2: 19.8486 | H2: 85.1924 | I2: 100 | J2: 0.338523 | K2: 0.00123639 | L2: 0.995116
A3: Run Original ACO1 | B3: 129.494 | C3: 108.971 | D3: 2.94613 | E3: 10.8 | F3: 55.3746 | G3: 20.5229 | H3: 83.4328 | I3: 100 | J3: 0.334572 | K3: 0.00123296 | L3: 0.995116
A4: Run Original ACO2 | B4: 128.977 | C4: 108.388 | D4: 2.94421 | E4: 10.7481 | F4: 55.28 | G4: 20.5893 | H4: 81.962 | I4: 100 | J4: 0.335913 | K4: 0.00123299 | L4: 0.995116
A5: Run Original ACO3 | B5: 128.234 | C5: 108.036 | D5: 2.9331 | E5: 10.7159 | F5: 55.2661 | G5: 20.1978 | H5: 80.7632 | I5: 100 | J5: 0.337861 | K5: 0.00123005 | L5: 0.995115
A6: Run Original ACO4 | B6: 127.932 | C6: 108.013 | D6: 2.94869 | E6: 10.669 | F6: 55.2645 | G6: 19.9183 | H6: 79.5 | I6: 100 | J6: 0.338658 | K6: 0.00125279 | L6: 0.995116
A7: Run Original ACO5 | B7: 128.229 | C7: 108.265 | D7: 2.9356 | E7: 10.677 | F7: 55.3601 | G7: 19.9633 | H7: 78.708 | I7: 100 | J7: 0.337874 | K7: 0.0013247 | L7: 0.995115
A8: Run Original ACO6 | B8: 129.094 | C8: 109.072 | D8: 2.94782 | E8: 10.6542 | F8: 55.365 | G8: 20.0213 | H8: 77.9964 | I8: 100 | J8: 0.33561 | K8: 0.00132495 | L8: 0.995116
A9: Run Original ACO7 | B9: 127.83 | C9: 108.052 | D9: 2.92965 | E9: 10.6283 | F9: 55.3926 | G9: 19.7779 | H9: 77.1864 | I9: 100 | J9: 0.338928 | K9: 0.00164594 | L9: 0.995116
A10: Run Original ACO8 | B10: 127.293 | C10: 107.456 | D10: 2.93752 | E10: 10.5956 | F10: 55.2597 | G10: 19.8378 | H10: 76.4628 | I10: 100 | J10: 0.340357 | K10: 0.00130738 | L10: 0.995116
A11: Run Original ACO9 | B11: 127.492 | C11: 107.699 | D11: 2.95777 | E11: 10.6022 | F11: 55.3588 | G11: 19.7938 | H11: 75.7392 | I11: 100 | J11: 0.339825 | K11: 0.00145367 | L11: 0.995115
A12: Run Original ACO10 | B12: 127.593 | C12: 107.893 | D12: 2.9411 | E12: 10.5909 | F12: 55.2873 | G12: 19.6992 | H12: 75.1492 | I12: 100 | J12: 0.339558 | K12: 0.00129425 | L12: 0.995114
A13: Run Original ACO11 | B13: 128.04 | C13: 108.059 | D13: 2.97422 | E13: 10.5901 | F13: 55.2633 | G13: 19.9812 | H13: 74.3784 | I13: 100 | J13: 0.338373 | K13: 0.00145367 | L13: 0.995115
... A101: Run Combined Run49 | B101: 102.722 | C101: 82.4004 | D101: 51.8108 | E101: 10.3824 | F101: 0 | G101: 20.3212 | H101: 67.964 | I101: 100 | J101: 0.429388 | K101: 0.0290376 | L101: 0.993143
A102: Device 0: NVIDIA GeForce RTX 3060 | B102: Max thread in blocks: 1024 Total Global Memory: 12287,4 MB GPU Global Memory Usage: 0,0887489 MB GPU Global Memory Hash Table: 1024 MB Max PARAMETR_SIZE in GPU Global Memory: 5570990 Shared memory per block: 49152 bytes (48 KB) Shared memory per multiprocessor: 102400 bytes (100 KB) Data size in Shared memory per block: 336 bytes (0,328125 KB) Constant Memory: 65536 bytes Parameter data size (in Constant Memory): 1680 bytes (1,64062 KB) Registers per Block: 65536 Warp Size: 32 Compute Capability: 8,6 Can Map Host Memory: Yes Clock Rate: 1777 MHz L2 Cache Size: 2359296 bytes Multiprocessor Count: 28 | C102: Max thread in blocks by axis: (1024, 1024, 64) | D102: Max blocks by axis: (2147483647, 65535, 65535) | E102: PARAMETR_SIZE: 42 | F102: PARAMETR_SIZE_ONE_X: 21 | G102: MAX_VALUE_SIZE: 5 | H102: NAME_FILE_GRAPH: Parametr_Graph/test42,txt | I102: ANT_SIZE: 500 | J102: KOL_ITERATION: 500 | K102: KOL_PROGON_STATISTICS: 50 | L102: PARAMETR_Q: 1 | M102: PARAMETR_RO: 0,999 | N102: TYPE_ACO: 1 | O102: ACOCCyN_KOL_ITERATION: 50, MAX_PARAMETR_VALUE_TO_MIN_OPT: 1, HASH_TABLE_SIZE: 67108864, MAX_PROBES: 10000, MAX_THREAD_CUDA: 512, CPU_RANDOM: 0, KOL_THREAD_CPU_ANT: 12, CONST_RANDOM: 100000, MAX_CONST: 8192, OPTIMIZE: OPTIMIZE_MIN_1 | P102: FUNCTION: SHAFFERA GO_ALG_MINMAX: 1(1, 1000)
A103: Run Original ACO0 | B103: 129.617 | C103: 109.269 | D103: 2.98453 | E103: 10.9102 | F103: 55.4307 | G103: 20.3483 | H103: 83.5484 | I103: 100 | J103: 0.334255 | K103: 0.00123238 | L103: 0.995115
A104: Run Original ACO1 | B104: 129.921 | C104: 109.275 | D104: 2.9516 | E104: 10.897 | F104: 55.3203 | G104: 20.6457 | H104: 82.6104 | I104: 100 | J104: 0.333474 | K104: 0.00124651 | L104: 0.995116
A105: Run Original ACO2 | B105: 128.897 | C105: 108.36 | D105: 2.96369 | E105: 10.8623 | F105: 55.315 | G105: 20.5372 | H105: 81.59 | I105: 100 | J105: 0.336121 | K105: 0.00123079 | L105: 0.995116
A106: Run Original ACO3 | B106: 128.868 | C106: 108.911 | D106: 2.93963 | E106: 10.8159 | F106: 55.5094 | G106: 19.9571 | H106: 80.6456 | I106: 100 | J106: 0.336197 | K106: 0.00123079 | L106: 0.995116
A107: Run Original ACO4 | B107: 128.594 | C107: 108.396 | D107: 2.94459 | E107: 10.7953 | F107: 55.3166 | G107: 20.1978 | H107: 79.782 | I107: 100 | J107: 0.336914 | K107: 0.00123081 | L107: 0.995116
A108: Run Original ACO5 | B108: 128.537 | C108: 108.468 | D108: 2.95937 | E108: 10.7837 | F108: 55.3139 | G108: 20.069 | H108: 78.9096 | I108: 100 | J108: 0.337064 | K108: 0.00123223 | L108: 0.995115
A109: Run Original ACO6 | B109: 128.874 | C109: 108.674 | D109: 2.95691 | E109: 10.7393 | F109: 55.4101 | G109: 20.1993 | H109: 78.1868 | I109: 100 | J109: 0.336183 | K109: 0.00123206 | L109: 0.995101
A110: Run Original ACO7 | B110: 129.064 | C110: 108.774 | D110: 2.95406 | E110: 10.7363 | F110: 55.5206 | G110: 20.2907 | H110: 77.8672 | I110: 100 | J110: 0.335686 | K110: 0.00123061 | L110: 0.995113
A111: Run Original ACO8 | B111: 130.673 | C111: 110.117 | D111: 2.94177 | E111: 11.5616 | F111: 55.5119 | G111: 20.5562 | H111: 91.3856 | I111: 100 | J111: 0.331555 | K111: 0.00123214 | L111: 0.995116
A112: Run Original ACO9 | B112: 129.709 | C112: 109.326 | D112: 2.95873 | E112: 11.5347 | F112: 55.3097 | G112: 20.3832 | H112: 91.8032 | I112: 100 | J112: 0.334018 | K112: 0.00123571 | L112: 0.995116
A113: Run Original ACO10 | B113: 129.608 | C113: 109.251 | D113: 2.93473 | E113: 11.146 | F113: 55.4259 | G113: 20.3571 | H113: 87.2728 | I113: 100 | J113: 0.334279 | K113: 0.0012321 | L113: 0.995116
A114: Run Original ACO11 | B114: 129.482 | C114: 109.261 | D114: 2.94609 | E114: 10.9564 | F114: 55.5584 | G114: 20.2202 | H114: 84.554 | I114: 100 | J114: 0.334605 | K114: 0.00124211 | L114: 0.995116
... A202: Run Combined Run49 | B202: 103.596 | C202: 83.9112 | D202: 53.4159 | E202: 10.3286 | F202: 0 | G202: 19.6847 | H202: 63.8308 | I202: 100 | J202: 0.425764 | K202: 0.0108569 | L202: 0.955756
A203: Device 0: NVIDIA GeForce RTX 3060 | B203: Max thread in blocks: 1024 Total Global Memory: 12287,4 MB GPU Global Memory Usage: 0,0887489 MB GPU Global Memory Hash Table: 1024 MB Max PARAMETR_SIZE in GPU Global Memory: 5570990 Shared memory per block: 49152 bytes (48 KB) Shared memory per multiprocessor: 102400 bytes (100 KB) Data size in Shared memory per block: 336 bytes (0,328125 KB) Constant Memory: 65536 bytes Parameter data size (in Constant Memory): 1680 bytes (1,64062 KB) Registers per Block: 65536 Warp Size: 32 Compute Capability: 8,6 Can Map Host Memory: Yes Clock Rate: 1777 MHz L2 Cache Size: 2359296 bytes Multiprocessor Count: 28 | C203: Max thread in blocks by axis: (1024, 1024, 64) | D203: Max blocks by axis: (2147483647, 65535, 65535) | E203: PARAMETR_SIZE: 42 | F203: PARAMETR_SIZE_ONE_X: 21 | G203: MAX_VALUE_SIZE: 5 | H203: NAME_FILE_GRAPH: Parametr_Graph/test42,txt | I203: ANT_SIZE: 500 | J203: KOL_ITERATION: 500 | K203: KOL_PROGON_STATISTICS: 50 | L203: PARAMETR_Q: 1 | M203: PARAMETR_RO: 0,999 | N203: TYPE_ACO: 1 | O203: ACOCCyN_KOL_ITERATION: 50, MAX_PARAMETR_VALUE_TO_MIN_OPT: 1, HASH_TABLE_SIZE: 67108864, MAX_PROBES: 10000, MAX_THREAD_CUDA: 512, CPU_RANDOM: 0, KOL_THREAD_CPU_ANT: 12, CONST_RANDOM: 100000, MAX_CONST: 8192, OPTIMIZE: OPTIMIZE_MIN_1 | P203: FUNCTION: SHAFFERA GO_ALG_MINMAX: 1(1, 1000)
A204: Run Original ACO0 | B204: 128.63 | C204: 108.553 | D204: 2.94686 | E204: 11.09 | F204: 55.7242 | G204: 20.0773 | H204: 85.5392 | I204: 100 | J204: 0.33682 | K204: 0.00123009 | L204: 0.995116
A205: Run Original ACO1 | B205: 128.98 | C205: 109.392 | D205: 2.94133 | E205: 11.9017 | F205: 55.727 | G205: 19.5878 | H205: 95.6728 | I205: 100 | J205: 0.335906 | K205: 0.00123029 | L205: 0.995116
A206: Run Original ACO2 | B206: 128.285 | C206: 108.832 | D206: 2.95121 | E206: 11.5593 | F206: 55.7174 | G206: 19.4529 | H206: 90.7588 | I206: 100 | J206: 0.337727 | K206: 0.00123006 | L206: 0.995116
A207: Run Original ACO3 | B207: 128.538 | C207: 108.696 | D207: 2.94904 | E207: 11.2937 | F207: 55.7564 | G207: 19.8418 | H207: 88.16 | I207: 100 | J207: 0.337061 | K207: 0.00123005 | L207: 0.995116
A208: Run Original ACO4 | B208: 129.202 | C208: 109.323 | D208: 2.98203 | E208: 11.1155 | F208: 55.7375 | G208: 19.8788 | H208: 86.4916 | I208: 100 | J208: 0.335328 | K208: 0.00123006 | L208: 0.995116
A209: Run Original ACO5 | B209: 128.362 | C209: 108.5 | D209: 2.95573 | E209: 11.0214 | F209: 55.8492 | G209: 19.8622 | H209: 85.6212 | I209: 100 | J209: 0.337522 | K209: 0.00123006 | L209: 0.995116
A210: Run Original ACO6 | B210: 128.298 | C210: 108.652 | D210: 2.95141 | E210: 10.9778 | F210: 55.7519 | G210: 19.6458 | H210: 84.7816 | I210: 100 | J210: 0.337691 | K210: 0.00123005 | L210: 0.995116
A211: Run Original ACO7 | B211: 128.477 | C211: 108.552 | D211: 2.96382 | E211: 10.9664 | F211: 55.659 | G211: 19.9245 | H211: 84.2652 | I211: 100 | J211: 0.337222 | K211: 0.00123011 | L211: 0.995115
A212: Run Original ACO8 | B212: 128.208 | C212: 108.306 | D212: 2.94619 | E212: 10.9469 | F212: 55.6333 | G212: 19.9016 | H212: 83.9068 | I212: 100 | J212: 0.337929 | K212: 0.00123014 | L212: 0.995116
A213: Run Original ACO9 | B213: 128.244 | C213: 108.432 | D213: 2.96593 | E213: 10.9401 | F213: 55.644 | G213: 19.8121 | H213: 83.5216 | I213: 100 | J213: 0.337834 | K213: 0.00123017 | L213: 0.995116
A214: Run Original ACO10 | B214: 128.141 | C214: 108.495 | D214: 2.95582 | E214: 10.9401 | F214: 55.7666 | G214: 19.6458 | H214: 82.812 | I214: 100 | J214: 0.338104 | K214: 0.00123006 | L214: 0.995116
...

Sheet t84
A1: Device 0: NVIDIA GeForce RTX 3060 | B1: Max thread in blocks: 1024 Total Global Memory: 12287,4 MB GPU Global Memory Usage: 0,173664 MB GPU Global Memory Hash Table: 1024 MB Max PARAMETR_SIZE in GPU Global Memory: 5570990 Shared memory per block: 49152 bytes (48 KB) Shared memory per multiprocessor: 102400 bytes (100 KB) Data size in Shared memory per block: 672 bytes (0,65625 KB) Constant Memory: 65536 bytes Parameter data size (in Constant Memory): 3360 bytes (3,28125 KB) Registers per Block: 65536 Warp Size: 32 Compute Capability: 8,6 Can Map Host Memory: Yes Clock Rate: 1777 MHz L2 Cache Size: 2359296 bytes Multiprocessor Count: 28 | C1: Max thread in blocks by axis: (1024, 1024, 64) | D1: Max blocks by axis: (2147483647, 65535, 65535) | E1: PARAMETR_SIZE: 84 | F1: PARAMETR_SIZE_ONE_X: 21 | G1: MAX_VALUE_SIZE: 5 | H1: NAME_FILE_GRAPH: Parametr_Graph/test84,txt | I1: ANT_SIZE: 500 | J1: KOL_ITERATION: 500 | K1: KOL_PROGON_STATISTICS: 50 | L1: PARAMETR_Q: 1 | M1: PARAMETR_RO: 0,999 | N1: TYPE_ACO: 1 | O1: ACOCCyN_KOL_ITERATION: 50, MAX_PARAMETR_VALUE_TO_MIN_OPT: 1, HASH_TABLE_SIZE: 67108864, MAX_PROBES: 10000, MAX_THREAD_CUDA: 512, CPU_RANDOM: 0, KOL_THREAD_CPU_ANT: 12, CONST_RANDOM: 100000, MAX_CONST: 8192, OPTIMIZE: OPTIMIZE_MIN_1 | P1: FUNCTION: SHAFFERA GO_ALG_MINMAX: 1(1, 1000)
A2: Run Original ACO0 | B2: 150.34 | C2: 130.141 | D2: 3.13073 | E2: 17.9364 | F2: 69.5344 | G2: 20.1987 | H2: 99.3948 | I2: 100 | J2: 0.563974 | K2: 0.0012316 | L2: 0.995116
A3: Run Original ACO1 | B3: 149.678 | C3: 129.893 | D3: 3.11921 | E3: 17.9197 | F3: 69.8922 | G3: 19.7848 | H3: 99.336 | I3: 100 | J3: 0.566466 | K3: 0.0012323 | L3: 0.995116
A4: Run Original ACO2 | B4: 149.232 | C4: 129.293 | D4: 3.10353 | E4: 17.9243 | F4: 69.4924 | G4: 19.9394 | H4: 99.2868 | I4: 100 | J4: 0.568159 | K4: 0.00123061 | L4: 0.995116
A5: Run Original ACO3 | B5: 149.225 | C5: 129.443 | D5: 3.12827 | E5: 17.7961 | F5: 69.4836 | G5: 19.7821 | H5: 99.5904 | I5: 100 | J5: 0.568187 | K5: 0.00123096 | L5: 0.995116
A6: Run Original ACO4 | B6: 149.339 | C6: 129.715 | D6: 3.1083 | E6: 17.7739 | F6: 69.8552 | G6: 19.6247 | H6: 99.7508 | I6: 100 | J6: 0.567751 | K6: 0.00123049 | L6: 0.995116
A7: Run Original ACO5 | B7: 149.636 | C7: 129.804 | D7: 3.09573 | E7: 17.8099 | F7: 69.4572 | G7: 19.8323 | H7: 99.6312 | I7: 100 | J7: 0.566626 | K7: 0.00124341 | L7: 0.995115
A8: Run Original ACO6 | B8: 149.423 | C8: 129.887 | D8: 3.10078 | E8: 17.935 | F8: 69.7051 | G8: 19.5363 | H8: 99.5068 | I8: 100 | J8: 0.567433 | K8: 0.00128626 | L8: 0.995116
A9: Run Original ACO7 | B9: 149.078 | C9: 129.502 | D9: 3.11294 | E9: 17.9352 | F9: 69.8146 | G9: 19.5764 | H9: 99.3884 | I9: 100 | J9: 0.568745 | K9: 0.00123286 | L9: 0.995116
A10: Run Original ACO8 | B10: 149.739 | C10: 130.172 | D10: 3.11429 | E10: 17.9581 | F10: 69.77 | G10: 19.5671 | H10: 99.3832 | I10: 100 | J10: 0.566238 | K10: 0.00124789 | L10: 0.995116
A11: Run Original ACO9 | B11: 149.777 | C11: 130.185 | D11: 3.12341 | E11: 17.9738 | F11: 69.7596 | G11: 19.5917 | H11: 99.296 | I11: 100 | J11: 0.566093 | K11: 0.00128027 | L11: 0.995116
A12: Run Original ACO10 | B12: 160.262 | C12: 136.414 | D12: 3.11045 | E12: 17.9699 | F12: 69.7928 | G12: 23.8479 | H12: 99.272 | I12: 100 | J12: 0.529056 | K12: 0.00125238 | L12: 0.995115
A13: Run Original ACO11 | B13: 149.559 | C13: 129.851 | D13: 3.11121 | E13: 18.0048 | F13: 69.6191 | G13: 19.7074 | H13: 99.1816 | I13: 100 | J13: 0.566919 | K13: 0.00123027 | L13: 0.995116
... A101: Run Combined Run49 | B101: 117.003 | C101: 96.8939 | D101: 59.6286 | E101: 17.8635 | F101: 0 | G101: 20.109 | H101: 98.3284 | I101: 100 | J101: 0.738035 | K101: 0.0108569 | L101: 0.995114
A102: Device 0: NVIDIA GeForce RTX 3060 | B102: Max thread in blocks: 1024 Total Global Memory: 12287,4 MB GPU Global Memory Usage: 0,173664 MB GPU Global Memory Hash Table: 1024 MB Max PARAMETR_SIZE in GPU Global Memory: 5570990 Shared memory per block: 49152 bytes (48 KB) Shared memory per multiprocessor: 102400 bytes (100 KB) Data size in Shared memory per block: 672 bytes (0,65625 KB) Constant Memory: 65536 bytes Parameter data size (in Constant Memory): 3360 bytes (3,28125 KB) Registers per Block: 65536 Warp Size: 32 Compute Capability: 8,6 Can Map Host Memory: Yes Clock Rate: 1777 MHz L2 Cache Size: 2359296 bytes Multiprocessor Count: 28 | C102: Max thread in blocks by axis: (1024, 1024, 64) | D102: Max blocks by axis: (2147483647, 65535, 65535) | E102: PARAMETR_SIZE: 84 | F102: PARAMETR_SIZE_ONE_X: 21 | G102: MAX_VALUE_SIZE: 5 | H102: NAME_FILE_GRAPH: Parametr_Graph/test84,txt | I102: ANT_SIZE: 500 | J102: KOL_ITERATION: 500 | K102: KOL_PROGON_STATISTICS: 50 | L102: PARAMETR_Q: 1 | M102: PARAMETR_RO: 0,999 | N102: TYPE_ACO: 1 | O102: ACOCCyN_KOL_ITERATION: 50, MAX_PARAMETR_VALUE_TO_MIN_OPT: 1, HASH_TABLE_SIZE: 67108864, MAX_PROBES: 10000, MAX_THREAD_CUDA: 512, CPU_RANDOM: 0, KOL_THREAD_CPU_ANT: 12, CONST_RANDOM: 100000, MAX_CONST: 8192, OPTIMIZE: OPTIMIZE_MIN_1 | P102: FUNCTION: SHAFFERA GO_ALG_MINMAX: 1(1, 1000)
A103: Run Original ACO0 | B103: 148.873 | C103: 129.168 | D103: 3.11118 | E103: 18.2417 | F103: 68.708 | G103: 19.705 | H103: 99.744 | I103: 100 | J103: 0.569531 | K103: 0.00128901 | L103: 0.995116
A104: Run Original ACO1 | B104: 148.525 | C104: 128.628 | D104: 3.09662 | E104: 18.2532 | F104: 68.5734 | G104: 19.8965 | H104: 99.9324 | I104: 100 | J104: 0.570865 | K104: 0.00259363 | L104: 0.995098
A105: Run Original ACO2 | B105: 148.464 | C105: 128.714 | D105: 3.10779 | E105: 18.2551 | F105: 68.675 | G105: 19.7498 | H105: 99.858 | I105: 100 | J105: 0.571099 | K105: 0.00217169 | L105: 0.995115
A106: Run Original ACO3 | B106: 148.62 | C106: 129.154 | D106: 3.09089 | E106: 18.2547 | F106: 68.8133 | G106: 19.4662 | H106: 99.7796 | I106: 100 | J106: 0.570499 | K106: 0.00128656 | L106: 0.995102
A107: Run Original ACO4 | B107: 148.55 | C107: 128.735 | D107: 3.10078 | E107: 18.2814 | F107: 68.5978 | G107: 19.815 | H107: 99.74 | I107: 100 | J107: 0.570767 | K107: 0.0017453 | L107: 0.995112
A108: Run Original ACO5 | B108: 148.77 | C108: 129.057 | D108: 3.09393 | E108: 18.2727 | F108: 68.7693 | G108: 19.7128 | H108: 99.6704 | I108: 100 | J108: 0.569926 | K108: 0.00150226 | L108: 0.995068
A109: Run Original ACO6 | B109: 152.536 | C109: 131.508 | D109: 3.14856 | E109: 18.344 | F109: 68.9734 | G109: 21.0281 | H109: 99.668 | I109: 100 | J109: 0.555854 | K109: 0.00230751 | L109: 0.995064
A110: Run Original ACO7 | B110: 151.231 | C110: 130.365 | D110: 3.11528 | E110: 18.26 | F110: 68.698 | G110: 20.8662 | H110: 99.6404 | I110: 100 | J110: 0.560648 | K110: 0.00665858 | L110: 0.995103
A111: Run Original ACO8 | B111: 148.826 | C111: 128.979 | D111: 3.09777 | E111: 18.2708 | F111: 68.845 | G111: 19.8473 | H111: 99.6112 | I111: 100 | J111: 0.56971 | K111: 0.00310624 | L111: 0.995116
A112: Run Original ACO9 | B112: 148.842 | C112: 129.116 | D112: 3.1011 | E112: 18.2984 | F112: 68.6933 | G112: 19.7255 | H112: 99.62 | I112: 100 | J112: 0.569649 | K112: 0.0108576 | L112: 0.995116
A113: Run Original ACO10 | B113: 149.172 | C113: 129.562 | D113: 3.09125 | E113: 18.3333 | F113: 68.7143 | G113: 19.6099 | H113: 99.56 | I113: 100 | J113: 0.568388 | K113: 0.0108569 | L113: 0.9951
A114: Run Original ACO11 | B114: 148.901 | C114: 129.137 | D114: 3.09963 | E114: 18.2878 | F114: 68.6091 | G114: 19.7639 | H114: 99.5904 | I114: 100 | J114: 0.569424 | K114: 0.0108569 | L114: 0.995112
... A202: Run Combined Run49 | B202: 117.952 | C202: 98.0906 | D202: 59.4877 | E202: 18.5245 | F202: 0 | G202: 19.8612 | H202: 99.498 | I202: 100 | J202: 0.732098 | K202: 0.0108737 | L202: 0.981019
A203: Device 0: NVIDIA GeForce RTX 3060 | B203: Max thread in blocks: 1024 Total Global Memory: 12287,4 MB GPU Global Memory Usage: 0,173664 MB GPU Global Memory Hash Table: 1024 MB Max PARAMETR_SIZE in GPU Global Memory: 5570990 Shared memory per block: 49152 bytes (48 KB) Shared memory per multiprocessor: 102400 bytes (100 KB) Data size in Shared memory per block: 672 bytes (0,65625 KB) Constant Memory: 65536 bytes Parameter data size (in Constant Memory): 3360 bytes (3,28125 KB) Registers per Block: 65536 Warp Size: 32 Compute Capability: 8,6 Can Map Host Memory: Yes Clock Rate: 1777 MHz L2 Cache Size: 2359296 bytes Multiprocessor Count: 28 | C203: Max thread in blocks by axis: (1024, 1024, 64) | D203: Max blocks by axis: (2147483647, 65535, 65535) | E203: PARAMETR_SIZE: 84 | F203: PARAMETR_SIZE_ONE_X: 21 | G203: MAX_VALUE_SIZE: 5 | H203: NAME_FILE_GRAPH: Parametr_Graph/test84,txt | I203: ANT_SIZE: 500 | J203: KOL_ITERATION: 500 | K203: KOL_PROGON_STATISTICS: 50 | L203: PARAMETR_Q: 1 | M203: PARAMETR_RO: 0,999 | N203: TYPE_ACO: 1 | O203: ACOCCyN_KOL_ITERATION: 50, MAX_PARAMETR_VALUE_TO_MIN_OPT: 1, HASH_TABLE_SIZE: 67108864, MAX_PROBES: 10000, MAX_THREAD_CUDA: 512, CPU_RANDOM: 0, KOL_THREAD_CPU_ANT: 12, CONST_RANDOM: 100000, MAX_CONST: 8192, OPTIMIZE: OPTIMIZE_MIN_1 | P203: FUNCTION: SHAFFERA GO_ALG_MINMAX: 1(1, 1000)
A204: Run Original ACO0 | B204: 148.637 | C204: 128.922 | D204: 3.09928 | E204: 18.2679 | F204: 68.7102 | G204: 19.7151 | H204: 99.742 | I204: 100 | J204: 0.570433 | K204: 0.00125258 | L204: 0.995115
A205: Run Original ACO1 | B205: 148.601 | C205: 128.828 | D205: 3.09182 | E205: 18.2562 | F205: 68.5826 | G205: 19.7726 | H205: 99.6876 | I205: 100 | J205: 0.570573 | K205: 0.00130441 | L205: 0.995115
A206: Run Original ACO2 | B206: 149.031 | C206: 129.158 | D206: 3.09777 | E206: 18.2542 | F206: 68.6004 | G206: 19.8725 | H206: 99.6172 | I206: 100 | J206: 0.568928 | K206: 0.00123029 | L206: 0.995094
A207: Run Original ACO3 | B207: 148.838 | C207: 129.317 | D207: 3.09345 | E207: 18.2727 | F207: 68.922 | G207: 19.5217 | H207: 99.608 | I207: 100 | J207: 0.569663 | K207: 0.00123013 | L207: 0.995115
A208: Run Original ACO4 | B208: 148.918 | C208: 129.167 | D208: 3.09358 | E208: 18.297 | F208: 68.6832 | G208: 19.7506 | H208: 99.568 | I208: 100 | J208: 0.569358 | K208: 0.00191867 | L208: 0.995115
A209: Run Original ACO5 | B209: 148.669 | C209: 128.837 | D209: 3.09147 | E209: 18.2956 | F209: 68.6774 | G209: 19.8317 | H209: 99.5412 | I209: 100 | J209: 0.570312 | K209: 0.00160429 | L209: 0.995116
A210: Run Original ACO6 | B210: 164.044 | C210: 138.682 | D210: 3.11144 | E210: 18.3047 | F210: 68.9189 | G210: 25.3621 | H210: 99.4688 | I210: 100 | J210: 0.51686 | K210: 0.0012326 | L210: 0.995116
A211: Run Original ACO7 | B211: 149.319 | C211: 129.517 | D211: 3.09733 | E211: 18.3081 | F211: 68.7851 | G211: 19.8022 | H211: 99.4416 | I211: 100 | J211: 0.56783 | K211: 0.001299 | L211: 0.995116
A212: Run Original ACO8 | B212: 149.133 | C212: 129.529 | D212: 3.11153 | E212: 18.3045 | F212: 68.7728 | G212: 19.6042 | H212: 99.4176 | I212: 100 | J212: 0.568536 | K212: 0.00130447 | L212: 0.995114
A213: Run Original ACO9 | B213: 148.45 | C213: 128.689 | D213: 3.09317 | E213: 18.3379 | F213: 68.5278 | G213: 19.761 | H213: 99.4308 | I213: 100 | J213: 0.571155 | K213: 0.00141646 | L213: 0.995108
A214: Run Original ACO10 | B214: 149.119 | C214: 129.319 | D214: 3.09352 | E214: 18.3044 | F214: 68.786 | G214: 19.8006 | H214: 99.3648 | I214: 100 | J214: 0.568589 | K214: 0.00146344 | L214: 0.995115
...

Sheet t168
A1: Device 0: NVIDIA GeForce RTX 3060 | B1: Max thread in blocks: 1024 Total Global Memory: 12287,4 MB GPU Global Memory Usage: 0,343494 MB GPU Global Memory Hash Table: 1024 MB Max PARAMETR_SIZE in GPU Global Memory: 5570990 Shared memory per block: 49152 bytes (48 KB) Shared memory per multiprocessor: 102400 bytes (100 KB) Data size in Shared memory per block: 1344 bytes (1,3125 KB) Constant Memory: 65536 bytes Parameter data size (in Constant Memory): 6720 bytes (6,5625 KB) Registers per Block: 65536 Warp Size: 32 Compute Capability: 8,6 Can Map Host Memory: Yes Clock Rate: 1777 MHz L2 Cache Size: 2359296 bytes Multiprocessor Count: 28 | C1: Max thread in blocks by axis: (1024, 1024, 64) | D1: Max blocks by axis: (2147483647, 65535, 65535) | E1: PARAMETR_SIZE: 168 | F1: PARAMETR_SIZE_ONE_X: 21 | G1: MAX_VALUE_SIZE: 5 | H1: NAME_FILE_GRAPH: Parametr_Graph/test168,txt | I1: ANT_SIZE: 500 | J1: KOL_ITERATION: 500 | K1: KOL_PROGON_STATISTICS: 50 | L1: PARAMETR_Q: 1 | M1: PARAMETR_RO: 0,999 | N1: TYPE_ACO: 1 | O1: ACOCCyN_KOL_ITERATION: 50, MAX_PARAMETR_VALUE_TO_MIN_OPT: 1, HASH_TABLE_SIZE: 67108864, MAX_PROBES: 10000, MAX_THREAD_CUDA: 512, CPU_RANDOM: 0, KOL_THREAD_CPU_ANT: 12, CONST_RANDOM: 100000, MAX_CONST: 8192, OPTIMIZE: OPTIMIZE_MIN_1 | P1: FUNCTION: SHAFFERA GO_ALG_MINMAX: 1(1, 1000)
A2: Run Original ACO0 | B2: 188.314 | C2: 168.521 | D2: 3.95771 | E2: 31.4536 | F2: 94.0566 | G2: 19.7933 | H2: 99.9804 | I2: 100 | J2: 0.890599 | K2: 0.0123252 | L2: 0.98101
A3: Run Original ACO1 | B3: 188.101 | C3: 168.3 | D3: 3.98216 | E3: 31.2743 | F3: 94.5263 | G3: 19.8012 | H3: 99.9856 | I3: 100 | J3: 0.89161 | K3: 0.0199395 | L3: 0.986967
A4: Run Original ACO2 | B4: 188.103 | C4: 168.423 | D4: 3.96231 | E4: 31.1981 | F4: 94.6153 | G4: 19.6803 | H4: 99.9844 | I4: 100 | J4: 0.891598 | K4: 0.0110661 | L4: 0.980996
A5: Run Original ACO3 | B5: 187.96 | C5: 168.262 | D5: 3.95553 | E5: 31.1995 | F5: 94.633 | G5: 19.6988 | H5: 99.9816 | I5: 100 | J5: 0.892276 | K5: 0.0162082 | L5: 0.981017
A6: Run Original ACO4 | B6: 187.729 | C6: 168.102 | D6: 3.95566 | E6: 31.1527 | F6: 94.4528 | G6: 19.6276 | H6: 99.9784 | I6: 100 | J6: 0.893375 | K6: 0.010864 | L6: 0.981016
A7: Run Original ACO5 | B7: 187.599 | C7: 167.846 | D7: 3.95838 | E7: 31.1069 | F7: 94.1361 | G7: 19.7531 | H7: 99.9824 | I7: 100 | J7: 0.893995 | K7: 0.0125582 | L7: 0.984009
A8: Run Original ACO6 | B8: 187.625 | C8: 167.77 | D8: 3.95147 | E8: 31.0366 | F8: 94.1581 | G8: 19.8555 | H8: 99.98 | I8: 100 | J8: 0.89387 | K8: 0.0117452 | L8: 0.981019
A9: Run Original ACO7 | B9: 187.902 | C9: 168.353 | D9: 3.94961 | E9: 30.8358 | F9: 94.7488 | G9: 19.5494 | H9: 99.9792 | I9: 100 | J9: 0.892554 | K9: 0.0112904 | L9: 0.981019
A10: Run Original ACO8 | B10: 188.883 | C10: 168.676 | D10: 3.99246 | E10: 30.8168 | F10: 94.1942 | G10: 20.2074 | H10: 99.974 | I10: 100 | J10: 0.887917 | K10: 0.0111078 | L10: 0.981016
A11: Run Original ACO9 | B11: 187.49 | C11: 167.947 | D11: 3.97553 | E11: 30.8359 | F11: 94.3375 | G11: 19.543 | H11: 99.9848 | I11: 100 | J11: 0.894514 | K11: 0.0112181 | L11: 0.981011
A12: Run Original ACO10 | B12: 188.126 | C12: 168.432 | D12: 3.95035 | E12: 30.821 | F12: 94.3255 | G12: 19.6944 | H12: 99.9856 | I12: 100 | J12: 0.891489 | K12: 0.0109547 | L12: 0.981017
A13: Run Original ACO11 | B13: 187.537 | C13: 168.042 | D13: 3.97608 | E13: 30.7253 | F13: 94.6385 | G13: 19.4947 | H13: 99.9708 | I13: 100 | J13: 0.894291 | K13: 0.0112503 | L13: 0.981019
... A101: Run Combined Run49 | B101: 142.27 | C101: 122.246 | D101: 72.3526 | E101: 30.1298 | F101: 0 | G101: 20.0241 | H101: 99.976 | I101: 100 | J101: 1.20083 | K101: 0.0108727 | L101: 0.994851
A102: Device 0: NVIDIA GeForce RTX 3060 | B102: Max thread in blocks: 1024 Total Global Memory: 12287,4 MB GPU Global Memory Usage: 0,343494 MB GPU Global Memory Hash Table: 1024 MB Max PARAMETR_SIZE in GPU Global Memory: 5570990 Shared memory per block: 49152 bytes (48 KB) Shared memory per multiprocessor: 102400 bytes (100 KB) Data size in Shared memory per block: 1344 bytes (1,3125 KB) Constant Memory: 65536 bytes Parameter data size (in Constant Memory): 6720 bytes (6,5625 KB) Registers per Block: 65536 Warp Size: 32 Compute Capability: 8,6 Can Map Host Memory: Yes Clock Rate: 1777 MHz L2 Cache Size: 2359296 bytes Multiprocessor Count: 28 | C102: Max thread in blocks by axis: (1024, 1024, 64) | D102: Max blocks by axis: (2147483647, 65535, 65535) | E102: PARAMETR_SIZE: 168 | F102: PARAMETR_SIZE_ONE_X: 21 | G102: MAX_VALUE_SIZE: 5 | H102: NAME_FILE_GRAPH: Parametr_Graph/test168,txt | I102: ANT_SIZE: 500 | J102: KOL_ITERATION: 500 | K102: KOL_PROGON_STATISTICS: 50 | L102: PARAMETR_Q: 1 | M102: PARAMETR_RO: 0,999 | N102: TYPE_ACO: 1 | O102: ACOCCyN_KOL_ITERATION: 50, MAX_PARAMETR_VALUE_TO_MIN_OPT: 1, HASH_TABLE_SIZE: 67108864, MAX_PROBES: 10000, MAX_THREAD_CUDA: 512, CPU_RANDOM: 0, KOL_THREAD_CPU_ANT: 12, CONST_RANDOM: 100000, MAX_CONST: 8192, OPTIMIZE: OPTIMIZE_MIN_1 | P102: FUNCTION: SHAFFERA GO_ALG_MINMAX: 1(1, 1000)
A103: Run Original ACO0 | B103: 186.881 | C103: 167.176 | D103: 3.99438 | E103: 29.7188 | F103: 94.1033 | G103: 19.7052 | H103: 99.9588 | I103: 100 | J103: 0.89743 | K103: 0.0290377 | L103: 0.98067
A104: Run Original ACO1 | B104: 186.033 | C104: 166.43 | D104: 4.02209 | E104: 29.7212 | F104: 94.1068 | G104: 19.6024 | H104: 99.968 | I104: 100 | J104: 0.901522 | K104: 0.0290408 | L104: 0.980882
A105: Run Original ACO2 | B105: 186.187 | C105: 166.436 | D105: 4.00222 | E105: 29.7178 | F105: 93.9582 | G105: 19.7519 | H105: 99.9552 | I105: 100 | J105: 0.900773 | K105: 0.0290422 | L105: 0.981019
A106: Run Original ACO3 | B106: 186.688 | C106: 167.208 | D106: 3.99886 | E106: 29.743 | F106: 94.1591 | G106: 19.4808 | H106: 99.9488 | I106: 100 | J106: 0.898355 | K106: 0.0110147 | L106: 0.980709
A107: Run Original ACO4 | B107: 186.222 | C107: 166.38 | D107: 4.01361 | E107: 29.7005 | F107: 93.7102 | G107: 19.8427 | H107: 99.9452 | I107: 100 | J107: 0.900604 | K107: 0.0112818 | L107: 0.980688
A108: Run Original ACO5 | B108: 186.168 | C108: 166.461 | D108: 4.0091 | E108: 29.7398 | F108: 94.1896 | G108: 19.7072 | H108: 99.9284 | I108: 100 | J108: 0.900865 | K108: 0.0113026 | L108: 0.980411
A109: Run Original ACO6 | B109: 189.058 | C109: 168.596 | D109: 4.02042 | E109: 29.7394 | F109: 93.9321 | G109: 20.4625 | H109: 99.9512 | I109: 100 | J109: 0.887095 | K109: 0.02904 | L109: 0.979393
A110: Run Original ACO7 | B110: 187.401 | C110: 166.874 | D110: 4.00747 | E110: 29.7403 | F110: 93.6888 | G110: 20.5268 | H110: 99.95 | I110: 100 | J110: 0.894938 | K110: 0.0290507 | L110: 0.980918
A111: Run Original ACO8 | B111: 186.161 | C111: 166.718 | D111: 3.99457 | E111: 29.6921 | F111: 94.1476 | G111: 19.4434 | H111: 99.9452 | I111: 100 | J111: 0.900899 | K111: 0.0123733 | L111: 0.980238
A112: Run Original ACO9 | B112: 187.198 | C112: 167.22 | D112: 4.01543 | E112: 29.7318 | F112: 93.9774 | G112: 19.9775 | H112: 99.9156 | I112: 100 | J112: 0.895911 | K112: 0.0290377 | L112: 0.985254
A113: Run Original ACO10 | B113: 186.255 | C113: 166.545 | D113: 3.98225 | E113: 29.7234 | F113: 94.1854 | G113: 19.7101 | H113: 99.9272 | I113: 100 | J113: 0.900446 | K113: 0.0201651 | L113: 0.980443
A114: Run Original ACO11 | B114: 185.954 | C114: 166.537 | D114: 4.00698 | E114: 29.7238 | F114: 93.8737 | G114: 19.4169 | H114: 99.9168 | I114: 100 | J114: 0.901902 | K114: 0.0290735 | L114: 0.98098
... A202: Run Combined Run49 | B202: 141.084 | C202: 121.158 | D202: 71.5447 | E202: 30.1853 | F202: 0 | G202: 19.9262 | H202: 99.9276 | I202: 100 | J202: 1.21092 | K202: 0.0127048 | L202: 0.981016
A203: Device 0: NVIDIA GeForce RTX 3060 | B203: Max thread in blocks: 1024 Total Global Memory: 12287,4 MB GPU Global Memory Usage: 0,343494 MB GPU Global Memory Hash Table: 1024 MB Max PARAMETR_SIZE in GPU Global Memory: 5570990 Shared memory per block: 49152 bytes (48 KB) Shared memory per multiprocessor: 102400 bytes (100 KB) Data size in Shared memory per block: 1344 bytes (1,3125 KB) Constant Memory: 65536 bytes Parameter data size (in Constant Memory): 6720 bytes (6,5625 KB) Registers per Block: 65536 Warp Size: 32 Compute Capability: 8,6 Can Map Host Memory: Yes Clock Rate: 1777 MHz L2 Cache Size: 2359296 bytes Multiprocessor Count: 28 | C203: Max thread in blocks by axis: (1024, 1024, 64) | D203: Max blocks by axis: (2147483647, 65535, 65535) | E203: PARAMETR_SIZE: 168 | F203: PARAMETR_SIZE_ONE_X: 21 | G203: MAX_VALUE_SIZE: 5 | H203: NAME_FILE_GRAPH: Parametr_Graph/test168,txt | I203: ANT_SIZE: 500 | J203: KOL_ITERATION: 500 | K203: KOL_PROGON_STATISTICS: 50 | L203: PARAMETR_Q: 1 | M203: PARAMETR_RO: 0,999 | N203: TYPE_ACO: 1 | O203: ACOCCyN_KOL_ITERATION: 50, MAX_PARAMETR_VALUE_TO_MIN_OPT: 1, HASH_TABLE_SIZE: 67108864, MAX_PROBES: 10000, MAX_THREAD_CUDA: 512, CPU_RANDOM: 0, KOL_THREAD_CPU_ANT: 12, CONST_RANDOM: 100000, MAX_CONST: 8192, OPTIMIZE: OPTIMIZE_MIN_1 | P203: FUNCTION: SHAFFERA GO_ALG_MINMAX: 1(1, 1000)
A204: Run Original ACO0 | B204: 187.402 | C204: 167.545 | D204: 4.04558 | E204: 29.9594 | F204: 94.4852 | G204: 19.8571 | H204: 99.9468 | I204: 100 | J204: 0.894932 | K204: 0.0291083 | L204: 0.980977
A205: Run Original ACO1 | B205: 187.487 | C205: 168.144 | D205: 4.04747 | E205: 29.9615 | F205: 94.8862 | G205: 19.343 | H205: 99.9396 | I205: 100 | J205: 0.89453 | K205: 0.0290414 | L205: 0.981018
A206: Run Original ACO2 | B206: 187.77 | C206: 167.784 | D206: 4.05956 | E206: 29.9345 | F206: 94.466 | G206: 19.986 | H206: 99.9304 | I206: 100 | J206: 0.893181 | K206: 0.0290402 | L206: 0.980777
A207: Run Original ACO3 | B207: 187.808 | C207: 167.866 | D207: 4.05822 | E207: 29.9466 | F207: 94.467 | G207: 19.9417 | H207: 99.9184 | I207: 100 | J207: 0.893001 | K207: 0.0149624 | L207: 0.981018
A208: Run Original ACO4 | B208: 187.337 | C208: 167.494 | D208: 4.05105 | E208: 29.9597 | F208: 94.4307 | G208: 19.8431 | H208: 99.9328 | I208: 100 | J208: 0.895245 | K208: 0.0138767 | L208: 0.981001
A209: Run Original ACO5 | B209: 187.229 | C209: 167.338 | D209: 4.03502 | E209: 29.998 | F209: 94.5373 | G209: 19.8914 | H209: 99.9768 | I209: 100 | J209: 0.89576 | K209: 0.0290417 | L209: 0.980462
A210: Run Original ACO6 | B210: 187.793 | C210: 167.798 | D210: 4.06279 | E210: 29.9353 | F210: 94.4688 | G210: 19.9944 | H210: 99.9548 | I210: 100 | J210: 0.893072 | K210: 0.0149918 | L210: 0.980789
A211: Run Original ACO7 | B211: 187.58 | C211: 168.083 | D211: 4.04747 | E211: 29.9428 | F211: 95.0223 | G211: 19.4974 | H211: 99.9404 | I211: 100 | J211: 0.894086 | K211: 0.0168791 | L211: 0.980993
A212: Run Original ACO8 | B212: 187.366 | C212: 167.675 | D212: 4.03393 | E212: 29.967 | F212: 94.8414 | G212: 19.691 | H212: 99.9392 | I212: 100 | J212: 0.895108 | K212: 0.0120237 | L212: 0.981014
A213: Run Original ACO9 | B213: 187.261 | C213: 167.369 | D213: 4.05454 | E213: 29.9296 | F213: 94.5037 | G213: 19.8914 | H213: 99.922 | I213: 100 | J213: 0.89561 | K213: 0.018114 | L213: 0.980808
A214: Run Original ACO10 | B214: 187.118 | C214: 167.272 | D214: 4.05086 | E214: 29.9442 | F214: 94.4876 | G214: 19.8458 | H214: 99.9384 | I214: 100 | J214: 0.896292 | K214: 0.0145739 | L214: 0.984555
...

Sheet t336
