Workbook

Sheet Itog
E1: 42 | F1: =E1*2 -> 84 | G1: =F1*2 -> 168 | H1: =G1*2 -> 336 | I1: =H1*2 -> 672 | J1: =I1*2 -> 1344 | K1: =J1*2 -> 2688 | L1: =K1*2 -> 5376 | M1: =L1*2 -> 10752 | ... U1: =T1*2 -> 2752512 | X1: 1 | Y1: << "Time=" << metrics.total_time_ms << "ms "
B2: 1 | D2: 50 | E2: 0 | F2: 49 | J2: const | L2: shared | X2: 2 | Y2: << "Kernel=" << metrics.kernel_time_ms << "ms "
B3: 42clangOMP31 | D3: 1 | E3: 1 | X3: 3 | Y3: << "Probabilities=" << metrics.computeProbabilities_time_ms << "ms "
A4: 0 | B4: 1 | C4: 16 | D4: =OFFSET('t42'!$A$1,$B$2+($B4-1)*$D$2+$A4,D$3) -> 56.3141 | E4: =AVERAGE(OFFSET('t42'!$A$1,$B$2+($B4-1)*$D$2+$E$2+$A4,E$3):OFFSET('t42'!$A$1,$B$2+($B4-1)*$D$2+$E$2+$F$2+$A4,E$3)) -> 47.154472 | F4: =AVERAGE(OFFSET('t84'!$A$1,$B$2+($B4-1)*$D$2+$E$2+$A4,E$3):OFFSET('t84'!$A$1,$B$2+($B4-1)*$D$2+$E$2+$F$2+$A4,E$3)) -> 62.285718 | G4: =AVERAGE(OFFSET('t168'!$A$1,$B$2+($B4-1)*$D$2+$E$2+$A4,E$3):OFFSET('t168'!$A$1,$B$2+($B4-1)*$D$2+$E$2+$F$2+$A4,E$3)) -> 115.20932 | H4: =AVERAGE(OFFSET('t336'!$A$1,$B$2+($B4-1)*$D$2+$E$2+$A4,E$3):OFFSET('t336'!$A$1,$B$2+($B4-1)*$D$2+$E$2+$F$2+$A4,E$3)) -> 133.81526 | I4: =AVERAGE(OFFSET('t672'!$A$1,$B$2+($B4-1)*$D$2+$E$2+$A4,E$3):OFFSET('t672'!$A$1,$B$2+($B4-1)*$D$2+$E$2+$F$2+$A4,E$3)) -> 170.0248 | J4: =AVERAGE(OFFSET('t1344'!$A$1,$B$2+($B4-1)*$D$2+$E$2+$A4,E$3):OFFSET('t1344'!$A$1,$B$2+($B4-1)*$D$2+$E$2+$F$2+$A4,E$3)) -> 231.86086 | K4: =AVERAGE(OFFSET('t2688'!$A$1,$B$2+($B4-1)*$D$2+$E$2+$A4,E$3):OFFSET('t2688'!$A$1,$B$2+($B4-1)*$D$2+$E$2+$F$2+$A4,E$3)) -> 357.8891 | L4: =AVERAGE(OFFSET('t5376'!$A$1,$B$2+($B4-1)*$D$2+$E$2+$A4,E$3):OFFSET('t5376'!$A$1,$B$2+($B4-1)*$D$2+$E$2+$F$2+$A4,E$3)) -> 669.12722 | M4: =AVERAGE(OFFSET('t10752'!$A$1,$B$2+($B4-1)*$D$2+$E$2+$A4,E$3):OFFSET('t10752'!$A$1,$B$2+($B4-1)*$D$2+$E$2+$F$2+$A4,E$3)) -> 1507.3066 | N4: =AVERAGE(OFFSET('t21504'!$A$1,$B$2+($B4-1)*$D$2+$E$2+$A4,E$3):OFFSET('t21504'!$A$1,$B$2+($B4-1)*$D$2+$E$2+$F$2+$A4,E$3)) -> 3650.4502 | O4: =AVERAGE(OFFSET('t43008'!$A$1,$B$2+($B4-1)*$D$2+$E$2+$A4,E$3):OFFSET('t43008'!$A$1,$B$2+($B4-1)*$D$2+$E$2+$F$2+$A4,E$3)) -> 8818.8636 | P4: =AVERAGE(OFFSET('t86016'!$A$1,$B$2+($B4-1)*$D$2+$E$2+$A4,E$3):OFFSET('t86016'!$A$1,$B$2+($B4-1)*$D$2+$E$2+$F$2+$A4,E$3)) -> 18806.928 | Q4: =AVERAGE(OFFSET('t172032'!$A$1,$B$2+($B4-1)*$D$2+$E$2+$A4,E$3):OFFSET('t172032'!$A$1,$B$2+($B4-1)*$D$2+$E$2+$F$2+$A4,E$3)) -> 37713.192 | R4: =AVERAGE(OFFSET('t344064'!$A$1,$B$2+($B4-1)*$D$2+$E$2+$A4,E$3):OFFSET('t344064'!$A$1,$B$2+($B4-1)*$D$2+$E$2+$F$2+$A4,E$3)) -> #DIV/0! | S4: =AVERAGE(OFFSET('t688128'!$A$1,$B$2+($B4-1)*$D$2+$E$2+$A4,E$3):OFFSET('t688128'!$A$1,$B$2+($B4-1)*$D$2+$E$2+$F$2+$A4,E$3)) -> #DIV/0! | T4: =AVERAGE(OFFSET(t1376256!$A$1,$B$2+($B4-1)*$D$2+$E$2+$A4,E$3):OFFSET(t1376256!$A$1,$B$2+($B4-1)*$D$2+$E$2+$F$2+$A4,E$3)) -> #DIV/0! | X4: 4 | Y4: << "Ant=" << metrics.antColonyOptimization_time_ms << "ms "
A5: 0 | B5: 2 | D5: =OFFSET('t42'!$A$1,$B$2+($B5-1)*$D$2+$A4,D$3) -> 47.392 | E5: =AVERAGE(OFFSET('t42'!$A$1,$B$2+($B5-1)*$D$2+$E$2+$A4+1,E$3):OFFSET('t42'!$A$1,$B$2+($B5-1)*$D$2+$E$2+$F$2+$A4,E$3)) -> 47.377951 | F5: =AVERAGE(OFFSET('t84'!$A$1,$B$2+($B5-1)*$D$2+$E$2+$A4+1,E$3):OFFSET('t84'!$A$1,$B$2+($B5-1)*$D$2+$E$2+$F$2+$A4,E$3)) -> 63.860014 | G5: =AVERAGE(OFFSET('t168'!$A$1,$B$2+($B5-1)*$D$2+$E$2+$A4+1,E$3):OFFSET('t168'!$A$1,$B$2+($B5-1)*$D$2+$E$2+$F$2+$A4,E$3)) -> 119.24151 | H5: =AVERAGE(OFFSET('t336'!$A$1,$B$2+($B5-1)*$D$2+$E$2+$A4+1,E$3):OFFSET('t336'!$A$1,$B$2+($B5-1)*$D$2+$E$2+$F$2+$A4,E$3)) -> 143.69594 | I5: =AVERAGE(OFFSET('t672'!$A$1,$B$2+($B5-1)*$D$2+$E$2+$A4+1,E$3):OFFSET('t672'!$A$1,$B$2+($B5-1)*$D$2+$E$2+$F$2+$A4,E$3)) -> 177.45671 | J5: =AVERAGE(OFFSET('t1344'!$A$1,$B$2+($B5-1)*$D$2+$E$2+$A4+1,E$3):OFFSET('t1344'!$A$1,$B$2+($B5-1)*$D$2+$E$2+$F$2+$A4,E$3)) -> 234.53257 | K5: =AVERAGE(OFFSET('t2688'!$A$1,$B$2+($B5-1)*$D$2+$E$2+$A4+1,E$3):OFFSET('t2688'!$A$1,$B$2+($B5-1)*$D$2+$E$2+$F$2+$A4,E$3)) -> 361.24855 | L5: =AVERAGE(OFFSET('t5376'!$A$1,$B$2+($B5-1)*$D$2+$E$2+$A4+1,E$3):OFFSET('t5376'!$A$1,$B$2+($B5-1)*$D$2+$E$2+$F$2+$A4,E$3)) -> 673.17743 | M5: =AVERAGE(OFFSET('t10752'!$A$1,$B$2+($B5-1)*$D$2+$E$2+$A4+1,E$3):OFFSET('t10752'!$A$1,$B$2+($B5-1)*$D$2+$E$2+$F$2+$A4,E$3)) -> 1514.8122 | N5: =AVERAGE(OFFSET('t21504'!$A$1,$B$2+($B5-1)*$D$2+$E$2+$A4+1,E$3):OFFSET('t21504'!$A$1,$B$2+($B5-1)*$D$2+$E$2+$F$2+$A4,E$3)) -> 3652.3396 | O5: =AVERAGE(OFFSET('t43008'!$A$1,$B$2+($B5-1)*$D$2+$E$2+$A4+1,E$3):OFFSET('t43008'!$A$1,$B$2+($B5-1)*$D$2+$E$2+$F$2+$A4,E$3)) -> 8828.0292 | P5: =AVERAGE(OFFSET('t86016'!$A$1,$B$2+($B5-1)*$D$2+$E$2+$A4+1,E$3):OFFSET('t86016'!$A$1,$B$2+($B5-1)*$D$2+$E$2+$F$2+$A4,E$3)) -> 18797.545 | Q5: =AVERAGE(OFFSET('t172032'!$A$1,$B$2+($B5-1)*$D$2+$E$2+$A4+1,E$3):OFFSET('t172032'!$A$1,$B$2+($B5-1)*$D$2+$E$2+$F$2+$A4,E$3)) -> 37824.247 | R5: =AVERAGE(OFFSET('t344064'!$A$1,$B$2+($B5-1)*$D$2+$E$2+$A4+1,E$3):OFFSET('t344064'!$A$1,$B$2+($B5-1)*$D$2+$E$2+$F$2+$A4,E$3)) -> #DIV/0! | S5: =AVERAGE(OFFSET('t688128'!$A$1,$B$2+($B5-1)*$D$2+$E$2+$A4+1,E$3):OFFSET('t688128'!$A$1,$B$2+($B5-1)*$D$2+$E$2+$F$2+$A4,E$3)) -> #DIV/0! | T5: =AVERAGE(OFFSET(t1376256!$A$1,$B$2+($B5-1)*$D$2+$E$2+$A4+1,E$3):OFFSET(t1376256!$A$1,$B$2+($B5-1)*$D$2+$E$2+$F$2+$A4,E$3)) -> #DIV/0! | X5: 5 | Y5: << "Update=" << metrics.updatePheromones_time_ms << "ms "
A6: 0 | B6: 3 | D6: =OFFSET('t42'!$A$1,$B$2+($B6-1)*$D$2+$A4,D$3) -> 35.2752 | E6: =AVERAGE(OFFSET('t42'!$A$1,$B$2+($B6-1)*$D$2+$E$2+$A5+1,E$3):OFFSET('t42'!$A$1,$B$2+($B6-1)*$D$2+$E$2+$F$2+$A5,E$3)) -> 36.691382 | F6: =AVERAGE(OFFSET('t84'!$A$1,$B$2+($B6-1)*$D$2+$E$2+$A5+1,E$3):OFFSET('t84'!$A$1,$B$2+($B6-1)*$D$2+$E$2+$F$2+$A5,E$3)) -> 54.827639 | G6: =AVERAGE(OFFSET('t168'!$A$1,$B$2+($B6-1)*$D$2+$E$2+$A5+1,E$3):OFFSET('t168'!$A$1,$B$2+($B6-1)*$D$2+$E$2+$F$2+$A5,E$3)) -> 126.55471 | H6: =AVERAGE(OFFSET('t336'!$A$1,$B$2+($B6-1)*$D$2+$E$2+$A5+1,E$3):OFFSET('t336'!$A$1,$B$2+($B6-1)*$D$2+$E$2+$F$2+$A5,E$3)) -> 163.47143 | I6: =AVERAGE(OFFSET('t672'!$A$1,$B$2+($B6-1)*$D$2+$E$2+$A5+1,E$3):OFFSET('t672'!$A$1,$B$2+($B6-1)*$D$2+$E$2+$F$2+$A5,E$3)) -> 198.37616 | J6: =AVERAGE(OFFSET('t1344'!$A$1,$B$2+($B6-1)*$D$2+$E$2+$A5+1,E$3):OFFSET('t1344'!$A$1,$B$2+($B6-1)*$D$2+$E$2+$F$2+$A5,E$3)) -> 261.31184 | K6: =AVERAGE(OFFSET('t2688'!$A$1,$B$2+($B6-1)*$D$2+$E$2+$A5+1,E$3):OFFSET('t2688'!$A$1,$B$2+($B6-1)*$D$2+$E$2+$F$2+$A5,E$3)) -> 390.14227 | L6: =AVERAGE(OFFSET('t5376'!$A$1,$B$2+($B6-1)*$D$2+$E$2+$A5+1,E$3):OFFSET('t5376'!$A$1,$B$2+($B6-1)*$D$2+$E$2+$F$2+$A5,E$3)) -> 685.18802 | M6: =AVERAGE(OFFSET('t10752'!$A$1,$B$2+($B6-1)*$D$2+$E$2+$A5+1,E$3):OFFSET('t10752'!$A$1,$B$2+($B6-1)*$D$2+$E$2+$F$2+$A5,E$3)) -> 1537.2816 | N6: =AVERAGE(OFFSET('t21504'!$A$1,$B$2+($B6-1)*$D$2+$E$2+$A5+1,E$3):OFFSET('t21504'!$A$1,$B$2+($B6-1)*$D$2+$E$2+$F$2+$A5,E$3)) -> 3731.7718 | O6: =AVERAGE(OFFSET('t43008'!$A$1,$B$2+($B6-1)*$D$2+$E$2+$A5+1,E$3):OFFSET('t43008'!$A$1,$B$2+($B6-1)*$D$2+$E$2+$F$2+$A5,E$3)) -> 9023.6324 | P6: =AVERAGE(OFFSET('t86016'!$A$1,$B$2+($B6-1)*$D$2+$E$2+$A5+1,E$3):OFFSET('t86016'!$A$1,$B$2+($B6-1)*$D$2+$E$2+$F$2+$A5,E$3)) -> 18960.894 | Q6: =AVERAGE(OFFSET('t172032'!$A$1,$B$2+($B6-1)*$D$2+$E$2+$A5+1,E$3):OFFSET('t172032'!$A$1,$B$2+($B6-1)*$D$2+$E$2+$F$2+$A5,E$3)) -> 37973.08 | R6: =AVERAGE(OFFSET('t344064'!$A$1,$B$2+($B6-1)*$D$2+$E$2+$A5+1,E$3):OFFSET('t344064'!$A$1,$B$2+($B6-1)*$D$2+$E$2+$F$2+$A5,E$3)) -> #DIV/0! | S6: =AVERAGE(OFFSET('t688128'!$A$1,$B$2+($B6-1)*$D$2+$E$2+$A5+1,E$3):OFFSET('t688128'!$A$1,$B$2+($B6-1)*$D$2+$E$2+$F$2+$A5,E$3)) -> #DIV/0! | T6: =AVERAGE(OFFSET(t1376256!$A$1,$B$2+($B6-1)*$D$2+$E$2+$A5+1,E$3):OFFSET(t1376256!$A$1,$B$2+($B6-1)*$D$2+$E$2+$F$2+$A5,E$3)) -> #DIV/0!
A7: 0 | B7: 4 | D7: =OFFSET('t42'!$A$1,$B$2+($B7-1)*$D$2+$A5,D$3) -> 93.3345 | E7: =AVERAGE(OFFSET('t42'!$A$1,$B$2+($B7-1)*$D$2+$E$2+$A6+1,E$3):OFFSET('t42'!$A$1,$B$2+($B7-1)*$D$2+$E$2+$F$2+$A6,E$3)) -> 93.241412 | F7: =AVERAGE(OFFSET('t84'!$A$1,$B$2+($B7-1)*$D$2+$E$2+$A6+1,E$3):OFFSET('t84'!$A$1,$B$2+($B7-1)*$D$2+$E$2+$F$2+$A6,E$3)) -> 113.04014 | G7: =AVERAGE(OFFSET('t168'!$A$1,$B$2+($B7-1)*$D$2+$E$2+$A6+1,E$3):OFFSET('t168'!$A$1,$B$2+($B7-1)*$D$2+$E$2+$F$2+$A6,E$3)) -> 168.27645 | H7: =AVERAGE(OFFSET('t336'!$A$1,$B$2+($B7-1)*$D$2+$E$2+$A6+1,E$3):OFFSET('t336'!$A$1,$B$2+($B7-1)*$D$2+$E$2+$F$2+$A6,E$3)) -> 288.29916 | I7: =AVERAGE(OFFSET('t672'!$A$1,$B$2+($B7-1)*$D$2+$E$2+$A6+1,E$3):OFFSET('t672'!$A$1,$B$2+($B7-1)*$D$2+$E$2+$F$2+$A6,E$3)) -> 506.71882 | J7: =AVERAGE(OFFSET('t1344'!$A$1,$B$2+($B7-1)*$D$2+$E$2+$A6+1,E$3):OFFSET('t1344'!$A$1,$B$2+($B7-1)*$D$2+$E$2+$F$2+$A6,E$3)) -> 916.18692 | K7: =AVERAGE(OFFSET('t2688'!$A$1,$B$2+($B7-1)*$D$2+$E$2+$A6+1,E$3):OFFSET('t2688'!$A$1,$B$2+($B7-1)*$D$2+$E$2+$F$2+$A6,E$3)) -> 1761.191 | L7: =AVERAGE(OFFSET('t5376'!$A$1,$B$2+($B7-1)*$D$2+$E$2+$A6+1,E$3):OFFSET('t5376'!$A$1,$B$2+($B7-1)*$D$2+$E$2+$F$2+$A6,E$3)) -> 3641.879 | M7: =AVERAGE(OFFSET('t10752'!$A$1,$B$2+($B7-1)*$D$2+$E$2+$A6+1,E$3):OFFSET('t10752'!$A$1,$B$2+($B7-1)*$D$2+$E$2+$F$2+$A6,E$3)) -> 7195.5265 | N7: =AVERAGE(OFFSET('t21504'!$A$1,$B$2+($B7-1)*$D$2+$E$2+$A6+1,E$3):OFFSET('t21504'!$A$1,$B$2+($B7-1)*$D$2+$E$2+$F$2+$A6,E$3)) -> 14196.131 | O7: =AVERAGE(OFFSET('t43008'!$A$1,$B$2+($B7-1)*$D$2+$E$2+$A6+1,E$3):OFFSET('t43008'!$A$1,$B$2+($B7-1)*$D$2+$E$2+$F$2+$A6,E$3)) -> 27882.953 | P7: =AVERAGE(OFFSET('t86016'!$A$1,$B$2+($B7-1)*$D$2+$E$2+$A6+1,E$3):OFFSET('t86016'!$A$1,$B$2+($B7-1)*$D$2+$E$2+$F$2+$A6,E$3)) -> 56317.435 | Q7: =AVERAGE(OFFSET('t172032'!$A$1,$B$2+($B7-1)*$D$2+$E$2+$A6+1,E$3):OFFSET('t172032'!$A$1,$B$2+($B7-1)*$D$2+$E$2+$F$2+$A6,E$3)) -> 114205.12 | R7: =AVERAGE(OFFSET('t344064'!$A$1,$B$2+($B7-1)*$D$2+$E$2+$A6+1,E$3):OFFSET('t344064'!$A$1,$B$2+($B7-1)*$D$2+$E$2+$F$2+$A6,E$3)) -> #DIV/0! | S7: =AVERAGE(OFFSET('t688128'!$A$1,$B$2+($B7-1)*$D$2+$E$2+$A6+1,E$3):OFFSET('t688128'!$A$1,$B$2+($B7-1)*$D$2+$E$2+$F$2+$A6,E$3)) -> #DIV/0! | T7: =AVERAGE(OFFSET(t1376256!$A$1,$B$2+($B7-1)*$D$2+$E$2+$A6+1,E$3):OFFSET(t1376256!$A$1,$B$2+($B7-1)*$D$2+$E$2+$F$2+$A6,E$3)) -> #DIV/0!
A8: 1 | B8: 5 | C8: 32 | D8: =OFFSET('t42'!$A$1,$B$2+($B8-1)*$D$2+$A8,D$3) -> 42.2004 | E8: =AVERAGE(OFFSET('t42'!$A$1,$B$2+($B8-1)*$D$2+$E$2+$A8,E$3):OFFSET('t42'!$A$1,$B$2+($B8-1)*$D$2+$E$2+$F$2+$A8,E$3)) -> 43.67896 | F8: =AVERAGE(OFFSET('t84'!$A$1,$B$2+($B8-1)*$D$2+$E$2+$A8,E$3):OFFSET('t84'!$A$1,$B$2+($B8-1)*$D$2+$E$2+$F$2+$A8,E$3)) -> 58.564478 | G8: =AVERAGE(OFFSET('t168'!$A$1,$B$2+($B8-1)*$D$2+$E$2+$A8,E$3):OFFSET('t168'!$A$1,$B$2+($B8-1)*$D$2+$E$2+$F$2+$A8,E$3)) -> 107.51348 | H8: =AVERAGE(OFFSET('t336'!$A$1,$B$2+($B8-1)*$D$2+$E$2+$A8,E$3):OFFSET('t336'!$A$1,$B$2+($B8-1)*$D$2+$E$2+$F$2+$A8,E$3)) -> 128.59174 | I8: =AVERAGE(OFFSET('t672'!$A$1,$B$2+($B8-1)*$D$2+$E$2+$A8,E$3):OFFSET('t672'!$A$1,$B$2+($B8-1)*$D$2+$E$2+$F$2+$A8,E$3)) -> 163.77792 | J8: =AVERAGE(OFFSET('t1344'!$A$1,$B$2+($B8-1)*$D$2+$E$2+$A8,E$3):OFFSET('t1344'!$A$1,$B$2+($B8-1)*$D$2+$E$2+$F$2+$A8,E$3)) -> 228.10774 | K8: =AVERAGE(OFFSET('t2688'!$A$1,$B$2+($B8-1)*$D$2+$E$2+$A8,E$3):OFFSET('t2688'!$A$1,$B$2+($B8-1)*$D$2+$E$2+$F$2+$A8,E$3)) -> 350.09898 | L8: =AVERAGE(OFFSET('t5376'!$A$1,$B$2+($B8-1)*$D$2+$E$2+$A8,E$3):OFFSET('t5376'!$A$1,$B$2+($B8-1)*$D$2+$E$2+$F$2+$A8,E$3)) -> 665.3512 | M8: =AVERAGE(OFFSET('t10752'!$A$1,$B$2+($B8-1)*$D$2+$E$2+$A8,E$3):OFFSET('t10752'!$A$1,$B$2+($B8-1)*$D$2+$E$2+$F$2+$A8,E$3)) -> 1428.4594 | N8: =AVERAGE(OFFSET('t21504'!$A$1,$B$2+($B8-1)*$D$2+$E$2+$A8,E$3):OFFSET('t21504'!$A$1,$B$2+($B8-1)*$D$2+$E$2+$F$2+$A8,E$3)) -> 3455.3222 | O8: =AVERAGE(OFFSET('t43008'!$A$1,$B$2+($B8-1)*$D$2+$E$2+$A8,E$3):OFFSET('t43008'!$A$1,$B$2+($B8-1)*$D$2+$E$2+$F$2+$A8,E$3)) -> 7182.159 | P8: =AVERAGE(OFFSET('t86016'!$A$1,$B$2+($B8-1)*$D$2+$E$2+$A8,E$3):OFFSET('t86016'!$A$1,$B$2+($B8-1)*$D$2+$E$2+$F$2+$A8,E$3)) -> 16948.524 | Q8: =AVERAGE(OFFSET('t172032'!$A$1,$B$2+($B8-1)*$D$2+$E$2+$A8,E$3):OFFSET('t172032'!$A$1,$B$2+($B8-1)*$D$2+$E$2+$F$2+$A8,E$3)) -> 27067.98 | R8: =AVERAGE(OFFSET('t344064'!$A$1,$B$2+($B8-1)*$D$2+$E$2+$A8,E$3):OFFSET('t344064'!$A$1,$B$2+($B8-1)*$D$2+$E$2+$F$2+$A8,E$3)) -> #DIV/0! | S8: =AVERAGE(OFFSET('t688128'!$A$1,$B$2+($B8-1)*$D$2+$E$2+$A8,E$3):OFFSET('t688128'!$A$1,$B$2+($B8-1)*$D$2+$E$2+$F$2+$A8,E$3)) -> #DIV/0! | T8: =AVERAGE(OFFSET(t1376256!$A$1,$B$2+($B8-1)*$D$2+$E$2+$A8,E$3):OFFSET(t1376256!$A$1,$B$2+($B8-1)*$D$2+$E$2+$F$2+$A8,E$3)) -> #DIV/0! | X8: 6 | Y8: << "Memory=" << metrics.memory_time_ms << "ms "
A9: 1 | B9: 6 | D9: =OFFSET('t42'!$A$1,$B$2+($B9-1)*$D$2+$A8,D$3) -> 51.1788 | E9: =AVERAGE(OFFSET('t42'!$A$1,$B$2+($B9-1)*$D$2+$E$2+$A8+1,E$3):OFFSET('t42'!$A$1,$B$2+($B9-1)*$D$2+$E$2+$F$2+$A8,E$3)) -> 47.250218 | F9: =AVERAGE(OFFSET('t84'!$A$1,$B$2+($B9-1)*$D$2+$E$2+$A8+1,E$3):OFFSET('t84'!$A$1,$B$2+($B9-1)*$D$2+$E$2+$F$2+$A8,E$3)) -> 60.245782 | G9: =AVERAGE(OFFSET('t168'!$A$1,$B$2+($B9-1)*$D$2+$E$2+$A8+1,E$3):OFFSET('t168'!$A$1,$B$2+($B9-1)*$D$2+$E$2+$F$2+$A8,E$3)) -> 111.51386 | H9: =AVERAGE(OFFSET('t336'!$A$1,$B$2+($B9-1)*$D$2+$E$2+$A8+1,E$3):OFFSET('t336'!$A$1,$B$2+($B9-1)*$D$2+$E$2+$F$2+$A8,E$3)) -> 135.89604 | I9: =AVERAGE(OFFSET('t672'!$A$1,$B$2+($B9-1)*$D$2+$E$2+$A8+1,E$3):OFFSET('t672'!$A$1,$B$2+($B9-1)*$D$2+$E$2+$F$2+$A8,E$3)) -> 168.33622 | J9: =AVERAGE(OFFSET('t1344'!$A$1,$B$2+($B9-1)*$D$2+$E$2+$A8+1,E$3):OFFSET('t1344'!$A$1,$B$2+($B9-1)*$D$2+$E$2+$F$2+$A8,E$3)) -> 230.77906 | K9: =AVERAGE(OFFSET('t2688'!$A$1,$B$2+($B9-1)*$D$2+$E$2+$A8+1,E$3):OFFSET('t2688'!$A$1,$B$2+($B9-1)*$D$2+$E$2+$F$2+$A8,E$3)) -> 351.48788 | L9: =AVERAGE(OFFSET('t5376'!$A$1,$B$2+($B9-1)*$D$2+$E$2+$A8+1,E$3):OFFSET('t5376'!$A$1,$B$2+($B9-1)*$D$2+$E$2+$F$2+$A8,E$3)) -> 674.46729 | M9: =AVERAGE(OFFSET('t10752'!$A$1,$B$2+($B9-1)*$D$2+$E$2+$A8+1,E$3):OFFSET('t10752'!$A$1,$B$2+($B9-1)*$D$2+$E$2+$F$2+$A8,E$3)) -> 1436.4814 | N9: =AVERAGE(OFFSET('t21504'!$A$1,$B$2+($B9-1)*$D$2+$E$2+$A8+1,E$3):OFFSET('t21504'!$A$1,$B$2+($B9-1)*$D$2+$E$2+$F$2+$A8,E$3)) -> 3460.5314 | O9: =AVERAGE(OFFSET('t43008'!$A$1,$B$2+($B9-1)*$D$2+$E$2+$A8+1,E$3):OFFSET('t43008'!$A$1,$B$2+($B9-1)*$D$2+$E$2+$F$2+$A8,E$3)) -> 7189.6739 | P9: =AVERAGE(OFFSET('t86016'!$A$1,$B$2+($B9-1)*$D$2+$E$2+$A8+1,E$3):OFFSET('t86016'!$A$1,$B$2+($B9-1)*$D$2+$E$2+$F$2+$A8,E$3)) -> 16950.882 | Q9: =AVERAGE(OFFSET('t172032'!$A$1,$B$2+($B9-1)*$D$2+$E$2+$A8+1,E$3):OFFSET('t172032'!$A$1,$B$2+($B9-1)*$D$2+$E$2+$F$2+$A8,E$3)) -> 26279.543 | R9: =AVERAGE(OFFSET('t344064'!$A$1,$B$2+($B9-1)*$D$2+$E$2+$A8+1,E$3):OFFSET('t344064'!$A$1,$B$2+($B9-1)*$D$2+$E$2+$F$2+$A8,E$3)) -> #DIV/0! | S9: =AVERAGE(OFFSET('t688128'!$A$1,$B$2+($B9-1)*$D$2+$E$2+$A8+1,E$3):OFFSET('t688128'!$A$1,$B$2+($B9-1)*$D$2+$E$2+$F$2+$A8,E$3)) -> #DIV/0! | T9: =AVERAGE(OFFSET(t1376256!$A$1,$B$2+($B9-1)*$D$2+$E$2+$A8+1,E$3):OFFSET(t1376256!$A$1,$B$2+($B9-1)*$D$2+$E$2+$F$2+$A8,E$3)) -> #DIV/0! | X9: 7 | Y9: << "HitRate=" << (100.0 * metrics.hash_hits / (metrics.hash_hits + metrics.hash_misses)) << "% "
A10: 1 | B10: 7 | D10: =OFFSET('t42'!$A$1,$B$2+($B10-1)*$D$2+$A8,D$3) -> 34.5754 | E10: =AVERAGE(OFFSET('t42'!$A$1,$B$2+($B10-1)*$D$2+$E$2+$A9+1,E$3):OFFSET('t42'!$A$1,$B$2+($B10-1)*$D$2+$E$2+$F$2+$A9,E$3)) -> 34.894424 | F10: =AVERAGE(OFFSET('t84'!$A$1,$B$2+($B10-1)*$D$2+$E$2+$A9+1,E$3):OFFSET('t84'!$A$1,$B$2+($B10-1)*$D$2+$E$2+$F$2+$A9,E$3)) -> 50.507445 | G10: =AVERAGE(OFFSET('t168'!$A$1,$B$2+($B10-1)*$D$2+$E$2+$A9+1,E$3):OFFSET('t168'!$A$1,$B$2+($B10-1)*$D$2+$E$2+$F$2+$A9,E$3)) -> 123.68096 | H10: =AVERAGE(OFFSET('t336'!$A$1,$B$2+($B10-1)*$D$2+$E$2+$A9+1,E$3):OFFSET('t336'!$A$1,$B$2+($B10-1)*$D$2+$E$2+$F$2+$A9,E$3)) -> 156.92698 | I10: =AVERAGE(OFFSET('t672'!$A$1,$B$2+($B10-1)*$D$2+$E$2+$A9+1,E$3):OFFSET('t672'!$A$1,$B$2+($B10-1)*$D$2+$E$2+$F$2+$A9,E$3)) -> 188.44608 | J10: =AVERAGE(OFFSET('t1344'!$A$1,$B$2+($B10-1)*$D$2+$E$2+$A9+1,E$3):OFFSET('t1344'!$A$1,$B$2+($B10-1)*$D$2+$E$2+$F$2+$A9,E$3)) -> 253.33465 | K10: =AVERAGE(OFFSET('t2688'!$A$1,$B$2+($B10-1)*$D$2+$E$2+$A9+1,E$3):OFFSET('t2688'!$A$1,$B$2+($B10-1)*$D$2+$E$2+$F$2+$A9,E$3)) -> 378.44929 | L10: =AVERAGE(OFFSET('t5376'!$A$1,$B$2+($B10-1)*$D$2+$E$2+$A9+1,E$3):OFFSET('t5376'!$A$1,$B$2+($B10-1)*$D$2+$E$2+$F$2+$A9,E$3)) -> 673.05237 | M10: =AVERAGE(OFFSET('t10752'!$A$1,$B$2+($B10-1)*$D$2+$E$2+$A9+1,E$3):OFFSET('t10752'!$A$1,$B$2+($B10-1)*$D$2+$E$2+$F$2+$A9,E$3)) -> 1466.0267 | N10: =AVERAGE(OFFSET('t21504'!$A$1,$B$2+($B10-1)*$D$2+$E$2+$A9+1,E$3):OFFSET('t21504'!$A$1,$B$2+($B10-1)*$D$2+$E$2+$F$2+$A9,E$3)) -> 3514.96 | O10: =AVERAGE(OFFSET('t43008'!$A$1,$B$2+($B10-1)*$D$2+$E$2+$A9+1,E$3):OFFSET('t43008'!$A$1,$B$2+($B10-1)*$D$2+$E$2+$F$2+$A9,E$3)) -> 7457.4333 | P10: =AVERAGE(OFFSET('t86016'!$A$1,$B$2+($B10-1)*$D$2+$E$2+$A9+1,E$3):OFFSET('t86016'!$A$1,$B$2+($B10-1)*$D$2+$E$2+$F$2+$A9,E$3)) -> 17119.488 | Q10: =AVERAGE(OFFSET('t172032'!$A$1,$B$2+($B10-1)*$D$2+$E$2+$A9+1,E$3):OFFSET('t172032'!$A$1,$B$2+($B10-1)*$D$2+$E$2+$F$2+$A9,E$3)) -> 26411.059 | R10: =AVERAGE(OFFSET('t344064'!$A$1,$B$2+($B10-1)*$D$2+$E$2+$A9+1,E$3):OFFSET('t344064'!$A$1,$B$2+($B10-1)*$D$2+$E$2+$F$2+$A9,E$3)) -> #DIV/0! | S10: =AVERAGE(OFFSET('t688128'!$A$1,$B$2+($B10-1)*$D$2+$E$2+$A9+1,E$3):OFFSET('t688128'!$A$1,$B$2+($B10-1)*$D$2+$E$2+$F$2+$A9,E$3)) -> #DIV/0! | T10: =AVERAGE(OFFSET(t1376256!$A$1,$B$2+($B10-1)*$D$2+$E$2+$A9+1,E$3):OFFSET(t1376256!$A$1,$B$2+($B10-1)*$D$2+$E$2+$F$2+$A9,E$3)) -> #DIV/0!
A11: 1 | B11: 8 | D11: =OFFSET('t42'!$A$1,$B$2+($B11-1)*$D$2+$A9,D$3) -> 87.136 | E11: =AVERAGE(OFFSET('t42'!$A$1,$B$2+($B11-1)*$D$2+$E$2+$A10+1,E$3):OFFSET('t42'!$A$1,$B$2+($B11-1)*$D$2+$E$2+$F$2+$A10,E$3)) -> 88.853714 | F11: =AVERAGE(OFFSET('t84'!$A$1,$B$2+($B11-1)*$D$2+$E$2+$A10+1,E$3):OFFSET('t84'!$A$1,$B$2+($B11-1)*$D$2+$E$2+$F$2+$A10,E$3)) -> 112.69649 | G11: =AVERAGE(OFFSET('t168'!$A$1,$B$2+($B11-1)*$D$2+$E$2+$A10+1,E$3):OFFSET('t168'!$A$1,$B$2+($B11-1)*$D$2+$E$2+$F$2+$A10,E$3)) -> 159.90382 | H11: =AVERAGE(OFFSET('t336'!$A$1,$B$2+($B11-1)*$D$2+$E$2+$A10+1,E$3):OFFSET('t336'!$A$1,$B$2+($B11-1)*$D$2+$E$2+$F$2+$A10,E$3)) -> 268.51514 | I11: =AVERAGE(OFFSET('t672'!$A$1,$B$2+($B11-1)*$D$2+$E$2+$A10+1,E$3):OFFSET('t672'!$A$1,$B$2+($B11-1)*$D$2+$E$2+$F$2+$A10,E$3)) -> 471.27376 | J11: =AVERAGE(OFFSET('t1344'!$A$1,$B$2+($B11-1)*$D$2+$E$2+$A10+1,E$3):OFFSET('t1344'!$A$1,$B$2+($B11-1)*$D$2+$E$2+$F$2+$A10,E$3)) -> 890.77122 | K11: =AVERAGE(OFFSET('t2688'!$A$1,$B$2+($B11-1)*$D$2+$E$2+$A10+1,E$3):OFFSET('t2688'!$A$1,$B$2+($B11-1)*$D$2+$E$2+$F$2+$A10,E$3)) -> 1714.602 | L11: =AVERAGE(OFFSET('t5376'!$A$1,$B$2+($B11-1)*$D$2+$E$2+$A10+1,E$3):OFFSET('t5376'!$A$1,$B$2+($B11-1)*$D$2+$E$2+$F$2+$A10,E$3)) -> 3411.2498 | M11: =AVERAGE(OFFSET('t10752'!$A$1,$B$2+($B11-1)*$D$2+$E$2+$A10+1,E$3):OFFSET('t10752'!$A$1,$B$2+($B11-1)*$D$2+$E$2+$F$2+$A10,E$3)) -> 6658.8229 | N11: =AVERAGE(OFFSET('t21504'!$A$1,$B$2+($B11-1)*$D$2+$E$2+$A10+1,E$3):OFFSET('t21504'!$A$1,$B$2+($B11-1)*$D$2+$E$2+$F$2+$A10,E$3)) -> 13319.6 | O11: =AVERAGE(OFFSET('t43008'!$A$1,$B$2+($B11-1)*$D$2+$E$2+$A10+1,E$3):OFFSET('t43008'!$A$1,$B$2+($B11-1)*$D$2+$E$2+$F$2+$A10,E$3)) -> 26243.465 | P11: =AVERAGE(OFFSET('t86016'!$A$1,$B$2+($B11-1)*$D$2+$E$2+$A10+1,E$3):OFFSET('t86016'!$A$1,$B$2+($B11-1)*$D$2+$E$2+$F$2+$A10,E$3)) -> 53020.798 | Q11: =AVERAGE(OFFSET('t172032'!$A$1,$B$2+($B11-1)*$D$2+$E$2+$A10+1,E$3):OFFSET('t172032'!$A$1,$B$2+($B11-1)*$D$2+$E$2+$F$2+$A10,E$3)) -> 108443.63 | R11: =AVERAGE(OFFSET('t344064'!$A$1,$B$2+($B11-1)*$D$2+$E$2+$A10+1,E$3):OFFSET('t344064'!$A$1,$B$2+($B11-1)*$D$2+$E$2+$F$2+$A10,E$3)) -> #DIV/0! | S11: =AVERAGE(OFFSET('t688128'!$A$1,$B$2+($B11-1)*$D$2+$E$2+$A10+1,E$3):OFFSET('t688128'!$A$1,$B$2+($B11-1)*$D$2+$E$2+$F$2+$A10,E$3)) -> #DIV/0! | T11: =AVERAGE(OFFSET(t1376256!$A$1,$B$2+($B11-1)*$D$2+$E$2+$A10+1,E$3):OFFSET(t1376256!$A$1,$B$2+($B11-1)*$D$2+$E$2+$F$2+$A10,E$3)) -> #DIV/0!
A12: 2 | B12: 9 | C12: 64 | D12: =OFFSET('t42'!$A$1,$B$2+($B12-1)*$D$2+$A12,D$3) -> 42.5421 | E12: =AVERAGE(OFFSET('t42'!$A$1,$B$2+($B12-1)*$D$2+$E$2+$A12,E$3):OFFSET('t42'!$A$1,$B$2+($B12-1)*$D$2+$E$2+$F$2+$A12,E$3)) -> 42.92245 | F12: =AVERAGE(OFFSET('t84'!$A$1,$B$2+($B12-1)*$D$2+$E$2+$A12,E$3):OFFSET('t84'!$A$1,$B$2+($B12-1)*$D$2+$E$2+$F$2+$A12,E$3)) -> 60.245924 | G12: =AVERAGE(OFFSET('t168'!$A$1,$B$2+($B12-1)*$D$2+$E$2+$A12,E$3):OFFSET('t168'!$A$1,$B$2+($B12-1)*$D$2+$E$2+$F$2+$A12,E$3)) -> 107.97424 | H12: =AVERAGE(OFFSET('t336'!$A$1,$B$2+($B12-1)*$D$2+$E$2+$A12,E$3):OFFSET('t336'!$A$1,$B$2+($B12-1)*$D$2+$E$2+$F$2+$A12,E$3)) -> 134.21168 | I12: =AVERAGE(OFFSET('t672'!$A$1,$B$2+($B12-1)*$D$2+$E$2+$A12,E$3):OFFSET('t672'!$A$1,$B$2+($B12-1)*$D$2+$E$2+$F$2+$A12,E$3)) -> 177.66522 | J12: =AVERAGE(OFFSET('t1344'!$A$1,$B$2+($B12-1)*$D$2+$E$2+$A12,E$3):OFFSET('t1344'!$A$1,$B$2+($B12-1)*$D$2+$E$2+$F$2+$A12,E$3)) -> 246.94008 | K12: =AVERAGE(OFFSET('t2688'!$A$1,$B$2+($B12-1)*$D$2+$E$2+$A12,E$3):OFFSET('t2688'!$A$1,$B$2+($B12-1)*$D$2+$E$2+$F$2+$A12,E$3)) -> 388.7497 | L12: =AVERAGE(OFFSET('t5376'!$A$1,$B$2+($B12-1)*$D$2+$E$2+$A12,E$3):OFFSET('t5376'!$A$1,$B$2+($B12-1)*$D$2+$E$2+$F$2+$A12,E$3)) -> 893.47018 | M12: =AVERAGE(OFFSET('t10752'!$A$1,$B$2+($B12-1)*$D$2+$E$2+$A12,E$3):OFFSET('t10752'!$A$1,$B$2+($B12-1)*$D$2+$E$2+$F$2+$A12,E$3)) -> 1668.4398 | N12: =AVERAGE(OFFSET('t21504'!$A$1,$B$2+($B12-1)*$D$2+$E$2+$A12,E$3):OFFSET('t21504'!$A$1,$B$2+($B12-1)*$D$2+$E$2+$F$2+$A12,E$3)) -> 3207.266 | O12: =AVERAGE(OFFSET('t43008'!$A$1,$B$2+($B12-1)*$D$2+$E$2+$A12,E$3):OFFSET('t43008'!$A$1,$B$2+($B12-1)*$D$2+$E$2+$F$2+$A12,E$3)) -> 8231.2544 | P12: =AVERAGE(OFFSET('t86016'!$A$1,$B$2+($B12-1)*$D$2+$E$2+$A12,E$3):OFFSET('t86016'!$A$1,$B$2+($B12-1)*$D$2+$E$2+$F$2+$A12,E$3)) -> 19653.926 | Q12: =AVERAGE(OFFSET('t172032'!$A$1,$B$2+($B12-1)*$D$2+$E$2+$A12,E$3):OFFSET('t172032'!$A$1,$B$2+($B12-1)*$D$2+$E$2+$F$2+$A12,E$3)) -> 29218.908 | R12: =AVERAGE(OFFSET('t344064'!$A$1,$B$2+($B12-1)*$D$2+$E$2+$A12,E$3):OFFSET('t344064'!$A$1,$B$2+($B12-1)*$D$2+$E$2+$F$2+$A12,E$3)) -> #DIV/0! | S12: =AVERAGE(OFFSET('t688128'!$A$1,$B$2+($B12-1)*$D$2+$E$2+$A12,E$3):OFFSET('t688128'!$A$1,$B$2+($B12-1)*$D$2+$E$2+$F$2+$A12,E$3)) -> #DIV/0! | T12: =AVERAGE(OFFSET(t1376256!$A$1,$B$2+($B12-1)*$D$2+$E$2+$A12,E$3):OFFSET(t1376256!$A$1,$B$2+($B12-1)*$D$2+$E$2+$F$2+$A12,E$3)) -> #DIV/0! | X12: 8 | Y12: << "Occupancy=" << metrics.occupancy << "% "
A13: 2 | B13: 10 | D13: =OFFSET('t42'!$A$1,$B$2+($B13-1)*$D$2+$A12,D$3) -> 47.2071 | E13: =AVERAGE(OFFSET('t42'!$A$1,$B$2+($B13-1)*$D$2+$E$2+$A12+1,E$3):OFFSET('t42'!$A$1,$B$2+($B13-1)*$D$2+$E$2+$F$2+$A12,E$3)) -> 46.662608 | F13: =AVERAGE(OFFSET('t84'!$A$1,$B$2+($B13-1)*$D$2+$E$2+$A12+1,E$3):OFFSET('t84'!$A$1,$B$2+($B13-1)*$D$2+$E$2+$F$2+$A12,E$3)) -> 61.091645 | G13: =AVERAGE(OFFSET('t168'!$A$1,$B$2+($B13-1)*$D$2+$E$2+$A12+1,E$3):OFFSET('t168'!$A$1,$B$2+($B13-1)*$D$2+$E$2+$F$2+$A12,E$3)) -> 112.82929 | H13: =AVERAGE(OFFSET('t336'!$A$1,$B$2+($B13-1)*$D$2+$E$2+$A12+1,E$3):OFFSET('t336'!$A$1,$B$2+($B13-1)*$D$2+$E$2+$F$2+$A12,E$3)) -> 143.78767 | I13: =AVERAGE(OFFSET('t672'!$A$1,$B$2+($B13-1)*$D$2+$E$2+$A12+1,E$3):OFFSET('t672'!$A$1,$B$2+($B13-1)*$D$2+$E$2+$F$2+$A12,E$3)) -> 183.04237 | J13: =AVERAGE(OFFSET('t1344'!$A$1,$B$2+($B13-1)*$D$2+$E$2+$A12+1,E$3):OFFSET('t1344'!$A$1,$B$2+($B13-1)*$D$2+$E$2+$F$2+$A12,E$3)) -> 249.10741 | K13: =AVERAGE(OFFSET('t2688'!$A$1,$B$2+($B13-1)*$D$2+$E$2+$A12+1,E$3):OFFSET('t2688'!$A$1,$B$2+($B13-1)*$D$2+$E$2+$F$2+$A12,E$3)) -> 392.40955 | L13: =AVERAGE(OFFSET('t5376'!$A$1,$B$2+($B13-1)*$D$2+$E$2+$A12+1,E$3):OFFSET('t5376'!$A$1,$B$2+($B13-1)*$D$2+$E$2+$F$2+$A12,E$3)) -> 895.62773 | M13: =AVERAGE(OFFSET('t10752'!$A$1,$B$2+($B13-1)*$D$2+$E$2+$A12+1,E$3):OFFSET('t10752'!$A$1,$B$2+($B13-1)*$D$2+$E$2+$F$2+$A12,E$3)) -> 1668.4808 | N13: =AVERAGE(OFFSET('t21504'!$A$1,$B$2+($B13-1)*$D$2+$E$2+$A12+1,E$3):OFFSET('t21504'!$A$1,$B$2+($B13-1)*$D$2+$E$2+$F$2+$A12,E$3)) -> 3152.4469 | O13: =AVERAGE(OFFSET('t43008'!$A$1,$B$2+($B13-1)*$D$2+$E$2+$A12+1,E$3):OFFSET('t43008'!$A$1,$B$2+($B13-1)*$D$2+$E$2+$F$2+$A12,E$3)) -> 8239.3273 | P13: =AVERAGE(OFFSET('t86016'!$A$1,$B$2+($B13-1)*$D$2+$E$2+$A12+1,E$3):OFFSET('t86016'!$A$1,$B$2+($B13-1)*$D$2+$E$2+$F$2+$A12,E$3)) -> 19249.853 | Q13: =AVERAGE(OFFSET('t172032'!$A$1,$B$2+($B13-1)*$D$2+$E$2+$A12+1,E$3):OFFSET('t172032'!$A$1,$B$2+($B13-1)*$D$2+$E$2+$F$2+$A12,E$3)) -> 29330.667 | R13: =AVERAGE(OFFSET('t344064'!$A$1,$B$2+($B13-1)*$D$2+$E$2+$A12+1,E$3):OFFSET('t344064'!$A$1,$B$2+($B13-1)*$D$2+$E$2+$F$2+$A12,E$3)) -> #DIV/0! | S13: =AVERAGE(OFFSET('t688128'!$A$1,$B$2+($B13-1)*$D$2+$E$2+$A12+1,E$3):OFFSET('t688128'!$A$1,$B$2+($B13-1)*$D$2+$E$2+$F$2+$A12,E$3)) -> #DIV/0! | T13: =AVERAGE(OFFSET(t1376256!$A$1,$B$2+($B13-1)*$D$2+$E$2+$A12+1,E$3):OFFSET(t1376256!$A$1,$B$2+($B13-1)*$D$2+$E$2+$F$2+$A12,E$3)) -> #DIV/0! | X13: 9 | Y13: << "memory_throughput_gbs=" << metrics.memory_throughput_gbs << " "
A14: 2 | B14: 11 | D14: =OFFSET('t42'!$A$1,$B$2+($B14-1)*$D$2+$A12,D$3) -> 34.344 | E14: =AVERAGE(OFFSET('t42'!$A$1,$B$2+($B14-1)*$D$2+$E$2+$A13+1,E$3):OFFSET('t42'!$A$1,$B$2+($B14-1)*$D$2+$E$2+$F$2+$A13,E$3)) -> 35.209461 | F14: =AVERAGE(OFFSET('t84'!$A$1,$B$2+($B14-1)*$D$2+$E$2+$A13+1,E$3):OFFSET('t84'!$A$1,$B$2+($B14-1)*$D$2+$E$2+$F$2+$A13,E$3)) -> 52.542008 | G14: =AVERAGE(OFFSET('t168'!$A$1,$B$2+($B14-1)*$D$2+$E$2+$A13+1,E$3):OFFSET('t168'!$A$1,$B$2+($B14-1)*$D$2+$E$2+$F$2+$A13,E$3)) -> 123.10869 | H14: =AVERAGE(OFFSET('t336'!$A$1,$B$2+($B14-1)*$D$2+$E$2+$A13+1,E$3):OFFSET('t336'!$A$1,$B$2+($B14-1)*$D$2+$E$2+$F$2+$A13,E$3)) -> 159.77555 | I14: =AVERAGE(OFFSET('t672'!$A$1,$B$2+($B14-1)*$D$2+$E$2+$A13+1,E$3):OFFSET('t672'!$A$1,$B$2+($B14-1)*$D$2+$E$2+$F$2+$A13,E$3)) -> 196.72669 | J14: =AVERAGE(OFFSET('t1344'!$A$1,$B$2+($B14-1)*$D$2+$E$2+$A13+1,E$3):OFFSET('t1344'!$A$1,$B$2+($B14-1)*$D$2+$E$2+$F$2+$A13,E$3)) -> 272.18847 | K14: =AVERAGE(OFFSET('t2688'!$A$1,$B$2+($B14-1)*$D$2+$E$2+$A13+1,E$3):OFFSET('t2688'!$A$1,$B$2+($B14-1)*$D$2+$E$2+$F$2+$A13,E$3)) -> 419.25012 | L14: =AVERAGE(OFFSET('t5376'!$A$1,$B$2+($B14-1)*$D$2+$E$2+$A13+1,E$3):OFFSET('t5376'!$A$1,$B$2+($B14-1)*$D$2+$E$2+$F$2+$A13,E$3)) -> 890.7669 | M14: =AVERAGE(OFFSET('t10752'!$A$1,$B$2+($B14-1)*$D$2+$E$2+$A13+1,E$3):OFFSET('t10752'!$A$1,$B$2+($B14-1)*$D$2+$E$2+$F$2+$A13,E$3)) -> 1715.9592 | N14: =AVERAGE(OFFSET('t21504'!$A$1,$B$2+($B14-1)*$D$2+$E$2+$A13+1,E$3):OFFSET('t21504'!$A$1,$B$2+($B14-1)*$D$2+$E$2+$F$2+$A13,E$3)) -> 3192.062 | O14: =AVERAGE(OFFSET('t43008'!$A$1,$B$2+($B14-1)*$D$2+$E$2+$A13+1,E$3):OFFSET('t43008'!$A$1,$B$2+($B14-1)*$D$2+$E$2+$F$2+$A13,E$3)) -> 8517.8553 | P14: =AVERAGE(OFFSET('t86016'!$A$1,$B$2+($B14-1)*$D$2+$E$2+$A13+1,E$3):OFFSET('t86016'!$A$1,$B$2+($B14-1)*$D$2+$E$2+$F$2+$A13,E$3)) -> 19057.392 | Q14: =AVERAGE(OFFSET('t172032'!$A$1,$B$2+($B14-1)*$D$2+$E$2+$A13+1,E$3):OFFSET('t172032'!$A$1,$B$2+($B14-1)*$D$2+$E$2+$F$2+$A13,E$3)) -> 30106.49 | R14: =AVERAGE(OFFSET('t344064'!$A$1,$B$2+($B14-1)*$D$2+$E$2+$A13+1,E$3):OFFSET('t344064'!$A$1,$B$2+($B14-1)*$D$2+$E$2+$F$2+$A13,E$3)) -> #DIV/0! | S14: =AVERAGE(OFFSET('t688128'!$A$1,$B$2+($B14-1)*$D$2+$E$2+$A13+1,E$3):OFFSET('t688128'!$A$1,$B$2+($B14-1)*$D$2+$E$2+$F$2+$A13,E$3)) -> #DIV/0! | T14: =AVERAGE(OFFSET(t1376256!$A$1,$B$2+($B14-1)*$D$2+$E$2+$A13+1,E$3):OFFSET(t1376256!$A$1,$B$2+($B14-1)*$D$2+$E$2+$F$2+$A13,E$3)) -> #DIV/0!
A15: 2 | B15: 12 | D15: =OFFSET('t42'!$A$1,$B$2+($B15-1)*$D$2+$A13,D$3) -> 87.461 | E15: =AVERAGE(OFFSET('t42'!$A$1,$B$2+($B15-1)*$D$2+$E$2+$A14+1,E$3):OFFSET('t42'!$A$1,$B$2+($B15-1)*$D$2+$E$2+$F$2+$A14,E$3)) -> 89.824682 | F15: =AVERAGE(OFFSET('t84'!$A$1,$B$2+($B15-1)*$D$2+$E$2+$A14+1,E$3):OFFSET('t84'!$A$1,$B$2+($B15-1)*$D$2+$E$2+$F$2+$A14,E$3)) -> 108.90963 | G15: =AVERAGE(OFFSET('t168'!$A$1,$B$2+($B15-1)*$D$2+$E$2+$A14+1,E$3):OFFSET('t168'!$A$1,$B$2+($B15-1)*$D$2+$E$2+$F$2+$A14,E$3)) -> 159.4482 | H15: =AVERAGE(OFFSET('t336'!$A$1,$B$2+($B15-1)*$D$2+$E$2+$A14+1,E$3):OFFSET('t336'!$A$1,$B$2+($B15-1)*$D$2+$E$2+$F$2+$A14,E$3)) -> 267.38869 | I15: =AVERAGE(OFFSET('t672'!$A$1,$B$2+($B15-1)*$D$2+$E$2+$A14+1,E$3):OFFSET('t672'!$A$1,$B$2+($B15-1)*$D$2+$E$2+$F$2+$A14,E$3)) -> 467.49361 | J15: =AVERAGE(OFFSET('t1344'!$A$1,$B$2+($B15-1)*$D$2+$E$2+$A14+1,E$3):OFFSET('t1344'!$A$1,$B$2+($B15-1)*$D$2+$E$2+$F$2+$A14,E$3)) -> 866.38555 | K15: =AVERAGE(OFFSET('t2688'!$A$1,$B$2+($B15-1)*$D$2+$E$2+$A14+1,E$3):OFFSET('t2688'!$A$1,$B$2+($B15-1)*$D$2+$E$2+$F$2+$A14,E$3)) -> 1666.7784 | L15: =AVERAGE(OFFSET('t5376'!$A$1,$B$2+($B15-1)*$D$2+$E$2+$A14+1,E$3):OFFSET('t5376'!$A$1,$B$2+($B15-1)*$D$2+$E$2+$F$2+$A14,E$3)) -> 3368.9 | M15: =AVERAGE(OFFSET('t10752'!$A$1,$B$2+($B15-1)*$D$2+$E$2+$A14+1,E$3):OFFSET('t10752'!$A$1,$B$2+($B15-1)*$D$2+$E$2+$F$2+$A14,E$3)) -> 6953.3171 | N15: =AVERAGE(OFFSET('t21504'!$A$1,$B$2+($B15-1)*$D$2+$E$2+$A14+1,E$3):OFFSET('t21504'!$A$1,$B$2+($B15-1)*$D$2+$E$2+$F$2+$A14,E$3)) -> 13610.731 | O15: =AVERAGE(OFFSET('t43008'!$A$1,$B$2+($B15-1)*$D$2+$E$2+$A14+1,E$3):OFFSET('t43008'!$A$1,$B$2+($B15-1)*$D$2+$E$2+$F$2+$A14,E$3)) -> 27490.553 | P15: =AVERAGE(OFFSET('t86016'!$A$1,$B$2+($B15-1)*$D$2+$E$2+$A14+1,E$3):OFFSET('t86016'!$A$1,$B$2+($B15-1)*$D$2+$E$2+$F$2+$A14,E$3)) -> 55914.949 | Q15: =AVERAGE(OFFSET('t172032'!$A$1,$B$2+($B15-1)*$D$2+$E$2+$A14+1,E$3):OFFSET('t172032'!$A$1,$B$2+($B15-1)*$D$2+$E$2+$F$2+$A14,E$3)) -> 113327.53 | R15: =AVERAGE(OFFSET('t344064'!$A$1,$B$2+($B15-1)*$D$2+$E$2+$A14+1,E$3):OFFSET('t344064'!$A$1,$B$2+($B15-1)*$D$2+$E$2+$F$2+$A14,E$3)) -> #DIV/0! | S15: =AVERAGE(OFFSET('t688128'!$A$1,$B$2+($B15-1)*$D$2+$E$2+$A14+1,E$3):OFFSET('t688128'!$A$1,$B$2+($B15-1)*$D$2+$E$2+$F$2+$A14,E$3)) -> #DIV/0! | T15: =AVERAGE(OFFSET(t1376256!$A$1,$B$2+($B15-1)*$D$2+$E$2+$A14+1,E$3):OFFSET(t1376256!$A$1,$B$2+($B15-1)*$D$2+$E$2+$F$2+$A14,E$3)) -> #DIV/0!
A16: 3 | B16: 13 | C16: 128 | D16: =OFFSET('t42'!$A$1,$B$2+($B16-1)*$D$2+$A16,D$3) -> 43.549 | E16: =AVERAGE(OFFSET('t42'!$A$1,$B$2+($B16-1)*$D$2+$E$2+$A16,E$3):OFFSET('t42'!$A$1,$B$2+($B16-1)*$D$2+$E$2+$F$2+$A16,E$3)) -> 45.378484 | F16: =AVERAGE(OFFSET('t84'!$A$1,$B$2+($B16-1)*$D$2+$E$2+$A16,E$3):OFFSET('t84'!$A$1,$B$2+($B16-1)*$D$2+$E$2+$F$2+$A16,E$3)) -> 60.429126 | G16: =AVERAGE(OFFSET('t168'!$A$1,$B$2+($B16-1)*$D$2+$E$2+$A16,E$3):OFFSET('t168'!$A$1,$B$2+($B16-1)*$D$2+$E$2+$F$2+$A16,E$3)) -> 114.31828 | H16: =AVERAGE(OFFSET('t336'!$A$1,$B$2+($B16-1)*$D$2+$E$2+$A16,E$3):OFFSET('t336'!$A$1,$B$2+($B16-1)*$D$2+$E$2+$F$2+$A16,E$3)) -> 144.97436 | I16: =AVERAGE(OFFSET('t672'!$A$1,$B$2+($B16-1)*$D$2+$E$2+$A16,E$3):OFFSET('t672'!$A$1,$B$2+($B16-1)*$D$2+$E$2+$F$2+$A16,E$3)) -> 180.323 | J16: =AVERAGE(OFFSET('t1344'!$A$1,$B$2+($B16-1)*$D$2+$E$2+$A16,E$3):OFFSET('t1344'!$A$1,$B$2+($B16-1)*$D$2+$E$2+$F$2+$A16,E$3)) -> 264.07746 | K16: =AVERAGE(OFFSET('t2688'!$A$1,$B$2+($B16-1)*$D$2+$E$2+$A16,E$3):OFFSET('t2688'!$A$1,$B$2+($B16-1)*$D$2+$E$2+$F$2+$A16,E$3)) -> 471.68424 | L16: =AVERAGE(OFFSET('t5376'!$A$1,$B$2+($B16-1)*$D$2+$E$2+$A16,E$3):OFFSET('t5376'!$A$1,$B$2+($B16-1)*$D$2+$E$2+$F$2+$A16,E$3)) -> 1039.9108 | M16: =AVERAGE(OFFSET('t10752'!$A$1,$B$2+($B16-1)*$D$2+$E$2+$A16,E$3):OFFSET('t10752'!$A$1,$B$2+($B16-1)*$D$2+$E$2+$F$2+$A16,E$3)) -> 2381.8232 | N16: =AVERAGE(OFFSET('t21504'!$A$1,$B$2+($B16-1)*$D$2+$E$2+$A16,E$3):OFFSET('t21504'!$A$1,$B$2+($B16-1)*$D$2+$E$2+$F$2+$A16,E$3)) -> 4714.7742 | O16: =AVERAGE(OFFSET('t43008'!$A$1,$B$2+($B16-1)*$D$2+$E$2+$A16,E$3):OFFSET('t43008'!$A$1,$B$2+($B16-1)*$D$2+$E$2+$F$2+$A16,E$3)) -> 8872.5884 | P16: =AVERAGE(OFFSET('t86016'!$A$1,$B$2+($B16-1)*$D$2+$E$2+$A16,E$3):OFFSET('t86016'!$A$1,$B$2+($B16-1)*$D$2+$E$2+$F$2+$A16,E$3)) -> 23164.07 | Q16: =AVERAGE(OFFSET('t172032'!$A$1,$B$2+($B16-1)*$D$2+$E$2+$A16,E$3):OFFSET('t172032'!$A$1,$B$2+($B16-1)*$D$2+$E$2+$F$2+$A16,E$3)) -> 41675.328 | R16: =AVERAGE(OFFSET('t344064'!$A$1,$B$2+($B16-1)*$D$2+$E$2+$A16,E$3):OFFSET('t344064'!$A$1,$B$2+($B16-1)*$D$2+$E$2+$F$2+$A16,E$3)) -> #DIV/0! | S16: =AVERAGE(OFFSET('t688128'!$A$1,$B$2+($B16-1)*$D$2+$E$2+$A16,E$3):OFFSET('t688128'!$A$1,$B$2+($B16-1)*$D$2+$E$2+$F$2+$A16,E$3)) -> #DIV/0! | T16: =AVERAGE(OFFSET(t1376256!$A$1,$B$2+($B16-1)*$D$2+$E$2+$A16,E$3):OFFSET(t1376256!$A$1,$B$2+($B16-1)*$D$2+$E$2+$F$2+$A16,E$3)) -> #DIV/0! | X16: 10 | Y16: << "MIN=" << metrics.min_fitness << " "
A17: 3 | B17: 14 | D17: =OFFSET('t42'!$A$1,$B$2+($B17-1)*$D$2+$A16,D$3) -> 47.4078 | E17: =AVERAGE(OFFSET('t42'!$A$1,$B$2+($B17-1)*$D$2+$E$2+$A16+1,E$3):OFFSET('t42'!$A$1,$B$2+($B17-1)*$D$2+$E$2+$F$2+$A16,E$3)) -> 46.032992 | F17: =AVERAGE(OFFSET('t84'!$A$1,$B$2+($B17-1)*$D$2+$E$2+$A16+1,E$3):OFFSET('t84'!$A$1,$B$2+($B17-1)*$D$2+$E$2+$F$2+$A16,E$3)) -> 61.35128 | G17: =AVERAGE(OFFSET('t168'!$A$1,$B$2+($B17-1)*$D$2+$E$2+$A16+1,E$3):OFFSET('t168'!$A$1,$B$2+($B17-1)*$D$2+$E$2+$F$2+$A16,E$3)) -> 116.497 | H17: =AVERAGE(OFFSET('t336'!$A$1,$B$2+($B17-1)*$D$2+$E$2+$A16+1,E$3):OFFSET('t336'!$A$1,$B$2+($B17-1)*$D$2+$E$2+$F$2+$A16,E$3)) -> 147.07861 | I17: =AVERAGE(OFFSET('t672'!$A$1,$B$2+($B17-1)*$D$2+$E$2+$A16+1,E$3):OFFSET('t672'!$A$1,$B$2+($B17-1)*$D$2+$E$2+$F$2+$A16,E$3)) -> 186.08586 | J17: =AVERAGE(OFFSET('t1344'!$A$1,$B$2+($B17-1)*$D$2+$E$2+$A16+1,E$3):OFFSET('t1344'!$A$1,$B$2+($B17-1)*$D$2+$E$2+$F$2+$A16,E$3)) -> 264.85984 | K17: =AVERAGE(OFFSET('t2688'!$A$1,$B$2+($B17-1)*$D$2+$E$2+$A16+1,E$3):OFFSET('t2688'!$A$1,$B$2+($B17-1)*$D$2+$E$2+$F$2+$A16,E$3)) -> 474.1712 | L17: =AVERAGE(OFFSET('t5376'!$A$1,$B$2+($B17-1)*$D$2+$E$2+$A16+1,E$3):OFFSET('t5376'!$A$1,$B$2+($B17-1)*$D$2+$E$2+$F$2+$A16,E$3)) -> 1042.2182 | M17: =AVERAGE(OFFSET('t10752'!$A$1,$B$2+($B17-1)*$D$2+$E$2+$A16+1,E$3):OFFSET('t10752'!$A$1,$B$2+($B17-1)*$D$2+$E$2+$F$2+$A16,E$3)) -> 2381.8059 | N17: =AVERAGE(OFFSET('t21504'!$A$1,$B$2+($B17-1)*$D$2+$E$2+$A16+1,E$3):OFFSET('t21504'!$A$1,$B$2+($B17-1)*$D$2+$E$2+$F$2+$A16,E$3)) -> 4714.7402 | O17: =AVERAGE(OFFSET('t43008'!$A$1,$B$2+($B17-1)*$D$2+$E$2+$A16+1,E$3):OFFSET('t43008'!$A$1,$B$2+($B17-1)*$D$2+$E$2+$F$2+$A16,E$3)) -> 8882.6873 | P17: =AVERAGE(OFFSET('t86016'!$A$1,$B$2+($B17-1)*$D$2+$E$2+$A16+1,E$3):OFFSET('t86016'!$A$1,$B$2+($B17-1)*$D$2+$E$2+$F$2+$A16,E$3)) -> 23167.627 | Q17: =AVERAGE(OFFSET('t172032'!$A$1,$B$2+($B17-1)*$D$2+$E$2+$A16+1,E$3):OFFSET('t172032'!$A$1,$B$2+($B17-1)*$D$2+$E$2+$F$2+$A16,E$3)) -> 41677.551 | R17: =AVERAGE(OFFSET('t344064'!$A$1,$B$2+($B17-1)*$D$2+$E$2+$A16+1,E$3):OFFSET('t344064'!$A$1,$B$2+($B17-1)*$D$2+$E$2+$F$2+$A16,E$3)) -> #DIV/0! | S17: =AVERAGE(OFFSET('t688128'!$A$1,$B$2+($B17-1)*$D$2+$E$2+$A16+1,E$3):OFFSET('t688128'!$A$1,$B$2+($B17-1)*$D$2+$E$2+$F$2+$A16,E$3)) -> #DIV/0! | T17: =AVERAGE(OFFSET(t1376256!$A$1,$B$2+($B17-1)*$D$2+$E$2+$A16+1,E$3):OFFSET(t1376256!$A$1,$B$2+($B17-1)*$D$2+$E$2+$F$2+$A16,E$3)) -> #DIV/0! | X17: 11 | Y17: << "MAX=" << metrics.max_fitness << " "
A18: 3 | B18: 15 | D18: =OFFSET('t42'!$A$1,$B$2+($B18-1)*$D$2+$A16,D$3) -> 33.7382 | E18: =AVERAGE(OFFSET('t42'!$A$1,$B$2+($B18-1)*$D$2+$E$2+$A17+1,E$3):OFFSET('t42'!$A$1,$B$2+($B18-1)*$D$2+$E$2+$F$2+$A17,E$3)) -> 34.103773 | F18: =AVERAGE(OFFSET('t84'!$A$1,$B$2+($B18-1)*$D$2+$E$2+$A17+1,E$3):OFFSET('t84'!$A$1,$B$2+($B18-1)*$D$2+$E$2+$F$2+$A17,E$3)) -> 52.602939 | G18: =AVERAGE(OFFSET('t168'!$A$1,$B$2+($B18-1)*$D$2+$E$2+$A17+1,E$3):OFFSET('t168'!$A$1,$B$2+($B18-1)*$D$2+$E$2+$F$2+$A17,E$3)) -> 126.7788 | H18: =AVERAGE(OFFSET('t336'!$A$1,$B$2+($B18-1)*$D$2+$E$2+$A17+1,E$3):OFFSET('t336'!$A$1,$B$2+($B18-1)*$D$2+$E$2+$F$2+$A17,E$3)) -> 164.21649 | I18: =AVERAGE(OFFSET('t672'!$A$1,$B$2+($B18-1)*$D$2+$E$2+$A17+1,E$3):OFFSET('t672'!$A$1,$B$2+($B18-1)*$D$2+$E$2+$F$2+$A17,E$3)) -> 202.10276 | J18: =AVERAGE(OFFSET('t1344'!$A$1,$B$2+($B18-1)*$D$2+$E$2+$A17+1,E$3):OFFSET('t1344'!$A$1,$B$2+($B18-1)*$D$2+$E$2+$F$2+$A17,E$3)) -> 289.48602 | K18: =AVERAGE(OFFSET('t2688'!$A$1,$B$2+($B18-1)*$D$2+$E$2+$A17+1,E$3):OFFSET('t2688'!$A$1,$B$2+($B18-1)*$D$2+$E$2+$F$2+$A17,E$3)) -> 501.37588 | L18: =AVERAGE(OFFSET('t5376'!$A$1,$B$2+($B18-1)*$D$2+$E$2+$A17+1,E$3):OFFSET('t5376'!$A$1,$B$2+($B18-1)*$D$2+$E$2+$F$2+$A17,E$3)) -> 1036.7796 | M18: =AVERAGE(OFFSET('t10752'!$A$1,$B$2+($B18-1)*$D$2+$E$2+$A17+1,E$3):OFFSET('t10752'!$A$1,$B$2+($B18-1)*$D$2+$E$2+$F$2+$A17,E$3)) -> 2406.0961 | N18: =AVERAGE(OFFSET('t21504'!$A$1,$B$2+($B18-1)*$D$2+$E$2+$A17+1,E$3):OFFSET('t21504'!$A$1,$B$2+($B18-1)*$D$2+$E$2+$F$2+$A17,E$3)) -> 4747.4859 | O18: =AVERAGE(OFFSET('t43008'!$A$1,$B$2+($B18-1)*$D$2+$E$2+$A17+1,E$3):OFFSET('t43008'!$A$1,$B$2+($B18-1)*$D$2+$E$2+$F$2+$A17,E$3)) -> 9154.982 | P18: =AVERAGE(OFFSET('t86016'!$A$1,$B$2+($B18-1)*$D$2+$E$2+$A17+1,E$3):OFFSET('t86016'!$A$1,$B$2+($B18-1)*$D$2+$E$2+$F$2+$A17,E$3)) -> 23338.443 | Q18: =AVERAGE(OFFSET('t172032'!$A$1,$B$2+($B18-1)*$D$2+$E$2+$A17+1,E$3):OFFSET('t172032'!$A$1,$B$2+($B18-1)*$D$2+$E$2+$F$2+$A17,E$3)) -> 41752.071 | R18: =AVERAGE(OFFSET('t344064'!$A$1,$B$2+($B18-1)*$D$2+$E$2+$A17+1,E$3):OFFSET('t344064'!$A$1,$B$2+($B18-1)*$D$2+$E$2+$F$2+$A17,E$3)) -> #DIV/0! | S18: =AVERAGE(OFFSET('t688128'!$A$1,$B$2+($B18-1)*$D$2+$E$2+$A17+1,E$3):OFFSET('t688128'!$A$1,$B$2+($B18-1)*$D$2+$E$2+$F$2+$A17,E$3)) -> #DIV/0! | T18: =AVERAGE(OFFSET(t1376256!$A$1,$B$2+($B18-1)*$D$2+$E$2+$A17+1,E$3):OFFSET(t1376256!$A$1,$B$2+($B18-1)*$D$2+$E$2+$F$2+$A17,E$3)) -> #DIV/0!
A19: 3 | B19: 16 | D19: =OFFSET('t42'!$A$1,$B$2+($B19-1)*$D$2+$A17,D$3) -> 86.441 | E19: =AVERAGE(OFFSET('t42'!$A$1,$B$2+($B19-1)*$D$2+$E$2+$A18+1,E$3):OFFSET('t42'!$A$1,$B$2+($B19-1)*$D$2+$E$2+$F$2+$A18,E$3)) -> 90.271751 | F19: =AVERAGE(OFFSET('t84'!$A$1,$B$2+($B19-1)*$D$2+$E$2+$A18+1,E$3):OFFSET('t84'!$A$1,$B$2+($B19-1)*$D$2+$E$2+$F$2+$A18,E$3)) -> 108.92739 | G19: =AVERAGE(OFFSET('t168'!$A$1,$B$2+($B19-1)*$D$2+$E$2+$A18+1,E$3):OFFSET('t168'!$A$1,$B$2+($B19-1)*$D$2+$E$2+$F$2+$A18,E$3)) -> 138.72776 | H19: =AVERAGE(OFFSET('t336'!$A$1,$B$2+($B19-1)*$D$2+$E$2+$A18+1,E$3):OFFSET('t336'!$A$1,$B$2+($B19-1)*$D$2+$E$2+$F$2+$A18,E$3)) -> 270.11124 | I19: =AVERAGE(OFFSET('t672'!$A$1,$B$2+($B19-1)*$D$2+$E$2+$A18+1,E$3):OFFSET('t672'!$A$1,$B$2+($B19-1)*$D$2+$E$2+$F$2+$A18,E$3)) -> 473.47702 | J19: =AVERAGE(OFFSET('t1344'!$A$1,$B$2+($B19-1)*$D$2+$E$2+$A18+1,E$3):OFFSET('t1344'!$A$1,$B$2+($B19-1)*$D$2+$E$2+$F$2+$A18,E$3)) -> 871.14239 | K19: =AVERAGE(OFFSET('t2688'!$A$1,$B$2+($B19-1)*$D$2+$E$2+$A18+1,E$3):OFFSET('t2688'!$A$1,$B$2+($B19-1)*$D$2+$E$2+$F$2+$A18,E$3)) -> 1673.3896 | L19: =AVERAGE(OFFSET('t5376'!$A$1,$B$2+($B19-1)*$D$2+$E$2+$A18+1,E$3):OFFSET('t5376'!$A$1,$B$2+($B19-1)*$D$2+$E$2+$F$2+$A18,E$3)) -> 3424.9986 | M19: =AVERAGE(OFFSET('t10752'!$A$1,$B$2+($B19-1)*$D$2+$E$2+$A18+1,E$3):OFFSET('t10752'!$A$1,$B$2+($B19-1)*$D$2+$E$2+$F$2+$A18,E$3)) -> 7111.9247 | N19: =AVERAGE(OFFSET('t21504'!$A$1,$B$2+($B19-1)*$D$2+$E$2+$A18+1,E$3):OFFSET('t21504'!$A$1,$B$2+($B19-1)*$D$2+$E$2+$F$2+$A18,E$3)) -> 13882.651 | O19: =AVERAGE(OFFSET('t43008'!$A$1,$B$2+($B19-1)*$D$2+$E$2+$A18+1,E$3):OFFSET('t43008'!$A$1,$B$2+($B19-1)*$D$2+$E$2+$F$2+$A18,E$3)) -> 28022.704 | P19: =AVERAGE(OFFSET('t86016'!$A$1,$B$2+($B19-1)*$D$2+$E$2+$A18+1,E$3):OFFSET('t86016'!$A$1,$B$2+($B19-1)*$D$2+$E$2+$F$2+$A18,E$3)) -> 56738.584 | Q19: =AVERAGE(OFFSET('t172032'!$A$1,$B$2+($B19-1)*$D$2+$E$2+$A18+1,E$3):OFFSET('t172032'!$A$1,$B$2+($B19-1)*$D$2+$E$2+$F$2+$A18,E$3)) -> 114349.67 | R19: =AVERAGE(OFFSET('t344064'!$A$1,$B$2+($B19-1)*$D$2+$E$2+$A18+1,E$3):OFFSET('t344064'!$A$1,$B$2+($B19-1)*$D$2+$E$2+$F$2+$A18,E$3)) -> #DIV/0! | S19: =AVERAGE(OFFSET('t688128'!$A$1,$B$2+($B19-1)*$D$2+$E$2+$A18+1,E$3):OFFSET('t688128'!$A$1,$B$2+($B19-1)*$D$2+$E$2+$F$2+$A18,E$3)) -> #DIV/0! | T19: =AVERAGE(OFFSET(t1376256!$A$1,$B$2+($B19-1)*$D$2+$E$2+$A18+1,E$3):OFFSET(t1376256!$A$1,$B$2+($B19-1)*$D$2+$E$2+$F$2+$A18,E$3)) -> #DIV/0!
A20: 4 | B20: 17 | C20: 256 | D20: =OFFSET('t42'!$A$1,$B$2+($B20-1)*$D$2+$A20,D$3) -> 45.4056 | E20: =AVERAGE(OFFSET('t42'!$A$1,$B$2+($B20-1)*$D$2+$E$2+$A20,E$3):OFFSET('t42'!$A$1,$B$2+($B20-1)*$D$2+$E$2+$F$2+$A20,E$3)) -> 43.271462 | F20: =AVERAGE(OFFSET('t84'!$A$1,$B$2+($B20-1)*$D$2+$E$2+$A20,E$3):OFFSET('t84'!$A$1,$B$2+($B20-1)*$D$2+$E$2+$F$2+$A20,E$3)) -> 64.32148 | G20: =AVERAGE(OFFSET('t168'!$A$1,$B$2+($B20-1)*$D$2+$E$2+$A20,E$3):OFFSET('t168'!$A$1,$B$2+($B20-1)*$D$2+$E$2+$F$2+$A20,E$3)) -> 122.9774 | H20: =AVERAGE(OFFSET('t336'!$A$1,$B$2+($B20-1)*$D$2+$E$2+$A20,E$3):OFFSET('t336'!$A$1,$B$2+($B20-1)*$D$2+$E$2+$F$2+$A20,E$3)) -> 172.13972 | I20: =AVERAGE(OFFSET('t672'!$A$1,$B$2+($B20-1)*$D$2+$E$2+$A20,E$3):OFFSET('t672'!$A$1,$B$2+($B20-1)*$D$2+$E$2+$F$2+$A20,E$3)) -> 233.32184 | J20: =AVERAGE(OFFSET('t1344'!$A$1,$B$2+($B20-1)*$D$2+$E$2+$A20,E$3):OFFSET('t1344'!$A$1,$B$2+($B20-1)*$D$2+$E$2+$F$2+$A20,E$3)) -> 395.14108 | K20: =AVERAGE(OFFSET('t2688'!$A$1,$B$2+($B20-1)*$D$2+$E$2+$A20,E$3):OFFSET('t2688'!$A$1,$B$2+($B20-1)*$D$2+$E$2+$F$2+$A20,E$3)) -> 765.17808 | L20: =AVERAGE(OFFSET('t5376'!$A$1,$B$2+($B20-1)*$D$2+$E$2+$A20,E$3):OFFSET('t5376'!$A$1,$B$2+($B20-1)*$D$2+$E$2+$F$2+$A20,E$3)) -> 1575.636 | M20: =AVERAGE(OFFSET('t10752'!$A$1,$B$2+($B20-1)*$D$2+$E$2+$A20,E$3):OFFSET('t10752'!$A$1,$B$2+($B20-1)*$D$2+$E$2+$F$2+$A20,E$3)) -> 3610.951 | N20: =AVERAGE(OFFSET('t21504'!$A$1,$B$2+($B20-1)*$D$2+$E$2+$A20,E$3):OFFSET('t21504'!$A$1,$B$2+($B20-1)*$D$2+$E$2+$F$2+$A20,E$3)) -> 7585.805 | O20: =AVERAGE(OFFSET('t43008'!$A$1,$B$2+($B20-1)*$D$2+$E$2+$A20,E$3):OFFSET('t43008'!$A$1,$B$2+($B20-1)*$D$2+$E$2+$F$2+$A20,E$3)) -> 15028.086 | P20: =AVERAGE(OFFSET('t86016'!$A$1,$B$2+($B20-1)*$D$2+$E$2+$A20,E$3):OFFSET('t86016'!$A$1,$B$2+($B20-1)*$D$2+$E$2+$F$2+$A20,E$3)) -> 40880.124 | Q20: =AVERAGE(OFFSET('t172032'!$A$1,$B$2+($B20-1)*$D$2+$E$2+$A20,E$3):OFFSET('t172032'!$A$1,$B$2+($B20-1)*$D$2+$E$2+$F$2+$A20,E$3)) -> 103229.2 | R20: =AVERAGE(OFFSET('t344064'!$A$1,$B$2+($B20-1)*$D$2+$E$2+$A20,E$3):OFFSET('t344064'!$A$1,$B$2+($B20-1)*$D$2+$E$2+$F$2+$A20,E$3)) -> #DIV/0! | S20: =AVERAGE(OFFSET('t688128'!$A$1,$B$2+($B20-1)*$D$2+$E$2+$A20,E$3):OFFSET('t688128'!$A$1,$B$2+($B20-1)*$D$2+$E$2+$F$2+$A20,E$3)) -> #DIV/0! | T20: =AVERAGE(OFFSET(t1376256!$A$1,$B$2+($B20-1)*$D$2+$E$2+$A20,E$3):OFFSET(t1376256!$A$1,$B$2+($B20-1)*$D$2+$E$2+$F$2+$A20,E$3)) -> #DIV/0!
A21: 4 | B21: 18 | D21: =OFFSET('t42'!$A$1,$B$2+($B21-1)*$D$2+$A20,D$3) -> 53.4414 | E21: =AVERAGE(OFFSET('t42'!$A$1,$B$2+($B21-1)*$D$2+$E$2+$A20+1,E$3):OFFSET('t42'!$A$1,$B$2+($B21-1)*$D$2+$E$2+$F$2+$A20,E$3)) -> 46.027659 | F21: =AVERAGE(OFFSET('t84'!$A$1,$B$2+($B21-1)*$D$2+$E$2+$A20+1,E$3):OFFSET('t84'!$A$1,$B$2+($B21-1)*$D$2+$E$2+$F$2+$A20,E$3)) -> 64.59312 | G21: =AVERAGE(OFFSET('t168'!$A$1,$B$2+($B21-1)*$D$2+$E$2+$A20+1,E$3):OFFSET('t168'!$A$1,$B$2+($B21-1)*$D$2+$E$2+$F$2+$A20,E$3)) -> 125.71239 | H21: =AVERAGE(OFFSET('t336'!$A$1,$B$2+($B21-1)*$D$2+$E$2+$A20+1,E$3):OFFSET('t336'!$A$1,$B$2+($B21-1)*$D$2+$E$2+$F$2+$A20,E$3)) -> 180.48459 | I21: =AVERAGE(OFFSET('t672'!$A$1,$B$2+($B21-1)*$D$2+$E$2+$A20+1,E$3):OFFSET('t672'!$A$1,$B$2+($B21-1)*$D$2+$E$2+$F$2+$A20,E$3)) -> 235.513 | J21: =AVERAGE(OFFSET('t1344'!$A$1,$B$2+($B21-1)*$D$2+$E$2+$A20+1,E$3):OFFSET('t1344'!$A$1,$B$2+($B21-1)*$D$2+$E$2+$F$2+$A20,E$3)) -> 397.625 | K21: =AVERAGE(OFFSET('t2688'!$A$1,$B$2+($B21-1)*$D$2+$E$2+$A20+1,E$3):OFFSET('t2688'!$A$1,$B$2+($B21-1)*$D$2+$E$2+$F$2+$A20,E$3)) -> 766.49478 | L21: =AVERAGE(OFFSET('t5376'!$A$1,$B$2+($B21-1)*$D$2+$E$2+$A20+1,E$3):OFFSET('t5376'!$A$1,$B$2+($B21-1)*$D$2+$E$2+$F$2+$A20,E$3)) -> 1579.2655 | M21: =AVERAGE(OFFSET('t10752'!$A$1,$B$2+($B21-1)*$D$2+$E$2+$A20+1,E$3):OFFSET('t10752'!$A$1,$B$2+($B21-1)*$D$2+$E$2+$F$2+$A20,E$3)) -> 3613.8531 | N21: =AVERAGE(OFFSET('t21504'!$A$1,$B$2+($B21-1)*$D$2+$E$2+$A20+1,E$3):OFFSET('t21504'!$A$1,$B$2+($B21-1)*$D$2+$E$2+$F$2+$A20,E$3)) -> 7587.8043 | O21: =AVERAGE(OFFSET('t43008'!$A$1,$B$2+($B21-1)*$D$2+$E$2+$A20+1,E$3):OFFSET('t43008'!$A$1,$B$2+($B21-1)*$D$2+$E$2+$F$2+$A20,E$3)) -> 15032.922 | P21: =AVERAGE(OFFSET('t86016'!$A$1,$B$2+($B21-1)*$D$2+$E$2+$A20+1,E$3):OFFSET('t86016'!$A$1,$B$2+($B21-1)*$D$2+$E$2+$F$2+$A20,E$3)) -> 40838.822 | Q21: =AVERAGE(OFFSET('t172032'!$A$1,$B$2+($B21-1)*$D$2+$E$2+$A20+1,E$3):OFFSET('t172032'!$A$1,$B$2+($B21-1)*$D$2+$E$2+$F$2+$A20,E$3)) -> 103212.18 | R21: =AVERAGE(OFFSET('t344064'!$A$1,$B$2+($B21-1)*$D$2+$E$2+$A20+1,E$3):OFFSET('t344064'!$A$1,$B$2+($B21-1)*$D$2+$E$2+$F$2+$A20,E$3)) -> #DIV/0! | S21: =AVERAGE(OFFSET('t688128'!$A$1,$B$2+($B21-1)*$D$2+$E$2+$A20+1,E$3):OFFSET('t688128'!$A$1,$B$2+($B21-1)*$D$2+$E$2+$F$2+$A20,E$3)) -> #DIV/0! | T21: =AVERAGE(OFFSET(t1376256!$A$1,$B$2+($B21-1)*$D$2+$E$2+$A20+1,E$3):OFFSET(t1376256!$A$1,$B$2+($B21-1)*$D$2+$E$2+$F$2+$A20,E$3)) -> #DIV/0!
A22: 4 | B22: 19 | D22: =OFFSET('t42'!$A$1,$B$2+($B22-1)*$D$2+$A20,D$3) -> 34.6682 | E22: =AVERAGE(OFFSET('t42'!$A$1,$B$2+($B22-1)*$D$2+$E$2+$A21+1,E$3):OFFSET('t42'!$A$1,$B$2+($B22-1)*$D$2+$E$2+$F$2+$A21,E$3)) -> 34.159253 | F22: =AVERAGE(OFFSET('t84'!$A$1,$B$2+($B22-1)*$D$2+$E$2+$A21+1,E$3):OFFSET('t84'!$A$1,$B$2+($B22-1)*$D$2+$E$2+$F$2+$A21,E$3)) -> 55.533386 | G22: =AVERAGE(OFFSET('t168'!$A$1,$B$2+($B22-1)*$D$2+$E$2+$A21+1,E$3):OFFSET('t168'!$A$1,$B$2+($B22-1)*$D$2+$E$2+$F$2+$A21,E$3)) -> 134.69939 | H22: =AVERAGE(OFFSET('t336'!$A$1,$B$2+($B22-1)*$D$2+$E$2+$A21+1,E$3):OFFSET('t336'!$A$1,$B$2+($B22-1)*$D$2+$E$2+$F$2+$A21,E$3)) -> 199.92682 | I22: =AVERAGE(OFFSET('t672'!$A$1,$B$2+($B22-1)*$D$2+$E$2+$A21+1,E$3):OFFSET('t672'!$A$1,$B$2+($B22-1)*$D$2+$E$2+$F$2+$A21,E$3)) -> 261.07847 | J22: =AVERAGE(OFFSET('t1344'!$A$1,$B$2+($B22-1)*$D$2+$E$2+$A21+1,E$3):OFFSET('t1344'!$A$1,$B$2+($B22-1)*$D$2+$E$2+$F$2+$A21,E$3)) -> 422.2478 | K22: =AVERAGE(OFFSET('t2688'!$A$1,$B$2+($B22-1)*$D$2+$E$2+$A21+1,E$3):OFFSET('t2688'!$A$1,$B$2+($B22-1)*$D$2+$E$2+$F$2+$A21,E$3)) -> 794.97843 | L22: =AVERAGE(OFFSET('t5376'!$A$1,$B$2+($B22-1)*$D$2+$E$2+$A21+1,E$3):OFFSET('t5376'!$A$1,$B$2+($B22-1)*$D$2+$E$2+$F$2+$A21,E$3)) -> 1575.8457 | M22: =AVERAGE(OFFSET('t10752'!$A$1,$B$2+($B22-1)*$D$2+$E$2+$A21+1,E$3):OFFSET('t10752'!$A$1,$B$2+($B22-1)*$D$2+$E$2+$F$2+$A21,E$3)) -> 3640.0829 | N22: =AVERAGE(OFFSET('t21504'!$A$1,$B$2+($B22-1)*$D$2+$E$2+$A21+1,E$3):OFFSET('t21504'!$A$1,$B$2+($B22-1)*$D$2+$E$2+$F$2+$A21,E$3)) -> 7624.1973 | O22: =AVERAGE(OFFSET('t43008'!$A$1,$B$2+($B22-1)*$D$2+$E$2+$A21+1,E$3):OFFSET('t43008'!$A$1,$B$2+($B22-1)*$D$2+$E$2+$F$2+$A21,E$3)) -> 15314.094 | P22: =AVERAGE(OFFSET('t86016'!$A$1,$B$2+($B22-1)*$D$2+$E$2+$A21+1,E$3):OFFSET('t86016'!$A$1,$B$2+($B22-1)*$D$2+$E$2+$F$2+$A21,E$3)) -> 41046.51 | Q22: =AVERAGE(OFFSET('t172032'!$A$1,$B$2+($B22-1)*$D$2+$E$2+$A21+1,E$3):OFFSET('t172032'!$A$1,$B$2+($B22-1)*$D$2+$E$2+$F$2+$A21,E$3)) -> 103513.9 | R22: =AVERAGE(OFFSET('t344064'!$A$1,$B$2+($B22-1)*$D$2+$E$2+$A21+1,E$3):OFFSET('t344064'!$A$1,$B$2+($B22-1)*$D$2+$E$2+$F$2+$A21,E$3)) -> #DIV/0! | S22: =AVERAGE(OFFSET('t688128'!$A$1,$B$2+($B22-1)*$D$2+$E$2+$A21+1,E$3):OFFSET('t688128'!$A$1,$B$2+($B22-1)*$D$2+$E$2+$F$2+$A21,E$3)) -> #DIV/0! | T22: =AVERAGE(OFFSET(t1376256!$A$1,$B$2+($B22-1)*$D$2+$E$2+$A21+1,E$3):OFFSET(t1376256!$A$1,$B$2+($B22-1)*$D$2+$E$2+$F$2+$A21,E$3)) -> #DIV/0!
A23: 4 | B23: 20 | D23: =OFFSET('t42'!$A$1,$B$2+($B23-1)*$D$2+$A21,D$3) -> 88.4163 | E23: =AVERAGE(OFFSET('t42'!$A$1,$B$2+($B23-1)*$D$2+$E$2+$A22+1,E$3):OFFSET('t42'!$A$1,$B$2+($B23-1)*$D$2+$E$2+$F$2+$A22,E$3)) -> 89.133555 | F23: =AVERAGE(OFFSET('t84'!$A$1,$B$2+($B23-1)*$D$2+$E$2+$A22+1,E$3):OFFSET('t84'!$A$1,$B$2+($B23-1)*$D$2+$E$2+$F$2+$A22,E$3)) -> 103.56423 | G23: =AVERAGE(OFFSET('t168'!$A$1,$B$2+($B23-1)*$D$2+$E$2+$A22+1,E$3):OFFSET('t168'!$A$1,$B$2+($B23-1)*$D$2+$E$2+$F$2+$A22,E$3)) -> 117.01549 | H23: =AVERAGE(OFFSET('t336'!$A$1,$B$2+($B23-1)*$D$2+$E$2+$A22+1,E$3):OFFSET('t336'!$A$1,$B$2+($B23-1)*$D$2+$E$2+$F$2+$A22,E$3)) -> 195.32314 | I23: =AVERAGE(OFFSET('t672'!$A$1,$B$2+($B23-1)*$D$2+$E$2+$A22+1,E$3):OFFSET('t672'!$A$1,$B$2+($B23-1)*$D$2+$E$2+$F$2+$A22,E$3)) -> 313.40312 | J23: =AVERAGE(OFFSET('t1344'!$A$1,$B$2+($B23-1)*$D$2+$E$2+$A22+1,E$3):OFFSET('t1344'!$A$1,$B$2+($B23-1)*$D$2+$E$2+$F$2+$A22,E$3)) -> 552.29469 | K23: =AVERAGE(OFFSET('t2688'!$A$1,$B$2+($B23-1)*$D$2+$E$2+$A22+1,E$3):OFFSET('t2688'!$A$1,$B$2+($B23-1)*$D$2+$E$2+$F$2+$A22,E$3)) -> 1030.0312 | L23: =AVERAGE(OFFSET('t5376'!$A$1,$B$2+($B23-1)*$D$2+$E$2+$A22+1,E$3):OFFSET('t5376'!$A$1,$B$2+($B23-1)*$D$2+$E$2+$F$2+$A22,E$3)) -> 2166.1196 | M23: =AVERAGE(OFFSET('t10752'!$A$1,$B$2+($B23-1)*$D$2+$E$2+$A22+1,E$3):OFFSET('t10752'!$A$1,$B$2+($B23-1)*$D$2+$E$2+$F$2+$A22,E$3)) -> 4644.0039 | N23: =AVERAGE(OFFSET('t21504'!$A$1,$B$2+($B23-1)*$D$2+$E$2+$A22+1,E$3):OFFSET('t21504'!$A$1,$B$2+($B23-1)*$D$2+$E$2+$F$2+$A22,E$3)) -> 9369.119 | O23: =AVERAGE(OFFSET('t43008'!$A$1,$B$2+($B23-1)*$D$2+$E$2+$A22+1,E$3):OFFSET('t43008'!$A$1,$B$2+($B23-1)*$D$2+$E$2+$F$2+$A22,E$3)) -> 19074.867 | P23: =AVERAGE(OFFSET('t86016'!$A$1,$B$2+($B23-1)*$D$2+$E$2+$A22+1,E$3):OFFSET('t86016'!$A$1,$B$2+($B23-1)*$D$2+$E$2+$F$2+$A22,E$3)) -> 38483.184 | Q23: =AVERAGE(OFFSET('t172032'!$A$1,$B$2+($B23-1)*$D$2+$E$2+$A22+1,E$3):OFFSET('t172032'!$A$1,$B$2+($B23-1)*$D$2+$E$2+$F$2+$A22,E$3)) -> 78227.835 | R23: =AVERAGE(OFFSET('t344064'!$A$1,$B$2+($B23-1)*$D$2+$E$2+$A22+1,E$3):OFFSET('t344064'!$A$1,$B$2+($B23-1)*$D$2+$E$2+$F$2+$A22,E$3)) -> #DIV/0! | S23: =AVERAGE(OFFSET('t688128'!$A$1,$B$2+($B23-1)*$D$2+$E$2+$A22+1,E$3):OFFSET('t688128'!$A$1,$B$2+($B23-1)*$D$2+$E$2+$F$2+$A22,E$3)) -> #DIV/0! | T23: =AVERAGE(OFFSET(t1376256!$A$1,$B$2+($B23-1)*$D$2+$E$2+$A22+1,E$3):OFFSET(t1376256!$A$1,$B$2+($B23-1)*$D$2+$E$2+$F$2+$A22,E$3)) -> #DIV/0!
A24: 5 | B24: 21 | C24: 64 | D24: =OFFSET('t42'!$A$1,$B$2+($B24-1)*$D$2+$A24,D$3) -> 0 | E24: =AVERAGE(OFFSET('t42'!$A$1,$B$2+($B24-1)*$D$2+$E$2+$A24,E$3):OFFSET('t42'!$A$1,$B$2+($B24-1)*$D$2+$E$2+$F$2+$A24,E$3)) -> #DIV/0! | F24: =AVERAGE(OFFSET('t84'!$A$1,$B$2+($B24-1)*$D$2+$E$2+$A24,E$3):OFFSET('t84'!$A$1,$B$2+($B24-1)*$D$2+$E$2+$F$2+$A24,E$3)) -> #DIV/0! | G24: =AVERAGE(OFFSET('t168'!$A$1,$B$2+($B24-1)*$D$2+$E$2+$A24,E$3):OFFSET('t168'!$A$1,$B$2+($B24-1)*$D$2+$E$2+$F$2+$A24,E$3)) -> #DIV/0! | H24: =AVERAGE(OFFSET('t336'!$A$1,$B$2+($B24-1)*$D$2+$E$2+$A24,E$3):OFFSET('t336'!$A$1,$B$2+($B24-1)*$D$2+$E$2+$F$2+$A24,E$3)) -> #DIV/0! | I24: =AVERAGE(OFFSET('t672'!$A$1,$B$2+($B24-1)*$D$2+$E$2+$A24,E$3):OFFSET('t672'!$A$1,$B$2+($B24-1)*$D$2+$E$2+$F$2+$A24,E$3)) -> #DIV/0! | J24: =AVERAGE(OFFSET('t1344'!$A$1,$B$2+($B24-1)*$D$2+$E$2+$A24,E$3):OFFSET('t1344'!$A$1,$B$2+($B24-1)*$D$2+$E$2+$F$2+$A24,E$3)) -> #DIV/0! | K24: =AVERAGE(OFFSET('t2688'!$A$1,$B$2+($B24-1)*$D$2+$E$2+$A24,E$3):OFFSET('t2688'!$A$1,$B$2+($B24-1)*$D$2+$E$2+$F$2+$A24,E$3)) -> #DIV/0! | L24: =AVERAGE(OFFSET('t5376'!$A$1,$B$2+($B24-1)*$D$2+$E$2+$A24,E$3):OFFSET('t5376'!$A$1,$B$2+($B24-1)*$D$2+$E$2+$F$2+$A24,E$3)) -> #DIV/0! | M24: =AVERAGE(OFFSET('t10752'!$A$1,$B$2+($B24-1)*$D$2+$E$2+$A24,E$3):OFFSET('t10752'!$A$1,$B$2+($B24-1)*$D$2+$E$2+$F$2+$A24,E$3)) -> #DIV/0! | N24: =AVERAGE(OFFSET('t21504'!$A$1,$B$2+($B24-1)*$D$2+$E$2+$A24,E$3):OFFSET('t21504'!$A$1,$B$2+($B24-1)*$D$2+$E$2+$F$2+$A24,E$3)) -> #DIV/0! | O24: =AVERAGE(OFFSET('t43008'!$A$1,$B$2+($B24-1)*$D$2+$E$2+$A24,E$3):OFFSET('t43008'!$A$1,$B$2+($B24-1)*$D$2+$E$2+$F$2+$A24,E$3)) -> #DIV/0! | P24: =AVERAGE(OFFSET('t86016'!$A$1,$B$2+($B24-1)*$D$2+$E$2+$A24,E$3):OFFSET('t86016'!$A$1,$B$2+($B24-1)*$D$2+$E$2+$F$2+$A24,E$3)) -> #DIV/0! | Q24: =AVERAGE(OFFSET('t172032'!$A$1,$B$2+($B24-1)*$D$2+$E$2+$A24,E$3):OFFSET('t172032'!$A$1,$B$2+($B24-1)*$D$2+$E$2+$F$2+$A24,E$3)) -> #DIV/0! | R24: =AVERAGE(OFFSET('t344064'!$A$1,$B$2+($B24-1)*$D$2+$E$2+$A24,E$3):OFFSET('t344064'!$A$1,$B$2+($B24-1)*$D$2+$E$2+$F$2+$A24,E$3)) -> #DIV/0! | S24: =AVERAGE(OFFSET('t688128'!$A$1,$B$2+($B24-1)*$D$2+$E$2+$A24,E$3):OFFSET('t688128'!$A$1,$B$2+($B24-1)*$D$2+$E$2+$F$2+$A24,E$3)) -> #DIV/0! | T24: =AVERAGE(OFFSET(t1376256!$A$1,$B$2+($B24-1)*$D$2+$E$2+$A24,E$3):OFFSET(t1376256!$A$1,$B$2+($B24-1)*$D$2+$E$2+$F$2+$A24,E$3)) -> #DIV/0!
A25: 5 | B25: 22 | D25: =OFFSET('t42'!$A$1,$B$2+($B25-1)*$D$2+$A24,D$3) -> 0 | E25: =AVERAGE(OFFSET('t42'!$A$1,$B$2+($B25-1)*$D$2+$E$2+$A24+1,E$3):OFFSET('t42'!$A$1,$B$2+($B25-1)*$D$2+$E$2+$F$2+$A24,E$3)) -> #DIV/0! | F25: =AVERAGE(OFFSET('t84'!$A$1,$B$2+($B25-1)*$D$2+$E$2+$A24+1,E$3):OFFSET('t84'!$A$1,$B$2+($B25-1)*$D$2+$E$2+$F$2+$A24,E$3)) -> #DIV/0! | G25: =AVERAGE(OFFSET('t168'!$A$1,$B$2+($B25-1)*$D$2+$E$2+$A24+1,E$3):OFFSET('t168'!$A$1,$B$2+($B25-1)*$D$2+$E$2+$F$2+$A24,E$3)) -> #DIV/0! | H25: =AVERAGE(OFFSET('t336'!$A$1,$B$2+($B25-1)*$D$2+$E$2+$A24+1,E$3):OFFSET('t336'!$A$1,$B$2+($B25-1)*$D$2+$E$2+$F$2+$A24,E$3)) -> #DIV/0! | I25: =AVERAGE(OFFSET('t672'!$A$1,$B$2+($B25-1)*$D$2+$E$2+$A24+1,E$3):OFFSET('t672'!$A$1,$B$2+($B25-1)*$D$2+$E$2+$F$2+$A24,E$3)) -> #DIV/0! | J25: =AVERAGE(OFFSET('t1344'!$A$1,$B$2+($B25-1)*$D$2+$E$2+$A24+1,E$3):OFFSET('t1344'!$A$1,$B$2+($B25-1)*$D$2+$E$2+$F$2+$A24,E$3)) -> #DIV/0! | K25: =AVERAGE(OFFSET('t2688'!$A$1,$B$2+($B25-1)*$D$2+$E$2+$A24+1,E$3):OFFSET('t2688'!$A$1,$B$2+($B25-1)*$D$2+$E$2+$F$2+$A24,E$3)) -> #DIV/0! | L25: =AVERAGE(OFFSET('t5376'!$A$1,$B$2+($B25-1)*$D$2+$E$2+$A24+1,E$3):OFFSET('t5376'!$A$1,$B$2+($B25-1)*$D$2+$E$2+$F$2+$A24,E$3)) -> #DIV/0! | M25: =AVERAGE(OFFSET('t10752'!$A$1,$B$2+($B25-1)*$D$2+$E$2+$A24+1,E$3):OFFSET('t10752'!$A$1,$B$2+($B25-1)*$D$2+$E$2+$F$2+$A24,E$3)) -> #DIV/0! | N25: =AVERAGE(OFFSET('t21504'!$A$1,$B$2+($B25-1)*$D$2+$E$2+$A24+1,E$3):OFFSET('t21504'!$A$1,$B$2+($B25-1)*$D$2+$E$2+$F$2+$A24,E$3)) -> #DIV/0! | O25: =AVERAGE(OFFSET('t43008'!$A$1,$B$2+($B25-1)*$D$2+$E$2+$A24+1,E$3):OFFSET('t43008'!$A$1,$B$2+($B25-1)*$D$2+$E$2+$F$2+$A24,E$3)) -> #DIV/0! | P25: =AVERAGE(OFFSET('t86016'!$A$1,$B$2+($B25-1)*$D$2+$E$2+$A24+1,E$3):OFFSET('t86016'!$A$1,$B$2+($B25-1)*$D$2+$E$2+$F$2+$A24,E$3)) -> #DIV/0! | Q25: =AVERAGE(OFFSET('t172032'!$A$1,$B$2+($B25-1)*$D$2+$E$2+$A24+1,E$3):OFFSET('t172032'!$A$1,$B$2+($B25-1)*$D$2+$E$2+$F$2+$A24,E$3)) -> #DIV/0! | R25: =AVERAGE(OFFSET('t344064'!$A$1,$B$2+($B25-1)*$D$2+$E$2+$A24+1,E$3):OFFSET('t344064'!$A$1,$B$2+($B25-1)*$D$2+$E$2+$F$2+$A24,E$3)) -> #DIV/0! | S25: =AVERAGE(OFFSET('t688128'!$A$1,$B$2+($B25-1)*$D$2+$E$2+$A24+1,E$3):OFFSET('t688128'!$A$1,$B$2+($B25-1)*$D$2+$E$2+$F$2+$A24,E$3)) -> #DIV/0! | T25: =AVERAGE(OFFSET(t1376256!$A$1,$B$2+($B25-1)*$D$2+$E$2+$A24+1,E$3):OFFSET(t1376256!$A$1,$B$2+($B25-1)*$D$2+$E$2+$F$2+$A24,E$3)) -> #DIV/0!
A26: 5 | B26: 23 | D26: =OFFSET('t42'!$A$1,$B$2+($B26-1)*$D$2+$A24,D$3) -> 0 | E26: =AVERAGE(OFFSET('t42'!$A$1,$B$2+($B26-1)*$D$2+$E$2+$A25+1,E$3):OFFSET('t42'!$A$1,$B$2+($B26-1)*$D$2+$E$2+$F$2+$A25,E$3)) -> #DIV/0! | F26: =AVERAGE(OFFSET('t84'!$A$1,$B$2+($B26-1)*$D$2+$E$2+$A25+1,E$3):OFFSET('t84'!$A$1,$B$2+($B26-1)*$D$2+$E$2+$F$2+$A25,E$3)) -> #DIV/0! | G26: =AVERAGE(OFFSET('t168'!$A$1,$B$2+($B26-1)*$D$2+$E$2+$A25+1,E$3):OFFSET('t168'!$A$1,$B$2+($B26-1)*$D$2+$E$2+$F$2+$A25,E$3)) -> #DIV/0! | H26: =AVERAGE(OFFSET('t336'!$A$1,$B$2+($B26-1)*$D$2+$E$2+$A25+1,E$3):OFFSET('t336'!$A$1,$B$2+($B26-1)*$D$2+$E$2+$F$2+$A25,E$3)) -> #DIV/0! | I26: =AVERAGE(OFFSET('t672'!$A$1,$B$2+($B26-1)*$D$2+$E$2+$A25+1,E$3):OFFSET('t672'!$A$1,$B$2+($B26-1)*$D$2+$E$2+$F$2+$A25,E$3)) -> #DIV/0! | J26: =AVERAGE(OFFSET('t1344'!$A$1,$B$2+($B26-1)*$D$2+$E$2+$A25+1,E$3):OFFSET('t1344'!$A$1,$B$2+($B26-1)*$D$2+$E$2+$F$2+$A25,E$3)) -> #DIV/0! | K26: =AVERAGE(OFFSET('t2688'!$A$1,$B$2+($B26-1)*$D$2+$E$2+$A25+1,E$3):OFFSET('t2688'!$A$1,$B$2+($B26-1)*$D$2+$E$2+$F$2+$A25,E$3)) -> #DIV/0! | L26: =AVERAGE(OFFSET('t5376'!$A$1,$B$2+($B26-1)*$D$2+$E$2+$A25+1,E$3):OFFSET('t5376'!$A$1,$B$2+($B26-1)*$D$2+$E$2+$F$2+$A25,E$3)) -> #DIV/0! | M26: =AVERAGE(OFFSET('t10752'!$A$1,$B$2+($B26-1)*$D$2+$E$2+$A25+1,E$3):OFFSET('t10752'!$A$1,$B$2+($B26-1)*$D$2+$E$2+$F$2+$A25,E$3)) -> #DIV/0! | N26: =AVERAGE(OFFSET('t21504'!$A$1,$B$2+($B26-1)*$D$2+$E$2+$A25+1,E$3):OFFSET('t21504'!$A$1,$B$2+($B26-1)*$D$2+$E$2+$F$2+$A25,E$3)) -> #DIV/0! | O26: =AVERAGE(OFFSET('t43008'!$A$1,$B$2+($B26-1)*$D$2+$E$2+$A25+1,E$3):OFFSET('t43008'!$A$1,$B$2+($B26-1)*$D$2+$E$2+$F$2+$A25,E$3)) -> #DIV/0! | P26: =AVERAGE(OFFSET('t86016'!$A$1,$B$2+($B26-1)*$D$2+$E$2+$A25+1,E$3):OFFSET('t86016'!$A$1,$B$2+($B26-1)*$D$2+$E$2+$F$2+$A25,E$3)) -> #DIV/0! | Q26: =AVERAGE(OFFSET('t172032'!$A$1,$B$2+($B26-1)*$D$2+$E$2+$A25+1,E$3):OFFSET('t172032'!$A$1,$B$2+($B26-1)*$D$2+$E$2+$F$2+$A25,E$3)) -> #DIV/0! | R26: =AVERAGE(OFFSET('t344064'!$A$1,$B$2+($B26-1)*$D$2+$E$2+$A25+1,E$3):OFFSET('t344064'!$A$1,$B$2+($B26-1)*$D$2+$E$2+$F$2+$A25,E$3)) -> #DIV/0! | S26: =AVERAGE(OFFSET('t688128'!$A$1,$B$2+($B26-1)*$D$2+$E$2+$A25+1,E$3):OFFSET('t688128'!$A$1,$B$2+($B26-1)*$D$2+$E$2+$F$2+$A25,E$3)) -> #DIV/0! | T26: =AVERAGE(OFFSET(t1376256!$A$1,$B$2+($B26-1)*$D$2+$E$2+$A25+1,E$3):OFFSET(t1376256!$A$1,$B$2+($B26-1)*$D$2+$E$2+$F$2+$A25,E$3)) -> #DIV/0!
A27: 5 | B27: 24 | D27: =OFFSET('t42'!$A$1,$B$2+($B27-1)*$D$2+$A25,D$3) -> 0 | E27: =AVERAGE(OFFSET('t42'!$A$1,$B$2+($B27-1)*$D$2+$E$2+$A26+1,E$3):OFFSET('t42'!$A$1,$B$2+($B27-1)*$D$2+$E$2+$F$2+$A26,E$3)) -> #DIV/0! | F27: =AVERAGE(OFFSET('t84'!$A$1,$B$2+($B27-1)*$D$2+$E$2+$A26+1,E$3):OFFSET('t84'!$A$1,$B$2+($B27-1)*$D$2+$E$2+$F$2+$A26,E$3)) -> #DIV/0! | G27: =AVERAGE(OFFSET('t168'!$A$1,$B$2+($B27-1)*$D$2+$E$2+$A26+1,E$3):OFFSET('t168'!$A$1,$B$2+($B27-1)*$D$2+$E$2+$F$2+$A26,E$3)) -> #DIV/0! | H27: =AVERAGE(OFFSET('t336'!$A$1,$B$2+($B27-1)*$D$2+$E$2+$A26+1,E$3):OFFSET('t336'!$A$1,$B$2+($B27-1)*$D$2+$E$2+$F$2+$A26,E$3)) -> #DIV/0! | I27: =AVERAGE(OFFSET('t672'!$A$1,$B$2+($B27-1)*$D$2+$E$2+$A26+1,E$3):OFFSET('t672'!$A$1,$B$2+($B27-1)*$D$2+$E$2+$F$2+$A26,E$3)) -> #DIV/0! | J27: =AVERAGE(OFFSET('t1344'!$A$1,$B$2+($B27-1)*$D$2+$E$2+$A26+1,E$3):OFFSET('t1344'!$A$1,$B$2+($B27-1)*$D$2+$E$2+$F$2+$A26,E$3)) -> #DIV/0! | K27: =AVERAGE(OFFSET('t2688'!$A$1,$B$2+($B27-1)*$D$2+$E$2+$A26+1,E$3):OFFSET('t2688'!$A$1,$B$2+($B27-1)*$D$2+$E$2+$F$2+$A26,E$3)) -> #DIV/0! | L27: =AVERAGE(OFFSET('t5376'!$A$1,$B$2+($B27-1)*$D$2+$E$2+$A26+1,E$3):OFFSET('t5376'!$A$1,$B$2+($B27-1)*$D$2+$E$2+$F$2+$A26,E$3)) -> #DIV/0! | M27: =AVERAGE(OFFSET('t10752'!$A$1,$B$2+($B27-1)*$D$2+$E$2+$A26+1,E$3):OFFSET('t10752'!$A$1,$B$2+($B27-1)*$D$2+$E$2+$F$2+$A26,E$3)) -> #DIV/0! | N27: =AVERAGE(OFFSET('t21504'!$A$1,$B$2+($B27-1)*$D$2+$E$2+$A26+1,E$3):OFFSET('t21504'!$A$1,$B$2+($B27-1)*$D$2+$E$2+$F$2+$A26,E$3)) -> #DIV/0! | O27: =AVERAGE(OFFSET('t43008'!$A$1,$B$2+($B27-1)*$D$2+$E$2+$A26+1,E$3):OFFSET('t43008'!$A$1,$B$2+($B27-1)*$D$2+$E$2+$F$2+$A26,E$3)) -> #DIV/0! | P27: =AVERAGE(OFFSET('t86016'!$A$1,$B$2+($B27-1)*$D$2+$E$2+$A26+1,E$3):OFFSET('t86016'!$A$1,$B$2+($B27-1)*$D$2+$E$2+$F$2+$A26,E$3)) -> #DIV/0! | Q27: =AVERAGE(OFFSET('t172032'!$A$1,$B$2+($B27-1)*$D$2+$E$2+$A26+1,E$3):OFFSET('t172032'!$A$1,$B$2+($B27-1)*$D$2+$E$2+$F$2+$A26,E$3)) -> #DIV/0! | R27: =AVERAGE(OFFSET('t344064'!$A$1,$B$2+($B27-1)*$D$2+$E$2+$A26+1,E$3):OFFSET('t344064'!$A$1,$B$2+($B27-1)*$D$2+$E$2+$F$2+$A26,E$3)) -> #DIV/0! | S27: =AVERAGE(OFFSET('t688128'!$A$1,$B$2+($B27-1)*$D$2+$E$2+$A26+1,E$3):OFFSET('t688128'!$A$1,$B$2+($B27-1)*$D$2+$E$2+$F$2+$A26,E$3)) -> #DIV/0! | T27: =AVERAGE(OFFSET(t1376256!$A$1,$B$2+($B27-1)*$D$2+$E$2+$A26+1,E$3):OFFSET(t1376256!$A$1,$B$2+($B27-1)*$D$2+$E$2+$F$2+$A26,E$3)) -> #DIV/0!
